{
  "version": 8,
  "blockIdVersion": 11,
  "anchorX": 0,
  "anchorY": 0,
  "anchorZ": 0,
  "blocks": [
    {
      "x": -3,
      "y": 0,
      "z": -1,
      "name": "Rock_Crystal_White_Block"
    },
    {
      "x": -3,
      "y": -1,
      "z": 0,
      "name": "Rock_Crystal_White_Block"
    },
    {
      "x": -3,
      "y": 0,
      "z": 0,
      "name": "Rock_Crystal_White_Block"
    },
    {
      "x": -3,
      "y": 1,
      "z": 0,
      "name": "Rock_Crystal_White_Block",
      "rotation": 2
    },
    {
      "x": -3,
      "y": 0,
      "z": 1,
      "name": "Rock_Crystal_White_Block",
      "rotation": 2
    },
    {
      "x": -2,
      "y": -7,
      "z": -12,
      "name": "Rock_Crystal_White_Block"
    },
    {
      "x": -2,
      "y": 7,
      "z": -12,
      "name": "Rock_Crystal_White_Block"
    },
    {
      "x": -2,
      "y": -7,
      "z": -11,
      "name": "Rock_Crystal_White_Block"
    },
    {
      "x": -2,
      "y": 7,
      "z": -11,
      "name": "Rock_Crystal_White_Block"
    },
    {
      "x": -2,
      "y": -6,
      "z": -10,
      "name": "Rock_Crystal_White_Block"
    },
    {
      "x": -2,
      "y": 6,
      "z": -10,
      "name": "Rock_Crystal_White_Block"
    },
    {
      "x": -2,
      "y": -5,
      "z": -9,
      "name": "Rock_Crystal_White_Block"
    },
    {
      "x": -2,
      "y": 5,
      "z": -9,
      "name": "Rock_Crystal_White_Block"
    },
    {
      "x": -2,
      "y": -5,
      "z": -8,
      "name": "Rock_Crystal_White_Block"
    },
    {
      "x": -2,
      "y": 5,
      "z": -8,
      "name": "Rock_Crystal_White_Block"
    },
    {
      "x": -2,
      "y": -4,
      "z": -7,
      "name": "Rock_Crystal_White_Block"
    },
    {
      "x": -2,
      "y": 4,
      "z": -7,
      "name": "Rock_Crystal_White_Block"
    },
    {
      "x": -2,
      "y": -3,
      "z": -6,
      "name": "Rock_Crystal_White_Block"
    },
    {
      "x": -2,
      "y": 3,
      "z": -6,
      "name": "Rock_Crystal_White_Block"
    },
    {
      "x": -2,
      "y": -3,
      "z": -5,
      "name": "Rock_Crystal_White_Block"
    },
    {
      "x": -2,
      "y": 3,
      "z": -5,
      "name": "Rock_Crystal_White_Block"
    },
    {
      "x": -2,
      "y": -2,
      "z": -4,
      "name": "Rock_Crystal_White_Block"
    },
    {
      "x": -2,
      "y": 2,
      "z": -4,
      "name": "Rock_Crystal_White_Block"
    },
    {
      "x": -2,
      "y": -1,
      "z": -3,
      "name": "Rock_Crystal_White_Block"
    },
    {
      "x": -2,
      "y": 1,
      "z": -3,
      "name": "Rock_Crystal_White_Block"
    },
    {
      "x": -2,
      "y": -1,
      "z": -2,
      "name": "Rock_Crystal_White_Block"
    },
    {
      "x": -2,
      "y": 0,
      "z": -2,
      "name": "Rock_Crystal_White_Block"
    },
    {
      "x": -2,
      "y": 1,
      "z": -2,
      "name": "Rock_Crystal_White_Block"
    },
    {
      "x": -2,
      "y": -2,
      "z": -1,
      "name": "Rock_Crystal_White_Block"
    },
    {
      "x": -2,
      "y": -1,
      "z": -1,
      "name": "Rock_Crystal_White_Block"
    },
    {
      "x": -2,
      "y": 0,
      "z": -1,
      "name": "Rock_Crystal_White_Block"
    },
    {
      "x": -2,
      "y": 1,
      "z": -1,
      "name": "Rock_Crystal_White_Block"
    },
    {
      "x": -2,
      "y": 2,
      "z": -1,
      "name": "Rock_Crystal_White_Block"
    },
    {
      "x": -2,
      "y": -12,
      "z": 0,
      "name": "Rock_Crystal_White_Block"
    },
    {
      "x": -2,
      "y": -11,
      "z": 0,
      "name": "Rock_Crystal_White_Block"
    },
    {
      "x": -2,
      "y": -10,
      "z": 0,
      "name": "Rock_Crystal_White_Block"
    },
    {
      "x": -2,
      "y": -9,
      "z": 0,
      "name": "Rock_Crystal_White_Block"
    },
    {
      "x": -2,
      "y": -8,
      "z": 0,
      "name": "Rock_Crystal_White_Block"
    },
    {
      "x": -2,
      "y": -7,
      "z": 0,
      "name": "Rock_Crystal_White_Block"
    },
    {
      "x": -2,
      "y": -6,
      "z": 0,
      "name": "Rock_Crystal_White_Block"
    },
    {
      "x": -2,
      "y": -5,
      "z": 0,
      "name": "Rock_Crystal_White_Block"
    },
    {
      "x": -2,
      "y": -4,
      "z": 0,
      "name": "Rock_Crystal_White_Block"
    },
    {
      "x": -2,
      "y": -3,
      "z": 0,
      "name": "Rock_Crystal_White_Block"
    },
    {
      "x": -2,
      "y": -2,
      "z": 0,
      "name": "Rock_Crystal_White_Block"
    },
    {
      "x": -2,
      "y": -1,
      "z": 0,
      "name": "Rock_Crystal_White_Block"
    },
    {
      "x": -2,
      "y": 0,
      "z": 0,
      "name": "Rock_Crystal_White_Block"
    },
    {
      "x": -2,
      "y": 1,
      "z": 0,
      "name": "Rock_Crystal_White_Block",
      "rotation": 2
    },
    {
      "x": -2,
      "y": 2,
      "z": 0,
      "name": "Rock_Crystal_White_Block",
      "rotation": 2
    },
    {
      "x": -2,
      "y": 3,
      "z": 0,
      "name": "Rock_Crystal_White_Block",
      "rotation": 2
    },
    {
      "x": -2,
      "y": 4,
      "z": 0,
      "name": "Rock_Crystal_White_Block",
      "rotation": 2
    },
    {
      "x": -2,
      "y": 5,
      "z": 0,
      "name": "Rock_Crystal_White_Block",
      "rotation": 2
    },
    {
      "x": -2,
      "y": 6,
      "z": 0,
      "name": "Rock_Crystal_White_Block",
      "rotation": 2
    },
    {
      "x": -2,
      "y": 7,
      "z": 0,
      "name": "Rock_Crystal_White_Block",
      "rotation": 2
    },
    {
      "x": -2,
      "y": 8,
      "z": 0,
      "name": "Rock_Crystal_White_Block",
      "rotation": 2
    },
    {
      "x": -2,
      "y": 9,
      "z": 0,
      "name": "Rock_Crystal_White_Block",
      "rotation": 2
    },
    {
      "x": -2,
      "y": 10,
      "z": 0,
      "name": "Rock_Crystal_White_Block",
      "rotation": 2
    },
    {
      "x": -2,
      "y": 11,
      "z": 0,
      "name": "Rock_Crystal_White_Block",
      "rotation": 2
    },
    {
      "x": -2,
      "y": 12,
      "z": 0,
      "name": "Rock_Crystal_White_Block",
      "rotation": 2
    },
    {
      "x": -2,
      "y": -2,
      "z": 1,
      "name": "Rock_Crystal_White_Block"
    },
    {
      "x": -2,
      "y": -1,
      "z": 1,
      "name": "Rock_Crystal_White_Block",
      "rotation": 2
    },
    {
      "x": -2,
      "y": 0,
      "z": 1,
      "name": "Rock_Crystal_White_Block",
      "rotation": 2
    },
    {
      "x": -2,
      "y": 1,
      "z": 1,
      "name": "Rock_Crystal_White_Block",
      "rotation": 2
    },
    {
      "x": -2,
      "y": 2,
      "z": 1,
      "name": "Rock_Crystal_White_Block"
    },
    {
      "x": -2,
      "y": -1,
      "z": 2,
      "name": "Rock_Crystal_White_Block",
      "rotation": 2
    },
    {
      "x": -2,
      "y": 0,
      "z": 2,
      "name": "Rock_Crystal_White_Block"
    },
    {
      "x": -2,
      "y": 1,
      "z": 2,
      "name": "Rock_Crystal_White_Block",
      "rotation": 2
    },
    {
      "x": -2,
      "y": -1,
      "z": 3,
      "name": "Rock_Crystal_White_Block",
      "rotation": 2
    },
    {
      "x": -2,
      "y": 1,
      "z": 3,
      "name": "Rock_Crystal_White_Block",
      "rotation": 2
    },
    {
      "x": -2,
      "y": -2,
      "z": 4,
      "name": "Rock_Crystal_White_Block",
      "rotation": 2
    },
    {
      "x": -2,
      "y": 2,
      "z": 4,
      "name": "Rock_Crystal_White_Block",
      "rotation": 2
    },
    {
      "x": -2,
      "y": -3,
      "z": 5,
      "name": "Rock_Crystal_White_Block",
      "rotation": 2
    },
    {
      "x": -2,
      "y": 3,
      "z": 5,
      "name": "Rock_Crystal_White_Block",
      "rotation": 2
    },
    {
      "x": -2,
      "y": -3,
      "z": 6,
      "name": "Rock_Crystal_White_Block",
      "rotation": 2
    },
    {
      "x": -2,
      "y": 3,
      "z": 6,
      "name": "Rock_Crystal_White_Block",
      "rotation": 2
    },
    {
      "x": -2,
      "y": -4,
      "z": 7,
      "name": "Rock_Crystal_White_Block",
      "rotation": 2
    },
    {
      "x": -2,
      "y": 4,
      "z": 7,
      "name": "Rock_Crystal_White_Block",
      "rotation": 2
    },
    {
      "x": -2,
      "y": -5,
      "z": 8,
      "name": "Rock_Crystal_White_Block",
      "rotation": 2
    },
    {
      "x": -2,
      "y": 5,
      "z": 8,
      "name": "Rock_Crystal_White_Block",
      "rotation": 2
    },
    {
      "x": -2,
      "y": -5,
      "z": 9,
      "name": "Rock_Crystal_White_Block",
      "rotation": 2
    },
    {
      "x": -2,
      "y": 5,
      "z": 9,
      "name": "Rock_Crystal_White_Block",
      "rotation": 2
    },
    {
      "x": -2,
      "y": -6,
      "z": 10,
      "name": "Rock_Crystal_White_Block",
      "rotation": 2
    },
    {
      "x": -2,
      "y": 6,
      "z": 10,
      "name": "Rock_Crystal_White_Block",
      "rotation": 2
    },
    {
      "x": -2,
      "y": -7,
      "z": 11,
      "name": "Rock_Crystal_White_Block",
      "rotation": 2
    },
    {
      "x": -2,
      "y": 7,
      "z": 11,
      "name": "Rock_Crystal_White_Block",
      "rotation": 2
    },
    {
      "x": -2,
      "y": -7,
      "z": 12,
      "name": "Rock_Crystal_White_Block",
      "rotation": 2
    },
    {
      "x": -2,
      "y": 7,
      "z": 12,
      "name": "Rock_Crystal_White_Block",
      "rotation": 2
    },
    {
      "x": -1,
      "y": -10,
      "z": -16,
      "name": "Rock_Crystal_White_Block"
    },
    {
      "x": -1,
      "y": 10,
      "z": -16,
      "name": "Rock_Crystal_White_Block"
    },
    {
      "x": -1,
      "y": -9,
      "z": -15,
      "name": "Rock_Crystal_White_Block"
    },
    {
      "x": -1,
      "y": -7,
      "z": -15,
      "name": "Rock_Crystal_White_Block"
    },
    {
      "x": -1,
      "y": 7,
      "z": -15,
      "name": "Rock_Crystal_White_Block"
    },
    {
      "x": -1,
      "y": 9,
      "z": -15,
      "name": "Rock_Crystal_White_Block"
    },
    {
      "x": -1,
      "y": -9,
      "z": -14,
      "name": "Rock_Crystal_White_Block"
    },
    {
      "x": -1,
      "y": -8,
      "z": -14,
      "name": "Rock_Crystal_White_Block"
    },
    {
      "x": -1,
      "y": -6,
      "z": -14,
      "name": "Rock_Crystal_White_Block"
    },
    {
      "x": -1,
      "y": 6,
      "z": -14,
      "name": "Rock_Crystal_White_Block"
    },
    {
      "x": -1,
      "y": 8,
      "z": -14,
      "name": "Rock_Crystal_White_Block"
    },
    {
      "x": -1,
      "y": 9,
      "z": -14,
      "name": "Rock_Crystal_White_Block"
    },
    {
      "x": -1,
      "y": -10,
      "z": -13,
      "name": "Rock_Crystal_White_Block"
    },
    {
      "x": -1,
      "y": -8,
      "z": -13,
      "name": "Rock_Crystal_White_Block"
    },
    {
      "x": -1,
      "y": -7,
      "z": -13,
      "name": "Rock_Crystal_White_Block"
    },
    {
      "x": -1,
      "y": 7,
      "z": -13,
      "name": "Rock_Crystal_White_Block"
    },
    {
      "x": -1,
      "y": 8,
      "z": -13,
      "name": "Rock_Crystal_White_Block"
    },
    {
      "x": -1,
      "y": 10,
      "z": -13,
      "name": "Rock_Crystal_White_Block"
    },
    {
      "x": -1,
      "y": -9,
      "z": -12,
      "name": "Rock_Crystal_White_Block"
    },
    {
      "x": -1,
      "y": -7,
      "z": -12,
      "name": "Rock_Crystal_White_Block"
    },
    {
      "x": -1,
      "y": -5,
      "z": -12,
      "name": "Rock_Crystal_White_Block"
    },
    {
      "x": -1,
      "y": 5,
      "z": -12,
      "name": "Rock_Crystal_White_Block"
    },
    {
      "x": -1,
      "y": 7,
      "z": -12,
      "name": "Rock_Crystal_White_Block"
    },
    {
      "x": -1,
      "y": 9,
      "z": -12,
      "name": "Rock_Crystal_White_Block"
    },
    {
      "x": -1,
      "y": -7,
      "z": -11,
      "name": "Rock_Crystal_White_Block"
    },
    {
      "x": -1,
      "y": -6,
      "z": -11,
      "name": "Rock_Crystal_White_Block"
    },
    {
      "x": -1,
      "y": -3,
      "z": -11,
      "name": "Rock_Crystal_White_Block"
    },
    {
      "x": -1,
      "y": 3,
      "z": -11,
      "name": "Rock_Crystal_White_Block"
    },
    {
      "x": -1,
      "y": 6,
      "z": -11,
      "name": "Rock_Crystal_White_Block"
    },
    {
      "x": -1,
      "y": 7,
      "z": -11,
      "name": "Rock_Crystal_White_Block"
    },
    {
      "x": -1,
      "y": -8,
      "z": -10,
      "name": "Rock_Crystal_White_Block"
    },
    {
      "x": -1,
      "y": -6,
      "z": -10,
      "name": "Rock_Crystal_White_Block"
    },
    {
      "x": -1,
      "y": -4,
      "z": -10,
      "name": "Rock_Crystal_White_Block"
    },
    {
      "x": -1,
      "y": 4,
      "z": -10,
      "name": "Rock_Crystal_White_Block"
    },
    {
      "x": -1,
      "y": 6,
      "z": -10,
      "name": "Rock_Crystal_White_Block"
    },
    {
      "x": -1,
      "y": 8,
      "z": -10,
      "name": "Rock_Crystal_White_Block"
    },
    {
      "x": -1,
      "y": -5,
      "z": -9,
      "name": "Rock_Crystal_White_Block"
    },
    {
      "x": -1,
      "y": -2,
      "z": -9,
      "name": "Rock_Crystal_White_Block"
    },
    {
      "x": -1,
      "y": 2,
      "z": -9,
      "name": "Rock_Crystal_White_Block"
    },
    {
      "x": -1,
      "y": 5,
      "z": -9,
      "name": "Rock_Crystal_White_Block"
    },
    {
      "x": -1,
      "y": -7,
      "z": -8,
      "name": "Rock_Crystal_White_Block"
    },
    {
      "x": -1,
      "y": -6,
      "z": -8,
      "name": "Rock_Crystal_White_Block"
    },
    {
      "x": -1,
      "y": -5,
      "z": -8,
      "name": "Rock_Crystal_White_Block"
    },
    {
      "x": -1,
      "y": -3,
      "z": -8,
      "name": "Rock_Crystal_White_Block"
    },
    {
      "x": -1,
      "y": 3,
      "z": -8,
      "name": "Rock_Crystal_White_Block"
    },
    {
      "x": -1,
      "y": 5,
      "z": -8,
      "name": "Rock_Crystal_White_Block"
    },
    {
      "x": -1,
      "y": 6,
      "z": -8,
      "name": "Rock_Crystal_White_Block"
    },
    {
      "x": -1,
      "y": 7,
      "z": -8,
      "name": "Rock_Crystal_White_Block"
    },
    {
      "x": -1,
      "y": -5,
      "z": -7,
      "name": "Rock_Crystal_White_Block"
    },
    {
      "x": -1,
      "y": -4,
      "z": -7,
      "name": "Rock_Crystal_White_Block"
    },
    {
      "x": -1,
      "y": 4,
      "z": -7,
      "name": "Rock_Crystal_White_Block"
    },
    {
      "x": -1,
      "y": 5,
      "z": -7,
      "name": "Rock_Crystal_White_Block"
    },
    {
      "x": -1,
      "y": -7,
      "z": -6,
      "name": "Rock_Crystal_White_Block"
    },
    {
      "x": -1,
      "y": -6,
      "z": -6,
      "name": "Rock_Crystal_White_Block"
    },
    {
      "x": -1,
      "y": -3,
      "z": -6,
      "name": "Rock_Crystal_White_Block"
    },
    {
      "x": -1,
      "y": -2,
      "z": -6,
      "name": "Rock_Crystal_White_Block"
    },
    {
      "x": -1,
      "y": 2,
      "z": -6,
      "name": "Rock_Crystal_White_Block"
    },
    {
      "x": -1,
      "y": 3,
      "z": -6,
      "name": "Rock_Crystal_White_Block"
    },
    {
      "x": -1,
      "y": 6,
      "z": -6,
      "name": "Rock_Crystal_White_Block"
    },
    {
      "x": -1,
      "y": 7,
      "z": -6,
      "name": "Rock_Crystal_White_Block"
    },
    {
      "x": -1,
      "y": -4,
      "z": -5,
      "name": "Rock_Crystal_White_Block"
    },
    {
      "x": -1,
      "y": -3,
      "z": -5,
      "name": "Rock_Crystal_White_Block"
    },
    {
      "x": -1,
      "y": -1,
      "z": -5,
      "name": "Rock_Crystal_White_Block"
    },
    {
      "x": -1,
      "y": 1,
      "z": -5,
      "name": "Rock_Crystal_White_Block"
    },
    {
      "x": -1,
      "y": 3,
      "z": -5,
      "name": "Rock_Crystal_White_Block"
    },
    {
      "x": -1,
      "y": 4,
      "z": -5,
      "name": "Rock_Crystal_White_Block"
    },
    {
      "x": -1,
      "y": -5,
      "z": -4,
      "name": "Rock_Crystal_White_Block"
    },
    {
      "x": -1,
      "y": -2,
      "z": -4,
      "name": "Rock_Crystal_White_Block"
    },
    {
      "x": -1,
      "y": 0,
      "z": -4,
      "name": "Rock_Crystal_White_Block"
    },
    {
      "x": -1,
      "y": 2,
      "z": -4,
      "name": "Rock_Crystal_White_Block"
    },
    {
      "x": -1,
      "y": 5,
      "z": -4,
      "name": "Rock_Crystal_White_Block"
    },
    {
      "x": -1,
      "y": -3,
      "z": -3,
      "name": "Rock_Crystal_White_Block"
    },
    {
      "x": -1,
      "y": -1,
      "z": -3,
      "name": "Rock_Crystal_White_Block"
    },
    {
      "x": -1,
      "y": 1,
      "z": -3,
      "name": "Rock_Crystal_White_Block"
    },
    {
      "x": -1,
      "y": 3,
      "z": -3,
      "name": "Rock_Crystal_White_Block"
    },
    {
      "x": -1,
      "y": -14,
      "z": -2,
      "name": "Rock_Crystal_White_Block"
    },
    {
      "x": -1,
      "y": -11,
      "z": -2,
      "name": "Rock_Crystal_White_Block"
    },
    {
      "x": -1,
      "y": -9,
      "z": -2,
      "name": "Rock_Crystal_White_Block"
    },
    {
      "x": -1,
      "y": -2,
      "z": -2,
      "name": "Rock_Crystal_White_Block"
    },
    {
      "x": -1,
      "y": -1,
      "z": -2,
      "name": "Rock_Crystal_White_Block"
    },
    {
      "x": -1,
      "y": 0,
      "z": -2,
      "name": "Rock_Crystal_White_Block"
    },
    {
      "x": -1,
      "y": 1,
      "z": -2,
      "name": "Rock_Crystal_White_Block"
    },
    {
      "x": -1,
      "y": 2,
      "z": -2,
      "name": "Rock_Crystal_White_Block"
    },
    {
      "x": -1,
      "y": 9,
      "z": -2,
      "name": "Rock_Crystal_White_Block"
    },
    {
      "x": -1,
      "y": 11,
      "z": -2,
      "name": "Rock_Crystal_White_Block"
    },
    {
      "x": -1,
      "y": 14,
      "z": -2,
      "name": "Rock_Crystal_White_Block"
    },
    {
      "x": -1,
      "y": -16,
      "z": -1,
      "name": "Rock_Crystal_White_Block"
    },
    {
      "x": -1,
      "y": -13,
      "z": -1,
      "name": "Rock_Crystal_White_Block"
    },
    {
      "x": -1,
      "y": -11,
      "z": -1,
      "name": "Rock_Crystal_White_Block"
    },
    {
      "x": -1,
      "y": -8,
      "z": -1,
      "name": "Rock_Crystal_White_Block"
    },
    {
      "x": -1,
      "y": -6,
      "z": -1,
      "name": "Rock_Crystal_White_Block"
    },
    {
      "x": -1,
      "y": -4,
      "z": -1,
      "name": "Rock_Crystal_White_Block"
    },
    {
      "x": -1,
      "y": -3,
      "z": -1,
      "name": "Rock_Crystal_White_Block"
    },
    {
      "x": -1,
      "y": -2,
      "z": -1,
      "name": "Rock_Crystal_White_Block"
    },
    {
      "x": -1,
      "y": -1,
      "z": -1,
      "name": "Rock_Crystal_White_Block"
    },
    {
      "x": -1,
      "y": 0,
      "z": -1,
      "name": "Rock_Crystal_White_Block"
    },
    {
      "x": -1,
      "y": 1,
      "z": -1,
      "name": "Rock_Crystal_White_Block"
    },
    {
      "x": -1,
      "y": 2,
      "z": -1,
      "name": "Rock_Crystal_White_Block"
    },
    {
      "x": -1,
      "y": 3,
      "z": -1,
      "name": "Rock_Crystal_White_Block"
    },
    {
      "x": -1,
      "y": 4,
      "z": -1,
      "name": "Rock_Crystal_White_Block"
    },
    {
      "x": -1,
      "y": 6,
      "z": -1,
      "name": "Rock_Crystal_White_Block"
    },
    {
      "x": -1,
      "y": 8,
      "z": -1,
      "name": "Rock_Crystal_White_Block"
    },
    {
      "x": -1,
      "y": 11,
      "z": -1,
      "name": "Rock_Crystal_White_Block"
    },
    {
      "x": -1,
      "y": 13,
      "z": -1,
      "name": "Rock_Crystal_White_Block"
    },
    {
      "x": -1,
      "y": 16,
      "z": -1,
      "name": "Rock_Crystal_White_Block"
    },
    {
      "x": -1,
      "y": -18,
      "z": 0,
      "name": "Rock_Crystal_White_Block"
    },
    {
      "x": -1,
      "y": -17,
      "z": 0,
      "name": "Rock_Crystal_White_Block"
    },
    {
      "x": -1,
      "y": -16,
      "z": 0,
      "name": "Rock_Crystal_White_Block"
    },
    {
      "x": -1,
      "y": -15,
      "z": 0,
      "name": "Rock_Crystal_White_Block"
    },
    {
      "x": -1,
      "y": -14,
      "z": 0,
      "name": "Rock_Crystal_White_Block"
    },
    {
      "x": -1,
      "y": -13,
      "z": 0,
      "name": "Rock_Crystal_White_Block"
    },
    {
      "x": -1,
      "y": -12,
      "z": 0,
      "name": "Rock_Crystal_White_Block"
    },
    {
      "x": -1,
      "y": -11,
      "z": 0,
      "name": "Rock_Crystal_White_Block"
    },
    {
      "x": -1,
      "y": -10,
      "z": 0,
      "name": "Rock_Crystal_White_Block"
    },
    {
      "x": -1,
      "y": -9,
      "z": 0,
      "name": "Rock_Crystal_White_Block"
    },
    {
      "x": -1,
      "y": -8,
      "z": 0,
      "name": "Rock_Crystal_White_Block"
    },
    {
      "x": -1,
      "y": -7,
      "z": 0,
      "name": "Rock_Crystal_White_Block"
    },
    {
      "x": -1,
      "y": -6,
      "z": 0,
      "name": "Rock_Crystal_White_Block"
    },
    {
      "x": -1,
      "y": -5,
      "z": 0,
      "name": "Rock_Crystal_White_Block"
    },
    {
      "x": -1,
      "y": -4,
      "z": 0,
      "name": "Rock_Crystal_White_Block"
    },
    {
      "x": -1,
      "y": -3,
      "z": 0,
      "name": "Rock_Crystal_White_Block"
    },
    {
      "x": -1,
      "y": -2,
      "z": 0,
      "name": "Rock_Crystal_White_Block"
    },
    {
      "x": -1,
      "y": -1,
      "z": 0,
      "name": "Rock_Crystal_White_Block"
    },
    {
      "x": -1,
      "y": 0,
      "z": 0,
      "name": "Rock_Crystal_White_Block"
    },
    {
      "x": -1,
      "y": 1,
      "z": 0,
      "name": "Rock_Crystal_White_Block",
      "rotation": 2
    },
    {
      "x": -1,
      "y": 2,
      "z": 0,
      "name": "Rock_Crystal_White_Block",
      "rotation": 2
    },
    {
      "x": -1,
      "y": 3,
      "z": 0,
      "name": "Rock_Crystal_White_Block",
      "rotation": 2
    },
    {
      "x": -1,
      "y": 4,
      "z": 0,
      "name": "Rock_Crystal_White_Block",
      "rotation": 2
    },
    {
      "x": -1,
      "y": 5,
      "z": 0,
      "name": "Rock_Crystal_White_Block",
      "rotation": 2
    },
    {
      "x": -1,
      "y": 6,
      "z": 0,
      "name": "Rock_Crystal_White_Block",
      "rotation": 2
    },
    {
      "x": -1,
      "y": 7,
      "z": 0,
      "name": "Rock_Crystal_White_Block",
      "rotation": 2
    },
    {
      "x": -1,
      "y": 8,
      "z": 0,
      "name": "Rock_Crystal_White_Block",
      "rotation": 2
    },
    {
      "x": -1,
      "y": 9,
      "z": 0,
      "name": "Rock_Crystal_White_Block",
      "rotation": 2
    },
    {
      "x": -1,
      "y": 10,
      "z": 0,
      "name": "Rock_Crystal_White_Block",
      "rotation": 2
    },
    {
      "x": -1,
      "y": 11,
      "z": 0,
      "name": "Rock_Crystal_White_Block",
      "rotation": 2
    },
    {
      "x": -1,
      "y": 12,
      "z": 0,
      "name": "Rock_Crystal_White_Block",
      "rotation": 2
    },
    {
      "x": -1,
      "y": 13,
      "z": 0,
      "name": "Rock_Crystal_White_Block",
      "rotation": 2
    },
    {
      "x": -1,
      "y": 14,
      "z": 0,
      "name": "Rock_Crystal_White_Block",
      "rotation": 2
    },
    {
      "x": -1,
      "y": 15,
      "z": 0,
      "name": "Rock_Crystal_White_Block",
      "rotation": 2
    },
    {
      "x": -1,
      "y": 16,
      "z": 0,
      "name": "Rock_Crystal_White_Block",
      "rotation": 2
    },
    {
      "x": -1,
      "y": 17,
      "z": 0,
      "name": "Rock_Crystal_White_Block",
      "rotation": 2
    },
    {
      "x": -1,
      "y": 18,
      "z": 0,
      "name": "Rock_Crystal_White_Block",
      "rotation": 2
    },
    {
      "x": -1,
      "y": -16,
      "z": 1,
      "name": "Rock_Crystal_White_Block",
      "rotation": 2
    },
    {
      "x": -1,
      "y": -13,
      "z": 1,
      "name": "Rock_Crystal_White_Block",
      "rotation": 2
    },
    {
      "x": -1,
      "y": -11,
      "z": 1,
      "name": "Rock_Crystal_White_Block",
      "rotation": 2
    },
    {
      "x": -1,
      "y": -8,
      "z": 1,
      "name": "Rock_Crystal_White_Block",
      "rotation": 2
    },
    {
      "x": -1,
      "y": -6,
      "z": 1,
      "name": "Rock_Crystal_White_Block",
      "rotation": 2
    },
    {
      "x": -1,
      "y": -4,
      "z": 1,
      "name": "Rock_Crystal_White_Block",
      "rotation": 2
    },
    {
      "x": -1,
      "y": -3,
      "z": 1,
      "name": "Rock_Crystal_White_Block"
    },
    {
      "x": -1,
      "y": -2,
      "z": 1,
      "name": "Rock_Crystal_White_Block",
      "rotation": 2
    },
    {
      "x": -1,
      "y": -1,
      "z": 1,
      "name": "Rock_Crystal_White_Block",
      "rotation": 2
    },
    {
      "x": -1,
      "y": 0,
      "z": 1,
      "name": "Rock_Crystal_White_Block",
      "rotation": 2
    },
    {
      "x": -1,
      "y": 1,
      "z": 1,
      "name": "Rock_Crystal_White_Block",
      "rotation": 2
    },
    {
      "x": -1,
      "y": 2,
      "z": 1,
      "name": "Rock_Crystal_White_Block",
      "rotation": 2
    },
    {
      "x": -1,
      "y": 3,
      "z": 1,
      "name": "Rock_Crystal_White_Block"
    },
    {
      "x": -1,
      "y": 4,
      "z": 1,
      "name": "Rock_Crystal_White_Block",
      "rotation": 2
    },
    {
      "x": -1,
      "y": 6,
      "z": 1,
      "name": "Rock_Crystal_White_Block",
      "rotation": 2
    },
    {
      "x": -1,
      "y": 8,
      "z": 1,
      "name": "Rock_Crystal_White_Block",
      "rotation": 2
    },
    {
      "x": -1,
      "y": 11,
      "z": 1,
      "name": "Rock_Crystal_White_Block",
      "rotation": 2
    },
    {
      "x": -1,
      "y": 13,
      "z": 1,
      "name": "Rock_Crystal_White_Block",
      "rotation": 2
    },
    {
      "x": -1,
      "y": 16,
      "z": 1,
      "name": "Rock_Crystal_White_Block",
      "rotation": 2
    },
    {
      "x": -1,
      "y": -14,
      "z": 2,
      "name": "Rock_Crystal_White_Block",
      "rotation": 2
    },
    {
      "x": -1,
      "y": -11,
      "z": 2,
      "name": "Rock_Crystal_White_Block",
      "rotation": 2
    },
    {
      "x": -1,
      "y": -9,
      "z": 2,
      "name": "Rock_Crystal_White_Block",
      "rotation": 2
    },
    {
      "x": -1,
      "y": -2,
      "z": 2,
      "name": "Rock_Crystal_White_Block"
    },
    {
      "x": -1,
      "y": -1,
      "z": 2,
      "name": "Rock_Crystal_White_Block",
      "rotation": 2
    },
    {
      "x": -1,
      "y": 0,
      "z": 2,
      "name": "Rock_Crystal_White_Block",
      "rotation": 2
    },
    {
      "x": -1,
      "y": 1,
      "z": 2,
      "name": "Rock_Crystal_White_Block",
      "rotation": 2
    },
    {
      "x": -1,
      "y": 2,
      "z": 2,
      "name": "Rock_Crystal_White_Block"
    },
    {
      "x": -1,
      "y": 9,
      "z": 2,
      "name": "Rock_Crystal_White_Block",
      "rotation": 2
    },
    {
      "x": -1,
      "y": 11,
      "z": 2,
      "name": "Rock_Crystal_White_Block",
      "rotation": 2
    },
    {
      "x": -1,
      "y": 14,
      "z": 2,
      "name": "Rock_Crystal_White_Block",
      "rotation": 2
    },
    {
      "x": -1,
      "y": -3,
      "z": 3,
      "name": "Rock_Crystal_White_Block",
      "rotation": 2
    },
    {
      "x": -1,
      "y": -1,
      "z": 3,
      "name": "Rock_Crystal_White_Block",
      "rotation": 2
    },
    {
      "x": -1,
      "y": 1,
      "z": 3,
      "name": "Rock_Crystal_White_Block",
      "rotation": 2
    },
    {
      "x": -1,
      "y": 3,
      "z": 3,
      "name": "Rock_Crystal_White_Block",
      "rotation": 2
    },
    {
      "x": -1,
      "y": -5,
      "z": 4,
      "name": "Rock_Crystal_White_Block",
      "rotation": 2
    },
    {
      "x": -1,
      "y": -2,
      "z": 4,
      "name": "Rock_Crystal_White_Block",
      "rotation": 2
    },
    {
      "x": -1,
      "y": 0,
      "z": 4,
      "name": "Rock_Crystal_White_Block",
      "rotation": 2
    },
    {
      "x": -1,
      "y": 2,
      "z": 4,
      "name": "Rock_Crystal_White_Block",
      "rotation": 2
    },
    {
      "x": -1,
      "y": 5,
      "z": 4,
      "name": "Rock_Crystal_White_Block",
      "rotation": 2
    },
    {
      "x": -1,
      "y": -4,
      "z": 5,
      "name": "Rock_Crystal_White_Block",
      "rotation": 2
    },
    {
      "x": -1,
      "y": -3,
      "z": 5,
      "name": "Rock_Crystal_White_Block",
      "rotation": 2
    },
    {
      "x": -1,
      "y": -1,
      "z": 5,
      "name": "Rock_Crystal_White_Block",
      "rotation": 2
    },
    {
      "x": -1,
      "y": 1,
      "z": 5,
      "name": "Rock_Crystal_White_Block",
      "rotation": 2
    },
    {
      "x": -1,
      "y": 3,
      "z": 5,
      "name": "Rock_Crystal_White_Block",
      "rotation": 2
    },
    {
      "x": -1,
      "y": 4,
      "z": 5,
      "name": "Rock_Crystal_White_Block",
      "rotation": 2
    },
    {
      "x": -1,
      "y": -7,
      "z": 6,
      "name": "Rock_Crystal_White_Block",
      "rotation": 2
    },
    {
      "x": -1,
      "y": -6,
      "z": 6,
      "name": "Rock_Crystal_White_Block",
      "rotation": 2
    },
    {
      "x": -1,
      "y": -3,
      "z": 6,
      "name": "Rock_Crystal_White_Block",
      "rotation": 2
    },
    {
      "x": -1,
      "y": -2,
      "z": 6,
      "name": "Rock_Crystal_White_Block",
      "rotation": 2
    },
    {
      "x": -1,
      "y": 2,
      "z": 6,
      "name": "Rock_Crystal_White_Block",
      "rotation": 2
    },
    {
      "x": -1,
      "y": 3,
      "z": 6,
      "name": "Rock_Crystal_White_Block",
      "rotation": 2
    },
    {
      "x": -1,
      "y": 6,
      "z": 6,
      "name": "Rock_Crystal_White_Block",
      "rotation": 2
    },
    {
      "x": -1,
      "y": 7,
      "z": 6,
      "name": "Rock_Crystal_White_Block",
      "rotation": 2
    },
    {
      "x": -1,
      "y": -5,
      "z": 7,
      "name": "Rock_Crystal_White_Block",
      "rotation": 2
    },
    {
      "x": -1,
      "y": -4,
      "z": 7,
      "name": "Rock_Crystal_White_Block",
      "rotation": 2
    },
    {
      "x": -1,
      "y": 4,
      "z": 7,
      "name": "Rock_Crystal_White_Block",
      "rotation": 2
    },
    {
      "x": -1,
      "y": 5,
      "z": 7,
      "name": "Rock_Crystal_White_Block",
      "rotation": 2
    },
    {
      "x": -1,
      "y": -7,
      "z": 8,
      "name": "Rock_Crystal_White_Block",
      "rotation": 2
    },
    {
      "x": -1,
      "y": -6,
      "z": 8,
      "name": "Rock_Crystal_White_Block",
      "rotation": 2
    },
    {
      "x": -1,
      "y": -5,
      "z": 8,
      "name": "Rock_Crystal_White_Block",
      "rotation": 2
    },
    {
      "x": -1,
      "y": -3,
      "z": 8,
      "name": "Rock_Crystal_White_Block",
      "rotation": 2
    },
    {
      "x": -1,
      "y": 3,
      "z": 8,
      "name": "Rock_Crystal_White_Block",
      "rotation": 2
    },
    {
      "x": -1,
      "y": 5,
      "z": 8,
      "name": "Rock_Crystal_White_Block",
      "rotation": 2
    },
    {
      "x": -1,
      "y": 6,
      "z": 8,
      "name": "Rock_Crystal_White_Block",
      "rotation": 2
    },
    {
      "x": -1,
      "y": 7,
      "z": 8,
      "name": "Rock_Crystal_White_Block",
      "rotation": 2
    },
    {
      "x": -1,
      "y": -5,
      "z": 9,
      "name": "Rock_Crystal_White_Block",
      "rotation": 2
    },
    {
      "x": -1,
      "y": -2,
      "z": 9,
      "name": "Rock_Crystal_White_Block",
      "rotation": 2
    },
    {
      "x": -1,
      "y": 2,
      "z": 9,
      "name": "Rock_Crystal_White_Block",
      "rotation": 2
    },
    {
      "x": -1,
      "y": 5,
      "z": 9,
      "name": "Rock_Crystal_White_Block",
      "rotation": 2
    },
    {
      "x": -1,
      "y": -8,
      "z": 10,
      "name": "Rock_Crystal_White_Block",
      "rotation": 2
    },
    {
      "x": -1,
      "y": -6,
      "z": 10,
      "name": "Rock_Crystal_White_Block",
      "rotation": 2
    },
    {
      "x": -1,
      "y": -4,
      "z": 10,
      "name": "Rock_Crystal_White_Block",
      "rotation": 2
    },
    {
      "x": -1,
      "y": 4,
      "z": 10,
      "name": "Rock_Crystal_White_Block",
      "rotation": 2
    },
    {
      "x": -1,
      "y": 6,
      "z": 10,
      "name": "Rock_Crystal_White_Block",
      "rotation": 2
    },
    {
      "x": -1,
      "y": 8,
      "z": 10,
      "name": "Rock_Crystal_White_Block",
      "rotation": 2
    },
    {
      "x": -1,
      "y": -7,
      "z": 11,
      "name": "Rock_Crystal_White_Block",
      "rotation": 2
    },
    {
      "x": -1,
      "y": -6,
      "z": 11,
      "name": "Rock_Crystal_White_Block",
      "rotation": 2
    },
    {
      "x": -1,
      "y": -3,
      "z": 11,
      "name": "Rock_Crystal_White_Block",
      "rotation": 2
    },
    {
      "x": -1,
      "y": 3,
      "z": 11,
      "name": "Rock_Crystal_White_Block",
      "rotation": 2
    },
    {
      "x": -1,
      "y": 6,
      "z": 11,
      "name": "Rock_Crystal_White_Block",
      "rotation": 2
    },
    {
      "x": -1,
      "y": 7,
      "z": 11,
      "name": "Rock_Crystal_White_Block",
      "rotation": 2
    },
    {
      "x": -1,
      "y": -9,
      "z": 12,
      "name": "Rock_Crystal_White_Block",
      "rotation": 2
    },
    {
      "x": -1,
      "y": -7,
      "z": 12,
      "name": "Rock_Crystal_White_Block",
      "rotation": 2
    },
    {
      "x": -1,
      "y": -5,
      "z": 12,
      "name": "Rock_Crystal_White_Block",
      "rotation": 2
    },
    {
      "x": -1,
      "y": 5,
      "z": 12,
      "name": "Rock_Crystal_White_Block",
      "rotation": 2
    },
    {
      "x": -1,
      "y": 7,
      "z": 12,
      "name": "Rock_Crystal_White_Block",
      "rotation": 2
    },
    {
      "x": -1,
      "y": 9,
      "z": 12,
      "name": "Rock_Crystal_White_Block",
      "rotation": 2
    },
    {
      "x": -1,
      "y": -10,
      "z": 13,
      "name": "Rock_Crystal_White_Block",
      "rotation": 2
    },
    {
      "x": -1,
      "y": -8,
      "z": 13,
      "name": "Rock_Crystal_White_Block",
      "rotation": 2
    },
    {
      "x": -1,
      "y": -7,
      "z": 13,
      "name": "Rock_Crystal_White_Block",
      "rotation": 2
    },
    {
      "x": -1,
      "y": 7,
      "z": 13,
      "name": "Rock_Crystal_White_Block",
      "rotation": 2
    },
    {
      "x": -1,
      "y": 8,
      "z": 13,
      "name": "Rock_Crystal_White_Block",
      "rotation": 2
    },
    {
      "x": -1,
      "y": 10,
      "z": 13,
      "name": "Rock_Crystal_White_Block",
      "rotation": 2
    },
    {
      "x": -1,
      "y": -9,
      "z": 14,
      "name": "Rock_Crystal_White_Block",
      "rotation": 2
    },
    {
      "x": -1,
      "y": -8,
      "z": 14,
      "name": "Rock_Crystal_White_Block",
      "rotation": 2
    },
    {
      "x": -1,
      "y": -6,
      "z": 14,
      "name": "Rock_Crystal_White_Block",
      "rotation": 2
    },
    {
      "x": -1,
      "y": 6,
      "z": 14,
      "name": "Rock_Crystal_White_Block",
      "rotation": 2
    },
    {
      "x": -1,
      "y": 8,
      "z": 14,
      "name": "Rock_Crystal_White_Block",
      "rotation": 2
    },
    {
      "x": -1,
      "y": 9,
      "z": 14,
      "name": "Rock_Crystal_White_Block",
      "rotation": 2
    },
    {
      "x": -1,
      "y": -9,
      "z": 15,
      "name": "Rock_Crystal_White_Block",
      "rotation": 2
    },
    {
      "x": -1,
      "y": -7,
      "z": 15,
      "name": "Rock_Crystal_White_Block",
      "rotation": 2
    },
    {
      "x": -1,
      "y": 7,
      "z": 15,
      "name": "Rock_Crystal_White_Block",
      "rotation": 2
    },
    {
      "x": -1,
      "y": 9,
      "z": 15,
      "name": "Rock_Crystal_White_Block",
      "rotation": 2
    },
    {
      "x": -1,
      "y": -10,
      "z": 16,
      "name": "Rock_Crystal_White_Block",
      "rotation": 2
    },
    {
      "x": -1,
      "y": 10,
      "z": 16,
      "name": "Rock_Crystal_White_Block",
      "rotation": 2
    },
    {
      "x": 0,
      "y": -11,
      "z": -18,
      "name": "Rock_Crystal_White_Block"
    },
    {
      "x": 0,
      "y": 11,
      "z": -18,
      "name": "Rock_Crystal_White_Block"
    },
    {
      "x": 0,
      "y": -11,
      "z": -17,
      "name": "Rock_Crystal_White_Block"
    },
    {
      "x": 0,
      "y": -10,
      "z": -17,
      "name": "Rock_Crystal_White_Block"
    },
    {
      "x": 0,
      "y": -8,
      "z": -17,
      "name": "Rock_Crystal_White_Block"
    },
    {
      "x": 0,
      "y": 8,
      "z": -17,
      "name": "Rock_Crystal_White_Block"
    },
    {
      "x": 0,
      "y": 10,
      "z": -17,
      "name": "Rock_Crystal_White_Block"
    },
    {
      "x": 0,
      "y": 11,
      "z": -17,
      "name": "Rock_Crystal_White_Block"
    },
    {
      "x": 0,
      "y": -10,
      "z": -16,
      "name": "Rock_Crystal_White_Block"
    },
    {
      "x": 0,
      "y": -9,
      "z": -16,
      "name": "Rock_Crystal_White_Block"
    },
    {
      "x": 0,
      "y": -6,
      "z": -16,
      "name": "Rock_Crystal_White_Block"
    },
    {
      "x": 0,
      "y": 6,
      "z": -16,
      "name": "Rock_Crystal_White_Block"
    },
    {
      "x": 0,
      "y": 9,
      "z": -16,
      "name": "Rock_Crystal_White_Block"
    },
    {
      "x": 0,
      "y": 10,
      "z": -16,
      "name": "Rock_Crystal_White_Block"
    },
    {
      "x": 0,
      "y": -11,
      "z": -15,
      "name": "Rock_Crystal_White_Block"
    },
    {
      "x": 0,
      "y": -10,
      "z": -15,
      "name": "Rock_Crystal_White_Block"
    },
    {
      "x": 0,
      "y": -9,
      "z": -15,
      "name": "Rock_Crystal_White_Block"
    },
    {
      "x": 0,
      "y": -7,
      "z": -15,
      "name": "Rock_Crystal_White_Block"
    },
    {
      "x": 0,
      "y": -4,
      "z": -15,
      "name": "Rock_Crystal_White_Block"
    },
    {
      "x": 0,
      "y": 4,
      "z": -15,
      "name": "Rock_Crystal_White_Block"
    },
    {
      "x": 0,
      "y": 7,
      "z": -15,
      "name": "Rock_Crystal_White_Block"
    },
    {
      "x": 0,
      "y": 9,
      "z": -15,
      "name": "Rock_Crystal_White_Block"
    },
    {
      "x": 0,
      "y": 10,
      "z": -15,
      "name": "Rock_Crystal_White_Block"
    },
    {
      "x": 0,
      "y": 11,
      "z": -15,
      "name": "Rock_Crystal_White_Block"
    },
    {
      "x": 0,
      "y": -10,
      "z": -14,
      "name": "Rock_Crystal_White_Block"
    },
    {
      "x": 0,
      "y": -9,
      "z": -14,
      "name": "Rock_Crystal_White_Block"
    },
    {
      "x": 0,
      "y": -8,
      "z": -14,
      "name": "Rock_Crystal_White_Block"
    },
    {
      "x": 0,
      "y": -7,
      "z": -14,
      "name": "Rock_Crystal_White_Block"
    },
    {
      "x": 0,
      "y": -6,
      "z": -14,
      "name": "Rock_Crystal_White_Block"
    },
    {
      "x": 0,
      "y": -5,
      "z": -14,
      "name": "Rock_Crystal_White_Block"
    },
    {
      "x": 0,
      "y": -2,
      "z": -14,
      "name": "Rock_Crystal_White_Block"
    },
    {
      "x": 0,
      "y": 2,
      "z": -14,
      "name": "Rock_Crystal_White_Block"
    },
    {
      "x": 0,
      "y": 5,
      "z": -14,
      "name": "Rock_Crystal_White_Block"
    },
    {
      "x": 0,
      "y": 6,
      "z": -14,
      "name": "Rock_Crystal_White_Block"
    },
    {
      "x": 0,
      "y": 7,
      "z": -14,
      "name": "Rock_Crystal_White_Block"
    },
    {
      "x": 0,
      "y": 8,
      "z": -14,
      "name": "Rock_Crystal_White_Block"
    },
    {
      "x": 0,
      "y": 9,
      "z": -14,
      "name": "Rock_Crystal_White_Block"
    },
    {
      "x": 0,
      "y": 10,
      "z": -14,
      "name": "Rock_Crystal_White_Block"
    },
    {
      "x": 0,
      "y": -11,
      "z": -13,
      "name": "Rock_Crystal_White_Block"
    },
    {
      "x": 0,
      "y": -10,
      "z": -13,
      "name": "Rock_Crystal_White_Block"
    },
    {
      "x": 0,
      "y": -8,
      "z": -13,
      "name": "Rock_Crystal_White_Block"
    },
    {
      "x": 0,
      "y": -7,
      "z": -13,
      "name": "Rock_Crystal_White_Block"
    },
    {
      "x": 0,
      "y": -4,
      "z": -13,
      "name": "Rock_Crystal_White_Block"
    },
    {
      "x": 0,
      "y": -3,
      "z": -13,
      "name": "Rock_Crystal_White_Block"
    },
    {
      "x": 0,
      "y": 3,
      "z": -13,
      "name": "Rock_Crystal_White_Block"
    },
    {
      "x": 0,
      "y": 4,
      "z": -13,
      "name": "Rock_Crystal_White_Block"
    },
    {
      "x": 0,
      "y": 7,
      "z": -13,
      "name": "Rock_Crystal_White_Block"
    },
    {
      "x": 0,
      "y": 8,
      "z": -13,
      "name": "Rock_Crystal_White_Block"
    },
    {
      "x": 0,
      "y": 10,
      "z": -13,
      "name": "Rock_Crystal_White_Block"
    },
    {
      "x": 0,
      "y": 11,
      "z": -13,
      "name": "Rock_Crystal_White_Block"
    },
    {
      "x": 0,
      "y": -9,
      "z": -12,
      "name": "Rock_Crystal_White_Block"
    },
    {
      "x": 0,
      "y": -8,
      "z": -12,
      "name": "Rock_Crystal_White_Block"
    },
    {
      "x": 0,
      "y": -7,
      "z": -12,
      "name": "Rock_Crystal_White_Block"
    },
    {
      "x": 0,
      "y": -6,
      "z": -12,
      "name": "Rock_Crystal_White_Block"
    },
    {
      "x": 0,
      "y": -5,
      "z": -12,
      "name": "Rock_Crystal_White_Block"
    },
    {
      "x": 0,
      "y": -1,
      "z": -12,
      "name": "Rock_Crystal_White_Block"
    },
    {
      "x": 0,
      "y": 1,
      "z": -12,
      "name": "Rock_Crystal_White_Block"
    },
    {
      "x": 0,
      "y": 5,
      "z": -12,
      "name": "Rock_Crystal_White_Block"
    },
    {
      "x": 0,
      "y": 6,
      "z": -12,
      "name": "Rock_Crystal_White_Block"
    },
    {
      "x": 0,
      "y": 7,
      "z": -12,
      "name": "Rock_Crystal_White_Block"
    },
    {
      "x": 0,
      "y": 8,
      "z": -12,
      "name": "Rock_Crystal_White_Block"
    },
    {
      "x": 0,
      "y": 9,
      "z": -12,
      "name": "Rock_Crystal_White_Block"
    },
    {
      "x": 0,
      "y": -11,
      "z": -11,
      "name": "Rock_Crystal_White_Block"
    },
    {
      "x": 0,
      "y": -10,
      "z": -11,
      "name": "Rock_Crystal_White_Block"
    },
    {
      "x": 0,
      "y": -7,
      "z": -11,
      "name": "Rock_Crystal_White_Block"
    },
    {
      "x": 0,
      "y": -6,
      "z": -11,
      "name": "Rock_Crystal_White_Block"
    },
    {
      "x": 0,
      "y": -5,
      "z": -11,
      "name": "Rock_Crystal_White_Block"
    },
    {
      "x": 0,
      "y": -3,
      "z": -11,
      "name": "Rock_Crystal_White_Block"
    },
    {
      "x": 0,
      "y": -2,
      "z": -11,
      "name": "Rock_Crystal_White_Block"
    },
    {
      "x": 0,
      "y": 2,
      "z": -11,
      "name": "Rock_Crystal_White_Block"
    },
    {
      "x": 0,
      "y": 3,
      "z": -11,
      "name": "Rock_Crystal_White_Block"
    },
    {
      "x": 0,
      "y": 5,
      "z": -11,
      "name": "Rock_Crystal_White_Block"
    },
    {
      "x": 0,
      "y": 6,
      "z": -11,
      "name": "Rock_Crystal_White_Block"
    },
    {
      "x": 0,
      "y": 7,
      "z": -11,
      "name": "Rock_Crystal_White_Block"
    },
    {
      "x": 0,
      "y": 10,
      "z": -11,
      "name": "Rock_Crystal_White_Block"
    },
    {
      "x": 0,
      "y": 11,
      "z": -11,
      "name": "Rock_Crystal_White_Block"
    },
    {
      "x": 0,
      "y": -8,
      "z": -10,
      "name": "Rock_Crystal_White_Block"
    },
    {
      "x": 0,
      "y": -7,
      "z": -10,
      "name": "Rock_Crystal_White_Block"
    },
    {
      "x": 0,
      "y": -6,
      "z": -10,
      "name": "Rock_Crystal_White_Block"
    },
    {
      "x": 0,
      "y": -5,
      "z": -10,
      "name": "Rock_Crystal_White_Block"
    },
    {
      "x": 0,
      "y": -4,
      "z": -10,
      "name": "Rock_Crystal_White_Block"
    },
    {
      "x": 0,
      "y": -1,
      "z": -10,
      "name": "Rock_Crystal_White_Block"
    },
    {
      "x": 0,
      "y": 1,
      "z": -10,
      "name": "Rock_Crystal_White_Block"
    },
    {
      "x": 0,
      "y": 4,
      "z": -10,
      "name": "Rock_Crystal_White_Block"
    },
    {
      "x": 0,
      "y": 5,
      "z": -10,
      "name": "Rock_Crystal_White_Block"
    },
    {
      "x": 0,
      "y": 6,
      "z": -10,
      "name": "Rock_Crystal_White_Block"
    },
    {
      "x": 0,
      "y": 7,
      "z": -10,
      "name": "Rock_Crystal_White_Block"
    },
    {
      "x": 0,
      "y": 8,
      "z": -10,
      "name": "Rock_Crystal_White_Block"
    },
    {
      "x": 0,
      "y": -10,
      "z": -9,
      "name": "Rock_Crystal_White_Block"
    },
    {
      "x": 0,
      "y": -9,
      "z": -9,
      "name": "Rock_Crystal_White_Block"
    },
    {
      "x": 0,
      "y": -6,
      "z": -9,
      "name": "Rock_Crystal_White_Block"
    },
    {
      "x": 0,
      "y": -5,
      "z": -9,
      "name": "Rock_Crystal_White_Block"
    },
    {
      "x": 0,
      "y": -4,
      "z": -9,
      "name": "Rock_Crystal_White_Block"
    },
    {
      "x": 0,
      "y": -2,
      "z": -9,
      "name": "Rock_Crystal_White_Block"
    },
    {
      "x": 0,
      "y": 0,
      "z": -9,
      "name": "Rock_Crystal_White_Block"
    },
    {
      "x": 0,
      "y": 2,
      "z": -9,
      "name": "Rock_Crystal_White_Block"
    },
    {
      "x": 0,
      "y": 4,
      "z": -9,
      "name": "Rock_Crystal_White_Block"
    },
    {
      "x": 0,
      "y": 5,
      "z": -9,
      "name": "Rock_Crystal_White_Block"
    },
    {
      "x": 0,
      "y": 6,
      "z": -9,
      "name": "Rock_Crystal_White_Block"
    },
    {
      "x": 0,
      "y": 9,
      "z": -9,
      "name": "Rock_Crystal_White_Block"
    },
    {
      "x": 0,
      "y": 10,
      "z": -9,
      "name": "Rock_Crystal_White_Block"
    },
    {
      "x": 0,
      "y": -7,
      "z": -8,
      "name": "Rock_Crystal_White_Block"
    },
    {
      "x": 0,
      "y": -6,
      "z": -8,
      "name": "Rock_Crystal_White_Block"
    },
    {
      "x": 0,
      "y": -5,
      "z": -8,
      "name": "Rock_Crystal_White_Block"
    },
    {
      "x": 0,
      "y": -4,
      "z": -8,
      "name": "Rock_Crystal_White_Block"
    },
    {
      "x": 0,
      "y": -3,
      "z": -8,
      "name": "Rock_Crystal_White_Block"
    },
    {
      "x": 0,
      "y": -1,
      "z": -8,
      "name": "Rock_Crystal_White_Block"
    },
    {
      "x": 0,
      "y": 1,
      "z": -8,
      "name": "Rock_Crystal_White_Block"
    },
    {
      "x": 0,
      "y": 3,
      "z": -8,
      "name": "Rock_Crystal_White_Block"
    },
    {
      "x": 0,
      "y": 4,
      "z": -8,
      "name": "Rock_Crystal_White_Block"
    },
    {
      "x": 0,
      "y": 5,
      "z": -8,
      "name": "Rock_Crystal_White_Block"
    },
    {
      "x": 0,
      "y": 6,
      "z": -8,
      "name": "Rock_Crystal_White_Block"
    },
    {
      "x": 0,
      "y": 7,
      "z": -8,
      "name": "Rock_Crystal_White_Block"
    },
    {
      "x": 0,
      "y": -10,
      "z": -7,
      "name": "Rock_Crystal_White_Block"
    },
    {
      "x": 0,
      "y": -9,
      "z": -7,
      "name": "Rock_Crystal_White_Block"
    },
    {
      "x": 0,
      "y": -8,
      "z": -7,
      "name": "Rock_Crystal_White_Block"
    },
    {
      "x": 0,
      "y": -5,
      "z": -7,
      "name": "Rock_Crystal_White_Block"
    },
    {
      "x": 0,
      "y": -4,
      "z": -7,
      "name": "Rock_Crystal_White_Block"
    },
    {
      "x": 0,
      "y": -3,
      "z": -7,
      "name": "Rock_Crystal_White_Block"
    },
    {
      "x": 0,
      "y": -2,
      "z": -7,
      "name": "Rock_Crystal_White_Block"
    },
    {
      "x": 0,
      "y": -1,
      "z": -7,
      "name": "Rock_Crystal_White_Block"
    },
    {
      "x": 0,
      "y": 1,
      "z": -7,
      "name": "Rock_Crystal_White_Block"
    },
    {
      "x": 0,
      "y": 2,
      "z": -7,
      "name": "Rock_Crystal_White_Block"
    },
    {
      "x": 0,
      "y": 3,
      "z": -7,
      "name": "Rock_Crystal_White_Block"
    },
    {
      "x": 0,
      "y": 4,
      "z": -7,
      "name": "Rock_Crystal_White_Block"
    },
    {
      "x": 0,
      "y": 5,
      "z": -7,
      "name": "Rock_Crystal_White_Block"
    },
    {
      "x": 0,
      "y": 8,
      "z": -7,
      "name": "Rock_Crystal_White_Block"
    },
    {
      "x": 0,
      "y": 9,
      "z": -7,
      "name": "Rock_Crystal_White_Block"
    },
    {
      "x": 0,
      "y": 10,
      "z": -7,
      "name": "Rock_Crystal_White_Block"
    },
    {
      "x": 0,
      "y": -7,
      "z": -6,
      "name": "Rock_Crystal_White_Block"
    },
    {
      "x": 0,
      "y": -6,
      "z": -6,
      "name": "Rock_Crystal_White_Block"
    },
    {
      "x": 0,
      "y": -4,
      "z": -6,
      "name": "Rock_Crystal_White_Block"
    },
    {
      "x": 0,
      "y": -3,
      "z": -6,
      "name": "Rock_Crystal_White_Block"
    },
    {
      "x": 0,
      "y": -2,
      "z": -6,
      "name": "Rock_Crystal_White_Block"
    },
    {
      "x": 0,
      "y": 0,
      "z": -6,
      "name": "Rock_Crystal_White_Block"
    },
    {
      "x": 0,
      "y": 2,
      "z": -6,
      "name": "Rock_Crystal_White_Block"
    },
    {
      "x": 0,
      "y": 3,
      "z": -6,
      "name": "Rock_Crystal_White_Block"
    },
    {
      "x": 0,
      "y": 4,
      "z": -6,
      "name": "Rock_Crystal_White_Block"
    },
    {
      "x": 0,
      "y": 6,
      "z": -6,
      "name": "Rock_Crystal_White_Block"
    },
    {
      "x": 0,
      "y": 7,
      "z": -6,
      "name": "Rock_Crystal_White_Block"
    },
    {
      "x": 0,
      "y": -10,
      "z": -5,
      "name": "Rock_Crystal_White_Block"
    },
    {
      "x": 0,
      "y": -8,
      "z": -5,
      "name": "Rock_Crystal_White_Block"
    },
    {
      "x": 0,
      "y": -4,
      "z": -5,
      "name": "Rock_Crystal_White_Block"
    },
    {
      "x": 0,
      "y": -3,
      "z": -5,
      "name": "Rock_Crystal_White_Block"
    },
    {
      "x": 0,
      "y": -2,
      "z": -5,
      "name": "Rock_Crystal_White_Block"
    },
    {
      "x": 0,
      "y": -1,
      "z": -5,
      "name": "Rock_Crystal_White_Block"
    },
    {
      "x": 0,
      "y": 1,
      "z": -5,
      "name": "Rock_Crystal_White_Block"
    },
    {
      "x": 0,
      "y": 2,
      "z": -5,
      "name": "Rock_Crystal_White_Block"
    },
    {
      "x": 0,
      "y": 3,
      "z": -5,
      "name": "Rock_Crystal_White_Block"
    },
    {
      "x": 0,
      "y": 4,
      "z": -5,
      "name": "Rock_Crystal_White_Block"
    },
    {
      "x": 0,
      "y": 8,
      "z": -5,
      "name": "Rock_Crystal_White_Block"
    },
    {
      "x": 0,
      "y": 10,
      "z": -5,
      "name": "Rock_Crystal_White_Block"
    },
    {
      "x": 0,
      "y": -12,
      "z": -4,
      "name": "Rock_Crystal_White_Block"
    },
    {
      "x": 0,
      "y": -10,
      "z": -4,
      "name": "Rock_Crystal_White_Block"
    },
    {
      "x": 0,
      "y": -9,
      "z": -4,
      "name": "Rock_Crystal_White_Block"
    },
    {
      "x": 0,
      "y": -6,
      "z": -4,
      "name": "Rock_Crystal_White_Block"
    },
    {
      "x": 0,
      "y": -5,
      "z": -4,
      "name": "Rock_Crystal_White_Block"
    },
    {
      "x": 0,
      "y": -3,
      "z": -4,
      "name": "Rock_Crystal_White_Block"
    },
    {
      "x": 0,
      "y": -2,
      "z": -4,
      "name": "Rock_Crystal_White_Block"
    },
    {
      "x": 0,
      "y": -1,
      "z": -4,
      "name": "Rock_Crystal_White_Block"
    },
    {
      "x": 0,
      "y": 0,
      "z": -4,
      "name": "Rock_Crystal_White_Block"
    },
    {
      "x": 0,
      "y": 1,
      "z": -4,
      "name": "Rock_Crystal_White_Block"
    },
    {
      "x": 0,
      "y": 2,
      "z": -4,
      "name": "Rock_Crystal_White_Block"
    },
    {
      "x": 0,
      "y": 3,
      "z": -4,
      "name": "Rock_Crystal_White_Block"
    },
    {
      "x": 0,
      "y": 5,
      "z": -4,
      "name": "Rock_Crystal_White_Block"
    },
    {
      "x": 0,
      "y": 6,
      "z": -4,
      "name": "Rock_Crystal_White_Block"
    },
    {
      "x": 0,
      "y": 9,
      "z": -4,
      "name": "Rock_Crystal_White_Block"
    },
    {
      "x": 0,
      "y": 10,
      "z": -4,
      "name": "Rock_Crystal_White_Block"
    },
    {
      "x": 0,
      "y": 12,
      "z": -4,
      "name": "Rock_Crystal_White_Block"
    },
    {
      "x": 0,
      "y": -16,
      "z": -3,
      "name": "Rock_Crystal_White_Block"
    },
    {
      "x": 0,
      "y": -14,
      "z": -3,
      "name": "Rock_Crystal_White_Block"
    },
    {
      "x": 0,
      "y": -12,
      "z": -3,
      "name": "Rock_Crystal_White_Block"
    },
    {
      "x": 0,
      "y": -9,
      "z": -3,
      "name": "Rock_Crystal_White_Block"
    },
    {
      "x": 0,
      "y": -7,
      "z": -3,
      "name": "Rock_Crystal_White_Block"
    },
    {
      "x": 0,
      "y": -3,
      "z": -3,
      "name": "Rock_Crystal_White_Block"
    },
    {
      "x": 0,
      "y": -2,
      "z": -3,
      "name": "Rock_Crystal_White_Block"
    },
    {
      "x": 0,
      "y": -1,
      "z": -3,
      "name": "Rock_Crystal_White_Block"
    },
    {
      "x": 0,
      "y": 1,
      "z": -3,
      "name": "Rock_Crystal_White_Block"
    },
    {
      "x": 0,
      "y": 2,
      "z": -3,
      "name": "Rock_Crystal_White_Block"
    },
    {
      "x": 0,
      "y": 3,
      "z": -3,
      "name": "Rock_Crystal_White_Block"
    },
    {
      "x": 0,
      "y": 7,
      "z": -3,
      "name": "Rock_Crystal_White_Block"
    },
    {
      "x": 0,
      "y": 9,
      "z": -3,
      "name": "Rock_Crystal_White_Block"
    },
    {
      "x": 0,
      "y": 12,
      "z": -3,
      "name": "Rock_Crystal_White_Block"
    },
    {
      "x": 0,
      "y": 14,
      "z": -3,
      "name": "Rock_Crystal_White_Block"
    },
    {
      "x": 0,
      "y": 16,
      "z": -3,
      "name": "Rock_Crystal_White_Block"
    },
    {
      "x": 0,
      "y": -18,
      "z": -2,
      "name": "Rock_Crystal_White_Block"
    },
    {
      "x": 0,
      "y": -16,
      "z": -2,
      "name": "Rock_Crystal_White_Block"
    },
    {
      "x": 0,
      "y": -14,
      "z": -2,
      "name": "Rock_Crystal_White_Block"
    },
    {
      "x": 0,
      "y": -13,
      "z": -2,
      "name": "Rock_Crystal_White_Block"
    },
    {
      "x": 0,
      "y": -11,
      "z": -2,
      "name": "Rock_Crystal_White_Block"
    },
    {
      "x": 0,
      "y": -9,
      "z": -2,
      "name": "Rock_Crystal_White_Block"
    },
    {
      "x": 0,
      "y": -8,
      "z": -2,
      "name": "Rock_Crystal_White_Block"
    },
    {
      "x": 0,
      "y": -6,
      "z": -2,
      "name": "Rock_Crystal_White_Block"
    },
    {
      "x": 0,
      "y": -4,
      "z": -2,
      "name": "Rock_Crystal_White_Block"
    },
    {
      "x": 0,
      "y": -2,
      "z": -2,
      "name": "Rock_Crystal_White_Block"
    },
    {
      "x": 0,
      "y": -1,
      "z": -2,
      "name": "Rock_Crystal_White_Block"
    },
    {
      "x": 0,
      "y": 0,
      "z": -2,
      "name": "Rock_Crystal_White_Block"
    },
    {
      "x": 0,
      "y": 1,
      "z": -2,
      "name": "Rock_Crystal_White_Block"
    },
    {
      "x": 0,
      "y": 2,
      "z": -2,
      "name": "Rock_Crystal_White_Block"
    },
    {
      "x": 0,
      "y": 4,
      "z": -2,
      "name": "Rock_Crystal_White_Block"
    },
    {
      "x": 0,
      "y": 6,
      "z": -2,
      "name": "Rock_Crystal_White_Block"
    },
    {
      "x": 0,
      "y": 8,
      "z": -2,
      "name": "Rock_Crystal_White_Block"
    },
    {
      "x": 0,
      "y": 9,
      "z": -2,
      "name": "Rock_Crystal_White_Block"
    },
    {
      "x": 0,
      "y": 11,
      "z": -2,
      "name": "Rock_Crystal_White_Block"
    },
    {
      "x": 0,
      "y": 13,
      "z": -2,
      "name": "Rock_Crystal_White_Block"
    },
    {
      "x": 0,
      "y": 14,
      "z": -2,
      "name": "Rock_Crystal_White_Block"
    },
    {
      "x": 0,
      "y": 16,
      "z": -2,
      "name": "Rock_Crystal_White_Block"
    },
    {
      "x": 0,
      "y": 18,
      "z": -2,
      "name": "Rock_Crystal_White_Block"
    },
    {
      "x": 0,
      "y": -20,
      "z": -1,
      "name": "Rock_Crystal_White_Block"
    },
    {
      "x": 0,
      "y": -18,
      "z": -1,
      "name": "Rock_Crystal_White_Block"
    },
    {
      "x": 0,
      "y": -16,
      "z": -1,
      "name": "Rock_Crystal_White_Block"
    },
    {
      "x": 0,
      "y": -15,
      "z": -1,
      "name": "Rock_Crystal_White_Block"
    },
    {
      "x": 0,
      "y": -13,
      "z": -1,
      "name": "Rock_Crystal_White_Block"
    },
    {
      "x": 0,
      "y": -12,
      "z": -1,
      "name": "Rock_Crystal_White_Block"
    },
    {
      "x": 0,
      "y": -11,
      "z": -1,
      "name": "Rock_Crystal_White_Block"
    },
    {
      "x": 0,
      "y": -10,
      "z": -1,
      "name": "Rock_Crystal_White_Block"
    },
    {
      "x": 0,
      "y": -8,
      "z": -1,
      "name": "Rock_Crystal_White_Block"
    },
    {
      "x": 0,
      "y": -7,
      "z": -1,
      "name": "Rock_Crystal_White_Block"
    },
    {
      "x": 0,
      "y": -6,
      "z": -1,
      "name": "Rock_Crystal_White_Block"
    },
    {
      "x": 0,
      "y": -5,
      "z": -1,
      "name": "Rock_Crystal_White_Block"
    },
    {
      "x": 0,
      "y": -4,
      "z": -1,
      "name": "Rock_Crystal_White_Block"
    },
    {
      "x": 0,
      "y": -3,
      "z": -1,
      "name": "Rock_Crystal_White_Block"
    },
    {
      "x": 0,
      "y": -2,
      "z": -1,
      "name": "Rock_Crystal_White_Block"
    },
    {
      "x": 0,
      "y": -1,
      "z": -1,
      "name": "Rock_Crystal_White_Block"
    },
    {
      "x": 0,
      "y": 0,
      "z": -1,
      "name": "Rock_Crystal_White_Block"
    },
    {
      "x": 0,
      "y": 1,
      "z": -1,
      "name": "Rock_Crystal_White_Block"
    },
    {
      "x": 0,
      "y": 2,
      "z": -1,
      "name": "Rock_Crystal_White_Block"
    },
    {
      "x": 0,
      "y": 3,
      "z": -1,
      "name": "Rock_Crystal_White_Block"
    },
    {
      "x": 0,
      "y": 4,
      "z": -1,
      "name": "Rock_Crystal_White_Block"
    },
    {
      "x": 0,
      "y": 5,
      "z": -1,
      "name": "Rock_Crystal_White_Block"
    },
    {
      "x": 0,
      "y": 6,
      "z": -1,
      "name": "Rock_Crystal_White_Block"
    },
    {
      "x": 0,
      "y": 7,
      "z": -1,
      "name": "Rock_Crystal_White_Block"
    },
    {
      "x": 0,
      "y": 8,
      "z": -1,
      "name": "Rock_Crystal_White_Block"
    },
    {
      "x": 0,
      "y": 10,
      "z": -1,
      "name": "Rock_Crystal_White_Block"
    },
    {
      "x": 0,
      "y": 11,
      "z": -1,
      "name": "Rock_Crystal_White_Block"
    },
    {
      "x": 0,
      "y": 12,
      "z": -1,
      "name": "Rock_Crystal_White_Block"
    },
    {
      "x": 0,
      "y": 13,
      "z": -1,
      "name": "Rock_Crystal_White_Block"
    },
    {
      "x": 0,
      "y": 15,
      "z": -1,
      "name": "Rock_Crystal_White_Block"
    },
    {
      "x": 0,
      "y": 16,
      "z": -1,
      "name": "Rock_Crystal_White_Block"
    },
    {
      "x": 0,
      "y": 18,
      "z": -1,
      "name": "Rock_Crystal_White_Block"
    },
    {
      "x": 0,
      "y": 20,
      "z": -1,
      "name": "Rock_Crystal_White_Block"
    },
    {
      "x": 0,
      "y": -21,
      "z": 0,
      "name": "Rock_Crystal_White_Block"
    },
    {
      "x": 0,
      "y": -20,
      "z": 0,
      "name": "Rock_Crystal_White_Block"
    },
    {
      "x": 0,
      "y": -19,
      "z": 0,
      "name": "Rock_Crystal_White_Block"
    },
    {
      "x": 0,
      "y": -18,
      "z": 0,
      "name": "Rock_Crystal_White_Block"
    },
    {
      "x": 0,
      "y": -17,
      "z": 0,
      "name": "Rock_Crystal_White_Block"
    },
    {
      "x": 0,
      "y": -16,
      "z": 0,
      "name": "Rock_Crystal_White_Block"
    },
    {
      "x": 0,
      "y": -15,
      "z": 0,
      "name": "Rock_Crystal_White_Block"
    },
    {
      "x": 0,
      "y": -14,
      "z": 0,
      "name": "Rock_Crystal_White_Block"
    },
    {
      "x": 0,
      "y": -13,
      "z": 0,
      "name": "Rock_Crystal_White_Block"
    },
    {
      "x": 0,
      "y": -12,
      "z": 0,
      "name": "Rock_Crystal_White_Block"
    },
    {
      "x": 0,
      "y": -11,
      "z": 0,
      "name": "Rock_Crystal_White_Block"
    },
    {
      "x": 0,
      "y": -10,
      "z": 0,
      "name": "Rock_Crystal_White_Block"
    },
    {
      "x": 0,
      "y": -9,
      "z": 0,
      "name": "Rock_Crystal_White_Block"
    },
    {
      "x": 0,
      "y": -8,
      "z": 0,
      "name": "Rock_Crystal_White_Block"
    },
    {
      "x": 0,
      "y": -7,
      "z": 0,
      "name": "Rock_Crystal_White_Block"
    },
    {
      "x": 0,
      "y": -6,
      "z": 0,
      "name": "Rock_Crystal_White_Block"
    },
    {
      "x": 0,
      "y": -5,
      "z": 0,
      "name": "Rock_Crystal_White_Block"
    },
    {
      "x": 0,
      "y": -4,
      "z": 0,
      "name": "Rock_Crystal_White_Block"
    },
    {
      "x": 0,
      "y": -3,
      "z": 0,
      "name": "Rock_Crystal_White_Block"
    },
    {
      "x": 0,
      "y": -2,
      "z": 0,
      "name": "Rock_Crystal_White_Block"
    },
    {
      "x": 0,
      "y": -1,
      "z": 0,
      "name": "Rock_Crystal_White_Block"
    },
    {
      "x": 0,
      "y": 0,
      "z": 0,
      "name": "Rock_Crystal_White_Block"
    },
    {
      "x": 0,
      "y": 1,
      "z": 0,
      "name": "Rock_Crystal_White_Block",
      "rotation": 2
    },
    {
      "x": 0,
      "y": 2,
      "z": 0,
      "name": "Rock_Crystal_White_Block",
      "rotation": 2
    },
    {
      "x": 0,
      "y": 3,
      "z": 0,
      "name": "Rock_Crystal_White_Block",
      "rotation": 2
    },
    {
      "x": 0,
      "y": 4,
      "z": 0,
      "name": "Rock_Crystal_White_Block",
      "rotation": 2
    },
    {
      "x": 0,
      "y": 5,
      "z": 0,
      "name": "Rock_Crystal_White_Block",
      "rotation": 2
    },
    {
      "x": 0,
      "y": 6,
      "z": 0,
      "name": "Rock_Crystal_White_Block",
      "rotation": 2
    },
    {
      "x": 0,
      "y": 7,
      "z": 0,
      "name": "Rock_Crystal_White_Block",
      "rotation": 2
    },
    {
      "x": 0,
      "y": 8,
      "z": 0,
      "name": "Rock_Crystal_White_Block",
      "rotation": 2
    },
    {
      "x": 0,
      "y": 9,
      "z": 0,
      "name": "Rock_Crystal_White_Block",
      "rotation": 2
    },
    {
      "x": 0,
      "y": 10,
      "z": 0,
      "name": "Rock_Crystal_White_Block",
      "rotation": 2
    },
    {
      "x": 0,
      "y": 11,
      "z": 0,
      "name": "Rock_Crystal_White_Block",
      "rotation": 2
    },
    {
      "x": 0,
      "y": 12,
      "z": 0,
      "name": "Rock_Crystal_White_Block",
      "rotation": 2
    },
    {
      "x": 0,
      "y": 13,
      "z": 0,
      "name": "Rock_Crystal_White_Block",
      "rotation": 2
    },
    {
      "x": 0,
      "y": 14,
      "z": 0,
      "name": "Rock_Crystal_White_Block",
      "rotation": 2
    },
    {
      "x": 0,
      "y": 15,
      "z": 0,
      "name": "Rock_Crystal_White_Block",
      "rotation": 2
    },
    {
      "x": 0,
      "y": 16,
      "z": 0,
      "name": "Rock_Crystal_White_Block",
      "rotation": 2
    },
    {
      "x": 0,
      "y": 17,
      "z": 0,
      "name": "Rock_Crystal_White_Block",
      "rotation": 2
    },
    {
      "x": 0,
      "y": 18,
      "z": 0,
      "name": "Rock_Crystal_White_Block",
      "rotation": 2
    },
    {
      "x": 0,
      "y": 19,
      "z": 0,
      "name": "Rock_Crystal_White_Block",
      "rotation": 2
    },
    {
      "x": 0,
      "y": 20,
      "z": 0,
      "name": "Rock_Crystal_White_Block",
      "rotation": 2
    },
    {
      "x": 0,
      "y": 21,
      "z": 0,
      "name": "Rock_Crystal_White_Block",
      "rotation": 2
    },
    {
      "x": 0,
      "y": 22,
      "z": 0,
      "name": "Rock_Crystal_White_Block",
      "rotation": 2
    },
    {
      "x": 0,
      "y": -20,
      "z": 1,
      "name": "Rock_Crystal_White_Block",
      "rotation": 2
    },
    {
      "x": 0,
      "y": -18,
      "z": 1,
      "name": "Rock_Crystal_White_Block",
      "rotation": 2
    },
    {
      "x": 0,
      "y": -16,
      "z": 1,
      "name": "Rock_Crystal_White_Block",
      "rotation": 2
    },
    {
      "x": 0,
      "y": -15,
      "z": 1,
      "name": "Rock_Crystal_White_Block",
      "rotation": 2
    },
    {
      "x": 0,
      "y": -13,
      "z": 1,
      "name": "Rock_Crystal_White_Block",
      "rotation": 2
    },
    {
      "x": 0,
      "y": -12,
      "z": 1,
      "name": "Rock_Crystal_White_Block",
      "rotation": 2
    },
    {
      "x": 0,
      "y": -11,
      "z": 1,
      "name": "Rock_Crystal_White_Block",
      "rotation": 2
    },
    {
      "x": 0,
      "y": -10,
      "z": 1,
      "name": "Rock_Crystal_White_Block",
      "rotation": 2
    },
    {
      "x": 0,
      "y": -8,
      "z": 1,
      "name": "Rock_Crystal_White_Block",
      "rotation": 2
    },
    {
      "x": 0,
      "y": -7,
      "z": 1,
      "name": "Rock_Crystal_White_Block",
      "rotation": 2
    },
    {
      "x": 0,
      "y": -6,
      "z": 1,
      "name": "Rock_Crystal_White_Block",
      "rotation": 2
    },
    {
      "x": 0,
      "y": -5,
      "z": 1,
      "name": "Rock_Crystal_White_Block",
      "rotation": 2
    },
    {
      "x": 0,
      "y": -4,
      "z": 1,
      "name": "Rock_Crystal_White_Block",
      "rotation": 2
    },
    {
      "x": 0,
      "y": -3,
      "z": 1,
      "name": "Rock_Crystal_White_Block",
      "rotation": 2
    },
    {
      "x": 0,
      "y": -2,
      "z": 1,
      "name": "Rock_Crystal_White_Block",
      "rotation": 2
    },
    {
      "x": 0,
      "y": -1,
      "z": 1,
      "name": "Rock_Crystal_White_Block",
      "rotation": 2
    },
    {
      "x": 0,
      "y": 0,
      "z": 1,
      "name": "Rock_Crystal_White_Block",
      "rotation": 2
    },
    {
      "x": 0,
      "y": 1,
      "z": 1,
      "name": "Rock_Crystal_White_Block",
      "rotation": 2
    },
    {
      "x": 0,
      "y": 2,
      "z": 1,
      "name": "Rock_Crystal_White_Block",
      "rotation": 2
    },
    {
      "x": 0,
      "y": 3,
      "z": 1,
      "name": "Rock_Crystal_White_Block",
      "rotation": 2
    },
    {
      "x": 0,
      "y": 4,
      "z": 1,
      "name": "Rock_Crystal_White_Block",
      "rotation": 2
    },
    {
      "x": 0,
      "y": 5,
      "z": 1,
      "name": "Rock_Crystal_White_Block",
      "rotation": 2
    },
    {
      "x": 0,
      "y": 6,
      "z": 1,
      "name": "Rock_Crystal_White_Block",
      "rotation": 2
    },
    {
      "x": 0,
      "y": 7,
      "z": 1,
      "name": "Rock_Crystal_White_Block",
      "rotation": 2
    },
    {
      "x": 0,
      "y": 8,
      "z": 1,
      "name": "Rock_Crystal_White_Block",
      "rotation": 2
    },
    {
      "x": 0,
      "y": 10,
      "z": 1,
      "name": "Rock_Crystal_White_Block",
      "rotation": 2
    },
    {
      "x": 0,
      "y": 11,
      "z": 1,
      "name": "Rock_Crystal_White_Block",
      "rotation": 2
    },
    {
      "x": 0,
      "y": 12,
      "z": 1,
      "name": "Rock_Crystal_White_Block",
      "rotation": 2
    },
    {
      "x": 0,
      "y": 13,
      "z": 1,
      "name": "Rock_Crystal_White_Block",
      "rotation": 2
    },
    {
      "x": 0,
      "y": 15,
      "z": 1,
      "name": "Rock_Crystal_White_Block",
      "rotation": 2
    },
    {
      "x": 0,
      "y": 16,
      "z": 1,
      "name": "Rock_Crystal_White_Block",
      "rotation": 2
    },
    {
      "x": 0,
      "y": 18,
      "z": 1,
      "name": "Rock_Crystal_White_Block",
      "rotation": 2
    },
    {
      "x": 0,
      "y": 20,
      "z": 1,
      "name": "Rock_Crystal_White_Block",
      "rotation": 2
    },
    {
      "x": 0,
      "y": -18,
      "z": 2,
      "name": "Rock_Crystal_White_Block",
      "rotation": 2
    },
    {
      "x": 0,
      "y": -16,
      "z": 2,
      "name": "Rock_Crystal_White_Block",
      "rotation": 2
    },
    {
      "x": 0,
      "y": -14,
      "z": 2,
      "name": "Rock_Crystal_White_Block",
      "rotation": 2
    },
    {
      "x": 0,
      "y": -13,
      "z": 2,
      "name": "Rock_Crystal_White_Block",
      "rotation": 2
    },
    {
      "x": 0,
      "y": -11,
      "z": 2,
      "name": "Rock_Crystal_White_Block",
      "rotation": 2
    },
    {
      "x": 0,
      "y": -9,
      "z": 2,
      "name": "Rock_Crystal_White_Block",
      "rotation": 2
    },
    {
      "x": 0,
      "y": -8,
      "z": 2,
      "name": "Rock_Crystal_White_Block",
      "rotation": 2
    },
    {
      "x": 0,
      "y": -6,
      "z": 2,
      "name": "Rock_Crystal_White_Block",
      "rotation": 2
    },
    {
      "x": 0,
      "y": -4,
      "z": 2,
      "name": "Rock_Crystal_White_Block",
      "rotation": 2
    },
    {
      "x": 0,
      "y": -2,
      "z": 2,
      "name": "Rock_Crystal_White_Block",
      "rotation": 2
    },
    {
      "x": 0,
      "y": -1,
      "z": 2,
      "name": "Rock_Crystal_White_Block",
      "rotation": 2
    },
    {
      "x": 0,
      "y": 0,
      "z": 2,
      "name": "Rock_Crystal_White_Block",
      "rotation": 2
    },
    {
      "x": 0,
      "y": 1,
      "z": 2,
      "name": "Rock_Crystal_White_Block",
      "rotation": 2
    },
    {
      "x": 0,
      "y": 2,
      "z": 2,
      "name": "Rock_Crystal_White_Block",
      "rotation": 2
    },
    {
      "x": 0,
      "y": 4,
      "z": 2,
      "name": "Rock_Crystal_White_Block",
      "rotation": 2
    },
    {
      "x": 0,
      "y": 6,
      "z": 2,
      "name": "Rock_Crystal_White_Block",
      "rotation": 2
    },
    {
      "x": 0,
      "y": 8,
      "z": 2,
      "name": "Rock_Crystal_White_Block",
      "rotation": 2
    },
    {
      "x": 0,
      "y": 9,
      "z": 2,
      "name": "Rock_Crystal_White_Block",
      "rotation": 2
    },
    {
      "x": 0,
      "y": 11,
      "z": 2,
      "name": "Rock_Crystal_White_Block",
      "rotation": 2
    },
    {
      "x": 0,
      "y": 13,
      "z": 2,
      "name": "Rock_Crystal_White_Block",
      "rotation": 2
    },
    {
      "x": 0,
      "y": 14,
      "z": 2,
      "name": "Rock_Crystal_White_Block",
      "rotation": 2
    },
    {
      "x": 0,
      "y": 16,
      "z": 2,
      "name": "Rock_Crystal_White_Block",
      "rotation": 2
    },
    {
      "x": 0,
      "y": 18,
      "z": 2,
      "name": "Rock_Crystal_White_Block",
      "rotation": 2
    },
    {
      "x": 0,
      "y": -16,
      "z": 3,
      "name": "Rock_Crystal_White_Block",
      "rotation": 2
    },
    {
      "x": 0,
      "y": -14,
      "z": 3,
      "name": "Rock_Crystal_White_Block",
      "rotation": 2
    },
    {
      "x": 0,
      "y": -12,
      "z": 3,
      "name": "Rock_Crystal_White_Block",
      "rotation": 2
    },
    {
      "x": 0,
      "y": -9,
      "z": 3,
      "name": "Rock_Crystal_White_Block",
      "rotation": 2
    },
    {
      "x": 0,
      "y": -7,
      "z": 3,
      "name": "Rock_Crystal_White_Block",
      "rotation": 2
    },
    {
      "x": 0,
      "y": -3,
      "z": 3,
      "name": "Rock_Crystal_White_Block",
      "rotation": 2
    },
    {
      "x": 0,
      "y": -2,
      "z": 3,
      "name": "Rock_Crystal_White_Block",
      "rotation": 2
    },
    {
      "x": 0,
      "y": -1,
      "z": 3,
      "name": "Rock_Crystal_White_Block",
      "rotation": 2
    },
    {
      "x": 0,
      "y": 1,
      "z": 3,
      "name": "Rock_Crystal_White_Block",
      "rotation": 2
    },
    {
      "x": 0,
      "y": 2,
      "z": 3,
      "name": "Rock_Crystal_White_Block",
      "rotation": 2
    },
    {
      "x": 0,
      "y": 3,
      "z": 3,
      "name": "Rock_Crystal_White_Block",
      "rotation": 2
    },
    {
      "x": 0,
      "y": 7,
      "z": 3,
      "name": "Rock_Crystal_White_Block",
      "rotation": 2
    },
    {
      "x": 0,
      "y": 9,
      "z": 3,
      "name": "Rock_Crystal_White_Block",
      "rotation": 2
    },
    {
      "x": 0,
      "y": 12,
      "z": 3,
      "name": "Rock_Crystal_White_Block",
      "rotation": 2
    },
    {
      "x": 0,
      "y": 14,
      "z": 3,
      "name": "Rock_Crystal_White_Block",
      "rotation": 2
    },
    {
      "x": 0,
      "y": 16,
      "z": 3,
      "name": "Rock_Crystal_White_Block",
      "rotation": 2
    },
    {
      "x": 0,
      "y": -12,
      "z": 4,
      "name": "Rock_Crystal_White_Block",
      "rotation": 2
    },
    {
      "x": 0,
      "y": -10,
      "z": 4,
      "name": "Rock_Crystal_White_Block",
      "rotation": 2
    },
    {
      "x": 0,
      "y": -9,
      "z": 4,
      "name": "Rock_Crystal_White_Block",
      "rotation": 2
    },
    {
      "x": 0,
      "y": -6,
      "z": 4,
      "name": "Rock_Crystal_White_Block",
      "rotation": 2
    },
    {
      "x": 0,
      "y": -5,
      "z": 4,
      "name": "Rock_Crystal_White_Block",
      "rotation": 2
    },
    {
      "x": 0,
      "y": -3,
      "z": 4,
      "name": "Rock_Crystal_White_Block",
      "rotation": 2
    },
    {
      "x": 0,
      "y": -2,
      "z": 4,
      "name": "Rock_Crystal_White_Block",
      "rotation": 2
    },
    {
      "x": 0,
      "y": -1,
      "z": 4,
      "name": "Rock_Crystal_White_Block",
      "rotation": 2
    },
    {
      "x": 0,
      "y": 0,
      "z": 4,
      "name": "Rock_Crystal_White_Block",
      "rotation": 2
    },
    {
      "x": 0,
      "y": 1,
      "z": 4,
      "name": "Rock_Crystal_White_Block",
      "rotation": 2
    },
    {
      "x": 0,
      "y": 2,
      "z": 4,
      "name": "Rock_Crystal_White_Block",
      "rotation": 2
    },
    {
      "x": 0,
      "y": 3,
      "z": 4,
      "name": "Rock_Crystal_White_Block",
      "rotation": 2
    },
    {
      "x": 0,
      "y": 5,
      "z": 4,
      "name": "Rock_Crystal_White_Block",
      "rotation": 2
    },
    {
      "x": 0,
      "y": 6,
      "z": 4,
      "name": "Rock_Crystal_White_Block",
      "rotation": 2
    },
    {
      "x": 0,
      "y": 9,
      "z": 4,
      "name": "Rock_Crystal_White_Block",
      "rotation": 2
    },
    {
      "x": 0,
      "y": 10,
      "z": 4,
      "name": "Rock_Crystal_White_Block",
      "rotation": 2
    },
    {
      "x": 0,
      "y": 12,
      "z": 4,
      "name": "Rock_Crystal_White_Block",
      "rotation": 2
    },
    {
      "x": 0,
      "y": -10,
      "z": 5,
      "name": "Rock_Crystal_White_Block",
      "rotation": 2
    },
    {
      "x": 0,
      "y": -8,
      "z": 5,
      "name": "Rock_Crystal_White_Block",
      "rotation": 2
    },
    {
      "x": 0,
      "y": -4,
      "z": 5,
      "name": "Rock_Crystal_White_Block",
      "rotation": 2
    },
    {
      "x": 0,
      "y": -3,
      "z": 5,
      "name": "Rock_Crystal_White_Block",
      "rotation": 2
    },
    {
      "x": 0,
      "y": -2,
      "z": 5,
      "name": "Rock_Crystal_White_Block",
      "rotation": 2
    },
    {
      "x": 0,
      "y": -1,
      "z": 5,
      "name": "Rock_Crystal_White_Block",
      "rotation": 2
    },
    {
      "x": 0,
      "y": 1,
      "z": 5,
      "name": "Rock_Crystal_White_Block",
      "rotation": 2
    },
    {
      "x": 0,
      "y": 2,
      "z": 5,
      "name": "Rock_Crystal_White_Block",
      "rotation": 2
    },
    {
      "x": 0,
      "y": 3,
      "z": 5,
      "name": "Rock_Crystal_White_Block",
      "rotation": 2
    },
    {
      "x": 0,
      "y": 4,
      "z": 5,
      "name": "Rock_Crystal_White_Block",
      "rotation": 2
    },
    {
      "x": 0,
      "y": 8,
      "z": 5,
      "name": "Rock_Crystal_White_Block",
      "rotation": 2
    },
    {
      "x": 0,
      "y": 10,
      "z": 5,
      "name": "Rock_Crystal_White_Block",
      "rotation": 2
    },
    {
      "x": 0,
      "y": -7,
      "z": 6,
      "name": "Rock_Crystal_White_Block",
      "rotation": 2
    },
    {
      "x": 0,
      "y": -6,
      "z": 6,
      "name": "Rock_Crystal_White_Block",
      "rotation": 2
    },
    {
      "x": 0,
      "y": -4,
      "z": 6,
      "name": "Rock_Crystal_White_Block",
      "rotation": 2
    },
    {
      "x": 0,
      "y": -3,
      "z": 6,
      "name": "Rock_Crystal_White_Block",
      "rotation": 2
    },
    {
      "x": 0,
      "y": -2,
      "z": 6,
      "name": "Rock_Crystal_White_Block",
      "rotation": 2
    },
    {
      "x": 0,
      "y": 0,
      "z": 6,
      "name": "Rock_Crystal_White_Block",
      "rotation": 2
    },
    {
      "x": 0,
      "y": 2,
      "z": 6,
      "name": "Rock_Crystal_White_Block",
      "rotation": 2
    },
    {
      "x": 0,
      "y": 3,
      "z": 6,
      "name": "Rock_Crystal_White_Block",
      "rotation": 2
    },
    {
      "x": 0,
      "y": 4,
      "z": 6,
      "name": "Rock_Crystal_White_Block",
      "rotation": 2
    },
    {
      "x": 0,
      "y": 6,
      "z": 6,
      "name": "Rock_Crystal_White_Block",
      "rotation": 2
    },
    {
      "x": 0,
      "y": 7,
      "z": 6,
      "name": "Rock_Crystal_White_Block",
      "rotation": 2
    },
    {
      "x": 0,
      "y": -10,
      "z": 7,
      "name": "Rock_Crystal_White_Block",
      "rotation": 2
    },
    {
      "x": 0,
      "y": -9,
      "z": 7,
      "name": "Rock_Crystal_White_Block",
      "rotation": 2
    },
    {
      "x": 0,
      "y": -8,
      "z": 7,
      "name": "Rock_Crystal_White_Block",
      "rotation": 2
    },
    {
      "x": 0,
      "y": -5,
      "z": 7,
      "name": "Rock_Crystal_White_Block",
      "rotation": 2
    },
    {
      "x": 0,
      "y": -4,
      "z": 7,
      "name": "Rock_Crystal_White_Block",
      "rotation": 2
    },
    {
      "x": 0,
      "y": -3,
      "z": 7,
      "name": "Rock_Crystal_White_Block",
      "rotation": 2
    },
    {
      "x": 0,
      "y": -2,
      "z": 7,
      "name": "Rock_Crystal_White_Block",
      "rotation": 2
    },
    {
      "x": 0,
      "y": -1,
      "z": 7,
      "name": "Rock_Crystal_White_Block",
      "rotation": 2
    },
    {
      "x": 0,
      "y": 1,
      "z": 7,
      "name": "Rock_Crystal_White_Block",
      "rotation": 2
    },
    {
      "x": 0,
      "y": 2,
      "z": 7,
      "name": "Rock_Crystal_White_Block",
      "rotation": 2
    },
    {
      "x": 0,
      "y": 3,
      "z": 7,
      "name": "Rock_Crystal_White_Block",
      "rotation": 2
    },
    {
      "x": 0,
      "y": 4,
      "z": 7,
      "name": "Rock_Crystal_White_Block",
      "rotation": 2
    },
    {
      "x": 0,
      "y": 5,
      "z": 7,
      "name": "Rock_Crystal_White_Block",
      "rotation": 2
    },
    {
      "x": 0,
      "y": 8,
      "z": 7,
      "name": "Rock_Crystal_White_Block",
      "rotation": 2
    },
    {
      "x": 0,
      "y": 9,
      "z": 7,
      "name": "Rock_Crystal_White_Block",
      "rotation": 2
    },
    {
      "x": 0,
      "y": 10,
      "z": 7,
      "name": "Rock_Crystal_White_Block",
      "rotation": 2
    },
    {
      "x": 0,
      "y": -7,
      "z": 8,
      "name": "Rock_Crystal_White_Block",
      "rotation": 2
    },
    {
      "x": 0,
      "y": -6,
      "z": 8,
      "name": "Rock_Crystal_White_Block",
      "rotation": 2
    },
    {
      "x": 0,
      "y": -5,
      "z": 8,
      "name": "Rock_Crystal_White_Block",
      "rotation": 2
    },
    {
      "x": 0,
      "y": -4,
      "z": 8,
      "name": "Rock_Crystal_White_Block",
      "rotation": 2
    },
    {
      "x": 0,
      "y": -3,
      "z": 8,
      "name": "Rock_Crystal_White_Block",
      "rotation": 2
    },
    {
      "x": 0,
      "y": -1,
      "z": 8,
      "name": "Rock_Crystal_White_Block",
      "rotation": 2
    },
    {
      "x": 0,
      "y": 1,
      "z": 8,
      "name": "Rock_Crystal_White_Block",
      "rotation": 2
    },
    {
      "x": 0,
      "y": 3,
      "z": 8,
      "name": "Rock_Crystal_White_Block",
      "rotation": 2
    },
    {
      "x": 0,
      "y": 4,
      "z": 8,
      "name": "Rock_Crystal_White_Block",
      "rotation": 2
    },
    {
      "x": 0,
      "y": 5,
      "z": 8,
      "name": "Rock_Crystal_White_Block",
      "rotation": 2
    },
    {
      "x": 0,
      "y": 6,
      "z": 8,
      "name": "Rock_Crystal_White_Block",
      "rotation": 2
    },
    {
      "x": 0,
      "y": 7,
      "z": 8,
      "name": "Rock_Crystal_White_Block",
      "rotation": 2
    },
    {
      "x": 0,
      "y": -10,
      "z": 9,
      "name": "Rock_Crystal_White_Block",
      "rotation": 2
    },
    {
      "x": 0,
      "y": -9,
      "z": 9,
      "name": "Rock_Crystal_White_Block",
      "rotation": 2
    },
    {
      "x": 0,
      "y": -6,
      "z": 9,
      "name": "Rock_Crystal_White_Block",
      "rotation": 2
    },
    {
      "x": 0,
      "y": -5,
      "z": 9,
      "name": "Rock_Crystal_White_Block",
      "rotation": 2
    },
    {
      "x": 0,
      "y": -4,
      "z": 9,
      "name": "Rock_Crystal_White_Block",
      "rotation": 2
    },
    {
      "x": 0,
      "y": -2,
      "z": 9,
      "name": "Rock_Crystal_White_Block",
      "rotation": 2
    },
    {
      "x": 0,
      "y": 0,
      "z": 9,
      "name": "Rock_Crystal_White_Block",
      "rotation": 2
    },
    {
      "x": 0,
      "y": 2,
      "z": 9,
      "name": "Rock_Crystal_White_Block",
      "rotation": 2
    },
    {
      "x": 0,
      "y": 4,
      "z": 9,
      "name": "Rock_Crystal_White_Block",
      "rotation": 2
    },
    {
      "x": 0,
      "y": 5,
      "z": 9,
      "name": "Rock_Crystal_White_Block",
      "rotation": 2
    },
    {
      "x": 0,
      "y": 6,
      "z": 9,
      "name": "Rock_Crystal_White_Block",
      "rotation": 2
    },
    {
      "x": 0,
      "y": 9,
      "z": 9,
      "name": "Rock_Crystal_White_Block",
      "rotation": 2
    },
    {
      "x": 0,
      "y": 10,
      "z": 9,
      "name": "Rock_Crystal_White_Block",
      "rotation": 2
    },
    {
      "x": 0,
      "y": -8,
      "z": 10,
      "name": "Rock_Crystal_White_Block",
      "rotation": 2
    },
    {
      "x": 0,
      "y": -7,
      "z": 10,
      "name": "Rock_Crystal_White_Block",
      "rotation": 2
    },
    {
      "x": 0,
      "y": -6,
      "z": 10,
      "name": "Rock_Crystal_White_Block",
      "rotation": 2
    },
    {
      "x": 0,
      "y": -5,
      "z": 10,
      "name": "Rock_Crystal_White_Block",
      "rotation": 2
    },
    {
      "x": 0,
      "y": -4,
      "z": 10,
      "name": "Rock_Crystal_White_Block",
      "rotation": 2
    },
    {
      "x": 0,
      "y": -1,
      "z": 10,
      "name": "Rock_Crystal_White_Block",
      "rotation": 2
    },
    {
      "x": 0,
      "y": 1,
      "z": 10,
      "name": "Rock_Crystal_White_Block",
      "rotation": 2
    },
    {
      "x": 0,
      "y": 4,
      "z": 10,
      "name": "Rock_Crystal_White_Block",
      "rotation": 2
    },
    {
      "x": 0,
      "y": 5,
      "z": 10,
      "name": "Rock_Crystal_White_Block",
      "rotation": 2
    },
    {
      "x": 0,
      "y": 6,
      "z": 10,
      "name": "Rock_Crystal_White_Block",
      "rotation": 2
    },
    {
      "x": 0,
      "y": 7,
      "z": 10,
      "name": "Rock_Crystal_White_Block",
      "rotation": 2
    },
    {
      "x": 0,
      "y": 8,
      "z": 10,
      "name": "Rock_Crystal_White_Block",
      "rotation": 2
    },
    {
      "x": 0,
      "y": -11,
      "z": 11,
      "name": "Rock_Crystal_White_Block",
      "rotation": 2
    },
    {
      "x": 0,
      "y": -10,
      "z": 11,
      "name": "Rock_Crystal_White_Block",
      "rotation": 2
    },
    {
      "x": 0,
      "y": -7,
      "z": 11,
      "name": "Rock_Crystal_White_Block",
      "rotation": 2
    },
    {
      "x": 0,
      "y": -6,
      "z": 11,
      "name": "Rock_Crystal_White_Block",
      "rotation": 2
    },
    {
      "x": 0,
      "y": -5,
      "z": 11,
      "name": "Rock_Crystal_White_Block",
      "rotation": 2
    },
    {
      "x": 0,
      "y": -3,
      "z": 11,
      "name": "Rock_Crystal_White_Block",
      "rotation": 2
    },
    {
      "x": 0,
      "y": -2,
      "z": 11,
      "name": "Rock_Crystal_White_Block",
      "rotation": 2
    },
    {
      "x": 0,
      "y": 2,
      "z": 11,
      "name": "Rock_Crystal_White_Block",
      "rotation": 2
    },
    {
      "x": 0,
      "y": 3,
      "z": 11,
      "name": "Rock_Crystal_White_Block",
      "rotation": 2
    },
    {
      "x": 0,
      "y": 5,
      "z": 11,
      "name": "Rock_Crystal_White_Block",
      "rotation": 2
    },
    {
      "x": 0,
      "y": 6,
      "z": 11,
      "name": "Rock_Crystal_White_Block",
      "rotation": 2
    },
    {
      "x": 0,
      "y": 7,
      "z": 11,
      "name": "Rock_Crystal_White_Block",
      "rotation": 2
    },
    {
      "x": 0,
      "y": 10,
      "z": 11,
      "name": "Rock_Crystal_White_Block",
      "rotation": 2
    },
    {
      "x": 0,
      "y": 11,
      "z": 11,
      "name": "Rock_Crystal_White_Block",
      "rotation": 2
    },
    {
      "x": 0,
      "y": -9,
      "z": 12,
      "name": "Rock_Crystal_White_Block",
      "rotation": 2
    },
    {
      "x": 0,
      "y": -8,
      "z": 12,
      "name": "Rock_Crystal_White_Block",
      "rotation": 2
    },
    {
      "x": 0,
      "y": -7,
      "z": 12,
      "name": "Rock_Crystal_White_Block",
      "rotation": 2
    },
    {
      "x": 0,
      "y": -6,
      "z": 12,
      "name": "Rock_Crystal_White_Block",
      "rotation": 2
    },
    {
      "x": 0,
      "y": -5,
      "z": 12,
      "name": "Rock_Crystal_White_Block",
      "rotation": 2
    },
    {
      "x": 0,
      "y": -1,
      "z": 12,
      "name": "Rock_Crystal_White_Block",
      "rotation": 2
    },
    {
      "x": 0,
      "y": 1,
      "z": 12,
      "name": "Rock_Crystal_White_Block",
      "rotation": 2
    },
    {
      "x": 0,
      "y": 5,
      "z": 12,
      "name": "Rock_Crystal_White_Block",
      "rotation": 2
    },
    {
      "x": 0,
      "y": 6,
      "z": 12,
      "name": "Rock_Crystal_White_Block",
      "rotation": 2
    },
    {
      "x": 0,
      "y": 7,
      "z": 12,
      "name": "Rock_Crystal_White_Block",
      "rotation": 2
    },
    {
      "x": 0,
      "y": 8,
      "z": 12,
      "name": "Rock_Crystal_White_Block",
      "rotation": 2
    },
    {
      "x": 0,
      "y": 9,
      "z": 12,
      "name": "Rock_Crystal_White_Block",
      "rotation": 2
    },
    {
      "x": 0,
      "y": -11,
      "z": 13,
      "name": "Rock_Crystal_White_Block",
      "rotation": 2
    },
    {
      "x": 0,
      "y": -10,
      "z": 13,
      "name": "Rock_Crystal_White_Block",
      "rotation": 2
    },
    {
      "x": 0,
      "y": -8,
      "z": 13,
      "name": "Rock_Crystal_White_Block",
      "rotation": 2
    },
    {
      "x": 0,
      "y": -7,
      "z": 13,
      "name": "Rock_Crystal_White_Block",
      "rotation": 2
    },
    {
      "x": 0,
      "y": -4,
      "z": 13,
      "name": "Rock_Crystal_White_Block",
      "rotation": 2
    },
    {
      "x": 0,
      "y": -3,
      "z": 13,
      "name": "Rock_Crystal_White_Block",
      "rotation": 2
    },
    {
      "x": 0,
      "y": 3,
      "z": 13,
      "name": "Rock_Crystal_White_Block",
      "rotation": 2
    },
    {
      "x": 0,
      "y": 4,
      "z": 13,
      "name": "Rock_Crystal_White_Block",
      "rotation": 2
    },
    {
      "x": 0,
      "y": 7,
      "z": 13,
      "name": "Rock_Crystal_White_Block",
      "rotation": 2
    },
    {
      "x": 0,
      "y": 8,
      "z": 13,
      "name": "Rock_Crystal_White_Block",
      "rotation": 2
    },
    {
      "x": 0,
      "y": 10,
      "z": 13,
      "name": "Rock_Crystal_White_Block",
      "rotation": 2
    },
    {
      "x": 0,
      "y": 11,
      "z": 13,
      "name": "Rock_Crystal_White_Block",
      "rotation": 2
    },
    {
      "x": 0,
      "y": -10,
      "z": 14,
      "name": "Rock_Crystal_White_Block",
      "rotation": 2
    },
    {
      "x": 0,
      "y": -9,
      "z": 14,
      "name": "Rock_Crystal_White_Block",
      "rotation": 2
    },
    {
      "x": 0,
      "y": -8,
      "z": 14,
      "name": "Rock_Crystal_White_Block",
      "rotation": 2
    },
    {
      "x": 0,
      "y": -7,
      "z": 14,
      "name": "Rock_Crystal_White_Block",
      "rotation": 2
    },
    {
      "x": 0,
      "y": -6,
      "z": 14,
      "name": "Rock_Crystal_White_Block",
      "rotation": 2
    },
    {
      "x": 0,
      "y": -5,
      "z": 14,
      "name": "Rock_Crystal_White_Block",
      "rotation": 2
    },
    {
      "x": 0,
      "y": -2,
      "z": 14,
      "name": "Rock_Crystal_White_Block",
      "rotation": 2
    },
    {
      "x": 0,
      "y": 2,
      "z": 14,
      "name": "Rock_Crystal_White_Block",
      "rotation": 2
    },
    {
      "x": 0,
      "y": 5,
      "z": 14,
      "name": "Rock_Crystal_White_Block",
      "rotation": 2
    },
    {
      "x": 0,
      "y": 6,
      "z": 14,
      "name": "Rock_Crystal_White_Block",
      "rotation": 2
    },
    {
      "x": 0,
      "y": 7,
      "z": 14,
      "name": "Rock_Crystal_White_Block",
      "rotation": 2
    },
    {
      "x": 0,
      "y": 8,
      "z": 14,
      "name": "Rock_Crystal_White_Block",
      "rotation": 2
    },
    {
      "x": 0,
      "y": 9,
      "z": 14,
      "name": "Rock_Crystal_White_Block",
      "rotation": 2
    },
    {
      "x": 0,
      "y": 10,
      "z": 14,
      "name": "Rock_Crystal_White_Block",
      "rotation": 2
    },
    {
      "x": 0,
      "y": -11,
      "z": 15,
      "name": "Rock_Crystal_White_Block",
      "rotation": 2
    },
    {
      "x": 0,
      "y": -10,
      "z": 15,
      "name": "Rock_Crystal_White_Block",
      "rotation": 2
    },
    {
      "x": 0,
      "y": -9,
      "z": 15,
      "name": "Rock_Crystal_White_Block",
      "rotation": 2
    },
    {
      "x": 0,
      "y": -7,
      "z": 15,
      "name": "Rock_Crystal_White_Block",
      "rotation": 2
    },
    {
      "x": 0,
      "y": -4,
      "z": 15,
      "name": "Rock_Crystal_White_Block",
      "rotation": 2
    },
    {
      "x": 0,
      "y": 4,
      "z": 15,
      "name": "Rock_Crystal_White_Block",
      "rotation": 2
    },
    {
      "x": 0,
      "y": 7,
      "z": 15,
      "name": "Rock_Crystal_White_Block",
      "rotation": 2
    },
    {
      "x": 0,
      "y": 9,
      "z": 15,
      "name": "Rock_Crystal_White_Block",
      "rotation": 2
    },
    {
      "x": 0,
      "y": 10,
      "z": 15,
      "name": "Rock_Crystal_White_Block",
      "rotation": 2
    },
    {
      "x": 0,
      "y": 11,
      "z": 15,
      "name": "Rock_Crystal_White_Block",
      "rotation": 2
    },
    {
      "x": 0,
      "y": -10,
      "z": 16,
      "name": "Rock_Crystal_White_Block",
      "rotation": 2
    },
    {
      "x": 0,
      "y": -9,
      "z": 16,
      "name": "Rock_Crystal_White_Block",
      "rotation": 2
    },
    {
      "x": 0,
      "y": -6,
      "z": 16,
      "name": "Rock_Crystal_White_Block",
      "rotation": 2
    },
    {
      "x": 0,
      "y": 6,
      "z": 16,
      "name": "Rock_Crystal_White_Block",
      "rotation": 2
    },
    {
      "x": 0,
      "y": 9,
      "z": 16,
      "name": "Rock_Crystal_White_Block",
      "rotation": 2
    },
    {
      "x": 0,
      "y": 10,
      "z": 16,
      "name": "Rock_Crystal_White_Block",
      "rotation": 2
    },
    {
      "x": 0,
      "y": -11,
      "z": 17,
      "name": "Rock_Crystal_White_Block",
      "rotation": 2
    },
    {
      "x": 0,
      "y": -10,
      "z": 17,
      "name": "Rock_Crystal_White_Block",
      "rotation": 2
    },
    {
      "x": 0,
      "y": -8,
      "z": 17,
      "name": "Rock_Crystal_White_Block",
      "rotation": 2
    },
    {
      "x": 0,
      "y": 8,
      "z": 17,
      "name": "Rock_Crystal_White_Block",
      "rotation": 2
    },
    {
      "x": 0,
      "y": 10,
      "z": 17,
      "name": "Rock_Crystal_White_Block",
      "rotation": 2
    },
    {
      "x": 0,
      "y": 11,
      "z": 17,
      "name": "Rock_Crystal_White_Block",
      "rotation": 2
    },
    {
      "x": 0,
      "y": -11,
      "z": 18,
      "name": "Rock_Crystal_White_Block",
      "rotation": 2
    },
    {
      "x": 0,
      "y": 11,
      "z": 18,
      "name": "Rock_Crystal_White_Block",
      "rotation": 2
    },
    {
      "x": 1,
      "y": -10,
      "z": -16,
      "name": "Rock_Crystal_White_Block"
    },
    {
      "x": 1,
      "y": 10,
      "z": -16,
      "name": "Rock_Crystal_White_Block"
    },
    {
      "x": 1,
      "y": -9,
      "z": -15,
      "name": "Rock_Crystal_White_Block"
    },
    {
      "x": 1,
      "y": -7,
      "z": -15,
      "name": "Rock_Crystal_White_Block"
    },
    {
      "x": 1,
      "y": 7,
      "z": -15,
      "name": "Rock_Crystal_White_Block"
    },
    {
      "x": 1,
      "y": 9,
      "z": -15,
      "name": "Rock_Crystal_White_Block"
    },
    {
      "x": 1,
      "y": -9,
      "z": -14,
      "name": "Rock_Crystal_White_Block"
    },
    {
      "x": 1,
      "y": -8,
      "z": -14,
      "name": "Rock_Crystal_White_Block"
    },
    {
      "x": 1,
      "y": -6,
      "z": -14,
      "name": "Rock_Crystal_White_Block"
    },
    {
      "x": 1,
      "y": 6,
      "z": -14,
      "name": "Rock_Crystal_White_Block"
    },
    {
      "x": 1,
      "y": 8,
      "z": -14,
      "name": "Rock_Crystal_White_Block"
    },
    {
      "x": 1,
      "y": 9,
      "z": -14,
      "name": "Rock_Crystal_White_Block"
    },
    {
      "x": 1,
      "y": -10,
      "z": -13,
      "name": "Rock_Crystal_White_Block"
    },
    {
      "x": 1,
      "y": -8,
      "z": -13,
      "name": "Rock_Crystal_White_Block"
    },
    {
      "x": 1,
      "y": -7,
      "z": -13,
      "name": "Rock_Crystal_White_Block"
    },
    {
      "x": 1,
      "y": 7,
      "z": -13,
      "name": "Rock_Crystal_White_Block"
    },
    {
      "x": 1,
      "y": 8,
      "z": -13,
      "name": "Rock_Crystal_White_Block"
    },
    {
      "x": 1,
      "y": 10,
      "z": -13,
      "name": "Rock_Crystal_White_Block"
    },
    {
      "x": 1,
      "y": -9,
      "z": -12,
      "name": "Rock_Crystal_White_Block"
    },
    {
      "x": 1,
      "y": -7,
      "z": -12,
      "name": "Rock_Crystal_White_Block"
    },
    {
      "x": 1,
      "y": -5,
      "z": -12,
      "name": "Rock_Crystal_White_Block"
    },
    {
      "x": 1,
      "y": 5,
      "z": -12,
      "name": "Rock_Crystal_White_Block"
    },
    {
      "x": 1,
      "y": 7,
      "z": -12,
      "name": "Rock_Crystal_White_Block"
    },
    {
      "x": 1,
      "y": 9,
      "z": -12,
      "name": "Rock_Crystal_White_Block"
    },
    {
      "x": 1,
      "y": -7,
      "z": -11,
      "name": "Rock_Crystal_White_Block"
    },
    {
      "x": 1,
      "y": -6,
      "z": -11,
      "name": "Rock_Crystal_White_Block"
    },
    {
      "x": 1,
      "y": -3,
      "z": -11,
      "name": "Rock_Crystal_White_Block"
    },
    {
      "x": 1,
      "y": 3,
      "z": -11,
      "name": "Rock_Crystal_White_Block"
    },
    {
      "x": 1,
      "y": 6,
      "z": -11,
      "name": "Rock_Crystal_White_Block"
    },
    {
      "x": 1,
      "y": 7,
      "z": -11,
      "name": "Rock_Crystal_White_Block"
    },
    {
      "x": 1,
      "y": -8,
      "z": -10,
      "name": "Rock_Crystal_White_Block"
    },
    {
      "x": 1,
      "y": -6,
      "z": -10,
      "name": "Rock_Crystal_White_Block"
    },
    {
      "x": 1,
      "y": -4,
      "z": -10,
      "name": "Rock_Crystal_White_Block"
    },
    {
      "x": 1,
      "y": 4,
      "z": -10,
      "name": "Rock_Crystal_White_Block"
    },
    {
      "x": 1,
      "y": 6,
      "z": -10,
      "name": "Rock_Crystal_White_Block"
    },
    {
      "x": 1,
      "y": 8,
      "z": -10,
      "name": "Rock_Crystal_White_Block"
    },
    {
      "x": 1,
      "y": -5,
      "z": -9,
      "name": "Rock_Crystal_White_Block"
    },
    {
      "x": 1,
      "y": -2,
      "z": -9,
      "name": "Rock_Crystal_White_Block"
    },
    {
      "x": 1,
      "y": 2,
      "z": -9,
      "name": "Rock_Crystal_White_Block"
    },
    {
      "x": 1,
      "y": 5,
      "z": -9,
      "name": "Rock_Crystal_White_Block"
    },
    {
      "x": 1,
      "y": -7,
      "z": -8,
      "name": "Rock_Crystal_White_Block"
    },
    {
      "x": 1,
      "y": -6,
      "z": -8,
      "name": "Rock_Crystal_White_Block"
    },
    {
      "x": 1,
      "y": -5,
      "z": -8,
      "name": "Rock_Crystal_White_Block"
    },
    {
      "x": 1,
      "y": -3,
      "z": -8,
      "name": "Rock_Crystal_White_Block"
    },
    {
      "x": 1,
      "y": 3,
      "z": -8,
      "name": "Rock_Crystal_White_Block"
    },
    {
      "x": 1,
      "y": 5,
      "z": -8,
      "name": "Rock_Crystal_White_Block"
    },
    {
      "x": 1,
      "y": 6,
      "z": -8,
      "name": "Rock_Crystal_White_Block"
    },
    {
      "x": 1,
      "y": 7,
      "z": -8,
      "name": "Rock_Crystal_White_Block"
    },
    {
      "x": 1,
      "y": -5,
      "z": -7,
      "name": "Rock_Crystal_White_Block"
    },
    {
      "x": 1,
      "y": -4,
      "z": -7,
      "name": "Rock_Crystal_White_Block"
    },
    {
      "x": 1,
      "y": 4,
      "z": -7,
      "name": "Rock_Crystal_White_Block"
    },
    {
      "x": 1,
      "y": 5,
      "z": -7,
      "name": "Rock_Crystal_White_Block"
    },
    {
      "x": 1,
      "y": -7,
      "z": -6,
      "name": "Rock_Crystal_White_Block"
    },
    {
      "x": 1,
      "y": -6,
      "z": -6,
      "name": "Rock_Crystal_White_Block"
    },
    {
      "x": 1,
      "y": -3,
      "z": -6,
      "name": "Rock_Crystal_White_Block"
    },
    {
      "x": 1,
      "y": -2,
      "z": -6,
      "name": "Rock_Crystal_White_Block"
    },
    {
      "x": 1,
      "y": 2,
      "z": -6,
      "name": "Rock_Crystal_White_Block"
    },
    {
      "x": 1,
      "y": 3,
      "z": -6,
      "name": "Rock_Crystal_White_Block"
    },
    {
      "x": 1,
      "y": 6,
      "z": -6,
      "name": "Rock_Crystal_White_Block"
    },
    {
      "x": 1,
      "y": 7,
      "z": -6,
      "name": "Rock_Crystal_White_Block"
    },
    {
      "x": 1,
      "y": -4,
      "z": -5,
      "name": "Rock_Crystal_White_Block"
    },
    {
      "x": 1,
      "y": -3,
      "z": -5,
      "name": "Rock_Crystal_White_Block"
    },
    {
      "x": 1,
      "y": -1,
      "z": -5,
      "name": "Rock_Crystal_White_Block"
    },
    {
      "x": 1,
      "y": 1,
      "z": -5,
      "name": "Rock_Crystal_White_Block"
    },
    {
      "x": 1,
      "y": 3,
      "z": -5,
      "name": "Rock_Crystal_White_Block"
    },
    {
      "x": 1,
      "y": 4,
      "z": -5,
      "name": "Rock_Crystal_White_Block"
    },
    {
      "x": 1,
      "y": -5,
      "z": -4,
      "name": "Rock_Crystal_White_Block"
    },
    {
      "x": 1,
      "y": -2,
      "z": -4,
      "name": "Rock_Crystal_White_Block"
    },
    {
      "x": 1,
      "y": 0,
      "z": -4,
      "name": "Rock_Crystal_White_Block"
    },
    {
      "x": 1,
      "y": 2,
      "z": -4,
      "name": "Rock_Crystal_White_Block"
    },
    {
      "x": 1,
      "y": 5,
      "z": -4,
      "name": "Rock_Crystal_White_Block"
    },
    {
      "x": 1,
      "y": -3,
