{
  "version": 8,
  "blockIdVersion": 11,
  "anchorX": 2,
  "anchorY": 18,
  "anchorZ": 0,
  "blocks": [
    {
      "x": -8,
      "y": 1,
      "z": -1,
      "name": "Rock_Crystal_White_Block"
    },
    {
      "x": -8,
      "y": 0,
      "z": 0,
      "name": "Rock_Crystal_White_Block"
    },
    {
      "x": -8,
      "y": 1,
      "z": 0,
      "name": "Rock_Crystal_White_Block"
    },
    {
      "x": -8,
      "y": 3,
      "z": 0,
      "name": "Rock_Crystal_White_Block"
    },
    {
      "x": -8,
      "y": 1,
      "z": 1,
      "name": "Rock_Crystal_White_Block",
      "rotation": 2
    },
    {
      "x": -7,
      "y": 2,
      "z": -2,
      "name": "Rock_Crystal_White_Block"
    },
    {
      "x": -7,
      "y": 2,
      "z": -1,
      "name": "Rock_Crystal_White_Block"
    },
    {
      "x": -7,
      "y": 5,
      "z": -1,
      "name": "Rock_Crystal_White_Block"
    },
    {
      "x": -7,
      "y": 2,
      "z": 0,
      "name": "Rock_Crystal_White_Block"
    },
    {
      "x": -7,
      "y": 3,
      "z": 0,
      "name": "Rock_Crystal_White_Block"
    },
    {
      "x": -7,
      "y": 4,
      "z": 0,
      "name": "Rock_Crystal_White_Block"
    },
    {
      "x": -7,
      "y": 5,
      "z": 0,
      "name": "Rock_Crystal_White_Block"
    },
    {
      "x": -7,
      "y": 2,
      "z": 1,
      "name": "Rock_Crystal_White_Block",
      "rotation": 2
    },
    {
      "x": -7,
      "y": 5,
      "z": 1,
      "name": "Rock_Crystal_White_Block",
      "rotation": 2
    },
    {
      "x": -7,
      "y": 2,
      "z": 2,
      "name": "Rock_Crystal_White_Block",
      "rotation": 2
    },
    {
      "x": -6,
      "y": 4,
      "z": -3,
      "name": "Rock_Crystal_White_Block"
    },
    {
      "x": -6,
      "y": 4,
      "z": -2,
      "name": "Rock_Crystal_White_Block"
    },
    {
      "x": -6,
      "y": 6,
      "z": -2,
      "name": "Rock_Crystal_White_Block"
    },
    {
      "x": -6,
      "y": 7,
      "z": -2,
      "name": "Rock_Crystal_White_Block"
    },
    {
      "x": -6,
      "y": 4,
      "z": -1,
      "name": "Rock_Crystal_White_Block"
    },
    {
      "x": -6,
      "y": 5,
      "z": -1,
      "name": "Rock_Crystal_White_Block"
    },
    {
      "x": -6,
      "y": 2,
      "z": 0,
      "name": "Rock_Crystal_White_Block"
    },
    {
      "x": -6,
      "y": 3,
      "z": 0,
      "name": "Rock_Crystal_White_Block"
    },
    {
      "x": -6,
      "y": 4,
      "z": 0,
      "name": "Rock_Crystal_White_Block"
    },
    {
      "x": -6,
      "y": 5,
      "z": 0,
      "name": "Rock_Crystal_White_Block"
    },
    {
      "x": -6,
      "y": 6,
      "z": 0,
      "name": "Rock_Crystal_White_Block"
    },
    {
      "x": -6,
      "y": 7,
      "z": 0,
      "name": "Rock_Crystal_White_Block"
    },
    {
      "x": -6,
      "y": 9,
      "z": 0,
      "name": "Rock_Crystal_White_Block"
    },
    {
      "x": -6,
      "y": 4,
      "z": 1,
      "name": "Rock_Crystal_White_Block",
      "rotation": 2
    },
    {
      "x": -6,
      "y": 5,
      "z": 1,
      "name": "Rock_Crystal_White_Block",
      "rotation": 2
    },
    {
      "x": -6,
      "y": 4,
      "z": 2,
      "name": "Rock_Crystal_White_Block",
      "rotation": 2
    },
    {
      "x": -6,
      "y": 6,
      "z": 2,
      "name": "Rock_Crystal_White_Block",
      "rotation": 2
    },
    {
      "x": -6,
      "y": 7,
      "z": 2,
      "name": "Rock_Crystal_White_Block",
      "rotation": 2
    },
    {
      "x": -6,
      "y": 4,
      "z": 3,
      "name": "Rock_Crystal_White_Block",
      "rotation": 2
    },
    {
      "x": -5,
      "y": 6,
      "z": -3,
      "name": "Rock_Crystal_White_Block"
    },
    {
      "x": -5,
      "y": 6,
      "z": -2,
      "name": "Rock_Crystal_White_Block"
    },
    {
      "x": -5,
      "y": 3,
      "z": -1,
      "name": "Rock_Crystal_White_Block"
    },
    {
      "x": -5,
      "y": 4,
      "z": -1,
      "name": "Rock_Crystal_White_Block"
    },
    {
      "x": -5,
      "y": 5,
      "z": -1,
      "name": "Rock_Crystal_White_Block"
    },
    {
      "x": -5,
      "y": 7,
      "z": -1,
      "name": "Rock_Crystal_White_Block"
    },
    {
      "x": -5,
      "y": 3,
      "z": 0,
      "name": "Rock_Crystal_White_Block"
    },
    {
      "x": -5,
      "y": 4,
      "z": 0,
      "name": "Rock_Crystal_White_Block"
    },
    {
      "x": -5,
      "y": 5,
      "z": 0,
      "name": "Rock_Crystal_White_Block"
    },
    {
      "x": -5,
      "y": 6,
      "z": 0,
      "name": "Rock_Crystal_White_Block"
    },
    {
      "x": -5,
      "y": 7,
      "z": 0,
      "name": "Rock_Crystal_White_Block"
    },
    {
      "x": -5,
      "y": 8,
      "z": 0,
      "name": "Rock_Crystal_White_Block"
    },
    {
      "x": -5,
      "y": 9,
      "z": 0,
      "name": "Rock_Crystal_White_Block"
    },
    {
      "x": -5,
      "y": 10,
      "z": 0,
      "name": "Rock_Crystal_White_Block"
    },
    {
      "x": -5,
      "y": 3,
      "z": 1,
      "name": "Rock_Crystal_White_Block",
      "rotation": 2
    },
    {
      "x": -5,
      "y": 4,
      "z": 1,
      "name": "Rock_Crystal_White_Block",
      "rotation": 2
    },
    {
      "x": -5,
      "y": 5,
      "z": 1,
      "name": "Rock_Crystal_White_Block",
      "rotation": 2
    },
    {
      "x": -5,
      "y": 7,
      "z": 1,
      "name": "Rock_Crystal_White_Block",
      "rotation": 2
    },
    {
      "x": -5,
      "y": 6,
      "z": 2,
      "name": "Rock_Crystal_White_Block",
      "rotation": 2
    },
    {
      "x": -5,
      "y": 6,
      "z": 3,
      "name": "Rock_Crystal_White_Block",
      "rotation": 2
    },
    {
      "x": -4,
      "y": 10,
      "z": -16,
      "name": "Rock_Crystal_White_Block"
    },
    {
      "x": -4,
      "y": 10,
      "z": -13,
      "name": "Rock_Crystal_White_Block"
    },
    {
      "x": -4,
      "y": 8,
      "z": -4,
      "name": "Rock_Crystal_White_Block"
    },
    {
      "x": -4,
      "y": 8,
      "z": -3,
      "name": "Rock_Crystal_White_Block"
    },
    {
      "x": -4,
      "y": 5,
      "z": -2,
      "name": "Rock_Crystal_White_Block"
    },
    {
      "x": -4,
      "y": 7,
      "z": -2,
      "name": "Rock_Crystal_White_Block"
    },
    {
      "x": -4,
      "y": 9,
      "z": -2,
      "name": "Rock_Crystal_White_Block"
    },
    {
      "x": -4,
      "y": 6,
      "z": -1,
      "name": "Rock_Crystal_White_Block"
    },
    {
      "x": -4,
      "y": 7,
      "z": -1,
      "name": "Rock_Crystal_White_Block"
    },
    {
      "x": -4,
      "y": 8,
      "z": -1,
      "name": "Rock_Crystal_White_Block"
    },
    {
      "x": -4,
      "y": 9,
      "z": -1,
      "name": "Rock_Crystal_White_Block"
    },
    {
      "x": -4,
      "y": 5,
      "z": 0,
      "name": "Rock_Crystal_White_Block"
    },
    {
      "x": -4,
      "y": 6,
      "z": 0,
      "name": "Rock_Crystal_White_Block"
    },
    {
      "x": -4,
      "y": 7,
      "z": 0,
      "name": "Rock_Crystal_White_Block"
    },
    {
      "x": -4,
      "y": 8,
      "z": 0,
      "name": "Rock_Crystal_White_Block"
    },
    {
      "x": -4,
      "y": 9,
      "z": 0,
      "name": "Rock_Crystal_White_Block"
    },
    {
      "x": -4,
      "y": 10,
      "z": 0,
      "name": "Rock_Crystal_White_Block"
    },
    {
      "x": -4,
      "y": 11,
      "z": 0,
      "name": "Rock_Crystal_White_Block"
    },
    {
      "x": -4,
      "y": 12,
      "z": 0,
      "name": "Rock_Crystal_White_Block"
    },
    {
      "x": -4,
      "y": 6,
      "z": 1,
      "name": "Rock_Crystal_White_Block",
      "rotation": 2
    },
    {
      "x": -4,
      "y": 7,
      "z": 1,
      "name": "Rock_Crystal_White_Block",
      "rotation": 2
    },
    {
      "x": -4,
      "y": 8,
      "z": 1,
      "name": "Rock_Crystal_White_Block",
      "rotation": 2
    },
    {
      "x": -4,
      "y": 9,
      "z": 1,
      "name": "Rock_Crystal_White_Block",
      "rotation": 2
    },
    {
      "x": -4,
      "y": 5,
      "z": 2,
      "name": "Rock_Crystal_White_Block",
      "rotation": 2
    },
    {
      "x": -4,
      "y": 7,
      "z": 2,
      "name": "Rock_Crystal_White_Block",
      "rotation": 2
    },
    {
      "x": -4,
      "y": 9,
      "z": 2,
      "name": "Rock_Crystal_White_Block",
      "rotation": 2
    },
    {
      "x": -4,
      "y": 8,
      "z": 3,
      "name": "Rock_Crystal_White_Block",
      "rotation": 2
    },
    {
      "x": -4,
      "y": 8,
      "z": 4,
      "name": "Rock_Crystal_White_Block",
      "rotation": 2
    },
    {
      "x": -4,
      "y": 10,
      "z": 13,
      "name": "Rock_Crystal_White_Block",
      "rotation": 2
    },
    {
      "x": -4,
      "y": 10,
      "z": 16,
      "name": "Rock_Crystal_White_Block",
      "rotation": 2
    },
    {
      "x": -3,
      "y": 9,
      "z": -17,
      "name": "Rock_Crystal_White_Block"
    },
    {
      "x": -3,
      "y": 9,
      "z": -16,
      "name": "Rock_Crystal_White_Block"
    },
    {
      "x": -3,
      "y": 10,
      "z": -16,
      "name": "Rock_Crystal_White_Block"
    },
    {
      "x": -3,
      "y": 9,
      "z": -15,
      "name": "Rock_Crystal_White_Block"
    },
    {
      "x": -3,
      "y": 10,
      "z": -15,
      "name": "Rock_Crystal_White_Block"
    },
    {
      "x": -3,
      "y": 11,
      "z": -15,
      "name": "Rock_Crystal_White_Block"
    },
    {
      "x": -3,
      "y": 9,
      "z": -14,
      "name": "Rock_Crystal_White_Block"
    },
    {
      "x": -3,
      "y": 10,
      "z": -14,
      "name": "Rock_Crystal_White_Block"
    },
    {
      "x": -3,
      "y": 11,
      "z": -14,
      "name": "Rock_Crystal_White_Block"
    },
    {
      "x": -3,
      "y": 12,
      "z": -14,
      "name": "Rock_Crystal_White_Block"
    },
    {
      "x": -3,
      "y": 9,
      "z": -13,
      "name": "Rock_Crystal_White_Block"
    },
    {
      "x": -3,
      "y": 12,
      "z": -13,
      "name": "Rock_Crystal_White_Block"
    },
    {
      "x": -3,
      "y": 10,
      "z": -12,
      "name": "Rock_Crystal_White_Block"
    },
    {
      "x": -3,
      "y": 11,
      "z": -12,
      "name": "Rock_Crystal_White_Block"
    },
    {
      "x": -3,
      "y": 13,
      "z": -12,
      "name": "Rock_Crystal_White_Block"
    },
    {
      "x": -3,
      "y": 9,
      "z": -11,
      "name": "Rock_Crystal_White_Block"
    },
    {
      "x": -3,
      "y": 13,
      "z": -11,
      "name": "Rock_Crystal_White_Block"
    },
    {
      "x": -3,
      "y": 12,
      "z": -10,
      "name": "Rock_Crystal_White_Block"
    },
    {
      "x": -3,
      "y": 14,
      "z": -10,
      "name": "Rock_Crystal_White_Block"
    },
    {
      "x": -3,
      "y": 9,
      "z": -9,
      "name": "Rock_Crystal_White_Block"
    },
    {
      "x": -3,
      "y": 10,
      "z": -9,
      "name": "Rock_Crystal_White_Block"
    },
    {
      "x": -3,
      "y": 9,
      "z": -7,
      "name": "Rock_Crystal_White_Block"
    },
    {
      "x": -3,
      "y": 10,
      "z": -7,
      "name": "Rock_Crystal_White_Block"
    },
    {
      "x": -3,
      "y": 9,
      "z": -5,
      "name": "Rock_Crystal_White_Block"
    },
    {
      "x": -3,
      "y": 9,
      "z": -4,
      "name": "Rock_Crystal_White_Block"
    },
    {
      "x": -3,
      "y": 10,
      "z": -4,
      "name": "Rock_Crystal_White_Block"
    },
    {
      "x": -3,
      "y": 10,
      "z": -3,
      "name": "Rock_Crystal_White_Block"
    },
    {
      "x": -3,
      "y": 8,
      "z": -2,
      "name": "Rock_Crystal_White_Block"
    },
    {
      "x": -3,
      "y": 10,
      "z": -2,
      "name": "Rock_Crystal_White_Block"
    },
    {
      "x": -3,
      "y": 11,
      "z": -2,
      "name": "Rock_Crystal_White_Block"
    },
    {
      "x": -3,
      "y": 8,
      "z": -1,
      "name": "Rock_Crystal_White_Block"
    },
    {
      "x": -3,
      "y": 9,
      "z": -1,
      "name": "Rock_Crystal_White_Block"
    },
    {
      "x": -3,
      "y": 12,
      "z": -1,
      "name": "Rock_Crystal_White_Block"
    },
    {
      "x": -3,
      "y": 7,
      "z": 0,
      "name": "Rock_Crystal_White_Block"
    },
    {
      "x": -3,
      "y": 8,
      "z": 0,
      "name": "Rock_Crystal_White_Block"
    },
    {
      "x": -3,
      "y": 9,
      "z": 0,
      "name": "Rock_Crystal_White_Block"
    },
    {
      "x": -3,
      "y": 10,
      "z": 0,
      "name": "Rock_Crystal_White_Block"
    },
    {
      "x": -3,
      "y": 11,
      "z": 0,
      "name": "Rock_Crystal_White_Block"
    },
    {
      "x": -3,
      "y": 12,
      "z": 0,
      "name": "Rock_Crystal_White_Block"
    },
    {
      "x": -3,
      "y": 13,
      "z": 0,
      "name": "Rock_Crystal_White_Block"
    },
    {
      "x": -3,
      "y": 14,
      "z": 0,
      "name": "Rock_Crystal_White_Block"
    },
    {
      "x": -3,
      "y": 8,
      "z": 1,
      "name": "Rock_Crystal_White_Block",
      "rotation": 2
    },
    {
      "x": -3,
      "y": 9,
      "z": 1,
      "name": "Rock_Crystal_White_Block",
      "rotation": 2
    },
    {
      "x": -3,
      "y": 12,
      "z": 1,
      "name": "Rock_Crystal_White_Block",
      "rotation": 2
    },
    {
      "x": -3,
      "y": 8,
      "z": 2,
      "name": "Rock_Crystal_White_Block",
      "rotation": 2
    },
    {
      "x": -3,
      "y": 10,
      "z": 2,
      "name": "Rock_Crystal_White_Block",
      "rotation": 2
    },
    {
      "x": -3,
      "y": 11,
      "z": 2,
      "name": "Rock_Crystal_White_Block",
      "rotation": 2
    },
    {
      "x": -3,
      "y": 10,
      "z": 3,
      "name": "Rock_Crystal_White_Block",
      "rotation": 2
    },
    {
      "x": -3,
      "y": 9,
      "z": 4,
      "name": "Rock_Crystal_White_Block",
      "rotation": 2
    },
    {
      "x": -3,
      "y": 10,
      "z": 4,
      "name": "Rock_Crystal_White_Block",
      "rotation": 2
    },
    {
      "x": -3,
      "y": 9,
      "z": 5,
      "name": "Rock_Crystal_White_Block",
      "rotation": 2
    },
    {
      "x": -3,
      "y": 9,
      "z": 7,
      "name": "Rock_Crystal_White_Block",
      "rotation": 2
    },
    {
      "x": -3,
      "y": 10,
      "z": 7,
      "name": "Rock_Crystal_White_Block",
      "rotation": 2
    },
    {
      "x": -3,
      "y": 9,
      "z": 9,
      "name": "Rock_Crystal_White_Block",
      "rotation": 2
    },
    {
      "x": -3,
      "y": 10,
      "z": 9,
      "name": "Rock_Crystal_White_Block",
      "rotation": 2
    },
    {
      "x": -3,
      "y": 12,
      "z": 10,
      "name": "Rock_Crystal_White_Block",
      "rotation": 2
    },
    {
      "x": -3,
      "y": 14,
      "z": 10,
      "name": "Rock_Crystal_White_Block",
      "rotation": 2
    },
    {
      "x": -3,
      "y": 9,
      "z": 11,
      "name": "Rock_Crystal_White_Block",
      "rotation": 2
    },
    {
      "x": -3,
      "y": 13,
      "z": 11,
      "name": "Rock_Crystal_White_Block",
      "rotation": 2
    },
    {
      "x": -3,
      "y": 10,
      "z": 12,
      "name": "Rock_Crystal_White_Block",
      "rotation": 2
    },
    {
      "x": -3,
      "y": 11,
      "z": 12,
      "name": "Rock_Crystal_White_Block",
      "rotation": 2
    },
    {
      "x": -3,
      "y": 13,
      "z": 12,
      "name": "Rock_Crystal_White_Block",
      "rotation": 2
    },
    {
      "x": -3,
      "y": 9,
      "z": 13,
      "name": "Rock_Crystal_White_Block",
      "rotation": 2
    },
    {
      "x": -3,
      "y": 12,
      "z": 13,
      "name": "Rock_Crystal_White_Block",
      "rotation": 2
    },
    {
      "x": -3,
      "y": 9,
      "z": 14,
      "name": "Rock_Crystal_White_Block",
      "rotation": 2
    },
    {
      "x": -3,
      "y": 10,
      "z": 14,
      "name": "Rock_Crystal_White_Block",
      "rotation": 2
    },
    {
      "x": -3,
      "y": 11,
      "z": 14,
      "name": "Rock_Crystal_White_Block",
      "rotation": 2
    },
    {
      "x": -3,
      "y": 12,
      "z": 14,
      "name": "Rock_Crystal_White_Block",
      "rotation": 2
    },
    {
      "x": -3,
      "y": 9,
      "z": 15,
      "name": "Rock_Crystal_White_Block",
      "rotation": 2
    },
    {
      "x": -3,
      "y": 10,
      "z": 15,
      "name": "Rock_Crystal_White_Block",
      "rotation": 2
    },
    {
      "x": -3,
      "y": 11,
      "z": 15,
      "name": "Rock_Crystal_White_Block",
      "rotation": 2
    },
    {
      "x": -3,
      "y": 9,
      "z": 16,
      "name": "Rock_Crystal_White_Block",
      "rotation": 2
    },
    {
      "x": -3,
      "y": 10,
      "z": 16,
      "name": "Rock_Crystal_White_Block",
      "rotation": 2
    },
    {
      "x": -3,
      "y": 9,
      "z": 17,
      "name": "Rock_Crystal_White_Block",
      "rotation": 2
    },
    {
      "x": -2,
      "y": 11,
      "z": -17,
      "name": "Rock_Crystal_White_Block"
    },
    {
      "x": -2,
      "y": 9,
      "z": -16,
      "name": "Rock_Crystal_White_Block"
    },
    {
      "x": -2,
      "y": 10,
      "z": -15,
      "name": "Rock_Crystal_White_Block"
    },
    {
      "x": -2,
      "y": 12,
      "z": -15,
      "name": "Rock_Crystal_White_Block"
    },
    {
      "x": -2,
      "y": 10,
      "z": -14,
      "name": "Rock_Crystal_White_Block"
    },
    {
      "x": -2,
      "y": 11,
      "z": -14,
      "name": "Rock_Crystal_White_Block"
    },
    {
      "x": -2,
      "y": 12,
      "z": -14,
      "name": "Rock_Crystal_White_Block"
    },
    {
      "x": -2,
      "y": 13,
      "z": -14,
      "name": "Rock_Crystal_White_Block"
    },
    {
      "x": -2,
      "y": 9,
      "z": -13,
      "name": "Rock_Crystal_White_Block"
    },
    {
      "x": -2,
      "y": 11,
      "z": -13,
      "name": "Rock_Crystal_White_Block"
    },
    {
      "x": -2,
      "y": 12,
      "z": -13,
      "name": "Rock_Crystal_White_Block"
    },
    {
      "x": -2,
      "y": 10,
      "z": -12,
      "name": "Rock_Crystal_White_Block"
    },
    {
      "x": -2,
      "y": 11,
      "z": -12,
      "name": "Rock_Crystal_White_Block"
    },
    {
      "x": -2,
      "y": 12,
      "z": -12,
      "name": "Rock_Crystal_White_Block"
    },
    {
      "x": -2,
      "y": 14,
      "z": -12,
      "name": "Rock_Crystal_White_Block"
    },
    {
      "x": -2,
      "y": 12,
      "z": -11,
      "name": "Rock_Crystal_White_Block"
    },
    {
      "x": -2,
      "y": 13,
      "z": -11,
      "name": "Rock_Crystal_White_Block"
    },
    {
      "x": -2,
      "y": 11,
      "z": -10,
      "name": "Rock_Crystal_White_Block"
    },
    {
      "x": -2,
      "y": 12,
      "z": -10,
      "name": "Rock_Crystal_White_Block"
    },
    {
      "x": -2,
      "y": 13,
      "z": -10,
      "name": "Rock_Crystal_White_Block"
    },
    {
      "x": -2,
      "y": 14,
      "z": -9,
      "name": "Rock_Crystal_White_Block"
    },
    {
      "x": -2,
      "y": 15,
      "z": -9,
      "name": "Rock_Crystal_White_Block"
    },
    {
      "x": -2,
      "y": 12,
      "z": -8,
      "name": "Rock_Crystal_White_Block"
    },
    {
      "x": -2,
      "y": 13,
      "z": -8,
      "name": "Rock_Crystal_White_Block"
    },
    {
      "x": -2,
      "y": 14,
      "z": -8,
      "name": "Rock_Crystal_White_Block"
    },
    {
      "x": -2,
      "y": 15,
      "z": -8,
      "name": "Rock_Crystal_White_Block"
    },
    {
      "x": -2,
      "y": 11,
      "z": -7,
      "name": "Rock_Crystal_White_Block"
    },
    {
      "x": -2,
      "y": 14,
      "z": -7,
      "name": "Rock_Crystal_White_Block"
    },
    {
      "x": -2,
      "y": 16,
      "z": -7,
      "name": "Rock_Crystal_White_Block"
    },
    {
      "x": -2,
      "y": 12,
      "z": -6,
      "name": "Rock_Crystal_White_Block"
    },
    {
      "x": -2,
      "y": 13,
      "z": -6,
      "name": "Rock_Crystal_White_Block"
    },
    {
      "x": -2,
      "y": 11,
      "z": -5,
      "name": "Rock_Crystal_White_Block"
    },
    {
      "x": -2,
      "y": 14,
      "z": -4,
      "name": "Rock_Crystal_White_Block"
    },
    {
      "x": -2,
      "y": 12,
      "z": -3,
      "name": "Rock_Crystal_White_Block"
    },
    {
      "x": -2,
      "y": 10,
      "z": -2,
      "name": "Rock_Crystal_White_Block"
    },
    {
      "x": -2,
      "y": 11,
      "z": -2,
      "name": "Rock_Crystal_White_Block"
    },
    {
      "x": -2,
      "y": 11,
      "z": -1,
      "name": "Rock_Crystal_White_Block"
    },
    {
      "x": -2,
      "y": 12,
      "z": -1,
      "name": "Rock_Crystal_White_Block"
    },
    {
      "x": -2,
      "y": 13,
      "z": -1,
      "name": "Rock_Crystal_White_Block"
    },
    {
      "x": -2,
      "y": 7,
      "z": 0,
      "name": "Rock_Crystal_White_Block"
    },
    {
      "x": -2,
      "y": 8,
      "z": 0,
      "name": "Rock_Crystal_White_Block"
    },
    {
      "x": -2,
      "y": 9,
      "z": 0,
      "name": "Rock_Crystal_White_Block"
    },
    {
      "x": -2,
      "y": 10,
      "z": 0,
      "name": "Rock_Crystal_White_Block"
    },
    {
      "x": -2,
      "y": 11,
      "z": 0,
      "name": "Rock_Crystal_White_Block"
    },
    {
      "x": -2,
      "y": 12,
      "z": 0,
      "name": "Rock_Crystal_White_Block"
    },
    {
      "x": -2,
      "y": 13,
      "z": 0,
      "name": "Rock_Crystal_White_Block"
    },
    {
      "x": -2,
      "y": 14,
      "z": 0,
      "name": "Rock_Crystal_White_Block"
    },
    {
      "x": -2,
      "y": 15,
      "z": 0,
      "name": "Rock_Crystal_White_Block"
    },
    {
      "x": -2,
      "y": 16,
      "z": 0,
      "name": "Rock_Crystal_White_Block"
    },
    {
      "x": -2,
      "y": 11,
      "z": 1,
      "name": "Rock_Crystal_White_Block",
      "rotation": 2
    },
    {
      "x": -2,
      "y": 12,
      "z": 1,
      "name": "Rock_Crystal_White_Block",
      "rotation": 2
    },
    {
      "x": -2,
      "y": 13,
      "z": 1,
      "name": "Rock_Crystal_White_Block",
      "rotation": 2
    },
    {
      "x": -2,
      "y": 10,
      "z": 2,
      "name": "Rock_Crystal_White_Block",
      "rotation": 2
    },
    {
      "x": -2,
      "y": 11,
      "z": 2,
      "name": "Rock_Crystal_White_Block",
      "rotation": 2
    },
    {
      "x": -2,
      "y": 12,
      "z": 3,
      "name": "Rock_Crystal_White_Block",
      "rotation": 2
    },
    {
      "x": -2,
      "y": 14,
      "z": 4,
      "name": "Rock_Crystal_White_Block",
      "rotation": 2
    },
    {
      "x": -2,
      "y": 11,
      "z": 5,
      "name": "Rock_Crystal_White_Block",
      "rotation": 2
    },
    {
      "x": -2,
      "y": 12,
      "z": 6,
      "name": "Rock_Crystal_White_Block",
      "rotation": 2
    },
    {
      "x": -2,
      "y": 13,
      "z": 6,
      "name": "Rock_Crystal_White_Block",
      "rotation": 2
    },
    {
      "x": -2,
      "y": 11,
      "z": 7,
      "name": "Rock_Crystal_White_Block",
      "rotation": 2
    },
    {
      "x": -2,
      "y": 14,
      "z": 7,
      "name": "Rock_Crystal_White_Block",
      "rotation": 2
    },
    {
      "x": -2,
      "y": 16,
      "z": 7,
      "name": "Rock_Crystal_White_Block",
      "rotation": 2
    },
    {
      "x": -2,
      "y": 12,
      "z": 8,
      "name": "Rock_Crystal_White_Block",
      "rotation": 2
    },
    {
      "x": -2,
      "y": 13,
      "z": 8,
      "name": "Rock_Crystal_White_Block",
      "rotation": 2
    },
    {
      "x": -2,
      "y": 14,
      "z": 8,
      "name": "Rock_Crystal_White_Block",
      "rotation": 2
    },
    {
      "x": -2,
      "y": 15,
      "z": 8,
      "name": "Rock_Crystal_White_Block",
      "rotation": 2
    },
    {
      "x": -2,
      "y": 14,
      "z": 9,
      "name": "Rock_Crystal_White_Block",
      "rotation": 2
    },
    {
      "x": -2,
      "y": 15,
      "z": 9,
      "name": "Rock_Crystal_White_Block",
      "rotation": 2
    },
    {
      "x": -2,
      "y": 11,
      "z": 10,
      "name": "Rock_Crystal_White_Block",
      "rotation": 2
    },
    {
      "x": -2,
      "y": 12,
      "z": 10,
      "name": "Rock_Crystal_White_Block",
      "rotation": 2
    },
    {
      "x": -2,
      "y": 13,
      "z": 10,
      "name": "Rock_Crystal_White_Block",
      "rotation": 2
    },
    {
      "x": -2,
      "y": 12,
      "z": 11,
      "name": "Rock_Crystal_White_Block",
      "rotation": 2
    },
    {
      "x": -2,
      "y": 13,
      "z": 11,
      "name": "Rock_Crystal_White_Block",
      "rotation": 2
    },
    {
      "x": -2,
      "y": 10,
      "z": 12,
      "name": "Rock_Crystal_White_Block",
      "rotation": 2
    },
    {
      "x": -2,
      "y": 11,
      "z": 12,
      "name": "Rock_Crystal_White_Block",
      "rotation": 2
    },
    {
      "x": -2,
      "y": 12,
      "z": 12,
      "name": "Rock_Crystal_White_Block",
      "rotation": 2
    },
    {
      "x": -2,
      "y": 14,
      "z": 12,
      "name": "Rock_Crystal_White_Block",
      "rotation": 2
    },
    {
      "x": -2,
      "y": 9,
      "z": 13,
      "name": "Rock_Crystal_White_Block",
      "rotation": 2
    },
    {
      "x": -2,
      "y": 11,
      "z": 13,
      "name": "Rock_Crystal_White_Block",
      "rotation": 2
    },
    {
      "x": -2,
      "y": 12,
      "z": 13,
      "name": "Rock_Crystal_White_Block",
      "rotation": 2
    },
    {
      "x": -2,
      "y": 10,
      "z": 14,
      "name": "Rock_Crystal_White_Block",
      "rotation": 2
    },
    {
      "x": -2,
      "y": 11,
      "z": 14,
      "name": "Rock_Crystal_White_Block",
      "rotation": 2
    },
    {
      "x": -2,
      "y": 12,
      "z": 14,
      "name": "Rock_Crystal_White_Block",
      "rotation": 2
    },
    {
      "x": -2,
      "y": 13,
      "z": 14,
      "name": "Rock_Crystal_White_Block",
      "rotation": 2
    },
    {
      "x": -2,
      "y": 10,
      "z": 15,
      "name": "Rock_Crystal_White_Block",
      "rotation": 2
    },
    {
      "x": -2,
      "y": 12,
      "z": 15,
      "name": "Rock_Crystal_White_Block",
      "rotation": 2
    },
    {
      "x": -2,
      "y": 9,
      "z": 16,
      "name": "Rock_Crystal_White_Block",
      "rotation": 2
    },
    {
      "x": -2,
      "y": 11,
      "z": 17,
      "name": "Rock_Crystal_White_Block",
      "rotation": 2
    },
    {
      "x": -1,
      "y": 13,
      "z": -16,
      "name": "Rock_Crystal_White_Block"
    },
    {
      "x": -1,
      "y": 12,
      "z": -15,
      "name": "Rock_Crystal_White_Block"
    },
    {
      "x": -1,
      "y": 10,
      "z": -14,
      "name": "Rock_Crystal_White_Block"
    },
    {
      "x": -1,
      "y": 11,
      "z": -14,
      "name": "Rock_Crystal_White_Block"
    },
    {
      "x": -1,
      "y": 12,
      "z": -14,
      "name": "Rock_Crystal_White_Block"
    },
    {
      "x": -1,
      "y": 13,
      "z": -14,
      "name": "Rock_Crystal_White_Block"
    },
    {
      "x": -1,
      "y": 10,
      "z": -13,
      "name": "Rock_Crystal_White_Block"
    },
    {
      "x": -1,
      "y": 11,
      "z": -13,
      "name": "Rock_Crystal_White_Block"
    },
    {
      "x": -1,
      "y": 12,
      "z": -13,
      "name": "Rock_Crystal_White_Block"
    },
    {
      "x": -1,
      "y": 12,
      "z": -12,
      "name": "Rock_Crystal_White_Block"
    },
    {
      "x": -1,
      "y": 13,
      "z": -12,
      "name": "Rock_Crystal_White_Block"
    },
    {
      "x": -1,
      "y": 14,
      "z": -12,
      "name": "Rock_Crystal_White_Block"
    },
    {
      "x": -1,
      "y": 12,
      "z": -11,
      "name": "Rock_Crystal_White_Block"
    },
    {
      "x": -1,
      "y": 13,
      "z": -11,
      "name": "Rock_Crystal_White_Block"
    },
    {
      "x": -1,
      "y": 10,
      "z": -10,
      "name": "Rock_Crystal_White_Block"
    },
    {
      "x": -1,
      "y": 11,
      "z": -10,
      "name": "Rock_Crystal_White_Block"
    },
    {
      "x": -1,
      "y": 12,
      "z": -10,
      "name": "Rock_Crystal_White_Block"
    },
    {
      "x": -1,
      "y": 13,
      "z": -10,
      "name": "Rock_Crystal_White_Block"
    },
    {
      "x": -1,
      "y": 15,
      "z": -10,
      "name": "Rock_Crystal_White_Block"
    },
    {
      "x": -1,
      "y": 13,
      "z": -9,
      "name": "Rock_Crystal_White_Block"
    },
    {
      "x": -1,
      "y": 14,
      "z": -9,
      "name": "Rock_Crystal_White_Block"
    },
    {
      "x": -1,
      "y": 12,
      "z": -8,
      "name": "Rock_Crystal_White_Block"
    },
    {
      "x": -1,
      "y": 13,
      "z": -8,
      "name": "Rock_Crystal_White_Block"
    },
    {
      "x": -1,
      "y": 14,
      "z": -8,
      "name": "Rock_Crystal_White_Block"
    },
    {
      "x": -1,
      "y": 14,
      "z": -7,
      "name": "Rock_Crystal_White_Block"
    },
    {
      "x": -1,
      "y": 15,
      "z": -7,
      "name": "Rock_Crystal_White_Block"
    },
    {
      "x": -1,
      "y": 12,
      "z": -6,
      "name": "Rock_Crystal_White_Block"
    },
    {
      "x": -1,
      "y": 13,
      "z": -6,
      "name": "Rock_Crystal_White_Block"
    },
    {
      "x": -1,
      "y": 16,
      "z": -6,
      "name": "Rock_Crystal_White_Block"
    },
    {
      "x": -1,
      "y": 15,
      "z": -5,
      "name": "Rock_Crystal_White_Block"
    },
    {
      "x": -1,
      "y": 16,
      "z": -5,
      "name": "Rock_Crystal_White_Block"
    },
    {
      "x": -1,
      "y": 13,
      "z": -4,
      "name": "Rock_Crystal_White_Block"
    },
    {
      "x": -1,
      "y": 14,
      "z": -4,
      "name": "Rock_Crystal_White_Block"
    },
    {
      "x": -1,
      "y": 17,
      "z": -4,
      "name": "Rock_Crystal_White_Block"
    },
    {
      "x": -1,
      "y": 12,
      "z": -3,
      "name": "Rock_Crystal_White_Block"
    },
    {
      "x": -1,
      "y": 13,
      "z": -2,
      "name": "Rock_Crystal_White_Block"
    },
    {
      "x": -1,
      "y": 10,
      "z": -1,
      "name": "Rock_Crystal_White_Block"
    },
    {
      "x": -1,
      "y": 11,
      "z": -1,
      "name": "Rock_Crystal_White_Block"
    },
    {
      "x": -1,
      "y": 12,
      "z": -1,
      "name": "Rock_Crystal_White_Block"
    },
    {
      "x": -1,
      "y": 13,
      "z": -1,
      "name": "Rock_Crystal_White_Block"
    },
    {
      "x": -1,
      "y": 15,
      "z": -1,
      "name": "Rock_Crystal_White_Block"
    },
    {
      "x": -1,
      "y": 17,
      "z": -1,
      "name": "Rock_Crystal_White_Block"
    },
    {
      "x": -1,
      "y": 8,
      "z": 0,
      "name": "Rock_Crystal_White_Block"
    },
    {
      "x": -1,
      "y": 9,
      "z": 0,
      "name": "Rock_Crystal_White_Block"
    },
    {
      "x": -1,
      "y": 10,
      "z": 0,
      "name": "Rock_Crystal_White_Block"
    },
    {
      "x": -1,
      "y": 11,
      "z": 0,
      "name": "Rock_Crystal_White_Block"
    },
    {
      "x": -1,
      "y": 12,
      "z": 0,
      "name": "Rock_Crystal_White_Block"
    },
    {
      "x": -1,
      "y": 13,
      "z": 0,
      "name": "Rock_Crystal_White_Block"
    },
    {
      "x": -1,
      "y": 14,
      "z": 0,
      "name": "Rock_Crystal_White_Block"
    },
    {
      "x": -1,
      "y": 15,
      "z": 0,
      "name": "Rock_Crystal_White_Block"
    },
    {
      "x": -1,
      "y": 16,
      "z": 0,
      "name": "Rock_Crystal_White_Block"
    },
    {
      "x": -1,
      "y": 17,
      "z": 0,
      "name": "Rock_Crystal_White_Block"
    },
    {
      "x": -1,
      "y": 19,
      "z": 0,
      "name": "Rock_Crystal_White_Block"
    },
    {
      "x": -1,
      "y": 10,
      "z": 1,
      "name": "Rock_Crystal_White_Block",
      "rotation": 2
    },
    {
      "x": -1,
      "y": 11,
      "z": 1,
      "name": "Rock_Crystal_White_Block",
      "rotation": 2
    },
    {
      "x": -1,
      "y": 12,
      "z": 1,
      "name": "Rock_Crystal_White_Block",
      "rotation": 2
    },
    {
      "x": -1,
      "y": 13,
      "z": 1,
      "name": "Rock_Crystal_White_Block",
      "rotation": 2
    },
    {
      "x": -1,
      "y": 15,
      "z": 1,
      "name": "Rock_Crystal_White_Block",
      "rotation": 2
    },
    {
      "x": -1,
      "y": 17,
      "z": 1,
      "name": "Rock_Crystal_White_Block"
    },
    {
      "x": -1,
      "y": 13,
      "z": 2,
      "name": "Rock_Crystal_White_Block",
      "rotation": 2
    },
    {
      "x": -1,
      "y": 12,
      "z": 3,
      "name": "Rock_Crystal_White_Block",
      "rotation": 2
    },
    {
      "x": -1,
      "y": 13,
      "z": 4,
      "name": "Rock_Crystal_White_Block",
      "rotation": 2
    },
    {
      "x": -1,
      "y": 14,
      "z": 4,
      "name": "Rock_Crystal_White_Block",
      "rotation": 2
    },
    {
      "x": -1,
      "y": 17,
      "z": 4,
      "name": "Rock_Crystal_White_Block",
      "rotation": 2
    },
    {
      "x": -1,
      "y": 15,
      "z": 5,
      "name": "Rock_Crystal_White_Block",
      "rotation": 2
    },
    {
      "x": -1,
      "y": 16,
      "z": 5,
      "name": "Rock_Crystal_White_Block",
      "rotation": 2
    },
    {
      "x": -1,
      "y": 12,
      "z": 6,
      "name": "Rock_Crystal_White_Block",
      "rotation": 2
    },
    {
      "x": -1,
      "y": 13,
      "z": 6,
      "name": "Rock_Crystal_White_Block",
      "rotation": 2
    },
    {
      "x": -1,
      "y": 16,
      "z": 6,
      "name": "Rock_Crystal_White_Block",
      "rotation": 2
    },
    {
      "x": -1,
      "y": 14,
      "z": 7,
      "name": "Rock_Crystal_White_Block",
      "rotation": 2
    },
    {
      "x": -1,
      "y": 15,
      "z": 7,
      "name": "Rock_Crystal_White_Block",
      "rotation": 2
    },
    {
      "x": -1,
      "y": 12,
      "z": 8,
      "name": "Rock_Crystal_White_Block",
      "rotation": 2
    },
    {
      "x": -1,
      "y": 13,
      "z": 8,
      "name": "Rock_Crystal_White_Block",
      "rotation": 2
    },
    {
      "x": -1,
      "y": 14,
      "z": 8,
      "name": "Rock_Crystal_White_Block",
      "rotation": 2
    },
    {
      "x": -1,
      "y": 13,
      "z": 9,
      "name": "Rock_Crystal_White_Block",
      "rotation": 2
    },
    {
      "x": -1,
      "y": 14,
      "z": 9,
      "name": "Rock_Crystal_White_Block",
      "rotation": 2
    },
    {
      "x": -1,
      "y": 10,
      "z": 10,
      "name": "Rock_Crystal_White_Block",
      "rotation": 2
    },
    {
      "x": -1,
      "y": 11,
      "z": 10,
      "name": "Rock_Crystal_White_Block",
      "rotation": 2
    },
    {
      "x": -1,
      "y": 12,
      "z": 10,
      "name": "Rock_Crystal_White_Block",
      "rotation": 2
    },
    {
      "x": -1,
      "y": 13,
      "z": 10,
      "name": "Rock_Crystal_White_Block",
      "rotation": 2
    },
    {
      "x": -1,
      "y": 15,
      "z": 10,
      "name": "Rock_Crystal_White_Block",
      "rotation": 2
    },
    {
      "x": -1,
      "y": 12,
      "z": 11,
      "name": "Rock_Crystal_White_Block",
      "rotation": 2
    },
    {
      "x": -1,
      "y": 13,
      "z": 11,
      "name": "Rock_Crystal_White_Block",
      "rotation": 2
    },
    {
      "x": -1,
      "y": 12,
      "z": 12,
      "name": "Rock_Crystal_White_Block",
      "rotation": 2
    },
    {
      "x": -1,
      "y": 13,
      "z": 12,
      "name": "Rock_Crystal_White_Block",
      "rotation": 2
    },
    {
      "x": -1,
      "y": 14,
      "z": 12,
      "name": "Rock_Crystal_White_Block",
      "rotation": 2
    },
    {
      "x": -1,
      "y": 10,
      "z": 13,
      "name": "Rock_Crystal_White_Block",
      "rotation": 2
    },
    {
      "x": -1,
      "y": 11,
      "z": 13,
      "name": "Rock_Crystal_White_Block",
      "rotation": 2
    },
    {
      "x": -1,
      "y": 12,
      "z": 13,
      "name": "Rock_Crystal_White_Block",
      "rotation": 2
    },
    {
      "x": -1,
      "y": 10,
      "z": 14,
      "name": "Rock_Crystal_White_Block",
      "rotation": 2
    },
    {
      "x": -1,
      "y": 11,
      "z": 14,
      "name": "Rock_Crystal_White_Block",
      "rotation": 2
    },
    {
      "x": -1,
      "y": 12,
      "z": 14,
      "name": "Rock_Crystal_White_Block",
      "rotation": 2
    },
    {
      "x": -1,
      "y": 13,
      "z": 14,
      "name": "Rock_Crystal_White_Block",
      "rotation": 2
    },
    {
      "x": -1,
      "y": 12,
      "z": 15,
      "name": "Rock_Crystal_White_Block",
      "rotation": 2
    },
    {
      "x": -1,
      "y": 13,
      "z": 16,
      "name": "Rock_Crystal_White_Block",
      "rotation": 2
    },
    {
      "x": 0,
      "y": 14,
      "z": -15,
      "name": "Rock_Crystal_White_Block"
    },
    {
      "x": 0,
      "y": 15,
      "z": -15,
      "name": "Rock_Crystal_White_Block"
    },
    {
      "x": 0,
      "y": 12,
      "z": -14,
      "name": "Rock_Crystal_White_Block"
    },
    {
      "x": 0,
      "y": 14,
      "z": -13,
      "name": "Rock_Crystal_White_Block"
    },
    {
      "x": 0,
      "y": 15,
      "z": -13,
      "name": "Rock_Crystal_White_Block"
    },
    {
      "x": 0,
      "y": 11,
      "z": -12,
      "name": "Rock_Crystal_White_Block"
    },
    {
      "x": 0,
      "y": 13,
      "z": -12,
      "name": "Rock_Crystal_White_Block"
    },
    {
      "x": 0,
      "y": 11,
      "z": -11,
      "name": "Rock_Crystal_White_Block"
    },
    {
      "x": 0,
      "y": 12,
      "z": -11,
      "name": "Rock_Crystal_White_Block"
    },
    {
      "x": 0,
      "y": 16,
      "z": -11,
      "name": "Rock_Crystal_White_Block"
    },
    {
      "x": 0,
      "y": 12,
      "z": -10,
      "name": "Rock_Crystal_White_Block"
    },
    {
      "x": 0,
      "y": 14,
      "z": -10,
      "name": "Rock_Crystal_White_Block"
    },
    {
      "x": 0,
      "y": 15,
      "z": -10,
      "name": "Rock_Crystal_White_Block"
    },
    {
      "x": 0,
      "y": 13,
      "z": -9,
      "name": "Rock_Crystal_White_Block"
    },
    {
      "x": 0,
      "y": 14,
      "z": -9,
      "name": "Rock_Crystal_White_Block"
    },
    {
      "x": 0,
      "y": 15,
      "z": -9,
      "name": "Rock_Crystal_White_Block"
    },
    {
      "x": 0,
      "y": 17,
      "z": -9,
      "name": "Rock_Crystal_White_Block"
    },
    {
      "x": 0,
      "y": 12,
      "z": -8,
      "name": "Rock_Crystal_White_Block"
    },
    {
      "x": 0,
      "y": 13,
      "z": -8,
      "name": "Rock_Crystal_White_Block"
    },
    {
      "x": 0,
      "y": 14,
      "z": -8,
      "name": "Rock_Crystal_White_Block"
    },
    {
      "x": 0,
      "y": 15,
      "z": -8,
      "name": "Rock_Crystal_White_Block"
    },
    {
      "x": 0,
      "y": 16,
      "z": -8,
      "name": "Rock_Crystal_White_Block"
    },
    {
      "x": 0,
      "y": 13,
      "z": -7,
      "name": "Rock_Crystal_White_Block"
    },
    {
      "x": 0,
      "y": 14,
      "z": -7,
      "name": "Rock_Crystal_White_Block"
    },
    {
      "x": 0,
      "y": 15,
      "z": -7,
      "name": "Rock_Crystal_White_Block"
    },
    {
      "x": 0,
      "y": 12,
      "z": -6,
      "name": "Rock_Crystal_White_Block"
    },
    {
      "x": 0,
      "y": 14,
      "z": -6,
      "name": "Rock_Crystal_White_Block"
    },
    {
      "x": 0,
      "y": 15,
      "z": -6,
      "name": "Rock_Crystal_White_Block"
    },
    {
      "x": 0,
      "y": 16,
      "z": -6,
      "name": "Rock_Crystal_White_Block"
    },
    {
      "x": 0,
      "y": 17,
      "z": -6,
      "name": "Rock_Crystal_White_Block"
    },
    {
      "x": 0,
      "y": 14,
      "z": -5,
      "name": "Rock_Crystal_White_Block"
    },
    {
      "x": 0,
      "y": 15,
      "z": -5,
      "name": "Rock_Crystal_White_Block"
    },
    {
      "x": 0,
      "y": 16,
      "z": -5,
      "name": "Rock_Crystal_White_Block"
    },
    {
      "x": 0,
      "y": 13,
      "z": -4,
      "name": "Rock_Crystal_White_Block"
    },
    {
      "x": 0,
      "y": 17,
      "z": -4,
      "name": "Rock_Crystal_White_Block"
    },
    {
      "x": 0,
      "y": 16,
      "z": -3,
      "name": "Rock_Crystal_White_Block"
    },
    {
      "x": 0,
      "y": 18,
      "z": -3,
      "name": "Rock_Crystal_White_Block"
    },
    {
      "x": 0,
      "y": 14,
      "z": -2,
      "name": "Rock_Crystal_White_Block"
    },
    {
      "x": 0,
      "y": 15,
      "z": -2,
      "name": "Rock_Crystal_White_Block"
    },
    {
      "x": 0,
      "y": 17,
      "z": -2,
      "name": "Rock_Crystal_White_Block"
    },
    {
      "x": 0,
      "y": 18,
      "z": -2,
      "name": "Rock_Crystal_White_Block"
    },
    {
      "x": 0,
      "y": 19,
      "z": -2,
      "name": "Rock_Crystal_White_Block"
    },
    {
      "x": 0,
      "y": 12,
      "z": -1,
      "name": "Rock_Crystal_White_Block"
    },
    {
      "x": 0,
      "y": 14,
      "z": -1,
      "name": "Rock_Crystal_White_Block"
    },
    {
      "x": 0,
      "y": 15,
      "z": -1,
      "name": "Rock_Crystal_White_Block"
    },
    {
      "x": 0,
      "y": 16,
      "z": -1,
      "name": "Rock_Crystal_White_Block"
    },
    {
      "x": 0,
      "y": 17,
      "z": -1,
      "name": "Rock_Crystal_White_Block"
    },
    {
      "x": 0,
      "y": 18,
      "z": -1,
      "name": "Rock_Crystal_White_Block"
    },
    {
      "x": 0,
      "y": 19,
      "z": -1,
      "name": "Rock_Crystal_White_Block"
    },
    {
      "x": 0,
      "y": 10,
      "z": 0,
      "name": "Rock_Crystal_White_Block"
    },
    {
      "x": 0,
      "y": 11,
      "z": 0,
      "name": "Rock_Crystal_White_Block"
    },
    {
      "x": 0,
      "y": 12,
      "z": 0,
      "name": "Rock_Crystal_White_Block"
    },
    {
      "x": 0,
      "y": 13,
      "z": 0,
      "name": "Rock_Crystal_White_Block"
    },
    {
      "x": 0,
      "y": 14,
      "z": 0,
      "name": "Rock_Crystal_White_Block"
    },
    {
      "x": 0,
      "y": 15,
      "z": 0,
      "name": "Rock_Crystal_White_Block"
    },
    {
      "x": 0,
      "y": 16,
      "z": 0,
      "name": "Rock_Crystal_White_Block"
    },
    {
      "x": 0,
      "y": 17,
      "z": 0,
      "name": "Rock_Crystal_White_Block"
    },
    {
      "x": 0,
      "y": 18,
      "z": 0,
      "name": "Rock_Crystal_White_Block"
    },
    {
      "x": 0,
      "y": 19,
      "z": 0,
      "name": "Rock_Crystal_White_Block"
    },
    {
      "x": 0,
      "y": 20,
      "z": 0,
      "name": "Rock_Crystal_White_Block",
      "rotation": 2
    },
    {
      "x": 0,
      "y": 12,
      "z": 1,
      "name": "Rock_Crystal_White_Block",
      "rotation": 2
    },
    {
      "x": 0,
      "y": 14,
      "z": 1,
      "name": "Rock_Crystal_White_Block",
      "rotation": 2
    },
    {
      "x": 0,
      "y": 15,
      "z": 1,
      "name": "Rock_Crystal_White_Block",
      "rotation": 2
    },
    {
      "x": 0,
      "y": 16,
      "z": 1,
      "name": "Rock_Crystal_White_Block"
    },
    {
      "x": 0,
      "y": 17,
      "z": 1,
      "name": "Rock_Crystal_White_Block",
      "rotation": 2
    },
    {
      "x": 0,
      "y": 18,
      "z": 1,
      "name": "Rock_Crystal_White_Block",
      "rotation": 2
    },
    {
      "x": 0,
      "y": 19,
      "z": 1,
      "name": "Rock_Crystal_White_Block",
      "rotation": 2
    },
    {
      "x": 0,
      "y": 14,
      "z": 2,
      "name": "Rock_Crystal_White_Block",
      "rotation": 2
    },
    {
      "x": 0,
      "y": 15,
      "z": 2,
      "name": "Rock_Crystal_White_Block",
      "rotation": 2
    },
    {
      "x": 0,
      "y": 17,
      "z": 2,
      "name": "Rock_Crystal_White_Block"
    },
    {
      "x": 0,
      "y": 18,
      "z": 2,
      "name": "Rock_Crystal_White_Block",
      "rotation": 2
    },
    {
      "x": 0,
      "y": 19,
      "z": 2,
      "name": "Rock_Crystal_White_Block"
    },
    {
      "x": 0,
      "y": 16,
      "z": 3,
      "name": "Rock_Crystal_White_Block",
      "rotation": 2
    },
    {
      "x": 0,
      "y": 18,
      "z": 3,
      "name": "Rock_Crystal_White_Block",
      "rotation": 2
    },
    {
      "x": 0,
      "y": 13,
      "z": 4,
      "name": "Rock_Crystal_White_Block",
      "rotation": 2
    },
    {
      "x": 0,
      "y": 17,
      "z": 4,
      "name": "Rock_Crystal_White_Block",
      "rotation": 2
    },
    {
      "x": 0,
      "y": 14,
      "z": 5,
      "name": "Rock_Crystal_White_Block",
      "rotation": 2
    },
    {
      "x": 0,
      "y": 15,
      "z": 5,
      "name": "Rock_Crystal_White_Block",
      "rotation": 2
    },
    {
      "x": 0,
      "y": 16,
      "z": 5,
      "name": "Rock_Crystal_White_Block",
      "rotation": 2
    },
    {
      "x": 0,
      "y": 12,
      "z": 6,
      "name": "Rock_Crystal_White_Block",
      "rotation": 2
    },
    {
      "x": 0,
      "y": 14,
      "z": 6,
      "name": "Rock_Crystal_White_Block",
      "rotation": 2
    },
    {
      "x": 0,
      "y": 15,
      "z": 6,
      "name": "Rock_Crystal_White_Block",
      "rotation": 2
    },
    {
      "x": 0,
      "y": 16,
      "z": 6,
      "name": "Rock_Crystal_White_Block",
      "rotation": 2
    },
    {
      "x": 0,
      "y": 17,
      "z": 6,
      "name": "Rock_Crystal_White_Block",
      "rotation": 2
    },
    {
      "x": 0,
      "y": 13,
      "z": 7,
      "name": "Rock_Crystal_White_Block",
      "rotation": 2
    },
    {
      "x": 0,
      "y": 14,
      "z": 7,
      "name": "Rock_Crystal_White_Block",
      "rotation": 2
    },
    {
      "x": 0,
      "y": 15,
      "z": 7,
      "name": "Rock_Crystal_White_Block",
      "rotation": 2
    },
    {
      "x": 0,
      "y": 12,
      "z": 8,
      "name": "Rock_Crystal_White_Block",
      "rotation": 2
    },
    {
      "x": 0,
      "y": 13,
      "z": 8,
      "name": "Rock_Crystal_White_Block",
      "rotation": 2
    },
    {
      "x": 0,
      "y": 14,
      "z": 8,
      "name": "Rock_Crystal_White_Block",
      "rotation": 2
    },
    {
      "x": 0,
      "y": 15,
      "z": 8,
      "name": "Rock_Crystal_White_Block",
      "rotation": 2
    },
    {
      "x": 0,
      "y": 16,
      "z": 8,
      "name": "Rock_Crystal_White_Block",
      "rotation": 2
    },
    {
      "x": 0,
      "y": 13,
      "z": 9,
      "name": "Rock_Crystal_White_Block",
      "rotation": 2
    },
    {
      "x": 0,
      "y": 14,
      "z": 9,
      "name": "Rock_Crystal_White_Block",
      "rotation": 2
    },
    {
      "x": 0,
      "y": 15,
      "z": 9,
      "name": "Rock_Crystal_White_Block",
      "rotation": 2
    },
    {
      "x": 0,
      "y": 17,
      "z": 9,
      "name": "Rock_Crystal_White_Block",
      "rotation": 2
    },
    {
      "x": 0,
      "y": 12,
      "z": 10,
      "name": "Rock_Crystal_White_Block",
      "rotation": 2
    },
    {
      "x": 0,
      "y": 14,
      "z": 10,
      "name": "Rock_Crystal_White_Block",
      "rotation": 2
    },
    {
      "x": 0,
      "y": 15,
      "z": 10,
      "name": "Rock_Crystal_White_Block",
      "rotation": 2
    },
    {
      "x": 0,
      "y": 11,
      "z": 11,
      "name": "Rock_Crystal_White_Block",
      "rotation": 2
    },
    {
      "x": 0,
      "y": 12,
      "z": 11,
      "name": "Rock_Crystal_White_Block",
      "rotation": 2
    },
    {
      "x": 0,
      "y": 16,
      "z": 11,
      "name": "Rock_Crystal_White_Block",
      "rotation": 2
    },
    {
      "x": 0,
      "y": 11,
      "z": 12,
      "name": "Rock_Crystal_White_Block",
      "rotation": 2
    },
    {
      "x": 0,
      "y": 13,
      "z": 12,
      "name": "Rock_Crystal_White_Block",
      "rotation": 2
    },
    {
      "x": 0,
      "y": 14,
      "z": 13,
      "name": "Rock_Crystal_White_Block",
      "rotation": 2
    },
    {
      "x": 0,
      "y": 15,
      "z": 13,
      "name": "Rock_Crystal_White_Block",
      "rotation": 2
    },
    {
      "x": 0,
      "y": 12,
      "z": 14,
      "name": "Rock_Crystal_White_Block",
      "rotation": 2
    },
    {
      "x": 0,
      "y": 14,
      "z": 15,
      "name": "Rock_Crystal_White_Block",
      "rotation": 2
    },
    {
      "x": 0,
      "y": 15,
      "z": 15,
      "name": "Rock_Crystal_White_Block",
      "rotation": 2
    },
    {
      "x": 1,
      "y": 16,
      "z": -14,
      "name": "Rock_Crystal_White_Block"
    },
    {
      "x": 1,
      "y": 17,
      "z": -12,
      "name": "Rock_Crystal_White_Block"
    },
    {
      "x": 1,
      "y": 15,
      "z": -11,
      "name": "Rock_Crystal_White_Block"
    },
    {
      "x": 1,
      "y": 16,
      "z": -11,
      "name": "Rock_Crystal_White_Block"
    },
    {
      "x": 1,
      "y": 12,
      "z": -10,
      "name": "Rock_Crystal_White_Block"
    },
    {
      "x": 1,
      "y": 14,
      "z": -10,
      "name": "Rock_Crystal_White_Block"
    },
    {
      "x": 1,
      "y": 17,
      "z": -10,
      "name": "Rock_Crystal_White_Block"
    },
    {
      "x": 1,
      "y": 13,
      "z": -9,
      "name": "Rock_Crystal_White_Block"
    },
    {
      "x": 1,
      "y": 16,
      "z": -9,
      "name": "Rock_Crystal_White_Block"
    },
    {
      "x": 1,
      "y": 13,
      "z": -8,
      "name": "Rock_Crystal_White_Block"
    },
    {
      "x": 1,
      "y": 15,
      "z": -8,
      "name": "Rock_Crystal_White_Block"
    },
    {
      "x": 1,
      "y": 17,
      "z": -8,
      "name": "Rock_Crystal_White_Block"
    },
    {
      "x": 1,
      "y": 14,
      "z": -7,
      "name": "Rock_Crystal_White_Block"
    },
    {
      "x": 1,
      "y": 16,
      "z": -7,
      "name": "Rock_Crystal_White_Block"
    },
    {
      "x": 1,
      "y": 17,
      "z": -7,
      "name": "Rock_Crystal_White_Block"
    },
    {
      "x": 1,
      "y": 15,
      "z": -6,
      "name": "Rock_Crystal_White_Block"
    },
    {
      "x": 1,
      "y": 16,
      "z": -6,
      "name": "Rock_Crystal_White_Block"
    },
    {
      "x": 1,
      "y": 14,
      "z": -5,
      "name": "Rock_Crystal_White_Block"
    },
    {
      "x": 1,
      "y": 15,
      "z": -5,
      "name": "Rock_Crystal_White_Block"
    },
    {
      "x": 1,
      "y": 16,
      "z": -5,
      "name": "Rock_Crystal_White_Block"
    },
    {
      "x": 1,
      "y": 17,
      "z": -5,
      "name": "Rock_Crystal_White_Block"
    },
    {
      "x": 1,
      "y": 18,
      "z": -5,
      "name": "Rock_Crystal_White_Block"
    },
    {
      "x": 1,
      "y": 16,
      "z": -4,
      "name": "Rock_Crystal_White_Block"
    },
    {
      "x": 1,
      "y": 17,
      "z": -4,
      "name": "Rock_Crystal_White_Block"
    },
    {
      "x": 1,
      "y": 19,
      "z": -4,
      "name": "Rock_Crystal_White_Block"
    },
    {
      "x": 1,
      "y": 21,
      "z": -4,
      "name": "Rock_Crystal_White_Block"
    },
    {
      "x": 1,
      "y": 15,
      "z": -3,
      "name": "Rock_Crystal_White_Block"
    },
    {
      "x": 1,
      "y": 16,
      "z": -3,
      "name": "Rock_Crystal_White_Block"
    },
    {
      "x": 1,
      "y": 17,
      "z": -3,
      "name": "Rock_Crystal_White_Block"
    },
    {
      "x": 1,
      "y": 18,
      "z": -3,
      "name": "Rock_Crystal_White_Block"
    },
    {
      "x": 1,
      "y": 20,
      "z": -3,
      "name": "Rock_Crystal_White_Block"
    },
    {
      "x": 1,
      "y": 16,
      "z": -2,
      "name": "Rock_Crystal_White_Block"
    },
    {
      "x": 1,
      "y": 17,
      "z": -2,
      "name": "Rock_Crystal_White_Block"
    },
    {
      "x": 1,
      "y": 18,
      "z": -2,
      "name": "Rock_Crystal_White_Block"
    },
    {
      "x": 1,
      "y": 19,
      "z": -2,
      "name": "Rock_Crystal_White_Block"
    },
    {
      "x": 1,
      "y": 20,
      "z": -2,
      "name": "Rock_Crystal_White_Block"
    },
    {
      "x": 1,
      "y": 14,
      "z": -1,
      "name": "Rock_Crystal_White_Block"
    },
    {
      "x": 1,
      "y": 15,
      "z": -1,
      "name": "Rock_Crystal_White_Block"
    },
    {
      "x": 1,
      "y": 16,
      "z": -1,
      "name": "Rock_Crystal_White_Block"
    },
    {
      "x": 1,
      "y": 17,
      "z": -1,
      "name": "Rock_Crystal_White_Block"
    },
    {
      "x": 1,
      "y": 18,
      "z": -1,
      "name": "Rock_Crystal_White_Block"
    },
    {
      "x": 1,
      "y": 19,
      "z": -1,
      "name": "Rock_Crystal_White_Block"
    },
    {
      "x": 1,
      "y": 20,
      "z": -1,
      "name": "Rock_Crystal_White_Block"
    },
    {
      "x": 1,
      "y": 21,
      "z": -1,
      "name": "Rock_Crystal_White_Block"
    },
    {
      "x": 1,
      "y": 12,
      "z": 0,
      "name": "Rock_Crystal_White_Block"
    },
    {
      "x": 1,
      "y": 13,
      "z": 0,
      "name": "Rock_Crystal_White_Block"
    },
    {
      "x": 1,
      "y": 14,
      "z": 0,
      "name": "Rock_Crystal_White_Block"
    },
    {
      "x": 1,
      "y": 15,
      "z": 0,
      "name": "Rock_Crystal_White_Block"
    },
    {
      "x": 1,
      "y": 16,
      "z": 0,
      "name": "Rock_Crystal_White_Block"
    },
    {
      "x": 1,
      "y": 17,
      "z": 0,
      "name": "Rock_Crystal_White_Block"
    },
    {
      "x": 1,
      "y": 18,
      "z": 0,
      "name": "Rock_Crystal_White_Block"
    },
    {
      "x": 1,
      "y": 19,
      "z": 0,
      "name": "Rock_Crystal_White_Block"
    },
    {
      "x": 1,
      "y": 20,
      "z": 0,
      "name": "Rock_Crystal_White_Block",
      "rotation": 2
    },
    {
      "x": 1,
      "y": 21,
      "z": 0,
      "name": "Rock_Crystal_White_Block",
      "rotation": 2
    },
    {
      "x": 1,
      "y": 14,
      "z": 1,
      "name": "Rock_Crystal_White_Block",
      "rotation": 2
    },
    {
      "x": 1,
      "y": 15,
      "z": 1,
      "name": "Rock_Crystal_White_Block"
    },
    {
      "x": 1,
      "y": 16,
      "z": 1,
      "name": "Rock_Crystal_White_Block",
      "rotation": 2
    },
    {
      "x": 1,
      "y": 17,
      "z": 1,
      "name": "Rock_Crystal_White_Block",
      "rotation": 2
    },
    {
      "x": 1,
      "y": 18,
      "z": 1,
      "name": "Rock_Crystal_White_Block",
      "rotation": 2
    },
    {
      "x": 1,
      "y": 19,
      "z": 1,
      "name": "Rock_Crystal_White_Block",
      "rotation": 2
    },
    {
      "x": 1,
      "y": 20,
      "z": 1,
      "name": "Rock_Crystal_White_Block",
      "rotation": 2
    },
    {
      "x": 1,
      "y": 21,
      "z": 1,
      "name": "Rock_Crystal_White_Block"
    },
    {
      "x": 1,
      "y": 16,
      "z": 2,
      "name": "Rock_Crystal_White_Block",
      "rotation": 2
    },
    {
      "x": 1,
      "y": 17,
      "z": 2,
      "name": "Rock_Crystal_White_Block",
      "rotation": 2
    },
    {
      "x": 1,
      "y": 18,
      "z": 2,
      "name": "Rock_Crystal_White_Block",
      "rotation": 2
    },
    {
      "x": 1,
      "y": 19,
      "z": 2,
      "name": "Rock_Crystal_White_Block",
      "rotation": 2
    },
    {
      "x": 1,
      "y": 20,
      "z": 2,
      "name": "Rock_Crystal_White_Block",
      "rotation": 2
    },
    {
      "x": 1,
      "y": 15,
      "z": 3,
      "name": "Rock_Crystal_White_Block",
      "rotation": 2
    },
    {
      "x": 1,
      "y": 16,
      "z": 3,
      "name": "Rock_Crystal_White_Block",
      "rotation": 2
    },
    {
      "x": 1,
      "y": 17,
      "z": 3,
      "name": "Rock_Crystal_White_Block",
      "rotation": 2
    },
    {
      "x": 1,
      "y": 18,
      "z": 3,
      "name": "Rock_Crystal_White_Block",
      "rotation": 2
    },
    {
      "x": 1,
      "y": 20,
      "z": 3,
      "name": "Rock_Crystal_White_Block",
      "rotation": 2
    },
    {
      "x": 1,
      "y": 16,
      "z": 4,
      "name": "Rock_Crystal_White_Block",
      "rotation": 2
    },
    {
      "x": 1,
      "y": 17,
      "z": 4,
      "name": "Rock_Crystal_White_Block",
      "rotation": 2
    },
    {
      "x": 1,
      "y": 19,
      "z": 4,
      "name": "Rock_Crystal_White_Block",
      "rotation": 2
    },
    {
      "x": 1,
      "y": 21,
      "z": 4,
      "name": "Rock_Crystal_White_Block",
      "rotation": 2
    },
    {
      "x": 1,
      "y": 14,
      "z": 5,
      "name": "Rock_Crystal_White_Block",
      "rotation": 2
    },
    {
      "x": 1,
      "y": 15,
      "z": 5,
      "name": "Rock_Crystal_White_Block",
      "rotation": 2
    },
    {
      "x": 1,
      "y": 16,
      "z": 5,
      "name": "Rock_Crystal_White_Block",
      "rotation": 2
    },
    {
      "x": 1,
      "y": 17,
      "z": 5,
      "name": "Rock_Crystal_White_Block",
      "rotation": 2
    },
    {
      "x": 1,
      "y": 18,
      "z": 5,
      "name": "Rock_Crystal_White_Block",
      "rotation": 2
    },
    {
      "x": 1,
      "y": 15,
      "z": 6,
      "name": "Rock_Crystal_White_Block",
      "rotation": 2
    },
    {
      "x": 1,
      "y": 16,
      "z": 6,
      "name": "Rock_Crystal_White_Block",
      "rotation": 2
    },
    {
      "x": 1,
      "y": 14,
      "z": 7,
      "name": "Rock_Crystal_White_Block",
      "rotation": 2
    },
    {
      "x": 1,
      "y": 16,
      "z": 7,
      "name": "Rock_Crystal_White_Block",
      "rotation": 2
    },
    {
      "x": 1,
      "y": 17,
      "z": 7,
      "name": "Rock_Crystal_White_Block",
      "rotation": 2
    },
    {
      "x": 1,
      "y": 13,
      "z": 8,
      "name": "Rock_Crystal_White_Block",
      "rotation": 2
    },
    {
      "x": 1,
      "y": 15,
      "z": 8,
      "name": "Rock_Crystal_White_Block",
      "rotation": 2
    },
    {
      "x": 1,
      "y": 17,
      "z": 8,
      "name": "Rock_Crystal_White_Block",
      "rotation": 2
    },
    {
      "x": 1,
      "y": 13,
      "z": 9,
      "name": "Rock_Crystal_White_Block",
      "rotation": 2
    },
    {
      "x": 1,
      "y": 16,
      "z": 9,
      "name": "Rock_Crystal_White_Block",
      "rotation": 2
    },
    {
      "x": 1,
      "y": 12,
      "z": 10,
      "name": "Rock_Crystal_White_Block",
      "rotation": 2
    },
    {
      "x": 1,
      "y": 14,
      "z": 10,
      "name": "Rock_Crystal_White_Block",
      "rotation": 2
    },
    {
      "x": 1,
      "y": 17,
      "z": 10,
      "name": "Rock_Crystal_White_Block",
      "rotation": 2
    },
    {
      "x": 1,
      "y": 15,
      "z": 11,
      "name": "Rock_Crystal_White_Block",
      "rotation": 2
    },
    {
      "x": 1,
      "y": 16,
      "z": 11,
      "name": "Rock_Crystal_White_Block",
      "rotation": 2
    },
    {
      "x": 1,
      "y": 17,
      "z": 12,
      "name": "Rock_Crystal_White_Block",
      "rotation": 2
    },
    {
      "x": 1,
      "y": 16,
      "z": 14,
      "name": "Rock_Crystal_White_Block",
      "rotation": 2
    },
    {
      "x": 2,
      "y": 16,
      "z": -9,
      "name": "Rock_Crystal_White_Block"
    },
    {
      "x": 2,
      "y": 18,
      "z": -9,
      "name": "Rock_Crystal_White_Block"
    },
    {
      "x": 2,
      "y": 20,
      "z": -9,
      "name": "Rock_Crystal_White_Block"
    },
    {
      "x": 2,
      "y": 14,
      "z": -6,
      "name": "Rock_Crystal_White_Block"
    },
    {
      "x": 2,
      "y": 15,
      "z": -6,
      "name": "Rock_Crystal_White_Block"
    },
    {
      "x": 2,
      "y": 16,
      "z": -6,
      "name": "Rock_Crystal_White_Block"
    },
    {
      "x": 2,
      "y": 18,
      "z": -6,
      "name": "Rock_Crystal_White_Block"
    },
    {
      "x": 2,
      "y": 20,
      "z": -6,
      "name": "Rock_Crystal_White_Block"
    },
    {
      "x": 2,
      "y": 21,
      "z": -6,
      "name": "Rock_Crystal_White_Block"
    },
    {
      "x": 2,
      "y": 22,
      "z": -6,
      "name": "Rock_Crystal_White_Block"
    },
    {
      "x": 2,
      "y": 14,
      "z": -5,
      "name": "Rock_Crystal_White_Block"
    },
    {
      "x": 2,
      "y": 15,
      "z": -5,
      "name": "Rock_Crystal_White_Block"
    },
    {
      "x": 2,
      "y": 17,
      "z": -5,
      "name": "Rock_Crystal_White_Block"
    },
    {
      "x": 2,
      "y": 19,
      "z": -5,
      "name": "Rock_Crystal_White_Block"
    },
    {
      "x": 2,
      "y": 21,
      "z": -5,
      "name": "Rock_Crystal_White_Block"
    },
    {
      "x": 2,
      "y": 22,
      "z": -5,
      "name": "Rock_Crystal_White_Block"
    },
    {
      "x": 2,
      "y": 16,
      "z": -4,
      "name": "Rock_Crystal_White_Block"
    },
    {
      "x": 2,
      "y": 18,
      "z": -4,
      "name": "Rock_Crystal_White_Block"
    },
    {
      "x": 2,
      "y": 20,
      "z": -4,
      "name": "Rock_Crystal_White_Block"
    },
    {
      "x": 2,
      "y": 17,
      "z": -3,
      "name": "Rock_Crystal_White_Block"
    },
    {
      "x": 2,
      "y": 19,
      "z": -3,
      "name": "Rock_Crystal_White_Block"
    },
    {
      "x": 2,
      "y": 16,
      "z": -2,
      "name": "Rock_Crystal_White_Block"
    },
    {
      "x": 2,
      "y": 17,
      "z": -2,
      "name": "Rock_Crystal_White_Block"
    },
    {
      "x": 2,
      "y": 18,
      "z": -2,
      "name": "Rock_Crystal_White_Block"
    },
    {
      "x": 2,
      "y": 19,
      "z": -2,
      "name": "Rock_Crystal_White_Block"
    },
    {
      "x": 2,
      "y": 20,
      "z": -2,
      "name": "Rock_Crystal_White_Block"
    },
    {
      "x": 2,
      "y": 16,
      "z": -1,
      "name": "Rock_Crystal_White_Block"
    },
    {
      "x": 2,
      "y": 17,
      "z": -1,
      "name": "Rock_Crystal_White_Block"
    },
    {
      "x": 2,
      "y": 18,
      "z": -1,
      "name": "Rock_Crystal_White_Block"
    },
    {
      "x": 2,
      "y": 19,
      "z": -1,
      "name": "Rock_Crystal_White_Block"
    },
    {
      "x": 2,
      "y": 20,
      "z": -1,
      "name": "Rock_Crystal_White_Block"
    },
    {
      "x": 2,
      "y": 14,
      "z": 0,
      "name": "Rock_Crystal_White_Block"
    },
    {
      "x": 2,
      "y": 15,
      "z": 0,
      "name": "Rock_Crystal_White_Block"
    },
    {
      "x": 2,
      "y": 16,
      "z": 0,
      "name": "Rock_Crystal_White_Block"
    },
    {
      "x": 2,
      "y": 17,
      "z": 0,
      "name": "Rock_Crystal_White_Block"
    },
    {
      "x": 2,
      "y": 18,
      "z": 0,
      "name": "Rock_Crystal_White_Block"
    },
    {
      "x": 2,
      "y": 19,
      "z": 0,
      "name": "Rock_Crystal_White_Block",
      "rotation": 2
    },
    {
      "x": 2,
      "y": 20,
      "z": 0,
      "name": "Rock_Crystal_White_Block",
      "rotation": 2
    },
    {
      "x": 2,
      "y": 21,
      "z": 0,
      "name": "Rock_Crystal_White_Block",
      "rotation": 2
    },
    {
      "x": 2,
      "y": 22,
      "z": 0,
      "name": "Rock_Crystal_White_Block",
      "rotation": 2
    },
    {
      "x": 2,
      "y": 16,
      "z": 1,
      "name": "Rock_Crystal_White_Block",
      "rotation": 2
    },
    {
      "x": 2,
      "y": 17,
      "z": 1,
      "name": "Rock_Crystal_White_Block",
      "rotation": 2
    },
    {
      "x": 2,
      "y": 18,
      "z": 1,
      "name": "Rock_Crystal_White_Block",
      "rotation": 2
    },
    {
      "x": 2,
      "y": 19,
      "z": 1,
      "name": "Rock_Crystal_White_Block",
      "rotation": 2
    },
    {
      "x": 2,
      "y": 20,
      "z": 1,
      "name": "Rock_Crystal_White_Block",
      "rotation": 2
    },
    {
      "x": 2,
      "y": 16,
      "z": 2,
      "name": "Rock_Crystal_White_Block"
    },
    {
      "x": 2,
      "y": 17,
      "z": 2,
      "name": "Rock_Crystal_White_Block",
      "rotation": 2
    },
    {
      "x": 2,
      "y": 18,
      "z": 2,
      "name": "Rock_Crystal_White_Block",
      "rotation": 2
    },
    {
      "x": 2,
      "y": 19,
      "z": 2,
      "name": "Rock_Crystal_White_Block",
      "rotation": 2
    },
    {
      "x": 2,
      "y": 20,
      "z": 2,
      "name": "Rock_Crystal_White_Block"
    },
    {
      "x": 2,
      "y": 17,
      "z": 3,
      "name": "Rock_Crystal_White_Block",
      "rotation": 2
    },
    {
      "x": 2,
      "y": 19,
      "z": 3,
      "name": "Rock_Crystal_White_Block",
      "rotation": 2
    },
    {
      "x": 2,
      "y": 16,
      "z": 4,
      "name": "Rock_Crystal_White_Block",
      "rotation": 2
    },
    {
      "x": 2,
      "y": 18,
      "z": 4,
      "name": "Rock_Crystal_White_Block",
      "rotation": 2
    },
    {
      "x": 2,
      "y": 20,
      "z": 4,
      "name": "Rock_Crystal_White_Block",
      "rotation": 2
    },
    {
      "x": 2,
      "y": 14,
      "z": 5,
      "name": "Rock_Crystal_White_Block",
      "rotation": 2
    },
    {
      "x": 2,
      "y": 15,
      "z": 5,
      "name": "Rock_Crystal_White_Block",
      "rotation": 2
    },
    {
      "x": 2,
      "y": 17,
      "z": 5,
      "name": "Rock_Crystal_White_Block",
      "rotation": 2
    },
    {
      "x": 2,
      "y": 19,
      "z": 5,
      "name": "Rock_Crystal_White_Block",
      "rotation": 2
    },
    {
      "x": 2,
      "y": 21,
      "z": 5,
      "name": "Rock_Crystal_White_Block",
      "rotation": 2
    },
    {
      "x": 2,
      "y": 22,
      "z": 5,
      "name": "Rock_Crystal_White_Block",
      "rotation": 2
    },
    {
      "x": 2,
      "y": 14,
      "z": 6,
      "name": "Rock_Crystal_White_Block",
      "rotation": 2
    },
    {
      "x": 2,
      "y": 15,
      "z": 6,
      "name": "Rock_Crystal_White_Block",
      "rotation": 2
    },
    {
      "x": 2,
      "y": 16,
      "z": 6,
      "name": "Rock_Crystal_White_Block",
      "rotation": 2
    },
    {
      "x": 2,
      "y": 18,
      "z": 6,
      "name": "Rock_Crystal_White_Block",
      "rotation": 2
    },
    {
      "x": 2,
      "y": 20,
      "z": 6,
      "name": "Rock_Crystal_White_Block",
      "rotation": 2
    },
    {
      "x": 2,
      "y": 21,
      "z": 6,
      "name": "Rock_Crystal_White_Block",
      "rotation": 2
    },
    {
      "x": 2,
      "y": 22,
      "z": 6,
      "name": "Rock_Crystal_White_Block",
      "rotation": 2
    },
    {
      "x": 2,
      "y": 16,
      "z": 9,
      "name": "Rock_Crystal_White_Block",
      "rotation": 2
    },
    {
      "x": 2,
      "y": 18,
      "z": 9,
      "name": "Rock_Crystal_White_Block",
      "rotation": 2
    },
    {
      "x": 2,
      "y": 20,
      "z": 9,
      "name": "Rock_Crystal_White_Block",
      "rotation": 2
    },
    {
      "x": 3,
      "y": 20,
      "z": -14,
      "name": "Rock_Crystal_White_Block"
    },
    {
      "x": 3,
      "y": 19,
      "z": -12,
      "name": "Rock_Crystal_White_Block"
    },
    {
      "x": 3,
      "y": 20,
      "z": -11,
      "name": "Rock_Crystal_White_Block"
    },
    {
      "x": 3,
      "y": 21,
      "z": -11,
      "name": "Rock_Crystal_White_Block"
    },
    {
      "x": 3,
      "y": 19,
      "z": -10,
      "name": "Rock_Crystal_White_Block"
    },
    {
      "x": 3,
      "y": 22,
      "z": -10,
      "name": "Rock_Crystal_White_Block"
    },
    {
      "x": 3,
      "y": 24,
      "z": -10,
      "name": "Rock_Crystal_White_Block"
    },
    {
      "x": 3,
      "y": 20,
      "z": -9,
      "name": "Rock_Crystal_White_Block"
    },
    {
      "x": 3,
      "y": 23,
      "z": -9,
      "name": "Rock_Crystal_White_Block"
    },
    {
      "x": 3,
      "y": 19,
      "z": -8,
      "name": "Rock_Crystal_White_Block"
    },
    {
      "x": 3,
      "y": 21,
      "z": -8,
      "name": "Rock_Crystal_White_Block"
    },
    {
      "x": 3,
      "y": 23,
      "z": -8,
      "name": "Rock_Crystal_White_Block"
    },
    {
      "x": 3,
      "y": 19,
      "z": -7,
      "name": "Rock_Crystal_White_Block"
    },
    {
      "x": 3,
      "y": 20,
      "z": -7,
      "name": "Rock_Crystal_White_Block"
    },
    {
      "x": 3,
      "y": 22,
      "z": -7,
      "name": "Rock_Crystal_White_Block"
    },
    {
      "x": 3,
      "y": 20,
      "z": -6,
      "name": "Rock_Crystal_White_Block"
    },
    {
      "x": 3,
      "y": 21,
      "z": -6,
      "name": "Rock_Crystal_White_Block"
    },
    {
      "x": 3,
      "y": 18,
      "z": -5,
      "name": "Rock_Crystal_White_Block"
    },
    {
      "x": 3,
      "y": 19,
      "z": -5,
      "name": "Rock_Crystal_White_Block"
    },
    {
      "x": 3,
      "y": 20,
      "z": -5,
      "name": "Rock_Crystal_White_Block"
    },
    {
      "x": 3,
      "y": 21,
      "z": -5,
      "name": "Rock_Crystal_White_Block"
    },
    {
      "x": 3,
      "y": 22,
      "z": -5,
      "name": "Rock_Crystal_White_Block"
    },
    {
      "x": 3,
      "y": 15,
      "z": -4,
      "name": "Rock_Crystal_White_Block"
    },
    {
      "x": 3,
      "y": 17,
      "z": -4,
      "name": "Rock_Crystal_White_Block"
    },
    {
      "x": 3,
      "y": 19,
      "z": -4,
      "name": "Rock_Crystal_White_Block"
    },
    {
      "x": 3,
      "y": 20,
      "z": -4,
      "name": "Rock_Crystal_White_Block"
    },
    {
      "x": 3,
      "y": 16,
      "z": -3,
      "name": "Rock_Crystal_White_Block"
    },
    {
      "x": 3,
      "y": 18,
      "z": -3,
      "name": "Rock_Crystal_White_Block"
    },
    {
      "x": 3,
      "y": 19,
      "z": -3,
      "name": "Rock_Crystal_White_Block"
    },
    {
      "x": 3,
      "y": 20,
      "z": -3,
      "name": "Rock_Crystal_White_Block"
    },
    {
      "x": 3,
      "y": 21,
      "z": -3,
      "name": "Rock_Crystal_White_Block"
    },
    {
      "x": 3,
      "y": 16,
      "z": -2,
      "name": "Rock_Crystal_White_Block"
    },
    {
      "x": 3,
      "y": 17,
      "z": -2,
      "name": "Rock_Crystal_White_Block"
    },
    {
      "x": 3,
      "y": 18,
      "z": -2,
      "name": "Rock_Crystal_White_Block"
    },
    {
      "x": 3,
      "y": 19,
      "z": -2,
      "name": "Rock_Crystal_White_Block"
    },
    {
      "x": 3,
      "y": 20,
      "z": -2,
      "name": "Rock_Crystal_White_Block"
    },
    {
      "x": 3,
      "y": 15,
      "z": -1,
      "name": "Rock_Crystal_White_Block"
    },
    {
      "x": 3,
      "y": 16,
      "z": -1,
      "name": "Rock_Crystal_White_Block"
    },
    {
      "x": 3,
      "y": 17,
      "z": -1,
      "name": "Rock_Crystal_White_Block"
    },
    {
      "x": 3,
      "y": 18,
      "z": -1,
      "name": "Rock_Crystal_White_Block"
    },
    {
      "x": 3,
      "y": 19,
      "z": -1,
      "name": "Rock_Crystal_White_Block"
    },
    {
      "x": 3,
      "y": 20,
      "z": -1,
      "name": "Rock_Crystal_White_Block"
    },
    {
      "x": 3,
      "y": 21,
      "z": -1,
      "name": "Rock_Crystal_White_Block"
    },
    {
      "x": 3,
      "y": 22,
      "z": -1,
      "name": "Rock_Crystal_White_Block"
    },
    {
      "x": 3,
      "y": 15,
      "z": 0,
      "name": "Rock_Crystal_White_Block"
    },
    {
      "x": 3,
      "y": 16,
      "z": 0,
      "name": "Rock_Crystal_White_Block"
    },
    {
      "x": 3,
      "y": 17,
      "z": 0,
      "name": "Rock_Crystal_White_Block"
    },
    {
      "x": 3,
      "y": 18,
      "z": 0,
      "name": "Rock_Crystal_White_Block",
      "rotation": 2
    },
    {
      "x": 3,
      "y": 19,
      "z": 0,
      "name": "Rock_Crystal_White_Block",
      "rotation": 2
    },
    {
      "x": 3,
      "y": 20,
      "z": 0,
      "name": "Rock_Crystal_White_Block",
      "rotation": 2
    },
    {
      "x": 3,
      "y": 21,
      "z": 0,
      "name": "Rock_Crystal_White_Block",
      "rotation": 2
    },
    {
      "x": 3,
      "y": 22,
      "z": 0,
      "name": "Rock_Crystal_White_Block",
      "rotation": 2
    },
    {
      "x": 3,
      "y": 23,
      "z": 0,
      "name": "Rock_Crystal_White_Block",
      "rotation": 2
    },
    {
      "x": 3,
      "y": 24,
      "z": 0,
      "name": "Rock_Crystal_White_Block",
      "rotation": 2
    },
    {
      "x": 3,
      "y": 15,
      "z": 1,
      "name": "Rock_Crystal_White_Block"
    },
    {
      "x": 3,
      "y": 16,
      "z": 1,
      "name": "Rock_Crystal_White_Block",
      "rotation": 2
    },
    {
      "x": 3,
      "y": 17,
      "z": 1,
      "name": "Rock_Crystal_White_Block",
      "rotation": 2
    },
    {
      "x": 3,
      "y": 18,
      "z": 1,
      "name": "Rock_Crystal_White_Block",
      "rotation": 2
    },
    {
      "x": 3,
      "y": 19,
      "z": 1,
      "name": "Rock_Crystal_White_Block",
      "rotation": 2
    },
    {
      "x": 3,
      "y": 20,
      "z": 1,
      "name": "Rock_Crystal_White_Block",
      "rotation": 2
    },
    {
      "x": 3,
      "y": 21,
      "z": 1,
      "name": "Rock_Crystal_White_Block"
    },
    {
      "x": 3,
      "y": 22,
      "z": 1,
      "name": "Rock_Crystal_White_Block",
      "rotation": 2
    },
    {
      "x": 3,
      "y": 16,
      "z": 2,
      "name": "Rock_Crystal_White_Block",
      "rotation": 2
    },
    {
      "x": 3,
      "y": 17,
      "z": 2,
      "name": "Rock_Crystal_White_Block",
      "rotation": 2
    },
    {
      "x": 3,
      "y": 18,
      "z": 2,
      "name": "Rock_Crystal_White_Block",
      "rotation": 2
    },
    {
      "x": 3,
      "y": 19,
      "z": 2,
      "name": "Rock_Crystal_White_Block",
      "rotation": 2
    },
    {
      "x": 3,
      "y": 20,
      "z": 2,
      "name": "Rock_Crystal_White_Block",
      "rotation": 2
    },
    {
      "x": 3,
      "y": 16,
      "z": 3,
      "name": "Rock_Crystal_White_Block",
      "rotation": 2
    },
    {
      "x": 3,
      "y": 18,
      "z": 3,
      "name": "Rock_Crystal_White_Block",
      "rotation": 2
    },
    {
      "x": 3,
      "y": 19,
      "z": 3,
      "name": "Rock_Crystal_White_Block",
      "rotation": 2
    },
    {
      "x": 3,
      "y": 20,
      "z": 3,
      "name": "Rock_Crystal_White_Block",
      "rotation": 2
    },
    {
      "x": 3,
      "y": 21,
      "z": 3,
      "name": "Rock_Crystal_White_Block",
      "rotation": 2
    },
    {
      "x": 3,
      "y": 15,
      "z": 4,
      "name": "Rock_Crystal_White_Block",
      "rotation": 2
    },
    {
      "x": 3,
      "y": 17,
      "z": 4,
      "name": "Rock_Crystal_White_Block"
    },
    {
      "x": 3,
      "y": 19,
      "z": 4,
      "name": "Rock_Crystal_White_Block",
      "rotation": 2
    },
    {
      "x": 3,
      "y": 20,
      "z": 4,
      "name": "Rock_Crystal_White_Block",
      "rotation": 2
    },
    {
      "x": 3,
      "y": 18,
      "z": 5,
      "name": "Rock_Crystal_White_Block",
      "rotation": 2
    },
    {
      "x": 3,
      "y": 19,
      "z": 5,
      "name": "Rock_Crystal_White_Block",
      "rotation": 2
    },
    {
      "x": 3,
      "y": 20,
      "z": 5,
      "name": "Rock_Crystal_White_Block",
      "rotation": 2
    },
    {
      "x": 3,
      "y": 21,
      "z": 5,
      "name": "Rock_Crystal_White_Block",
      "rotation": 2
    },
    {
      "x": 3,
      "y": 22,
      "z": 5,
      "name": "Rock_Crystal_White_Block",
      "rotation": 2
    },
    {
      "x": 3,
      "y": 20,
      "z": 6,
      "name": "Rock_Crystal_White_Block",
      "rotation": 2
    },
    {
      "x": 3,
      "y": 21,
      "z": 6,
      "name": "Rock_Crystal_White_Block",
      "rotation": 2
    },
    {
      "x": 3,
      "y": 19,
      "z": 7,
      "name": "Rock_Crystal_White_Block",
      "rotation": 2
    },
    {
      "x": 3,
      "y": 20,
      "z": 7,
      "name": "Rock_Crystal_White_Block",
      "rotation": 2
    },
    {
      "x": 3,
      "y": 22,
      "z": 7,
      "name": "Rock_Crystal_White_Block",
      "rotation": 2
    },
    {
      "x": 3,
      "y": 19,
      "z": 8,
      "name": "Rock_Crystal_White_Block",
      "rotation": 2
    },
    {
      "x": 3,
      "y": 21,
      "z": 8,
      "name": "Rock_Crystal_White_Block",
      "rotation": 2
    },
    {
      "x": 3,
      "y": 23,
      "z": 8,
      "name": "Rock_Crystal_White_Block",
      "rotation": 2
    },
    {
      "x": 3,
      "y": 20,
      "z": 9,
      "name": "Rock_Crystal_White_Block",
      "rotation": 2
    },
    {
      "x": 3,
      "y": 23,
      "z": 9,
      "name": "Rock_Crystal_White_Block",
      "rotation": 2
    },
    {
      "x": 3,
      "y": 19,
      "z": 10,
      "name": "Rock_Crystal_White_Block",
      "rotation": 2
    },
    {
      "x": 3,
      "y": 22,
      "z": 10,
      "name": "Rock_Crystal_White_Block",
      "rotation": 2
    },
    {
      "x": 3,
      "y": 24,
      "z": 10,
      "name": "Rock_Crystal_White_Block",
      "rotation": 2
    },
    {
      "x": 3,
      "y": 20,
      "z": 11,
      "name": "Rock_Crystal_White_Block",
      "rotation": 2
    },
    {
      "x": 3,
      "y": 21,
      "z": 11,
      "name": "Rock_Crystal_White_Block",
      "rotation": 2
    },
    {
      "x": 3,
      "y": 19,
      "z": 12,
      "name": "Rock_Crystal_White_Block",
      "rotation": 2
    },
    {
      "x": 3,
      "y": 20,
      "z": 14,
      "name": "Rock_Crystal_White_Block",
      "rotation": 2
    },
    {
      "x": 4,
      "y": 21,
      "z": -15,
      "name": "Rock_Crystal_White_Block"
    },
    {
      "x": 4,
      "y": 22,
      "z": -15,
      "name": "Rock_Crystal_White_Block"
    },
    {
      "x": 4,
      "y": 24,
      "z": -14,
      "name": "Rock_Crystal_White_Block"
    },
    {
      "x": 4,
      "y": 21,
      "z": -13,
      "name": "Rock_Crystal_White_Block"
    },
    {
      "x": 4,
      "y": 22,
      "z": -13,
      "name": "Rock_Crystal_White_Block"
    },
    {
      "x": 4,
      "y": 23,
      "z": -12,
      "name": "Rock_Crystal_White_Block"
    },
    {
      "x": 4,
      "y": 25,
      "z": -12,
      "name": "Rock_Crystal_White_Block"
    },
    {
      "x": 4,
      "y": 20,
      "z": -11,
      "name": "Rock_Crystal_White_Block"
    },
    {
      "x": 4,
      "y": 24,
      "z": -11,
      "name": "Rock_Crystal_White_Block"
    },
    {
      "x": 4,
      "y": 25,
      "z": -11,
      "name": "Rock_Crystal_White_Block"
    },
    {
      "x": 4,
      "y": 21,
      "z": -10,
      "name": "Rock_Crystal_White_Block"
    },
    {
      "x": 4,
      "y": 22,
      "z": -10,
      "name": "Rock_Crystal_White_Block"
    },
    {
      "x": 4,
      "y": 24,
      "z": -10,
      "name": "Rock_Crystal_White_Block"
    },
    {
      "x": 4,
      "y": 19,
      "z": -9,
      "name": "Rock_Crystal_White_Block"
    },
    {
      "x": 4,
      "y": 21,
      "z": -9,
      "name": "Rock_Crystal_White_Block"
    },
    {
      "x": 4,
      "y": 22,
      "z": -9,
      "name": "Rock_Crystal_White_Block"
    },
    {
      "x": 4,
      "y": 23,
      "z": -9,
      "name": "Rock_Crystal_White_Block"
    },
    {
      "x": 4,
      "y": 20,
      "z": -8,
      "name": "Rock_Crystal_White_Block"
    },
    {
      "x": 4,
      "y": 21,
      "z": -8,
      "name": "Rock_Crystal_White_Block"
    },
    {
      "x": 4,
      "y": 22,
      "z": -8,
      "name": "Rock_Crystal_White_Block"
    },
    {
      "x": 4,
      "y": 23,
      "z": -8,
      "name": "Rock_Crystal_White_Block"
    },
    {
      "x": 4,
      "y": 24,
      "z": -8,
      "name": "Rock_Crystal_White_Block"
    },
    {
      "x": 4,
      "y": 21,
      "z": -7,
      "name": "Rock_Crystal_White_Block"
    },
    {
      "x": 4,
      "y": 22,
      "z": -7,
      "name": "Rock_Crystal_White_Block"
    },
    {
      "x": 4,
      "y": 23,
      "z": -7,
      "name": "Rock_Crystal_White_Block"
    },
    {
      "x": 4,
      "y": 19,
      "z": -6,
      "name": "Rock_Crystal_White_Block"
    },
    {
      "x": 4,
      "y": 20,
      "z": -6,
      "name": "Rock_Crystal_White_Block"
    },
    {
      "x": 4,
      "y": 21,
      "z": -6,
      "name": "Rock_Crystal_White_Block"
    },
    {
      "x": 4,
      "y": 22,
      "z": -6,
      "name": "Rock_Crystal_White_Block"
    },
    {
      "x": 4,
      "y": 24,
      "z": -6,
      "name": "Rock_Crystal_White_Block"
    },
    {
      "x": 4,
      "y": 20,
      "z": -5,
      "name": "Rock_Crystal_White_Block"
    },
    {
      "x": 4,
      "y": 21,
      "z": -5,
      "name": "Rock_Crystal_White_Block"
    },
    {
      "x": 4,
      "y": 22,
      "z": -5,
      "name": "Rock_Crystal_White_Block"
    },
    {
      "x": 4,
      "y": 19,
      "z": -4,
      "name": "Rock_Crystal_White_Block"
    },
    {
      "x": 4,
      "y": 23,
      "z": -4,
      "name": "Rock_Crystal_White_Block"
    },
    {
      "x": 4,
      "y": 18,
      "z": -3,
      "name": "Rock_Crystal_White_Block"
    },
    {
      "x": 4,
      "y": 20,
      "z": -3,
      "name": "Rock_Crystal_White_Block"
    },
    {
      "x": 4,
      "y": 17,
      "z": -2,
      "name": "Rock_Crystal_White_Block"
    },
    {
      "x": 4,
      "y": 18,
      "z": -2,
      "name": "Rock_Crystal_White_Block"
    },
    {
      "x": 4,
      "y": 19,
      "z": -2,
      "name": "Rock_Crystal_White_Block"
    },
    {
      "x": 4,
      "y": 21,
      "z": -2,
      "name": "Rock_Crystal_White_Block"
    },
    {
      "x": 4,
      "y": 22,
      "z": -2,
      "name": "Rock_Crystal_White_Block"
    },
    {
      "x": 4,
      "y": 17,
      "z": -1,
      "name": "Rock_Crystal_White_Block"
    },
    {
      "x": 4,
      "y": 18,
      "z": -1,
      "name": "Rock_Crystal_White_Block"
    },
    {
      "x": 4,
      "y": 19,
      "z": -1,
      "name": "Rock_Crystal_White_Block"
    },
    {
      "x": 4,
      "y": 20,
      "z": -1,
      "name": "Rock_Crystal_White_Block"
    },
    {
      "x": 4,
      "y": 21,
      "z": -1,
      "name": "Rock_Crystal_White_Block"
    },
    {
      "x": 4,
      "y": 22,
      "z": -1,
      "name": "Rock_Crystal_White_Block"
    },
    {
      "x": 4,
      "y": 24,
      "z": -1,
      "name": "Rock_Crystal_White_Block"
    },
    {
      "x": 4,
      "y": 16,
      "z": 0,
      "name": "Rock_Crystal_White_Block"
    },
    {
      "x": 4,
      "y": 17,
      "z": 0,
      "name": "Rock_Crystal_White_Block"
    },
    {
      "x": 4,
      "y": 18,
      "z": 0,
      "name": "Rock_Crystal_White_Block",
      "rotation": 2
    },
    {
      "x": 4,
      "y": 19,
      "z": 0,
      "name": "Rock_Crystal_White_Block",
      "rotation": 2
    },
    {
      "x": 4,
      "y": 20,
      "z": 0,
      "name": "Rock_Crystal_White_Block",
      "rotation": 2
    },
    {
      "x": 4,
      "y": 21,
      "z": 0,
      "name": "Rock_Crystal_White_Block",
      "rotation": 2
    },
    {
      "x": 4,
      "y": 22,
      "z": 0,
      "name": "Rock_Crystal_White_Block",
      "rotation": 2
    },
    {
      "x": 4,
      "y": 23,
      "z": 0,
      "name": "Rock_Crystal_White_Block",
      "rotation": 2
    },
    {
      "x": 4,
      "y": 24,
      "z": 0,
      "name": "Rock_Crystal_White_Block",
      "rotation": 2
    },
    {
      "x": 4,
      "y": 25,
      "z": 0,
      "name": "Rock_Crystal_White_Block",
      "rotation": 2
    },
    {
      "x": 4,
      "y": 26,
      "z": 0,
      "name": "Rock_Crystal_White_Block",
      "rotation": 2
    },
    {
      "x": 4,
      "y": 17,
      "z": 1,
      "name": "Rock_Crystal_White_Block",
      "rotation": 2
    },
    {
      "x": 4,
      "y": 18,
      "z": 1,
      "name": "Rock_Crystal_White_Block",
      "rotation": 2
    },
    {
      "x": 4,
      "y": 19,
      "z": 1,
      "name": "Rock_Crystal_White_Block",
      "rotation": 2
    },
    {
      "x": 4,
      "y": 20,
      "z": 1,
      "name": "Rock_Crystal_White_Block"
    },
    {
      "x": 4,
      "y": 21,
      "z": 1,
      "name": "Rock_Crystal_White_Block",
      "rotation": 2
    },
    {
      "x": 4,
      "y": 22,
      "z": 1,
      "name": "Rock_Crystal_White_Block",
      "rotation": 2
    },
    {
      "x": 4,
      "y": 24,
      "z": 1,
      "name": "Rock_Crystal_White_Block",
      "rotation": 2
    },
    {
      "x": 4,
      "y": 17,
      "z": 2,
      "name": "Rock_Crystal_White_Block"
    },
    {
      "x": 4,
      "y": 18,
      "z": 2,
      "name": "Rock_Crystal_White_Block",
      "rotation": 2
    },
    {
      "x": 4,
      "y": 19,
      "z": 2,
      "name": "Rock_Crystal_White_Block"
    },
    {
      "x": 4,
      "y": 21,
      "z": 2,
      "name": "Rock_Crystal_White_Block",
      "rotation": 2
    },
    {
      "x": 4,
      "y": 22,
      "z": 2,
      "name": "Rock_Crystal_White_Block",
      "rotation": 2
    },
    {
      "x": 4,
      "y": 18,
      "z": 3,
      "name": "Rock_Crystal_White_Block",
      "rotation": 2
    },
    {
      "x": 4,
      "y": 20,
      "z": 3,
      "name": "Rock_Crystal_White_Block",
      "rotation": 2
    },
    {
      "x": 4,
      "y": 19,
      "z": 4,
      "name": "Rock_Crystal_White_Block",
      "rotation": 2
    },
    {
      "x": 4,
      "y": 23,
      "z": 4,
      "name": "Rock_Crystal_White_Block",
      "rotation": 2
    },
    {
      "x": 4,
      "y": 20,
      "z": 5,
      "name": "Rock_Crystal_White_Block",
      "rotation": 2
    },
    {
      "x": 4,
      "y": 21,
      "z": 5,
      "name": "Rock_Crystal_White_Block",
      "rotation": 2
    },
    {
      "x": 4,
      "y": 22,
      "z": 5,
      "name": "Rock_Crystal_White_Block",
      "rotation": 2
    },
    {
      "x": 4,
      "y": 19,
      "z": 6,
      "name": "Rock_Crystal_White_Block",
      "rotation": 2
    },
    {
      "x": 4,
      "y": 20,
      "z": 6,
      "name": "Rock_Crystal_White_Block",
      "rotation": 2
    },
    {
      "x": 4,
      "y": 21,
      "z": 6,
      "name": "Rock_Crystal_White_Block",
      "rotation": 2
    },
    {
      "x": 4,
      "y": 22,
      "z": 6,
      "name": "Rock_Crystal_White_Block",
      "rotation": 2
    },
    {
      "x": 4,
      "y": 24,
      "z": 6,
      "name": "Rock_Crystal_White_Block",
      "rotation": 2
    },
    {
      "x": 4,
      "y": 21,
      "z": 7,
      "name": "Rock_Crystal_White_Block",
      "rotation": 2
    },
    {
      "x": 4,
      "y": 22,
      "z": 7,
      "name": "Rock_Crystal_White_Block",
      "rotation": 2
    },
    {
      "x": 4,
      "y": 23,
      "z": 7,
      "name": "Rock_Crystal_White_Block",
      "rotation": 2
    },
    {
      "x": 4,
      "y": 20,
      "z": 8,
      "name": "Rock_Crystal_White_Block",
      "rotation": 2
    },
    {
      "x": 4,
      "y": 21,
      "z": 8,
      "name": "Rock_Crystal_White_Block",
      "rotation": 2
    },
    {
      "x": 4,
      "y": 22,
      "z": 8,
      "name": "Rock_Crystal_White_Block",
      "rotation": 2
    },
    {
      "x": 4,
      "y": 23,
      "z": 8,
      "name": "Rock_Crystal_White_Block",
      "rotation": 2
    },
    {
      "x": 4,
      "y": 24,
      "z": 8,
      "name": "Rock_Crystal_White_Block",
      "rotation": 2
    },
    {
      "x": 4,
      "y": 19,
      "z": 9,
      "name": "Rock_Crystal_White_Block",
      "rotation": 2
    },
    {
      "x": 4,
      "y": 21,
      "z": 9,
      "name": "Rock_Crystal_White_Block",
      "rotation": 2
    },
    {
      "x": 4,
      "y": 22,
      "z": 9,
      "name": "Rock_Crystal_White_Block",
      "rotation": 2
    },
    {
      "x": 4,
      "y": 23,
      "z": 9,
      "name": "Rock_Crystal_White_Block",
      "rotation": 2
    },
    {
      "x": 4,
      "y": 21,
      "z": 10,
      "name": "Rock_Crystal_White_Block",
      "rotation": 2
    },
    {
      "x": 4,
      "y": 22,
      "z": 10,
      "name": "Rock_Crystal_White_Block",
      "rotation": 2
    },
    {
      "x": 4,
      "y": 24,
      "z": 10,
      "name": "Rock_Crystal_White_Block",
      "rotation": 2
    },
    {
      "x": 4,
      "y": 20,
      "z": 11,
      "name": "Rock_Crystal_White_Block",
      "rotation": 2
    },
    {
      "x": 4,
      "y": 24,
      "z": 11,
      "name": "Rock_Crystal_White_Block",
      "rotation": 2
    },
    {
      "x": 4,
      "y": 25,
      "z": 11,
      "name": "Rock_Crystal_White_Block",
      "rotation": 2
    },
    {
      "x": 4,
      "y": 23,
      "z": 12,
      "name": "Rock_Crystal_White_Block",
      "rotation": 2
    },
    {
      "x": 4,
      "y": 25,
      "z": 12,
      "name": "Rock_Crystal_White_Block",
      "rotation": 2
    },
    {
      "x": 4,
      "y": 21,
      "z": 13,
      "name": "Rock_Crystal_White_Block",
      "rotation": 2
    },
    {
      "x": 4,
      "y": 22,
      "z": 13,
      "name": "Rock_Crystal_White_Block",
      "rotation": 2
    },
    {
      "x": 4,
      "y": 24,
      "z": 14,
      "name": "Rock_Crystal_White_Block",
      "rotation": 2
    },
    {
      "x": 4,
      "y": 21,
      "z": 15,
      "name": "Rock_Crystal_White_Block",
      "rotation": 2
    },
    {
      "x": 4,
      "y": 22,
      "z": 15,
      "name": "Rock_Crystal_White_Block",
      "rotation": 2
    },
    {
      "x": 5,
      "y": 23,
      "z": -16,
      "name": "Rock_Crystal_White_Block"
    },
    {
      "x": 5,
      "y": 24,
      "z": -15,
      "name": "Rock_Crystal_White_Block"
    },
    {
      "x": 5,
      "y": 23,
      "z": -14,
      "name": "Rock_Crystal_White_Block"
    },
    {
      "x": 5,
      "y": 24,
      "z": -14,
      "name": "Rock_Crystal_White_Block"
    },
    {
      "x": 5,
      "y": 25,
      "z": -14,
      "name": "Rock_Crystal_White_Block"
    },
    {
      "x": 5,
      "y": 26,
      "z": -14,
      "name": "Rock_Crystal_White_Block"
    },
    {
      "x": 5,
      "y": 24,
      "z": -13,
      "name": "Rock_Crystal_White_Block"
    },
    {
      "x": 5,
      "y": 25,
      "z": -13,
      "name": "Rock_Crystal_White_Block"
    },
    {
      "x": 5,
      "y": 26,
      "z": -13,
      "name": "Rock_Crystal_White_Block"
    },
    {
      "x": 5,
      "y": 22,
      "z": -12,
      "name": "Rock_Crystal_White_Block"
    },
    {
      "x": 5,
      "y": 23,
      "z": -12,
      "name": "Rock_Crystal_White_Block"
    },
    {
      "x": 5,
      "y": 24,
      "z": -12,
      "name": "Rock_Crystal_White_Block"
    },
    {
      "x": 5,
      "y": 23,
      "z": -11,
      "name": "Rock_Crystal_White_Block"
    },
    {
      "x": 5,
      "y": 24,
      "z": -11,
      "name": "Rock_Crystal_White_Block"
    },
    {
      "x": 5,
      "y": 21,
      "z": -10,
      "name": "Rock_Crystal_White_Block"
    },
    {
      "x": 5,
      "y": 23,
      "z": -10,
      "name": "Rock_Crystal_White_Block"
    },
    {
      "x": 5,
      "y": 24,
      "z": -10,
      "name": "Rock_Crystal_White_Block"
    },
    {
      "x": 5,
      "y": 25,
      "z": -10,
      "name": "Rock_Crystal_White_Block"
    },
    {
      "x": 5,
      "y": 26,
      "z": -10,
      "name": "Rock_Crystal_White_Block"
    },
    {
      "x": 5,
      "y": 22,
      "z": -9,
      "name": "Rock_Crystal_White_Block"
    },
    {
      "x": 5,
      "y": 23,
      "z": -9,
      "name": "Rock_Crystal_White_Block"
    },
    {
      "x": 5,
      "y": 22,
      "z": -8,
      "name": "Rock_Crystal_White_Block"
    },
    {
      "x": 5,
      "y": 23,
      "z": -8,
      "name": "Rock_Crystal_White_Block"
    },
    {
      "x": 5,
      "y": 24,
      "z": -8,
      "name": "Rock_Crystal_White_Block"
    },
    {
      "x": 5,
      "y": 21,
      "z": -7,
      "name": "Rock_Crystal_White_Block"
    },
    {
      "x": 5,
      "y": 22,
      "z": -7,
      "name": "Rock_Crystal_White_Block"
    },
    {
      "x": 5,
      "y": 20,
      "z": -6,
      "name": "Rock_Crystal_White_Block"
    },
    {
      "x": 5,
      "y": 23,
      "z": -6,
      "name": "Rock_Crystal_White_Block"
    },
    {
      "x": 5,
      "y": 24,
      "z": -6,
      "name": "Rock_Crystal_White_Block"
    },
    {
      "x": 5,
      "y": 20,
      "z": -5,
      "name": "Rock_Crystal_White_Block"
    },
    {
      "x": 5,
      "y": 21,
      "z": -5,
      "name": "Rock_Crystal_White_Block"
    },
    {
      "x": 5,
      "y": 19,
      "z": -4,
      "name": "Rock_Crystal_White_Block"
    },
    {
      "x": 5,
      "y": 22,
      "z": -4,
      "name": "Rock_Crystal_White_Block"
    },
    {
      "x": 5,
      "y": 23,
      "z": -4,
      "name": "Rock_Crystal_White_Block"
    },
    {
      "x": 5,
      "y": 24,
      "z": -3,
      "name": "Rock_Crystal_White_Block"
    },
    {
      "x": 5,
      "y": 23,
      "z": -2,
      "name": "Rock_Crystal_White_Block"
    },
    {
      "x": 5,
      "y": 19,
      "z": -1,
      "name": "Rock_Crystal_White_Block"
    },
    {
      "x": 5,
      "y": 21,
      "z": -1,
      "name": "Rock_Crystal_White_Block"
    },
    {
      "x": 5,
      "y": 23,
      "z": -1,
      "name": "Rock_Crystal_White_Block"
    },
    {
      "x": 5,
      "y": 24,
      "z": -1,
      "name": "Rock_Crystal_White_Block"
    },
    {
      "x": 5,
      "y": 25,
      "z": -1,
      "name": "Rock_Crystal_White_Block"
    },
    {
      "x": 5,
      "y": 26,
      "z": -1,
      "name": "Rock_Crystal_White_Block"
    },
    {
      "x": 5,
      "y": 17,
      "z": 0,
      "name": "Rock_Crystal_White_Block",
      "rotation": 2
    },
    {
      "x": 5,
      "y": 19,
      "z": 0,
      "name": "Rock_Crystal_White_Block",
      "rotation": 2
    },
    {
      "x": 5,
      "y": 20,
      "z": 0,
      "name": "Rock_Crystal_White_Block",
      "rotation": 2
    },
    {
      "x": 5,
      "y": 21,
      "z": 0,
      "name": "Rock_Crystal_White_Block",
      "rotation": 2
    },
    {
      "x": 5,
      "y": 22,
      "z": 0,
      "name": "Rock_Crystal_White_Block",
      "rotation": 2
    },
    {
      "x": 5,
      "y": 23,
      "z": 0,
      "name": "Rock_Crystal_White_Block",
      "rotation": 2
    },
    {
      "x": 5,
      "y": 24,
      "z": 0,
      "name": "Rock_Crystal_White_Block",
      "rotation": 2
    },
    {
      "x": 5,
      "y": 25,
      "z": 0,
      "name": "Rock_Crystal_White_Block",
      "rotation": 2
    },
    {
      "x": 5,
      "y": 26,
      "z": 0,
      "name": "Rock_Crystal_White_Block",
      "rotation": 2
    },
    {
      "x": 5,
      "y": 27,
      "z": 0,
      "name": "Rock_Crystal_White_Block",
      "rotation": 2
    },
    {
      "x": 5,
      "y": 28,
      "z": 0,
      "name": "Rock_Crystal_White_Block",
      "rotation": 2
    },
    {
      "x": 5,
      "y": 19,
      "z": 1,
      "name": "Rock_Crystal_White_Block"
    },
    {
      "x": 5,
      "y": 21,
      "z": 1,
      "name": "Rock_Crystal_White_Block",
      "rotation": 2
    },
    {
      "x": 5,
      "y": 23,
      "z": 1,
      "name": "Rock_Crystal_White_Block",
      "rotation": 2
    },
    {
      "x": 5,
      "y": 24,
      "z": 1,
      "name": "Rock_Crystal_White_Block",
      "rotation": 2
    },
    {
      "x": 5,
      "y": 25,
      "z": 1,
      "name": "Rock_Crystal_White_Block",
      "rotation": 2
    },
    {
      "x": 5,
      "y": 26,
      "z": 1,
      "name": "Rock_Crystal_White_Block",
      "rotation": 2
    },
    {
      "x": 5,
      "y": 23,
      "z": 2,
      "name": "Rock_Crystal_White_Block",
      "rotation": 2
    },
    {
      "x": 5,
      "y": 24,
      "z": 3,
      "name": "Rock_Crystal_White_Block",
      "rotation": 2
    },
    {
      "x": 5,
      "y": 19,
      "z": 4,
      "name": "Rock_Crystal_White_Block",
      "rotation": 2
    },
    {
      "x": 5,
      "y": 22,
      "z": 4,
      "name": "Rock_Crystal_White_Block",
      "rotation": 2
    },
    {
      "x": 5,
      "y": 23,
      "z": 4,
      "name": "Rock_Crystal_White_Block",
      "rotation": 2
    },
    {
      "x": 5,
      "y": 20,
      "z": 5,
      "name": "Rock_Crystal_White_Block",
      "rotation": 2
    },
    {
      "x": 5,
      "y": 21,
      "z": 5,
      "name": "Rock_Crystal_White_Block",
      "rotation": 2
    },
    {
      "x": 5,
      "y": 20,
      "z": 6,
      "name": "Rock_Crystal_White_Block",
      "rotation": 2
    },
    {
      "x": 5,
      "y": 23,
      "z": 6,
      "name": "Rock_Crystal_White_Block",
      "rotation": 2
    },
    {
      "x": 5,
      "y": 24,
      "z": 6,
      "name": "Rock_Crystal_White_Block",
      "rotation": 2
    },
    {
      "x": 5,
      "y": 21,
      "z": 7,
      "name": "Rock_Crystal_White_Block",
      "rotation": 2
    },
    {
      "x": 5,
      "y": 22,
      "z": 7,
      "name": "Rock_Crystal_White_Block",
      "rotation": 2
    },
    {
      "x": 5,
      "y": 22,
      "z": 8,
      "name": "Rock_Crystal_White_Block",
      "rotation": 2
    },
    {
      "x": 5,
      "y": 23,
      "z": 8,
      "name": "Rock_Crystal_White_Block",
      "rotation": 2
    },
    {
      "x": 5,
      "y": 24,
      "z": 8,
      "name": "Rock_Crystal_White_Block",
      "rotation": 2
    },
    {
      "x": 5,
      "y": 22,
      "z": 9,
      "name": "Rock_Crystal_White_Block",
      "rotation": 2
    },
    {
      "x": 5,
      "y": 23,
      "z": 9,
      "name": "Rock_Crystal_White_Block",
      "rotation": 2
    },
    {
      "x": 5,
      "y": 21,
      "z": 10,
      "name": "Rock_Crystal_White_Block",
      "rotation": 2
    },
    {
      "x": 5,
      "y": 23,
      "z": 10,
      "name": "Rock_Crystal_White_Block",
      "rotation": 2
    },
    {
      "x": 5,
      "y": 24,
      "z": 10,
      "name": "Rock_Crystal_White_Block",
      "rotation": 2
    },
    {
      "x": 5,
      "y": 25,
      "z": 10,
      "name": "Rock_Crystal_White_Block",
      "rotation": 2
    },
    {
      "x": 5,
      "y": 26,
      "z": 10,
      "name": "Rock_Crystal_White_Block",
      "rotation": 2
    },
    {
      "x": 5,
      "y": 23,
      "z": 11,
      "name": "Rock_Crystal_White_Block",
      "rotation": 2
    },
    {
      "x": 5,
      "y": 24,
      "z": 11,
      "name": "Rock_Crystal_White_Block",
      "rotation": 2
    },
    {
      "x": 5,
      "y": 22,
      "z": 12,
      "name": "Rock_Crystal_White_Block",
      "rotation": 2
    },
    {
      "x": 5,
      "y": 23,
      "z": 12,
      "name": "Rock_Crystal_White_Block",
      "rotation": 2
    },
    {
      "x": 5,
      "y": 24,
      "z": 12,
      "name": "Rock_Crystal_White_Block",
      "rotation": 2
    },
    {
      "x": 5,
      "y": 24,
      "z": 13,
      "name": "Rock_Crystal_White_Block",
      "rotation": 2
    },
    {
      "x": 5,
      "y": 25,
      "z": 13,
      "name": "Rock_Crystal_White_Block",
      "rotation": 2
    },
    {
      "x": 5,
      "y": 26,
      "z": 13,
      "name": "Rock_Crystal_White_Block",
      "rotation": 2
    },
    {
      "x": 5,
      "y": 23,
      "z": 14,
      "name": "Rock_Crystal_White_Block",
      "rotation": 2
    },
    {
      "x": 5,
      "y": 24,
      "z": 14,
      "name": "Rock_Crystal_White_Block",
      "rotation": 2
    },
    {
      "x": 5,
      "y": 25,
      "z": 14,
      "name": "Rock_Crystal_White_Block",
      "rotation": 2
    },
    {
      "x": 5,
      "y": 26,
      "z": 14,
      "name": "Rock_Crystal_White_Block",
      "rotation": 2
    },
    {
      "x": 5,
      "y": 24,
      "z": 15,
      "name": "Rock_Crystal_White_Block",
      "rotation": 2
    },
    {
      "x": 5,
      "y": 23,
      "z": 16,
      "name": "Rock_Crystal_White_Block",
      "rotation": 2
    },
    {
      "x": 6,
      "y": 25,
      "z": -17,
      "name": "Rock_Crystal_White_Block"
    },
    {
      "x": 6,
      "y": 27,
      "z": -16,
      "name": "Rock_Crystal_White_Block"
    },
    {
      "x": 6,
      "y": 24,
      "z": -15,
      "name": "Rock_Crystal_White_Block"
    },
    {
      "x": 6,
      "y": 26,
      "z": -15,
      "name": "Rock_Crystal_White_Block"
    },
    {
      "x": 6,
      "y": 23,
      "z": -14,
      "name": "Rock_Crystal_White_Block"
    },
    {
      "x": 6,
      "y": 24,
      "z": -14,
      "name": "Rock_Crystal_White_Block"
    },
    {
      "x": 6,
      "y": 25,
      "z": -14,
      "name": "Rock_Crystal_White_Block"
    },
    {
      "x": 6,
      "y": 26,
      "z": -14,
      "name": "Rock_Crystal_White_Block"
    },
    {
      "x": 6,
      "y": 24,
      "z": -13,
      "name": "Rock_Crystal_White_Block"
    },
