{
  "version": 8,
  "blockIdVersion": 11,
  "anchorX": 0,
  "anchorY": 18,
  "anchorZ": 0,
  "blocks": [
    {
      "x": -13,
      "y": 13,
      "z": 15,
      "name": "Rock_Crystal_White_Block",
      "rotation": 2
    },
    {
      "x": -13,
      "y": 13,
      "z": 16,
      "name": "Rock_Crystal_White_Block",
      "rotation": 2
    },
    {
      "x": -12,
      "y": 13,
      "z": 11,
      "name": "Rock_Crystal_White_Block",
      "rotation": 2
    },
    {
      "x": -12,
      "y": 14,
      "z": 12,
      "name": "Rock_Crystal_White_Block",
      "rotation": 2
    },
    {
      "x": -12,
      "y": 12,
      "z": 13,
      "name": "Rock_Crystal_White_Block",
      "rotation": 2
    },
    {
      "x": -12,
      "y": 13,
      "z": 13,
      "name": "Rock_Crystal_White_Block",
      "rotation": 2
    },
    {
      "x": -12,
      "y": 14,
      "z": 13,
      "name": "Rock_Crystal_White_Block",
      "rotation": 2
    },
    {
      "x": -12,
      "y": 13,
      "z": 14,
      "name": "Rock_Crystal_White_Block",
      "rotation": 2
    },
    {
      "x": -12,
      "y": 14,
      "z": 14,
      "name": "Rock_Crystal_White_Block",
      "rotation": 2
    },
    {
      "x": -11,
      "y": 0,
      "z": 0,
      "name": "Rock_Crystal_White_Block"
    },
    {
      "x": -11,
      "y": 1,
      "z": 1,
      "name": "Rock_Crystal_White_Block",
      "rotation": 2
    },
    {
      "x": -11,
      "y": 12,
      "z": 11,
      "name": "Rock_Crystal_White_Block",
      "rotation": 2
    },
    {
      "x": -11,
      "y": 13,
      "z": 11,
      "name": "Rock_Crystal_White_Block",
      "rotation": 2
    },
    {
      "x": -11,
      "y": 15,
      "z": 11,
      "name": "Rock_Crystal_White_Block",
      "rotation": 2
    },
    {
      "x": -11,
      "y": 13,
      "z": 12,
      "name": "Rock_Crystal_White_Block",
      "rotation": 2
    },
    {
      "x": -11,
      "y": 14,
      "z": 12,
      "name": "Rock_Crystal_White_Block",
      "rotation": 2
    },
    {
      "x": -11,
      "y": 15,
      "z": 12,
      "name": "Rock_Crystal_White_Block",
      "rotation": 2
    },
    {
      "x": -11,
      "y": 16,
      "z": 12,
      "name": "Rock_Crystal_White_Block",
      "rotation": 2
    },
    {
      "x": -11,
      "y": 13,
      "z": 13,
      "name": "Rock_Crystal_White_Block",
      "rotation": 2
    },
    {
      "x": -11,
      "y": 14,
      "z": 13,
      "name": "Rock_Crystal_White_Block",
      "rotation": 2
    },
    {
      "x": -11,
      "y": 13,
      "z": 14,
      "name": "Rock_Crystal_White_Block",
      "rotation": 2
    },
    {
      "x": -11,
      "y": 14,
      "z": 14,
      "name": "Rock_Crystal_White_Block",
      "rotation": 2
    },
    {
      "x": -10,
      "y": 0,
      "z": 0,
      "name": "Rock_Crystal_White_Block"
    },
    {
      "x": -10,
      "y": 1,
      "z": 0,
      "name": "Rock_Crystal_White_Block"
    },
    {
      "x": -10,
      "y": 1,
      "z": 1,
      "name": "Rock_Crystal_White_Block",
      "rotation": 2
    },
    {
      "x": -10,
      "y": 3,
      "z": 2,
      "name": "Rock_Crystal_White_Block",
      "rotation": 2
    },
    {
      "x": -10,
      "y": 12,
      "z": 9,
      "name": "Rock_Crystal_White_Block",
      "rotation": 2
    },
    {
      "x": -10,
      "y": 16,
      "z": 9,
      "name": "Rock_Crystal_White_Block",
      "rotation": 2
    },
    {
      "x": -10,
      "y": 12,
      "z": 10,
      "name": "Rock_Crystal_White_Block",
      "rotation": 2
    },
    {
      "x": -10,
      "y": 13,
      "z": 10,
      "name": "Rock_Crystal_White_Block",
      "rotation": 2
    },
    {
      "x": -10,
      "y": 16,
      "z": 10,
      "name": "Rock_Crystal_White_Block",
      "rotation": 2
    },
    {
      "x": -10,
      "y": 14,
      "z": 11,
      "name": "Rock_Crystal_White_Block",
      "rotation": 2
    },
    {
      "x": -10,
      "y": 15,
      "z": 11,
      "name": "Rock_Crystal_White_Block",
      "rotation": 2
    },
    {
      "x": -10,
      "y": 16,
      "z": 11,
      "name": "Rock_Crystal_White_Block",
      "rotation": 2
    },
    {
      "x": -10,
      "y": 12,
      "z": 12,
      "name": "Rock_Crystal_White_Block",
      "rotation": 2
    },
    {
      "x": -10,
      "y": 14,
      "z": 12,
      "name": "Rock_Crystal_White_Block",
      "rotation": 2
    },
    {
      "x": -10,
      "y": 15,
      "z": 12,
      "name": "Rock_Crystal_White_Block",
      "rotation": 2
    },
    {
      "x": -10,
      "y": 17,
      "z": 12,
      "name": "Rock_Crystal_White_Block",
      "rotation": 2
    },
    {
      "x": -10,
      "y": 13,
      "z": 13,
      "name": "Rock_Crystal_White_Block",
      "rotation": 2
    },
    {
      "x": -10,
      "y": 16,
      "z": 13,
      "name": "Rock_Crystal_White_Block",
      "rotation": 2
    },
    {
      "x": -10,
      "y": 17,
      "z": 14,
      "name": "Rock_Crystal_White_Block",
      "rotation": 2
    },
    {
      "x": -9,
      "y": 2,
      "z": -1,
      "name": "Rock_Crystal_White_Block"
    },
    {
      "x": -9,
      "y": 4,
      "z": -1,
      "name": "Rock_Crystal_White_Block"
    },
    {
      "x": -9,
      "y": 2,
      "z": 0,
      "name": "Rock_Crystal_White_Block"
    },
    {
      "x": -9,
      "y": 3,
      "z": 0,
      "name": "Rock_Crystal_White_Block"
    },
    {
      "x": -9,
      "y": 4,
      "z": 0,
      "name": "Rock_Crystal_White_Block"
    },
    {
      "x": -9,
      "y": 5,
      "z": 0,
      "name": "Rock_Crystal_White_Block",
      "rotation": 2
    },
    {
      "x": -9,
      "y": 7,
      "z": 1,
      "name": "Rock_Crystal_White_Block",
      "rotation": 2
    },
    {
      "x": -9,
      "y": 5,
      "z": 2,
      "name": "Rock_Crystal_White_Block",
      "rotation": 2
    },
    {
      "x": -9,
      "y": 5,
      "z": 3,
      "name": "Rock_Crystal_White_Block",
      "rotation": 2
    },
    {
      "x": -9,
      "y": 12,
      "z": 8,
      "name": "Rock_Crystal_White_Block",
      "rotation": 2
    },
    {
      "x": -9,
      "y": 14,
      "z": 8,
      "name": "Rock_Crystal_White_Block",
      "rotation": 2
    },
    {
      "x": -9,
      "y": 16,
      "z": 8,
      "name": "Rock_Crystal_White_Block",
      "rotation": 2
    },
    {
      "x": -9,
      "y": 15,
      "z": 9,
      "name": "Rock_Crystal_White_Block",
      "rotation": 2
    },
    {
      "x": -9,
      "y": 16,
      "z": 9,
      "name": "Rock_Crystal_White_Block",
      "rotation": 2
    },
    {
      "x": -9,
      "y": 14,
      "z": 10,
      "name": "Rock_Crystal_White_Block",
      "rotation": 2
    },
    {
      "x": -9,
      "y": 15,
      "z": 10,
      "name": "Rock_Crystal_White_Block",
      "rotation": 2
    },
    {
      "x": -9,
      "y": 17,
      "z": 10,
      "name": "Rock_Crystal_White_Block",
      "rotation": 2
    },
    {
      "x": -9,
      "y": 13,
      "z": 11,
      "name": "Rock_Crystal_White_Block",
      "rotation": 2
    },
    {
      "x": -9,
      "y": 14,
      "z": 11,
      "name": "Rock_Crystal_White_Block",
      "rotation": 2
    },
    {
      "x": -9,
      "y": 15,
      "z": 11,
      "name": "Rock_Crystal_White_Block",
      "rotation": 2
    },
    {
      "x": -9,
      "y": 14,
      "z": 12,
      "name": "Rock_Crystal_White_Block",
      "rotation": 2
    },
    {
      "x": -9,
      "y": 16,
      "z": 12,
      "name": "Rock_Crystal_White_Block",
      "rotation": 2
    },
    {
      "x": -9,
      "y": 17,
      "z": 12,
      "name": "Rock_Crystal_White_Block",
      "rotation": 2
    },
    {
      "x": -9,
      "y": 14,
      "z": 13,
      "name": "Rock_Crystal_White_Block",
      "rotation": 2
    },
    {
      "x": -8,
      "y": 2,
      "z": -2,
      "name": "Rock_Crystal_White_Block"
    },
    {
      "x": -8,
      "y": 2,
      "z": -1,
      "name": "Rock_Crystal_White_Block"
    },
    {
      "x": -8,
      "y": 4,
      "z": -1,
      "name": "Rock_Crystal_White_Block"
    },
    {
      "x": -8,
      "y": 6,
      "z": -1,
      "name": "Rock_Crystal_White_Block"
    },
    {
      "x": -8,
      "y": 3,
      "z": 0,
      "name": "Rock_Crystal_White_Block"
    },
    {
      "x": -8,
      "y": 4,
      "z": 0,
      "name": "Rock_Crystal_White_Block"
    },
    {
      "x": -8,
      "y": 5,
      "z": 0,
      "name": "Rock_Crystal_White_Block"
    },
    {
      "x": -8,
      "y": 6,
      "z": 0,
      "name": "Rock_Crystal_White_Block"
    },
    {
      "x": -8,
      "y": 2,
      "z": 1,
      "name": "Rock_Crystal_White_Block"
    },
    {
      "x": -8,
      "y": 4,
      "z": 1,
      "name": "Rock_Crystal_White_Block",
      "rotation": 2
    },
    {
      "x": -8,
      "y": 5,
      "z": 1,
      "name": "Rock_Crystal_White_Block",
      "rotation": 2
    },
    {
      "x": -8,
      "y": 7,
      "z": 1,
      "name": "Rock_Crystal_White_Block",
      "rotation": 2
    },
    {
      "x": -8,
      "y": 6,
      "z": 2,
      "name": "Rock_Crystal_White_Block",
      "rotation": 2
    },
    {
      "x": -8,
      "y": 7,
      "z": 2,
      "name": "Rock_Crystal_White_Block",
      "rotation": 2
    },
    {
      "x": -8,
      "y": 7,
      "z": 3,
      "name": "Rock_Crystal_White_Block",
      "rotation": 2
    },
    {
      "x": -8,
      "y": 11,
      "z": 6,
      "name": "Rock_Crystal_White_Block",
      "rotation": 2
    },
    {
      "x": -8,
      "y": 12,
      "z": 6,
      "name": "Rock_Crystal_White_Block",
      "rotation": 2
    },
    {
      "x": -8,
      "y": 14,
      "z": 6,
      "name": "Rock_Crystal_White_Block",
      "rotation": 2
    },
    {
      "x": -8,
      "y": 17,
      "z": 7,
      "name": "Rock_Crystal_White_Block",
      "rotation": 2
    },
    {
      "x": -8,
      "y": 16,
      "z": 8,
      "name": "Rock_Crystal_White_Block",
      "rotation": 2
    },
    {
      "x": -8,
      "y": 13,
      "z": 9,
      "name": "Rock_Crystal_White_Block",
      "rotation": 2
    },
    {
      "x": -8,
      "y": 14,
      "z": 9,
      "name": "Rock_Crystal_White_Block",
      "rotation": 2
    },
    {
      "x": -8,
      "y": 15,
      "z": 9,
      "name": "Rock_Crystal_White_Block",
      "rotation": 2
    },
    {
      "x": -8,
      "y": 16,
      "z": 9,
      "name": "Rock_Crystal_White_Block",
      "rotation": 2
    },
    {
      "x": -8,
      "y": 14,
      "z": 10,
      "name": "Rock_Crystal_White_Block",
      "rotation": 2
    },
    {
      "x": -8,
      "y": 15,
      "z": 10,
      "name": "Rock_Crystal_White_Block",
      "rotation": 2
    },
    {
      "x": -8,
      "y": 16,
      "z": 10,
      "name": "Rock_Crystal_White_Block",
      "rotation": 2
    },
    {
      "x": -8,
      "y": 17,
      "z": 10,
      "name": "Rock_Crystal_White_Block",
      "rotation": 2
    },
    {
      "x": -8,
      "y": 14,
      "z": 11,
      "name": "Rock_Crystal_White_Block",
      "rotation": 2
    },
    {
      "x": -8,
      "y": 15,
      "z": 11,
      "name": "Rock_Crystal_White_Block",
      "rotation": 2
    },
    {
      "x": -8,
      "y": 16,
      "z": 11,
      "name": "Rock_Crystal_White_Block",
      "rotation": 2
    },
    {
      "x": -8,
      "y": 18,
      "z": 11,
      "name": "Rock_Crystal_White_Block",
      "rotation": 2
    },
    {
      "x": -8,
      "y": 15,
      "z": 12,
      "name": "Rock_Crystal_White_Block",
      "rotation": 2
    },
    {
      "x": -8,
      "y": 17,
      "z": 12,
      "name": "Rock_Crystal_White_Block",
      "rotation": 2
    },
    {
      "x": -8,
      "y": 16,
      "z": 13,
      "name": "Rock_Crystal_White_Block",
      "rotation": 2
    },
    {
      "x": -7,
      "y": 3,
      "z": -3,
      "name": "Rock_Crystal_White_Block"
    },
    {
      "x": -7,
      "y": 3,
      "z": -2,
      "name": "Rock_Crystal_White_Block"
    },
    {
      "x": -7,
      "y": 4,
      "z": -2,
      "name": "Rock_Crystal_White_Block"
    },
    {
      "x": -7,
      "y": 6,
      "z": -2,
      "name": "Rock_Crystal_White_Block"
    },
    {
      "x": -7,
      "y": 7,
      "z": -2,
      "name": "Rock_Crystal_White_Block"
    },
    {
      "x": -7,
      "y": 4,
      "z": -1,
      "name": "Rock_Crystal_White_Block"
    },
    {
      "x": -7,
      "y": 5,
      "z": -1,
      "name": "Rock_Crystal_White_Block"
    },
    {
      "x": -7,
      "y": 7,
      "z": -1,
      "name": "Rock_Crystal_White_Block"
    },
    {
      "x": -7,
      "y": 8,
      "z": -1,
      "name": "Rock_Crystal_White_Block"
    },
    {
      "x": -7,
      "y": 9,
      "z": -1,
      "name": "Rock_Crystal_White_Block"
    },
    {
      "x": -7,
      "y": 10,
      "z": -1,
      "name": "Rock_Crystal_White_Block"
    },
    {
      "x": -7,
      "y": 3,
      "z": 0,
      "name": "Rock_Crystal_White_Block"
    },
    {
      "x": -7,
      "y": 4,
      "z": 0,
      "name": "Rock_Crystal_White_Block"
    },
    {
      "x": -7,
      "y": 5,
      "z": 0,
      "name": "Rock_Crystal_White_Block"
    },
    {
      "x": -7,
      "y": 6,
      "z": 0,
      "name": "Rock_Crystal_White_Block"
    },
    {
      "x": -7,
      "y": 7,
      "z": 0,
      "name": "Rock_Crystal_White_Block"
    },
    {
      "x": -7,
      "y": 9,
      "z": 0,
      "name": "Rock_Crystal_White_Block",
      "rotation": 2
    },
    {
      "x": -7,
      "y": 4,
      "z": 1,
      "name": "Rock_Crystal_White_Block"
    },
    {
      "x": -7,
      "y": 7,
      "z": 1,
      "name": "Rock_Crystal_White_Block",
      "rotation": 2
    },
    {
      "x": -7,
      "y": 8,
      "z": 1,
      "name": "Rock_Crystal_White_Block",
      "rotation": 2
    },
    {
      "x": -7,
      "y": 9,
      "z": 1,
      "name": "Rock_Crystal_White_Block",
      "rotation": 2
    },
    {
      "x": -7,
      "y": 6,
      "z": 2,
      "name": "Rock_Crystal_White_Block",
      "rotation": 2
    },
    {
      "x": -7,
      "y": 10,
      "z": 3,
      "name": "Rock_Crystal_White_Block",
      "rotation": 2
    },
    {
      "x": -7,
      "y": 10,
      "z": 4,
      "name": "Rock_Crystal_White_Block",
      "rotation": 2
    },
    {
      "x": -7,
      "y": 11,
      "z": 4,
      "name": "Rock_Crystal_White_Block",
      "rotation": 2
    },
    {
      "x": -7,
      "y": 14,
      "z": 5,
      "name": "Rock_Crystal_White_Block",
      "rotation": 2
    },
    {
      "x": -7,
      "y": 17,
      "z": 5,
      "name": "Rock_Crystal_White_Block",
      "rotation": 2
    },
    {
      "x": -7,
      "y": 12,
      "z": 6,
      "name": "Rock_Crystal_White_Block",
      "rotation": 2
    },
    {
      "x": -7,
      "y": 13,
      "z": 6,
      "name": "Rock_Crystal_White_Block",
      "rotation": 2
    },
    {
      "x": -7,
      "y": 16,
      "z": 6,
      "name": "Rock_Crystal_White_Block",
      "rotation": 2
    },
    {
      "x": -7,
      "y": 14,
      "z": 7,
      "name": "Rock_Crystal_White_Block",
      "rotation": 2
    },
    {
      "x": -7,
      "y": 15,
      "z": 7,
      "name": "Rock_Crystal_White_Block",
      "rotation": 2
    },
    {
      "x": -7,
      "y": 16,
      "z": 7,
      "name": "Rock_Crystal_White_Block",
      "rotation": 2
    },
    {
      "x": -7,
      "y": 15,
      "z": 8,
      "name": "Rock_Crystal_White_Block",
      "rotation": 2
    },
    {
      "x": -7,
      "y": 16,
      "z": 8,
      "name": "Rock_Crystal_White_Block",
      "rotation": 2
    },
    {
      "x": -7,
      "y": 17,
      "z": 8,
      "name": "Rock_Crystal_White_Block",
      "rotation": 2
    },
    {
      "x": -7,
      "y": 18,
      "z": 8,
      "name": "Rock_Crystal_White_Block",
      "rotation": 2
    },
    {
      "x": -7,
      "y": 13,
      "z": 9,
      "name": "Rock_Crystal_White_Block",
      "rotation": 2
    },
    {
      "x": -7,
      "y": 15,
      "z": 9,
      "name": "Rock_Crystal_White_Block",
      "rotation": 2
    },
    {
      "x": -7,
      "y": 16,
      "z": 9,
      "name": "Rock_Crystal_White_Block",
      "rotation": 2
    },
    {
      "x": -7,
      "y": 19,
      "z": 9,
      "name": "Rock_Crystal_White_Block",
      "rotation": 2
    },
    {
      "x": -7,
      "y": 14,
      "z": 10,
      "name": "Rock_Crystal_White_Block",
      "rotation": 2
    },
    {
      "x": -7,
      "y": 15,
      "z": 10,
      "name": "Rock_Crystal_White_Block",
      "rotation": 2
    },
    {
      "x": -7,
      "y": 14,
      "z": 11,
      "name": "Rock_Crystal_White_Block",
      "rotation": 2
    },
    {
      "x": -7,
      "y": 16,
      "z": 11,
      "name": "Rock_Crystal_White_Block",
      "rotation": 2
    },
    {
      "x": -7,
      "y": 18,
      "z": 11,
      "name": "Rock_Crystal_White_Block",
      "rotation": 2
    },
    {
      "x": -7,
      "y": 19,
      "z": 11,
      "name": "Rock_Crystal_White_Block",
      "rotation": 2
    },
    {
      "x": -7,
      "y": 14,
      "z": 12,
      "name": "Rock_Crystal_White_Block",
      "rotation": 2
    },
    {
      "x": -7,
      "y": 20,
      "z": 12,
      "name": "Rock_Crystal_White_Block",
      "rotation": 2
    },
    {
      "x": -6,
      "y": 5,
      "z": -3,
      "name": "Rock_Crystal_White_Block"
    },
    {
      "x": -6,
      "y": 5,
      "z": -2,
      "name": "Rock_Crystal_White_Block"
    },
    {
      "x": -6,
      "y": 6,
      "z": -2,
      "name": "Rock_Crystal_White_Block"
    },
    {
      "x": -6,
      "y": 5,
      "z": -1,
      "name": "Rock_Crystal_White_Block"
    },
    {
      "x": -6,
      "y": 6,
      "z": -1,
      "name": "Rock_Crystal_White_Block"
    },
    {
      "x": -6,
      "y": 7,
      "z": -1,
      "name": "Rock_Crystal_White_Block"
    },
    {
      "x": -6,
      "y": 9,
      "z": -1,
      "name": "Rock_Crystal_White_Block"
    },
    {
      "x": -6,
      "y": 10,
      "z": -1,
      "name": "Rock_Crystal_White_Block"
    },
    {
      "x": -6,
      "y": 11,
      "z": -1,
      "name": "Rock_Crystal_White_Block"
    },
    {
      "x": -6,
      "y": 12,
      "z": -1,
      "name": "Rock_Crystal_White_Block"
    },
    {
      "x": -6,
      "y": 6,
      "z": 0,
      "name": "Rock_Crystal_White_Block"
    },
    {
      "x": -6,
      "y": 7,
      "z": 0,
      "name": "Rock_Crystal_White_Block"
    },
    {
      "x": -6,
      "y": 8,
      "z": 0,
      "name": "Rock_Crystal_White_Block"
    },
    {
      "x": -6,
      "y": 9,
      "z": 0,
      "name": "Rock_Crystal_White_Block"
    },
    {
      "x": -6,
      "y": 6,
      "z": 1,
      "name": "Rock_Crystal_White_Block"
    },
    {
      "x": -6,
      "y": 7,
      "z": 1,
      "name": "Rock_Crystal_White_Block",
      "rotation": 2
    },
    {
      "x": -6,
      "y": 8,
      "z": 1,
      "name": "Rock_Crystal_White_Block",
      "rotation": 2
    },
    {
      "x": -6,
      "y": 9,
      "z": 1,
      "name": "Rock_Crystal_White_Block",
      "rotation": 2
    },
    {
      "x": -6,
      "y": 11,
      "z": 1,
      "name": "Rock_Crystal_White_Block",
      "rotation": 2
    },
    {
      "x": -6,
      "y": 9,
      "z": 2,
      "name": "Rock_Crystal_White_Block",
      "rotation": 2
    },
    {
      "x": -6,
      "y": 11,
      "z": 2,
      "name": "Rock_Crystal_White_Block",
      "rotation": 2
    },
    {
      "x": -6,
      "y": 11,
      "z": 3,
      "name": "Rock_Crystal_White_Block",
      "rotation": 2
    },
    {
      "x": -6,
      "y": 12,
      "z": 4,
      "name": "Rock_Crystal_White_Block",
      "rotation": 2
    },
    {
      "x": -6,
      "y": 18,
      "z": 4,
      "name": "Rock_Crystal_White_Block",
      "rotation": 2
    },
    {
      "x": -6,
      "y": 13,
      "z": 5,
      "name": "Rock_Crystal_White_Block",
      "rotation": 2
    },
    {
      "x": -6,
      "y": 14,
      "z": 5,
      "name": "Rock_Crystal_White_Block",
      "rotation": 2
    },
    {
      "x": -6,
      "y": 15,
      "z": 5,
      "name": "Rock_Crystal_White_Block",
      "rotation": 2
    },
    {
      "x": -6,
      "y": 17,
      "z": 5,
      "name": "Rock_Crystal_White_Block",
      "rotation": 2
    },
    {
      "x": -6,
      "y": 16,
      "z": 6,
      "name": "Rock_Crystal_White_Block",
      "rotation": 2
    },
    {
      "x": -6,
      "y": 18,
      "z": 6,
      "name": "Rock_Crystal_White_Block",
      "rotation": 2
    },
    {
      "x": -6,
      "y": 14,
      "z": 7,
      "name": "Rock_Crystal_White_Block",
      "rotation": 2
    },
    {
      "x": -6,
      "y": 15,
      "z": 7,
      "name": "Rock_Crystal_White_Block",
      "rotation": 2
    },
    {
      "x": -6,
      "y": 16,
      "z": 7,
      "name": "Rock_Crystal_White_Block",
      "rotation": 2
    },
    {
      "x": -6,
      "y": 19,
      "z": 7,
      "name": "Rock_Crystal_White_Block",
      "rotation": 2
    },
    {
      "x": -6,
      "y": 16,
      "z": 8,
      "name": "Rock_Crystal_White_Block",
      "rotation": 2
    },
    {
      "x": -6,
      "y": 17,
      "z": 8,
      "name": "Rock_Crystal_White_Block",
      "rotation": 2
    },
    {
      "x": -6,
      "y": 15,
      "z": 9,
      "name": "Rock_Crystal_White_Block",
      "rotation": 2
    },
    {
      "x": -6,
      "y": 17,
      "z": 9,
      "name": "Rock_Crystal_White_Block",
      "rotation": 2
    },
    {
      "x": -6,
      "y": 19,
      "z": 9,
      "name": "Rock_Crystal_White_Block",
      "rotation": 2
    },
    {
      "x": -6,
      "y": 14,
      "z": 10,
      "name": "Rock_Crystal_White_Block",
      "rotation": 2
    },
    {
      "x": -6,
      "y": 18,
      "z": 10,
      "name": "Rock_Crystal_White_Block",
      "rotation": 2
    },
    {
      "x": -6,
      "y": 20,
      "z": 10,
      "name": "Rock_Crystal_White_Block",
      "rotation": 2
    },
    {
      "x": -5,
      "y": 7,
      "z": -3,
      "name": "Rock_Crystal_White_Block"
    },
    {
      "x": -5,
      "y": 8,
      "z": -2,
      "name": "Rock_Crystal_White_Block"
    },
    {
      "x": -5,
      "y": 10,
      "z": -2,
      "name": "Rock_Crystal_White_Block"
    },
    {
      "x": -5,
      "y": 5,
      "z": -1,
      "name": "Rock_Crystal_White_Block"
    },
    {
      "x": -5,
      "y": 8,
      "z": -1,
      "name": "Rock_Crystal_White_Block"
    },
    {
      "x": -5,
      "y": 9,
      "z": -1,
      "name": "Rock_Crystal_White_Block"
    },
    {
      "x": -5,
      "y": 11,
      "z": -1,
      "name": "Rock_Crystal_White_Block"
    },
    {
      "x": -5,
      "y": 12,
      "z": -1,
      "name": "Rock_Crystal_White_Block"
    },
    {
      "x": -5,
      "y": 13,
      "z": -1,
      "name": "Rock_Crystal_White_Block"
    },
    {
      "x": -5,
      "y": 6,
      "z": 0,
      "name": "Rock_Crystal_White_Block"
    },
    {
      "x": -5,
      "y": 8,
      "z": 0,
      "name": "Rock_Crystal_White_Block"
    },
    {
      "x": -5,
      "y": 9,
      "z": 0,
      "name": "Rock_Crystal_White_Block"
    },
    {
      "x": -5,
      "y": 10,
      "z": 0,
      "name": "Rock_Crystal_White_Block"
    },
    {
      "x": -5,
      "y": 11,
      "z": 0,
      "name": "Rock_Crystal_White_Block"
    },
    {
      "x": -5,
      "y": 12,
      "z": 0,
      "name": "Rock_Crystal_White_Block",
      "rotation": 2
    },
    {
      "x": -5,
      "y": 7,
      "z": 1,
      "name": "Rock_Crystal_White_Block"
    },
    {
      "x": -5,
      "y": 8,
      "z": 1,
      "name": "Rock_Crystal_White_Block",
      "rotation": 2
    },
    {
      "x": -5,
      "y": 10,
      "z": 2,
      "name": "Rock_Crystal_White_Block",
      "rotation": 2
    },
    {
      "x": -5,
      "y": 11,
      "z": 2,
      "name": "Rock_Crystal_White_Block",
      "rotation": 2
    },
    {
      "x": -5,
      "y": 12,
      "z": 2,
      "name": "Rock_Crystal_White_Block",
      "rotation": 2
    },
    {
      "x": -5,
      "y": 15,
      "z": 3,
      "name": "Rock_Crystal_White_Block",
      "rotation": 2
    },
    {
      "x": -5,
      "y": 17,
      "z": 3,
      "name": "Rock_Crystal_White_Block",
      "rotation": 2
    },
    {
      "x": -5,
      "y": 18,
      "z": 3,
      "name": "Rock_Crystal_White_Block",
      "rotation": 2
    },
    {
      "x": -5,
      "y": 16,
      "z": 4,
      "name": "Rock_Crystal_White_Block",
      "rotation": 2
    },
    {
      "x": -5,
      "y": 17,
      "z": 4,
      "name": "Rock_Crystal_White_Block",
      "rotation": 2
    },
    {
      "x": -5,
      "y": 18,
      "z": 4,
      "name": "Rock_Crystal_White_Block",
      "rotation": 2
    },
    {
      "x": -5,
      "y": 16,
      "z": 5,
      "name": "Rock_Crystal_White_Block",
      "rotation": 2
    },
    {
      "x": -5,
      "y": 17,
      "z": 5,
      "name": "Rock_Crystal_White_Block",
      "rotation": 2
    },
    {
      "x": -5,
      "y": 18,
      "z": 5,
      "name": "Rock_Crystal_White_Block",
      "rotation": 2
    },
    {
      "x": -5,
      "y": 13,
      "z": 6,
      "name": "Rock_Crystal_White_Block",
      "rotation": 2
    },
    {
      "x": -5,
      "y": 14,
      "z": 6,
      "name": "Rock_Crystal_White_Block",
      "rotation": 2
    },
    {
      "x": -5,
      "y": 15,
      "z": 6,
      "name": "Rock_Crystal_White_Block",
      "rotation": 2
    },
    {
      "x": -5,
      "y": 16,
      "z": 6,
      "name": "Rock_Crystal_White_Block",
      "rotation": 2
    },
    {
      "x": -5,
      "y": 17,
      "z": 6,
      "name": "Rock_Crystal_White_Block",
      "rotation": 2
    },
    {
      "x": -5,
      "y": 15,
      "z": 7,
      "name": "Rock_Crystal_White_Block",
      "rotation": 2
    },
    {
      "x": -5,
      "y": 17,
      "z": 7,
      "name": "Rock_Crystal_White_Block",
      "rotation": 2
    },
    {
      "x": -5,
      "y": 18,
      "z": 7,
      "name": "Rock_Crystal_White_Block",
      "rotation": 2
    },
    {
      "x": -5,
      "y": 15,
      "z": 8,
      "name": "Rock_Crystal_White_Block",
      "rotation": 2
    },
    {
      "x": -5,
      "y": 19,
      "z": 8,
      "name": "Rock_Crystal_White_Block",
      "rotation": 2
    },
    {
      "x": -5,
      "y": 15,
      "z": 9,
      "name": "Rock_Crystal_White_Block",
      "rotation": 2
    },
    {
      "x": -5,
      "y": 20,
      "z": 9,
      "name": "Rock_Crystal_White_Block",
      "rotation": 2
    },
    {
      "x": -5,
      "y": 18,
      "z": 10,
      "name": "Rock_Crystal_White_Block",
      "rotation": 2
    },
    {
      "x": -5,
      "y": 22,
      "z": 10,
      "name": "Rock_Crystal_White_Block",
      "rotation": 2
    },
    {
      "x": -5,
      "y": 23,
      "z": 12,
      "name": "Rock_Crystal_White_Block",
      "rotation": 2
    },
    {
      "x": -5,
      "y": 25,
      "z": 13,
      "name": "Rock_Crystal_White_Block",
      "rotation": 2
    },
    {
      "x": -4,
      "y": 7,
      "z": -4,
      "name": "Rock_Crystal_White_Block"
    },
    {
      "x": -4,
      "y": 7,
      "z": -3,
      "name": "Rock_Crystal_White_Block"
    },
    {
      "x": -4,
      "y": 10,
      "z": -2,
      "name": "Rock_Crystal_White_Block"
    },
    {
      "x": -4,
      "y": 8,
      "z": -1,
      "name": "Rock_Crystal_White_Block"
    },
    {
      "x": -4,
      "y": 9,
      "z": -1,
      "name": "Rock_Crystal_White_Block"
    },
    {
      "x": -4,
      "y": 11,
      "z": -1,
      "name": "Rock_Crystal_White_Block"
    },
    {
      "x": -4,
      "y": 13,
      "z": -1,
      "name": "Rock_Crystal_White_Block"
    },
    {
      "x": -4,
      "y": 14,
      "z": -1,
      "name": "Rock_Crystal_White_Block"
    },
    {
      "x": -4,
      "y": 15,
      "z": -1,
      "name": "Rock_Crystal_White_Block"
    },
    {
      "x": -4,
      "y": 8,
      "z": 0,
      "name": "Rock_Crystal_White_Block"
    },
    {
      "x": -4,
      "y": 10,
      "z": 0,
      "name": "Rock_Crystal_White_Block"
    },
    {
      "x": -4,
      "y": 11,
      "z": 0,
      "name": "Rock_Crystal_White_Block"
    },
    {
      "x": -4,
      "y": 12,
      "z": 0,
      "name": "Rock_Crystal_White_Block"
    },
    {
      "x": -4,
      "y": 13,
      "z": 0,
      "name": "Rock_Crystal_White_Block"
    },
    {
      "x": -4,
      "y": 7,
      "z": 1,
      "name": "Rock_Crystal_White_Block"
    },
    {
      "x": -4,
      "y": 8,
      "z": 1,
      "name": "Rock_Crystal_White_Block"
    },
    {
      "x": -4,
      "y": 9,
      "z": 1,
      "name": "Rock_Crystal_White_Block"
    },
    {
      "x": -4,
      "y": 11,
      "z": 1,
      "name": "Rock_Crystal_White_Block",
      "rotation": 2
    },
    {
      "x": -4,
      "y": 12,
      "z": 1,
      "name": "Rock_Crystal_White_Block",
      "rotation": 2
    },
    {
      "x": -4,
      "y": 13,
      "z": 1,
      "name": "Rock_Crystal_White_Block",
      "rotation": 2
    },
    {
      "x": -4,
      "y": 13,
      "z": 2,
      "name": "Rock_Crystal_White_Block",
      "rotation": 2
    },
    {
      "x": -4,
      "y": 15,
      "z": 3,
      "name": "Rock_Crystal_White_Block",
      "rotation": 2
    },
    {
      "x": -4,
      "y": 18,
      "z": 3,
      "name": "Rock_Crystal_White_Block",
      "rotation": 2
    },
    {
      "x": -4,
      "y": 14,
      "z": 4,
      "name": "Rock_Crystal_White_Block",
      "rotation": 2
    },
    {
      "x": -4,
      "y": 15,
      "z": 4,
      "name": "Rock_Crystal_White_Block",
      "rotation": 2
    },
    {
      "x": -4,
      "y": 16,
      "z": 4,
      "name": "Rock_Crystal_White_Block",
      "rotation": 2
    },
    {
      "x": -4,
      "y": 17,
      "z": 4,
      "name": "Rock_Crystal_White_Block",
      "rotation": 2
    },
    {
      "x": -4,
      "y": 19,
      "z": 4,
      "name": "Rock_Crystal_White_Block",
      "rotation": 2
    },
    {
      "x": -4,
      "y": 16,
      "z": 5,
      "name": "Rock_Crystal_White_Block",
      "rotation": 2
    },
    {
      "x": -4,
      "y": 17,
      "z": 5,
      "name": "Rock_Crystal_White_Block",
      "rotation": 2
    },
    {
      "x": -4,
      "y": 18,
      "z": 5,
      "name": "Rock_Crystal_White_Block",
      "rotation": 2
    },
    {
      "x": -4,
      "y": 17,
      "z": 6,
      "name": "Rock_Crystal_White_Block",
      "rotation": 2
    },
    {
      "x": -4,
      "y": 18,
      "z": 6,
      "name": "Rock_Crystal_White_Block",
      "rotation": 2
    },
    {
      "x": -4,
      "y": 19,
      "z": 6,
      "name": "Rock_Crystal_White_Block",
      "rotation": 2
    },
    {
      "x": -4,
      "y": 16,
      "z": 7,
      "name": "Rock_Crystal_White_Block",
      "rotation": 2
    },
    {
      "x": -4,
      "y": 17,
      "z": 7,
      "name": "Rock_Crystal_White_Block",
      "rotation": 2
    },
    {
      "x": -4,
      "y": 19,
      "z": 7,
      "name": "Rock_Crystal_White_Block",
      "rotation": 2
    },
    {
      "x": -4,
      "y": 15,
      "z": 8,
      "name": "Rock_Crystal_White_Block",
      "rotation": 2
    },
    {
      "x": -4,
      "y": 17,
      "z": 8,
      "name": "Rock_Crystal_White_Block",
      "rotation": 2
    },
    {
      "x": -4,
      "y": 18,
      "z": 8,
      "name": "Rock_Crystal_White_Block",
      "rotation": 2
    },
    {
      "x": -4,
      "y": 20,
      "z": 8,
      "name": "Rock_Crystal_White_Block",
      "rotation": 2
    },
    {
      "x": -4,
      "y": 21,
      "z": 9,
      "name": "Rock_Crystal_White_Block",
      "rotation": 2
    },
    {
      "x": -4,
      "y": 24,
      "z": 9,
      "name": "Rock_Crystal_White_Block",
      "rotation": 2
    },
    {
      "x": -4,
      "y": 26,
      "z": 10,
      "name": "Rock_Crystal_White_Block",
      "rotation": 2
    },
    {
      "x": -4,
      "y": 24,
      "z": 11,
      "name": "Rock_Crystal_White_Block",
      "rotation": 2
    },
    {
      "x": -4,
      "y": 27,
      "z": 11,
      "name": "Rock_Crystal_White_Block",
      "rotation": 2
    },
    {
      "x": -4,
      "y": 26,
      "z": 12,
      "name": "Rock_Crystal_White_Block",
      "rotation": 2
    },
    {
      "x": -4,
      "y": 27,
      "z": 12,
      "name": "Rock_Crystal_White_Block",
      "rotation": 2
    },
    {
      "x": -4,
      "y": 28,
      "z": 12,
      "name": "Rock_Crystal_White_Block",
      "rotation": 2
    },
    {
      "x": -4,
      "y": 25,
      "z": 13,
      "name": "Rock_Crystal_White_Block",
      "rotation": 2
    },
    {
      "x": -4,
      "y": 28,
      "z": 13,
      "name": "Rock_Crystal_White_Block",
      "rotation": 2
    },
    {
      "x": -4,
      "y": 27,
      "z": 14,
      "name": "Rock_Crystal_White_Block",
      "rotation": 2
    },
    {
      "x": -4,
      "y": 29,
      "z": 15,
      "name": "Rock_Crystal_White_Block",
      "rotation": 2
    },
    {
      "x": -3,
      "y": 8,
      "z": -4,
      "name": "Rock_Crystal_White_Block"
    },
    {
      "x": -3,
      "y": 9,
      "z": -4,
      "name": "Rock_Crystal_White_Block"
    },
    {
      "x": -3,
      "y": 9,
      "z": -3,
      "name": "Rock_Crystal_White_Block"
    },
    {
      "x": -3,
      "y": 10,
      "z": -2,
      "name": "Rock_Crystal_White_Block"
    },
    {
      "x": -3,
      "y": 11,
      "z": -2,
      "name": "Rock_Crystal_White_Block"
    },
    {
      "x": -3,
      "y": 9,
      "z": -1,
      "name": "Rock_Crystal_White_Block"
    },
    {
      "x": -3,
      "y": 11,
      "z": -1,
      "name": "Rock_Crystal_White_Block"
    },
    {
      "x": -3,
      "y": 12,
      "z": -1,
      "name": "Rock_Crystal_White_Block"
    },
    {
      "x": -3,
      "y": 13,
      "z": -1,
      "name": "Rock_Crystal_White_Block"
    },
    {
      "x": -3,
      "y": 15,
      "z": -1,
      "name": "Rock_Crystal_White_Block"
    },
    {
      "x": -3,
      "y": 16,
      "z": -1,
      "name": "Rock_Crystal_White_Block"
    },
    {
      "x": -3,
      "y": 17,
      "z": -1,
      "name": "Rock_Crystal_White_Block"
    },
    {
      "x": -3,
      "y": 10,
      "z": 0,
      "name": "Rock_Crystal_White_Block"
    },
    {
      "x": -3,
      "y": 11,
      "z": 0,
      "name": "Rock_Crystal_White_Block"
    },
    {
      "x": -3,
      "y": 12,
      "z": 0,
      "name": "Rock_Crystal_White_Block"
    },
    {
      "x": -3,
      "y": 13,
      "z": 0,
      "name": "Rock_Crystal_White_Block"
    },
    {
      "x": -3,
      "y": 14,
      "z": 0,
      "name": "Rock_Crystal_White_Block"
    },
    {
      "x": -3,
      "y": 15,
      "z": 0,
      "name": "Rock_Crystal_White_Block",
      "rotation": 2
    },
    {
      "x": -3,
      "y": 16,
      "z": 0,
      "name": "Rock_Crystal_White_Block"
    },
    {
      "x": -3,
      "y": 17,
      "z": 0,
      "name": "Rock_Crystal_White_Block"
    },
    {
      "x": -3,
      "y": 18,
      "z": 0,
      "name": "Rock_Crystal_White_Block"
    },
    {
      "x": -3,
      "y": 9,
      "z": 1,
      "name": "Rock_Crystal_White_Block"
    },
    {
      "x": -3,
      "y": 10,
      "z": 1,
      "name": "Rock_Crystal_White_Block"
    },
    {
      "x": -3,
      "y": 11,
      "z": 1,
      "name": "Rock_Crystal_White_Block"
    },
    {
      "x": -3,
      "y": 13,
      "z": 1,
      "name": "Rock_Crystal_White_Block",
      "rotation": 2
    },
    {
      "x": -3,
      "y": 14,
      "z": 1,
      "name": "Rock_Crystal_White_Block",
      "rotation": 2
    },
    {
      "x": -3,
      "y": 15,
      "z": 1,
      "name": "Rock_Crystal_White_Block",
      "rotation": 2
    },
    {
      "x": -3,
      "y": 17,
      "z": 1,
      "name": "Rock_Crystal_White_Block"
    },
    {
      "x": -3,
      "y": 19,
      "z": 1,
      "name": "Rock_Crystal_White_Block",
      "rotation": 2
    },
    {
      "x": -3,
      "y": 15,
      "z": 2,
      "name": "Rock_Crystal_White_Block",
      "rotation": 2
    },
    {
      "x": -3,
      "y": 16,
      "z": 2,
      "name": "Rock_Crystal_White_Block",
      "rotation": 2
    },
    {
      "x": -3,
      "y": 19,
      "z": 2,
      "name": "Rock_Crystal_White_Block",
      "rotation": 2
    },
    {
      "x": -3,
      "y": 16,
      "z": 3,
      "name": "Rock_Crystal_White_Block",
      "rotation": 2
    },
    {
      "x": -3,
      "y": 17,
      "z": 3,
      "name": "Rock_Crystal_White_Block",
      "rotation": 2
    },
    {
      "x": -3,
      "y": 18,
      "z": 3,
      "name": "Rock_Crystal_White_Block",
      "rotation": 2
    },
    {
      "x": -3,
      "y": 14,
      "z": 4,
      "name": "Rock_Crystal_White_Block",
      "rotation": 2
    },
    {
      "x": -3,
      "y": 17,
      "z": 4,
      "name": "Rock_Crystal_White_Block",
      "rotation": 2
    },
    {
      "x": -3,
      "y": 18,
      "z": 4,
      "name": "Rock_Crystal_White_Block",
      "rotation": 2
    },
    {
      "x": -3,
      "y": 19,
      "z": 4,
      "name": "Rock_Crystal_White_Block",
      "rotation": 2
    },
    {
      "x": -3,
      "y": 23,
      "z": 4,
      "name": "Rock_Crystal_White_Block",
      "rotation": 2
    },
    {
      "x": -3,
      "y": 16,
      "z": 5,
      "name": "Rock_Crystal_White_Block",
      "rotation": 2
    },
    {
      "x": -3,
      "y": 18,
      "z": 5,
      "name": "Rock_Crystal_White_Block",
      "rotation": 2
    },
    {
      "x": -3,
      "y": 24,
      "z": 5,
      "name": "Rock_Crystal_White_Block",
      "rotation": 2
    },
    {
      "x": -3,
      "y": 16,
      "z": 6,
      "name": "Rock_Crystal_White_Block",
      "rotation": 2
    },
    {
      "x": -3,
      "y": 17,
      "z": 6,
      "name": "Rock_Crystal_White_Block",
      "rotation": 2
    },
    {
      "x": -3,
      "y": 18,
      "z": 6,
      "name": "Rock_Crystal_White_Block",
      "rotation": 2
    },
    {
      "x": -3,
      "y": 19,
      "z": 6,
      "name": "Rock_Crystal_White_Block",
      "rotation": 2
    },
    {
      "x": -3,
      "y": 23,
      "z": 6,
      "name": "Rock_Crystal_White_Block",
      "rotation": 2
    },
    {
      "x": -3,
      "y": 25,
      "z": 6,
      "name": "Rock_Crystal_White_Block",
      "rotation": 2
    },
    {
      "x": -3,
      "y": 21,
      "z": 7,
      "name": "Rock_Crystal_White_Block",
      "rotation": 2
    },
    {
      "x": -3,
      "y": 25,
      "z": 7,
      "name": "Rock_Crystal_White_Block",
      "rotation": 2
    },
    {
      "x": -3,
      "y": 26,
      "z": 7,
      "name": "Rock_Crystal_White_Block",
      "rotation": 2
    },
    {
      "x": -3,
      "y": 22,
      "z": 8,
      "name": "Rock_Crystal_White_Block",
      "rotation": 2
    },
    {
      "x": -3,
      "y": 24,
      "z": 8,
      "name": "Rock_Crystal_White_Block",
      "rotation": 2
    },
    {
      "x": -3,
      "y": 27,
      "z": 8,
      "name": "Rock_Crystal_White_Block",
      "rotation": 2
    },
    {
      "x": -3,
      "y": 28,
      "z": 9,
      "name": "Rock_Crystal_White_Block",
      "rotation": 2
    },
    {
      "x": -3,
      "y": 23,
      "z": 10,
      "name": "Rock_Crystal_White_Block",
      "rotation": 2
    },
    {
      "x": -3,
      "y": 25,
      "z": 10,
      "name": "Rock_Crystal_White_Block",
      "rotation": 2
    },
    {
      "x": -3,
      "y": 26,
      "z": 10,
      "name": "Rock_Crystal_White_Block",
      "rotation": 2
    },
    {
      "x": -3,
      "y": 28,
      "z": 10,
      "name": "Rock_Crystal_White_Block",
      "rotation": 2
    },
    {
      "x": -3,
      "y": 28,
      "z": 11,
      "name": "Rock_Crystal_White_Block",
      "rotation": 2
    },
    {
      "x": -3,
      "y": 26,
      "z": 12,
      "name": "Rock_Crystal_White_Block",
      "rotation": 2
    },
    {
      "x": -3,
      "y": 27,
      "z": 12,
      "name": "Rock_Crystal_White_Block",
      "rotation": 2
    },
    {
      "x": -3,
      "y": 29,
      "z": 12,
      "name": "Rock_Crystal_White_Block",
      "rotation": 2
    },
    {
      "x": -3,
      "y": 30,
      "z": 12,
      "name": "Rock_Crystal_White_Block",
      "rotation": 2
    },
    {
      "x": -3,
      "y": 28,
      "z": 13,
      "name": "Rock_Crystal_White_Block",
      "rotation": 2
    },
    {
      "x": -3,
      "y": 31,
      "z": 13,
      "name": "Rock_Crystal_White_Block",
      "rotation": 2
    },
    {
      "x": -3,
      "y": 30,
      "z": 14,
      "name": "Rock_Crystal_White_Block",
      "rotation": 2
    },
    {
      "x": -3,
      "y": 29,
      "z": 15,
      "name": "Rock_Crystal_White_Block",
      "rotation": 2
    },
    {
      "x": -2,
      "y": 8,
      "z": -6,
      "name": "Rock_Crystal_White_Block"
    },
    {
      "x": -2,
      "y": 11,
      "z": -6,
      "name": "Rock_Crystal_White_Block"
    },
    {
      "x": -2,
      "y": 10,
      "z": -4,
      "name": "Rock_Crystal_White_Block"
    },
    {
      "x": -2,
      "y": 13,
      "z": -4,
      "name": "Rock_Crystal_White_Block"
    },
    {
      "x": -2,
      "y": 11,
      "z": -3,
      "name": "Rock_Crystal_White_Block"
    },
    {
      "x": -2,
      "y": 19,
      "z": -3,
      "name": "Rock_Crystal_White_Block"
    },
    {
      "x": -2,
      "y": 12,
      "z": -2,
      "name": "Rock_Crystal_White_Block"
    },
    {
      "x": -2,
      "y": 17,
      "z": -2,
      "name": "Rock_Crystal_White_Block"
    },
    {
      "x": -2,
      "y": 18,
      "z": -2,
      "name": "Rock_Crystal_White_Block"
    },
    {
      "x": -2,
      "y": 19,
      "z": -2,
      "name": "Rock_Crystal_White_Block"
    },
    {
      "x": -2,
      "y": 20,
      "z": -2,
      "name": "Rock_Crystal_White_Block",
      "rotation": 2
    },
    {
      "x": -2,
      "y": 13,
      "z": -1,
      "name": "Rock_Crystal_White_Block"
    },
    {
      "x": -2,
      "y": 14,
      "z": -1,
      "name": "Rock_Crystal_White_Block"
    },
    {
      "x": -2,
      "y": 15,
      "z": -1,
      "name": "Rock_Crystal_White_Block"
    },
    {
      "x": -2,
      "y": 16,
      "z": -1,
      "name": "Rock_Crystal_White_Block"
    },
    {
      "x": -2,
      "y": 17,
      "z": -1,
      "name": "Rock_Crystal_White_Block"
    },
    {
      "x": -2,
      "y": 18,
      "z": -1,
      "name": "Rock_Crystal_White_Block"
    },
    {
      "x": -2,
      "y": 19,
      "z": -1,
      "name": "Rock_Crystal_White_Block"
    },
    {
      "x": -2,
      "y": 12,
      "z": 0,
      "name": "Rock_Crystal_White_Block"
    },
    {
      "x": -2,
      "y": 13,
      "z": 0,
      "name": "Rock_Crystal_White_Block"
    },
    {
      "x": -2,
      "y": 14,
      "z": 0,
      "name": "Rock_Crystal_White_Block"
    },
    {
      "x": -2,
      "y": 15,
      "z": 0,
      "name": "Rock_Crystal_White_Block"
    },
    {
      "x": -2,
      "y": 16,
      "z": 0,
      "name": "Rock_Crystal_White_Block"
    },
    {
      "x": -2,
      "y": 17,
      "z": 0,
      "name": "Rock_Crystal_White_Block",
      "rotation": 2
    },
    {
      "x": -2,
      "y": 18,
      "z": 0,
      "name": "Rock_Crystal_White_Block",
      "rotation": 2
    },
    {
      "x": -2,
      "y": 19,
      "z": 0,
      "name": "Rock_Crystal_White_Block",
      "rotation": 2
    },
    {
      "x": -2,
      "y": 20,
      "z": 0,
      "name": "Rock_Crystal_White_Block",
      "rotation": 2
    },
    {
      "x": -2,
      "y": 10,
      "z": 1,
      "name": "Rock_Crystal_White_Block"
    },
    {
      "x": -2,
      "y": 11,
      "z": 1,
      "name": "Rock_Crystal_White_Block"
    },
    {
      "x": -2,
      "y": 12,
      "z": 1,
      "name": "Rock_Crystal_White_Block"
    },
    {
      "x": -2,
      "y": 13,
      "z": 1,
      "name": "Rock_Crystal_White_Block"
    },
    {
      "x": -2,
      "y": 14,
      "z": 1,
      "name": "Rock_Crystal_White_Block",
      "rotation": 2
    },
    {
      "x": -2,
      "y": 15,
      "z": 1,
      "name": "Rock_Crystal_White_Block",
      "rotation": 2
    },
    {
      "x": -2,
      "y": 16,
      "z": 1,
      "name": "Rock_Crystal_White_Block",
      "rotation": 2
    },
    {
      "x": -2,
      "y": 17,
      "z": 1,
      "name": "Rock_Crystal_White_Block",
      "rotation": 2
    },
    {
      "x": -2,
      "y": 18,
      "z": 1,
      "name": "Rock_Crystal_White_Block",
      "rotation": 2
    },
    {
      "x": -2,
      "y": 19,
      "z": 1,
      "name": "Rock_Crystal_White_Block",
      "rotation": 2
    },
    {
      "x": -2,
      "y": 20,
      "z": 1,
      "name": "Rock_Crystal_White_Block",
      "rotation": 2
    },
    {
      "x": -2,
      "y": 17,
      "z": 2,
      "name": "Rock_Crystal_White_Block",
      "rotation": 2
    },
    {
      "x": -2,
      "y": 18,
      "z": 2,
      "name": "Rock_Crystal_White_Block",
      "rotation": 2
    },
    {
      "x": -2,
      "y": 20,
      "z": 2,
      "name": "Rock_Crystal_White_Block",
      "rotation": 2
    },
    {
      "x": -2,
      "y": 22,
      "z": 2,
      "name": "Rock_Crystal_White_Block",
      "rotation": 2
    },
    {
      "x": -2,
      "y": 16,
      "z": 3,
      "name": "Rock_Crystal_White_Block",
      "rotation": 2
    },
    {
      "x": -2,
      "y": 17,
      "z": 3,
      "name": "Rock_Crystal_White_Block",
      "rotation": 2
    },
    {
      "x": -2,
      "y": 18,
      "z": 3,
      "name": "Rock_Crystal_White_Block",
      "rotation": 2
    },
    {
      "x": -2,
      "y": 19,
      "z": 3,
      "name": "Rock_Crystal_White_Block",
      "rotation": 2
    },
    {
      "x": -2,
      "y": 21,
      "z": 3,
      "name": "Rock_Crystal_White_Block",
      "rotation": 2
    },
    {
      "x": -2,
      "y": 22,
      "z": 3,
      "name": "Rock_Crystal_White_Block",
      "rotation": 2
    },
    {
      "x": -2,
      "y": 23,
      "z": 3,
      "name": "Rock_Crystal_White_Block",
      "rotation": 2
    },
    {
      "x": -2,
      "y": 17,
      "z": 4,
      "name": "Rock_Crystal_White_Block",
      "rotation": 2
    },
    {
      "x": -2,
      "y": 20,
      "z": 4,
      "name": "Rock_Crystal_White_Block",
      "rotation": 2
    },
    {
      "x": -2,
      "y": 23,
      "z": 4,
      "name": "Rock_Crystal_White_Block",
      "rotation": 2
    },
    {
      "x": -2,
      "y": 16,
      "z": 5,
      "name": "Rock_Crystal_White_Block",
      "rotation": 2
    },
    {
      "x": -2,
      "y": 18,
      "z": 5,
      "name": "Rock_Crystal_White_Block",
      "rotation": 2
    },
    {
      "x": -2,
      "y": 21,
      "z": 5,
      "name": "Rock_Crystal_White_Block",
      "rotation": 2
    },
    {
      "x": -2,
      "y": 22,
      "z": 5,
      "name": "Rock_Crystal_White_Block",
      "rotation": 2
    },
    {
      "x": -2,
      "y": 23,
      "z": 5,
      "name": "Rock_Crystal_White_Block",
      "rotation": 2
    },
    {
      "x": -2,
      "y": 24,
      "z": 5,
      "name": "Rock_Crystal_White_Block",
      "rotation": 2
    },
    {
      "x": -2,
      "y": 16,
      "z": 6,
      "name": "Rock_Crystal_White_Block",
      "rotation": 2
    },
    {
      "x": -2,
      "y": 21,
      "z": 6,
      "name": "Rock_Crystal_White_Block",
      "rotation": 2
    },
    {
      "x": -2,
      "y": 22,
      "z": 6,
      "name": "Rock_Crystal_White_Block",
      "rotation": 2
    },
    {
      "x": -2,
      "y": 25,
      "z": 6,
      "name": "Rock_Crystal_White_Block",
      "rotation": 2
    },
    {
      "x": -2,
      "y": 23,
      "z": 7,
      "name": "Rock_Crystal_White_Block",
      "rotation": 2
    },
    {
      "x": -2,
      "y": 25,
      "z": 7,
      "name": "Rock_Crystal_White_Block",
      "rotation": 2
    },
    {
      "x": -2,
      "y": 21,
      "z": 8,
      "name": "Rock_Crystal_White_Block",
      "rotation": 2
    },
    {
      "x": -2,
      "y": 22,
      "z": 8,
      "name": "Rock_Crystal_White_Block",
      "rotation": 2
    },
    {
      "x": -2,
      "y": 24,
      "z": 8,
      "name": "Rock_Crystal_White_Block",
      "rotation": 2
    },
    {
      "x": -2,
      "y": 26,
      "z": 8,
      "name": "Rock_Crystal_White_Block",
      "rotation": 2
    },
    {
      "x": -2,
      "y": 24,
      "z": 9,
      "name": "Rock_Crystal_White_Block",
      "rotation": 2
    },
    {
      "x": -2,
      "y": 25,
      "z": 9,
      "name": "Rock_Crystal_White_Block",
      "rotation": 2
    },
    {
      "x": -2,
      "y": 26,
      "z": 9,
      "name": "Rock_Crystal_White_Block",
      "rotation": 2
    },
    {
      "x": -2,
      "y": 27,
      "z": 9,
      "name": "Rock_Crystal_White_Block",
      "rotation": 2
    },
    {
      "x": -2,
      "y": 23,
      "z": 10,
      "name": "Rock_Crystal_White_Block",
      "rotation": 2
    },
    {
      "x": -2,
      "y": 25,
      "z": 10,
      "name": "Rock_Crystal_White_Block",
      "rotation": 2
    },
    {
      "x": -2,
      "y": 26,
      "z": 10,
      "name": "Rock_Crystal_White_Block",
      "rotation": 2
    },
    {
      "x": -2,
      "y": 27,
      "z": 10,
      "name": "Rock_Crystal_White_Block",
      "rotation": 2
    },
    {
      "x": -2,
      "y": 29,
      "z": 10,
      "name": "Rock_Crystal_White_Block",
      "rotation": 2
    },
    {
      "x": -2,
      "y": 25,
      "z": 11,
      "name": "Rock_Crystal_White_Block",
      "rotation": 2
    },
    {
      "x": -2,
      "y": 27,
      "z": 11,
      "name": "Rock_Crystal_White_Block",
      "rotation": 2
    },
    {
      "x": -2,
      "y": 28,
      "z": 11,
      "name": "Rock_Crystal_White_Block",
      "rotation": 2
    },
    {
      "x": -2,
      "y": 28,
      "z": 12,
      "name": "Rock_Crystal_White_Block",
      "rotation": 2
    },
    {
      "x": -2,
      "y": 29,
      "z": 12,
      "name": "Rock_Crystal_White_Block",
      "rotation": 2
    },
    {
      "x": -2,
      "y": 30,
      "z": 12,
      "name": "Rock_Crystal_White_Block",
      "rotation": 2
    },
    {
      "x": -2,
      "y": 29,
      "z": 13,
      "name": "Rock_Crystal_White_Block",
      "rotation": 2
    },
    {
      "x": -2,
      "y": 30,
      "z": 13,
      "name": "Rock_Crystal_White_Block",
      "rotation": 2
    },
    {
      "x": -2,
      "y": 30,
      "z": 14,
      "name": "Rock_Crystal_White_Block",
      "rotation": 2
    },
    {
      "x": -2,
      "y": 31,
      "z": 14,
      "name": "Rock_Crystal_White_Block",
      "rotation": 2
    },
    {
      "x": -2,
      "y": 31,
      "z": 15,
      "name": "Rock_Crystal_White_Block",
      "rotation": 2
    },
    {
      "x": -2,
      "y": 32,
      "z": 15,
      "name": "Rock_Crystal_White_Block",
      "rotation": 2
    },
    {
      "x": -2,
      "y": 32,
      "z": 16,
      "name": "Rock_Crystal_White_Block",
      "rotation": 2
    },
    {
      "x": -1,
      "y": 9,
      "z": -9,
      "name": "Rock_Crystal_White_Block"
    },
    {
      "x": -1,
      "y": 7,
      "z": -8,
      "name": "Rock_Crystal_White_Block"
    },
    {
      "x": -1,
      "y": 8,
      "z": -8,
      "name": "Rock_Crystal_White_Block"
    },
    {
      "x": -1,
      "y": 10,
      "z": -8,
      "name": "Rock_Crystal_White_Block"
    },
    {
      "x": -1,
      "y": 10,
      "z": -7,
      "name": "Rock_Crystal_White_Block"
    },
    {
      "x": -1,
      "y": 9,
      "z": -6,
      "name": "Rock_Crystal_White_Block"
    },
    {
      "x": -1,
      "y": 12,
      "z": -6,
      "name": "Rock_Crystal_White_Block"
    },
    {
      "x": -1,
      "y": 15,
      "z": -6,
      "name": "Rock_Crystal_White_Block"
    },
    {
      "x": -1,
      "y": 10,
      "z": -5,
      "name": "Rock_Crystal_White_Block"
    },
    {
      "x": -1,
      "y": 11,
      "z": -5,
      "name": "Rock_Crystal_White_Block"
    },
    {
      "x": -1,
      "y": 15,
      "z": -5,
      "name": "Rock_Crystal_White_Block"
    },
    {
      "x": -1,
      "y": 16,
      "z": -5,
      "name": "Rock_Crystal_White_Block"
    },
    {
      "x": -1,
      "y": 13,
      "z": -4,
      "name": "Rock_Crystal_White_Block"
    },
    {
      "x": -1,
      "y": 16,
      "z": -4,
      "name": "Rock_Crystal_White_Block"
    },
    {
      "x": -1,
      "y": 17,
      "z": -4,
      "name": "Rock_Crystal_White_Block"
    },
    {
      "x": -1,
      "y": 12,
      "z": -3,
      "name": "Rock_Crystal_White_Block"
    },
    {
      "x": -1,
      "y": 15,
      "z": -3,
      "name": "Rock_Crystal_White_Block"
    },
    {
      "x": -1,
      "y": 17,
      "z": -3,
      "name": "Rock_Crystal_White_Block"
    },
    {
      "x": -1,
      "y": 18,
      "z": -3,
      "name": "Rock_Crystal_White_Block"
    },
    {
      "x": -1,
      "y": 14,
      "z": -2,
      "name": "Rock_Crystal_White_Block"
    },
    {
      "x": -1,
      "y": 16,
      "z": -2,
      "name": "Rock_Crystal_White_Block"
    },
    {
      "x": -1,
      "y": 17,
      "z": -2,
      "name": "Rock_Crystal_White_Block"
    },
    {
      "x": -1,
      "y": 18,
      "z": -2,
      "name": "Rock_Crystal_White_Block"
    },
    {
      "x": -1,
      "y": 19,
      "z": -2,
      "name": "Rock_Crystal_White_Block"
    },
    {
      "x": -1,
      "y": 14,
      "z": -1,
      "name": "Rock_Crystal_White_Block"
    },
    {
      "x": -1,
      "y": 15,
      "z": -1,
      "name": "Rock_Crystal_White_Block"
    },
    {
      "x": -1,
      "y": 16,
      "z": -1,
      "name": "Rock_Crystal_White_Block"
    },
    {
      "x": -1,
      "y": 17,
      "z": -1,
      "name": "Rock_Crystal_White_Block"
    },
    {
      "x": -1,
      "y": 18,
      "z": -1,
      "name": "Rock_Crystal_White_Block"
    },
    {
      "x": -1,
      "y": 19,
      "z": -1,
      "name": "Rock_Crystal_White_Block"
    },
    {
      "x": -1,
      "y": 20,
      "z": -1,
      "name": "Rock_Crystal_White_Block",
      "rotation": 2
    },
    {
      "x": -1,
      "y": 14,
      "z": 0,
      "name": "Rock_Crystal_White_Block"
    },
    {
      "x": -1,
      "y": 15,
      "z": 0,
      "name": "Rock_Crystal_White_Block"
    },
    {
      "x": -1,
      "y": 16,
      "z": 0,
      "name": "Rock_Crystal_White_Block"
    },
    {
      "x": -1,
      "y": 17,
      "z": 0,
      "name": "Rock_Crystal_White_Block"
    },
    {
      "x": -1,
      "y": 18,
      "z": 0,
      "name": "Rock_Crystal_White_Block"
    },
    {
      "x": -1,
      "y": 19,
      "z": 0,
      "name": "Rock_Crystal_White_Block",
      "rotation": 2
    },
    {
      "x": -1,
      "y": 20,
      "z": 0,
      "name": "Rock_Crystal_White_Block",
      "rotation": 2
    },
    {
      "x": -1,
      "y": 21,
      "z": 0,
      "name": "Rock_Crystal_White_Block"
    },
    {
      "x": -1,
      "y": 12,
      "z": 1,
      "name": "Rock_Crystal_White_Block"
    },
    {
      "x": -1,
      "y": 13,
      "z": 1,
      "name": "Rock_Crystal_White_Block"
    },
    {
      "x": -1,
      "y": 14,
      "z": 1,
      "name": "Rock_Crystal_White_Block"
    },
    {
      "x": -1,
      "y": 15,
      "z": 1,
      "name": "Rock_Crystal_White_Block"
    },
    {
      "x": -1,
      "y": 16,
      "z": 1,
      "name": "Rock_Crystal_White_Block",
      "rotation": 2
    },
    {
      "x": -1,
      "y": 17,
      "z": 1,
      "name": "Rock_Crystal_White_Block",
      "rotation": 2
    },
    {
      "x": -1,
      "y": 18,
      "z": 1,
      "name": "Rock_Crystal_White_Block",
      "rotation": 2
    },
    {
      "x": -1,
      "y": 19,
      "z": 1,
      "name": "Rock_Crystal_White_Block",
      "rotation": 2
    },
    {
      "x": -1,
      "y": 20,
      "z": 1,
      "name": "Rock_Crystal_White_Block",
      "rotation": 2
    },
    {
      "x": -1,
      "y": 16,
      "z": 2,
      "name": "Rock_Crystal_White_Block"
    },
    {
      "x": -1,
      "y": 17,
      "z": 2,
      "name": "Rock_Crystal_White_Block",
      "rotation": 2
    },
    {
      "x": -1,
      "y": 18,
      "z": 2,
      "name": "Rock_Crystal_White_Block",
      "rotation": 2
    },
    {
      "x": -1,
      "y": 19,
      "z": 2,
      "name": "Rock_Crystal_White_Block",
      "rotation": 2
    },
    {
      "x": -1,
      "y": 20,
      "z": 2,
      "name": "Rock_Crystal_White_Block",
      "rotation": 2
    },
    {
      "x": -1,
      "y": 22,
      "z": 2,
      "name": "Rock_Crystal_White_Block",
      "rotation": 2
    },
    {
      "x": -1,
      "y": 17,
      "z": 3,
      "name": "Rock_Crystal_White_Block",
      "rotation": 2
    },
    {
      "x": -1,
      "y": 18,
      "z": 3,
      "name": "Rock_Crystal_White_Block",
      "rotation": 2
    },
    {
      "x": -1,
      "y": 20,
      "z": 3,
      "name": "Rock_Crystal_White_Block",
      "rotation": 2
    },
    {
      "x": -1,
      "y": 21,
      "z": 3,
      "name": "Rock_Crystal_White_Block",
      "rotation": 2
    },
    {
      "x": -1,
      "y": 19,
      "z": 4,
      "name": "Rock_Crystal_White_Block"
    },
    {
      "x": -1,
      "y": 20,
      "z": 4,
      "name": "Rock_Crystal_White_Block",
      "rotation": 2
    },
    {
      "x": -1,
      "y": 21,
      "z": 4,
      "name": "Rock_Crystal_White_Block",
      "rotation": 2
    },
    {
      "x": -1,
      "y": 22,
      "z": 4,
      "name": "Rock_Crystal_White_Block",
      "rotation": 2
    },
    {
      "x": -1,
      "y": 23,
      "z": 4,
      "name": "Rock_Crystal_White_Block",
      "rotation": 2
    },
    {
      "x": -1,
      "y": 20,
      "z": 5,
      "name": "Rock_Crystal_White_Block",
      "rotation": 2
    },
    {
      "x": -1,
      "y": 21,
      "z": 5,
      "name": "Rock_Crystal_White_Block",
      "rotation": 2
    },
    {
      "x": -1,
      "y": 22,
      "z": 5,
      "name": "Rock_Crystal_White_Block",
      "rotation": 2
    },
    {
      "x": -1,
      "y": 23,
      "z": 5,
      "name": "Rock_Crystal_White_Block",
      "rotation": 2
    },
    {
      "x": -1,
      "y": 21,
      "z": 6,
      "name": "Rock_Crystal_White_Block",
      "rotation": 2
    },
    {
      "x": -1,
      "y": 23,
      "z": 6,
      "name": "Rock_Crystal_White_Block",
      "rotation": 2
    },
    {
      "x": -1,
      "y": 24,
      "z": 6,
      "name": "Rock_Crystal_White_Block",
      "rotation": 2
    },
    {
      "x": -1,
      "y": 26,
      "z": 6,
      "name": "Rock_Crystal_White_Block",
      "rotation": 2
    },
    {
      "x": -1,
      "y": 24,
      "z": 7,
      "name": "Rock_Crystal_White_Block",
      "rotation": 2
    },
    {
      "x": -1,
      "y": 25,
      "z": 7,
      "name": "Rock_Crystal_White_Block",
      "rotation": 2
    },
    {
      "x": -1,
      "y": 26,
      "z": 7,
      "name": "Rock_Crystal_White_Block",
      "rotation": 2
    },
    {
      "x": -1,
      "y": 24,
      "z": 8,
      "name": "Rock_Crystal_White_Block",
      "rotation": 2
    },
    {
      "x": -1,
      "y": 25,
      "z": 8,
      "name": "Rock_Crystal_White_Block",
      "rotation": 2
    },
    {
      "x": -1,
      "y": 26,
      "z": 8,
      "name": "Rock_Crystal_White_Block",
      "rotation": 2
    },
    {
      "x": -1,
      "y": 28,
      "z": 8,
      "name": "Rock_Crystal_White_Block",
      "rotation": 2
    },
    {
      "x": -1,
      "y": 25,
      "z": 9,
      "name": "Rock_Crystal_White_Block",
      "rotation": 2
    },
    {
      "x": -1,
      "y": 26,
      "z": 9,
      "name": "Rock_Crystal_White_Block",
      "rotation": 2
    },
    {
      "x": -1,
      "y": 27,
      "z": 9,
      "name": "Rock_Crystal_White_Block",
      "rotation": 2
    },
    {
      "x": -1,
      "y": 25,
      "z": 10,
      "name": "Rock_Crystal_White_Block",
      "rotation": 2
    },
    {
      "x": -1,
      "y": 26,
      "z": 10,
      "name": "Rock_Crystal_White_Block",
      "rotation": 2
    },
    {
      "x": -1,
      "y": 27,
      "z": 10,
      "name": "Rock_Crystal_White_Block",
      "rotation": 2
    },
    {
      "x": -1,
      "y": 28,
      "z": 10,
      "name": "Rock_Crystal_White_Block",
      "rotation": 2
    },
    {
      "x": -1,
      "y": 29,
      "z": 10,
      "name": "Rock_Crystal_White_Block",
      "rotation": 2
    },
    {
      "x": -1,
      "y": 27,
      "z": 11,
      "name": "Rock_Crystal_White_Block",
      "rotation": 2
    },
    {
      "x": -1,
      "y": 28,
      "z": 11,
      "name": "Rock_Crystal_White_Block",
      "rotation": 2
    },
    {
      "x": -1,
      "y": 30,
      "z": 11,
      "name": "Rock_Crystal_White_Block",
      "rotation": 2
    },
    {
      "x": -1,
      "y": 27,
      "z": 12,
      "name": "Rock_Crystal_White_Block",
      "rotation": 2
    },
    {
      "x": -1,
      "y": 28,
      "z": 12,
      "name": "Rock_Crystal_White_Block",
      "rotation": 2
    },
    {
      "x": -1,
      "y": 29,
      "z": 12,
      "name": "Rock_Crystal_White_Block",
      "rotation": 2
    },
    {
      "x": -1,
      "y": 30,
      "z": 12,
      "name": "Rock_Crystal_White_Block",
      "rotation": 2
    },
    {
      "x": -1,
      "y": 28,
      "z": 13,
      "name": "Rock_Crystal_White_Block",
      "rotation": 2
    },
    {
      "x": -1,
      "y": 29,
      "z": 13,
      "name": "Rock_Crystal_White_Block",
      "rotation": 2
    },
    {
      "x": -1,
      "y": 31,
      "z": 13,
      "name": "Rock_Crystal_White_Block",
      "rotation": 2
    },
    {
      "x": -1,
      "y": 29,
      "z": 14,
      "name": "Rock_Crystal_White_Block",
      "rotation": 2
    },
    {
      "x": -1,
      "y": 30,
      "z": 14,
      "name": "Rock_Crystal_White_Block",
      "rotation": 2
    },
    {
      "x": 0,
      "y": 6,
      "z": -12,
      "name": "Rock_Crystal_White_Block"
    },
    {
      "x": 0,
      "y": 7,
      "z": -12,
      "name": "Rock_Crystal_White_Block"
    },
    {
      "x": 0,
      "y": 5,
      "z": -11,
      "name": "Rock_Crystal_White_Block"
    },
    {
      "x": 0,
      "y": 6,
      "z": -11,
      "name": "Rock_Crystal_White_Block"
    },
    {
      "x": 0,
      "y": 8,
      "z": -11,
      "name": "Rock_Crystal_White_Block"
    },
    {
      "x": 0,
      "y": 10,
      "z": -11,
      "name": "Rock_Crystal_White_Block"
    },
    {
      "x": 0,
      "y": 7,
      "z": -10,
      "name": "Rock_Crystal_White_Block"
    },
    {
      "x": 0,
      "y": 10,
      "z": -10,
      "name": "Rock_Crystal_White_Block"
    },
    {
      "x": 0,
      "y": 11,
      "z": -10,
      "name": "Rock_Crystal_White_Block"
    },
    {
      "x": 0,
      "y": 7,
      "z": -9,
      "name": "Rock_Crystal_White_Block"
    },
    {
      "x": 0,
      "y": 9,
      "z": -9,
      "name": "Rock_Crystal_White_Block"
    },
    {
      "x": 0,
      "y": 11,
      "z": -9,
      "name": "Rock_Crystal_White_Block"
    },
    {
      "x": 0,
      "y": 12,
      "z": -9,
      "name": "Rock_Crystal_White_Block"
    },
    {
      "x": 0,
      "y": 8,
      "z": -8,
      "name": "Rock_Crystal_White_Block"
    },
    {
      "x": 0,
      "y": 12,
      "z": -8,
      "name": "Rock_Crystal_White_Block"
    },
    {
      "x": 0,
      "y": 10,
      "z": -7,
      "name": "Rock_Crystal_White_Block"
    },
    {
      "x": 0,
      "y": 11,
      "z": -7,
      "name": "Rock_Crystal_White_Block"
    },
    {
      "x": 0,
      "y": 12,
      "z": -7,
      "name": "Rock_Crystal_White_Block"
    },
    {
      "x": 0,
      "y": 13,
      "z": -7,
      "name": "Rock_Crystal_White_Block"
    },
    {
      "x": 0,
      "y": 12,
      "z": -6,
      "name": "Rock_Crystal_White_Block"
    },
    {
      "x": 0,
      "y": 14,
      "z": -6,
      "name": "Rock_Crystal_White_Block"
    },
    {
      "x": 0,
      "y": 15,
      "z": -6,
      "name": "Rock_Crystal_White_Block"
    },
    {
      "x": 0,
      "y": 10,
      "z": -5,
      "name": "Rock_Crystal_White_Block"
    },
    {
      "x": 0,
      "y": 11,
      "z": -5,
      "name": "Rock_Crystal_White_Block"
    },
    {
      "x": 0,
      "y": 13,
      "z": -5,
      "name": "Rock_Crystal_White_Block"
    },
    {
      "x": 0,
      "y": 14,
      "z": -5,
      "name": "Rock_Crystal_White_Block"
    },
    {
      "x": 0,
      "y": 15,
      "z": -5,
      "name": "Rock_Crystal_White_Block"
    },
    {
      "x": 0,
      "y": 13,
      "z": -4,
      "name": "Rock_Crystal_White_Block"
    },
    {
      "x": 0,
      "y": 14,
      "z": -4,
      "name": "Rock_Crystal_White_Block"
    },
    {
      "x": 0,
      "y": 16,
      "z": -4,
      "name": "Rock_Crystal_White_Block"
    },
    {
      "x": 0,
      "y": 19,
      "z": -4,
      "name": "Rock_Crystal_White_Block"
    },
    {
      "x": 0,
      "y": 12,
      "z": -3,
      "name": "Rock_Crystal_White_Block"
    },
    {
      "x": 0,
      "y": 14,
      "z": -3,
      "name": "Rock_Crystal_White_Block"
    },
    {
      "x": 0,
      "y": 15,
      "z": -3,
      "name": "Rock_Crystal_White_Block"
    },
    {
      "x": 0,
      "y": 17,
      "z": -3,
      "name": "Rock_Crystal_White_Block"
    },
    {
      "x": 0,
      "y": 19,
      "z": -3,
      "name": "Rock_Crystal_White_Block"
    },
    {
      "x": 0,
      "y": 14,
      "z": -2,
      "name": "Rock_Crystal_White_Block"
    },
    {
      "x": 0,
      "y": 16,
      "z": -2,
      "name": "Rock_Crystal_White_Block"
    },
    {
      "x": 0,
      "y": 17,
      "z": -2,
      "name": "Rock_Crystal_White_Block"
    },
    {
      "x": 0,
      "y": 18,
      "z": -2,
      "name": "Rock_Crystal_White_Block"
    },
    {
      "x": 0,
      "y": 19,
      "z": -2,
      "name": "Rock_Crystal_White_Block"
    },
    {
      "x": 0,
      "y": 20,
      "z": -2,
      "name": "Rock_Crystal_White_Block"
    },
    {
      "x": 0,
      "y": 16,
      "z": -1,
      "name": "Rock_Crystal_White_Block"
    },
    {
      "x": 0,
      "y": 17,
      "z": -1,
      "name": "Rock_Crystal_White_Block"
    },
    {
      "x": 0,
      "y": 18,
      "z": -1,
      "name": "Rock_Crystal_White_Block"
    },
    {
      "x": 0,
      "y": 19,
      "z": -1,
      "name": "Rock_Crystal_White_Block"
    },
    {
      "x": 0,
      "y": 20,
      "z": -1,
      "name": "Rock_Crystal_White_Block",
      "rotation": 2
    },
    {
      "x": 0,
      "y": 21,
      "z": -1,
      "name": "Rock_Crystal_White_Block",
      "rotation": 2
    },
    {
      "x": 0,
      "y": 22,
      "z": -1,
      "name": "Rock_Crystal_White_Block",
      "rotation": 2
    },
    {
      "x": 0,
      "y": 15,
      "z": 0,
      "name": "Rock_Crystal_White_Block"
    },
    {
      "x": 0,
      "y": 16,
      "z": 0,
      "name": "Rock_Crystal_White_Block"
    },
    {
      "x": 0,
      "y": 17,
      "z": 0,
      "name": "Rock_Crystal_White_Block"
    },
    {
      "x": 0,
      "y": 18,
      "z": 0,
      "name": "Rock_Crystal_White_Block"
    },
    {
      "x": 0,
      "y": 19,
      "z": 0,
      "name": "Rock_Crystal_White_Block",
      "rotation": 2
    },
    {
      "x": 0,
      "y": 20,
      "z": 0,
      "name": "Rock_Crystal_White_Block",
      "rotation": 2
    },
    {
      "x": 0,
      "y": 21,
      "z": 0,
      "name": "Rock_Crystal_White_Block"
    },
    {
      "x": 0,
      "y": 14,
      "z": 1,
      "name": "Rock_Crystal_White_Block"
    },
    {
      "x": 0,
      "y": 15,
      "z": 1,
      "name": "Rock_Crystal_White_Block"
    },
    {
      "x": 0,
      "y": 16,
      "z": 1,
      "name": "Rock_Crystal_White_Block"
    },
    {
      "x": 0,
      "y": 17,
      "z": 1,
      "name": "Rock_Crystal_White_Block",
      "rotation": 2
    },
    {
      "x": 0,
      "y": 18,
      "z": 1,
      "name": "Rock_Crystal_White_Block",
      "rotation": 2
    },
    {
      "x": 0,
      "y": 19,
      "z": 1,
      "name": "Rock_Crystal_White_Block",
      "rotation": 2
    },
    {
      "x": 0,
      "y": 20,
      "z": 1,
      "name": "Rock_Crystal_White_Block",
      "rotation": 2
    },
    {
      "x": 0,
      "y": 16,
      "z": 2,
      "name": "Rock_Crystal_White_Block"
    },
    {
      "x": 0,
      "y": 17,
      "z": 2,
      "name": "Rock_Crystal_White_Block",
      "rotation": 2
    },
    {
      "x": 0,
      "y": 18,
      "z": 2,
      "name": "Rock_Crystal_White_Block",
      "rotation": 2
    },
    {
      "x": 0,
      "y": 19,
      "z": 2,
      "name": "Rock_Crystal_White_Block",
      "rotation": 2
    },
    {
      "x": 0,
      "y": 20,
      "z": 2,
      "name": "Rock_Crystal_White_Block",
      "rotation": 2
    },
    {
      "x": 0,
      "y": 22,
      "z": 2,
      "name": "Rock_Crystal_White_Block",
      "rotation": 2
    },
    {
      "x": 0,
      "y": 17,
      "z": 3,
      "name": "Rock_Crystal_White_Block",
      "rotation": 2
    },
    {
      "x": 0,
      "y": 19,
      "z": 3,
      "name": "Rock_Crystal_White_Block",
      "rotation": 2
    },
    {
      "x": 0,
      "y": 21,
      "z": 3,
      "name": "Rock_Crystal_White_Block",
      "rotation": 2
    },
    {
      "x": 0,
      "y": 22,
      "z": 3,
      "name": "Rock_Crystal_White_Block",
      "rotation": 2
    },
    {
      "x": 0,
      "y": 24,
      "z": 3,
      "name": "Rock_Crystal_White_Block",
      "rotation": 2
    },
    {
      "x": 0,
      "y": 17,
      "z": 4,
      "name": "Rock_Crystal_White_Block",
      "rotation": 2
    },
    {
      "x": 0,
      "y": 20,
      "z": 4,
      "name": "Rock_Crystal_White_Block",
      "rotation": 2
    },
    {
      "x": 0,
      "y": 22,
      "z": 4,
      "name": "Rock_Crystal_White_Block",
      "rotation": 2
    },
    {
      "x": 0,
      "y": 23,
      "z": 4,
      "name": "Rock_Crystal_White_Block",
      "rotation": 2
    },
    {
      "x": 0,
      "y": 21,
      "z": 5,
      "name": "Rock_Crystal_White_Block",
      "rotation": 2
    },
    {
      "x": 0,
      "y": 22,
      "z": 5,
      "name": "Rock_Crystal_White_Block",
      "rotation": 2
    },
    {
      "x": 0,
      "y": 23,
      "z": 5,
      "name": "Rock_Crystal_White_Block",
      "rotation": 2
    },
    {
      "x": 0,
      "y": 25,
      "z": 5,
      "name": "Rock_Crystal_White_Block",
      "rotation": 2
    },
    {
      "x": 0,
      "y": 26,
      "z": 5,
      "name": "Rock_Crystal_White_Block",
      "rotation": 2
    },
    {
      "x": 0,
      "y": 21,
      "z": 6,
      "name": "Rock_Crystal_White_Block",
      "rotation": 2
    },
    {
      "x": 0,
      "y": 22,
      "z": 6,
      "name": "Rock_Crystal_White_Block",
      "rotation": 2
    },
    {
      "x": 0,
      "y": 24,
      "z": 6,
      "name": "Rock_Crystal_White_Block",
      "rotation": 2
    },
    {
      "x": 0,
      "y": 23,
      "z": 7,
      "name": "Rock_Crystal_White_Block",
      "rotation": 2
    },
    {
      "x": 0,
      "y": 24,
      "z": 7,
      "name": "Rock_Crystal_White_Block",
      "rotation": 2
    },
    {
      "x": 0,
      "y": 25,
      "z": 7,
      "name": "Rock_Crystal_White_Block",
      "rotation": 2
    },
    {
      "x": 0,
      "y": 26,
      "z": 7,
      "name": "Rock_Crystal_White_Block",
      "rotation": 2
    },
    {
      "x": 0,
      "y": 24,
      "z": 8,
      "name": "Rock_Crystal_White_Block",
      "rotation": 2
    },
    {
      "x": 0,
      "y": 28,
      "z": 8,
      "name": "Rock_Crystal_White_Block",
      "rotation": 2
    },
    {
      "x": 0,
      "y": 24,
      "z": 9,
      "name": "Rock_Crystal_White_Block",
      "rotation": 2
    },
    {
      "x": 0,
      "y": 25,
      "z": 9,
      "name": "Rock_Crystal_White_Block",
      "rotation": 2
    },
    {
      "x": 0,
      "y": 27,
      "z": 9,
      "name": "Rock_Crystal_White_Block",
      "rotation": 2
    },
    {
      "x": 0,
      "y": 29,
      "z": 9,
      "name": "Rock_Crystal_White_Block",
      "rotation": 2
    },
    {
      "x": 0,
      "y": 25,
      "z": 10,
      "name": "Rock_Crystal_White_Block",
      "rotation": 2
    },
    {
      "x": 0,
      "y": 26,
      "z": 10,
      "name": "Rock_Crystal_White_Block",
      "rotation": 2
    },
    {
      "x": 0,
      "y": 29,
      "z": 10,
      "name": "Rock_Crystal_White_Block",
      "rotation": 2
    },
    {
      "x": 0,
      "y": 26,
      "z": 11,
      "name": "Rock_Crystal_White_Block",
      "rotation": 2
    },
    {
      "x": 0,
      "y": 28,
      "z": 11,
      "name": "Rock_Crystal_White_Block",
      "rotation": 2
    },
    {
      "x": 0,
      "y": 30,
      "z": 11,
      "name": "Rock_Crystal_White_Block",
      "rotation": 2
    },
    {
      "x": 0,
      "y": 31,
      "z": 11,
      "name": "Rock_Crystal_White_Block",
      "rotation": 2
    },
    {
      "x": 0,
      "y": 29,
      "z": 12,
      "name": "Rock_Crystal_White_Block",
      "rotation": 2
    },
    {
      "x": 0,
      "y": 30,
      "z": 12,
      "name": "Rock_Crystal_White_Block",
      "rotation": 2
    },
    {
      "x": 1,
      "y": 6,
      "z": -14,
      "name": "Rock_Crystal_White_Block"
    },
    {
      "x": 1,
      "y": 7,
      "z": -14,
      "name": "Rock_Crystal_White_Block"
    },
    {
      "x": 1,
      "y": 5,
      "z": -13,
      "name": "Rock_Crystal_White_Block"
    },
    {
      "x": 1,
      "y": 7,
      "z": -13,
      "name": "Rock_Crystal_White_Block"
    },
    {
      "x": 1,
      "y": 8,
      "z": -13,
      "name": "Rock_Crystal_White_Block"
    },
    {
      "x": 1,
      "y": 6,
      "z": -12,
      "name": "Rock_Crystal_White_Block"
    },
    {
      "x": 1,
      "y": 7,
      "z": -12,
      "name": "Rock_Crystal_White_Block"
    },
    {
      "x": 1,
      "y": 8,
      "z": -12,
      "name": "Rock_Crystal_White_Block"
    },
    {
      "x": 1,
      "y": 9,
      "z": -12,
      "name": "Rock_Crystal_White_Block"
    },
    {
      "x": 1,
      "y": 6,
      "z": -11,
      "name": "Rock_Crystal_White_Block"
    },
    {
      "x": 1,
      "y": 8,
      "z": -11,
      "name": "Rock_Crystal_White_Block"
    },
    {
      "x": 1,
      "y": 9,
      "z": -11,
      "name": "Rock_Crystal_White_Block"
    },
    {
      "x": 1,
      "y": 7,
      "z": -10,
      "name": "Rock_Crystal_White_Block"
    },
    {
      "x": 1,
      "y": 8,
      "z": -10,
      "name": "Rock_Crystal_White_Block"
    },
    {
      "x": 1,
      "y": 9,
      "z": -10,
      "name": "Rock_Crystal_White_Block"
    },
    {
      "x": 1,
      "y": 10,
      "z": -10,
      "name": "Rock_Crystal_White_Block"
    },
    {
      "x": 1,
      "y": 11,
      "z": -10,
      "name": "Rock_Crystal_White_Block"
    },
    {
      "x": 1,
      "y": 9,
      "z": -9,
      "name": "Rock_Crystal_White_Block"
    },
    {
      "x": 1,
      "y": 10,
      "z": -9,
      "name": "Rock_Crystal_White_Block"
    },
    {
      "x": 1,
      "y": 11,
      "z": -9,
      "name": "Rock_Crystal_White_Block"
    },
    {
      "x": 1,
      "y": 8,
      "z": -8,
      "name": "Rock_Crystal_White_Block"
    },
    {
      "x": 1,
      "y": 10,
      "z": -8,
      "name": "Rock_Crystal_White_Block"
    },
    {
      "x": 1,
      "y": 11,
      "z": -8,
      "name": "Rock_Crystal_White_Block"
    },
    {
      "x": 1,
      "y": 12,
      "z": -8,
      "name": "Rock_Crystal_White_Block"
    },
    {
      "x": 1,
      "y": 10,
      "z": -7,
      "name": "Rock_Crystal_White_Block"
    },
    {
      "x": 1,
      "y": 11,
      "z": -7,
      "name": "Rock_Crystal_White_Block"
    },
    {
      "x": 1,
      "y": 12,
      "z": -7,
      "name": "Rock_Crystal_White_Block"
    },
    {
      "x": 1,
      "y": 10,
      "z": -6,
      "name": "Rock_Crystal_White_Block"
    },
    {
      "x": 1,
      "y": 12,
      "z": -6,
      "name": "Rock_Crystal_White_Block"
    },
    {
      "x": 1,
      "y": 13,
      "z": -6,
      "name": "Rock_Crystal_White_Block"
    },
    {
      "x": 1,
      "y": 15,
      "z": -6,
      "name": "Rock_Crystal_White_Block"
    },
    {
      "x": 1,
      "y": 13,
      "z": -5,
      "name": "Rock_Crystal_White_Block"
    },
    {
      "x": 1,
      "y": 14,
      "z": -5,
      "name": "Rock_Crystal_White_Block"
    },
    {
      "x": 1,
      "y": 15,
      "z": -5,
      "name": "Rock_Crystal_White_Block"
    },
    {
      "x": 1,
      "y": 16,
      "z": -5,
      "name": "Rock_Crystal_White_Block"
    },
    {
      "x": 1,
      "y": 13,
      "z": -4,
      "name": "Rock_Crystal_White_Block"
    },
    {
      "x": 1,
      "y": 14,
      "z": -4,
      "name": "Rock_Crystal_White_Block"
    },
    {
      "x": 1,
      "y": 15,
      "z": -4,
      "name": "Rock_Crystal_White_Block"
    },
    {
      "x": 1,
      "y": 16,
      "z": -4,
      "name": "Rock_Crystal_White_Block"
    },
    {
      "x": 1,
      "y": 17,
      "z": -4,
      "name": "Rock_Crystal_White_Block"
    },
    {
      "x": 1,
      "y": 15,
      "z": -3,
      "name": "Rock_Crystal_White_Block"
    },
    {
      "x": 1,
      "y": 16,
      "z": -3,
      "name": "Rock_Crystal_White_Block"
    },
    {
      "x": 1,
      "y": 18,
      "z": -3,
      "name": "Rock_Crystal_White_Block"
    },
    {
      "x": 1,
      "y": 19,
      "z": -3,
      "name": "Rock_Crystal_White_Block"
    },
    {
      "x": 1,
      "y": 14,
      "z": -2,
      "name": "Rock_Crystal_White_Block"
    },
    {
      "x": 1,
      "y": 16,
      "z": -2,
      "name": "Rock_Crystal_White_Block"
    },
    {
      "x": 1,
      "y": 17,
      "z": -2,
      "name": "Rock_Crystal_White_Block"
    },
    {
      "x": 1,
      "y": 18,
      "z": -2,
      "name": "Rock_Crystal_White_Block"
    },
    {
      "x": 1,
      "y": 19,
      "z": -2,
      "name": "Rock_Crystal_White_Block"
    },
    {
      "x": 1,
      "y": 20,
      "z": -2,
      "name": "Rock_Crystal_White_Block"
    },
    {
      "x": 1,
      "y": 16,
      "z": -1,
      "name": "Rock_Crystal_White_Block"
    },
    {
      "x": 1,
      "y": 17,
      "z": -1,
      "name": "Rock_Crystal_White_Block"
    },
    {
      "x": 1,
      "y": 18,
      "z": -1,
      "name": "Rock_Crystal_White_Block"
    },
    {
      "x": 1,
      "y": 19,
      "z": -1,
      "name": "Rock_Crystal_White_Block"
    },
    {
      "x": 1,
      "y": 20,
      "z": -1,
      "name": "Rock_Crystal_White_Block"
    },
    {
      "x": 1,
      "y": 21,
      "z": -1,
      "name": "Rock_Crystal_White_Block"
    },
    {
      "x": 1,
      "y": 22,
      "z": -1,
      "name": "Rock_Crystal_White_Block",
      "rotation": 2
    },
    {
      "x": 1,
      "y": 23,
      "z": -1,
      "name": "Rock_Crystal_White_Block",
      "rotation": 2
    },
    {
      "x": 1,
      "y": 24,
      "z": -1,
      "name": "Rock_Crystal_White_Block",
      "rotation": 2
    },
    {
      "x": 1,
      "y": 15,
      "z": 0,
      "name": "Rock_Crystal_White_Block"
    },
    {
      "x": 1,
      "y": 16,
      "z": 0,
      "name": "Rock_Crystal_White_Block"
    },
    {
      "x": 1,
      "y": 17,
      "z": 0,
      "name": "Rock_Crystal_White_Block"
    },
    {
      "x": 1,
      "y": 18,
      "z": 0,
      "name": "Rock_Crystal_White_Block",
      "rotation": 2
    },
    {
      "x": 1,
      "y": 19,
      "z": 0,
      "name": "Rock_Crystal_White_Block",
      "rotation": 2
    },
    {
      "x": 1,
      "y": 20,
      "z": 0,
      "name": "Rock_Crystal_White_Block",
      "rotation": 2
    },
    {
      "x": 1,
      "y": 21,
      "z": 0,
      "name": "Rock_Crystal_White_Block",
      "rotation": 2
    },
    {
      "x": 1,
      "y": 22,
      "z": 0,
      "name": "Rock_Crystal_White_Block",
      "rotation": 2
    },
    {
      "x": 1,
      "y": 16,
      "z": 1,
      "name": "Rock_Crystal_White_Block"
    },
    {
      "x": 1,
      "y": 17,
      "z": 1,
      "name": "Rock_Crystal_White_Block"
    },
    {
      "x": 1,
      "y": 18,
      "z": 1,
      "name": "Rock_Crystal_White_Block",
      "rotation": 2
    },
    {
      "x": 1,
      "y": 19,
      "z": 1,
      "name": "Rock_Crystal_White_Block",
      "rotation": 2
    },
    {
      "x": 1,
      "y": 20,
      "z": 1,
      "name": "Rock_Crystal_White_Block",
      "rotation": 2
    },
    {
      "x": 1,
      "y": 21,
      "z": 1,
      "name": "Rock_Crystal_White_Block",
      "rotation": 2
    },
    {
      "x": 1,
      "y": 22,
      "z": 1,
      "name": "Rock_Crystal_White_Block",
      "rotation": 2
    },
    {
      "x": 1,
      "y": 17,
      "z": 2,
      "name": "Rock_Crystal_White_Block",
      "rotation": 2
    },
    {
      "x": 1,
      "y": 18,
      "z": 2,
      "name": "Rock_Crystal_White_Block",
      "rotation": 2
    },
    {
      "x": 1,
      "y": 19,
      "z": 2,
      "name": "Rock_Crystal_White_Block",
      "rotation": 2
    },
    {
      "x": 1,
      "y": 20,
      "z": 2,
      "name": "Rock_Crystal_White_Block"
    },
    {
      "x": 1,
      "y": 22,
      "z": 2,
      "name": "Rock_Crystal_White_Block",
      "rotation": 2
    },
    {
      "x": 1,
      "y": 18,
      "z": 3,
      "name": "Rock_Crystal_White_Block",
      "rotation": 2
    },
    {
      "x": 1,
      "y": 19,
      "z": 3,
      "name": "Rock_Crystal_White_Block",
      "rotation": 2
    },
    {
      "x": 1,
      "y": 21,
      "z": 3,
      "name": "Rock_Crystal_White_Block",
      "rotation": 2
    },
    {
      "x": 1,
      "y": 24,
      "z": 3,
      "name": "Rock_Crystal_White_Block",
      "rotation": 2
    },
    {
      "x": 1,
      "y": 19,
      "z": 4,
      "name": "Rock_Crystal_White_Block",
      "rotation": 2
    },
    {
      "x": 1,
      "y": 20,
      "z": 4,
      "name": "Rock_Crystal_White_Block",
      "rotation": 2
    },
    {
      "x": 1,
      "y": 23,
      "z": 4,
      "name": "Rock_Crystal_White_Block",
      "rotation": 2
    },
    {
      "x": 1,
      "y": 20,
      "z": 5,
      "name": "Rock_Crystal_White_Block",
      "rotation": 2
    },
    {
      "x": 1,
      "y": 21,
      "z": 5,
      "name": "Rock_Crystal_White_Block",
      "rotation": 2
    },
    {
      "x": 1,
      "y": 25,
      "z": 5,
      "name": "Rock_Crystal_White_Block",
      "rotation": 2
    },
    {
      "x": 1,
      "y": 26,
      "z": 5,
      "name": "Rock_Crystal_White_Block",
      "rotation": 2
    },
    {
      "x": 1,
      "y": 21,
      "z": 6,
      "name": "Rock_Crystal_White_Block",
      "rotation": 2
    },
    {
      "x": 1,
      "y": 24,
      "z": 6,
      "name": "Rock_Crystal_White_Block",
      "rotation": 2
    },
    {
      "x": 1,
      "y": 27,
      "z": 6,
      "name": "Rock_Crystal_White_Block",
      "rotation": 2
    },
    {
      "x": 1,
      "y": 26,
      "z": 7,
      "name": "Rock_Crystal_White_Block",
      "rotation": 2
    },
    {
      "x": 1,
      "y": 26,
      "z": 8,
      "name": "Rock_Crystal_White_Block",
      "rotation": 2
    },
    {
      "x": 1,
      "y": 28,
      "z": 8,
      "name": "Rock_Crystal_White_Block",
      "rotation": 2
    },
    {
      "x": 1,
      "y": 29,
      "z": 8,
      "name": "Rock_Crystal_White_Block",
      "rotation": 2
    },
    {
      "x": 1,
      "y": 27,
      "z": 9,
      "name": "Rock_Crystal_White_Block",
      "rotation": 2
    },
    {
      "x": 2,
      "y": 4,
      "z": -16,
      "name": "Rock_Crystal_White_Block"
    },
    {
      "x": 2,
      "y": 4,
      "z": -15,
      "name": "Rock_Crystal_White_Block"
    },
    {
      "x": 2,
      "y": 5,
      "z": -15,
      "name": "Rock_Crystal_White_Block"
    },
    {
      "x": 2,
      "y": 5,
      "z": -14,
      "name": "Rock_Crystal_White_Block"
    },
    {
      "x": 2,
      "y": 6,
      "z": -14,
      "name": "Rock_Crystal_White_Block"
    },
    {
      "x": 2,
      "y": 6,
      "z": -13,
      "name": "Rock_Crystal_White_Block"
    },
    {
      "x": 2,
      "y": 7,
      "z": -13,
      "name": "Rock_Crystal_White_Block"
    },
    {
      "x": 2,
      "y": 6,
      "z": -12,
      "name": "Rock_Crystal_White_Block"
    },
    {
      "x": 2,
      "y": 7,
      "z": -12,
      "name": "Rock_Crystal_White_Block"
    },
    {
      "x": 2,
      "y": 8,
      "z": -12,
      "name": "Rock_Crystal_White_Block"
    },
    {
      "x": 2,
      "y": 8,
      "z": -11,
      "name": "Rock_Crystal_White_Block"
    },
    {
      "x": 2,
      "y": 9,
      "z": -11,
      "name": "Rock_Crystal_White_Block"
    },
    {
      "x": 2,
      "y": 11,
      "z": -11,
      "name": "Rock_Crystal_White_Block"
    },
    {
      "x": 2,
      "y": 7,
      "z": -10,
      "name": "Rock_Crystal_White_Block"
    },
    {
      "x": 2,
      "y": 9,
      "z": -10,
      "name": "Rock_Crystal_White_Block"
    },
    {
      "x": 2,
      "y": 10,
      "z": -10,
      "name": "Rock_Crystal_White_Block"
    },
    {
      "x": 2,
      "y": 11,
      "z": -10,
      "name": "Rock_Crystal_White_Block"
    },
    {
      "x": 2,
      "y": 13,
      "z": -10,
      "name": "Rock_Crystal_White_Block"
    },
    {
      "x": 2,
      "y": 9,
      "z": -9,
      "name": "Rock_Crystal_White_Block"
    },
    {
      "x": 2,
      "y": 10,
      "z": -9,
      "name": "Rock_Crystal_White_Block"
    },
    {
      "x": 2,
      "y": 11,
      "z": -9,
      "name": "Rock_Crystal_White_Block"
    },
    {
      "x": 2,
      "y": 12,
      "z": -9,
      "name": "Rock_Crystal_White_Block"
    },
    {
      "x": 2,
      "y": 10,
      "z": -8,
      "name": "Rock_Crystal_White_Block"
    },
    {
      "x": 2,
      "y": 12,
      "z": -8,
      "name": "Rock_Crystal_White_Block"
    },
    {
      "x": 2,
      "y": 14,
      "z": -8,
      "name": "Rock_Crystal_White_Block"
    },
    {
      "x": 2,
      "y": 15,
      "z": -8,
      "name": "Rock_Crystal_White_Block"
    },
    {
      "x": 2,
      "y": 11,
      "z": -7,
      "name": "Rock_Crystal_White_Block"
    },
    {
      "x": 2,
      "y": 13,
      "z": -7,
      "name": "Rock_Crystal_White_Block"
    },
    {
      "x": 2,
      "y": 11,
      "z": -6,
      "name": "Rock_Crystal_White_Block"
    },
    {
      "x": 2,
      "y": 14,
      "z": -6,
      "name": "Rock_Crystal_White_Block"
    },
    {
      "x": 2,
      "y": 15,
      "z": -6,
      "name": "Rock_Crystal_White_Block"
    },
    {
      "x": 2,
      "y": 20,
      "z": -6,
      "name": "Rock_Crystal_White_Block"
    },
    {
      "x": 2,
      "y": 12,
      "z": -5,
      "name": "Rock_Crystal_White_Block"
    },
    {
      "x": 2,
      "y": 13,
      "z": -5,
      "name": "Rock_Crystal_White_Block"
    },
    {
      "x": 2,
      "y": 14,
      "z": -5,
      "name": "Rock_Crystal_White_Block"
    },
    {
      "x": 2,
      "y": 15,
      "z": -5,
      "name": "Rock_Crystal_White_Block"
    },
    {
      "x": 2,
      "y": 18,
      "z": -5,
      "name": "Rock_Crystal_White_Block"
    },
    {
      "x": 2,
      "y": 20,
      "z": -5,
      "name": "Rock_Crystal_White_Block"
    },
    {
      "x": 2,
      "y": 13,
      "z": -4,
      "name": "Rock_Crystal_White_Block"
    },
    {
      "x": 2,
      "y": 16,
      "z": -4,
      "name": "Rock_Crystal_White_Block"
    },
    {
      "x": 2,
      "y": 19,
      "z": -4,
      "name": "Rock_Crystal_White_Block"
    },
    {
      "x": 2,
      "y": 13,
      "z": -3,
      "name": "Rock_Crystal_White_Block"
    },
    {
      "x": 2,
      "y": 14,
      "z": -3,
      "name": "Rock_Crystal_White_Block"
    },
    {
      "x": 2,
      "y": 15,
      "z": -3,
      "name": "Rock_Crystal_White_Block"
    },
    {
      "x": 2,
      "y": 17,
      "z": -3,
      "name": "Rock_Crystal_White_Block"
    },
    {
      "x": 2,
      "y": 18,
      "z": -3,
      "name": "Rock_Crystal_White_Block"
    },
    {
      "x": 2,
      "y": 19,
      "z": -3,
      "name": "Rock_Crystal_White_Block"
    },
    {
      "x": 2,
      "y": 20,
      "z": -3,
      "name": "Rock_Crystal_White_Block"
    },
    {
      "x": 2,
      "y": 14,
      "z": -2,
      "name": "Rock_Crystal_White_Block"
    },
    {
      "x": 2,
      "y": 16,
      "z": -2,
      "name": "Rock_Crystal_White_Block"
    },
    {
      "x": 2,
      "y": 18,
      "z": -2,
      "name": "Rock_Crystal_White_Block"
    },
    {
      "x": 2,
      "y": 19,
      "z": -2,
      "name": "Rock_Crystal_White_Block"
    },
    {
      "x": 2,
      "y": 16,
      "z": -1,
      "name": "Rock_Crystal_White_Block"
    },
    {
      "x": 2,
      "y": 17,
      "z": -1,
      "name": "Rock_Crystal_White_Block"
    },
    {
      "x": 2,
      "y": 18,
      "z": -1,
      "name": "Rock_Crystal_White_Block"
    },
    {
      "x": 2,
      "y": 19,
      "z": -1,
      "name": "Rock_Crystal_White_Block"
    },
    {
      "x": 2,
      "y": 20,
      "z": -1,
      "name": "Rock_Crystal_White_Block"
    },
    {
      "x": 2,
      "y": 21,
      "z": -1,
      "name": "Rock_Crystal_White_Block"
    },
    {
      "x": 2,
      "y": 22,
      "z": -1,
      "name": "Rock_Crystal_White_Block"
    },
    {
      "x": 2,
      "y": 23,
      "z": -1,
      "name": "Rock_Crystal_White_Block",
      "rotation": 2
    },
    {
      "x": 2,
      "y": 24,
      "z": -1,
      "name": "Rock_Crystal_White_Block",
      "rotation": 2
    },
    {
      "x": 2,
      "y": 25,
      "z": -1,
      "name": "Rock_Crystal_White_Block",
      "rotation": 2
    },
    {
      "x": 2,
      "y": 26,
      "z": -1,
      "name": "Rock_Crystal_White_Block",
      "rotation": 2
    },
    {
      "x": 2,
      "y": 16,
      "z": 0,
      "name": "Rock_Crystal_White_Block"
    },
    {
      "x": 2,
      "y": 17,
      "z": 0,
      "name": "Rock_Crystal_White_Block"
    },
    {
      "x": 2,
      "y": 18,
      "z": 0,
      "name": "Rock_Crystal_White_Block"
    },
    {
      "x": 2,
      "y": 19,
      "z": 0,
      "name": "Rock_Crystal_White_Block"
    },
    {
      "x": 2,
      "y": 20,
      "z": 0,
      "name": "Rock_Crystal_White_Block",
      "rotation": 2
    },
    {
      "x": 2,
      "y": 21,
      "z": 0,
      "name": "Rock_Crystal_White_Block",
      "rotation": 2
    },
    {
      "x": 2,
      "y": 22,
      "z": 0,
      "name": "Rock_Crystal_White_Block",
      "rotation": 2
    },
    {
      "x": 2,
      "y": 23,
      "z": 0,
      "name": "Rock_Crystal_White_Block",
      "rotation": 2
    },
    {
      "x": 2,
      "y": 24,
      "z": 0,
      "name": "Rock_Crystal_White_Block",
      "rotation": 2
    },
    {
      "x": 2,
      "y": 17,
      "z": 1,
      "name": "Rock_Crystal_White_Block"
    },
    {
      "x": 2,
      "y": 18,
      "z": 1,
      "name": "Rock_Crystal_White_Block",
      "rotation": 2
    },
    {
      "x": 2,
      "y": 19,
      "z": 1,
      "name": "Rock_Crystal_White_Block",
      "rotation": 2
    },
    {
      "x": 2,
      "y": 20,
      "z": 1,
      "name": "Rock_Crystal_White_Block"
    },
    {
      "x": 2,
      "y": 21,
      "z": 1,
      "name": "Rock_Crystal_White_Block",
      "rotation": 2
    },
    {
      "x": 2,
      "y": 22,
      "z": 1,
      "name": "Rock_Crystal_White_Block",
      "rotation": 2
    },
    {
      "x": 2,
      "y": 23,
      "z": 1,
      "name": "Rock_Crystal_White_Block",
      "rotation": 2
    },
    {
      "x": 2,
      "y": 16,
      "z": 2,
      "name": "Rock_Crystal_White_Block"
    },
    {
      "x": 2,
      "y": 17,
      "z": 2,
      "name": "Rock_Crystal_White_Block",
      "rotation": 2
    },
    {
      "x": 2,
      "y": 18,
      "z": 2,
      "name": "Rock_Crystal_White_Block",
      "rotation": 2
    },
    {
      "x": 2,
      "y": 19,
      "z": 2,
      "name": "Rock_Crystal_White_Block"
    },
    {
      "x": 2,
      "y": 24,
      "z": 2,
      "name": "Rock_Crystal_White_Block",
      "rotation": 2
    },
    {
      "x": 2,
      "y": 17,
      "z": 3,
      "name": "Rock_Crystal_White_Block",
      "rotation": 2
    },
    {
      "x": 2,
      "y": 25,
      "z": 3,
      "name": "Rock_Crystal_White_Block",
      "rotation": 2
    },
    {
      "x": 2,
      "y": 23,
      "z": 4,
      "name": "Rock_Crystal_White_Block",
      "rotation": 2
    },
    {
      "x": 2,
      "y": 26,
      "z": 4,
      "name": "Rock_Crystal_White_Block",
      "rotation": 2
    },
    {
      "x": 2,
      "y": 25,
      "z": 6,
      "name": "Rock_Crystal_White_Block",
      "rotation": 2
    },
    {
      "x": 2,
      "y": 28,
      "z": 6,
      "name": "Rock_Crystal_White_Block",
      "rotation": 2
    },
    {
      "x": 3,
      "y": 7,
      "z": -15,
      "name": "Rock_Crystal_White_Block"
    },
    {
      "x": 3,
      "y": 6,
      "z": -14,
      "name": "Rock_Crystal_White_Block"
    },
    {
      "x": 3,
      "y": 5,
      "z": -13,
      "name": "Rock_Crystal_White_Block"
    },
    {
      "x": 3,
      "y": 8,
      "z": -13,
      "name": "Rock_Crystal_White_Block"
    },
    {
      "x": 3,
      "y": 6,
      "z": -12,
      "name": "Rock_Crystal_White_Block"
    },
    {
      "x": 3,
      "y": 7,
      "z": -12,
      "name": "Rock_Crystal_White_Block"
    },
    {
      "x": 3,
      "y": 9,
      "z": -12,
      "name": "Rock_Crystal_White_Block"
    },
    {
      "x": 3,
      "y": 10,
      "z": -12,
      "name": "Rock_Crystal_White_Block"
    },
    {
      "x": 3,
      "y": 8,
      "z": -11,
      "name": "Rock_Crystal_White_Block"
    },
    {
      "x": 3,
      "y": 8,
      "z": -10,
      "name": "Rock_Crystal_White_Block"
    },
    {
      "x": 3,
      "y": 10,
      "z": -10,
      "name": "Rock_Crystal_White_Block"
    },
    {
      "x": 3,
      "y": 11,
      "z": -10,
      "name": "Rock_Crystal_White_Block"
    },
    {
      "x": 3,
      "y": 13,
      "z": -10,
      "name": "Rock_Crystal_White_Block"
    },
    {
      "x": 3,
      "y": 8,
      "z": -9,
      "name": "Rock_Crystal_White_Block"
    },
    {
      "x": 3,
      "y": 9,
      "z": -8,
      "name": "Rock_Crystal_White_Block"
    },
    {
      "x": 3,
      "y": 12,
      "z": -8,
      "name": "Rock_Crystal_White_Block"
    },
    {
      "x": 3,
      "y": 14,
      "z": -8,
      "name": "Rock_Crystal_White_Block"
    },
    {
      "x": 3,
      "y": 10,
      "z": -7,
      "name": "Rock_Crystal_White_Block"
    },
    {
      "x": 3,
      "y": 11,
      "z": -7,
      "name": "Rock_Crystal_White_Block"
    },
    {
      "x": 3,
      "y": 15,
      "z": -7,
      "name": "Rock_Crystal_White_Block"
    },
    {
      "x": 3,
      "y": 11,
      "z": -6,
      "name": "Rock_Crystal_White_Block"
    },
    {
      "x": 3,
      "y": 13,
      "z": -6,
      "name": "Rock_Crystal_White_Block"
    },
    {
      "x": 3,
      "y": 17,
      "z": -6,
      "name": "Rock_Crystal_White_Block"
    },
    {
      "x": 3,
      "y": 18,
      "z": -6,
      "name": "Rock_Crystal_White_Block"
    },
    {
      "x": 3,
      "y": 19,
      "z": -6,
      "name": "Rock_Crystal_White_Block"
    },
    {
      "x": 3,
      "y": 20,
      "z": -6,
      "name": "Rock_Crystal_White_Block"
    },
    {
      "x": 3,
      "y": 12,
      "z": -5,
      "name": "Rock_Crystal_White_Block"
    },
    {
      "x": 3,
      "y": 18,
      "z": -5,
      "name": "Rock_Crystal_White_Block"
    },
    {
      "x": 3,
      "y": 20,
      "z": -5,
      "name": "Rock_Crystal_White_Block"
    },
    {
      "x": 3,
      "y": 13,
      "z": -4,
      "name": "Rock_Crystal_White_Block"
    },
    {
      "x": 3,
      "y": 17,
      "z": -4,
      "name": "Rock_Crystal_White_Block"
    },
    {
      "x": 3,
      "y": 18,
      "z": -4,
      "name": "Rock_Crystal_White_Block"
    },
    {
      "x": 3,
      "y": 19,
      "z": -4,
      "name": "Rock_Crystal_White_Block"
    },
    {
      "x": 3,
      "y": 22,
      "z": -4,
      "name": "Rock_Crystal_White_Block"
    },
    {
      "x": 3,
      "y": 18,
      "z": -3,
      "name": "Rock_Crystal_White_Block"
    },
    {
      "x": 3,
      "y": 19,
      "z": -3,
      "name": "Rock_Crystal_White_Block"
    },
    {
      "x": 3,
      "y": 20,
      "z": -3,
      "name": "Rock_Crystal_White_Block"
    },
    {
      "x": 3,
      "y": 17,
      "z": -2,
      "name": "Rock_Crystal_White_Block"
    },
    {
      "x": 3,
      "y": 20,
      "z": -2,
      "name": "Rock_Crystal_White_Block"
    },
    {
      "x": 3,
      "y": 21,
      "z": -2,
      "name": "Rock_Crystal_White_Block"
    },
    {
      "x": 3,
      "y": 17,
      "z": -1,
      "name": "Rock_Crystal_White_Block"
    },
    {
      "x": 3,
      "y": 19,
      "z": -1,
      "name": "Rock_Crystal_White_Block"
    },
    {
      "x": 3,
      "y": 21,
      "z": -1,
      "name": "Rock_Crystal_White_Block"
    },
    {
      "x": 3,
      "y": 22,
      "z": -1,
      "name": "Rock_Crystal_White_Block"
    },
    {
      "x": 3,
      "y": 23,
      "z": -1,
      "name": "Rock_Crystal_White_Block"
    },
    {
      "x": 3,
      "y": 25,
      "z": -1,
      "name": "Rock_Crystal_White_Block",
      "rotation": 2
    },
    {
      "x": 3,
      "y": 26,
      "z": -1,
      "name": "Rock_Crystal_White_Block",
      "rotation": 2
    },
    {
      "x": 3,
      "y": 27,
      "z": -1,
      "name": "Rock_Crystal_White_Block",
      "rotation": 2
    },
    {
      "x": 3,
      "y": 18,
      "z": 0,
      "name": "Rock_Crystal_White_Block"
    },
    {
      "x": 3,
      "y": 19,
      "z": 0,
      "name": "Rock_Crystal_White_Block"
    },
    {
      "x": 3,
      "y": 20,
      "z": 0,
      "name": "Rock_Crystal_White_Block"
    },
    {
      "x": 3,
      "y": 21,
      "z": 0,
      "name": "Rock_Crystal_White_Block"
    },
    {
      "x": 3,
      "y": 22,
      "z": 0,
      "name": "Rock_Crystal_White_Block",
      "rotation": 2
    },
    {
      "x": 3,
      "y": 23,
      "z": 0,
      "name": "Rock_Crystal_White_Block",
      "rotation": 2
    },
    {
      "x": 3,
      "y": 24,
      "z": 0,
      "name": "Rock_Crystal_White_Block",
      "rotation": 2
    },
    {
      "x": 3,
      "y": 25,
      "z": 0,
      "name": "Rock_Crystal_White_Block",
      "rotation": 2
    },
    {
      "x": 3,
      "y": 26,
      "z": 0,
      "name": "Rock_Crystal_White_Block",
      "rotation": 2
    },
    {
      "x": 3,
      "y": 19,
      "z": 1,
      "name": "Rock_Crystal_White_Block",
      "rotation": 2
    },
    {
      "x": 3,
      "y": 20,
      "z": 1,
      "name": "Rock_Crystal_White_Block",
      "rotation": 2
    },
    {
      "x": 3,
      "y": 21,
      "z": 1,
      "name": "Rock_Crystal_White_Block",
      "rotation": 2
    },
    {
      "x": 3,
      "y": 23,
      "z": 1,
      "name": "Rock_Crystal_White_Block",
      "rotation": 2
    },
    {
      "x": 3,
      "y": 24,
      "z": 1,
      "name": "Rock_Crystal_White_Block",
      "rotation": 2
    },
    {
      "x": 3,
      "y": 25,
      "z": 1,
      "name": "Rock_Crystal_White_Block",
      "rotation": 2
    },
    {
      "x": 3,
      "y": 27,
      "z": 1,
      "name": "Rock_Crystal_White_Block",
      "rotation": 2
    },
    {
      "x": 3,
      "y": 25,
      "z": 2,
      "name": "Rock_Crystal_White_Block",
      "rotation": 2
    },
    {
      "x": 3,
      "y": 26,
      "z": 2,
      "name": "Rock_Crystal_White_Block",
      "rotation": 2
    },
    {
      "x": 3,
      "y": 27,
      "z": 3,
      "name": "Rock_Crystal_White_Block",
      "rotation": 2
    },
    {
      "x": 3,
      "y": 27,
      "z": 4,
      "name": "Rock_Crystal_White_Block",
      "rotation": 2
    },
    {
      "x": 3,
      "y": 28,
      "z": 4,
      "name": "Rock_Crystal_White_Block",
      "rotation": 2
    },
    {
      "x": 4,
      "y": 7,
      "z": -15,
      "name": "Rock_Crystal_White_Block"
    },
    {
      "x": 4,
      "y": 9,
      "z": -14,
      "name": "Rock_Crystal_White_Block"
    },
    {
      "x": 4,
      "y": 8,
      "z": -13,
      "name": "Rock_Crystal_White_Block"
    },
    {
      "x": 4,
