{
  "version": 8,
  "blockIdVersion": 11,
  "anchorX": 0,
  "anchorY": 4,
  "anchorZ": 0,
  "blocks": [
    {
      "x": -8,
      "y": 9,
      "z": -1,
      "name": "Plant_Leaves_Dry"
    },
    {
      "x": -8,
      "y": 9,
      "z": 0,
      "name": "Plant_Leaves_Dry"
    },
    {
      "x": -7,
      "y": 9,
      "z": -5,
      "name": "Plant_Leaves_Dry"
    },
    {
      "x": -7,
      "y": 9,
      "z": -4,
      "name": "Plant_Leaves_Dry"
    },
    {
      "x": -7,
      "y": 9,
      "z": -2,
      "name": "Plant_Leaves_Dry"
    },
    {
      "x": -7,
      "y": 9,
      "z": 0,
      "name": "Wood_Spiral_Branch_Corner",
      "rotation": 3
    },
    {
      "x": -7,
      "y": 10,
      "z": 0,
      "name": "Plant_Leaves_Dry"
    },
    {
      "x": -7,
      "y": 9,
      "z": 1,
      "name": "Plant_Leaves_Dry"
    },
    {
      "x": -6,
      "y": 9,
      "z": -6,
      "name": "Plant_Leaves_Dry"
    },
    {
      "x": -6,
      "y": 8,
      "z": -4,
      "name": "Wood_Spiral_Branch_Corner",
      "rotation": 3
    },
    {
      "x": -6,
      "y": 9,
      "z": -4,
      "name": "Wood_Spiral_Branch_Long"
    },
    {
      "x": -6,
      "y": 10,
      "z": -4,
      "name": "Plant_Leaves_Dry"
    },
    {
      "x": -6,
      "y": 9,
      "z": -3,
      "name": "Plant_Leaves_Dry"
    },
    {
      "x": -6,
      "y": 9,
      "z": -2,
      "name": "Plant_Leaves_Dry"
    },
    {
      "x": -6,
      "y": 9,
      "z": -1,
      "name": "Wood_Spiral_Branch_Corner",
      "rotation": 2
    },
    {
      "x": -6,
      "y": 10,
      "z": -1,
      "name": "Plant_Leaves_Dry"
    },
    {
      "x": -6,
      "y": 14,
      "z": -1,
      "name": "Plant_Leaves_Dry"
    },
    {
      "x": -6,
      "y": 9,
      "z": 0,
      "name": "Wood_Spiral_Trunk_Full"
    },
    {
      "x": -6,
      "y": 10,
      "z": 0,
      "name": "Rock_Crystal_Yellow_Large"
    },
    {
      "x": -6,
      "y": 9,
      "z": 1,
      "name": "Wood_Spiral_Branch_Corner"
    },
    {
      "x": -6,
      "y": 10,
      "z": 1,
      "name": "Plant_Leaves_Dry"
    },
    {
      "x": -6,
      "y": 9,
      "z": 2,
      "name": "Plant_Leaves_Dry"
    },
    {
      "x": -6,
      "y": 9,
      "z": 4,
      "name": "Plant_Leaves_Dry"
    },
    {
      "x": -6,
      "y": 9,
      "z": 5,
      "name": "Plant_Leaves_Dry"
    },
    {
      "x": -5,
      "y": 9,
      "z": -7,
      "name": "Plant_Leaves_Dry"
    },
    {
      "x": -5,
      "y": 9,
      "z": -6,
      "name": "Wood_Spiral_Branch_Corner",
      "rotation": 2
    },
    {
      "x": -5,
      "y": 10,
      "z": -6,
      "name": "Plant_Leaves_Dry"
    },
    {
      "x": -5,
      "y": 8,
      "z": -5,
      "name": "Wood_Spiral_Branch_Corner",
      "rotation": 2
    },
    {
      "x": -5,
      "y": 9,
      "z": -5,
      "name": "Wood_Spiral_Branch_Corner",
      "rotation": 10
    },
    {
      "x": -5,
      "y": 10,
      "z": -5,
      "name": "Plant_Leaves_Dry"
    },
    {
      "x": -5,
      "y": 8,
      "z": -4,
      "name": "Wood_Spiral_Trunk_Full"
    },
    {
      "x": -5,
      "y": 9,
      "z": -4,
      "name": "Rock_Crystal_Yellow_Large"
    },
    {
      "x": -5,
      "y": 10,
      "z": -4,
      "name": "Plant_Leaves_Dry"
    },
    {
      "x": -5,
      "y": 10,
      "z": -3,
      "name": "Plant_Leaves_Dry"
    },
    {
      "x": -5,
      "y": 14,
      "z": -3,
      "name": "Plant_Leaves_Dry"
    },
    {
      "x": -5,
      "y": 15,
      "z": -2,
      "name": "Plant_Leaves_Dry"
    },
    {
      "x": -5,
      "y": 9,
      "z": -1,
      "name": "Plant_Leaves_Dry"
    },
    {
      "x": -5,
      "y": 14,
      "z": -1,
      "name": "Wood_Spiral_Branch_Corner",
      "rotation": 3
    },
    {
      "x": -5,
      "y": 15,
      "z": -1,
      "name": "Plant_Leaves_Dry"
    },
    {
      "x": -5,
      "y": 8,
      "z": 0,
      "name": "Wood_Spiral_Trunk_Full"
    },
    {
      "x": -5,
      "y": 10,
      "z": 0,
      "name": "Plant_Leaves_Dry"
    },
    {
      "x": -5,
      "y": 14,
      "z": 0,
      "name": "Plant_Leaves_Dry"
    },
    {
      "x": -5,
      "y": 10,
      "z": 1,
      "name": "Plant_Leaves_Dry"
    },
    {
      "x": -5,
      "y": 9,
      "z": 3,
      "name": "Plant_Leaves_Dry"
    },
    {
      "x": -5,
      "y": 15,
      "z": 3,
      "name": "Plant_Leaves_Dry"
    },
    {
      "x": -5,
      "y": 9,
      "z": 4,
      "name": "Wood_Spiral_Branch_Corner",
      "rotation": 3
    },
    {
      "x": -5,
      "y": 10,
      "z": 4,
      "name": "Plant_Leaves_Dry"
    },
    {
      "x": -5,
      "y": 9,
      "z": 6,
      "name": "Plant_Leaves_Dry"
    },
    {
      "x": -4,
      "y": 9,
      "z": -6,
      "name": "Plant_Leaves_Dry"
    },
    {
      "x": -4,
      "y": 10,
      "z": -4,
      "name": "Plant_Leaves_Dry"
    },
    {
      "x": -4,
      "y": 14,
      "z": -4,
      "name": "Plant_Leaves_Dry"
    },
    {
      "x": -4,
      "y": 7,
      "z": -3,
      "name": "Wood_Spiral_Trunk_Full"
    },
    {
      "x": -4,
      "y": 15,
      "z": -2,
      "name": "Plant_Leaves_Dry"
    },
    {
      "x": -4,
      "y": 17,
      "z": -2,
      "name": "Plant_Leaves_Dry"
    },
    {
      "x": -4,
      "y": 13,
      "z": -1,
      "name": "Wood_Spiral_Branch_Corner",
      "rotation": 3
    },
    {
      "x": -4,
      "y": 14,
      "z": -1,
      "name": "Wood_Spiral_Branch_Corner",
      "rotation": 11
    },
    {
      "x": -4,
      "y": 18,
      "z": -1,
      "name": "Plant_Leaves_Dry"
    },
    {
      "x": -4,
      "y": 14,
      "z": 0,
      "name": "Plant_Leaves_Dry"
    },
    {
      "x": -4,
      "y": 15,
      "z": 0,
      "name": "Plant_Leaves_Dry"
    },
    {
      "x": -4,
      "y": 8,
      "z": 1,
      "name": "Wood_Spiral_Trunk_Full"
    },
    {
      "x": -4,
      "y": 18,
      "z": 1,
      "name": "Plant_Leaves_Dry"
    },
    {
      "x": -4,
      "y": 15,
      "z": 2,
      "name": "Plant_Leaves_Dry"
    },
    {
      "x": -4,
      "y": 10,
      "z": 3,
      "name": "Plant_Leaves_Dry"
    },
    {
      "x": -4,
      "y": 15,
      "z": 3,
      "name": "Wood_Spiral_Branch_Corner",
      "rotation": 3
    },
    {
      "x": -4,
      "y": 16,
      "z": 3,
      "name": "Plant_Leaves_Dry"
    },
    {
      "x": -4,
      "y": 9,
      "z": 4,
      "name": "Wood_Spiral_Trunk_Full"
    },
    {
      "x": -4,
      "y": 10,
      "z": 4,
      "name": "Rock_Crystal_Yellow_Large"
    },
    {
      "x": -4,
      "y": 15,
      "z": 4,
      "name": "Plant_Leaves_Dry"
    },
    {
      "x": -4,
      "y": 9,
      "z": 5,
      "name": "Wood_Spiral_Branch_Corner"
    },
    {
      "x": -4,
      "y": 10,
      "z": 5,
      "name": "Plant_Leaves_Dry"
    },
    {
      "x": -4,
      "y": 10,
      "z": 6,
      "name": "Plant_Leaves_Dry"
    },
    {
      "x": -3,
      "y": 14,
      "z": -4,
      "name": "Plant_Leaves_Dry"
    },
    {
      "x": -3,
      "y": 13,
      "z": -3,
      "name": "Wood_Spiral_Trunk_Full"
    },
    {
      "x": -3,
      "y": 14,
      "z": -3,
      "name": "Wood_Spiral_Branch_Long"
    },
    {
      "x": -3,
      "y": 15,
      "z": -3,
      "name": "Plant_Leaves_Dry"
    },
    {
      "x": -3,
      "y": 17,
      "z": -3,
      "name": "Plant_Leaves_Dry"
    },
    {
      "x": -3,
      "y": 7,
      "z": -2,
      "name": "Wood_Spiral_Trunk_Full"
    },
    {
      "x": -3,
      "y": 18,
      "z": -2,
      "name": "Plant_Leaves_Dry"
    },
    {
      "x": -3,
      "y": 13,
      "z": -1,
      "name": "Wood_Spiral_Trunk_Full"
    },
    {
      "x": -3,
      "y": 14,
      "z": -1,
      "name": "Rock_Crystal_Yellow_Large"
    },
    {
      "x": -3,
      "y": 15,
      "z": -1,
      "name": "Plant_Leaves_Dry"
    },
    {
      "x": -3,
      "y": 7,
      "z": 0,
      "name": "Wood_Spiral_Trunk_Full"
    },
    {
      "x": -3,
      "y": 15,
      "z": 0,
      "name": "Plant_Leaves_Dry"
    },
    {
      "x": -3,
      "y": 19,
      "z": 0,
      "name": "Plant_Leaves_Dry"
    },
    {
      "x": -3,
      "y": 8,
      "z": 1,
      "name": "Wood_Spiral_Trunk_Full"
    },
    {
      "x": -3,
      "y": 16,
      "z": 2,
      "name": "Plant_Leaves_Dry"
    },
    {
      "x": -3,
      "y": 18,
      "z": 2,
      "name": "Plant_Leaves_Dry"
    },
    {
      "x": -3,
      "y": 8,
      "z": 3,
      "name": "Wood_Spiral_Trunk_Full"
    },
    {
      "x": -3,
      "y": 14,
      "z": 3,
      "name": "Wood_Spiral_Branch_Corner",
      "rotation": 2
    },
    {
      "x": -3,
      "y": 15,
      "z": 3,
      "name": "Wood_Spiral_Branch_Corner",
      "rotation": 11
    },
    {
      "x": -3,
      "y": 16,
      "z": 3,
      "name": "Plant_Leaves_Dry"
    },
    {
      "x": -3,
      "y": 18,
      "z": 3,
      "name": "Plant_Leaves_Dry"
    },
    {
      "x": -3,
      "y": 10,
      "z": 4,
      "name": "Plant_Leaves_Dry"
    },
    {
      "x": -3,
      "y": 13,
      "z": 4,
      "name": "Wood_Spiral_Branch_Corner",
      "rotation": 3
    },
    {
      "x": -3,
      "y": 14,
      "z": 4,
      "name": "Wood_Spiral_Branch_Corner",
      "rotation": 10
    },
    {
      "x": -3,
      "y": 16,
      "z": 4,
      "name": "Plant_Leaves_Dry"
    },
    {
      "x": -3,
      "y": 15,
      "z": 5,
      "name": "Plant_Leaves_Dry"
    },
    {
      "x": -3,
      "y": 9,
      "z": 6,
      "name": "Plant_Leaves_Dry"
    },
    {
      "x": -2,
      "y": 9,
      "z": -7,
      "name": "Plant_Leaves_Dry"
    },
    {
      "x": -2,
      "y": 14,
      "z": -6,
      "name": "Plant_Leaves_Dry"
    },
    {
      "x": -2,
      "y": 9,
      "z": -5,
      "name": "Plant_Leaves_Dry"
    },
    {
      "x": -2,
      "y": 18,
      "z": -3,
      "name": "Plant_Leaves_Dry"
    },
    {
      "x": -2,
      "y": 13,
      "z": -2,
      "name": "Wood_Spiral_Trunk_Full"
    },
    {
      "x": -2,
      "y": 19,
      "z": -2,
      "name": "Plant_Leaves_Dry"
    },
    {
      "x": -2,
      "y": 6,
      "z": -1,
      "name": "Wood_Spiral_Trunk_Full"
    },
    {
      "x": -2,
      "y": 7,
      "z": -1,
      "name": "Wood_Spiral_Trunk_Full"
    },
    {
      "x": -2,
      "y": 16,
      "z": -1,
      "name": "Wood_Spiral_Branch_Corner",
      "rotation": 3
    },
    {
      "x": -2,
      "y": 17,
      "z": -1,
      "name": "Wood_Spiral_Branch_Long"
    },
    {
      "x": -2,
      "y": 18,
      "z": -1,
      "name": "Wood_Spiral_Branch_Long"
    },
    {
      "x": -2,
      "y": 19,
      "z": -1,
      "name": "Plant_Leaves_Dry"
    },
    {
      "x": -2,
      "y": 7,
      "z": 0,
      "name": "Wood_Spiral_Trunk_Full"
    },
    {
      "x": -2,
      "y": 8,
      "z": 0,
      "name": "Wood_Spiral_Trunk_Full"
    },
    {
      "x": -2,
      "y": 20,
      "z": 0,
      "name": "Plant_Leaves_Dry"
    },
    {
      "x": -2,
      "y": 7,
      "z": 1,
      "name": "Wood_Spiral_Trunk_Full"
    },
    {
      "x": -2,
      "y": 8,
      "z": 1,
      "name": "Wood_Spiral_Trunk_Full"
    },
    {
      "x": -2,
      "y": 9,
      "z": 1,
      "name": "Wood_Spiral_Trunk_Full"
    },
    {
      "x": -2,
      "y": 19,
      "z": 1,
      "name": "Plant_Leaves_Dry"
    },
    {
      "x": -2,
      "y": 8,
      "z": 2,
      "name": "Wood_Spiral_Trunk_Full"
    },
    {
      "x": -2,
      "y": 14,
      "z": 2,
      "name": "Wood_Spiral_Trunk_Full"
    },
    {
      "x": -2,
      "y": 15,
      "z": 2,
      "name": "Wood_Spiral_Branch_Long"
    },
    {
      "x": -2,
      "y": 16,
      "z": 2,
      "name": "Wood_Spiral_Branch_Long"
    },
    {
      "x": -2,
      "y": 17,
      "z": 2,
      "name": "Wood_Spiral_Branch_Long"
    },
    {
      "x": -2,
      "y": 18,
      "z": 2,
      "name": "Wood_Spiral_Branch_Long"
    },
    {
      "x": -2,
      "y": 19,
      "z": 2,
      "name": "Plant_Leaves_Dry"
    },
    {
      "x": -2,
      "y": 14,
      "z": 3,
      "name": "Rock_Crystal_Yellow_Large",
      "rotation": 4
    },
    {
      "x": -2,
      "y": 18,
      "z": 3,
      "name": "Plant_Leaves_Dry"
    },
    {
      "x": -2,
      "y": 13,
      "z": 4,
      "name": "Wood_Spiral_Branch_Long",
      "rotation": 5
    },
    {
      "x": -2,
      "y": 16,
      "z": 4,
      "name": "Plant_Leaves_Dry"
    },
    {
      "x": -2,
      "y": 9,
      "z": 5,
      "name": "Plant_Leaves_Dry"
    },
    {
      "x": -2,
      "y": 14,
      "z": 6,
      "name": "Plant_Leaves_Dry"
    },
    {
      "x": -1,
      "y": 9,
      "z": -8,
      "name": "Plant_Leaves_Dry"
    },
    {
      "x": -1,
      "y": 9,
      "z": -7,
      "name": "Wood_Spiral_Branch_Corner",
      "rotation": 2
    },
    {
      "x": -1,
      "y": 10,
      "z": -7,
      "name": "Plant_Leaves_Dry"
    },
    {
      "x": -1,
      "y": 14,
      "z": -7,
      "name": "Plant_Leaves_Dry"
    },
    {
      "x": -1,
      "y": 8,
      "z": -6,
      "name": "Wood_Spiral_Branch_Corner",
      "rotation": 2
    },
    {
      "x": -1,
      "y": 9,
      "z": -6,
      "name": "Wood_Spiral_Branch_Corner",
      "rotation": 10
    },
    {
      "x": -1,
      "y": 10,
      "z": -6,
      "name": "Plant_Leaves_Dry"
    },
    {
      "x": -1,
      "y": 8,
      "z": -5,
      "name": "Wood_Spiral_Trunk_Full"
    },
    {
      "x": -1,
      "y": 9,
      "z": -5,
      "name": "Rock_Crystal_Yellow_Large"
    },
    {
      "x": -1,
      "y": 15,
      "z": -5,
      "name": "Plant_Leaves_Dry"
    },
    {
      "x": -1,
      "y": 7,
      "z": -4,
      "name": "Wood_Spiral_Trunk_Full"
    },
    {
      "x": -1,
      "y": 18,
      "z": -4,
      "name": "Plant_Leaves_Dry"
    },
    {
      "x": -1,
      "y": 7,
      "z": -3,
      "name": "Wood_Spiral_Trunk_Full"
    },
    {
      "x": -1,
      "y": 6,
      "z": -2,
      "name": "Wood_Spiral_Trunk_Full"
    },
    {
      "x": -1,
      "y": 12,
      "z": -2,
      "name": "Wood_Spiral_Trunk_Full"
    },
    {
      "x": -1,
      "y": 13,
      "z": -2,
      "name": "Wood_Spiral_Trunk_Full"
    },
    {
      "x": -1,
      "y": 19,
      "z": -2,
      "name": "Plant_Leaves_Dry"
    },
    {
      "x": -1,
      "y": 3,
      "z": -1,
      "name": "Wood_Spiral_Trunk_Full"
    },
    {
      "x": -1,
      "y": 5,
      "z": -1,
      "name": "Wood_Spiral_Trunk_Full"
    },
    {
      "x": -1,
      "y": 6,
      "z": -1,
      "name": "Wood_Spiral_Trunk_Full"
    },
    {
      "x": -1,
      "y": 12,
      "z": -1,
      "name": "Wood_Spiral_Trunk_Full"
    },
    {
      "x": -1,
      "y": 13,
      "z": -1,
      "name": "Wood_Spiral_Trunk_Full"
    },
    {
      "x": -1,
      "y": 14,
      "z": -1,
      "name": "Wood_Spiral_Trunk_Full"
    },
    {
      "x": -1,
      "y": 15,
      "z": -1,
      "name": "Wood_Spiral_Branch_Long"
    },
    {
      "x": -1,
      "y": 16,
      "z": -1,
      "name": "Wood_Spiral_Branch_Corner",
      "rotation": 11
    },
    {
      "x": -1,
      "y": 3,
      "z": 0,
      "name": "Wood_Spiral_Trunk_Full"
    },
    {
      "x": -1,
      "y": 4,
      "z": 0,
      "name": "Wood_Spiral_Trunk_Full"
    },
    {
      "x": -1,
      "y": 5,
      "z": 0,
      "name": "Wood_Spiral_Trunk_Full"
    },
    {
      "x": -1,
      "y": 6,
      "z": 0,
      "name": "Wood_Spiral_Trunk_Full"
    },
    {
      "x": -1,
      "y": 7,
      "z": 0,
      "name": "Wood_Spiral_Trunk_Full"
    },
    {
      "x": -1,
      "y": 17,
      "z": 0,
      "name": "Rock_Crystal_Yellow_Large",
      "rotation": 7
    },
    {
      "x": -1,
      "y": 20,
      "z": 0,
      "name": "Plant_Leaves_Dry"
    },
    {
      "x": -1,
      "y": 3,
      "z": 1,
      "name": "Wood_Spiral_Trunk_Full"
    },
    {
      "x": -1,
      "y": 4,
      "z": 1,
      "name": "Wood_Spiral_Trunk_Full"
    },
    {
      "x": -1,
      "y": 8,
      "z": 1,
      "name": "Wood_Spiral_Trunk_Full"
    },
    {
      "x": -1,
      "y": 20,
      "z": 1,
      "name": "Plant_Leaves_Dry"
    },
    {
      "x": -1,
      "y": 8,
      "z": 2,
      "name": "Wood_Spiral_Trunk_Full"
    },
    {
      "x": -1,
      "y": 9,
      "z": 2,
      "name": "Wood_Spiral_Trunk_Full"
    },
    {
      "x": -1,
      "y": 13,
      "z": 2,
      "name": "Wood_Spiral_Trunk_Full"
    },
    {
      "x": -1,
      "y": 19,
      "z": 2,
      "name": "Plant_Leaves_Dry"
    },
    {
      "x": -1,
      "y": 8,
      "z": 3,
      "name": "Wood_Spiral_Trunk_Full"
    },
    {
      "x": -1,
      "y": 19,
      "z": 3,
      "name": "Plant_Leaves_Dry"
    },
    {
      "x": -1,
      "y": 13,
      "z": 4,
      "name": "Wood_Spiral_Trunk_Full"
    },
    {
      "x": -1,
      "y": 18,
      "z": 4,
      "name": "Plant_Leaves_Dry"
    },
    {
      "x": -1,
      "y": 13,
      "z": 5,
      "name": "Wood_Spiral_Branch_Corner"
    },
    {
      "x": -1,
      "y": 14,
      "z": 5,
      "name": "Wood_Spiral_Branch_Long"
    },
    {
      "x": -1,
      "y": 15,
      "z": 5,
      "name": "Plant_Leaves_Dry"
    },
    {
      "x": -1,
      "y": 10,
      "z": 6,
      "name": "Plant_Leaves_Dry"
    },
    {
      "x": -1,
      "y": 15,
      "z": 6,
      "name": "Plant_Leaves_Dry"
    },
    {
      "x": -1,
      "y": 14,
      "z": 7,
      "name": "Plant_Leaves_Dry"
    },
    {
      "x": 0,
      "y": 9,
      "z": -7,
      "name": "Plant_Leaves_Dry"
    },
    {
      "x": 0,
      "y": 14,
      "z": -7,
      "name": "Plant_Leaves_Dry"
    },
    {
      "x": 0,
      "y": 14,
      "z": -6,
      "name": "Wood_Spiral_Branch_Corner",
      "rotation": 2
    },
    {
      "x": 0,
      "y": 15,
      "z": -6,
      "name": "Plant_Leaves_Dry"
    },
    {
      "x": 0,
      "y": 10,
      "z": -5,
      "name": "Plant_Leaves_Dry"
    },
    {
      "x": 0,
      "y": 13,
      "z": -5,
      "name": "Wood_Spiral_Branch_Corner",
      "rotation": 2
    },
    {
      "x": 0,
      "y": 14,
      "z": -5,
      "name": "Wood_Spiral_Branch_Corner",
      "rotation": 10
    },
    {
      "x": 0,
      "y": 13,
      "z": -4,
      "name": "Wood_Spiral_Trunk_Full"
    },
    {
      "x": 0,
      "y": 14,
      "z": -4,
      "name": "Wood_Spiral_Branch_Long"
    },
    {
      "x": 0,
      "y": 15,
      "z": -4,
      "name": "Wood_Spiral_Branch_Long"
    },
    {
      "x": 0,
      "y": 16,
      "z": -4,
      "name": "Plant_Leaves_Dry"
    },
    {
      "x": 0,
      "y": 18,
      "z": -4,
      "name": "Plant_Leaves_Dry"
    },
    {
      "x": 0,
      "y": 7,
      "z": -3,
      "name": "Wood_Spiral_Trunk_Full"
    },
    {
      "x": 0,
      "y": 12,
      "z": -3,
      "name": "Wood_Spiral_Trunk_Full"
    },
    {
      "x": 0,
      "y": 17,
      "z": -3,
      "name": "Wood_Spiral_Branch_Corner",
      "rotation": 2
    },
    {
      "x": 0,
      "y": 18,
      "z": -3,
      "name": "Wood_Spiral_Branch_Long"
    },
    {
      "x": 0,
      "y": 19,
      "z": -3,
      "name": "Plant_Leaves_Dry"
    },
    {
      "x": 0,
      "y": 11,
      "z": -2,
      "name": "Wood_Spiral_Trunk_Full"
    },
    {
      "x": 0,
      "y": 16,
      "z": -2,
      "name": "Wood_Spiral_Branch_Corner",
      "rotation": 2
    },
    {
      "x": 0,
      "y": 17,
      "z": -2,
      "name": "Wood_Spiral_Branch_Corner",
      "rotation": 10
    },
    {
      "x": 0,
      "y": 20,
      "z": -2,
      "name": "Plant_Leaves_Dry"
    },
    {
      "x": 0,
      "y": 3,
      "z": -1,
      "name": "Wood_Spiral_Trunk_Full"
    },
    {
      "x": 0,
      "y": 4,
      "z": -1,
      "name": "Wood_Spiral_Trunk_Full"
    },
    {
      "x": 0,
      "y": 5,
      "z": -1,
      "name": "Wood_Spiral_Trunk_Full"
    },
    {
      "x": 0,
      "y": 16,
      "z": -1,
      "name": "Wood_Spiral_Trunk_Full"
    },
    {
      "x": 0,
      "y": 17,
      "z": -1,
      "name": "Rock_Crystal_Yellow_Large",
      "rotation": 6
    },
    {
      "x": 0,
      "y": 20,
      "z": -1,
      "name": "Plant_Leaves_Dry"
    },
    {
      "x": 0,
      "y": 3,
      "z": 0,
      "name": "Wood_Spiral_Trunk_Full"
    },
    {
      "x": 0,
      "y": 4,
      "z": 0,
      "name": "Wood_Spiral_Trunk_Full"
    },
    {
      "x": 0,
      "y": 5,
      "z": 0,
      "name": "Wood_Spiral_Trunk_Full"
    },
    {
      "x": 0,
      "y": 6,
      "z": 0,
      "name": "Wood_Spiral_Trunk_Full"
    },
    {
      "x": 0,
      "y": 12,
      "z": 0,
      "name": "Wood_Spiral_Trunk_Full"
    },
    {
      "x": 0,
      "y": 15,
      "z": 0,
      "name": "Wood_Spiral_Trunk_Full"
    },
    {
      "x": 0,
      "y": 16,
      "z": 0,
      "name": "Wood_Spiral_Trunk_Full"
    },
    {
      "x": 0,
      "y": 17,
      "z": 0,
      "name": "Wood_Spiral_Trunk_Full"
    },
    {
      "x": 0,
      "y": 18,
      "z": 0,
      "name": "Wood_Spiral_Branch_Long"
    },
    {
      "x": 0,
      "y": 19,
      "z": 0,
      "name": "Wood_Spiral_Branch_Long"
    },
    {
      "x": 0,
      "y": 20,
      "z": 0,
      "name": "Plant_Leaves_Dry"
    },
    {
      "x": 0,
      "y": 3,
      "z": 1,
      "name": "Wood_Spiral_Trunk_Full"
    },
    {
      "x": 0,
      "y": 4,
      "z": 1,
      "name": "Wood_Spiral_Trunk_Full"
    },
    {
      "x": 0,
      "y": 5,
      "z": 1,
      "name": "Wood_Spiral_Trunk_Full"
    },
    {
      "x": 0,
      "y": 17,
      "z": 1,
      "name": "Wood_Spiral_Branch_Long",
      "rotation": 4
    },
    {
      "x": 0,
      "y": 8,
      "z": 2,
      "name": "Wood_Spiral_Trunk_Full"
    },
    {
      "x": 0,
      "y": 9,
      "z": 2,
      "name": "Wood_Spiral_Trunk_Full"
    },
    {
      "x": 0,
      "y": 17,
      "z": 2,
      "name": "Wood_Spiral_Branch_Corner"
    },
    {
      "x": 0,
      "y": 18,
      "z": 2,
      "name": "Wood_Spiral_Branch_Long"
    },
    {
      "x": 0,
      "y": 19,
      "z": 2,
      "name": "Plant_Leaves_Dry"
    },
    {
      "x": 0,
      "y": 9,
      "z": 3,
      "name": "Wood_Spiral_Trunk_Full"
    },
    {
      "x": 0,
      "y": 13,
      "z": 3,
      "name": "Wood_Spiral_Trunk_Full"
    },
    {
      "x": 0,
      "y": 18,
      "z": 3,
      "name": "Plant_Leaves_Dry"
    },
    {
      "x": 0,
      "y": 16,
      "z": 4,
      "name": "Plant_Leaves_Dry"
    },
    {
      "x": 0,
      "y": 15,
      "z": 5,
      "name": "Plant_Leaves_Dry"
    },
    {
      "x": 0,
      "y": 10,
      "z": 7,
      "name": "Plant_Leaves_Dry"
    },
    {
      "x": 0,
      "y": 14,
      "z": 7,
      "name": "Plant_Leaves_Dry"
    },
    {
      "x": 1,
      "y": 9,
      "z": -8,
      "name": "Plant_Leaves_Dry"
    },
    {
      "x": 1,
      "y": 14,
      "z": -7,
      "name": "Plant_Leaves_Dry"
    },
    {
      "x": 1,
      "y": 10,
      "z": -6,
      "name": "Plant_Leaves_Dry"
    },
    {
      "x": 1,
      "y": 15,
      "z": -6,
      "name": "Plant_Leaves_Dry"
    },
    {
      "x": 1,
      "y": 8,
      "z": -5,
      "name": "Wood_Spiral_Trunk_Full"
    },
    {
      "x": 1,
      "y": 9,
      "z": -5,
      "name": "Rock_Crystal_Yellow_Large"
    },
    {
      "x": 1,
      "y": 10,
      "z": -5,
      "name": "Plant_Leaves_Dry"
    },
    {
      "x": 1,
      "y": 15,
      "z": -5,
      "name": "Plant_Leaves_Dry"
    },
    {
      "x": 1,
      "y": 7,
      "z": -4,
      "name": "Wood_Spiral_Trunk_Full"
    },
    {
      "x": 1,
      "y": 13,
      "z": -4,
      "name": "Rock_Crystal_Yellow_Large",
      "rotation": 5
    },
    {
      "x": 1,
      "y": 11,
      "z": -3,
      "name": "Wood_Spiral_Trunk_Full"
    },
    {
      "x": 1,
      "y": 16,
      "z": -3,
      "name": "Plant_Leaves_Dry"
    },
    {
      "x": 1,
      "y": 10,
      "z": -2,
      "name": "Wood_Spiral_Trunk_Full"
    },
    {
      "x": 1,
      "y": 11,
      "z": -2,
      "name": "Wood_Spiral_Trunk_Full"
    },
    {
      "x": 1,
      "y": 19,
      "z": -2,
      "name": "Plant_Leaves_Dry"
    },
    {
      "x": 1,
      "y": 3,
      "z": -1,
      "name": "Wood_Spiral_Trunk_Full"
    },
    {
      "x": 1,
      "y": 4,
      "z": -1,
      "name": "Wood_Spiral_Trunk_Full"
    },
    {
      "x": 1,
      "y": 10,
      "z": -1,
      "name": "Wood_Spiral_Trunk_Full"
    },
    {
      "x": 1,
      "y": 20,
      "z": -1,
      "name": "Plant_Leaves_Dry"
    },
    {
      "x": 1,
      "y": 3,
      "z": 0,
      "name": "Wood_Spiral_Trunk_Full"
    },
    {
      "x": 1,
      "y": 4,
      "z": 0,
      "name": "Wood_Spiral_Trunk_Full"
    },
    {
      "x": 1,
      "y": 5,
      "z": 0,
      "name": "Wood_Spiral_Trunk_Full"
    },
    {
      "x": 1,
      "y": 16,
      "z": 0,
      "name": "Wood_Spiral_Trunk_Full"
    },
    {
      "x": 1,
      "y": 3,
      "z": 1,
      "name": "Wood_Spiral_Trunk_Full"
    },
    {
      "x": 1,
      "y": 4,
      "z": 1,
      "name": "Wood_Spiral_Trunk_Full"
    },
    {
      "x": 1,
      "y": 9,
      "z": 1,
      "name": "Wood_Spiral_Trunk_Full"
    },
    {
      "x": 1,
      "y": 12,
      "z": 1,
      "name": "Wood_Spiral_Trunk_Full"
    },
    {
      "x": 1,
      "y": 19,
      "z": 1,
      "name": "Plant_Leaves_Dry"
    },
    {
      "x": 1,
      "y": 8,
      "z": 2,
      "name": "Wood_Spiral_Trunk_Full"
    },
    {
      "x": 1,
      "y": 9,
      "z": 2,
      "name": "Wood_Spiral_Trunk_Full"
    },
    {
      "x": 1,
      "y": 13,
      "z": 2,
      "name": "Wood_Spiral_Trunk_Full"
    },
    {
      "x": 1,
      "y": 19,
      "z": 2,
      "name": "Plant_Leaves_Dry"
    },
    {
      "x": 1,
      "y": 9,
      "z": 3,
      "name": "Wood_Spiral_Trunk_Full"
    },
    {
      "x": 1,
      "y": 13,
      "z": 3,
      "name": "Wood_Spiral_Branch_Corner"
    },
    {
      "x": 1,
      "y": 14,
      "z": 3,
      "name": "Wood_Spiral_Branch_Corner",
      "rotation": 8
    },
    {
      "x": 1,
      "y": 16,
      "z": 3,
      "name": "Plant_Leaves_Dry"
    },
    {
      "x": 1,
      "y": 9,
      "z": 4,
      "name": "Wood_Spiral_Trunk_Full"
    },
    {
      "x": 1,
      "y": 14,
      "z": 4,
      "name": "Wood_Spiral_Branch_Corner"
    },
    {
      "x": 1,
      "y": 15,
      "z": 4,
      "name": "Wood_Spiral_Branch_Long"
    },
    {
      "x": 1,
      "y": 16,
      "z": 4,
      "name": "Plant_Leaves_Dry"
    },
    {
      "x": 1,
      "y": 9,
      "z": 5,
      "name": "Wood_Spiral_Trunk_Full"
    },
    {
      "x": 1,
      "y": 10,
      "z": 5,
      "name": "Rock_Crystal_Yellow_Large"
    },
    {
      "x": 1,
      "y": 15,
      "z": 5,
      "name": "Plant_Leaves_Dry"
    },
    {
      "x": 1,
      "y": 16,
      "z": 5,
      "name": "Plant_Leaves_Dry"
    },
    {
      "x": 1,
      "y": 9,
      "z": 6,
      "name": "Wood_Spiral_Branch_Corner"
    },
    {
      "x": 1,
      "y": 10,
      "z": 6,
      "name": "Wood_Spiral_Branch_Corner",
      "rotation": 8
    },
    {
      "x": 1,
      "y": 11,
      "z": 6,
      "name": "Plant_Leaves_Dry"
    },
    {
      "x": 1,
      "y": 14,
      "z": 6,
      "name": "Plant_Leaves_Dry"
    },
    {
      "x": 1,
      "y": 10,
      "z": 7,
      "name": "Wood_Spiral_Branch_Corner"
    },
    {
      "x": 1,
      "y": 11,
      "z": 7,
      "name": "Plant_Leaves_Dry"
    },
    {
      "x": 1,
      "y": 10,
      "z": 8,
      "name": "Plant_Leaves_Dry"
    },
    {
      "x": 2,
      "y": 9,
      "z": -8,
      "name": "Plant_Leaves_Dry"
    },
    {
      "x": 2,
      "y": 9,
      "z": -7,
      "name": "Wood_Spiral_Branch_Corner",
      "rotation": 2
    },
    {
      "x": 2,
      "y": 10,
      "z": -7,
      "name": "Plant_Leaves_Dry"
    },
    {
      "x": 2,
      "y": 9,
      "z": -6,
      "name": "Wood_Spiral_Branch_Long",
      "rotation": 4
    },
    {
      "x": 2,
      "y": 10,
      "z": -6,
      "name": "Plant_Leaves_Dry"
    },
    {
      "x": 2,
      "y": 14,
      "z": -6,
      "name": "Plant_Leaves_Dry"
    },
    {
      "x": 2,
      "y": 8,
      "z": -5,
      "name": "Wood_Spiral_Branch_Corner",
      "rotation": 1
    },
    {
      "x": 2,
      "y": 9,
      "z": -5,
      "name": "Wood_Spiral_Branch_Corner",
      "rotation": 10
    },
    {
      "x": 2,
      "y": 15,
      "z": -5,
      "name": "Plant_Leaves_Dry"
    },
    {
      "x": 2,
      "y": 9,
      "z": -4,
      "name": "Plant_Leaves_Dry"
    },
    {
      "x": 2,
      "y": 16,
      "z": -4,
      "name": "Plant_Leaves_Dry"
    },
    {
      "x": 2,
      "y": 16,
      "z": -3,
      "name": "Plant_Leaves_Dry"
    },
    {
      "x": 2,
      "y": 10,
      "z": -2,
      "name": "Wood_Spiral_Trunk_Full"
    },
    {
      "x": 2,
      "y": 11,
      "z": -2,
      "name": "Wood_Spiral_Trunk_Full"
    },
    {
      "x": 2,
      "y": 18,
      "z": -2,
      "name": "Plant_Leaves_Dry"
    },
    {
      "x": 2,
      "y": 9,
      "z": -1,
      "name": "Wood_Spiral_Trunk_Full"
    },
    {
      "x": 2,
      "y": 10,
      "z": -1,
      "name": "Wood_Spiral_Trunk_Full"
    },
    {
      "x": 2,
      "y": 9,
      "z": 0,
      "name": "Wood_Spiral_Trunk_Full"
    },
    {
      "x": 2,
      "y": 10,
      "z": 0,
      "name": "Wood_Spiral_Trunk_Full"
    },
    {
      "x": 2,
      "y": 13,
      "z": 0,
      "name": "Wood_Spiral_Trunk_Full"
    },
    {
      "x": 2,
      "y": 16,
      "z": 0,
      "name": "Wood_Spiral_Branch_Corner",
      "rotation": 1
    },
    {
      "x": 2,
      "y": 17,
      "z": 0,
      "name": "Wood_Spiral_Branch_Long"
    },
    {
      "x": 2,
      "y": 18,
      "z": 0,
      "name": "Wood_Spiral_Branch_Long"
    },
    {
      "x": 2,
      "y": 19,
      "z": 0,
      "name": "Plant_Leaves_Dry"
    },
    {
      "x": 2,
      "y": 8,
      "z": 1,
      "name": "Wood_Spiral_Trunk_Full"
    },
    {
      "x": 2,
      "y": 9,
      "z": 1,
      "name": "Wood_Spiral_Trunk_Full"
    },
    {
      "x": 2,
      "y": 10,
      "z": 1,
      "name": "Wood_Spiral_Trunk_Full"
    },
    {
      "x": 2,
      "y": 13,
      "z": 1,
      "name": "Wood_Spiral_Branch_Long",
      "rotation": 5
    },
    {
      "x": 2,
      "y": 9,
      "z": 2,
      "name": "Wood_Spiral_Trunk_Full"
    },
    {
      "x": 2,
      "y": 13,
      "z": 3,
      "name": "Wood_Spiral_Trunk_Full"
    },
    {
      "x": 2,
      "y": 14,
      "z": 3,
      "name": "Rock_Crystal_Yellow_Large"
    },
    {
      "x": 2,
      "y": 15,
      "z": 4,
      "name": "Plant_Leaves_Dry"
    },
    {
      "x": 2,
      "y": 9,
      "z": 5,
      "name": "Wood_Spiral_Branch_Corner",
      "rotation": 1
    },
    {
      "x": 2,
      "y": 10,
      "z": 5,
      "name": "Wood_Spiral_Branch_Corner",
      "rotation": 9
    },
    {
      "x": 2,
      "y": 11,
      "z": 5,
      "name": "Plant_Leaves_Dry"
    },
    {
      "x": 2,
      "y": 14,
      "z": 5,
      "name": "Plant_Leaves_Dry"
    },
    {
      "x": 2,
      "y": 10,
      "z": 7,
      "name": "Plant_Leaves_Dry"
    },
    {
      "x": 3,
      "y": 9,
      "z": -7,
      "name": "Plant_Leaves_Dry"
    },
    {
      "x": 3,
      "y": 14,
      "z": -6,
      "name": "Plant_Leaves_Dry"
    },
    {
      "x": 3,
      "y": 9,
      "z": -5,
      "name": "Plant_Leaves_Dry"
    },
    {
      "x": 3,
      "y": 14,
      "z": -4,
      "name": "Wood_Spiral_Branch_Corner",
      "rotation": 2
    },
    {
      "x": 3,
      "y": 15,
      "z": -4,
      "name": "Plant_Leaves_Dry"
    },
    {
      "x": 3,
      "y": 13,
      "z": -3,
      "name": "Wood_Spiral_Branch_Corner",
      "rotation": 2
    },
    {
      "x": 3,
      "y": 14,
      "z": -3,
      "name": "Wood_Spiral_Branch_Corner",
      "rotation": 10
    },
    {
      "x": 3,
      "y": 15,
      "z": -3,
      "name": "Plant_Leaves_Dry"
    },
    {
      "x": 3,
      "y": 13,
      "z": -2,
      "name": "Wood_Spiral_Branch_Long",
      "rotation": 4
    },
    {
      "x": 3,
      "y": 10,
      "z": -1,
      "name": "Wood_Spiral_Trunk_Full"
    },
    {
      "x": 3,
      "y": 13,
      "z": -1,
      "name": "Wood_Spiral_Trunk_Full"
    },
    {
      "x": 3,
      "y": 14,
      "z": -1,
      "name": "Rock_Crystal_Yellow_Large"
    },
    {
      "x": 3,
      "y": 18,
      "z": -1,
      "name": "Plant_Leaves_Dry"
    },
    {
      "x": 3,
      "y": 10,
      "z": 0,
      "name": "Wood_Spiral_Trunk_Full"
    },
    {
      "x": 3,
      "y": 18,
      "z": 0,
      "name": "Plant_Leaves_Dry"
    },
    {
      "x": 3,
      "y": 9,
      "z": 1,
      "name": "Wood_Spiral_Trunk_Full"
    },
    {
      "x": 3,
      "y": 13,
      "z": 1,
      "name": "Wood_Spiral_Branch_Corner",
      "rotation": 1
    },
    {
      "x": 3,
      "y": 14,
      "z": 1,
      "name": "Wood_Spiral_Branch_Corner",
      "rotation": 9
    },
    {
      "x": 3,
      "y": 16,
      "z": 1,
      "name": "Plant_Leaves_Dry"
    },
    {
      "x": 3,
      "y": 15,
      "z": 2,
      "name": "Plant_Leaves_Dry"
    },
    {
      "x": 3,
      "y": 13,
      "z": 3,
      "name": "Wood_Spiral_Branch_Corner",
      "rotation": 1
    },
    {
      "x": 3,
      "y": 14,
      "z": 3,
      "name": "Wood_Spiral_Branch_Corner",
      "rotation": 9
    },
    {
      "x": 3,
      "y": 15,
      "z": 3,
      "name": "Plant_Leaves_Dry"
    },
    {
      "x": 3,
      "y": 10,
      "z": 4,
      "name": "Plant_Leaves_Dry"
    },
    {
      "x": 3,
      "y": 10,
      "z": 5,
      "name": "Wood_Spiral_Branch_Corner",
      "rotation": 1
    },
    {
      "x": 3,
      "y": 11,
      "z": 5,
      "name": "Plant_Leaves_Dry"
    },
    {
      "x": 3,
      "y": 10,
      "z": 6,
      "name": "Plant_Leaves_Dry"
    },
    {
      "x": 3,
      "y": 11,
      "z": 6,
      "name": "Plant_Leaves_Dry"
    },
    {
      "x": 4,
      "y": 9,
      "z": -6,
      "name": "Plant_Leaves_Dry"
    },
    {
      "x": 4,
      "y": 11,
      "z": -5,
      "name": "Plant_Leaves_Dry"
    },
    {
      "x": 4,
      "y": 14,
      "z": -5,
      "name": "Plant_Leaves_Dry"
    },
    {
      "x": 4,
      "y": 12,
      "z": -4,
      "name": "Plant_Leaves_Dry"
    },
    {
      "x": 4,
      "y": 14,
      "z": -4,
      "name": "Plant_Leaves_Dry"
    },
    {
      "x": 4,
      "y": 15,
      "z": -4,
      "name": "Plant_Leaves_Dry"
    },
    {
      "x": 4,
      "y": 10,
      "z": -1,
      "name": "Wood_Spiral_Trunk_Full"
    },
    {
      "x": 4,
      "y": 13,
      "z": -1,
      "name": "Wood_Spiral_Branch_Corner",
      "rotation": 1
    },
    {
      "x": 4,
      "y": 14,
      "z": -1,
      "name": "Wood_Spiral_Branch_Corner",
      "rotation": 9
    },
    {
      "x": 4,
      "y": 16,
      "z": -1,
      "name": "Plant_Leaves_Dry"
    },
    {
      "x": 4,
      "y": 16,
      "z": 0,
      "name": "Plant_Leaves_Dry"
    },
    {
      "x": 4,
      "y": 14,
      "z": 1,
      "name": "Wood_Spiral_Branch_Corner",
      "rotation": 1
    },
    {
      "x": 4,
      "y": 15,
      "z": 1,
      "name": "Wood_Spiral_Branch_Long"
    },
    {
      "x": 4,
      "y": 16,
      "z": 1,
      "name": "Plant_Leaves_Dry"
    },
    {
      "x": 4,
      "y": 10,
      "z": 2,
      "name": "Wood_Spiral_Trunk_Full"
    },
    {
      "x": 4,
      "y": 11,
      "z": 3,
      "name": "Plant_Leaves_Dry"
    },
    {
      "x": 4,
      "y": 14,
      "z": 3,
      "name": "Wood_Spiral_Branch_Corner",
      "rotation": 1
    },
    {
      "x": 4,
      "y": 15,
      "z": 3,
      "name": "Plant_Leaves_Dry"
    },
    {
      "x": 4,
      "y": 11,
      "z": 4,
      "name": "Plant_Leaves_Dry"
    },
    {
      "x": 4,
      "y": 14,
      "z": 4,
      "name": "Plant_Leaves_Dry"
    },
    {
      "x": 4,
      "y": 10,
      "z": 5,
      "name": "Plant_Leaves_Dry"
    },
    {
      "x": 5,
      "y": 11,
      "z": -6,
      "name": "Plant_Leaves_Dry"
    },
    {
      "x": 5,
      "y": 11,
      "z": -5,
      "name": "Wood_Spiral_Branch_Corner",
      "rotation": 2
    },
    {
      "x": 5,
      "y": 12,
      "z": -5,
      "name": "Plant_Leaves_Dry"
    },
    {
      "x": 5,
      "y": 11,
      "z": -4,
      "name": "Wood_Spiral_Branch_Long",
      "rotation": 4
    },
    {
      "x": 5,
      "y": 12,
      "z": -4,
      "name": "Plant_Leaves_Dry"
    },
    {
      "x": 5,
      "y": 11,
      "z": -3,
      "name": "Wood_Spiral_Trunk_Full"
    },
    {
      "x": 5,
      "y": 12,
      "z": -3,
      "name": "Rock_Crystal_Yellow_Large"
    },
    {
      "x": 5,
      "y": 11,
      "z": -2,
      "name": "Wood_Spiral_Trunk_Full"
    },
    {
      "x": 5,
      "y": 12,
      "z": -2,
      "name": "Plant_Leaves_Dry"
    },
    {
      "x": 5,
      "y": 14,
      "z": -2,
      "name": "Plant_Leaves_Dry"
    },
    {
      "x": 5,
      "y": 15,
      "z": -2,
      "name": "Plant_Leaves_Dry"
    },
    {
      "x": 5,
      "y": 14,
      "z": -1,
      "name": "Wood_Spiral_Branch_Corner",
      "rotation": 1
    },
    {
      "x": 5,
      "y": 15,
      "z": -1,
      "name": "Plant_Leaves_Dry"
    },
    {
      "x": 5,
      "y": 16,
      "z": 0,
      "name": "Plant_Leaves_Dry"
    },
    {
      "x": 5,
      "y": 15,
      "z": 1,
      "name": "Plant_Leaves_Dry"
    },
    {
      "x": 5,
      "y": 14,
      "z": 2,
      "name": "Plant_Leaves_Dry"
    },
    {
      "x": 5,
      "y": 15,
      "z": 2,
      "name": "Plant_Leaves_Dry"
    },
    {
      "x": 5,
      "y": 10,
      "z": 3,
      "name": "Wood_Spiral_Trunk_Full"
    },
    {
      "x": 5,
      "y": 11,
      "z": 3,
      "name": "Rock_Crystal_Yellow_Large"
    },
    {
      "x": 5,
      "y": 14,
      "z": 3,
      "name": "Plant_Leaves_Dry"
    },
    {
      "x": 5,
      "y": 10,
      "z": 4,
      "name": "Wood_Spiral_Branch_Corner"
    },
    {
      "x": 5,
      "y": 11,
      "z": 4,
      "name": "Plant_Leaves_Dry"
    },
    {
      "x": 5,
      "y": 10,
      "z": 5,
      "name": "Plant_Leaves_Dry"
    },
    {
      "x": 5,
      "y": 11,
      "z": 5,
      "name": "Plant_Leaves_Dry"
    },
    {
      "x": 6,
      "y": 11,
      "z": -5,
      "name": "Plant_Leaves_Dry"
    },
    {
      "x": 6,
      "y": 12,
      "z": -3,
      "name": "Plant_Leaves_Dry"
    },
    {
      "x": 6,
      "y": 11,
      "z": -2,
      "name": "Wood_Spiral_Branch_Long",
      "rotation": 5
    },
    {
      "x": 6,
      "y": 12,
      "z": -2,
      "name": "Plant_Leaves_Dry"
    },
    {
      "x": 6,
      "y": 14,
      "z": -2,
      "name": "Plant_Leaves_Dry"
    },
    {
      "x": 6,
      "y": 12,
      "z": -1,
      "name": "Plant_Leaves_Dry"
    },
    {
      "x": 6,
      "y": 15,
      "z": -1,
      "name": "Plant_Leaves_Dry"
    },
    {
      "x": 6,
      "y": 10,
      "z": 1,
      "name": "Plant_Leaves_Dry"
    },
    {
      "x": 6,
      "y": 14,
      "z": 1,
      "name": "Plant_Leaves_Dry"
    },
    {
      "x": 6,
      "y": 10,
      "z": 2,
      "name": "Wood_Spiral_Branch_Corner",
      "rotation": 2
    },
    {
      "x": 6,
      "y": 11,
      "z": 2,
      "name": "Plant_Leaves_Dry"
    },
    {
      "x": 6,
      "y": 10,
      "z": 3,
      "name": "Wood_Spiral_Trunk_Full"
    },
    {
      "x": 6,
      "y": 11,
      "z": 3,
      "name": "Plant_Leaves_Dry"
    },
    {
      "x": 6,
      "y": 10,
      "z": 5,
      "name": "Plant_Leaves_Dry"
    },
    {
      "x": 7,
      "y": 11,
      "z": -4,
      "name": "Plant_Leaves_Dry"
    },
    {
      "x": 7,
      "y": 11,
      "z": -2,
      "name": "Wood_Spiral_Branch_Corner",
      "rotation": 1
    },
    {
      "x": 7,
      "y": 12,
      "z": -2,
      "name": "Plant_Leaves_Dry"
    },
    {
      "x": 7,
      "y": 11,
      "z": -1,
      "name": "Plant_Leaves_Dry"
    },
    {
      "x": 7,
      "y": 14,
      "z": -1,
      "name": "Plant_Leaves_Dry"
    },
    {
      "x": 7,
      "y": 14,
      "z": 0,
      "name": "Plant_Leaves_Dry"
    },
    {
      "x": 7,
      "y": 10,
      "z": 1,
      "name": "Plant_Leaves_Dry"
    },
    {
      "x": 7,
      "y": 10,
      "z": 3,
      "name": "Wood_Spiral_Branch_Corner",
      "rotation": 1
    },
    {
      "x": 7,
      "y": 11,
      "z": 3,
      "name": "Plant_Leaves_Dry"
    },
    {
      "x": 7,
      "y": 10,
      "z": 4,
      "name": "Plant_Leaves_Dry"
    },
    {
      "x": 8,
      "y": 11,
      "z": -2,
      "name": "Plant_Leaves_Dry"
    },
    {
      "x": 8,
      "y": 10,
      "z": 2,
      "name": "Plant_Leaves_Dry"
    },
    {
      "x": 8,
      "y": 10,
      "z": 3,
      "name": "Plant_Leaves_Dry"
    }
  ]
}