{
  "version": 8,
  "blockIdVersion": 11,
  "anchorX": 6,
  "anchorY": 0,
  "anchorZ": -6,
  "blocks": [
    {
      "x": -1,
      "y": -23,
      "z": -2,
      "name": "Rock_Ice_Permafrost",
      "rotation": 3
    },
    {
      "x": -1,
      "y": -22,
      "z": -2,
      "name": "Rock_Ice",
      "rotation": 3
    },
    {
      "x": -1,
      "y": -21,
      "z": -2,
      "name": "Soil_Snow",
      "rotation": 3
    },
    {
      "x": -1,
      "y": -28,
      "z": -1,
      "name": "Rock_Ice_Permafrost",
      "rotation": 3
    },
    {
      "x": -1,
      "y": -27,
      "z": -1,
      "name": "Rock_Ice_Permafrost",
      "rotation": 3
    },
    {
      "x": -1,
      "y": -26,
      "z": -1,
      "name": "Rock_Ice_Permafrost",
      "rotation": 3
    },
    {
      "x": -1,
      "y": -25,
      "z": -1,
      "name": "Rock_Ice_Permafrost",
      "rotation": 3
    },
    {
      "x": -1,
      "y": -24,
      "z": -1,
      "name": "Rock_Ice",
      "rotation": 3
    },
    {
      "x": -1,
      "y": -23,
      "z": -1,
      "name": "Rock_Ice",
      "rotation": 3
    },
    {
      "x": -1,
      "y": -22,
      "z": -1,
      "name": "Rock_Ice",
      "rotation": 3
    },
    {
      "x": -1,
      "y": -21,
      "z": -1,
      "name": "Rock_Ice",
      "rotation": 3
    },
    {
      "x": -1,
      "y": -20,
      "z": -1,
      "name": "Soil_Snow",
      "rotation": 3
    },
    {
      "x": -1,
      "y": -29,
      "z": 0,
      "name": "Rock_Ice_Permafrost",
      "rotation": 3
    },
    {
      "x": -1,
      "y": -28,
      "z": 0,
      "name": "Rock_Ice_Permafrost",
      "rotation": 3
    },
    {
      "x": -1,
      "y": -27,
      "z": 0,
      "name": "Rock_Ice_Permafrost",
      "rotation": 3
    },
    {
      "x": -1,
      "y": -26,
      "z": 0,
      "name": "Rock_Ice",
      "rotation": 3
    },
    {
      "x": -1,
      "y": -25,
      "z": 0,
      "name": "Rock_Ice",
      "rotation": 3
    },
    {
      "x": -1,
      "y": -24,
      "z": 0,
      "name": "Rock_Ice",
      "rotation": 3
    },
    {
      "x": -1,
      "y": -23,
      "z": 0,
      "name": "Rock_Ice",
      "rotation": 3
    },
    {
      "x": -1,
      "y": -22,
      "z": 0,
      "name": "Soil_Snow",
      "rotation": 3
    },
    {
      "x": -1,
      "y": -28,
      "z": 1,
      "name": "Rock_Ice_Permafrost",
      "rotation": 3
    },
    {
      "x": -1,
      "y": -27,
      "z": 1,
      "name": "Rock_Ice",
      "rotation": 3
    },
    {
      "x": -1,
      "y": -26,
      "z": 1,
      "name": "Rock_Ice",
      "rotation": 3
    },
    {
      "x": -1,
      "y": -25,
      "z": 1,
      "name": "Rock_Ice",
      "rotation": 3
    },
    {
      "x": -1,
      "y": -24,
      "z": 1,
      "name": "Rock_Ice",
      "rotation": 3
    },
    {
      "x": -1,
      "y": -23,
      "z": 1,
      "name": "Soil_Snow",
      "rotation": 3
    },
    {
      "x": -1,
      "y": -26,
      "z": 2,
      "name": "Rock_Ice",
      "rotation": 3
    },
    {
      "x": -1,
      "y": -25,
      "z": 2,
      "name": "Rock_Ice",
      "rotation": 3
    },
    {
      "x": -1,
      "y": -24,
      "z": 2,
      "name": "Rock_Ice",
      "rotation": 3
    },
    {
      "x": -1,
      "y": -23,
      "z": 2,
      "name": "Soil_Snow",
      "rotation": 3
    },
    {
      "x": -1,
      "y": -24,
      "z": 3,
      "name": "Soil_Snow",
      "rotation": 3
    },
    {
      "x": 0,
      "y": -23,
      "z": -4,
      "name": "Rock_Ice_Permafrost",
      "rotation": 3
    },
    {
      "x": 0,
      "y": -22,
      "z": -4,
      "name": "Rock_Ice",
      "rotation": 3
    },
    {
      "x": 0,
      "y": -21,
      "z": -4,
      "name": "Rock_Ice",
      "rotation": 3
    },
    {
      "x": 0,
      "y": -20,
      "z": -4,
      "name": "Soil_Snow",
      "rotation": 3
    },
    {
      "x": 0,
      "y": -26,
      "z": -3,
      "name": "Rock_Ice_Permafrost",
      "rotation": 3
    },
    {
      "x": 0,
      "y": -25,
      "z": -3,
      "name": "Rock_Ice_Permafrost",
      "rotation": 3
    },
    {
      "x": 0,
      "y": -24,
      "z": -3,
      "name": "Rock_Ice_Permafrost",
      "rotation": 3
    },
    {
      "x": 0,
      "y": -23,
      "z": -3,
      "name": "Rock_Ice_Permafrost",
      "rotation": 3
    },
    {
      "x": 0,
      "y": -22,
      "z": -3,
      "name": "Rock_Ice",
      "rotation": 3
    },
    {
      "x": 0,
      "y": -21,
      "z": -3,
      "name": "Rock_Ice",
      "rotation": 3
    },
    {
      "x": 0,
      "y": -20,
      "z": -3,
      "name": "Soil_Snow",
      "rotation": 3
    },
    {
      "x": 0,
      "y": -19,
      "z": -3,
      "name": "Soil_Snow",
      "rotation": 3
    },
    {
      "x": 0,
      "y": -30,
      "z": -2,
      "name": "Rock_Ice_Permafrost",
      "rotation": 3
    },
    {
      "x": 0,
      "y": -29,
      "z": -2,
      "name": "Rock_Ice_Permafrost",
      "rotation": 3
    },
    {
      "x": 0,
      "y": -28,
      "z": -2,
      "name": "Rock_Ice_Permafrost",
      "rotation": 3
    },
    {
      "x": 0,
      "y": -27,
      "z": -2,
      "name": "Rock_Ice_Permafrost",
      "rotation": 3
    },
    {
      "x": 0,
      "y": -26,
      "z": -2,
      "name": "Rock_Ice_Permafrost",
      "rotation": 3
    },
    {
      "x": 0,
      "y": -25,
      "z": -2,
      "name": "Rock_Ice_Permafrost",
      "rotation": 3
    },
    {
      "x": 0,
      "y": -24,
      "z": -2,
      "name": "Rock_Ice_Permafrost",
      "rotation": 3
    },
    {
      "x": 0,
      "y": -23,
      "z": -2,
      "name": "Rock_Ice",
      "rotation": 3
    },
    {
      "x": 0,
      "y": -22,
      "z": -2,
      "name": "Rock_Ice",
      "rotation": 3
    },
    {
      "x": 0,
      "y": -21,
      "z": -2,
      "name": "Rock_Ice",
      "rotation": 3
    },
    {
      "x": 0,
      "y": -20,
      "z": -2,
      "name": "Rock_Ice",
      "rotation": 3
    },
    {
      "x": 0,
      "y": -19,
      "z": -2,
      "name": "Soil_Snow",
      "rotation": 3
    },
    {
      "x": 0,
      "y": -32,
      "z": -1,
      "name": "Rock_Ice_Permafrost",
      "rotation": 3
    },
    {
      "x": 0,
      "y": -31,
      "z": -1,
      "name": "Rock_Ice_Permafrost",
      "rotation": 3
    },
    {
      "x": 0,
      "y": -30,
      "z": -1,
      "name": "Rock_Ice_Permafrost",
      "rotation": 3
    },
    {
      "x": 0,
      "y": -29,
      "z": -1,
      "name": "Rock_Ice_Permafrost",
      "rotation": 3
    },
    {
      "x": 0,
      "y": -28,
      "z": -1,
      "name": "Rock_Ice_Permafrost",
      "rotation": 3
    },
    {
      "x": 0,
      "y": -27,
      "z": -1,
      "name": "Rock_Ice_Permafrost",
      "rotation": 3
    },
    {
      "x": 0,
      "y": -26,
      "z": -1,
      "name": "Rock_Ice_Permafrost",
      "rotation": 3
    },
    {
      "x": 0,
      "y": -25,
      "z": -1,
      "name": "Rock_Ice_Permafrost",
      "rotation": 3
    },
    {
      "x": 0,
      "y": -24,
      "z": -1,
      "name": "Rock_Ice_Permafrost",
      "rotation": 3
    },
    {
      "x": 0,
      "y": -23,
      "z": -1,
      "name": "Rock_Ice",
      "rotation": 3
    },
    {
      "x": 0,
      "y": -22,
      "z": -1,
      "name": "Rock_Ice",
      "rotation": 3
    },
    {
      "x": 0,
      "y": -21,
      "z": -1,
      "name": "Rock_Ice",
      "rotation": 3
    },
    {
      "x": 0,
      "y": -20,
      "z": -1,
      "name": "Soil_Snow",
      "rotation": 3
    },
    {
      "x": 0,
      "y": -14,
      "z": -1,
      "name": "Rock_Ice",
      "rotation": 3
    },
    {
      "x": 0,
      "y": -13,
      "z": -1,
      "name": "Soil_Snow",
      "rotation": 3
    },
    {
      "x": 0,
      "y": -12,
      "z": -1,
      "name": "Soil_Snow",
      "rotation": 3
    },
    {
      "x": 0,
      "y": -32,
      "z": 0,
      "name": "Rock_Ice_Permafrost",
      "rotation": 3
    },
    {
      "x": 0,
      "y": -31,
      "z": 0,
      "name": "Rock_Ice_Permafrost",
      "rotation": 3
    },
    {
      "x": 0,
      "y": -30,
      "z": 0,
      "name": "Rock_Ice_Permafrost",
      "rotation": 3
    },
    {
      "x": 0,
      "y": -29,
      "z": 0,
      "name": "Rock_Ice_Permafrost",
      "rotation": 3
    },
    {
      "x": 0,
      "y": -28,
      "z": 0,
      "name": "Rock_Ice_Permafrost",
      "rotation": 3
    },
    {
      "x": 0,
      "y": -27,
      "z": 0,
      "name": "Rock_Ice_Permafrost",
      "rotation": 3
    },
    {
      "x": 0,
      "y": -26,
      "z": 0,
      "name": "Rock_Ice_Permafrost",
      "rotation": 3
    },
    {
      "x": 0,
      "y": -25,
      "z": 0,
      "name": "Rock_Ice",
      "rotation": 3
    },
    {
      "x": 0,
      "y": -24,
      "z": 0,
      "name": "Rock_Ice",
      "rotation": 3
    },
    {
      "x": 0,
      "y": -23,
      "z": 0,
      "name": "Rock_Ice",
      "rotation": 3
    },
    {
      "x": 0,
      "y": -22,
      "z": 0,
      "name": "Soil_Snow",
      "rotation": 3
    },
    {
      "x": 0,
      "y": -16,
      "z": 0,
      "name": "Rock_Ice_Permafrost",
      "rotation": 3
    },
    {
      "x": 0,
      "y": -15,
      "z": 0,
      "name": "Rock_Ice_Permafrost",
      "rotation": 3
    },
    {
      "x": 0,
      "y": -14,
      "z": 0,
      "name": "Rock_Ice",
      "rotation": 3
    },
    {
      "x": 0,
      "y": -13,
      "z": 0,
      "name": "Rock_Ice",
      "rotation": 3
    },
    {
      "x": 0,
      "y": -12,
      "z": 0,
      "name": "Soil_Snow",
      "rotation": 3
    },
    {
      "x": 0,
      "y": -11,
      "z": 0,
      "name": "Soil_Snow",
      "rotation": 3
    },
    {
      "x": 0,
      "y": -30,
      "z": 1,
      "name": "Rock_Ice_Permafrost",
      "rotation": 3
    },
    {
      "x": 0,
      "y": -29,
      "z": 1,
      "name": "Rock_Ice_Permafrost",
      "rotation": 3
    },
    {
      "x": 0,
      "y": -28,
      "z": 1,
      "name": "Rock_Ice_Permafrost",
      "rotation": 3
    },
    {
      "x": 0,
      "y": -27,
      "z": 1,
      "name": "Rock_Ice_Permafrost",
      "rotation": 3
    },
    {
      "x": 0,
      "y": -26,
      "z": 1,
      "name": "Rock_Ice",
      "rotation": 3
    },
    {
      "x": 0,
      "y": -25,
      "z": 1,
      "name": "Rock_Ice",
      "rotation": 3
    },
    {
      "x": 0,
      "y": -24,
      "z": 1,
      "name": "Rock_Ice",
      "rotation": 3
    },
    {
      "x": 0,
      "y": -23,
      "z": 1,
      "name": "Rock_Ice_Permafrost",
      "rotation": 3
    },
    {
      "x": 0,
      "y": -22,
      "z": 1,
      "name": "Soil_Snow",
      "rotation": 3
    },
    {
      "x": 0,
      "y": -15,
      "z": 1,
      "name": "Rock_Ice_Permafrost",
      "rotation": 3
    },
    {
      "x": 0,
      "y": -14,
      "z": 1,
      "name": "Rock_Ice_Permafrost",
      "rotation": 3
    },
    {
      "x": 0,
      "y": -13,
      "z": 1,
      "name": "Rock_Ice",
      "rotation": 3
    },
    {
      "x": 0,
      "y": -12,
      "z": 1,
      "name": "Soil_Snow",
      "rotation": 3
    },
    {
      "x": 0,
      "y": -29,
      "z": 2,
      "name": "Rock_Ice_Permafrost",
      "rotation": 3
    },
    {
      "x": 0,
      "y": -28,
      "z": 2,
      "name": "Rock_Ice_Permafrost",
      "rotation": 3
    },
    {
      "x": 0,
      "y": -27,
      "z": 2,
      "name": "Rock_Ice_Permafrost",
      "rotation": 3
    },
    {
      "x": 0,
      "y": -26,
      "z": 2,
      "name": "Rock_Ice",
      "rotation": 3
    },
    {
      "x": 0,
      "y": -25,
      "z": 2,
      "name": "Rock_Ice",
      "rotation": 3
    },
    {
      "x": 0,
      "y": -24,
      "z": 2,
      "name": "Rock_Ice",
      "rotation": 3
    },
    {
      "x": 0,
      "y": -23,
      "z": 2,
      "name": "Rock_Ice_Permafrost",
      "rotation": 3
    },
    {
      "x": 0,
      "y": -22,
      "z": 2,
      "name": "Soil_Snow",
      "rotation": 3
    },
    {
      "x": 0,
      "y": -27,
      "z": 3,
      "name": "Rock_Ice",
      "rotation": 3
    },
    {
      "x": 0,
      "y": -26,
      "z": 3,
      "name": "Rock_Ice",
      "rotation": 3
    },
    {
      "x": 0,
      "y": -25,
      "z": 3,
      "name": "Rock_Ice",
      "rotation": 3
    },
    {
      "x": 0,
      "y": -24,
      "z": 3,
      "name": "Rock_Ice",
      "rotation": 3
    },
    {
      "x": 0,
      "y": -23,
      "z": 3,
      "name": "Soil_Snow",
      "rotation": 3
    },
    {
      "x": 0,
      "y": -24,
      "z": 4,
      "name": "Rock_Ice",
      "rotation": 3
    },
    {
      "x": 0,
      "y": -23,
      "z": 4,
      "name": "Soil_Snow",
      "rotation": 3
    },
    {
      "x": 1,
      "y": -22,
      "z": -5,
      "name": "Rock_Ice",
      "rotation": 3
    },
    {
      "x": 1,
      "y": -21,
      "z": -5,
      "name": "Soil_Snow",
      "rotation": 3
    },
    {
      "x": 1,
      "y": -20,
      "z": -5,
      "name": "Soil_Snow",
      "rotation": 3
    },
    {
      "x": 1,
      "y": -26,
      "z": -4,
      "name": "Rock_Ice_Permafrost",
      "rotation": 3
    },
    {
      "x": 1,
      "y": -25,
      "z": -4,
      "name": "Rock_Ice_Permafrost",
      "rotation": 3
    },
    {
      "x": 1,
      "y": -24,
      "z": -4,
      "name": "Rock_Ice_Permafrost",
      "rotation": 3
    },
    {
      "x": 1,
      "y": -23,
      "z": -4,
      "name": "Rock_Ice",
      "rotation": 3
    },
    {
      "x": 1,
      "y": -22,
      "z": -4,
      "name": "Rock_Ice",
      "rotation": 3
    },
    {
      "x": 1,
      "y": -21,
      "z": -4,
      "name": "Rock_Ice",
      "rotation": 3
    },
    {
      "x": 1,
      "y": -20,
      "z": -4,
      "name": "Rock_Ice",
      "rotation": 3
    },
    {
      "x": 1,
      "y": -19,
      "z": -4,
      "name": "Soil_Snow",
      "rotation": 3
    },
    {
      "x": 1,
      "y": -31,
      "z": -3,
      "name": "Rock_Ice",
      "rotation": 3
    },
    {
      "x": 1,
      "y": -30,
      "z": -3,
      "name": "Rock_Ice",
      "rotation": 3
    },
    {
      "x": 1,
      "y": -29,
      "z": -3,
      "name": "Rock_Ice_Permafrost",
      "rotation": 3
    },
    {
      "x": 1,
      "y": -28,
      "z": -3,
      "name": "Rock_Ice_Permafrost",
      "rotation": 3
    },
    {
      "x": 1,
      "y": -27,
      "z": -3,
      "name": "Rock_Ice_Permafrost",
      "rotation": 3
    },
    {
      "x": 1,
      "y": -26,
      "z": -3,
      "name": "Rock_Ice_Permafrost",
      "rotation": 3
    },
    {
      "x": 1,
      "y": -25,
      "z": -3,
      "name": "Rock_Ice_Permafrost",
      "rotation": 3
    },
    {
      "x": 1,
      "y": -24,
      "z": -3,
      "name": "Rock_Ice_Permafrost",
      "rotation": 3
    },
    {
      "x": 1,
      "y": -23,
      "z": -3,
      "name": "Rock_Ice",
      "rotation": 3
    },
    {
      "x": 1,
      "y": -22,
      "z": -3,
      "name": "Rock_Ice",
      "rotation": 3
    },
    {
      "x": 1,
      "y": -21,
      "z": -3,
      "name": "Rock_Ice",
      "rotation": 3
    },
    {
      "x": 1,
      "y": -20,
      "z": -3,
      "name": "Rock_Ice",
      "rotation": 3
    },
    {
      "x": 1,
      "y": -19,
      "z": -3,
      "name": "Soil_Snow",
      "rotation": 3
    },
    {
      "x": 1,
      "y": -36,
      "z": -2,
      "name": "Rock_Ice",
      "rotation": 3
    },
    {
      "x": 1,
      "y": -35,
      "z": -2,
      "name": "Rock_Ice",
      "rotation": 3
    },
    {
      "x": 1,
      "y": -34,
      "z": -2,
      "name": "Rock_Ice",
      "rotation": 3
    },
    {
      "x": 1,
      "y": -33,
      "z": -2,
      "name": "Rock_Ice",
      "rotation": 3
    },
    {
      "x": 1,
      "y": -32,
      "z": -2,
      "name": "Rock_Ice",
      "rotation": 3
    },
    {
      "x": 1,
      "y": -31,
      "z": -2,
      "name": "Rock_Ice",
      "rotation": 3
    },
    {
      "x": 1,
      "y": -30,
      "z": -2,
      "name": "Rock_Ice_Permafrost",
      "rotation": 3
    },
    {
      "x": 1,
      "y": -29,
      "z": -2,
      "name": "Rock_Ice_Permafrost",
      "rotation": 3
    },
    {
      "x": 1,
      "y": -28,
      "z": -2,
      "name": "Rock_Ice_Permafrost",
      "rotation": 3
    },
    {
      "x": 1,
      "y": -27,
      "z": -2,
      "name": "Rock_Ice_Permafrost",
      "rotation": 3
    },
    {
      "x": 1,
      "y": -26,
      "z": -2,
      "name": "Rock_Ice_Permafrost",
      "rotation": 3
    },
    {
      "x": 1,
      "y": -25,
      "z": -2,
      "name": "Rock_Ice_Permafrost",
      "rotation": 3
    },
    {
      "x": 1,
      "y": -24,
      "z": -2,
      "name": "Rock_Ice_Permafrost",
      "rotation": 3
    },
    {
      "x": 1,
      "y": -23,
      "z": -2,
      "name": "Rock_Ice_Permafrost",
      "rotation": 3
    },
    {
      "x": 1,
      "y": -22,
      "z": -2,
      "name": "Rock_Ice_Permafrost",
      "rotation": 3
    },
    {
      "x": 1,
      "y": -21,
      "z": -2,
      "name": "Rock_Ice_Permafrost",
      "rotation": 3
    },
    {
      "x": 1,
      "y": -20,
      "z": -2,
      "name": "Rock_Ice_Permafrost",
      "rotation": 3
    },
    {
      "x": 1,
      "y": -19,
      "z": -2,
      "name": "Soil_Snow",
      "rotation": 3
    },
    {
      "x": 1,
      "y": -14,
      "z": -2,
      "name": "Rock_Ice",
      "rotation": 3
    },
    {
      "x": 1,
      "y": -13,
      "z": -2,
      "name": "Soil_Snow",
      "rotation": 3
    },
    {
      "x": 1,
      "y": -39,
      "z": -1,
      "name": "Rock_Ice_Permafrost",
      "rotation": 3
    },
    {
      "x": 1,
      "y": -38,
      "z": -1,
      "name": "Rock_Ice_Permafrost",
      "rotation": 3
    },
    {
      "x": 1,
      "y": -37,
      "z": -1,
      "name": "Rock_Ice_Permafrost",
      "rotation": 3
    },
    {
      "x": 1,
      "y": -36,
      "z": -1,
      "name": "Rock_Ice_Permafrost",
      "rotation": 3
    },
    {
      "x": 1,
      "y": -35,
      "z": -1,
      "name": "Rock_Ice_Permafrost",
      "rotation": 3
    },
    {
      "x": 1,
      "y": -34,
      "z": -1,
      "name": "Rock_Ice_Permafrost",
      "rotation": 3
    },
    {
      "x": 1,
      "y": -33,
      "z": -1,
      "name": "Rock_Ice",
      "rotation": 3
    },
    {
      "x": 1,
      "y": -32,
      "z": -1,
      "name": "Rock_Ice_Permafrost",
      "rotation": 3
    },
    {
      "x": 1,
      "y": -31,
      "z": -1,
      "name": "Rock_Ice_Permafrost",
      "rotation": 3
    },
    {
      "x": 1,
      "y": -30,
      "z": -1,
      "name": "Rock_Ice_Permafrost",
      "rotation": 3
    },
    {
      "x": 1,
      "y": -29,
      "z": -1,
      "name": "Rock_Ice_Permafrost",
      "rotation": 3
    },
    {
      "x": 1,
      "y": -28,
      "z": -1,
      "name": "Rock_Ice_Permafrost",
      "rotation": 3
    },
    {
      "x": 1,
      "y": -27,
      "z": -1,
      "name": "Rock_Ice_Permafrost",
      "rotation": 3
    },
    {
      "x": 1,
      "y": -26,
      "z": -1,
      "name": "Rock_Ice_Permafrost",
      "rotation": 3
    },
    {
      "x": 1,
      "y": -25,
      "z": -1,
      "name": "Rock_Ice_Permafrost",
      "rotation": 3
    },
    {
      "x": 1,
      "y": -24,
      "z": -1,
      "name": "Rock_Ice_Permafrost",
      "rotation": 3
    },
    {
      "x": 1,
      "y": -23,
      "z": -1,
      "name": "Rock_Ice_Permafrost",
      "rotation": 3
    },
    {
      "x": 1,
      "y": -22,
      "z": -1,
      "name": "Rock_Ice_Permafrost",
      "rotation": 3
    },
    {
      "x": 1,
      "y": -21,
      "z": -1,
      "name": "Rock_Ice_Permafrost",
      "rotation": 3
    },
    {
      "x": 1,
      "y": -20,
      "z": -1,
      "name": "Rock_Ice_Permafrost",
      "rotation": 3
    },
    {
      "x": 1,
      "y": -19,
      "z": -1,
      "name": "Soil_Snow",
      "rotation": 3
    },
    {
      "x": 1,
      "y": -16,
      "z": -1,
      "name": "Rock_Ice_Permafrost",
      "rotation": 3
    },
    {
      "x": 1,
      "y": -15,
      "z": -1,
      "name": "Rock_Ice",
      "rotation": 3
    },
    {
      "x": 1,
      "y": -14,
      "z": -1,
      "name": "Rock_Ice",
      "rotation": 3
    },
    {
      "x": 1,
      "y": -13,
      "z": -1,
      "name": "Rock_Ice",
      "rotation": 3
    },
    {
      "x": 1,
      "y": -12,
      "z": -1,
      "name": "Soil_Snow",
      "rotation": 3
    },
    {
      "x": 1,
      "y": -11,
      "z": -1,
      "name": "Soil_Snow",
      "rotation": 3
    },
    {
      "x": 1,
      "y": -35,
      "z": 0,
      "name": "Rock_Ice_Permafrost",
      "rotation": 3
    },
    {
      "x": 1,
      "y": -34,
      "z": 0,
      "name": "Rock_Ice_Permafrost",
      "rotation": 3
    },
    {
      "x": 1,
      "y": -33,
      "z": 0,
      "name": "Rock_Ice_Permafrost",
      "rotation": 3
    },
    {
      "x": 1,
      "y": -32,
      "z": 0,
      "name": "Rock_Ice_Permafrost",
      "rotation": 3
    },
    {
      "x": 1,
      "y": -31,
      "z": 0,
      "name": "Rock_Ice_Permafrost",
      "rotation": 3
    },
    {
      "x": 1,
      "y": -30,
      "z": 0,
      "name": "Rock_Ice",
      "rotation": 3
    },
    {
      "x": 1,
      "y": -29,
      "z": 0,
      "name": "Rock_Ice",
      "rotation": 3
    },
    {
      "x": 1,
      "y": -28,
      "z": 0,
      "name": "Rock_Ice_Permafrost",
      "rotation": 3
    },
    {
      "x": 1,
      "y": -27,
      "z": 0,
      "name": "Rock_Ice_Permafrost",
      "rotation": 3
    },
    {
      "x": 1,
      "y": -26,
      "z": 0,
      "name": "Rock_Ice_Permafrost",
      "rotation": 3
    },
    {
      "x": 1,
      "y": -25,
      "z": 0,
      "name": "Rock_Ice_Permafrost",
      "rotation": 3
    },
    {
      "x": 1,
      "y": -24,
      "z": 0,
      "name": "Rock_Ice_Permafrost",
      "rotation": 3
    },
    {
      "x": 1,
      "y": -23,
      "z": 0,
      "name": "Rock_Ice_Permafrost",
      "rotation": 3
    },
    {
      "x": 1,
      "y": -22,
      "z": 0,
      "name": "Rock_Ice_Permafrost",
      "rotation": 3
    },
    {
      "x": 1,
      "y": -21,
      "z": 0,
      "name": "Soil_Snow",
      "rotation": 3
    },
    {
      "x": 1,
      "y": -19,
      "z": 0,
      "name": "Rock_Ice_Permafrost",
      "rotation": 3
    },
    {
      "x": 1,
      "y": -18,
      "z": 0,
      "name": "Rock_Ice_Permafrost",
      "rotation": 3
    },
    {
      "x": 1,
      "y": -17,
      "z": 0,
      "name": "Rock_Ice_Permafrost",
      "rotation": 3
    },
    {
      "x": 1,
      "y": -16,
      "z": 0,
      "name": "Rock_Ice_Permafrost",
      "rotation": 3
    },
    {
      "x": 1,
      "y": -15,
      "z": 0,
      "name": "Rock_Ice_Permafrost",
      "rotation": 3
    },
    {
      "x": 1,
      "y": -14,
      "z": 0,
      "name": "Rock_Ice",
      "rotation": 3
    },
    {
      "x": 1,
      "y": -13,
      "z": 0,
      "name": "Rock_Ice",
      "rotation": 3
    },
    {
      "x": 1,
      "y": -12,
      "z": 0,
      "name": "Rock_Ice",
      "rotation": 3
    },
    {
      "x": 1,
      "y": -11,
      "z": 0,
      "name": "Soil_Snow",
      "rotation": 3
    },
    {
      "x": 1,
      "y": -31,
      "z": 1,
      "name": "Rock_Ice_Permafrost",
      "rotation": 3
    },
    {
      "x": 1,
      "y": -30,
      "z": 1,
      "name": "Rock_Ice_Permafrost",
      "rotation": 3
    },
    {
      "x": 1,
      "y": -29,
      "z": 1,
      "name": "Rock_Ice",
      "rotation": 3
    },
    {
      "x": 1,
      "y": -28,
      "z": 1,
      "name": "Rock_Ice_Permafrost",
      "rotation": 3
    },
    {
      "x": 1,
      "y": -27,
      "z": 1,
      "name": "Rock_Ice_Permafrost",
      "rotation": 3
    },
    {
      "x": 1,
      "y": -26,
      "z": 1,
      "name": "Rock_Ice_Permafrost",
      "rotation": 3
    },
    {
      "x": 1,
      "y": -25,
      "z": 1,
      "name": "Rock_Ice_Permafrost",
      "rotation": 3
    },
    {
      "x": 1,
      "y": -24,
      "z": 1,
      "name": "Rock_Ice_Permafrost",
      "rotation": 3
    },
    {
      "x": 1,
      "y": -23,
      "z": 1,
      "name": "Rock_Ice_Permafrost",
      "rotation": 3
    },
    {
      "x": 1,
      "y": -22,
      "z": 1,
      "name": "Soil_Snow",
      "rotation": 3
    },
    {
      "x": 1,
      "y": -18,
      "z": 1,
      "name": "Rock_Ice_Permafrost",
      "rotation": 3
    },
    {
      "x": 1,
      "y": -17,
      "z": 1,
      "name": "Rock_Ice_Permafrost",
      "rotation": 3
    },
    {
      "x": 1,
      "y": -16,
      "z": 1,
      "name": "Rock_Ice_Permafrost",
      "rotation": 3
    },
    {
      "x": 1,
      "y": -15,
      "z": 1,
      "name": "Rock_Ice",
      "rotation": 3
    },
    {
      "x": 1,
      "y": -14,
      "z": 1,
      "name": "Rock_Ice",
      "rotation": 3
    },
    {
      "x": 1,
      "y": -13,
      "z": 1,
      "name": "Rock_Ice",
      "rotation": 3
    },
    {
      "x": 1,
      "y": -12,
      "z": 1,
      "name": "Rock_Ice",
      "rotation": 3
    },
    {
      "x": 1,
      "y": -11,
      "z": 1,
      "name": "Soil_Snow",
      "rotation": 3
    },
    {
      "x": 1,
      "y": -28,
      "z": 2,
      "name": "Rock_Ice_Permafrost",
      "rotation": 3
    },
    {
      "x": 1,
      "y": -27,
      "z": 2,
      "name": "Rock_Ice_Permafrost",
      "rotation": 3
    },
    {
      "x": 1,
      "y": -26,
      "z": 2,
      "name": "Rock_Ice_Permafrost",
      "rotation": 3
    },
    {
      "x": 1,
      "y": -25,
      "z": 2,
      "name": "Rock_Ice_Permafrost",
      "rotation": 3
    },
    {
      "x": 1,
      "y": -24,
      "z": 2,
      "name": "Rock_Ice_Permafrost",
      "rotation": 3
    },
    {
      "x": 1,
      "y": -23,
      "z": 2,
      "name": "Rock_Ice_Permafrost",
      "rotation": 3
    },
    {
      "x": 1,
      "y": -22,
      "z": 2,
      "name": "Soil_Snow",
      "rotation": 3
    },
    {
      "x": 1,
      "y": -16,
      "z": 2,
      "name": "Rock_Ice_Permafrost",
      "rotation": 3
    },
    {
      "x": 1,
      "y": -15,
      "z": 2,
      "name": "Rock_Ice_Permafrost",
      "rotation": 3
    },
    {
      "x": 1,
      "y": -14,
      "z": 2,
      "name": "Rock_Ice_Permafrost",
      "rotation": 3
    },
    {
      "x": 1,
      "y": -13,
      "z": 2,
      "name": "Rock_Ice",
      "rotation": 3
    },
    {
      "x": 1,
      "y": -12,
      "z": 2,
      "name": "Soil_Snow",
      "rotation": 3
    },
    {
      "x": 1,
      "y": -27,
      "z": 3,
      "name": "Rock_Ice_Permafrost",
      "rotation": 3
    },
    {
      "x": 1,
      "y": -26,
      "z": 3,
      "name": "Rock_Ice",
      "rotation": 3
    },
    {
      "x": 1,
      "y": -25,
      "z": 3,
      "name": "Rock_Ice",
      "rotation": 3
    },
    {
      "x": 1,
      "y": -24,
      "z": 3,
      "name": "Rock_Ice",
      "rotation": 3
    },
    {
      "x": 1,
      "y": -23,
      "z": 3,
      "name": "Rock_Ice",
      "rotation": 3
    },
    {
      "x": 1,
      "y": -22,
      "z": 3,
      "name": "Soil_Snow",
      "rotation": 3
    },
    {
      "x": 1,
      "y": -25,
      "z": 4,
      "name": "Rock_Ice",
      "rotation": 3
    },
    {
      "x": 1,
      "y": -24,
      "z": 4,
      "name": "Rock_Ice",
      "rotation": 3
    },
    {
      "x": 1,
      "y": -23,
      "z": 4,
      "name": "Rock_Ice",
      "rotation": 3
    },
    {
      "x": 1,
      "y": -22,
      "z": 4,
      "name": "Soil_Snow",
      "rotation": 3
    },
    {
      "x": 1,
      "y": -24,
      "z": 5,
      "name": "Rock_Ice",
      "rotation": 3
    },
    {
      "x": 1,
      "y": -23,
      "z": 5,
      "name": "Soil_Snow",
      "rotation": 3
    },
    {
      "x": 2,
      "y": -20,
      "z": -6,
      "name": "Soil_Snow",
      "rotation": 3
    },
    {
      "x": 2,
      "y": -25,
      "z": -5,
      "name": "Rock_Ice_Permafrost",
      "rotation": 3
    },
    {
      "x": 2,
      "y": -24,
      "z": -5,
      "name": "Rock_Ice",
      "rotation": 3
    },
    {
      "x": 2,
      "y": -23,
      "z": -5,
      "name": "Rock_Ice",
      "rotation": 3
    },
    {
      "x": 2,
      "y": -22,
      "z": -5,
      "name": "Rock_Ice",
      "rotation": 3
    },
    {
      "x": 2,
      "y": -21,
      "z": -5,
      "name": "Rock_Ice",
      "rotation": 3
    },
    {
      "x": 2,
      "y": -20,
      "z": -5,
      "name": "Rock_Ice",
      "rotation": 3
    },
    {
      "x": 2,
      "y": -19,
      "z": -5,
      "name": "Soil_Snow",
      "rotation": 3
    },
    {
      "x": 2,
      "y": -28,
      "z": -4,
      "name": "Rock_Ice_Permafrost",
      "rotation": 3
    },
    {
      "x": 2,
      "y": -27,
      "z": -4,
      "name": "Rock_Ice_Permafrost",
      "rotation": 3
    },
    {
      "x": 2,
      "y": -26,
      "z": -4,
      "name": "Rock_Ice_Permafrost",
      "rotation": 3
    },
    {
      "x": 2,
      "y": -25,
      "z": -4,
      "name": "Rock_Ice_Permafrost",
      "rotation": 3
    },
    {
      "x": 2,
      "y": -24,
      "z": -4,
      "name": "Rock_Ice_Permafrost",
      "rotation": 3
    },
    {
      "x": 2,
      "y": -23,
      "z": -4,
      "name": "Rock_Ice",
      "rotation": 3
    },
    {
      "x": 2,
      "y": -22,
      "z": -4,
      "name": "Rock_Ice",
      "rotation": 3
    },
    {
      "x": 2,
      "y": -21,
      "z": -4,
      "name": "Rock_Ice",
      "rotation": 3
    },
    {
      "x": 2,
      "y": -20,
      "z": -4,
      "name": "Rock_Ice",
      "rotation": 3
    },
    {
      "x": 2,
      "y": -19,
      "z": -4,
      "name": "Soil_Snow",
      "rotation": 3
    },
    {
      "x": 2,
      "y": -36,
      "z": -3,
      "name": "Rock_Ice",
      "rotation": 3
    },
    {
      "x": 2,
      "y": -35,
      "z": -3,
      "name": "Rock_Ice",
      "rotation": 3
    },
    {
      "x": 2,
      "y": -34,
      "z": -3,
      "name": "Rock_Ice",
      "rotation": 3
    },
    {
      "x": 2,
      "y": -33,
      "z": -3,
      "name": "Rock_Ice",
      "rotation": 3
    },
    {
      "x": 2,
      "y": -32,
      "z": -3,
      "name": "Rock_Ice",
      "rotation": 3
    },
    {
      "x": 2,
      "y": -31,
      "z": -3,
      "name": "Rock_Ice",
      "rotation": 3
    },
    {
      "x": 2,
      "y": -30,
      "z": -3,
      "name": "Rock_Ice",
      "rotation": 3
    },
    {
      "x": 2,
      "y": -29,
      "z": -3,
      "name": "Rock_Ice_Permafrost",
      "rotation": 3
    },
    {
      "x": 2,
      "y": -28,
      "z": -3,
      "name": "Rock_Ice_Permafrost",
      "rotation": 3
    },
    {
      "x": 2,
      "y": -27,
      "z": -3,
      "name": "Rock_Ice_Permafrost",
      "rotation": 3
    },
    {
      "x": 2,
      "y": -26,
      "z": -3,
      "name": "Rock_Ice_Permafrost",
      "rotation": 3
    },
    {
      "x": 2,
      "y": -25,
      "z": -3,
      "name": "Rock_Ice_Permafrost",
      "rotation": 3
    },
    {
      "x": 2,
      "y": -24,
      "z": -3,
      "name": "Rock_Ice_Permafrost",
      "rotation": 3
    },
    {
      "x": 2,
      "y": -23,
      "z": -3,
      "name": "Rock_Ice_Permafrost",
      "rotation": 3
    },
    {
      "x": 2,
      "y": -22,
      "z": -3,
      "name": "Rock_Ice_Permafrost",
      "rotation": 3
    },
    {
      "x": 2,
      "y": -21,
      "z": -3,
      "name": "Rock_Ice_Permafrost",
      "rotation": 3
    },
    {
      "x": 2,
      "y": -20,
      "z": -3,
      "name": "Rock_Ice",
      "rotation": 3
    },
    {
      "x": 2,
      "y": -19,
      "z": -3,
      "name": "Soil_Snow",
      "rotation": 3
    },
    {
      "x": 2,
      "y": -16,
      "z": -3,
      "name": "Soil_Snow",
      "rotation": 3
    },
    {
      "x": 2,
      "y": -42,
      "z": -2,
      "name": "Rock_Ice_Permafrost",
      "rotation": 3
    },
    {
      "x": 2,
      "y": -41,
      "z": -2,
      "name": "Rock_Ice_Permafrost",
      "rotation": 3
    },
    {
      "x": 2,
      "y": -40,
      "z": -2,
      "name": "Rock_Ice_Permafrost",
      "rotation": 3
    },
    {
      "x": 2,
      "y": -39,
      "z": -2,
      "name": "Rock_Ice",
      "rotation": 3
    },
    {
      "x": 2,
      "y": -38,
      "z": -2,
      "name": "Rock_Ice",
      "rotation": 3
    },
    {
      "x": 2,
      "y": -37,
      "z": -2,
      "name": "Rock_Ice",
      "rotation": 3
    },
    {
      "x": 2,
      "y": -36,
      "z": -2,
      "name": "Rock_Ice",
      "rotation": 3
    },
    {
      "x": 2,
      "y": -35,
      "z": -2,
      "name": "Rock_Ice",
      "rotation": 3
    },
    {
      "x": 2,
      "y": -34,
      "z": -2,
      "name": "Rock_Ice",
      "rotation": 3
    },
    {
      "x": 2,
      "y": -33,
      "z": -2,
      "name": "Rock_Ice",
      "rotation": 3
    },
    {
      "x": 2,
      "y": -32,
      "z": -2,
      "name": "Rock_Ice",
      "rotation": 3
    },
    {
      "x": 2,
      "y": -31,
      "z": -2,
      "name": "Rock_Ice",
      "rotation": 3
    },
    {
      "x": 2,
      "y": -30,
      "z": -2,
      "name": "Rock_Ice_Permafrost",
      "rotation": 3
    },
    {
      "x": 2,
      "y": -29,
      "z": -2,
      "name": "Rock_Ice_Permafrost",
      "rotation": 3
    },
    {
      "x": 2,
      "y": -28,
      "z": -2,
      "name": "Rock_Ice_Permafrost",
      "rotation": 3
    },
    {
      "x": 2,
      "y": -27,
      "z": -2,
      "name": "Rock_Ice_Permafrost",
      "rotation": 3
    },
    {
      "x": 2,
      "y": -26,
      "z": -2,
      "name": "Rock_Ice_Permafrost",
      "rotation": 3
    },
    {
      "x": 2,
      "y": -25,
      "z": -2,
      "name": "Rock_Ice_Permafrost",
      "rotation": 3
    },
    {
      "x": 2,
      "y": -24,
      "z": -2,
      "name": "Rock_Ice_Permafrost",
      "rotation": 3
    },
    {
      "x": 2,
      "y": -23,
      "z": -2,
      "name": "Rock_Ice_Permafrost",
      "rotation": 3
    },
    {
      "x": 2,
      "y": -22,
      "z": -2,
      "name": "Rock_Ice_Permafrost",
      "rotation": 3
    },
    {
      "x": 2,
      "y": -21,
      "z": -2,
      "name": "Rock_Ice_Permafrost",
      "rotation": 3
    },
    {
      "x": 2,
      "y": -20,
      "z": -2,
      "name": "Rock_Ice_Permafrost",
      "rotation": 3
    },
    {
      "x": 2,
      "y": -19,
      "z": -2,
      "name": "Soil_Snow",
      "rotation": 3
    },
    {
      "x": 2,
      "y": -15,
      "z": -2,
      "name": "Rock_Ice",
      "rotation": 3
    },
    {
      "x": 2,
      "y": -14,
      "z": -2,
      "name": "Rock_Ice",
      "rotation": 3
    },
    {
      "x": 2,
      "y": -13,
      "z": -2,
      "name": "Rock_Ice",
      "rotation": 3
    },
    {
      "x": 2,
      "y": -12,
      "z": -2,
      "name": "Soil_Snow",
      "rotation": 3
    },
    {
      "x": 2,
      "y": -43,
      "z": -1,
      "name": "Rock_Ice_Permafrost",
      "rotation": 3
    },
    {
      "x": 2,
      "y": -42,
      "z": -1,
      "name": "Rock_Ice_Permafrost",
      "rotation": 3
    },
    {
      "x": 2,
      "y": -41,
      "z": -1,
      "name": "Rock_Ice",
      "rotation": 3
    },
    {
      "x": 2,
      "y": -40,
      "z": -1,
      "name": "Rock_Ice",
      "rotation": 3
    },
    {
      "x": 2,
      "y": -39,
      "z": -1,
      "name": "Rock_Ice",
      "rotation": 3
    },
    {
      "x": 2,
      "y": -38,
      "z": -1,
      "name": "Rock_Ice",
      "rotation": 3
    },
    {
      "x": 2,
      "y": -37,
      "z": -1,
      "name": "Rock_Ice",
      "rotation": 3
    },
    {
      "x": 2,
      "y": -36,
      "z": -1,
      "name": "Rock_Ice_Permafrost",
      "rotation": 3
    },
    {
      "x": 2,
      "y": -35,
      "z": -1,
      "name": "Rock_Ice_Permafrost",
      "rotation": 3
    },
    {
      "x": 2,
      "y": -34,
      "z": -1,
      "name": "Rock_Ice_Permafrost",
      "rotation": 3
    },
    {
      "x": 2,
      "y": -33,
      "z": -1,
      "name": "Rock_Ice_Permafrost",
      "rotation": 3
    },
    {
      "x": 2,
      "y": -32,
      "z": -1,
      "name": "Rock_Ice_Permafrost",
      "rotation": 3
    },
    {
      "x": 2,
      "y": -31,
      "z": -1,
      "name": "Rock_Ice_Permafrost",
      "rotation": 3
    },
    {
      "x": 2,
      "y": -30,
      "z": -1,
      "name": "Rock_Ice",
      "rotation": 3
    },
    {
      "x": 2,
      "y": -29,
      "z": -1,
      "name": "Rock_Ice",
      "rotation": 3
    },
    {
      "x": 2,
      "y": -28,
      "z": -1,
      "name": "Rock_Ice_Permafrost",
      "rotation": 3
    },
    {
      "x": 2,
      "y": -27,
      "z": -1,
      "name": "Rock_Ice_Permafrost",
      "rotation": 3
    },
    {
      "x": 2,
      "y": -26,
      "z": -1,
      "name": "Rock_Ice_Permafrost",
      "rotation": 3
    },
    {
      "x": 2,
      "y": -25,
      "z": -1,
      "name": "Rock_Ice_Permafrost",
      "rotation": 3
    },
    {
      "x": 2,
      "y": -24,
      "z": -1,
      "name": "Rock_Ice_Permafrost",
      "rotation": 3
    },
    {
      "x": 2,
      "y": -23,
      "z": -1,
      "name": "Rock_Ice_Permafrost",
      "rotation": 3
    },
    {
      "x": 2,
      "y": -22,
      "z": -1,
      "name": "Rock_Ice_Permafrost",
      "rotation": 3
    },
    {
      "x": 2,
      "y": -21,
      "z": -1,
      "name": "Rock_Ice_Permafrost",
      "rotation": 3
    },
    {
      "x": 2,
      "y": -20,
      "z": -1,
      "name": "Rock_Ice_Permafrost",
      "rotation": 3
    },
    {
      "x": 2,
      "y": -19,
      "z": -1,
      "name": "Rock_Ice_Permafrost",
      "rotation": 3
    },
    {
      "x": 2,
      "y": -18,
      "z": -1,
      "name": "Rock_Ice_Permafrost",
      "rotation": 3
    },
    {
      "x": 2,
      "y": -17,
      "z": -1,
      "name": "Rock_Ice_Permafrost",
      "rotation": 3
    },
    {
      "x": 2,
      "y": -16,
      "z": -1,
      "name": "Rock_Ice",
      "rotation": 3
    },
    {
      "x": 2,
      "y": -15,
      "z": -1,
      "name": "Rock_Ice",
      "rotation": 3
    },
    {
      "x": 2,
      "y": -14,
      "z": -1,
      "name": "Rock_Ice",
      "rotation": 3
    },
    {
      "x": 2,
      "y": -13,
      "z": -1,
      "name": "Rock_Ice",
      "rotation": 3
    },
    {
      "x": 2,
      "y": -12,
      "z": -1,
      "name": "Rock_Ice",
      "rotation": 3
    },
    {
      "x": 2,
      "y": -11,
      "z": -1,
      "name": "Soil_Snow",
      "rotation": 3
    },
    {
      "x": 2,
      "y": -44,
      "z": 0,
      "name": "Rock_Ice",
      "rotation": 3
    },
    {
      "x": 2,
      "y": -43,
      "z": 0,
      "name": "Rock_Ice",
      "rotation": 3
    },
    {
      "x": 2,
      "y": -42,
      "z": 0,
      "name": "Rock_Ice",
      "rotation": 3
    },
    {
      "x": 2,
      "y": -41,
      "z": 0,
      "name": "Rock_Ice",
      "rotation": 3
    },
    {
      "x": 2,
      "y": -40,
      "z": 0,
      "name": "Rock_Ice",
      "rotation": 3
    },
    {
      "x": 2,
      "y": -39,
      "z": 0,
      "name": "Rock_Ice",
      "rotation": 3
    },
    {
      "x": 2,
      "y": -38,
      "z": 0,
      "name": "Rock_Ice",
      "rotation": 3
    },
    {
      "x": 2,
      "y": -37,
      "z": 0,
      "name": "Rock_Ice_Permafrost",
      "rotation": 3
    },
    {
      "x": 2,
      "y": -36,
      "z": 0,
      "name": "Rock_Ice_Permafrost",
      "rotation": 3
    },
    {
      "x": 2,
      "y": -35,
      "z": 0,
      "name": "Rock_Ice_Permafrost",
      "rotation": 3
    },
    {
      "x": 2,
      "y": -34,
      "z": 0,
      "name": "Rock_Ice_Permafrost",
      "rotation": 3
    },
    {
      "x": 2,
      "y": -33,
      "z": 0,
      "name": "Rock_Ice_Permafrost",
      "rotation": 3
    },
    {
      "x": 2,
      "y": -32,
      "z": 0,
      "name": "Rock_Ice_Permafrost",
      "rotation": 3
    },
    {
      "x": 2,
      "y": -31,
      "z": 0,
      "name": "Rock_Ice",
      "rotation": 3
    },
    {
      "x": 2,
      "y": -30,
      "z": 0,
      "name": "Rock_Ice",
      "rotation": 3
    },
    {
      "x": 2,
      "y": -29,
      "z": 0,
      "name": "Rock_Ice",
      "rotation": 3
    },
    {
      "x": 2,
      "y": -28,
      "z": 0,
      "name": "Rock_Ice",
      "rotation": 3
    },
    {
      "x": 2,
      "y": -27,
      "z": 0,
      "name": "Rock_Ice",
      "rotation": 3
    },
    {
      "x": 2,
      "y": -26,
      "z": 0,
      "name": "Rock_Ice_Permafrost",
      "rotation": 3
    },
    {
      "x": 2,
      "y": -25,
      "z": 0,
      "name": "Rock_Ice_Permafrost",
      "rotation": 3
    },
    {
      "x": 2,
      "y": -24,
      "z": 0,
      "name": "Rock_Ice_Permafrost",
      "rotation": 3
    },
    {
      "x": 2,
      "y": -23,
      "z": 0,
      "name": "Rock_Ice_Permafrost",
      "rotation": 3
    },
    {
      "x": 2,
      "y": -22,
      "z": 0,
      "name": "Rock_Ice_Permafrost",
      "rotation": 3
    },
    {
      "x": 2,
      "y": -21,
      "z": 0,
      "name": "Rock_Ice_Permafrost",
      "rotation": 3
    },
    {
      "x": 2,
      "y": -20,
      "z": 0,
      "name": "Rock_Ice_Permafrost",
      "rotation": 3
    },
    {
      "x": 2,
      "y": -19,
      "z": 0,
      "name": "Rock_Ice_Permafrost",
      "rotation": 3
    },
    {
      "x": 2,
      "y": -18,
      "z": 0,
      "name": "Rock_Ice_Permafrost",
      "rotation": 3
    },
    {
      "x": 2,
      "y": -17,
      "z": 0,
      "name": "Rock_Ice_Permafrost",
      "rotation": 3
    },
    {
      "x": 2,
      "y": -16,
      "z": 0,
      "name": "Rock_Ice_Permafrost",
      "rotation": 3
    },
    {
      "x": 2,
      "y": -15,
      "z": 0,
      "name": "Rock_Ice_Permafrost",
      "rotation": 3
    },
    {
      "x": 2,
      "y": -14,
      "z": 0,
      "name": "Rock_Ice",
      "rotation": 3
    },
    {
      "x": 2,
      "y": -13,
      "z": 0,
      "name": "Rock_Ice",
      "rotation": 3
    },
    {
      "x": 2,
      "y": -12,
      "z": 0,
      "name": "Rock_Ice",
      "rotation": 3
    },
    {
      "x": 2,
      "y": -11,
      "z": 0,
      "name": "Soil_Snow",
      "rotation": 3
    },
    {
      "x": 2,
      "y": -43,
      "z": 1,
      "name": "Soil_Snow",
      "rotation": 3
    },
    {
      "x": 2,
      "y": -42,
      "z": 1,
      "name": "Soil_Snow",
      "rotation": 3
    },
    {
      "x": 2,
      "y": -29,
      "z": 1,
      "name": "Rock_Ice",
      "rotation": 3
    },
    {
      "x": 2,
      "y": -28,
      "z": 1,
      "name": "Rock_Ice",
      "rotation": 3
    },
    {
      "x": 2,
      "y": -27,
      "z": 1,
      "name": "Rock_Ice_Permafrost",
      "rotation": 3
    },
    {
      "x": 2,
      "y": -26,
      "z": 1,
      "name": "Rock_Ice_Permafrost",
      "rotation": 3
    },
    {
      "x": 2,
      "y": -25,
      "z": 1,
      "name": "Rock_Ice_Permafrost",
      "rotation": 3
    },
    {
      "x": 2,
      "y": -24,
      "z": 1,
      "name": "Rock_Ice_Permafrost",
      "rotation": 3
    },
    {
      "x": 2,
      "y": -23,
      "z": 1,
      "name": "Rock_Ice_Permafrost",
      "rotation": 3
    },
    {
      "x": 2,
      "y": -22,
      "z": 1,
      "name": "Rock_Ice_Permafrost",
      "rotation": 3
    },
    {
      "x": 2,
      "y": -21,
      "z": 1,
      "name": "Rock_Ice_Permafrost",
      "rotation": 3
    },
    {
      "x": 2,
      "y": -20,
      "z": 1,
      "name": "Rock_Ice_Permafrost",
      "rotation": 3
    },
    {
      "x": 2,
      "y": -19,
      "z": 1,
      "name": "Rock_Ice_Permafrost",
      "rotation": 3
    },
    {
      "x": 2,
      "y": -18,
      "z": 1,
      "name": "Rock_Ice_Permafrost",
      "rotation": 3
    },
    {
      "x": 2,
      "y": -17,
      "z": 1,
      "name": "Rock_Ice_Permafrost",
      "rotation": 3
    },
    {
      "x": 2,
      "y": -16,
      "z": 1,
      "name": "Rock_Ice_Permafrost",
      "rotation": 3
    },
    {
      "x": 2,
      "y": -15,
      "z": 1,
      "name": "Rock_Ice",
      "rotation": 3
    },
    {
      "x": 2,
      "y": -14,
      "z": 1,
      "name": "Rock_Ice",
      "rotation": 3
    },
    {
      "x": 2,
      "y": -13,
      "z": 1,
      "name": "Rock_Ice",
      "rotation": 3
    },
    {
      "x": 2,
      "y": -12,
      "z": 1,
      "name": "Rock_Ice",
      "rotation": 3
    },
    {
      "x": 2,
      "y": -11,
      "z": 1,
      "name": "Soil_Snow",
      "rotation": 3
    },
    {
      "x": 2,
      "y": -27,
      "z": 2,
      "name": "Rock_Ice_Permafrost",
      "rotation": 3
    },
    {
      "x": 2,
      "y": -26,
      "z": 2,
      "name": "Rock_Ice_Permafrost",
      "rotation": 3
    },
    {
      "x": 2,
      "y": -25,
      "z": 2,
      "name": "Rock_Ice_Permafrost",
      "rotation": 3
    },
    {
      "x": 2,
      "y": -24,
      "z": 2,
      "name": "Rock_Ice_Permafrost",
      "rotation": 3
    },
    {
      "x": 2,
      "y": -23,
      "z": 2,
      "name": "Rock_Ice_Permafrost",
      "rotation": 3
    },
    {
      "x": 2,
      "y": -22,
      "z": 2,
      "name": "Rock_Ice",
      "rotation": 3
    },
    {
      "x": 2,
      "y": -21,
      "z": 2,
      "name": "Rock_Ice_Permafrost",
      "rotation": 3
    },
    {
      "x": 2,
      "y": -20,
      "z": 2,
      "name": "Rock_Ice",
      "rotation": 3
    },
    {
      "x": 2,
      "y": -19,
      "z": 2,
      "name": "Rock_Ice_Permafrost",
      "rotation": 3
    },
    {
      "x": 2,
      "y": -18,
      "z": 2,
      "name": "Rock_Ice_Permafrost",
      "rotation": 3
    },
    {
      "x": 2,
      "y": -17,
      "z": 2,
      "name": "Rock_Ice_Permafrost",
      "rotation": 3
    },
    {
      "x": 2,
      "y": -16,
      "z": 2,
      "name": "Rock_Ice_Permafrost",
      "rotation": 3
    },
    {
      "x": 2,
      "y": -15,
      "z": 2,
      "name": "Rock_Ice",
      "rotation": 3
    },
    {
      "x": 2,
      "y": -14,
      "z": 2,
      "name": "Rock_Ice",
      "rotation": 3
    },
    {
      "x": 2,
      "y": -13,
      "z": 2,
      "name": "Rock_Ice",
      "rotation": 3
    },
    {
      "x": 2,
      "y": -12,
      "z": 2,
      "name": "Soil_Snow",
      "rotation": 3
    },
    {
      "x": 2,
      "y": -11,
      "z": 2,
      "name": "Soil_Snow",
      "rotation": 3
    },
    {
      "x": 2,
      "y": -26,
      "z": 3,
      "name": "Rock_Ice_Permafrost",
      "rotation": 3
    },
    {
      "x": 2,
      "y": -25,
      "z": 3,
      "name": "Rock_Ice_Permafrost",
      "rotation": 3
    },
    {
      "x": 2,
      "y": -24,
      "z": 3,
      "name": "Rock_Ice_Permafrost",
      "rotation": 3
    },
    {
      "x": 2,
      "y": -23,
      "z": 3,
      "name": "Rock_Ice_Permafrost",
      "rotation": 3
    },
    {
      "x": 2,
      "y": -22,
      "z": 3,
      "name": "Rock_Ice",
      "rotation": 3
    },
    {
      "x": 2,
      "y": -21,
      "z": 3,
      "name": "Rock_Ice",
      "rotation": 3
    },
    {
      "x": 2,
      "y": -20,
      "z": 3,
      "name": "Rock_Ice",
      "rotation": 3
    },
    {
      "x": 2,
      "y": -19,
      "z": 3,
      "name": "Soil_Snow",
      "rotation": 3
    },
    {
      "x": 2,
      "y": -15,
      "z": 3,
      "name": "Rock_Ice_Permafrost",
      "rotation": 3
    },
    {
      "x": 2,
      "y": -14,
      "z": 3,
      "name": "Rock_Ice",
      "rotation": 3
    },
    {
      "x": 2,
      "y": -13,
      "z": 3,
      "name": "Soil_Snow",
      "rotation": 3
    },
    {
      "x": 2,
      "y": -25,
      "z": 4,
      "name": "Rock_Ice",
      "rotation": 3
    },
    {
      "x": 2,
      "y": -24,
      "z": 4,
      "name": "Rock_Ice",
      "rotation": 3
    },
    {
      "x": 2,
      "y": -23,
      "z": 4,
      "name": "Rock_Ice",
      "rotation": 3
    },
    {
      "x": 2,
      "y": -22,
      "z": 4,
      "name": "Rock_Ice",
      "rotation": 3
    },
    {
      "x": 2,
      "y": -21,
      "z": 4,
      "name": "Rock_Ice",
      "rotation": 3
    },
    {
      "x": 2,
      "y": -20,
      "z": 4,
      "name": "Rock_Ice",
      "rotation": 3
    },
    {
      "x": 2,
      "y": -19,
      "z": 4,
      "name": "Soil_Snow",
      "rotation": 3
    },
    {
      "x": 2,
      "y": -21,
      "z": 5,
      "name": "Rock_Ice",
      "rotation": 3
    },
    {
      "x": 2,
      "y": -20,
      "z": 5,
      "name": "Soil_Snow",
      "rotation": 3
    },
    {
      "x": 3,
      "y": -22,
      "z": -6,
      "name": "Rock_Ice",
      "rotation": 3
    },
    {
      "x": 3,
      "y": -21,
      "z": -6,
      "name": "Rock_Ice",
      "rotation": 3
    },
    {
      "x": 3,
      "y": -20,
      "z": -6,
      "name": "Rock_Ice",
      "rotation": 3
    },
    {
      "x": 3,
      "y": -19,
      "z": -6,
      "name": "Soil_Snow",
      "rotation": 3
    },
    {
      "x": 3,
      "y": -26,
      "z": -5,
      "name": "Rock_Ice_Permafrost",
      "rotation": 3
    },
    {
      "x": 3,
      "y": -25,
      "z": -5,
      "name": "Rock_Ice_Permafrost",
      "rotation": 3
    },
    {
      "x": 3,
      "y": -24,
      "z": -5,
      "name": "Rock_Ice_Permafrost",
      "rotation": 3
    },
    {
      "x": 3,
      "y": -23,
      "z": -5,
      "name": "Rock_Ice",
      "rotation": 3
    },
    {
      "x": 3,
      "y": -22,
      "z": -5,
      "name": "Rock_Ice",
      "rotation": 3
    },
    {
      "x": 3,
      "y": -21,
      "z": -5,
      "name": "Rock_Ice",
      "rotation": 3
    },
    {
      "x": 3,
      "y": -20,
      "z": -5,
      "name": "Rock_Ice",
      "rotation": 3
    },
    {
      "x": 3,
      "y": -19,
      "z": -5,
      "name": "Soil_Snow",
      "rotation": 3
    },
    {
      "x": 3,
      "y": -36,
      "z": -4,
      "name": "Rock_Ice",
      "rotation": 3
    },
    {
      "x": 3,
      "y": -35,
      "z": -4,
      "name": "Rock_Ice",
      "rotation": 3
    },
    {
      "x": 3,
      "y": -34,
      "z": -4,
      "name": "Rock_Ice",
      "rotation": 3
    },
    {
      "x": 3,
      "y": -33,
      "z": -4,
      "name": "Rock_Ice",
      "rotation": 3
    },
    {
      "x": 3,
      "y": -32,
      "z": -4,
      "name": "Rock_Ice",
      "rotation": 3
    },
    {
      "x": 3,
      "y": -31,
      "z": -4,
      "name": "Rock_Ice",
      "rotation": 3
    },
    {
      "x": 3,
      "y": -30,
      "z": -4,
      "name": "Rock_Ice_Permafrost",
      "rotation": 3
    },
    {
      "x": 3,
      "y": -29,
      "z": -4,
      "name": "Rock_Ice_Permafrost",
      "rotation": 3
    },
    {
      "x": 3,
      "y": -28,
      "z": -4,
      "name": "Rock_Ice",
      "rotation": 3
    },
    {
      "x": 3,
      "y": -27,
      "z": -4,
      "name": "Rock_Ice",
      "rotation": 3
    },
    {
      "x": 3,
      "y": -26,
      "z": -4,
      "name": "Rock_Ice",
      "rotation": 3
    },
    {
      "x": 3,
      "y": -25,
      "z": -4,
      "name": "Rock_Ice_Permafrost",
      "rotation": 3
    },
    {
      "x": 3,
      "y": -24,
      "z": -4,
      "name": "Rock_Ice_Permafrost",
      "rotation": 3
    },
    {
      "x": 3,
      "y": -23,
      "z": -4,
      "name": "Rock_Ice_Permafrost",
      "rotation": 3
    },
    {
      "x": 3,
      "y": -22,
      "z": -4,
      "name": "Rock_Ice_Permafrost",
      "rotation": 3
    },
    {
      "x": 3,
      "y": -21,
      "z": -4,
      "name": "Rock_Ice_Permafrost",
      "rotation": 3
    },
    {
      "x": 3,
      "y": -20,
      "z": -4,
      "name": "Rock_Ice",
      "rotation": 3
    },
    {
      "x": 3,
      "y": -19,
      "z": -4,
      "name": "Soil_Snow",
      "rotation": 3
    },
    {
      "x": 3,
      "y": -17,
      "z": -4,
      "name": "Soil_Snow",
      "rotation": 3
    },
    {
      "x": 3,
      "y": -16,
      "z": -4,
      "name": "Soil_Snow",
      "rotation": 3
    },
    {
      "x": 3,
      "y": -41,
      "z": -3,
      "name": "Rock_Ice_Permafrost",
      "rotation": 3
    },
    {
      "x": 3,
      "y": -40,
      "z": -3,
      "name": "Rock_Ice",
      "rotation": 3
    },
    {
      "x": 3,
      "y": -39,
      "z": -3,
      "name": "Rock_Ice",
      "rotation": 3
    },
    {
      "x": 3,
      "y": -38,
      "z": -3,
      "name": "Rock_Ice",
      "rotation": 3
    },
    {
      "x": 3,
      "y": -37,
      "z": -3,
      "name": "Rock_Ice",
      "rotation": 3
    },
    {
      "x": 3,
      "y": -36,
      "z": -3,
      "name": "Rock_Ice",
      "rotation": 3
    },
    {
      "x": 3,
      "y": -35,
      "z": -3,
      "name": "Rock_Ice",
      "rotation": 3
    },
    {
      "x": 3,
      "y": -34,
      "z": -3,
      "name": "Rock_Ice",
      "rotation": 3
    },
    {
      "x": 3,
      "y": -33,
      "z": -3,
      "name": "Rock_Ice",
      "rotation": 3
    },
    {
      "x": 3,
      "y": -32,
      "z": -3,
      "name": "Rock_Ice",
      "rotation": 3
    },
    {
      "x": 3,
      "y": -31,
      "z": -3,
      "name": "Rock_Ice",
      "rotation": 3
    },
    {
      "x": 3,
      "y": -30,
      "z": -3,
      "name": "Rock_Ice_Permafrost",
      "rotation": 3
    },
    {
      "x": 3,
      "y": -29,
      "z": -3,
      "name": "Rock_Ice_Permafrost",
      "rotation": 3
    },
    {
      "x": 3,
      "y": -28,
      "z": -3,
      "name": "Rock_Ice_Permafrost",
      "rotation": 3
    },
    {
      "x": 3,
      "y": -27,
      "z": -3,
      "name": "Rock_Ice_Permafrost",
      "rotation": 3
    },
    {
      "x": 3,
      "y": -26,
      "z": -3,
      "name": "Rock_Ice_Permafrost",
      "rotation": 3
    },
    {
      "x": 3,
      "y": -25,
      "z": -3,
      "name": "Rock_Ice_Permafrost",
      "rotation": 3
    },
    {
      "x": 3,
      "y": -24,
      "z": -3,
      "name": "Rock_Ice_Permafrost",
      "rotation": 3
    },
    {
      "x": 3,
      "y": -23,
      "z": -3,
      "name": "Rock_Ice_Permafrost",
      "rotation": 3
    },
    {
      "x": 3,
      "y": -22,
      "z": -3,
      "name": "Rock_Ice_Permafrost",
      "rotation": 3
    },
    {
      "x": 3,
      "y": -21,
      "z": -3,
      "name": "Rock_Ice_Permafrost",
      "rotation": 3
    },
    {
      "x": 3,
      "y": -20,
      "z": -3,
      "name": "Rock_Ice_Permafrost",
      "rotation": 3
    },
    {
      "x": 3,
      "y": -19,
      "z": -3,
      "name": "Rock_Ice",
      "rotation": 3
    },
    {
      "x": 3,
      "y": -18,
      "z": -3,
      "name": "Rock_Ice",
      "rotation": 3
    },
    {
      "x": 3,
      "y": -17,
      "z": -3,
      "name": "Rock_Ice",
      "rotation": 3
    },
    {
      "x": 3,
      "y": -16,
      "z": -3,
      "name": "Rock_Ice_Permafrost",
      "rotation": 3
    },
    {
      "x": 3,
      "y": -15,
      "z": -3,
      "name": "Soil_Snow",
      "rotation": 3
    },
    {
      "x": 3,
      "y": -9,
      "z": -3,
      "name": "Empty"
    },
    {
      "x": 3,
      "y": -8,
      "z": -3,
      "name": "Empty"
    },
    {
      "x": 3,
      "y": -7,
      "z": -3,
      "name": "Empty"
    },
    {
      "x": 3,
      "y": -43,
      "z": -2,
      "name": "Rock_Ice_Permafrost",
      "rotation": 3
    },
    {
      "x": 3,
      "y": -42,
      "z": -2,
      "name": "Rock_Ice_Permafrost",
      "rotation": 3
    },
    {
      "x": 3,
      "y": -41,
      "z": -2,
      "name": "Rock_Ice_Permafrost",
      "rotation": 3
    },
    {
      "x": 3,
      "y": -40,
      "z": -2,
      "name": "Rock_Ice_Permafrost",
      "rotation": 3
    },
    {
      "x": 3,
      "y": -39,
      "z": -2,
      "name": "Rock_Ice",
      "rotation": 3
    },
    {
      "x": 3,
      "y": -38,
      "z": -2,
      "name": "Rock_Ice",
      "rotation": 3
    },
    {
      "x": 3,
      "y": -37,
      "z": -2,
      "name": "Rock_Ice",
      "rotation": 3
    },
    {
      "x": 3,
      "y": -36,
      "z": -2,
      "name": "Rock_Ice_Permafrost",
      "rotation": 3
    },
    {
      "x": 3,
      "y": -35,
      "z": -2,
      "name": "Rock_Ice_Permafrost",
      "rotation": 3
    },
    {
      "x": 3,
      "y": -34,
      "z": -2,
      "name": "Rock_Ice_Permafrost",
      "rotation": 3
    },
    {
      "x": 3,
      "y": -33,
      "z": -2,
      "name": "Rock_Ice_Permafrost",
      "rotation": 3
    },
    {
      "x": 3,
      "y": -32,
      "z": -2,
      "name": "Rock_Ice_Permafrost",
      "rotation": 3
    },
    {
      "x": 3,
      "y": -31,
      "z": -2,
      "name": "Rock_Ice",
      "rotation": 3
    },
    {
      "x": 3,
      "y": -30,
      "z": -2,
      "name": "Rock_Ice",
      "rotation": 3
    },
    {
      "x": 3,
      "y": -29,
      "z": -2,
      "name": "Rock_Ice",
      "rotation": 3
    },
    {
      "x": 3,
      "y": -28,
      "z": -2,
      "name": "Rock_Ice_Permafrost",
      "rotation": 3
    },
    {
      "x": 3,
      "y": -27,
      "z": -2,
      "name": "Rock_Ice_Permafrost",
      "rotation": 3
    },
    {
      "x": 3,
      "y": -26,
      "z": -2,
      "name": "Rock_Ice_Permafrost",
      "rotation": 3
    },
    {
      "x": 3,
      "y": -25,
      "z": -2,
      "name": "Rock_Ice_Permafrost",
      "rotation": 3
    },
    {
      "x": 3,
      "y": -24,
      "z": -2,
      "name": "Rock_Ice_Permafrost",
      "rotation": 3
    },
    {
      "x": 3,
      "y": -23,
      "z": -2,
      "name": "Rock_Ice_Permafrost",
      "rotation": 3
    },
    {
      "x": 3,
      "y": -22,
      "z": -2,
      "name": "Rock_Ice_Permafrost",
      "rotation": 3
    },
    {
      "x": 3,
      "y": -21,
      "z": -2,
      "name": "Rock_Ice_Permafrost",
      "rotation": 3
    },
    {
      "x": 3,
      "y": -20,
      "z": -2,
      "name": "Rock_Ice_Permafrost",
      "rotation": 3
    },
    {
      "x": 3,
      "y": -19,
      "z": -2,
      "name": "Rock_Ice_Permafrost",
      "rotation": 3
    },
    {
      "x": 3,
      "y": -18,
      "z": -2,
      "name": "Rock_Ice",
      "rotation": 3
    },
    {
      "x": 3,
      "y": -17,
      "z": -2,
      "name": "Rock_Ice",
      "rotation": 3
    },
    {
      "x": 3,
      "y": -16,
      "z": -2,
      "name": "Rock_Ice",
      "rotation": 3
    },
    {
      "x": 3,
      "y": -15,
      "z": -2,
      "name": "Rock_Ice",
      "rotation": 3
    },
    {
      "x": 3,
      "y": -14,
      "z": -2,
      "name": "Rock_Ice",
      "rotation": 3
    },
    {
      "x": 3,
      "y": -13,
      "z": -2,
      "name": "Soil_Snow",
      "rotation": 3
    },
    {
      "x": 3,
      "y": -12,
      "z": -2,
      "name": "Soil_Snow",
      "rotation": 3
    },
    {
      "x": 3,
      "y": -9,
      "z": -2,
      "name": "Empty"
    },
    {
      "x": 3,
      "y": -8,
      "z": -2,
      "name": "Empty"
    },
    {
      "x": 3,
      "y": -3,
      "z": -2,
      "name": "Rock_Ice",
      "rotation": 3
    },
    {
      "x": 3,
      "y": -2,
      "z": -2,
      "name": "Soil_Snow",
      "rotation": 3
    },
    {
      "x": 3,
      "y": -44,
      "z": -1,
      "name": "Rock_Ice_Permafrost",
      "rotation": 3
    },
    {
      "x": 3,
      "y": -43,
      "z": -1,
      "name": "Rock_Ice_Permafrost",
      "rotation": 3
    },
    {
      "x": 3,
      "y": -42,
      "z": -1,
      "name": "Rock_Ice_Permafrost",
      "rotation": 3
    },
    {
      "x": 3,
      "y": -41,
      "z": -1,
      "name": "Rock_Ice_Permafrost",
      "rotation": 3
    },
    {
      "x": 3,
      "y": -40,
      "z": -1,
      "name": "Rock_Ice_Permafrost",
      "rotation": 3
    },
    {
      "x": 3,
      "y": -39,
      "z": -1,
      "name": "Rock_Ice_Permafrost",
      "rotation": 3
    },
    {
      "x": 3,
      "y": -38,
      "z": -1,
      "name": "Rock_Ice_Permafrost",
      "rotation": 3
    },
    {
      "x": 3,
      "y": -37,
      "z": -1,
      "name": "Rock_Ice_Permafrost",
      "rotation": 3
    },
    {
      "x": 3,
      "y": -36,
      "z": -1,
      "name": "Rock_Ice_Permafrost",
      "rotation": 3
    },
    {
      "x": 3,
      "y": -35,
      "z": -1,
      "name": "Rock_Ice_Permafrost",
      "rotation": 3
    },
    {
      "x": 3,
      "y": -34,
      "z": -1,
      "name": "Rock_Ice_Permafrost",
      "rotation": 3
    },
    {
      "x": 3,
      "y": -33,
      "z": -1,
      "name": "Rock_Ice_Permafrost",
      "rotation": 3
    },
    {
      "x": 3,
      "y": -32,
      "z": -1,
      "name": "Rock_Ice_Permafrost",
      "rotation": 3
    },
    {
      "x": 3,
      "y": -31,
      "z": -1,
      "name": "Rock_Ice_Permafrost",
      "rotation": 3
    },
    {
      "x": 3,
      "y": -30,
      "z": -1,
      "name": "Rock_Ice",
      "rotation": 3
    },
    {
      "x": 3,
      "y": -29,
      "z": -1,
      "name": "Rock_Ice",
      "rotation": 3
    },
    {
      "x": 3,
      "y": -28,
      "z": -1,
      "name": "Rock_Ice",
      "rotation": 3
    },
    {
      "x": 3,
      "y": -27,
      "z": -1,
      "name": "Rock_Ice",
      "rotation": 3
    },
    {
      "x": 3,
      "y": -26,
      "z": -1,
      "name": "Rock_Ice_Permafrost",
      "rotation": 3
    },
    {
      "x": 3,
      "y": -25,
      "z": -1,
      "name": "Rock_Ice_Permafrost",
      "rotation": 3
    },
    {
      "x": 3,
      "y": -24,
      "z": -1,
      "name": "Rock_Ice_Permafrost",
      "rotation": 3
    },
    {
      "x": 3,
      "y": -23,
      "z": -1,
      "name": "Rock_Ice_Permafrost",
      "rotation": 3
    },
    {
      "x": 3,
      "y": -22,
      "z": -1,
      "name": "Rock_Ice_Permafrost",
      "rotation": 3
    },
    {
      "x": 3,
      "y": -21,
      "z": -1,
      "name": "Rock_Ice_Permafrost",
      "rotation": 3
    },
    {
      "x": 3,
      "y": -20,
      "z": -1,
      "name": "Rock_Ice_Permafrost",
      "rotation": 3
    },
    {
      "x": 3,
      "y": -19,
      "z": -1,
      "name": "Rock_Ice_Permafrost",
      "rotation": 3
    },
    {
      "x": 3,
      "y": -18,
      "z": -1,
      "name": "Rock_Ice_Permafrost",
      "rotation": 3
    },
    {
      "x": 3,
      "y": -17,
      "z": -1,
      "name": "Rock_Ice_Permafrost",
      "rotation": 3
    },
    {
      "x": 3,
      "y": -16,
      "z": -1,
      "name": "Rock_Ice_Permafrost",
      "rotation": 3
    },
    {
      "x": 3,
      "y": -15,
      "z": -1,
      "name": "Rock_Ice",
      "rotation": 3
    },
    {
      "x": 3,
      "y": -14,
      "z": -1,
      "name": "Rock_Ice",
      "rotation": 3
    },
    {
      "x": 3,
      "y": -13,
      "z": -1,
      "name": "Rock_Ice",
      "rotation": 3
    },
    {
      "x": 3,
      "y": -12,
      "z": -1,
      "name": "Rock_Ice",
      "rotation": 3
    },
    {
      "x": 3,
      "y": -11,
      "z": -1,
      "name": "Soil_Snow",
      "rotation": 3
    },
    {
      "x": 3,
      "y": -5,
      "z": -1,
      "name": "Rock_Ice_Permafrost",
      "rotation": 3
    },
    {
      "x": 3,
      "y": -4,
      "z": -1,
      "name": "Rock_Ice",
      "rotation": 3
    },
    {
      "x": 3,
      "y": -3,
      "z": -1,
      "name": "Soil_Snow",
      "rotation": 3
    },
    {
      "x": 3,
      "y": -2,
      "z": -1,
      "name": "Soil_Snow",
      "rotation": 3
    },
    {
      "x": 3,
      "y": -45,
      "z": 0,
      "name": "Rock_Ice_Permafrost",
      "rotation": 3
    },
    {
      "x": 3,
      "y": -44,
      "z": 0,
      "name": "Rock_Ice_Permafrost",
      "rotation": 3
    },
    {
      "x": 3,
      "y": -43,
      "z": 0,
      "name": "Rock_Ice",
      "rotation": 3
    },
    {
      "x": 3,
      "y": -42,
      "z": 0,
      "name": "Rock_Ice",
      "rotation": 3
    },
    {
      "x": 3,
      "y": -41,
      "z": 0,
      "name": "Rock_Ice",
      "rotation": 3
    },
    {
      "x": 3,
      "y": -40,
      "z": 0,
      "name": "Rock_Ice",
      "rotation": 3
    },
    {
      "x": 3,
      "y": -39,
      "z": 0,
      "name": "Rock_Ice",
      "rotation": 3
    },
    {
      "x": 3,
      "y": -38,
      "z": 0,
      "name": "Rock_Ice",
      "rotation": 3
    },
    {
      "x": 3,
      "y": -37,
      "z": 0,
      "name": "Rock_Ice",
      "rotation": 3
    },
    {
      "x": 3,
      "y": -36,
      "z": 0,
      "name": "Rock_Ice",
      "rotation": 3
    },
    {
      "x": 3,
      "y": -35,
      "z": 0,
      "name": "Rock_Ice",
      "rotation": 3
    },
    {
      "x": 3,
      "y": -34,
      "z": 0,
      "name": "Rock_Ice_Permafrost",
      "rotation": 3
    },
    {
      "x": 3,
      "y": -33,
      "z": 0,
      "name": "Rock_Ice_Permafrost",
      "rotation": 3
    },
    {
      "x": 3,
      "y": -28,
      "z": 0,
      "name": "Rock_Ice",
      "rotation": 3
    },
    {
      "x": 3,
      "y": -27,
      "z": 0,
      "name": "Rock_Ice",
      "rotation": 3
    },
    {
      "x": 3,
      "y": -26,
      "z": 0,
      "name": "Rock_Ice",
      "rotation": 3
    },
    {
      "x": 3,
      "y": -25,
      "z": 0,
      "name": "Rock_Ice_Permafrost",
      "rotation": 3
    },
    {
      "x": 3,
      "y": -24,
      "z": 0,
      "name": "Rock_Ice_Permafrost",
      "rotation": 3
    },
    {
      "x": 3,
      "y": -23,
      "z": 0,
      "name": "Rock_Ice_Permafrost",
      "rotation": 3
    },
    {
      "x": 3,
      "y": -22,
      "z": 0,
      "name": "Rock_Ice_Permafrost",
      "rotation": 3
    },
    {
      "x": 3,
      "y": -21,
      "z": 0,
      "name": "Rock_Ice_Permafrost",
      "rotation": 3
    },
    {
      "x": 3,
      "y": -20,
      "z": 0,
      "name": "Rock_Ice_Permafrost",
      "rotation": 3
    },
    {
      "x": 3,
      "y": -19,
      "z": 0,
      "name": "Rock_Ice_Permafrost",
      "rotation": 3
    },
    {
      "x": 3,
      "y": -18,
      "z": 0,
      "name": "Rock_Ice_Permafrost",
      "rotation": 3
    },
    {
      "x": 3,
      "y": -17,
      "z": 0,
      "name": "Rock_Ice_Permafrost",
      "rotation": 3
    },
    {
      "x": 3,
      "y": -16,
      "z": 0,
      "name": "Rock_Ice_Permafrost",
      "rotation": 3
    },
    {
      "x": 3,
      "y": -15,
      "z": 0,
      "name": "Rock_Ice_Permafrost",
      "rotation": 3
    },
    {
      "x": 3,
      "y": -14,
      "z": 0,
      "name": "Rock_Ice_Permafrost",
      "rotation": 3
    },
    {
      "x": 3,
      "y": -13,
      "z": 0,
      "name": "Rock_Ice_Permafrost",
      "rotation": 3
    },
    {
      "x": 3,
      "y": -12,
      "z": 0,
      "name": "Rock_Ice_Permafrost",
      "rotation": 3
    },
    {
      "x": 3,
      "y": -11,
      "z": 0,
      "name": "Soil_Snow",
      "rotation": 3
    },
    {
      "x": 3,
      "y": -6,
      "z": 0,
      "name": "Soil_Snow",
      "rotation": 3
    },
    {
      "x": 3,
      "y": -4,
      "z": 0,
      "name": "Rock_Ice",
      "rotation": 3
    },
    {
      "x": 3,
      "y": -3,
      "z": 0,
      "name": "Soil_Snow",
      "rotation": 3
    },
    {
      "x": 3,
      "y": -44,
      "z": 1,
      "name": "Rock_Ice",
      "rotation": 3
    },
    {
      "x": 3,
      "y": -43,
      "z": 1,
      "name": "Rock_Ice",
      "rotation": 3
    },
    {
      "x": 3,
      "y": -42,
      "z": 1,
      "name": "Rock_Ice",
      "rotation": 3
    },
    {
      "x": 3,
      "y": -41,
      "z": 1,
      "name": "Soil_Snow",
      "rotation": 3
    },
    {
      "x": 3,
      "y": -40,
      "z": 1,
      "name": "Rock_Ice",
      "rotation": 3
    },
    {
      "x": 3,
      "y": -39,
      "z": 1,
      "name": "Rock_Ice",
      "rotation": 3
    },
    {
      "x": 3,
      "y": -38,
      "z": 1,
      "name": "Soil_Snow",
      "rotation": 3
    },
    {
      "x": 3,
      "y": -37,
      "z": 1,
      "name": "Soil_Snow",
      "rotation": 3
    },
    {
      "x": 3,
      "y": -27,
      "z": 1,
      "name": "Rock_Ice",
      "rotation": 3
    },
    {
      "x": 3,
      "y": -26,
      "z": 1,
      "name": "Rock_Ice_Permafrost",
      "rotation": 3
    },
    {
      "x": 3,
      "y": -25,
      "z": 1,
      "name": "Rock_Ice_Permafrost",
      "rotation": 3
    },
    {
      "x": 3,
      "y": -24,
      "z": 1,
      "name": "Rock_Ice_Permafrost",
      "rotation": 3
    },
    {
      "x": 3,
      "y": -23,
      "z": 1,
      "name": "Rock_Ice_Permafrost",
      "rotation": 3
    },
    {
      "x": 3,
      "y": -22,
      "z": 1,
      "name": "Rock_Ice_Permafrost",
      "rotation": 3
    },
    {
      "x": 3,
      "y": -21,
      "z": 1,
      "name": "Rock_Ice_Permafrost",
      "rotation": 3
    },
    {
      "x": 3,
      "y": -20,
      "z": 1,
      "name": "Rock_Ice_Permafrost",
      "rotation": 3
    },
    {
      "x": 3,
      "y": -19,
      "z": 1,
      "name": "Rock_Ice_Permafrost",
      "rotation": 3
    },
    {
      "x": 3,
      "y": -18,
      "z": 1,
      "name": "Rock_Ice_Permafrost",
      "rotation": 3
    },
    {
      "x": 3,
      "y": -17,
      "z": 1,
      "name": "Rock_Ice_Permafrost",
      "rotation": 3
    },
    {
      "x": 3,
      "y": -16,
      "z": 1,
      "name": "Rock_Ice_Permafrost",
      "rotation": 3
    },
    {
      "x": 3,
      "y": -15,
      "z": 1,
      "name": "Rock_Ice_Permafrost",
      "rotation": 3
    },
    {
      "x": 3,
      "y": -14,
      "z": 1,
      "name": "Rock_Ice_Permafrost",
      "rotation": 3
    },
    {
      "x": 3,
      "y": -13,
      "z": 1,
      "name": "Rock_Ice_Permafrost",
      "rotation": 3
    },
    {
      "x": 3,
      "y": -12,
      "z": 1,
      "name": "Rock_Ice_Permafrost",
      "rotation": 3
    },
    {
      "x": 3,
      "y": -11,
      "z": 1,
      "name": "Soil_Snow",
      "rotation": 3
    },
    {
      "x": 3,
      "y": -7,
      "z": 1,
      "name": "Rock_Ice",
      "rotation": 3
    },
    {
      "x": 3,
      "y": -6,
      "z": 1,
      "name": "Soil_Snow",
      "rotation": 3
    },
    {
      "x": 3,
      "y": -44,
      "z": 2,
      "name": "Rock_Ice",
      "rotation": 3
    },
    {
      "x": 3,
      "y": -43,
      "z": 2,
      "name": "Soil_Snow",
      "rotation": 3
    },
    {
      "x": 3,
      "y": -42,
      "z": 2,
      "name": "Soil_Snow",
      "rotation": 3
    },
    {
      "x": 3,
      "y": -41,
      "z": 2,
      "name": "Soil_Snow",
      "rotation": 3
    },
    {
      "x": 3,
      "y": -40,
      "z": 2,
      "name": "Soil_Snow",
      "rotation": 3
    },
    {
      "x": 3,
      "y": -39,
      "z": 2,
      "name": "Soil_Snow",
      "rotation": 3
    },
    {
      "x": 3,
      "y": -26,
      "z": 2,
      "name": "Rock_Ice",
      "rotation": 3
    },
    {
      "x": 3,
      "y": -25,
      "z": 2,
      "name": "Rock_Ice_Permafrost",
      "rotation": 3
    },
    {
      "x": 3,
      "y": -24,
      "z": 2,
      "name": "Rock_Ice_Permafrost",
      "rotation": 3
    },
    {
      "x": 3,
      "y": -23,
      "z": 2,
      "name": "Rock_Ice_Permafrost",
      "rotation": 3
    },
    {
      "x": 3,
      "y": -22,
      "z": 2,
      "name": "Rock_Ice_Permafrost",
      "rotation": 3
    },
    {
      "x": 3,
      "y": -21,
      "z": 2,
      "name": "Rock_Ice",
      "rotation": 3
    },
    {
      "x": 3,
      "y": -20,
      "z": 2,
      "name": "Rock_Ice",
      "rotation": 3
    },
    {
      "x": 3,
      "y": -19,
      "z": 2,
      "name": "Rock_Ice",
      "rotation": 3
    },
    {
      "x": 3,
      "y": -18,
      "z": 2,
      "name": "Rock_Ice_Permafrost",
      "rotation": 3
    },
    {
      "x": 3,
      "y": -17,
      "z": 2,
      "name": "Rock_Ice_Permafrost",
      "rotation": 3
    },
    {
      "x": 3,
      "y": -16,
      "z": 2,
      "name": "Rock_Ice_Permafrost",
      "rotation": 3
    },
    {
      "x": 3,
      "y": -15,
      "z": 2,
      "name": "Rock_Ice",
      "rotation": 3
    },
    {
      "x": 3,
      "y": -14,
      "z": 2,
      "name": "Rock_Ice",
      "rotation": 3
    },
    {
      "x": 3,
      "y": -13,
      "z": 2,
      "name": "Rock_Ice",
      "rotation": 3
    },
    {
      "x": 3,
      "y": -12,
      "z": 2,
      "name": "Rock_Ice",
      "rotation": 3
    },
    {
      "x": 3,
      "y": -11,
      "z": 2,
      "name": "Soil_Snow",
      "rotation": 3
    },
    {
      "x": 3,
      "y": -43,
      "z": 3,
      "name": "Soil_Snow",
      "rotation": 3
    },
    {
      "x": 3,
      "y": -26,
      "z": 3,
      "name": "Rock_Ice_Permafrost",
      "rotation": 3
    },
    {
      "x": 3,
      "y": -25,
      "z": 3,
      "name": "Rock_Ice_Permafrost",
      "rotation": 3
    },
    {
      "x": 3,
      "y": -24,
      "z": 3,
      "name": "Rock_Ice_Permafrost",
      "rotation": 3
    },
    {
      "x": 3,
      "y": -23,
      "z": 3,
      "name": "Rock_Ice_Permafrost",
      "rotation": 3
    },
    {
      "x": 3,
      "y": -22,
      "z": 3,
      "name": "Rock_Ice_Permafrost",
      "rotation": 3
    },
    {
      "x": 3,
      "y": -21,
      "z": 3,
      "name": "Rock_Ice_Permafrost",
      "rotation": 3
    },
    {
      "x": 3,
      "y": -20,
      "z": 3,
      "name": "Rock_Ice_Permafrost",
      "rotation": 3
    },
    {
      "x": 3,
      "y": -19,
      "z": 3,
      "name": "Rock_Ice_Permafrost",
      "rotation": 3
    },
    {
      "x": 3,
      "y": -18,
      "z": 3,
      "name": "Rock_Ice_Permafrost",
      "rotation": 3
    },
    {
      "x": 3,
      "y": -17,
      "z": 3,
      "name": "Rock_Ice_Permafrost",
      "rotation": 3
    },
    {
      "x": 3,
      "y": -16,
      "z": 3,
      "name": "Rock_Ice_Permafrost",
      "rotation": 3
    },
    {
      "x": 3,
      "y": -15,
      "z": 3,
      "name": "Rock_Ice",
      "rotation": 3
    },
    {
      "x": 3,
      "y": -14,
      "z": 3,
      "name": "Rock_Ice",
      "rotation": 3
    },
    {
      "x": 3,
      "y": -13,
      "z": 3,
      "name": "Rock_Ice",
      "rotation": 3
    },
    {
      "x": 3,
      "y": -12,
      "z": 3,
      "name": "Soil_Snow",
      "rotation": 3
    },
    {
      "x": 3,
      "y": -26,
      "z": 4,
      "name": "Rock_Ice_Permafrost",
      "rotation": 3
    },
    {
      "x": 3,
      "y": -25,
      "z": 4,
      "name": "Rock_Ice_Permafrost",
      "rotation": 3
    },
    {
      "x": 3,
      "y": -24,
      "z": 4,
      "name": "Rock_Ice_Permafrost",
      "rotation": 3
    },
    {
      "x": 3,
      "y": -23,
      "z": 4,
      "name": "Rock_Ice_Permafrost",
      "rotation": 3
    },
    {
      "x": 3,
      "y": -22,
      "z": 4,
      "name": "Rock_Ice",
      "rotation": 3
    },
    {
      "x": 3,
      "y": -21,
      "z": 4,
      "name": "Rock_Ice",
      "rotation": 3
    },
    {
      "x": 3,
      "y": -20,
      "z": 4,
      "name": "Rock_Ice",
      "rotation": 3
    },
    {
      "x": 3,
      "y": -19,
      "z": 4,
      "name": "Rock_Ice_Permafrost",
      "rotation": 3
    },
    {
      "x": 3,
      "y": -18,
      "z": 4,
      "name": "Soil_Snow",
      "rotation": 3
    },
    {
      "x": 3,
      "y": -23,
      "z": 5,
      "name": "Rock_Ice",
      "rotation": 3
    },
    {
      "x": 3,
      "y": -22,
      "z": 5,
      "name": "Rock_Ice",
      "rotation": 3
    },
    {
      "x": 3,
      "y": -21,
      "z": 5,
      "name": "Rock_Ice",
      "rotation": 3
    },
    {
      "x": 3,
      "y": -20,
      "z": 5,
      "name": "Soil_Snow",
      "rotation": 3
    },
    {
      "x": 3,
      "y": -19,
      "z": 5,
      "name": "Soil_Snow",
      "rotation": 3
    },
    {
      "x": 4,
      "y": -21,
      "z": -6,
      "name": "Rock_Ice",
      "rotation": 3
    },
    {
      "x": 4,
      "y": -20,
      "z": -6,
      "name": "Soil_Snow",
      "rotation": 3
    },
    {
      "x": 4,
      "y": -36,
      "z": -5,
      "name": "Rock_Ice",
      "rotation": 3
    },
    {
      "x": 4,
      "y": -35,
      "z": -5,
      "name": "Rock_Ice",
      "rotation": 3
    },
    {
      "x": 4,
      "y": -34,
      "z": -5,
      "name": "Rock_Ice",
      "rotation": 3
    },
    {
      "x": 4,
      "y": -27,
      "z": -5,
      "name": "Rock_Ice",
      "rotation": 3
    },
    {
      "x": 4,
      "y": -26,
      "z": -5,
      "name": "Rock_Ice",
      "rotation": 3
    },
    {
      "x": 4,
      "y": -25,
      "z": -5,
      "name": "Rock_Ice_Permafrost",
      "rotation": 3
    },
    {
      "x": 4,
      "y": -24,
      "z": -5,
      "name": "Rock_Ice_Permafrost",
      "rotation": 3
    },
    {
      "x": 4,
      "y": -23,
      "z": -5,
      "name": "Rock_Ice_Permafrost",
      "rotation": 3
    },
    {
      "x": 4,
      "y": -22,
      "z": -5,
      "name": "Rock_Ice_Permafrost",
      "rotation": 3
    },
    {
      "x": 4,
      "y": -21,
      "z": -5,
      "name": "Rock_Ice_Permafrost",
      "rotation": 3
    },
    {
      "x": 4,
      "y": -20,
      "z": -5,
      "name": "Rock_Ice_Permafrost",
      "rotation": 3
    },
    {
      "x": 4,
      "y": -19,
      "z": -5,
      "name": "Soil_Snow",
      "rotation": 3
    },
    {
      "x": 4,
      "y": -17,
      "z": -5,
      "name": "Soil_Snow",
      "rotation": 3
    },
    {
      "x": 4,
      "y": -40,
      "z": -4,
      "name": "Rock_Ice_Permafrost",
      "rotation": 3
    },
    {
      "x": 4,
      "y": -39,
      "z": -4,
      "name": "Rock_Ice",
      "rotation": 3
    },
    {
      "x": 4,
      "y": -38,
      "z": -4,
      "name": "Rock_Ice",
      "rotation": 3
    },
    {
      "x": 4,
      "y": -37,
      "z": -4,
      "name": "Rock_Ice",
      "rotation": 3
    },
    {
      "x": 4,
      "y": -36,
      "z": -4,
      "name": "Rock_Ice",
      "rotation": 3
    },
    {
      "x": 4,
      "y": -35,
      "z": -4,
      "name": "Rock_Ice",
      "rotation": 3
    },
    {
      "x": 4,
      "y": -34,
      "z": -4,
      "name": "Rock_Ice",
      "rotation": 3
    },
    {
      "x": 4,
      "y": -33,
      "z": -4,
      "name": "Rock_Ice",
      "rotation": 3
    },
    {
      "x": 4,
      "y": -32,
      "z": -4,
      "name": "Rock_Ice_Permafrost",
      "rotation": 3
    },
    {
      "x": 4,
      "y": -31,
      "z": -4,
      "name": "Rock_Ice_Permafrost",
      "rotation": 3
    },
    {
      "x": 4,
      "y": -30,
      "z": -4,
      "name": "Rock_Ice_Permafrost",
      "rotation": 3
    },
    {
      "x": 4,
      "y": -29,
      "z": -4,
      "name": "Rock_Ice",
      "rotation": 3
    },
    {
      "x": 4,
      "y": -28,
      "z": -4,
      "name": "Rock_Ice",
      "rotation": 3
    },
    {
      "x": 4,
      "y": -27,
      "z": -4,
      "name": "Rock_Ice",
      "rotation": 3
    },
    {
      "x": 4,
      "y": -26,
      "z": -4,
      "name": "Rock_Ice",
      "rotation": 3
    },
    {
      "x": 4,
      "y": -25,
      "z": -4,
      "name": "Rock_Ice",
      "rotation": 3
    },
    {
      "x": 4,
      "y": -24,
      "z": -4,
      "name": "Rock_Ice_Permafrost",
      "rotation": 3
    },
    {
      "x": 4,
      "y": -23,
      "z": -4,
      "name": "Rock_Ice_Permafrost",
      "rotation": 3
    },
    {
      "x": 4,
      "y": -22,
      "z": -4,
      "name": "Rock_Ice_Permafrost",
      "rotation": 3
    },
    {
      "x": 4,
      "y": -21,
      "z": -4,
      "name": "Rock_Ice_Permafrost",
      "rotation": 3
    },
    {
      "x": 4,
      "y": -20,
      "z": -4,
      "name": "Rock_Ice",
      "rotation": 3
    },
    {
      "x": 4,
      "y": -19,
      "z": -4,
      "name": "Rock_Ice",
      "rotation": 3
    },
    {
      "x": 4,
      "y": -18,
      "z": -4,
      "name": "Rock_Ice",
      "rotation": 3
    },
    {
      "x": 4,
      "y": -17,
      "z": -4,
      "name": "Rock_Ice",
      "rotation": 3
    },
    {
      "x": 4,
      "y": -16,
      "z": -4,
      "name": "Soil_Snow",
      "rotation": 3
    },
    {
      "x": 4,
      "y": -15,
      "z": -4,
      "name": "Soil_Snow",
      "rotation": 3
    },
    {
      "x": 4,
      "y": -8,
      "z": -4,
      "name": "Empty"
    },
    {
      "x": 4,
      "y": -7,
      "z": -4,
      "name": "Empty"
    },
    {
      "x": 4,
      "y": -42,
      "z": -3,
      "name": "Rock_Ice_Permafrost",
      "rotation": 3
    },
    {
      "x": 4,
      "y": -41,
      "z": -3,
      "name": "Rock_Ice_Permafrost",
      "rotation": 3
    },
    {
      "x": 4,
      "y": -40,
      "z": -3,
      "name": "Rock_Ice_Permafrost",
      "rotation": 3
    },
    {
      "x": 4,
      "y": -39,
      "z": -3,
      "name": "Rock_Ice",
      "rotation": 3
    },
    {
      "x": 4,
      "y": -38,
      "z": -3,
      "name": "Rock_Ice",
      "rotation": 3
    },
    {
      "x": 4,
      "y": -37,
      "z": -3,
      "name": "Rock_Ice",
      "rotation": 3
    },
    {
      "x": 4,
      "y": -36,
      "z": -3,
      "name": "Rock_Ice_Permafrost",
      "rotation": 3
    },
    {
      "x": 4,
      "y": -35,
      "z": -3,
      "name": "Rock_Ice_Permafrost",
      "rotation": 3
    },
    {
      "x": 4,
      "y": -34,
      "z": -3,
      "name": "Rock_Ice_Permafrost",
      "rotation": 3
    },
    {
      "x": 4,
      "y": -33,
      "z": -3,
      "name": "Rock_Ice_Permafrost",
      "rotation": 3
    },
    {
      "x": 4,
      "y": -32,
      "z": -3,
      "name": "Rock_Ice_Permafrost",
      "rotation": 3
    },
    {
      "x": 4,
      "y": -31,
      "z": -3,
      "name": "Rock_Ice",
      "rotation": 3
    },
    {
      "x": 4,
      "y": -30,
      "z": -3,
      "name": "Rock_Ice",
      "rotation": 3
    },
    {
      "x": 4,
      "y": -29,
      "z": -3,
      "name": "Rock_Ice_Permafrost",
      "rotation": 3
    },
    {
      "x": 4,
      "y": -28,
      "z": -3,
      "name": "Rock_Ice",
      "rotation": 3
    },
    {
      "x": 4,
      "y": -27,
      "z": -3,
      "name": "Rock_Ice",
      "rotation": 3
    },
    {
      "x": 4,
      "y": -26,
      "z": -3,
      "name": "Rock_Ice",
      "rotation": 3
    },
    {
      "x": 4,
      "y": -25,
      "z": -3,
      "name": "Rock_Ice_Permafrost",
      "rotation": 3
    },
    {
      "x": 4,
      "y": -24,
      "z": -3,
      "name": "Rock_Ice_Permafrost",
      "rotation": 3
    },
    {
      "x": 4,
      "y": -23,
      "z": -3,
      "name": "Rock_Ice_Permafrost",
      "rotation": 3
    },
    {
      "x": 4,
      "y": -22,
      "z": -3,
      "name": "Rock_Ice_Permafrost",
      "rotation": 3
    },
    {
      "x": 4,
      "y": -21,
      "z": -3,
      "name": "Rock_Ice_Permafrost",
      "rotation": 3
    },
    {
      "x": 4,
      "y": -20,
      "z": -3,
      "name": "Rock_Ice_Permafrost",
      "rotation": 3
    },
    {
      "x": 4,
      "y": -19,
      "z": -3,
      "name": "Rock_Ice",
      "rotation": 3
    },
    {
      "x": 4,
      "y": -18,
      "z": -3,
      "name": "Rock_Ice",
      "rotation": 3
    },
    {
      "x": 4,
      "y": -17,
      "z": -3,
      "name": "Rock_Ice",
      "rotation": 3
    },
    {
      "x": 4,
      "y": -16,
      "z": -3,
      "name": "Rock_Ice",
      "rotation": 3
    },
    {
      "x": 4,
      "y": -15,
      "z": -3,
      "name": "Soil_Snow",
      "rotation": 3
    },
    {
      "x": 4,
      "y": -9,
      "z": -3,
      "name": "Empty"
    },
    {
      "x": 4,
      "y": -8,
      "z": -3,
      "name": "Empty"
    },
    {
      "x": 4,
      "y": -7,
      "z": -3,
      "name": "Empty"
    },
    {
      "x": 4,
      "y": -6,
      "z": -3,
      "name": "Empty"
    },
    {
      "x": 4,
      "y": -3,
      "z": -3,
      "name": "Rock_Ice",
      "rotation": 3
    },
    {
      "x": 4,
      "y": -2,
      "z": -3,
      "name": "Soil_Snow",
      "rotation": 3
    },
    {
      "x": 4,
      "y": -44,
      "z": -2,
      "name": "Rock_Ice_Permafrost",
      "rotation": 3
    },
    {
      "x": 4,
      "y": -43,
      "z": -2,
      "name": "Rock_Ice_Permafrost",
      "rotation": 3
    },
    {
      "x": 4,
      "y": -42,
      "z": -2,
      "name": "Rock_Ice_Permafrost",
      "rotation": 3
    },
    {
      "x": 4,
      "y": -41,
      "z": -2,
      "name": "Rock_Ice_Permafrost",
      "rotation": 3
    },
    {
      "x": 4,
      "y": -40,
      "z": -2,
      "name": "Rock_Ice_Permafrost",
      "rotation": 3
    },
    {
      "x": 4,
      "y": -39,
      "z": -2,
      "name": "Rock_Ice_Permafrost",
      "rotation": 3
    },
    {
      "x": 4,
      "y": -38,
      "z": -2,
      "name": "Rock_Ice_Permafrost",
      "rotation": 3
    },
    {
      "x": 4,
      "y": -37,
      "z": -2,
      "name": "Rock_Ice_Permafrost",
      "rotation": 3
    },
    {
      "x": 4,
      "y": -36,
      "z": -2,
      "name": "Rock_Ice_Permafrost",
      "rotation": 3
    },
    {
      "x": 4,
      "y": -35,
      "z": -2,
      "name": "Rock_Ice_Permafrost",
      "rotation": 3
    },
    {
      "x": 4,
      "y": -34,
      "z": -2,
      "name": "Rock_Ice_Permafrost",
      "rotation": 3
    },
    {
      "x": 4,
      "y": -33,
      "z": -2,
      "name": "Rock_Ice_Permafrost",
      "rotation": 3
    },
    {
      "x": 4,
      "y": -32,
      "z": -2,
      "name": "Rock_Ice",
      "rotation": 3
    },
    {
      "x": 4,
      "y": -31,
      "z": -2,
      "name": "Rock_Ice",
      "rotation": 3
    },
    {
      "x": 4,
      "y": -30,
      "z": -2,
      "name": "Rock_Ice",
      "rotation": 3
    },
    {
      "x": 4,
      "y": -29,
      "z": -2,
      "name": "Rock_Ice",
      "rotation": 3
    },
    {
      "x": 4,
      "y": -28,
      "z": -2,
      "name": "Rock_Ice",
      "rotation": 3
    },
    {
      "x": 4,
      "y": -27,
      "z": -2,
      "name": "Rock_Ice",
      "rotation": 3
    },
    {
      "x": 4,
      "y": -26,
      "z": -2,
      "name": "Rock_Ice_Permafrost",
      "rotation": 3
    },
    {
      "x": 4,
      "y": -25,
      "z": -2,
      "name": "Rock_Ice_Permafrost",
      "rotation": 3
    },
    {
      "x": 4,
      "y": -24,
      "z": -2,
      "name": "Rock_Ice_Permafrost",
      "rotation": 3
    },
    {
      "x": 4,
      "y": -23,
      "z": -2,
      "name": "Rock_Ice_Permafrost",
      "rotation": 3
    },
    {
      "x": 4,
      "y": -22,
      "z": -2,
      "name": "Rock_Ice_Permafrost",
      "rotation": 3
    },
    {
      "x": 4,
      "y": -21,
      "z": -2,
      "name": "Rock_Ice_Permafrost",
      "rotation": 3
    },
    {
      "x": 4,
      "y": -20,
      "z": -2,
      "name": "Rock_Ice_Permafrost",
      "rotation": 3
    },
    {
      "x": 4,
      "y": -19,
      "z": -2,
      "name": "Rock_Ice_Permafrost",
      "rotation": 3
    },
    {
      "x": 4,
      "y": -18,
      "z": -2,
      "name": "Rock_Ice_Permafrost",
      "rotation": 3
    },
    {
      "x": 4,
      "y": -17,
      "z": -2,
      "name": "Rock_Ice",
      "rotation": 3
    },
    {
      "x": 4,
      "y": -16,
      "z": -2,
      "name": "Rock_Ice",
      "rotation": 3
    },
    {
      "x": 4,
      "y": -15,
      "z": -2,
      "name": "Rock_Ice",
      "rotation": 3
    },
    {
      "x": 4,
      "y": -14,
      "z": -2,
      "name": "Rock_Ice",
      "rotation": 3
    },
    {
      "x": 4,
      "y": -13,
      "z": -2,
      "name": "Soil_Snow",
      "rotation": 3
    },
    {
      "x": 4,
      "y": -9,
      "z": -2,
      "name": "Empty"
    },
    {
      "x": 4,
      "y": -8,
      "z": -2,
      "name": "Empty"
    },
    {
      "x": 4,
      "y": -7,
      "z": -2,
      "name": "Empty"
    },
    {
      "x": 4,
      "y": -5,
      "z": -2,
      "name": "Rock_Ice",
      "rotation": 3
    },
    {
      "x": 4,
      "y": -4,
      "z": -2,
      "name": "Rock_Ice",
      "rotation": 3
    },
    {
      "x": 4,
      "y": -3,
      "z": -2,
      "name": "Rock_Ice",
      "rotation": 3
    },
    {
      "x": 4,
      "y": -2,
      "z": -2,
      "name": "Soil_Snow",
      "rotation": 3
    },
    {
      "x": 4,
      "y": -45,
      "z": -1,
      "name": "Rock_Ice_Permafrost",
      "rotation": 3
    },
    {
      "x": 4,
      "y": -44,
      "z": -1,
      "name": "Rock_Ice_Permafrost",
      "rotation": 3
    },
    {
      "x": 4,
      "y": -43,
      "z": -1,
      "name": "Rock_Ice_Permafrost",
      "rotation": 3
    },
    {
      "x": 4,
      "y": -42,
      "z": -1,
      "name": "Rock_Ice_Permafrost",
      "rotation": 3
    },
    {
      "x": 4,
      "y": -41,
      "z": -1,
      "name": "Rock_Ice_Permafrost",
      "rotation": 3
    },
    {
      "x": 4,
      "y": -40,
      "z": -1,
      "name": "Rock_Ice_Permafrost",
      "rotation": 3
    },
    {
      "x": 4,
      "y": -39,
      "z": -1,
      "name": "Rock_Ice_Permafrost",
      "rotation": 3
    },
    {
      "x": 4,
      "y": -38,
      "z": -1,
      "name": "Rock_Ice_Permafrost",
      "rotation": 3
    },
    {
      "x": 4,
      "y": -37,
      "z": -1,
      "name": "Rock_Ice",
      "rotation": 3
    },
    {
      "x": 4,
      "y": -36,
      "z": -1,
      "name": "Rock_Ice",
      "rotation": 3
    },
    {
      "x": 4,
      "y": -35,
      "z": -1,
      "name": "Rock_Ice",
      "rotation": 3
    },
    {
      "x": 4,
      "y": -34,
      "z": -1,
      "name": "Rock_Ice",
      "rotation": 3
    },
    {
      "x": 4,
      "y": -33,
      "z": -1,
      "name": "Rock_Ice_Permafrost",
      "rotation": 3
    },
    {
      "x": 4,
      "y": -32,
      "z": -1,
      "name": "Rock_Ice_Permafrost",
      "rotation": 3
    },
    {
      "x": 4,
      "y": -27,
      "z": -1,
      "name": "Rock_Ice",
      "rotation": 3
    },
    {
      "x": 4,
      "y": -26,
      "z": -1,
      "name": "Rock_Ice",
      "rotation": 3
    },
    {
      "x": 4,
      "y": -25,
      "z": -1,
      "name": "Rock_Ice_Permafrost",
      "rotation": 3
    },
    {
      "x": 4,
      "y": -24,
      "z": -1,
      "name": "Rock_Ice_Permafrost",
      "rotation": 3
    },
    {
      "x": 4,
      "y": -23,
      "z": -1,
      "name": "Rock_Ice_Permafrost",
      "rotation": 3
    },
    {
      "x": 4,
      "y": -22,
      "z": -1,
      "name": "Rock_Ice_Permafrost",
      "rotation": 3
    },
    {
      "x": 4,
      "y": -21,
      "z": -1,
      "name": "Rock_Ice_Permafrost",
      "rotation": 3
    },
    {
      "x": 4,
      "y": -20,
      "z": -1,
      "name": "Rock_Ice_Permafrost",
      "rotation": 3
    },
    {
      "x": 4,
      "y": -19,
      "z": -1,
      "name": "Rock_Ice_Permafrost",
      "rotation": 3
    },
    {
      "x": 4,
      "y": -18,
      "z": -1,
      "name": "Rock_Ice_Permafrost",
      "rotation": 3
    },
    {
      "x": 4,
      "y": -17,
      "z": -1,
      "name": "Rock_Ice_Permafrost",
      "rotation": 3
    },
    {
      "x": 4,
      "y": -16,
      "z": -1,
      "name": "Rock_Ice",
      "rotation": 3
    },
    {
      "x": 4,
      "y": -15,
      "z": -1,
      "name": "Rock_Ice",
      "rotation": 3
    },
    {
      "x": 4,
      "y": -14,
      "z": -1,
      "name": "Rock_Ice",
      "rotation": 3
    },
    {
      "x": 4,
      "y": -13,
      "z": -1,
      "name": "Rock_Ice_Permafrost",
      "rotation": 3
    },
    {
      "x": 4,
      "y": -12,
      "z": -1,
      "name": "Rock_Ice_Permafrost",
      "rotation": 3
    },
    {
      "x": 4,
      "y": -11,
      "z": -1,
      "name": "Rock_Ice_Permafrost",
      "rotation": 3
    },
    {
      "x": 4,
      "y": -10,
      "z": -1,
      "name": "Rock_Ice_Permafrost",
      "rotation": 3
    },
    {
      "x": 4,
      "y": -9,
      "z": -1,
      "name": "Rock_Ice_Permafrost",
      "rotation": 3
    },
    {
      "x": 4,
      "y": -8,
      "z": -1,
      "name": "Rock_Ice_Permafrost",
      "rotation": 3
    },
    {
      "x": 4,
      "y": -7,
      "z": -1,
      "name": "Rock_Ice_Permafrost",
      "rotation": 3
    },
    {
      "x": 4,
      "y": -6,
      "z": -1,
      "name": "Rock_Ice_Permafrost",
      "rotation": 3
    },
    {
      "x": 4,
      "y": -5,
      "z": -1,
      "name": "Rock_Ice",
      "rotation": 3
    },
    {
      "x": 4,
      "y": -4,
      "z": -1,
      "name": "Rock_Ice",
      "rotation": 3
    },
    {
      "x": 4,
      "y": -3,
      "z": -1,
      "name": "Rock_Ice",
      "rotation": 3
    },
    {
      "x": 4,
      "y": -2,
      "z": -1,
      "name": "Soil_Snow",
      "rotation": 3
    },
    {
      "x": 4,
      "y": -45,
      "z": 0,
      "name": "Rock_Ice_Permafrost",
      "rotation": 3
    },
    {
      "x": 4,
      "y": -44,
      "z": 0,
      "name": "Rock_Ice_Permafrost",
      "rotation": 3
    },
    {
      "x": 4,
      "y": -43,
      "z": 0,
      "name": "Rock_Ice_Permafrost",
      "rotation": 3
    },
    {
      "x": 4,
      "y": -42,
      "z": 0,
      "name": "Rock_Ice_Permafrost",
      "rotation": 3
    },
    {
      "x": 4,
      "y": -41,
      "z": 0,
      "name": "Rock_Ice_Permafrost",
      "rotation": 3
    },
    {
      "x": 4,
      "y": -40,
      "z": 0,
      "name": "Rock_Ice_Permafrost",
      "rotation": 3
    },
    {
      "x": 4,
      "y": -39,
      "z": 0,
      "name": "Rock_Ice",
      "rotation": 3
    },
    {
      "x": 4,
      "y": -38,
      "z": 0,
      "name": "Rock_Ice",
      "rotation": 3
    },
    {
      "x": 4,
      "y": -37,
      "z": 0,
      "name": "Rock_Ice",
      "rotation": 3
    },
    {
      "x": 4,
      "y": -36,
      "z": 0,
      "name": "Rock_Ice",
      "rotation": 3
    },
    {
      "x": 4,
      "y": -35,
      "z": 0,
      "name": "Rock_Ice",
      "rotation": 3
    },
    {
      "x": 4,
      "y": -34,
      "z": 0,
      "name": "Soil_Snow",
      "rotation": 3
    },
    {
      "x": 4,
      "y": -26,
      "z": 0,
      "name": "Rock_Ice",
      "rotation": 3
    },
    {
      "x": 4,
      "y": -25,
      "z": 0,
      "name": "Rock_Ice_Permafrost",
      "rotation": 3
    },
    {
      "x": 4,
      "y": -24,
      "z": 0,
      "name": "Rock_Ice_Permafrost",
      "rotation": 3
    },
    {
      "x": 4,
      "y": -23,
      "z": 0,
      "name": "Rock_Ice_Permafrost",
      "rotation": 3
    },
    {
      "x": 4,
      "y": -22,
      "z": 0,
      "name": "Rock_Ice_Permafrost",
      "rotation": 3
    },
    {
      "x": 4,
      "y": -21,
      "z": 0,
      "name": "Rock_Ice_Permafrost",
      "rotation": 3
    },
    {
      "x": 4,
      "y": -20,
      "z": 0,
      "name": "Rock_Ice_Permafrost",
      "rotation": 3
    },
    {
      "x": 4,
      "y": -19,
      "z": 0,
      "name": "Rock_Ice_Permafrost",
      "rotation": 3
    },
    {
      "x": 4,
      "y": -18,
      "z": 0,
      "name": "Rock_Ice_Permafrost",
      "rotation": 3
    },
    {
      "x": 4,
      "y": -17,
      "z": 0,
      "name": "Rock_Ice_Permafrost",
      "rotation": 3
    },
    {
      "x": 4,
      "y": -16,
      "z": 0,
      "name": "Rock_Ice_Permafrost",
      "rotation": 3
    },
    {
      "x": 4,
      "y": -15,
      "z": 0,
      "name": "Rock_Ice_Permafrost",
      "rotation": 3
    },
    {
      "x": 4,
      "y": -14,
      "z": 0,
      "name": "Rock_Ice_Permafrost",
      "rotation": 3
    },
    {
      "x": 4,
      "y": -13,
      "z": 0,
      "name": "Rock_Ice_Permafrost",
      "rotation": 3
    },
    {
      "x": 4,
      "y": -12,
      "z": 0,
      "name": "Rock_Ice_Permafrost",
      "rotation": 3
    },
    {
      "x": 4,
      "y": -11,
      "z": 0,
      "name": "Rock_Ice_Permafrost",
      "rotation": 3
    },
    {
      "x": 4,
      "y": -10,
      "z": 0,
      "name": "Rock_Ice_Permafrost",
      "rotation": 3
    },
    {
      "x": 4,
      "y": -9,
      "z": 0,
      "name": "Rock_Ice_Permafrost",
      "rotation": 3
    },
    {
      "x": 4,
      "y": -8,
      "z": 0,
      "name": "Rock_Ice",
      "rotation": 3
    },
    {
      "x": 4,
      "y": -7,
      "z": 0,
      "name": "Rock_Ice",
      "rotation": 3
    },
    {
      "x": 4,
      "y": -6,
      "z": 0,
      "name": "Rock_Ice",
      "rotation": 3
    },
    {
      "x": 4,
      "y": -5,
      "z": 0,
      "name": "Rock_Ice",
      "rotation": 3
    },
    {
      "x": 4,
      "y": -4,
      "z": 0,
      "name": "Rock_Ice",
      "rotation": 3
    },
    {
      "x": 4,
      "y": -3,
      "z": 0,
      "name": "Rock_Ice",
      "rotation": 3
    },
    {
      "x": 4,
      "y": -2,
      "z": 0,
      "name": "Soil_Snow",
      "rotation": 3
    },
    {
      "x": 4,
      "y": -45,
      "z": 1,
      "name": "Rock_Ice_Permafrost",
      "rotation": 3
    },
    {
      "x": 4,
      "y": -44,
      "z": 1,
      "name": "Rock_Ice_Permafrost",
      "rotation": 3
    },
    {
      "x": 4,
      "y": -43,
      "z": 1,
      "name": "Rock_Ice",
      "rotation": 3
    },
    {
      "x": 4,
      "y": -42,
      "z": 1,
      "name": "Rock_Ice",
      "rotation": 3
    },
    {
      "x": 4,
      "y": -41,
      "z": 1,
      "name": "Rock_Ice",
      "rotation": 3
    },
    {
      "x": 4,
      "y": -40,
      "z": 1,
      "name": "Rock_Ice",
      "rotation": 3
    },
    {
      "x": 4,
      "y": -39,
      "z": 1,
      "name": "Rock_Ice",
      "rotation": 3
    },
    {
      "x": 4,
      "y": -38,
      "z": 1,
      "name": "Rock_Ice",
      "rotation": 3
    },
    {
      "x": 4,
      "y": -37,
      "z": 1,
      "name": "Rock_Ice",
      "rotation": 3
    },
    {
      "x": 4,
      "y": -36,
      "z": 1,
      "name": "Soil_Snow",
      "rotation": 3
    },
    {
      "x": 4,
      "y": -35,
      "z": 1,
      "name": "Soil_Snow",
      "rotation": 3
    },
    {
      "x": 4,
      "y": -26,
      "z": 1,
      "name": "Rock_Ice",
      "rotation": 3
    },
    {
      "x": 4,
      "y": -25,
      "z": 1,
      "name": "Rock_Ice_Permafrost",
      "rotation": 3
    },
    {
      "x": 4,
      "y": -24,
      "z": 1,
      "name": "Rock_Ice_Permafrost",
      "rotation": 3
    },
    {
      "x": 4,
      "y": -23,
      "z": 1,
      "name": "Rock_Ice_Permafrost",
      "rotation": 3
    },
    {
      "x": 4,
      "y": -22,
      "z": 1,
      "name": "Rock_Ice_Permafrost",
      "rotation": 3
    },
    {
      "x": 4,
      "y": -21,
      "z": 1,
      "name": "Rock_Ice_Permafrost",
      "rotation": 3
    },
    {
      "x": 4,
      "y": -20,
      "z": 1,
      "name": "Rock_Ice_Permafrost",
      "rotation": 3
    },
    {
      "x": 4,
      "y": -19,
      "z": 1,
      "name": "Rock_Ice_Permafrost",
      "rotation": 3
    },
    {
      "x": 4,
      "y": -18,
      "z": 1,
      "name": "Rock_Ice_Permafrost",
      "rotation": 3
    },
    {
      "x": 4,
      "y": -17,
      "z": 1,
      "name": "Rock_Ice_Permafrost",
      "rotation": 3
    },
    {
      "x": 4,
      "y": -16,
      "z": 1,
      "name": "Rock_Ice_Permafrost",
      "rotation": 3
    },
    {
      "x": 4,
      "y": -15,
      "z": 1,
      "name": "Rock_Ice_Permafrost",
      "rotation": 3
    },
    {
      "x": 4,
      "y": -14,
      "z": 1,
      "name": "Rock_Ice_Permafrost",
      "rotation": 3
    },
    {
      "x": 4,
      "y": -13,
      "z": 1,
      "name": "Rock_Ice_Permafrost",
      "rotation": 3
    },
    {
      "x": 4,
      "y": -12,
      "z": 1,
      "name": "Rock_Ice_Permafrost",
      "rotation": 3
    },
    {
      "x": 4,
      "y": -11,
      "z": 1,
      "name": "Soil_Snow",
      "rotation": 3
    },
    {
      "x": 4,
      "y": -8,
      "z": 1,
      "name": "Rock_Ice",
      "rotation": 3
    },
    {
      "x": 4,
      "y": -7,
      "z": 1,
      "name": "Rock_Ice",
      "rotation": 3
    },
    {
      "x": 4,
      "y": -6,
      "z": 1,
      "name": "Rock_Ice",
      "rotation": 3
    },
    {
      "x": 4,
      "y": -5,
      "z": 1,
      "name": "Soil_Snow",
      "rotation": 3
    },
    {
      "x": 4,
      "y": -3,
      "z": 1,
      "name": "Soil_Snow",
      "rotation": 3
    },
    {
      "x": 4,
      "y": -44,
      "z": 2,
      "name": "Rock_Ice",
      "rotation": 3
