{
  "version": 8,
  "blockIdVersion": 11,
  "anchorX": 0,
  "anchorY": 0,
  "anchorZ": 0,
  "blocks": [
    {
      "x": -2,
      "y": -1,
      "z": 0,
      "name": "Rock_Crystal_White_Block"
    },
    {
      "x": -2,
      "y": 0,
      "z": 0,
      "name": "Rock_Crystal_White_Block"
    },
    {
      "x": -2,
      "y": 1,
      "z": 0,
      "name": "Rock_Crystal_White_Medium"
    },
    {
      "x": -2,
      "y": -1,
      "z": 1,
      "name": "Rock_Crystal_White_Block"
    },
    {
      "x": -2,
      "y": 0,
      "z": 1,
      "name": "Rock_Crystal_White_Block"
    },
    {
      "x": -1,
      "y": -1,
      "z": -1,
      "name": "Rock_Crystal_White_Block"
    },
    {
      "x": -1,
      "y": 0,
      "z": -1,
      "name": "Rock_Crystal_White_Block"
    },
    {
      "x": -1,
      "y": 1,
      "z": -1,
      "name": "Rock_Crystal_White_Block"
    },
    {
      "x": -1,
      "y": 2,
      "z": -1,
      "name": "Rock_Crystal_White_Medium"
    },
    {
      "x": -1,
      "y": -1,
      "z": 0,
      "name": "Rock_Crystal_White_Block"
    },
    {
      "x": -1,
      "y": 0,
      "z": 0,
      "name": "Rock_Crystal_White_Block"
    },
    {
      "x": -1,
      "y": 1,
      "z": 0,
      "name": "Rock_Crystal_White_Block"
    },
    {
      "x": -1,
      "y": -1,
      "z": 1,
      "name": "Rock_Crystal_White_Block"
    },
    {
      "x": -1,
      "y": 0,
      "z": 1,
      "name": "Rock_Crystal_White_Block"
    },
    {
      "x": -1,
      "y": 1,
      "z": 1,
      "name": "Rock_Crystal_White_Medium"
    },
    {
      "x": -1,
      "y": -1,
      "z": 2,
      "name": "Rock_Crystal_White_Block"
    },
    {
      "x": -1,
      "y": 0,
      "z": 2,
      "name": "Rock_Crystal_White_Block"
    },
    {
      "x": 0,
      "y": 0,
      "z": -3,
      "name": "Rock_Crystal_White_Small",
      "rotation": 6
    },
    {
      "x": 0,
      "y": 0,
      "z": -2,
      "name": "Rock_Crystal_White_Block"
    },
    {
      "x": 0,
      "y": 1,
      "z": -2,
      "name": "Rock_Crystal_White_Block"
    },
    {
      "x": 0,
      "y": 2,
      "z": -2,
      "name": "Rock_Crystal_White_Medium"
    },
    {
      "x": 0,
      "y": -1,
      "z": -1,
      "name": "Rock_Crystal_White_Block"
    },
    {
      "x": 0,
      "y": 0,
      "z": -1,
      "name": "Rock_Crystal_White_Block"
    },
    {
      "x": 0,
      "y": 1,
      "z": -1,
      "name": "Rock_Crystal_White_Block"
    },
    {
      "x": 0,
      "y": 2,
      "z": -1,
      "name": "Rock_Crystal_White_Block"
    },
    {
      "x": 0,
      "y": 3,
      "z": -1,
      "name": "Rock_Crystal_White_Medium"
    },
    {
      "x": 0,
      "y": -1,
      "z": 0,
      "name": "Rock_Crystal_White_Block"
    },
    {
      "x": 0,
      "y": 0,
      "z": 0,
      "name": "Rock_Crystal_White_Block"
    },
    {
      "x": 0,
      "y": 1,
      "z": 0,
      "name": "Rock_Crystal_White_Block"
    },
    {
      "x": 0,
      "y": 2,
      "z": 0,
      "name": "Rock_Crystal_White_Block"
    },
    {
      "x": 0,
      "y": -1,
      "z": 1,
      "name": "Rock_Crystal_White_Block"
    },
    {
      "x": 0,
      "y": 0,
      "z": 1,
      "name": "Rock_Crystal_White_Block"
    },
    {
      "x": 0,
      "y": 1,
      "z": 1,
      "name": "Rock_Crystal_White_Block"
    },
    {
      "x": 0,
      "y": -1,
      "z": 2,
      "name": "Rock_Crystal_White_Block"
    },
    {
      "x": 0,
      "y": 0,
      "z": 2,
      "name": "Rock_Crystal_White_Block"
    },
    {
      "x": 0,
      "y": 1,
      "z": 2,
      "name": "Rock_Crystal_White_Medium"
    },
    {
      "x": 1,
      "y": 1,
      "z": -3,
      "name": "Rock_Crystal_White_Medium",
      "rotation": 6
    },
    {
      "x": 1,
      "y": 2,
      "z": -3,
      "name": "Rock_Crystal_White_Block"
    },
    {
      "x": 1,
      "y": 3,
      "z": -3,
      "name": "Rock_Crystal_White_Medium"
    },
    {
      "x": 1,
      "y": 0,
      "z": -2,
      "name": "Rock_Crystal_White_Block"
    },
    {
      "x": 1,
      "y": 1,
      "z": -2,
      "name": "Rock_Crystal_White_Block"
    },
    {
      "x": 1,
      "y": 2,
      "z": -2,
      "name": "Rock_Crystal_White_Block"
    },
    {
      "x": 1,
      "y": 3,
      "z": -2,
      "name": "Rock_Crystal_White_Block"
    },
    {
      "x": 1,
      "y": 4,
      "z": -2,
      "name": "Rock_Crystal_White_Small"
    },
    {
      "x": 1,
      "y": -1,
      "z": -1,
      "name": "Rock_Crystal_White_Block"
    },
    {
      "x": 1,
      "y": 0,
      "z": -1,
      "name": "Rock_Crystal_White_Block"
    },
    {
      "x": 1,
      "y": 1,
      "z": -1,
      "name": "Rock_Crystal_White_Block"
    },
    {
      "x": 1,
      "y": 2,
      "z": -1,
      "name": "Rock_Crystal_White_Block"
    },
    {
      "x": 1,
      "y": 3,
      "z": -1,
      "name": "Rock_Crystal_White_Block"
    },
    {
      "x": 1,
      "y": 4,
      "z": -1,
      "name": "Rock_Crystal_White_Small"
    },
    {
      "x": 1,
      "y": -1,
      "z": 0,
      "name": "Rock_Crystal_White_Block"
    },
    {
      "x": 1,
      "y": 0,
      "z": 0,
      "name": "Rock_Crystal_White_Block"
    },
    {
      "x": 1,
      "y": 1,
      "z": 0,
      "name": "Rock_Crystal_White_Block"
    },
    {
      "x": 1,
      "y": 2,
      "z": 0,
      "name": "Rock_Crystal_White_Block"
    },
    {
      "x": 1,
      "y": 3,
      "z": 0,
      "name": "Rock_Crystal_White_Medium"
    },
    {
      "x": 1,
      "y": -1,
      "z": 1,
      "name": "Rock_Crystal_White_Block"
    },
    {
      "x": 1,
      "y": 0,
      "z": 1,
      "name": "Rock_Crystal_White_Block"
    },
    {
      "x": 1,
      "y": 1,
      "z": 1,
      "name": "Rock_Crystal_White_Block"
    },
    {
      "x": 1,
      "y": 2,
      "z": 1,
      "name": "Rock_Crystal_White_Medium"
    },
    {
      "x": 2,
      "y": 2,
      "z": -4,
      "name": "Rock_Crystal_White_Small",
      "rotation": 6
    },
    {
      "x": 2,
      "y": 3,
      "z": -4,
      "name": "Rock_Crystal_White_Medium",
      "rotation": 6
    },
    {
      "x": 2,
      "y": 1,
      "z": -3,
      "name": "Rock_Crystal_White_Medium",
      "rotation": 8
    },
    {
      "x": 2,
      "y": 2,
      "z": -3,
      "name": "Rock_Crystal_White_Block"
    },
    {
      "x": 2,
      "y": 3,
      "z": -3,
      "name": "Rock_Crystal_White_Block"
    },
    {
      "x": 2,
      "y": 4,
      "z": -3,
      "name": "Rock_Crystal_White_Medium",
      "rotation": 7
    },
    {
      "x": 2,
      "y": 5,
      "z": -3,
      "name": "Rock_Crystal_White_Small",
      "rotation": 7
    },
    {
      "x": 2,
      "y": 0,
      "z": -2,
      "name": "Rock_Crystal_White_Medium",
      "rotation": 8
    },
    {
      "x": 2,
      "y": 1,
      "z": -2,
      "name": "Rock_Crystal_White_Block"
    },
    {
      "x": 2,
      "y": 2,
      "z": -2,
      "name": "Rock_Crystal_White_Block"
    },
    {
      "x": 2,
      "y": 3,
      "z": -2,
      "name": "Rock_Crystal_White_Block"
    },
    {
      "x": 2,
      "y": 4,
      "z": -2,
      "name": "Rock_Crystal_White_Block"
    },
    {
      "x": 2,
      "y": 5,
      "z": -2,
      "name": "Rock_Crystal_White_Small"
    },
    {
      "x": 2,
      "y": 0,
      "z": -1,
      "name": "Rock_Crystal_White_Block"
    },
    {
      "x": 2,
      "y": 1,
      "z": -1,
      "name": "Rock_Crystal_White_Block"
    },
    {
      "x": 2,
      "y": 2,
      "z": -1,
      "name": "Rock_Crystal_White_Block"
    },
    {
      "x": 2,
      "y": 3,
      "z": -1,
      "name": "Rock_Crystal_White_Block"
    },
    {
      "x": 2,
      "y": 4,
      "z": -1,
      "name": "Rock_Crystal_White_Small"
    },
    {
      "x": 2,
      "y": 0,
      "z": 0,
      "name": "Rock_Crystal_White_Block"
    },
    {
      "x": 2,
      "y": 1,
      "z": 0,
      "name": "Rock_Crystal_White_Block"
    },
    {
      "x": 2,
      "y": 2,
      "z": 0,
      "name": "Rock_Crystal_White_Medium"
    },
    {
      "x": 3,
      "y": 4,
      "z": -5,
      "name": "Rock_Crystal_White_Small",
      "rotation": 6
    },
    {
      "x": 3,
      "y": 3,
      "z": -4,
      "name": "Rock_Crystal_White_Small",
      "rotation": 6
    },
    {
      "x": 3,
      "y": 4,
      "z": -4,
      "name": "Rock_Crystal_White_Block"
    },
    {
      "x": 3,
      "y": 5,
      "z": -4,
      "name": "Rock_Crystal_White_Medium",
      "rotation": 7
    },
    {
      "x": 3,
      "y": 6,
      "z": -4,
      "name": "Rock_Crystal_White_Small",
      "rotation": 7
    },
    {
      "x": 3,
      "y": 2,
      "z": -3,
      "name": "Rock_Crystal_White_Medium",
      "rotation": 8
    },
    {
      "x": 3,
      "y": 3,
      "z": -3,
      "name": "Rock_Crystal_White_Block"
    },
    {
      "x": 3,
      "y": 4,
      "z": -3,
      "name": "Rock_Crystal_White_Block"
    },
    {
      "x": 3,
      "y": 5,
      "z": -3,
      "name": "Rock_Crystal_White_Block"
    },
    {
      "x": 3,
      "y": 6,
      "z": -3,
      "name": "Rock_Crystal_White_Small"
    },
    {
      "x": 3,
      "y": 1,
      "z": -2,
      "name": "Rock_Crystal_White_Medium",
      "rotation": 8
    },
    {
      "x": 3,
      "y": 2,
      "z": -2,
      "name": "Rock_Crystal_White_Block"
    },
    {
      "x": 3,
      "y": 3,
      "z": -2,
      "name": "Rock_Crystal_White_Block"
    },
    {
      "x": 3,
      "y": 4,
      "z": -2,
      "name": "Rock_Crystal_White_Medium",
      "rotation": 4
    },
    {
      "x": 3,
      "y": 5,
      "z": -2,
      "name": "Rock_Crystal_White_Small",
      "rotation": 4
    },
    {
      "x": 3,
      "y": 1,
      "z": -1,
      "name": "Rock_Crystal_White_Medium",
      "rotation": 5
    },
    {
      "x": 3,
      "y": 2,
      "z": -1,
      "name": "Rock_Crystal_White_Block"
    },
    {
      "x": 3,
      "y": 3,
      "z": -1,
      "name": "Rock_Crystal_White_Medium"
    },
    {
      "x": 3,
      "y": 0,
      "z": 0,
      "name": "Rock_Crystal_White_Small",
      "rotation": 5
    },
    {
      "x": 4,
      "y": 5,
      "z": -5,
      "name": "Rock_Crystal_White_Small",
      "rotation": 6
    },
    {
      "x": 4,
      "y": 6,
      "z": -5,
      "name": "Rock_Crystal_White_Medium",
      "rotation": 6
    },
    {
      "x": 4,
      "y": 7,
      "z": -5,
      "name": "Rock_Crystal_White_Small",
      "rotation": 7
    },
    {
      "x": 4,
      "y": 4,
      "z": -4,
      "name": "Rock_Crystal_White_Medium",
      "rotation": 8
    },
    {
      "x": 4,
      "y": 5,
      "z": -4,
      "name": "Rock_Crystal_White_Block"
    },
    {
      "x": 4,
      "y": 6,
      "z": -4,
      "name": "Rock_Crystal_White_Block"
    },
    {
      "x": 4,
      "y": 7,
      "z": -4,
      "name": "Rock_Crystal_White_Small"
    },
    {
      "x": 4,
      "y": 3,
      "z": -3,
      "name": "Rock_Crystal_White_Small",
      "rotation": 5
    },
    {
      "x": 4,
      "y": 4,
      "z": -3,
      "name": "Rock_Crystal_White_Block"
    },
    {
      "x": 4,
      "y": 5,
      "z": -3,
      "name": "Rock_Crystal_White_Medium",
      "rotation": 4
    },
    {
      "x": 4,
      "y": 6,
      "z": -3,
      "name": "Rock_Crystal_White_Small",
      "rotation": 4
    },
    {
      "x": 4,
      "y": 2,
      "z": -2,
      "name": "Rock_Crystal_White_Small",
      "rotation": 5
    },
    {
      "x": 4,
      "y": 3,
      "z": -2,
      "name": "Rock_Crystal_White_Medium",
      "rotation": 5
    },
    {
      "x": 5,
      "y": 7,
      "z": -6,
      "name": "Rock_Crystal_White_Small",
      "rotation": 6
    },
    {
      "x": 5,
      "y": 6,
      "z": -5,
      "name": "Rock_Crystal_White_Medium",
      "rotation": 8
    },
    {
      "x": 5,
      "y": 7,
      "z": -5,
      "name": "Rock_Crystal_White_Block"
    },
    {
      "x": 5,
      "y": 8,
      "z": -5,
      "name": "Rock_Crystal_White_Small"
    },
    {
      "x": 5,
      "y": 5,
      "z": -4,
      "name": "Rock_Crystal_White_Small",
      "rotation": 5
    },
    {
      "x": 5,
      "y": 6,
      "z": -4,
      "name": "Rock_Crystal_White_Medium",
      "rotation": 5
    },
    {
      "x": 5,
      "y": 7,
      "z": -4,
      "name": "Rock_Crystal_White_Small",
      "rotation": 4
    },
    {
      "x": 5,
      "y": 4,
      "z": -3,
      "name": "Rock_Crystal_White_Small",
      "rotation": 5
    },
    {
      "x": 6,
      "y": 7,
      "z": -5,
      "name": "Rock_Crystal_White_Small",
      "rotation": 5
    }
  ]
}