{
  "version": 8,
  "blockIdVersion": 11,
  "anchorX": 0,
  "anchorY": 1,
  "anchorZ": 0,
  "blocks": [
    {
      "x": -17,
      "y": 20,
      "z": 5,
      "name": "Plant_Leaves_Snow",
      "rotation": 1
    },
    {
      "x": -16,
      "y": 19,
      "z": 4,
      "name": "Plant_Leaves_Snow",
      "rotation": 1
    },
    {
      "x": -16,
      "y": 19,
      "z": 5,
      "name": "Plant_Leaves_Snow",
      "rotation": 1
    },
    {
      "x": -15,
      "y": 18,
      "z": 3,
      "name": "Plant_Leaves_Snow",
      "rotation": 1
    },
    {
      "x": -15,
      "y": 18,
      "z": 4,
      "name": "Plant_Leaves_Snow",
      "rotation": 1
    },
    {
      "x": -15,
      "y": 19,
      "z": 5,
      "name": "Plant_Leaves_Snow",
      "rotation": 1
    },
    {
      "x": -14,
      "y": 18,
      "z": 3,
      "name": "Plant_Leaves_Snow",
      "rotation": 1
    },
    {
      "x": -14,
      "y": 18,
      "z": 4,
      "name": "Plant_Leaves_Snow",
      "rotation": 1
    },
    {
      "x": -14,
      "y": 18,
      "z": 5,
      "name": "Plant_Leaves_Snow",
      "rotation": 1
    },
    {
      "x": -13,
      "y": 17,
      "z": 2,
      "name": "Plant_Leaves_Snow",
      "rotation": 1
    },
    {
      "x": -13,
      "y": 17,
      "z": 3,
      "name": "Plant_Leaves_Snow",
      "rotation": 1
    },
    {
      "x": -13,
      "y": 17,
      "z": 4,
      "name": "Plant_Leaves_Snow",
      "rotation": 1
    },
    {
      "x": -13,
      "y": 18,
      "z": 5,
      "name": "Plant_Leaves_Snow",
      "rotation": 1
    },
    {
      "x": -12,
      "y": 12,
      "z": -7,
      "name": "Plant_Leaves_Snow",
      "rotation": 1
    },
    {
      "x": -12,
      "y": 13,
      "z": -7,
      "name": "Plant_Leaves_Snow",
      "rotation": 2
    },
    {
      "x": -12,
      "y": 13,
      "z": -6,
      "name": "Plant_Leaves_Snow"
    },
    {
      "x": -12,
      "y": 14,
      "z": -6,
      "name": "Plant_Leaves_Snow",
      "rotation": 2
    },
    {
      "x": -12,
      "y": 14,
      "z": -5,
      "name": "Plant_Leaves_Snow"
    },
    {
      "x": -12,
      "y": 17,
      "z": 2,
      "name": "Plant_Leaves_Snow",
      "rotation": 1
    },
    {
      "x": -12,
      "y": 17,
      "z": 3,
      "name": "Plant_Leaves_Snow",
      "rotation": 1
    },
    {
      "x": -12,
      "y": 17,
      "z": 4,
      "name": "Plant_Leaves_Snow",
      "rotation": 1
    },
    {
      "x": -12,
      "y": 17,
      "z": 5,
      "name": "Plant_Leaves_Snow",
      "rotation": 1
    },
    {
      "x": -11,
      "y": 14,
      "z": -8,
      "name": "Plant_Leaves_Snow",
      "rotation": 1
    },
    {
      "x": -11,
      "y": 14,
      "z": -7,
      "name": "Plant_Leaves_Snow",
      "rotation": 2
    },
    {
      "x": -11,
      "y": 15,
      "z": -7,
      "name": "Plant_Leaves_Snow",
      "rotation": 2
    },
    {
      "x": -11,
      "y": 15,
      "z": -6,
      "name": "Plant_Leaves_Snow",
      "rotation": 2
    },
    {
      "x": -11,
      "y": 16,
      "z": -6,
      "name": "Plant_Leaves_Snow",
      "rotation": 2
    },
    {
      "x": -11,
      "y": 15,
      "z": -5,
      "name": "Plant_Leaves_Snow",
      "rotation": 2
    },
    {
      "x": -11,
      "y": 16,
      "z": -5,
      "name": "Plant_Leaves_Snow",
      "rotation": 2
    },
    {
      "x": -11,
      "y": 15,
      "z": -4,
      "name": "Plant_Leaves_Snow",
      "rotation": 2
    },
    {
      "x": -11,
      "y": 17,
      "z": 1,
      "name": "Plant_Leaves_Snow",
      "rotation": 1
    },
    {
      "x": -11,
      "y": 17,
      "z": 2,
      "name": "Plant_Leaves_Snow",
      "rotation": 3
    },
    {
      "x": -11,
      "y": 18,
      "z": 2,
      "name": "Plant_Leaves_Snow",
      "rotation": 1
    },
    {
      "x": -11,
      "y": 17,
      "z": 3,
      "name": "Wood_Camphor_Trunk_Full",
      "rotation": 1
    },
    {
      "x": -11,
      "y": 18,
      "z": 3,
      "name": "Plant_Leaves_Snow",
      "rotation": 1
    },
    {
      "x": -11,
      "y": 17,
      "z": 4,
      "name": "Plant_Leaves_Snow",
      "rotation": 3
    },
    {
      "x": -11,
      "y": 18,
      "z": 4,
      "name": "Plant_Leaves_Snow",
      "rotation": 1
    },
    {
      "x": -11,
      "y": 17,
      "z": 5,
      "name": "Plant_Leaves_Snow",
      "rotation": 1
    },
    {
      "x": -10,
      "y": 15,
      "z": -8,
      "name": "Plant_Leaves_Snow",
      "rotation": 2
    },
    {
      "x": -10,
      "y": 16,
      "z": -7,
      "name": "Plant_Leaves_Snow",
      "rotation": 2
    },
    {
      "x": -10,
      "y": 16,
      "z": -6,
      "name": "Plant_Leaves_Snow",
      "rotation": 2
    },
    {
      "x": -10,
      "y": 17,
      "z": -6,
      "name": "Plant_Leaves_Snow",
      "rotation": 2
    },
    {
      "x": -10,
      "y": 16,
      "z": -5,
      "name": "Wood_Camphor_Trunk_Full",
      "rotation": 1
    },
    {
      "x": -10,
      "y": 17,
      "z": -5,
      "name": "Plant_Leaves_Snow",
      "rotation": 2
    },
    {
      "x": -10,
      "y": 16,
      "z": -4,
      "name": "Plant_Leaves_Snow",
      "rotation": 2
    },
    {
      "x": -10,
      "y": 17,
      "z": -4,
      "name": "Plant_Leaves_Snow",
      "rotation": 2
    },
    {
      "x": -10,
      "y": 16,
      "z": -3,
      "name": "Plant_Leaves_Snow",
      "rotation": 2
    },
    {
      "x": -10,
      "y": 18,
      "z": 1,
      "name": "Plant_Leaves_Snow",
      "rotation": 1
    },
    {
      "x": -10,
      "y": 17,
      "z": 2,
      "name": "Plant_Leaves_Snow",
      "rotation": 3
    },
    {
      "x": -10,
      "y": 18,
      "z": 2,
      "name": "Plant_Leaves_Snow",
      "rotation": 3
    },
    {
      "x": -10,
      "y": 17,
      "z": 3,
      "name": "Wood_Camphor_Trunk_Full",
      "rotation": 1
    },
    {
      "x": -10,
      "y": 18,
      "z": 3,
      "name": "Plant_Leaves_Snow",
      "rotation": 3
    },
    {
      "x": -10,
      "y": 17,
      "z": 4,
      "name": "Plant_Leaves_Snow",
      "rotation": 3
    },
    {
      "x": -10,
      "y": 18,
      "z": 4,
      "name": "Plant_Leaves_Snow",
      "rotation": 3
    },
    {
      "x": -10,
      "y": 18,
      "z": 5,
      "name": "Plant_Leaves_Snow",
      "rotation": 1
    },
    {
      "x": -9,
      "y": 16,
      "z": -8,
      "name": "Plant_Leaves_Snow"
    },
    {
      "x": -9,
      "y": 16,
      "z": -7,
      "name": "Plant_Leaves_Snow",
      "rotation": 2
    },
    {
      "x": -9,
      "y": 17,
      "z": -6,
      "name": "Plant_Leaves_Snow",
      "rotation": 2
    },
    {
      "x": -9,
      "y": 17,
      "z": -5,
      "name": "Wood_Camphor_Trunk_Full",
      "rotation": 1
    },
    {
      "x": -9,
      "y": 18,
      "z": -5,
      "name": "Plant_Leaves_Snow",
      "rotation": 2
    },
    {
      "x": -9,
      "y": 17,
      "z": -4,
      "name": "Plant_Leaves_Snow",
      "rotation": 2
    },
    {
      "x": -9,
      "y": 18,
      "z": -4,
      "name": "Plant_Leaves_Snow",
      "rotation": 2
    },
    {
      "x": -9,
      "y": 17,
      "z": -3,
      "name": "Plant_Leaves_Snow",
      "rotation": 2
    },
    {
      "x": -9,
      "y": 18,
      "z": -3,
      "name": "Plant_Leaves_Snow",
      "rotation": 2
    },
    {
      "x": -9,
      "y": 17,
      "z": -2,
      "name": "Plant_Leaves_Snow",
      "rotation": 2
    },
    {
      "x": -9,
      "y": 18,
      "z": 0,
      "name": "Plant_Leaves_Snow",
      "rotation": 3
    },
    {
      "x": -9,
      "y": 18,
      "z": 1,
      "name": "Plant_Leaves_Snow",
      "rotation": 3
    },
    {
      "x": -9,
      "y": 19,
      "z": 1,
      "name": "Plant_Leaves_Snow",
      "rotation": 3
    },
    {
      "x": -9,
      "y": 18,
      "z": 2,
      "name": "Plant_Leaves_Snow",
      "rotation": 3
    },
    {
      "x": -9,
      "y": 19,
      "z": 2,
      "name": "Plant_Leaves_Snow",
      "rotation": 3
    },
    {
      "x": -9,
      "y": 18,
      "z": 3,
      "name": "Wood_Camphor_Trunk_Full",
      "rotation": 1
    },
    {
      "x": -9,
      "y": 19,
      "z": 3,
      "name": "Plant_Leaves_Snow",
      "rotation": 3
    },
    {
      "x": -9,
      "y": 18,
      "z": 4,
      "name": "Plant_Leaves_Snow",
      "rotation": 3
    },
    {
      "x": -9,
      "y": 18,
      "z": 5,
      "name": "Plant_Leaves_Snow",
      "rotation": 1
    },
    {
      "x": -8,
      "y": 17,
      "z": -7,
      "name": "Plant_Leaves_Snow",
      "rotation": 2
    },
    {
      "x": -8,
      "y": 17,
      "z": -6,
      "name": "Plant_Leaves_Snow",
      "rotation": 2
    },
    {
      "x": -8,
      "y": 18,
      "z": -6,
      "name": "Plant_Leaves_Snow",
      "rotation": 2
    },
    {
      "x": -8,
      "y": 17,
      "z": -5,
      "name": "Wood_Camphor_Trunk_Full",
      "rotation": 1
    },
    {
      "x": -8,
      "y": 18,
      "z": -5,
      "name": "Plant_Leaves_Snow",
      "rotation": 2
    },
    {
      "x": -8,
      "y": 17,
      "z": -4,
      "name": "Wood_Camphor_Trunk_Full",
      "rotation": 1
    },
    {
      "x": -8,
      "y": 18,
      "z": -4,
      "name": "Plant_Leaves_Snow",
      "rotation": 2
    },
    {
      "x": -8,
      "y": 19,
      "z": -4,
      "name": "Plant_Leaves_Snow",
      "rotation": 2
    },
    {
      "x": -8,
      "y": 18,
      "z": -3,
      "name": "Plant_Leaves_Snow",
      "rotation": 2
    },
    {
      "x": -8,
      "y": 19,
      "z": -3,
      "name": "Plant_Leaves_Snow",
      "rotation": 2
    },
    {
      "x": -8,
      "y": 18,
      "z": -2,
      "name": "Plant_Leaves_Snow",
      "rotation": 2
    },
    {
      "x": -8,
      "y": 18,
      "z": -1,
      "name": "Plant_Leaves_Snow",
      "rotation": 2
    },
    {
      "x": -8,
      "y": 25,
      "z": -1,
      "name": "Plant_Leaves_Petrified"
    },
    {
      "x": -8,
      "y": 26,
      "z": -1,
      "name": "Plant_Leaves_Petrified"
    },
    {
      "x": -8,
      "y": 19,
      "z": 0,
      "name": "Plant_Leaves_Snow",
      "rotation": 3
    },
    {
      "x": -8,
      "y": 25,
      "z": 0,
      "name": "Wood_Crystal_Trunk_Full",
      "rotation": 1
    },
    {
      "x": -8,
      "y": 26,
      "z": 0,
      "name": "Wood_Crystal_Trunk_Full",
      "rotation": 1
    },
    {
      "x": -8,
      "y": 27,
      "z": 0,
      "name": "Plant_Leaves_Petrified",
      "rotation": 1
    },
    {
      "x": -8,
      "y": 28,
      "z": 0,
      "name": "Plant_Leaves_Petrified",
      "rotation": 1
    },
    {
      "x": -8,
      "y": 18,
      "z": 1,
      "name": "Plant_Leaves_Snow",
      "rotation": 3
    },
    {
      "x": -8,
      "y": 19,
      "z": 1,
      "name": "Plant_Leaves_Snow",
      "rotation": 3
    },
    {
      "x": -8,
      "y": 25,
      "z": 1,
      "name": "Plant_Leaves_Petrified",
      "rotation": 1
    },
    {
      "x": -8,
      "y": 26,
      "z": 1,
      "name": "Plant_Leaves_Petrified",
      "rotation": 1
    },
    {
      "x": -8,
      "y": 18,
      "z": 2,
      "name": "Wood_Camphor_Trunk_Full",
      "rotation": 1
    },
    {
      "x": -8,
      "y": 19,
      "z": 2,
      "name": "Plant_Leaves_Snow",
      "rotation": 3
    },
    {
      "x": -8,
      "y": 18,
      "z": 3,
      "name": "Plant_Leaves_Snow",
      "rotation": 1
    },
    {
      "x": -8,
      "y": 19,
      "z": 3,
      "name": "Plant_Leaves_Snow",
      "rotation": 3
    },
    {
      "x": -8,
      "y": 18,
      "z": 4,
      "name": "Plant_Leaves_Snow",
      "rotation": 3
    },
    {
      "x": -8,
      "y": 19,
      "z": 4,
      "name": "Plant_Leaves_Snow",
      "rotation": 3
    },
    {
      "x": -8,
      "y": 19,
      "z": 5,
      "name": "Plant_Leaves_Snow",
      "rotation": 1
    },
    {
      "x": -8,
      "y": 16,
      "z": 9,
      "name": "Plant_Leaves_Snow"
    },
    {
      "x": -8,
      "y": 15,
      "z": 10,
      "name": "Plant_Leaves_Snow",
      "rotation": 3
    },
    {
      "x": -8,
      "y": 14,
      "z": 11,
      "name": "Plant_Leaves_Snow",
      "rotation": 2
    },
    {
      "x": -7,
      "y": 17,
      "z": -7,
      "name": "Plant_Leaves_Snow",
      "rotation": 2
    },
    {
      "x": -7,
      "y": 17,
      "z": -6,
      "name": "Plant_Leaves_Snow",
      "rotation": 2
    },
    {
      "x": -7,
      "y": 18,
      "z": -6,
      "name": "Plant_Leaves_Snow",
      "rotation": 2
    },
    {
      "x": -7,
      "y": 18,
      "z": -5,
      "name": "Plant_Leaves_Snow",
      "rotation": 2
    },
    {
      "x": -7,
      "y": 19,
      "z": -5,
      "name": "Plant_Leaves_Snow",
      "rotation": 2
    },
    {
      "x": -7,
      "y": 18,
      "z": -4,
      "name": "Wood_Camphor_Trunk_Full",
      "rotation": 1
    },
    {
      "x": -7,
      "y": 19,
      "z": -4,
      "name": "Plant_Leaves_Snow",
      "rotation": 2
    },
    {
      "x": -7,
      "y": 18,
      "z": -3,
      "name": "Wood_Camphor_Trunk_Full",
      "rotation": 1
    },
    {
      "x": -7,
      "y": 19,
      "z": -3,
      "name": "Plant_Leaves_Snow",
      "rotation": 2
    },
    {
      "x": -7,
      "y": 20,
      "z": -3,
      "name": "Plant_Leaves_Snow",
      "rotation": 2
    },
    {
      "x": -7,
      "y": 18,
      "z": -2,
      "name": "Plant_Leaves_Snow",
      "rotation": 2
    },
    {
      "x": -7,
      "y": 19,
      "z": -2,
      "name": "Plant_Leaves_Snow",
      "rotation": 2
    },
    {
      "x": -7,
      "y": 19,
      "z": -1,
      "name": "Plant_Leaves_Snow",
      "rotation": 3
    },
    {
      "x": -7,
      "y": 24,
      "z": -1,
      "name": "Plant_Leaves_Petrified"
    },
    {
      "x": -7,
      "y": 19,
      "z": 0,
      "name": "Plant_Leaves_Snow",
      "rotation": 3
    },
    {
      "x": -7,
      "y": 24,
      "z": 0,
      "name": "Wood_Crystal_Trunk_Full",
      "rotation": 1
    },
    {
      "x": -7,
      "y": 25,
      "z": 0,
      "name": "Rock_Crystal_White_Large",
      "rotation": 1
    },
    {
      "x": -7,
      "y": 19,
      "z": 1,
      "name": "Plant_Leaves_Snow",
      "rotation": 3
    },
    {
      "x": -7,
      "y": 20,
      "z": 1,
      "name": "Plant_Leaves_Snow",
      "rotation": 3
    },
    {
      "x": -7,
      "y": 24,
      "z": 1,
      "name": "Plant_Leaves_Petrified",
      "rotation": 1
    },
    {
      "x": -7,
      "y": 19,
      "z": 2,
      "name": "Wood_Camphor_Trunk_Full",
      "rotation": 1
    },
    {
      "x": -7,
      "y": 20,
      "z": 2,
      "name": "Plant_Leaves_Snow",
      "rotation": 3
    },
    {
      "x": -7,
      "y": 19,
      "z": 3,
      "name": "Plant_Leaves_Snow",
      "rotation": 1
    },
    {
      "x": -7,
      "y": 20,
      "z": 3,
      "name": "Plant_Leaves_Snow",
      "rotation": 3
    },
    {
      "x": -7,
      "y": 19,
      "z": 4,
      "name": "Plant_Leaves_Snow",
      "rotation": 3
    },
    {
      "x": -7,
      "y": 19,
      "z": 5,
      "name": "Plant_Leaves_Snow",
      "rotation": 1
    },
    {
      "x": -7,
      "y": 17,
      "z": 7,
      "name": "Plant_Leaves_Snow",
      "rotation": 3
    },
    {
      "x": -7,
      "y": 17,
      "z": 8,
      "name": "Plant_Leaves_Snow",
      "rotation": 3
    },
    {
      "x": -7,
      "y": 16,
      "z": 9,
      "name": "Plant_Leaves_Snow",
      "rotation": 3
    },
    {
      "x": -7,
      "y": 16,
      "z": 10,
      "name": "Plant_Leaves_Snow",
      "rotation": 3
    },
    {
      "x": -7,
      "y": 14,
      "z": 11,
      "name": "Plant_Leaves_Snow",
      "rotation": 3
    },
    {
      "x": -7,
      "y": 15,
      "z": 11,
      "name": "Plant_Leaves_Snow",
      "rotation": 3
    },
    {
      "x": -7,
      "y": 12,
      "z": 12,
      "name": "Plant_Leaves_Snow",
      "rotation": 2
    },
    {
      "x": -7,
      "y": 13,
      "z": 12,
      "name": "Plant_Leaves_Snow",
      "rotation": 3
    },
    {
      "x": -6,
      "y": 18,
      "z": -6,
      "name": "Plant_Leaves_Snow",
      "rotation": 2
    },
    {
      "x": -6,
      "y": 18,
      "z": -5,
      "name": "Plant_Leaves_Snow",
      "rotation": 2
    },
    {
      "x": -6,
      "y": 19,
      "z": -5,
      "name": "Plant_Leaves_Snow",
      "rotation": 2
    },
    {
      "x": -6,
      "y": 18,
      "z": -4,
      "name": "Wood_Camphor_Trunk_Full",
      "rotation": 1
    },
    {
      "x": -6,
      "y": 19,
      "z": -4,
      "name": "Plant_Leaves_Snow",
      "rotation": 2
    },
    {
      "x": -6,
      "y": 20,
      "z": -4,
      "name": "Plant_Leaves_Snow",
      "rotation": 2
    },
    {
      "x": -6,
      "y": 25,
      "z": -4,
      "name": "Plant_Leaves_Petrified"
    },
    {
      "x": -6,
      "y": 26,
      "z": -4,
      "name": "Plant_Leaves_Petrified"
    },
    {
      "x": -6,
      "y": 19,
      "z": -3,
      "name": "Wood_Camphor_Trunk_Full",
      "rotation": 1
    },
    {
      "x": -6,
      "y": 20,
      "z": -3,
      "name": "Plant_Leaves_Snow",
      "rotation": 2
    },
    {
      "x": -6,
      "y": 19,
      "z": -2,
      "name": "Plant_Leaves_Snow",
      "rotation": 2
    },
    {
      "x": -6,
      "y": 20,
      "z": -2,
      "name": "Plant_Leaves_Snow",
      "rotation": 2
    },
    {
      "x": -6,
      "y": 19,
      "z": -1,
      "name": "Plant_Leaves_Snow",
      "rotation": 3
    },
    {
      "x": -6,
      "y": 23,
      "z": -1,
      "name": "Plant_Leaves_Petrified"
    },
    {
      "x": -6,
      "y": 19,
      "z": 0,
      "name": "Plant_Leaves_Snow",
      "rotation": 3
    },
    {
      "x": -6,
      "y": 20,
      "z": 0,
      "name": "Plant_Leaves_Snow",
      "rotation": 3
    },
    {
      "x": -6,
      "y": 23,
      "z": 0,
      "name": "Wood_Crystal_Trunk_Full",
      "rotation": 1
    },
    {
      "x": -6,
      "y": 19,
      "z": 1,
      "name": "Wood_Camphor_Trunk_Full",
      "rotation": 1
    },
    {
      "x": -6,
      "y": 20,
      "z": 1,
      "name": "Plant_Leaves_Snow",
      "rotation": 3
    },
    {
      "x": -6,
      "y": 23,
      "z": 1,
      "name": "Plant_Leaves_Petrified",
      "rotation": 1
    },
    {
      "x": -6,
      "y": 19,
      "z": 2,
      "name": "Wood_Camphor_Trunk_Full",
      "rotation": 1
    },
    {
      "x": -6,
      "y": 20,
      "z": 2,
      "name": "Plant_Leaves_Snow",
      "rotation": 3
    },
    {
      "x": -6,
      "y": 19,
      "z": 3,
      "name": "Plant_Leaves_Snow",
      "rotation": 3
    },
    {
      "x": -6,
      "y": 20,
      "z": 3,
      "name": "Plant_Leaves_Snow",
      "rotation": 3
    },
    {
      "x": -6,
      "y": 19,
      "z": 4,
      "name": "Plant_Leaves_Snow",
      "rotation": 1
    },
    {
      "x": -6,
      "y": 25,
      "z": 4,
      "name": "Plant_Leaves_Petrified",
      "rotation": 1
    },
    {
      "x": -6,
      "y": 26,
      "z": 4,
      "name": "Plant_Leaves_Petrified",
      "rotation": 1
    },
    {
      "x": -6,
      "y": 19,
      "z": 5,
      "name": "Plant_Leaves_Snow"
    },
    {
      "x": -6,
      "y": 18,
      "z": 6,
      "name": "Plant_Leaves_Snow",
      "rotation": 3
    },
    {
      "x": -6,
      "y": 17,
      "z": 7,
      "name": "Plant_Leaves_Snow",
      "rotation": 3
    },
    {
      "x": -6,
      "y": 18,
      "z": 7,
      "name": "Plant_Leaves_Snow",
      "rotation": 3
    },
    {
      "x": -6,
      "y": 17,
      "z": 8,
      "name": "Plant_Leaves_Snow",
      "rotation": 3
    },
    {
      "x": -6,
      "y": 18,
      "z": 8,
      "name": "Plant_Leaves_Snow",
      "rotation": 3
    },
    {
      "x": -6,
      "y": 17,
      "z": 9,
      "name": "Plant_Leaves_Snow",
      "rotation": 3
    },
    {
      "x": -6,
      "y": 16,
      "z": 10,
      "name": "Plant_Leaves_Snow",
      "rotation": 3
    },
    {
      "x": -6,
      "y": 17,
      "z": 10,
      "name": "Plant_Leaves_Snow",
      "rotation": 3
    },
    {
      "x": -6,
      "y": 15,
      "z": 11,
      "name": "Plant_Leaves_Snow",
      "rotation": 3
    },
    {
      "x": -6,
      "y": 16,
      "z": 11,
      "name": "Plant_Leaves_Snow",
      "rotation": 3
    },
    {
      "x": -6,
      "y": 13,
      "z": 12,
      "name": "Plant_Leaves_Snow"
    },
    {
      "x": -6,
      "y": 14,
      "z": 12,
      "name": "Plant_Leaves_Snow",
      "rotation": 3
    },
    {
      "x": -5,
      "y": 20,
      "z": -17,
      "name": "Plant_Leaves_Snow"
    },
    {
      "x": -5,
      "y": 19,
      "z": -16,
      "name": "Plant_Leaves_Snow"
    },
    {
      "x": -5,
      "y": 19,
      "z": -15,
      "name": "Plant_Leaves_Snow"
    },
    {
      "x": -5,
      "y": 18,
      "z": -14,
      "name": "Plant_Leaves_Snow"
    },
    {
      "x": -5,
      "y": 18,
      "z": -13,
      "name": "Plant_Leaves_Snow"
    },
    {
      "x": -5,
      "y": 17,
      "z": -12,
      "name": "Plant_Leaves_Snow"
    },
    {
      "x": -5,
      "y": 17,
      "z": -11,
      "name": "Plant_Leaves_Snow"
    },
    {
      "x": -5,
      "y": 18,
      "z": -10,
      "name": "Plant_Leaves_Snow"
    },
    {
      "x": -5,
      "y": 18,
      "z": -9,
      "name": "Plant_Leaves_Snow"
    },
    {
      "x": -5,
      "y": 19,
      "z": -8,
      "name": "Plant_Leaves_Snow"
    },
    {
      "x": -5,
      "y": 19,
      "z": -7,
      "name": "Plant_Leaves_Snow"
    },
    {
      "x": -5,
      "y": 19,
      "z": -6,
      "name": "Plant_Leaves_Snow"
    },
    {
      "x": -5,
      "y": 18,
      "z": -5,
      "name": "Plant_Leaves_Snow",
      "rotation": 2
    },
    {
      "x": -5,
      "y": 19,
      "z": -5,
      "name": "Plant_Leaves_Snow",
      "rotation": 2
    },
    {
      "x": -5,
      "y": 25,
      "z": -5,
      "name": "Wood_Crystal_Trunk_Full"
    },
    {
      "x": -5,
      "y": 26,
      "z": -5,
      "name": "Wood_Crystal_Trunk_Full"
    },
    {
      "x": -5,
      "y": 27,
      "z": -5,
      "name": "Plant_Leaves_Petrified"
    },
    {
      "x": -5,
      "y": 28,
      "z": -5,
      "name": "Plant_Leaves_Petrified"
    },
    {
      "x": -5,
      "y": 19,
      "z": -4,
      "name": "Plant_Leaves_Snow",
      "rotation": 2
    },
    {
      "x": -5,
      "y": 20,
      "z": -4,
      "name": "Plant_Leaves_Snow",
      "rotation": 2
    },
    {
      "x": -5,
      "y": 24,
      "z": -4,
      "name": "Plant_Leaves_Petrified"
    },
    {
      "x": -5,
      "y": 19,
      "z": -3,
      "name": "Wood_Camphor_Trunk_Full",
      "rotation": 1
    },
    {
      "x": -5,
      "y": 20,
      "z": -3,
      "name": "Plant_Leaves_Snow",
      "rotation": 2
    },
    {
      "x": -5,
      "y": 23,
      "z": -3,
      "name": "Plant_Leaves_Petrified"
    },
    {
      "x": -5,
      "y": 24,
      "z": -3,
      "name": "Plant_Leaves_Petrified"
    },
    {
      "x": -5,
      "y": 19,
      "z": -2,
      "name": "Wood_Camphor_Trunk_Full",
      "rotation": 1
    },
    {
      "x": -5,
      "y": 20,
      "z": -2,
      "name": "Plant_Leaves_Snow",
      "rotation": 2
    },
    {
      "x": -5,
      "y": 19,
      "z": -1,
      "name": "Plant_Leaves_Snow",
      "rotation": 3
    },
    {
      "x": -5,
      "y": 23,
      "z": -1,
      "name": "Plant_Leaves_Petrified"
    },
    {
      "x": -5,
      "y": 19,
      "z": 0,
      "name": "Plant_Leaves_Snow",
      "rotation": 3
    },
    {
      "x": -5,
      "y": 23,
      "z": 0,
      "name": "Wood_Crystal_Trunk_Full",
      "rotation": 1
    },
    {
      "x": -5,
      "y": 19,
      "z": 1,
      "name": "Wood_Camphor_Trunk_Full",
      "rotation": 1
    },
    {
      "x": -5,
      "y": 20,
      "z": 1,
      "name": "Plant_Leaves_Snow",
      "rotation": 3
    },
    {
      "x": -5,
      "y": 23,
      "z": 1,
      "name": "Plant_Leaves_Petrified",
      "rotation": 1
    },
    {
      "x": -5,
      "y": 19,
      "z": 2,
      "name": "Wood_Camphor_Trunk_Full",
      "rotation": 1
    },
    {
      "x": -5,
      "y": 20,
      "z": 2,
      "name": "Plant_Leaves_Snow",
      "rotation": 3
    },
    {
      "x": -5,
      "y": 19,
      "z": 3,
      "name": "Plant_Leaves_Snow",
      "rotation": 3
    },
    {
      "x": -5,
      "y": 23,
      "z": 3,
      "name": "Plant_Leaves_Petrified",
      "rotation": 1
    },
    {
      "x": -5,
      "y": 24,
      "z": 3,
      "name": "Plant_Leaves_Petrified",
      "rotation": 1
    },
    {
      "x": -5,
      "y": 19,
      "z": 4,
      "name": "Plant_Leaves_Snow",
      "rotation": 3
    },
    {
      "x": -5,
      "y": 24,
      "z": 4,
      "name": "Plant_Leaves_Petrified",
      "rotation": 1
    },
    {
      "x": -5,
      "y": 18,
      "z": 5,
      "name": "Plant_Leaves_Snow",
      "rotation": 3
    },
    {
      "x": -5,
      "y": 19,
      "z": 5,
      "name": "Plant_Leaves_Snow",
      "rotation": 3
    },
    {
      "x": -5,
      "y": 25,
      "z": 5,
      "name": "Wood_Crystal_Trunk_Full",
      "rotation": 1
    },
    {
      "x": -5,
      "y": 26,
      "z": 5,
      "name": "Wood_Crystal_Trunk_Full",
      "rotation": 1
    },
    {
      "x": -5,
      "y": 27,
      "z": 5,
      "name": "Plant_Leaves_Petrified",
      "rotation": 1
    },
    {
      "x": -5,
      "y": 28,
      "z": 5,
      "name": "Plant_Leaves_Petrified",
      "rotation": 1
    },
    {
      "x": -5,
      "y": 18,
      "z": 6,
      "name": "Plant_Leaves_Snow",
      "rotation": 3
    },
    {
      "x": -5,
      "y": 19,
      "z": 6,
      "name": "Plant_Leaves_Snow",
      "rotation": 3
    },
    {
      "x": -5,
      "y": 18,
      "z": 7,
      "name": "Plant_Leaves_Snow",
      "rotation": 3
    },
    {
      "x": -5,
      "y": 19,
      "z": 7,
      "name": "Plant_Leaves_Snow",
      "rotation": 3
    },
    {
      "x": -5,
      "y": 17,
      "z": 8,
      "name": "Wood_Camphor_Trunk_Full",
      "rotation": 2
    },
    {
      "x": -5,
      "y": 18,
      "z": 8,
      "name": "Plant_Leaves_Snow",
      "rotation": 3
    },
    {
      "x": -5,
      "y": 17,
      "z": 9,
      "name": "Wood_Camphor_Trunk_Full",
      "rotation": 2
    },
    {
      "x": -5,
      "y": 18,
      "z": 9,
      "name": "Plant_Leaves_Snow",
      "rotation": 3
    },
    {
      "x": -5,
      "y": 16,
      "z": 10,
      "name": "Wood_Camphor_Trunk_Full",
      "rotation": 2
    },
    {
      "x": -5,
      "y": 17,
      "z": 10,
      "name": "Plant_Leaves_Snow",
      "rotation": 3
    },
    {
      "x": -5,
      "y": 15,
      "z": 11,
      "name": "Plant_Leaves_Snow",
      "rotation": 3
    },
    {
      "x": -5,
      "y": 16,
      "z": 11,
      "name": "Plant_Leaves_Snow",
      "rotation": 3
    },
    {
      "x": -5,
      "y": 14,
      "z": 12,
      "name": "Plant_Leaves_Snow"
    },
    {
      "x": -4,
      "y": 19,
      "z": -16,
      "name": "Plant_Leaves_Snow"
    },
    {
      "x": -4,
      "y": 18,
      "z": -15,
      "name": "Plant_Leaves_Snow"
    },
    {
      "x": -4,
      "y": 18,
      "z": -14,
      "name": "Plant_Leaves_Snow"
    },
    {
      "x": -4,
      "y": 17,
      "z": -13,
      "name": "Plant_Leaves_Snow"
    },
    {
      "x": -4,
      "y": 17,
      "z": -12,
      "name": "Plant_Leaves_Snow"
    },
    {
      "x": -4,
      "y": 17,
      "z": -11,
      "name": "Plant_Leaves_Snow",
      "rotation": 2
    },
    {
      "x": -4,
      "y": 18,
      "z": -11,
      "name": "Plant_Leaves_Snow"
    },
    {
      "x": -4,
      "y": 17,
      "z": -10,
      "name": "Plant_Leaves_Snow",
      "rotation": 2
    },
    {
      "x": -4,
      "y": 18,
      "z": -10,
      "name": "Plant_Leaves_Snow",
      "rotation": 2
    },
    {
      "x": -4,
      "y": 18,
      "z": -9,
      "name": "Plant_Leaves_Snow",
      "rotation": 2
    },
    {
      "x": -4,
      "y": 18,
      "z": -8,
      "name": "Plant_Leaves_Snow",
      "rotation": 2
    },
    {
      "x": -4,
      "y": 19,
      "z": -8,
      "name": "Plant_Leaves_Snow",
      "rotation": 2
    },
    {
      "x": -4,
      "y": 19,
      "z": -7,
      "name": "Plant_Leaves_Snow",
      "rotation": 2
    },
    {
      "x": -4,
      "y": 19,
      "z": -6,
      "name": "Plant_Leaves_Snow"
    },
    {
      "x": -4,
      "y": 25,
      "z": -6,
      "name": "Plant_Leaves_Petrified"
    },
    {
      "x": -4,
      "y": 26,
      "z": -6,
      "name": "Plant_Leaves_Petrified"
    },
    {
      "x": -4,
      "y": 19,
      "z": -5,
      "name": "Plant_Leaves_Snow",
      "rotation": 2
    },
    {
      "x": -4,
      "y": 24,
      "z": -5,
      "name": "Plant_Leaves_Petrified"
    },
    {
      "x": -4,
      "y": 19,
      "z": -4,
      "name": "Plant_Leaves_Snow",
      "rotation": 2
    },
    {
      "x": -4,
      "y": 23,
      "z": -4,
      "name": "Wood_Crystal_Trunk_Full"
    },
    {
      "x": -4,
      "y": 24,
      "z": -4,
      "name": "Wood_Crystal_Trunk_Full"
    },
    {
      "x": -4,
      "y": 25,
      "z": -4,
      "name": "Rock_Crystal_White_Large"
    },
    {
      "x": -4,
      "y": 19,
      "z": -3,
      "name": "Wood_Camphor_Trunk_Full",
      "rotation": 2
    },
    {
      "x": -4,
      "y": 20,
      "z": -3,
      "name": "Plant_Leaves_Snow",
      "rotation": 2
    },
    {
      "x": -4,
      "y": 22,
      "z": -3,
      "name": "Plant_Leaves_Petrified"
    },
    {
      "x": -4,
      "y": 19,
      "z": -2,
      "name": "Wood_Camphor_Trunk_Full",
      "rotation": 1
    },
    {
      "x": -4,
      "y": 20,
      "z": -2,
      "name": "Rock_Crystal_White_Large",
      "rotation": 1
    },
    {
      "x": -4,
      "y": 19,
      "z": -1,
      "name": "Wood_Camphor_Trunk_Full",
      "rotation": 3
    },
    {
      "x": -4,
      "y": 22,
      "z": -1,
      "name": "Plant_Leaves_Petrified"
    },
    {
      "x": -4,
      "y": 19,
      "z": 0,
      "name": "Wood_Camphor_Trunk_Full",
      "rotation": 1
    },
    {
      "x": -4,
      "y": 22,
      "z": 0,
      "name": "Wood_Crystal_Trunk_Full",
      "rotation": 1
    },
    {
      "x": -4,
      "y": 19,
      "z": 1,
      "name": "Wood_Camphor_Trunk_Full",
      "rotation": 1
    },
    {
      "x": -4,
      "y": 20,
      "z": 1,
      "name": "Rock_Crystal_White_Large",
      "rotation": 1
    },
    {
      "x": -4,
      "y": 22,
      "z": 1,
      "name": "Plant_Leaves_Petrified",
      "rotation": 1
    },
    {
      "x": -4,
      "y": 19,
      "z": 2,
      "name": "Wood_Camphor_Trunk_Full",
      "rotation": 3
    },
    {
      "x": -4,
      "y": 19,
      "z": 3,
      "name": "Plant_Leaves_Snow",
      "rotation": 3
    },
    {
      "x": -4,
      "y": 22,
      "z": 3,
      "name": "Plant_Leaves_Petrified",
      "rotation": 1
    },
    {
      "x": -4,
      "y": 19,
      "z": 4,
      "name": "Plant_Leaves_Snow",
      "rotation": 3
    },
    {
      "x": -4,
      "y": 23,
      "z": 4,
      "name": "Wood_Crystal_Trunk_Full",
      "rotation": 1
    },
    {
      "x": -4,
      "y": 24,
      "z": 4,
      "name": "Wood_Crystal_Trunk_Full",
      "rotation": 1
    },
    {
      "x": -4,
      "y": 25,
      "z": 4,
      "name": "Rock_Crystal_White_Large",
      "rotation": 1
    },
    {
      "x": -4,
      "y": 19,
      "z": 5,
      "name": "Plant_Leaves_Snow",
      "rotation": 3
    },
    {
      "x": -4,
      "y": 20,
      "z": 5,
      "name": "Plant_Leaves_Snow",
      "rotation": 3
    },
    {
      "x": -4,
      "y": 24,
      "z": 5,
      "name": "Plant_Leaves_Petrified",
      "rotation": 1
    },
    {
      "x": -4,
      "y": 18,
      "z": 6,
      "name": "Wood_Camphor_Trunk_Full",
      "rotation": 2
    },
    {
      "x": -4,
      "y": 19,
      "z": 6,
      "name": "Plant_Leaves_Snow",
      "rotation": 3
    },
    {
      "x": -4,
      "y": 20,
      "z": 6,
      "name": "Plant_Leaves_Snow",
      "rotation": 3
    },
    {
      "x": -4,
      "y": 25,
      "z": 6,
      "name": "Plant_Leaves_Petrified",
      "rotation": 1
    },
    {
      "x": -4,
      "y": 26,
      "z": 6,
      "name": "Plant_Leaves_Petrified",
      "rotation": 1
    },
    {
      "x": -4,
      "y": 18,
      "z": 7,
      "name": "Wood_Camphor_Trunk_Full",
      "rotation": 2
    },
    {
      "x": -4,
      "y": 19,
      "z": 7,
      "name": "Plant_Leaves_Snow",
      "rotation": 3
    },
    {
      "x": -4,
      "y": 17,
      "z": 8,
      "name": "Wood_Camphor_Trunk_Full",
      "rotation": 2
    },
    {
      "x": -4,
      "y": 18,
      "z": 8,
      "name": "Plant_Leaves_Snow",
      "rotation": 3
    },
    {
      "x": -4,
      "y": 19,
      "z": 8,
      "name": "Plant_Leaves_Snow",
      "rotation": 3
    },
    {
      "x": -4,
      "y": 17,
      "z": 9,
      "name": "Plant_Leaves_Snow",
      "rotation": 3
    },
    {
      "x": -4,
      "y": 18,
      "z": 9,
      "name": "Plant_Leaves_Snow",
      "rotation": 3
    },
    {
      "x": -4,
      "y": 16,
      "z": 10,
      "name": "Plant_Leaves_Snow",
      "rotation": 3
    },
    {
      "x": -4,
      "y": 17,
      "z": 10,
      "name": "Plant_Leaves_Snow",
      "rotation": 3
    },
    {
      "x": -4,
      "y": 15,
      "z": 11,
      "name": "Plant_Leaves_Snow",
      "rotation": 3
    },
    {
      "x": -3,
      "y": 18,
      "z": -15,
      "name": "Plant_Leaves_Snow"
    },
    {
      "x": -3,
      "y": 18,
      "z": -14,
      "name": "Plant_Leaves_Snow"
    },
    {
      "x": -3,
      "y": 17,
      "z": -13,
      "name": "Plant_Leaves_Snow"
    },
    {
      "x": -3,
      "y": 17,
      "z": -12,
      "name": "Plant_Leaves_Snow"
    },
    {
      "x": -3,
      "y": 17,
      "z": -11,
      "name": "Wood_Camphor_Trunk_Full"
    },
    {
      "x": -3,
      "y": 18,
      "z": -11,
      "name": "Plant_Leaves_Snow"
    },
    {
      "x": -3,
      "y": 17,
      "z": -10,
      "name": "Wood_Camphor_Trunk_Full"
    },
    {
      "x": -3,
      "y": 18,
      "z": -10,
      "name": "Plant_Leaves_Snow",
      "rotation": 2
    },
    {
      "x": -3,
      "y": 18,
      "z": -9,
      "name": "Wood_Camphor_Trunk_Full"
    },
    {
      "x": -3,
      "y": 19,
      "z": -9,
      "name": "Plant_Leaves_Snow",
      "rotation": 2
    },
    {
      "x": -3,
      "y": 18,
      "z": -8,
      "name": "Plant_Leaves_Snow"
    },
    {
      "x": -3,
      "y": 19,
      "z": -8,
      "name": "Plant_Leaves_Snow",
      "rotation": 2
    },
    {
      "x": -3,
      "y": 19,
      "z": -7,
      "name": "Plant_Leaves_Snow"
    },
    {
      "x": -3,
      "y": 20,
      "z": -7,
      "name": "Plant_Leaves_Snow",
      "rotation": 2
    },
    {
      "x": -3,
      "y": 19,
      "z": -6,
      "name": "Plant_Leaves_Snow",
      "rotation": 2
    },
    {
      "x": -3,
      "y": 20,
      "z": -6,
      "name": "Plant_Leaves_Snow",
      "rotation": 2
    },
    {
      "x": -3,
      "y": 19,
      "z": -5,
      "name": "Plant_Leaves_Snow",
      "rotation": 2
    },
    {
      "x": -3,
      "y": 23,
      "z": -5,
      "name": "Plant_Leaves_Petrified"
    },
    {
      "x": -3,
      "y": 24,
      "z": -5,
      "name": "Plant_Leaves_Petrified"
    },
    {
      "x": -3,
      "y": 19,
      "z": -4,
      "name": "Plant_Leaves_Snow",
      "rotation": 2
    },
    {
      "x": -3,
      "y": 22,
      "z": -4,
      "name": "Plant_Leaves_Petrified"
    },
    {
      "x": -3,
      "y": 19,
      "z": -3,
      "name": "Wood_Camphor_Trunk_Full",
      "rotation": 2
    },
    {
      "x": -3,
      "y": 22,
      "z": -3,
      "name": "Wood_Crystal_Trunk_Full"
    },
    {
      "x": -3,
      "y": 19,
      "z": -2,
      "name": "Wood_Camphor_Trunk_Full"
    },
    {
      "x": -3,
      "y": 22,
      "z": -2,
      "name": "Plant_Leaves_Petrified"
    },
    {
      "x": -3,
      "y": 0,
      "z": -1,
      "name": "Wood_Camphor_Trunk_Full"
    },
    {
      "x": -3,
      "y": 1,
      "z": -1,
      "name": "Wood_Camphor_Trunk_Full"
    },
    {
      "x": -3,
      "y": 18,
      "z": -1,
      "name": "Wood_Camphor_Trunk_Full"
    },
    {
      "x": -3,
      "y": 19,
      "z": -1,
      "name": "Wood_Camphor_Trunk_Full"
    },
    {
      "x": -3,
      "y": 20,
      "z": -1,
      "name": "Wood_Camphor_Trunk_Full",
      "rotation": 3
    },
    {
      "x": -3,
      "y": 21,
      "z": -1,
      "name": "Plant_Leaves_Petrified"
    },
    {
      "x": -3,
      "y": 28,
      "z": -1,
      "name": "Rock_Crystal_White_Block"
    },
    {
      "x": -3,
      "y": 29,
      "z": -1,
      "name": "Rock_Crystal_White_Block"
    },
    {
      "x": -3,
      "y": 30,
      "z": -1,
      "name": "Rock_Crystal_White_Block"
    },
    {
      "x": -3,
      "y": 0,
      "z": 0,
      "name": "Wood_Camphor_Trunk_Full"
    },
    {
      "x": -3,
      "y": 1,
      "z": 0,
      "name": "Wood_Camphor_Trunk_Full"
    },
    {
      "x": -3,
      "y": 2,
      "z": 0,
      "name": "Wood_Camphor_Trunk_Full"
    },
    {
      "x": -3,
      "y": 18,
      "z": 0,
      "name": "Wood_Camphor_Trunk_Full"
    },
    {
      "x": -3,
      "y": 19,
      "z": 0,
      "name": "Wood_Camphor_Trunk_Full"
    },
    {
      "x": -3,
      "y": 20,
      "z": 0,
      "name": "Wood_Camphor_Trunk_Full",
      "rotation": 3
    },
    {
      "x": -3,
      "y": 21,
      "z": 0,
      "name": "Wood_Crystal_Trunk_Full",
      "rotation": 1
    },
    {
      "x": -3,
      "y": 28,
      "z": 0,
      "name": "Rock_Crystal_White_Block"
    },
    {
      "x": -3,
      "y": 29,
      "z": 0,
      "name": "Rock_Crystal_White_Block"
    },
    {
      "x": -3,
      "y": 30,
      "z": 0,
      "name": "Rock_Crystal_White_Block"
    },
    {
      "x": -3,
      "y": 0,
      "z": 1,
      "name": "Wood_Camphor_Trunk_Full"
    },
    {
      "x": -3,
      "y": 1,
      "z": 1,
      "name": "Wood_Camphor_Trunk_Full"
    },
    {
      "x": -3,
      "y": 18,
      "z": 1,
      "name": "Wood_Camphor_Trunk_Full"
    },
    {
      "x": -3,
      "y": 19,
      "z": 1,
      "name": "Wood_Camphor_Trunk_Full"
    },
    {
      "x": -3,
      "y": 20,
      "z": 1,
      "name": "Wood_Camphor_Trunk_Full",
      "rotation": 3
    },
    {
      "x": -3,
      "y": 21,
      "z": 1,
      "name": "Plant_Leaves_Petrified",
      "rotation": 1
    },
    {
      "x": -3,
      "y": 28,
      "z": 1,
      "name": "Rock_Crystal_White_Block"
    },
    {
      "x": -3,
      "y": 29,
      "z": 1,
      "name": "Rock_Crystal_White_Block"
    },
    {
      "x": -3,
      "y": 30,
      "z": 1,
      "name": "Rock_Crystal_White_Block"
    },
    {
      "x": -3,
      "y": 19,
      "z": 2,
      "name": "Wood_Camphor_Trunk_Full",
      "rotation": 3
    },
    {
      "x": -3,
      "y": 22,
      "z": 2,
      "name": "Plant_Leaves_Petrified",
      "rotation": 1
    },
    {
      "x": -3,
      "y": 19,
      "z": 3,
      "name": "Wood_Camphor_Trunk_Full",
      "rotation": 3
    },
    {
      "x": -3,
      "y": 22,
      "z": 3,
      "name": "Wood_Crystal_Trunk_Full",
      "rotation": 1
    },
    {
      "x": -3,
      "y": 19,
      "z": 4,
      "name": "Wood_Camphor_Trunk_Full",
      "rotation": 3
    },
    {
      "x": -3,
      "y": 20,
      "z": 4,
      "name": "Plant_Leaves_Snow",
      "rotation": 3
    },
    {
      "x": -3,
      "y": 22,
      "z": 4,
      "name": "Plant_Leaves_Petrified",
      "rotation": 1
    },
    {
      "x": -3,
      "y": 19,
      "z": 5,
      "name": "Wood_Camphor_Trunk_Full",
      "rotation": 2
    },
    {
      "x": -3,
      "y": 20,
      "z": 5,
      "name": "Plant_Leaves_Snow",
      "rotation": 3
    },
    {
      "x": -3,
      "y": 23,
      "z": 5,
      "name": "Plant_Leaves_Petrified",
      "rotation": 1
    },
    {
      "x": -3,
      "y": 24,
      "z": 5,
      "name": "Plant_Leaves_Petrified",
      "rotation": 1
    },
    {
      "x": -3,
      "y": 19,
      "z": 6,
      "name": "Wood_Camphor_Trunk_Full",
      "rotation": 2
    },
    {
      "x": -3,
      "y": 20,
      "z": 6,
      "name": "Plant_Leaves_Snow",
      "rotation": 3
    },
    {
      "x": -3,
      "y": 18,
      "z": 7,
      "name": "Wood_Camphor_Trunk_Full",
      "rotation": 2
    },
    {
      "x": -3,
      "y": 19,
      "z": 7,
      "name": "Plant_Leaves_Snow",
      "rotation": 3
    },
    {
      "x": -3,
      "y": 20,
      "z": 7,
      "name": "Plant_Leaves_Snow",
      "rotation": 3
    },
    {
      "x": -3,
      "y": 18,
      "z": 8,
      "name": "Plant_Leaves_Snow",
      "rotation": 3
    },
    {
      "x": -3,
      "y": 19,
      "z": 8,
      "name": "Plant_Leaves_Snow",
      "rotation": 3
    },
    {
      "x": -3,
      "y": 17,
      "z": 9,
      "name": "Plant_Leaves_Snow",
      "rotation": 3
    },
    {
      "x": -3,
      "y": 18,
      "z": 9,
      "name": "Plant_Leaves_Snow",
      "rotation": 3
    },
    {
      "x": -3,
      "y": 16,
      "z": 10,
      "name": "Plant_Leaves_Snow",
      "rotation": 3
    },
    {
      "x": -2,
      "y": 17,
      "z": -13,
      "name": "Plant_Leaves_Snow"
    },
    {
      "x": -2,
      "y": 17,
      "z": -12,
      "name": "Plant_Leaves_Snow"
    },
    {
      "x": -2,
      "y": 17,
      "z": -11,
      "name": "Plant_Leaves_Snow",
      "rotation": 2
    },
    {
      "x": -2,
      "y": 18,
      "z": -11,
      "name": "Plant_Leaves_Snow"
    },
    {
      "x": -2,
      "y": 17,
      "z": -10,
      "name": "Plant_Leaves_Snow",
      "rotation": 2
    },
    {
      "x": -2,
      "y": 18,
      "z": -10,
      "name": "Plant_Leaves_Snow",
      "rotation": 2
    },
    {
      "x": -2,
      "y": 18,
      "z": -9,
      "name": "Plant_Leaves_Snow",
      "rotation": 2
    },
    {
      "x": -2,
      "y": 19,
      "z": -9,
      "name": "Plant_Leaves_Snow",
      "rotation": 2
    },
    {
      "x": -2,
      "y": 18,
      "z": -8,
      "name": "Wood_Camphor_Trunk_Full"
    },
    {
      "x": -2,
      "y": 19,
      "z": -8,
      "name": "Plant_Leaves_Snow",
      "rotation": 2
    },
    {
      "x": -2,
      "y": 19,
      "z": -7,
      "name": "Wood_Camphor_Trunk_Full"
    },
    {
      "x": -2,
      "y": 20,
      "z": -7,
      "name": "Plant_Leaves_Snow",
      "rotation": 2
    },
    {
      "x": -2,
      "y": 19,
      "z": -6,
      "name": "Wood_Camphor_Trunk_Full"
    },
    {
      "x": -2,
      "y": 20,
      "z": -6,
      "name": "Plant_Leaves_Snow",
      "rotation": 2
    },
    {
      "x": -2,
      "y": 19,
      "z": -5,
      "name": "Wood_Camphor_Trunk_Full"
    },
    {
      "x": -2,
      "y": 20,
      "z": -5,
      "name": "Plant_Leaves_Snow",
      "rotation": 2
    },
    {
      "x": -2,
      "y": 19,
      "z": -4,
      "name": "Wood_Camphor_Trunk_Full",
      "rotation": 2
    },
    {
      "x": -2,
      "y": 19,
      "z": -3,
      "name": "Wood_Camphor_Trunk_Full"
    },
    {
      "x": -2,
      "y": 22,
      "z": -3,
      "name": "Plant_Leaves_Petrified"
    },
    {
      "x": -2,
      "y": 0,
      "z": -2,
      "name": "Wood_Camphor_Trunk_Full"
    },
    {
      "x": -2,
      "y": 1,
      "z": -2,
      "name": "Wood_Camphor_Trunk_Full"
    },
    {
      "x": -2,
      "y": 2,
      "z": -2,
      "name": "Wood_Camphor_Trunk_Full"
    },
    {
      "x": -2,
      "y": 18,
      "z": -2,
      "name": "Wood_Camphor_Trunk_Full"
    },
    {
      "x": -2,
      "y": 19,
      "z": -2,
      "name": "Wood_Camphor_Trunk_Full"
    },
    {
      "x": -2,
      "y": 20,
      "z": -2,
      "name": "Wood_Camphor_Trunk_Full",
      "rotation": 2
    },
    {
      "x": -2,
      "y": 21,
      "z": -2,
      "name": "Wood_Crystal_Trunk_Full"
    },
    {
      "x": -2,
      "y": 28,
      "z": -2,
      "name": "Rock_Crystal_White_Block"
    },
    {
      "x": -2,
      "y": 29,
      "z": -2,
      "name": "Rock_Crystal_White_Block"
    },
    {
      "x": -2,
      "y": 30,
      "z": -2,
      "name": "Rock_Crystal_White_Block"
    },
    {
      "x": -2,
      "y": 0,
      "z": -1,
      "name": "Wood_Camphor_Trunk_Full"
    },
    {
      "x": -2,
      "y": 1,
      "z": -1,
      "name": "Wood_Camphor_Trunk_Full"
    },
    {
      "x": -2,
      "y": 2,
      "z": -1,
      "name": "Wood_Camphor_Trunk_Full"
    },
    {
      "x": -2,
      "y": 3,
      "z": -1,
      "name": "Wood_Camphor_Trunk_Full"
    },
    {
      "x": -2,
      "y": 16,
      "z": -1,
      "name": "Wood_Camphor_Trunk_Full",
      "rotation": 3
    },
    {
      "x": -2,
      "y": 17,
      "z": -1,
      "name": "Wood_Camphor_Trunk_Full"
    },
    {
      "x": -2,
      "y": 18,
      "z": -1,
      "name": "Wood_Camphor_Trunk_Full"
    },
    {
      "x": -2,
      "y": 19,
      "z": -1,
      "name": "Wood_Camphor_Trunk_Full"
    },
    {
      "x": -2,
      "y": 20,
      "z": -1,
      "name": "Wood_Crystal_Trunk_Full",
      "rotation": 3
    },
    {
      "x": -2,
      "y": 21,
      "z": -1,
      "name": "Plant_Leaves_Petrified"
    },
    {
      "x": -2,
      "y": 27,
      "z": -1,
      "name": "Rock_Crystal_White_Block"
    },
    {
      "x": -2,
      "y": 31,
      "z": -1,
      "name": "Rock_Crystal_White_Block"
    },
    {
      "x": -2,
      "y": 0,
      "z": 0,
      "name": "Wood_Camphor_Trunk_Full"
    },
    {
      "x": -2,
      "y": 1,
      "z": 0,
      "name": "Wood_Camphor_Trunk_Full"
    },
    {
      "x": -2,
      "y": 2,
      "z": 0,
      "name": "Wood_Camphor_Trunk_Full"
    },
    {
      "x": -2,
      "y": 3,
      "z": 0,
      "name": "Wood_Camphor_Trunk_Full"
    },
    {
      "x": -2,
      "y": 4,
      "z": 0,
      "name": "Wood_Camphor_Trunk_Full"
    },
    {
      "x": -2,
      "y": 17,
      "z": 0,
      "name": "Wood_Camphor_Trunk_Full"
    },
    {
      "x": -2,
      "y": 20,
      "z": 0,
      "name": "Wood_Crystal_Trunk_Full",
      "rotation": 3
    },
    {
      "x": -2,
      "y": 26,
      "z": 0,
      "name": "Wood_Crystal_Trunk_Full"
    },
    {
      "x": -2,
      "y": 27,
      "z": 0,
      "name": "Rock_Crystal_White_Block"
    },
    {
      "x": -2,
      "y": 31,
      "z": 0,
      "name": "Rock_Crystal_White_Block"
    },
    {
      "x": -2,
      "y": 0,
      "z": 1,
      "name": "Wood_Camphor_Trunk_Full"
    },
    {
      "x": -2,
      "y": 1,
      "z": 1,
      "name": "Wood_Camphor_Trunk_Full"
    },
    {
      "x": -2,
      "y": 2,
      "z": 1,
      "name": "Wood_Camphor_Trunk_Full"
    },
    {
      "x": -2,
      "y": 3,
      "z": 1,
      "name": "Wood_Camphor_Trunk_Full"
    },
    {
      "x": -2,
      "y": 17,
      "z": 1,
      "name": "Wood_Camphor_Trunk_Full"
    },
    {
      "x": -2,
      "y": 18,
      "z": 1,
      "name": "Wood_Camphor_Trunk_Full"
    },
    {
      "x": -2,
      "y": 19,
      "z": 1,
      "name": "Wood_Camphor_Trunk_Full"
    },
    {
      "x": -2,
      "y": 20,
      "z": 1,
      "name": "Wood_Crystal_Trunk_Full",
      "rotation": 3
    },
    {
      "x": -2,
      "y": 21,
      "z": 1,
      "name": "Plant_Leaves_Petrified",
      "rotation": 1
    },
    {
      "x": -2,
      "y": 27,
      "z": 1,
      "name": "Rock_Crystal_White_Block"
    },
    {
      "x": -2,
      "y": 31,
      "z": 1,
      "name": "Rock_Crystal_White_Block"
    },
    {
      "x": -2,
      "y": 0,
      "z": 2,
      "name": "Wood_Camphor_Trunk_Full"
    },
    {
      "x": -2,
      "y": 1,
      "z": 2,
      "name": "Wood_Camphor_Trunk_Full"
    },
    {
      "x": -2,
      "y": 18,
      "z": 2,
      "name": "Wood_Camphor_Trunk_Full"
    },
    {
      "x": -2,
      "y": 19,
      "z": 2,
      "name": "Wood_Camphor_Trunk_Full"
    },
    {
      "x": -2,
      "y": 20,
      "z": 2,
      "name": "Wood_Camphor_Trunk_Full",
      "rotation": 3
    },
    {
      "x": -2,
      "y": 21,
      "z": 2,
      "name": "Wood_Crystal_Trunk_Full",
      "rotation": 1
    },
    {
      "x": -2,
      "y": 28,
      "z": 2,
      "name": "Rock_Crystal_White_Block"
    },
    {
      "x": -2,
      "y": 29,
      "z": 2,
      "name": "Rock_Crystal_White_Block"
    },
    {
      "x": -2,
      "y": 30,
      "z": 2,
      "name": "Rock_Crystal_White_Block"
    },
    {
      "x": -2,
      "y": 19,
      "z": 3,
      "name": "Wood_Camphor_Trunk_Full",
      "rotation": 2
    },
    {
      "x": -2,
      "y": 22,
      "z": 3,
      "name": "Plant_Leaves_Petrified",
      "rotation": 1
    },
    {
      "x": -2,
      "y": 19,
      "z": 4,
      "name": "Wood_Camphor_Trunk_Full",
      "rotation": 2
    },
    {
      "x": -2,
      "y": 20,
      "z": 4,
      "name": "Rock_Crystal_White_Large",
      "rotation": 2
    },
    {
      "x": -2,
      "y": 19,
      "z": 5,
      "name": "Wood_Camphor_Trunk_Full",
      "rotation": 2
    },
    {
      "x": -2,
      "y": 20,
      "z": 5,
      "name": "Plant_Leaves_Snow",
      "rotation": 3
    },
    {
      "x": -2,
      "y": 19,
      "z": 6,
      "name": "Plant_Leaves_Snow",
      "rotation": 3
    },
    {
      "x": -2,
      "y": 20,
      "z": 6,
      "name": "Plant_Leaves_Snow",
      "rotation": 3
    },
    {
      "x": -2,
      "y": 18,
      "z": 7,
      "name": "Plant_Leaves_Snow",
      "rotation": 3
    },
    {
      "x": -2,
      "y": 19,
      "z": 7,
      "name": "Plant_Leaves_Snow",
      "rotation": 3
    },
    {
      "x": -2,
      "y": 18,
      "z": 8,
      "name": "Plant_Leaves_Snow",
      "rotation": 3
    },
    {
      "x": -2,
      "y": 17,
      "z": 9,
      "name": "Plant_Leaves_Snow",
      "rotation": 3
    },
    {
      "x": -1,
      "y": 17,
      "z": -11,
      "name": "Plant_Leaves_Snow"
    },
    {
      "x": -1,
      "y": 18,
      "z": -10,
      "name": "Plant_Leaves_Snow"
    },
    {
      "x": -1,
      "y": 18,
      "z": -9,
      "name": "Plant_Leaves_Snow",
      "rotation": 2
    },
    {
      "x": -1,
      "y": 19,
      "z": -9,
      "name": "Plant_Leaves_Snow",
      "rotation": 2
    },
    {
      "x": -1,
      "y": 18,
      "z": -8,
      "name": "Plant_Leaves_Snow",
      "rotation": 2
    },
    {
      "x": -1,
      "y": 19,
      "z": -8,
      "name": "Plant_Leaves_Snow",
      "rotation": 2
    },
    {
      "x": -1,
      "y": 25,
      "z": -8,
      "name": "Plant_Leaves_Petrified"
    },
    {
      "x": -1,
      "y": 26,
      "z": -8,
      "name": "Plant_Leaves_Petrified"
    },
    {
      "x": -1,
      "y": 19,
      "z": -7,
      "name": "Plant_Leaves_Snow",
      "rotation": 2
    },
    {
      "x": -1,
      "y": 20,
      "z": -7,
      "name": "Plant_Leaves_Snow",
      "rotation": 2
    },
    {
      "x": -1,
      "y": 24,
      "z": -7,
      "name": "Plant_Leaves_Petrified"
    },
    {
      "x": -1,
      "y": 19,
      "z": -6,
      "name": "Wood_Camphor_Trunk_Full"
    },
    {
      "x": -1,
      "y": 20,
      "z": -6,
      "name": "Plant_Leaves_Snow",
      "rotation": 2
    },
    {
      "x": -1,
      "y": 23,
      "z": -6,
      "name": "Plant_Leaves_Petrified"
    },
    {
      "x": -1,
      "y": 19,
      "z": -5,
      "name": "Wood_Camphor_Trunk_Full"
    },
    {
      "x": -1,
      "y": 20,
      "z": -5,
      "name": "Plant_Leaves_Snow",
      "rotation": 2
    },
    {
      "x": -1,
      "y": 23,
      "z": -5,
      "name": "Plant_Leaves_Petrified"
    },
    {
      "x": -1,
      "y": 19,
      "z": -4,
      "name": "Wood_Camphor_Trunk_Full"
    },
    {
      "x": -1,
      "y": 20,
      "z": -4,
      "name": "Rock_Crystal_White_Large"
    },
    {
      "x": -1,
      "y": 22,
      "z": -4,
      "name": "Plant_Leaves_Petrified"
    },
    {
      "x": -1,
      "y": 0,
      "z": -3,
      "name": "Wood_Camphor_Trunk_Full"
    },
    {
      "x": -1,
      "y": 1,
      "z": -3,
      "name": "Wood_Camphor_Trunk_Full"
    },
    {
      "x": -1,
      "y": 18,
      "z": -3,
      "name": "Wood_Camphor_Trunk_Full"
    },
    {
      "x": -1,
      "y": 19,
      "z": -3,
      "name": "Wood_Camphor_Trunk_Full"
    },
    {
      "x": -1,
      "y": 20,
      "z": -3,
      "name": "Wood_Camphor_Trunk_Full",
      "rotation": 2
    },
    {
      "x": -1,
      "y": 21,
      "z": -3,
      "name": "Plant_Leaves_Petrified"
    },
    {
      "x": -1,
      "y": 28,
      "z": -3,
      "name": "Rock_Crystal_White_Block"
    },
    {
      "x": -1,
      "y": 29,
      "z": -3,
      "name": "Rock_Crystal_White_Block"
    },
    {
      "x": -1,
      "y": 30,
      "z": -3,
      "name": "Rock_Crystal_White_Block"
    },
    {
      "x": -1,
      "y": 0,
      "z": -2,
      "name": "Wood_Camphor_Trunk_Full"
    },
    {
      "x": -1,
      "y": 1,
      "z": -2,
      "name": "Wood_Camphor_Trunk_Full"
    },
    {
      "x": -1,
      "y": 2,
      "z": -2,
      "name": "Wood_Camphor_Trunk_Full"
    },
    {
      "x": -1,
      "y": 3,
      "z": -2,
      "name": "Wood_Camphor_Trunk_Full"
    },
    {
      "x": -1,
      "y": 4,
      "z": -2,
      "name": "Wood_Camphor_Trunk_Full"
    },
    {
      "x": -1,
      "y": 16,
      "z": -2,
      "name": "Wood_Camphor_Trunk_Full"
    },
    {
      "x": -1,
      "y": 17,
      "z": -2,
      "name": "Wood_Camphor_Trunk_Full"
    },
    {
      "x": -1,
      "y": 18,
      "z": -2,
      "name": "Wood_Camphor_Trunk_Full"
    },
    {
      "x": -1,
      "y": 19,
      "z": -2,
      "name": "Wood_Camphor_Trunk_Full"
    },
    {
      "x": -1,
      "y": 20,
      "z": -2,
      "name": "Wood_Crystal_Trunk_Full",
      "rotation": 2
    },
    {
      "x": -1,
      "y": 21,
      "z": -2,
      "name": "Plant_Leaves_Petrified"
    },
    {
      "x": -1,
      "y": 27,
      "z": -2,
      "name": "Rock_Crystal_White_Block"
    },
    {
      "x": -1,
      "y": 31,
      "z": -2,
      "name": "Rock_Crystal_White_Block"
    },
    {
      "x": -1,
      "y": 0,
      "z": -1,
      "name": "Wood_Camphor_Trunk_Full"
    },
    {
      "x": -1,
      "y": 3,
      "z": -1,
      "name": "Wood_Camphor_Trunk_Full"
    },
    {
      "x": -1,
      "y": 4,
      "z": -1,
      "name": "Wood_Camphor_Trunk_Full"
    },
    {
      "x": -1,
      "y": 5,
      "z": -1,
      "name": "Wood_Camphor_Trunk_Full"
    },
    {
      "x": -1,
      "y": 6,
      "z": -1,
      "name": "Wood_Camphor_Trunk_Full"
    },
    {
      "x": -1,
      "y": 7,
      "z": -1,
      "name": "Wood_Camphor_Trunk_Full"
    },
    {
      "x": -1,
      "y": 14,
      "z": -1,
      "name": "Wood_Camphor_Trunk_Full"
    },
    {
      "x": -1,
      "y": 15,
      "z": -1,
      "name": "Wood_Camphor_Trunk_Full"
    },
    {
      "x": -1,
      "y": 20,
      "z": -1,
      "name": "Wood_Crystal_Trunk_Full",
      "rotation": 3
    },
    {
      "x": -1,
      "y": 26,
      "z": -1,
      "name": "Rock_Crystal_White_Block"
    },
    {
      "x": -1,
      "y": 32,
      "z": -1,
      "name": "Rock_Crystal_White_Block"
    },
    {
      "x": -1,
      "y": 0,
      "z": 0,
      "name": "Wood_Camphor_Trunk_Full"
    },
    {
      "x": -1,
      "y": 5,
      "z": 0,
      "name": "Wood_Camphor_Trunk_Full"
    },
    {
      "x": -1,
      "y": 6,
      "z": 0,
      "name": "Wood_Camphor_Trunk_Full"
    },
    {
      "x": -1,
      "y": 15,
      "z": 0,
      "name": "Wood_Camphor_Trunk_Full"
    },
    {
      "x": -1,
      "y": 16,
      "z": 0,
      "name": "Wood_Camphor_Trunk_Full"
    },
    {
      "x": -1,
      "y": 20,
      "z": 0,
      "name": "Wood_Crystal_Trunk_Full"
    },
    {
      "x": -1,
      "y": 21,
      "z": 0,
      "name": "Wood_Crystal_Trunk_Full",
      "rotation": 1
    },
    {
      "x": -1,
      "y": 25,
      "z": 0,
      "name": "Wood_Crystal_Trunk_Full"
    },
    {
      "x": -1,
      "y": 26,
      "z": 0,
      "name": "Rock_Crystal_White_Block"
    },
    {
      "x": -1,
      "y": 32,
      "z": 0,
      "name": "Rock_Crystal_White_Block"
    },
    {
      "x": -1,
      "y": 0,
      "z": 1,
      "name": "Wood_Camphor_Trunk_Full"
    },
    {
      "x": -1,
      "y": 3,
      "z": 1,
      "name": "Wood_Camphor_Trunk_Full"
    },
    {
      "x": -1,
      "y": 4,
      "z": 1,
      "name": "Wood_Camphor_Trunk_Full"
    },
    {
      "x": -1,
      "y": 5,
      "z": 1,
      "name": "Wood_Camphor_Trunk_Full"
    },
    {
      "x": -1,
      "y": 16,
      "z": 1,
      "name": "Wood_Camphor_Trunk_Full"
    },
    {
      "x": -1,
      "y": 17,
      "z": 1,
      "name": "Wood_Camphor_Trunk_Full"
    },
    {
      "x": -1,
      "y": 20,
      "z": 1,
      "name": "Wood_Crystal_Trunk_Full"
    },
    {
      "x": -1,
      "y": 26,
      "z": 1,
      "name": "Rock_Crystal_White_Block"
    },
    {
      "x": -1,
      "y": 32,
      "z": 1,
      "name": "Rock_Crystal_White_Block"
    },
    {
      "x": -1,
      "y": 0,
      "z": 2,
      "name": "Wood_Camphor_Trunk_Full"
    },
    {
      "x": -1,
      "y": 1,
      "z": 2,
      "name": "Wood_Camphor_Trunk_Full"
    },
    {
      "x": -1,
      "y": 2,
      "z": 2,
      "name": "Wood_Camphor_Trunk_Full"
    },
    {
      "x": -1,
      "y": 3,
      "z": 2,
      "name": "Wood_Camphor_Trunk_Full"
    },
    {
      "x": -1,
      "y": 17,
      "z": 2,
      "name": "Wood_Camphor_Trunk_Full"
    },
    {
      "x": -1,
      "y": 18,
      "z": 2,
      "name": "Wood_Camphor_Trunk_Full"
    },
    {
      "x": -1,
      "y": 19,
      "z": 2,
      "name": "Wood_Camphor_Trunk_Full"
    },
    {
      "x": -1,
      "y": 20,
      "z": 2,
      "name": "Wood_Crystal_Trunk_Full"
    },
    {
      "x": -1,
      "y": 21,
      "z": 2,
      "name": "Plant_Leaves_Petrified",
      "rotation": 1
    },
    {
      "x": -1,
      "y": 27,
      "z": 2,
      "name": "Rock_Crystal_White_Block"
    },
    {
      "x": -1,
      "y": 31,
      "z": 2,
      "name": "Rock_Crystal_White_Block"
    },
    {
      "x": -1,
      "y": 0,
      "z": 3,
      "name": "Wood_Camphor_Trunk_Full"
    },
    {
      "x": -1,
      "y": 1,
      "z": 3,
      "name": "Wood_Camphor_Trunk_Full"
    },
    {
      "x": -1,
      "y": 18,
      "z": 3,
      "name": "Wood_Camphor_Trunk_Full"
    },
    {
      "x": -1,
      "y": 19,
      "z": 3,
      "name": "Wood_Camphor_Trunk_Full"
    },
    {
      "x": -1,
      "y": 20,
      "z": 3,
      "name": "Wood_Camphor_Trunk_Full"
    },
    {
      "x": -1,
      "y": 21,
      "z": 3,
      "name": "Plant_Leaves_Petrified",
      "rotation": 1
    },
    {
      "x": -1,
      "y": 28,
      "z": 3,
      "name": "Rock_Crystal_White_Block"
    },
    {
      "x": -1,
      "y": 29,
      "z": 3,
      "name": "Rock_Crystal_White_Block"
    },
    {
      "x": -1,
      "y": 30,
      "z": 3,
      "name": "Rock_Crystal_White_Block"
    },
    {
      "x": -1,
      "y": 19,
      "z": 4,
      "name": "Wood_Camphor_Trunk_Full"
    },
    {
      "x": -1,
      "y": 22,
      "z": 4,
      "name": "Plant_Leaves_Petrified",
      "rotation": 1
    },
    {
      "x": -1,
      "y": 19,
      "z": 5,
      "name": "Plant_Leaves_Snow"
    },
    {
      "x": -1,
      "y": 23,
      "z": 5,
      "name": "Plant_Leaves_Petrified",
      "rotation": 1
    },
    {
      "x": -1,
      "y": 19,
      "z": 6,
      "name": "Plant_Leaves_Snow"
    },
    {
      "x": -1,
      "y": 23,
      "z": 6,
      "name": "Plant_Leaves_Petrified",
      "rotation": 1
    },
    {
      "x": -1,
      "y": 19,
      "z": 7,
      "name": "Plant_Leaves_Snow"
    },
    {
      "x": -1,
      "y": 24,
      "z": 7,
      "name": "Plant_Leaves_Petrified",
      "rotation": 1
    },
    {
      "x": -1,
      "y": 18,
      "z": 8,
      "name": "Plant_Leaves_Snow",
      "rotation": 3
    },
    {
      "x": -1,
      "y": 25,
      "z": 8,
      "name": "Plant_Leaves_Petrified",
      "rotation": 1
    },
    {
      "x": -1,
      "y": 26,
      "z": 8,
      "name": "Plant_Leaves_Petrified",
      "rotation": 1
    },
    {
      "x": 0,
      "y": 18,
      "z": -9,
      "name": "Plant_Leaves_Snow",
      "rotation": 2
    },
    {
      "x": 0,
      "y": 19,
      "z": -8,
      "name": "Plant_Leaves_Snow",
      "rotation": 2
    },
    {
      "x": 0,
      "y": 25,
      "z": -8,
      "name": "Wood_Crystal_Trunk_Full",
      "rotation": 3
    },
    {
      "x": 0,
      "y": 26,
      "z": -8,
      "name": "Wood_Crystal_Trunk_Full",
      "rotation": 3
    },
    {
      "x": 0,
      "y": 27,
      "z": -8,
      "name": "Plant_Leaves_Petrified",
      "rotation": 3
    },
    {
      "x": 0,
      "y": 28,
      "z": -8,
      "name": "Plant_Leaves_Petrified",
      "rotation": 3
    },
    {
      "x": 0,
      "y": 19,
      "z": -7,
      "name": "Plant_Leaves_Snow",
      "rotation": 2
    },
    {
      "x": 0,
      "y": 24,
      "z": -7,
      "name": "Wood_Crystal_Trunk_Full",
      "rotation": 3
    },
    {
      "x": 0,
      "y": 25,
      "z": -7,
      "name": "Rock_Crystal_White_Large",
      "rotation": 3
    },
    {
      "x": 0,
      "y": 19,
      "z": -6,
      "name": "Plant_Leaves_Snow",
      "rotation": 2
    },
    {
      "x": 0,
      "y": 20,
      "z": -6,
      "name": "Plant_Leaves_Snow",
      "rotation": 2
    },
    {
      "x": 0,
      "y": 23,
      "z": -6,
      "name": "Wood_Crystal_Trunk_Full",
      "rotation": 3
    },
    {
      "x": 0,
      "y": 24,
      "z": -6,
      "name": "Plant_Leaves_Petrified"
    },
    {
      "x": 0,
      "y": 19,
      "z": -5,
      "name": "Plant_Leaves_Snow",
      "rotation": 2
    },
    {
      "x": 0,
      "y": 23,
      "z": -5,
      "name": "Wood_Crystal_Trunk_Full",
      "rotation": 3
    },
    {
      "x": 0,
      "y": 19,
      "z": -4,
      "name": "Wood_Camphor_Trunk_Full"
    },
    {
      "x": 0,
      "y": 22,
      "z": -4,
      "name": "Wood_Crystal_Trunk_Full",
      "rotation": 3
    },
    {
      "x": 0,
      "y": 0,
      "z": -3,
      "name": "Wood_Camphor_Trunk_Full"
    },
    {
      "x": 0,
      "y": 1,
      "z": -3,
      "name": "Wood_Camphor_Trunk_Full"
    },
    {
      "x": 0,
      "y": 18,
      "z": -3,
      "name": "Wood_Camphor_Trunk_Full"
    },
    {
      "x": 0,
      "y": 19,
      "z": -3,
      "name": "Wood_Camphor_Trunk_Full"
    },
    {
      "x": 0,
      "y": 20,
      "z": -3,
      "name": "Wood_Camphor_Trunk_Full",
      "rotation": 2
    },
    {
      "x": 0,
      "y": 21,
      "z": -3,
      "name": "Wood_Crystal_Trunk_Full",
      "rotation": 3
    },
    {
      "x": 0,
      "y": 28,
      "z": -3,
      "name": "Rock_Crystal_White_Block"
    },
    {
      "x": 0,
      "y": 29,
      "z": -3,
      "name": "Rock_Crystal_White_Block"
    },
    {
      "x": 0,
      "y": 30,
      "z": -3,
      "name": "Rock_Crystal_White_Block"
    },
    {
      "x": 0,
      "y": 0,
      "z": -2,
      "name": "Wood_Camphor_Trunk_Full"
    },
    {
      "x": 0,
      "y": 1,
      "z": -2,
      "name": "Wood_Camphor_Trunk_Full"
    },
    {
      "x": 0,
      "y": 2,
      "z": -2,
      "name": "Wood_Camphor_Trunk_Full"
    },
    {
      "x": 0,
      "y": 3,
      "z": -2,
      "name": "Wood_Camphor_Trunk_Full"
    },
    {
      "x": 0,
      "y": 4,
      "z": -2,
      "name": "Wood_Camphor_Trunk_Full"
    },
    {
      "x": 0,
      "y": 5,
      "z": -2,
      "name": "Wood_Camphor_Trunk_Full"
    },
    {
      "x": 0,
      "y": 6,
      "z": -2,
      "name": "Wood_Camphor_Trunk_Full"
    },
    {
      "x": 0,
      "y": 7,
      "z": -2,
      "name": "Wood_Camphor_Trunk_Full"
    },
    {
      "x": 0,
      "y": 8,
      "z": -2,
      "name": "Wood_Camphor_Trunk_Full"
    },
    {
      "x": 0,
      "y": 9,
      "z": -2,
      "name": "Wood_Camphor_Trunk_Full"
    },
    {
      "x": 0,
      "y": 10,
      "z": -2,
      "name": "Wood_Camphor_Trunk_Full"
    },
    {
      "x": 0,
      "y": 11,
      "z": -2,
      "name": "Wood_Camphor_Trunk_Full"
    },
    {
      "x": 0,
      "y": 12,
      "z": -2,
      "name": "Wood_Camphor_Trunk_Full",
      "rotation": 1
    },
    {
      "x": 0,
      "y": 13,
      "z": -2,
      "name": "Wood_Camphor_Trunk_Full",
      "rotation": 1
    },
    {
      "x": 0,
      "y": 14,
      "z": -2,
      "name": "Wood_Camphor_Trunk_Full",
      "rotation": 2
    },
    {
      "x": 0,
      "y": 15,
      "z": -2,
      "name": "Wood_Camphor_Trunk_Full"
    },
    {
      "x": 0,
      "y": 16,
      "z": -2,
      "name": "Wood_Camphor_Trunk_Full",
      "rotation": 2
    },
    {
      "x": 0,
      "y": 17,
      "z": -2,
      "name": "Wood_Camphor_Trunk_Full"
    },
    {
      "x": 0,
      "y": 20,
      "z": -2,
      "name": "Wood_Crystal_Trunk_Full",
      "rotation": 2
    },
    {
      "x": 0,
      "y": 26,
      "z": -2,
      "name": "Wood_Crystal_Trunk_Full"
    },
    {
      "x": 0,
      "y": 27,
      "z": -2,
      "name": "Rock_Crystal_White_Block"
    },
    {
      "x": 0,
      "y": 31,
      "z": -2,
      "name": "Rock_Crystal_White_Block"
    },
    {
      "x": 0,
      "y": 0,
      "z": -1,
      "name": "Wood_Camphor_Trunk_Full"
    },
    {
      "x": 0,
      "y": 7,
      "z": -1,
      "name": "Wood_Camphor_Trunk_Full"
    },
    {
      "x": 0,
      "y": 8,
      "z": -1,
      "name": "Wood_Camphor_Trunk_Full"
    },
    {
      "x": 0,
      "y": 9,
      "z": -1,
      "name": "Wood_Camphor_Trunk_Full"
    },
    {
      "x": 0,
      "y": 10,
      "z": -1,
      "name": "Wood_Camphor_Trunk_Full"
    },
    {
      "x": 0,
      "y": 11,
      "z": -1,
      "name": "Wood_Camphor_Trunk_Full"
    },
    {
      "x": 0,
      "y": 12,
      "z": -1,
      "name": "Wood_Camphor_Trunk_Full"
    },
    {
      "x": 0,
      "y": 13,
      "z": -1,
      "name": "Wood_Camphor_Trunk_Full"
    },
    {
      "x": 0,
      "y": 14,
      "z": -1,
      "name": "Wood_Camphor_Trunk_Full"
    },
    {
      "x": 0,
      "y": 20,
      "z": -1,
      "name": "Wood_Crystal_Trunk_Full",
      "rotation": 3
    },
    {
      "x": 0,
      "y": 21,
      "z": -1,
      "name": "Wood_Crystal_Trunk_Full",
      "rotation": 3
    },
    {
      "x": 0,
      "y": 25,
      "z": -1,
      "name": "Wood_Crystal_Trunk_Full"
    },
    {
      "x": 0,
      "y": 26,
      "z": -1,
      "name": "Rock_Crystal_White_Block"
    },
    {
      "x": 0,
      "y": 32,
      "z": -1,
      "name": "Rock_Crystal_White_Block"
    },
    {
      "x": 0,
      "y": 0,
      "z": 0,
      "name": "Wood_Camphor_Trunk_Full"
    },
    {
      "x": 0,
      "y": 7,
      "z": 0,
      "name": "Wood_Camphor_Trunk_Full"
    },
    {
      "x": 0,
      "y": 8,
      "z": 0,
      "name": "Wood_Camphor_Trunk_Full"
    },
    {
      "x": 0,
      "y": 13,
      "z": 0,
      "name": "Wood_Camphor_Trunk_Full"
    },
    {
      "x": 0,
      "y": 14,
      "z": 0,
      "name": "Wood_Camphor_Trunk_Full"
    },
    {
      "x": 0,
      "y": 15,
      "z": 0,
      "name": "Wood_Camphor_Trunk_Full"
    },
    {
      "x": 0,
      "y": 20,
      "z": 0,
      "name": "Wood_Crystal_Trunk_Full",
      "rotation": 3
    },
    {
      "x": 0,
      "y": 21,
      "z": 0,
      "name": "Wood_Crystal_Trunk_Full",
      "rotation": 1
    },
    {
      "x": 0,
      "y": 22,
      "z": 0,
      "name": "Wood_Crystal_Trunk_Full",
      "rotation": 1
    },
    {
      "x": 0,
      "y": 23,
      "z": 0,
      "name": "Wood_Crystal_Trunk_Full",
      "rotation": 1
    },
    {
      "x": 0,
      "y": 24,
      "z": 0,
      "name": "Wood_Crystal_Trunk_Full"
    },
    {
      "x": 0,
      "y": 25,
      "z": 0,
      "name": "Wood_Crystal_Trunk_Full"
    },
    {
      "x": 0,
      "y": 26,
      "z": 0,
      "name": "Rock_Crystal_White_Block"
    },
    {
      "x": 0,
      "y": 32,
      "z": 0,
      "name": "Rock_Crystal_White_Block"
    },
    {
      "x": 0,
      "y": 0,
      "z": 1,
      "name": "Wood_Camphor_Trunk_Full"
    },
    {
      "x": 0,
      "y": 5,
      "z": 1,
      "name": "Wood_Camphor_Trunk_Full"
    },
    {
      "x": 0,
      "y": 6,
      "z": 1,
      "name": "Wood_Camphor_Trunk_Full"
    },
    {
      "x": 0,
      "y": 15,
      "z": 1,
      "name": "Wood_Camphor_Trunk_Full"
    },
    {
      "x": 0,
      "y": 16,
      "z": 1,
      "name": "Wood_Camphor_Trunk_Full"
    },
    {
      "x": 0,
      "y": 20,
      "z": 1,
      "name": "Wood_Crystal_Trunk_Full",
      "rotation": 1
    },
    {
      "x": 0,
      "y": 21,
      "z": 1,
      "name": "Wood_Crystal_Trunk_Full",
      "rotation": 1
    },
    {
      "x": 0,
      "y": 25,
      "z": 1,
      "name": "Wood_Crystal_Trunk_Full"
    },
    {
      "x": 0,
      "y": 26,
      "z": 1,
      "name": "Rock_Crystal_White_Block"
    },
    {
      "x": 0,
      "y": 32,
      "z": 1,
      "name": "Rock_Crystal_White_Block"
    },
    {
      "x": 0,
      "y": 0,
      "z": 2,
      "name": "Wood_Camphor_Trunk_Full"
    },
    {
      "x": 0,
      "y": 1,
      "z": 2,
      "name": "Wood_Camphor_Trunk_Full"
    },
    {
      "x": 0,
      "y": 2,
      "z": 2,
      "name": "Wood_Camphor_Trunk_Full"
    },
    {
      "x": 0,
      "y": 3,
      "z": 2,
      "name": "Wood_Camphor_Trunk_Full"
    },
    {
      "x": 0,
      "y": 4,
      "z": 2,
      "name": "Wood_Camphor_Trunk_Full"
    },
    {
      "x": 0,
      "y": 17,
      "z": 2,
      "name": "Wood_Camphor_Trunk_Full"
    },
    {
      "x": 0,
      "y": 20,
      "z": 2,
      "name": "Wood_Crystal_Trunk_Full"
    },
    {
      "x": 0,
      "y": 26,
      "z": 2,
      "name": "Wood_Crystal_Trunk_Full"
    },
    {
      "x": 0,
      "y": 27,
      "z": 2,
      "name": "Rock_Crystal_White_Block"
    },
    {
      "x": 0,
      "y": 31,
      "z": 2,
      "name": "Rock_Crystal_White_Block"
    },
    {
      "x": 0,
      "y": 0,
      "z": 3,
      "name": "Wood_Camphor_Trunk_Full"
    },
    {
      "x": 0,
      "y": 1,
      "z": 3,
      "name": "Wood_Camphor_Trunk_Full"
    },
    {
      "x": 0,
      "y": 2,
      "z": 3,
      "name": "Wood_Camphor_Trunk_Full"
    },
    {
      "x": 0,
      "y": 18,
      "z": 3,
      "name": "Wood_Camphor_Trunk_Full"
    },
    {
      "x": 0,
      "y": 19,
      "z": 3,
      "name": "Wood_Camphor_Trunk_Full"
    },
    {
      "x": 0,
      "y": 20,
      "z": 3,
      "name": "Wood_Camphor_Trunk_Full"
    },
    {
      "x": 0,
      "y": 21,
      "z": 3,
      "name": "Wood_Crystal_Trunk_Full",
      "rotation": 1
    },
    {
      "x": 0,
      "y": 28,
      "z": 3,
      "name": "Rock_Crystal_White_Block"
    },
    {
      "x": 0,
      "y": 29,
      "z": 3,
      "name": "Rock_Crystal_White_Block"
    },
    {
      "x": 0,
      "y": 30,
      "z": 3,
      "name": "Rock_Crystal_White_Block"
    },
    {
      "x": 0,
      "y": 19,
      "z": 4,
      "name": "Wood_Camphor_Trunk_Full",
      "rotation": 2
    },
    {
      "x": 0,
      "y": 22,
      "z": 4,
      "name": "Wood_Crystal_Trunk_Full",
      "rotation": 1
    },
    {
      "x": 0,
      "y": 19,
      "z": 5,
      "name": "Plant_Leaves_Snow"
    },
    {
      "x": 0,
      "y": 23,
      "z": 5,
      "name": "Wood_Crystal_Trunk_Full",
      "rotation": 1
    },
    {
      "x": 0,
      "y": 19,
      "z": 6,
      "name": "Plant_Leaves_Snow"
    },
    {
      "x": 0,
      "y": 20,
      "z": 6,
      "name": "Plant_Leaves_Snow"
    },
    {
      "x": 0,
      "y": 23,
      "z": 6,
      "name": "Wood_Crystal_Trunk_Full",
      "rotation": 1
    },
    {
      "x": 0,
      "y": 19,
      "z": 7,
      "name": "Plant_Leaves_Snow"
    },
    {
      "x": 0,
      "y": 24,
      "z": 7,
      "name": "Wood_Crystal_Trunk_Full",
      "rotation": 1
    },
    {
      "x": 0,
      "y": 25,
      "z": 7,
      "name": "Rock_Crystal_White_Large",
      "rotation": 1
    },
    {
      "x": 0,
      "y": 19,
      "z": 8,
      "name": "Plant_Leaves_Snow"
    },
    {
      "x": 0,
      "y": 25,
      "z": 8,
      "name": "Wood_Crystal_Trunk_Full",
      "rotation": 1
    },
    {
      "x": 0,
      "y": 26,
      "z": 8,
      "name": "Wood_Crystal_Trunk_Full",
      "rotation": 1
    },
    {
      "x": 0,
      "y": 27,
      "z": 8,
      "name": "Plant_Leaves_Petrified",
      "rotation": 1
    },
    {
      "x": 0,
      "y": 28,
      "z": 8,
      "name": "Plant_Leaves_Petrified",
      "rotation": 1
    },
    {
      "x": 0,
      "y": 18,
      "z": 9,
      "name": "Plant_Leaves_Snow"
    },
    {
      "x": 1,
      "y": 18,
      "z": -8,
      "name": "Plant_Leaves_Snow",
      "rotation": 1
    },
    {
      "x": 1,
      "y": 25,
      "z": -8,
      "name": "Plant_Leaves_Petrified",
      "rotation": 3
    },
    {
      "x": 1,
      "y": 26,
      "z": -8,
      "name": "Plant_Leaves_Petrified",
      "rotation": 3
    },
    {
      "x": 1,
      "y": 19,
      "z": -7,
      "name": "Plant_Leaves_Snow",
      "rotation": 2
    },
    {
      "x": 1,
      "y": 24,
      "z": -7,
      "name": "Plant_Leaves_Petrified",
      "rotation": 3
    },
    {
      "x": 1,
      "y": 19,
      "z": -6,
      "name": "Plant_Leaves_Snow",
      "rotation": 2
    },
    {
      "x": 1,
      "y": 23,
      "z": -6,
      "name": "Plant_Leaves_Petrified",
      "rotation": 3
    },
    {
      "x": 1,
      "y": 19,
      "z": -5,
      "name": "Plant_Leaves_Snow",
      "rotation": 2
    },
    {
      "x": 1,
      "y": 23,
      "z": -5,
      "name": "Plant_Leaves_Petrified",
      "rotation": 3
    },
    {
      "x": 1,
      "y": 19,
      "z": -4,
      "name": "Wood_Camphor_Trunk_Full",
      "rotation": 2
    },
    {
      "x": 1,
      "y": 22,
      "z": -4,
      "name": "Plant_Leaves_Petrified",
      "rotation": 3
    },
    {
      "x": 1,
      "y": 0,
      "z": -3,
      "name": "Wood_Camphor_Trunk_Full"
    },
    {
      "x": 1,
      "y": 9,
      "z": -3,
      "name": "Wood_Camphor_Trunk_Full"
    },
    {
      "x": 1,
      "y": 10,
      "z": -3,
      "name": "Wood_Camphor_Trunk_Full"
    },
    {
      "x": 1,
      "y": 11,
      "z": -3,
      "name": "Wood_Camphor_Trunk_Full"
    },
    {
      "x": 1,
      "y": 18,
      "z": -3,
      "name": "Wood_Camphor_Trunk_Full"
    },
    {
      "x": 1,
      "y": 19,
      "z": -3,
      "name": "Wood_Camphor_Trunk_Full"
    },
    {
      "x": 1,
      "y": 20,
      "z": -3,
      "name": "Wood_Camphor_Trunk_Full",
      "rotation": 2
    },
    {
      "x": 1,
      "y": 21,
      "z": -3,
      "name": "Plant_Leaves_Petrified",
      "rotation": 3
    },
    {
      "x": 1,
      "y": 28,
      "z": -3,
      "name": "Rock_Crystal_White_Block"
    },
    {
      "x": 1,
      "y": 29,
      "z": -3,
      "name": "Rock_Crystal_White_Block"
    },
    {
      "x": 1,
      "y": 30,
      "z": -3,
      "name": "Rock_Crystal_White_Block"
    },
    {
      "x": 1,
      "y": 0,
      "z": -2,
      "name": "Wood_Camphor_Trunk_Full"
    },
    {
      "x": 1,
      "y": 1,
      "z": -2,
      "name": "Wood_Camphor_Trunk_Full"
    },
    {
      "x": 1,
      "y": 2,
      "z": -2,
      "name": "Wood_Camphor_Trunk_Full"
    },
    {
      "x": 1,
      "y": 6,
      "z": -2,
      "name": "Wood_Camphor_Trunk_Full"
    },
    {
      "x": 1,
      "y": 7,
      "z": -2,
      "name": "Wood_Camphor_Trunk_Full"
    },
    {
      "x": 1,
      "y": 8,
      "z": -2,
      "name": "Wood_Camphor_Trunk_Full"
    },
    {
      "x": 1,
      "y": 9,
      "z": -2,
      "name": "Wood_Camphor_Trunk_Full"
    },
    {
      "x": 1,
      "y": 11,
      "z": -2,
      "name": "Wood_Camphor_Trunk_Full"
    },
    {
      "x": 1,
      "y": 12,
      "z": -2,
      "name": "Wood_Camphor_Trunk_Full"
    },
    {
      "x": 1,
      "y": 13,
      "z": -2,
      "name": "Wood_Camphor_Trunk_Full"
    },
    {
      "x": 1,
      "y": 14,
      "z": -2,
      "name": "Wood_Camphor_Trunk_Full"
    },
    {
      "x": 1,
      "y": 17,
      "z": -2,
      "name": "Wood_Camphor_Trunk_Full"
    },
    {
      "x": 1,
      "y": 18,
      "z": -2,
      "name": "Wood_Camphor_Trunk_Full"
    },
    {
      "x": 1,
      "y": 19,
      "z": -2,
      "name": "Wood_Camphor_Trunk_Full"
    },
    {
      "x": 1,
      "y": 20,
      "z": -2,
      "name": "Wood_Crystal_Trunk_Full",
      "rotation": 2
    },
    {
      "x": 1,
      "y": 21,
      "z": -2,
      "name": "Plant_Leaves_Petrified",
      "rotation": 3
    },
    {
      "x": 1,
      "y": 27,
      "z": -2,
      "name": "Rock_Crystal_White_Block"
    },
    {
      "x": 1,
      "y": 31,
      "z": -2,
      "name": "Rock_Crystal_White_Block"
    },
    {
      "x": 1,
      "y": 0,
      "z": -1,
      "name": "Wood_Camphor_Trunk_Full"
    },
    {
      "x": 1,
      "y": 2,
      "z": -1,
      "name": "Wood_Camphor_Trunk_Full"
    },
    {
      "x": 1,
      "y": 3,
      "z": -1,
      "name": "Wood_Camphor_Trunk_Full"
    },
    {
      "x": 1,
      "y": 4,
      "z": -1,
      "name": "Wood_Camphor_Trunk_Full"
    },
    {
      "x": 1,
      "y": 5,
      "z": -1,
      "name": "Wood_Camphor_Trunk_Full"
    },
    {
      "x": 1,
      "y": 14,
      "z": -1,
      "name": "Wood_Camphor_Trunk_Full"
    },
    {
      "x": 1,
      "y": 15,
      "z": -1,
      "name": "Wood_Camphor_Trunk_Full"
    },
    {
      "x": 1,
      "y": 16,
      "z": -1,
      "name": "Wood_Camphor_Trunk_Full"
    },
    {
      "x": 1,
      "y": 20,
      "z": -1,
      "name": "Wood_Crystal_Trunk_Full",
      "rotation": 2
    },
    {
      "x": 1,
      "y": 26,
      "z": -1,
      "name": "Rock_Crystal_White_Block"
    },
    {
      "x": 1,
      "y": 32,
      "z": -1,
      "name": "Rock_Crystal_White_Block"
    },
    {
      "x": 1,
      "y": 0,
      "z": 0,
      "name": "Wood_Camphor_Trunk_Full"
    },
    {
      "x": 1,
      "y": 7,
      "z": 0,
      "name": "Wood_Camphor_Trunk_Full"
    },
    {
      "x": 1,
      "y": 8,
      "z": 0,
      "name": "Wood_Camphor_Trunk_Full"
    },
    {
      "x": 1,
      "y": 9,
      "z": 0,
      "name": "Wood_Camphor_Trunk_Full"
    },
    {
      "x": 1,
      "y": 10,
      "z": 0,
      "name": "Wood_Camphor_Trunk_Full"
    },
    {
      "x": 1,
      "y": 11,
      "z": 0,
      "name": "Wood_Camphor_Trunk_Full"
    },
    {
      "x": 1,
      "y": 12,
      "z": 0,
      "name": "Wood_Camphor_Trunk_Full"
    },
    {
      "x": 1,
      "y": 13,
      "z": 0,
      "name": "Wood_Camphor_Trunk_Full"
    },
    {
      "x": 1,
      "y": 14,
      "z": 0,
      "name": "Wood_Camphor_Trunk_Full"
    },
    {
      "x": 1,
      "y": 20,
      "z": 0,
      "name": "Wood_Crystal_Trunk_Full",
      "rotation": 2
    },
    {
      "x": 1,
      "y": 21,
      "z": 0,
      "name": "Wood_Crystal_Trunk_Full",
      "rotation": 2
    },
    {
      "x": 1,
      "y": 25,
      "z": 0,
      "name": "Wood_Crystal_Trunk_Full"
    },
    {
      "x": 1,
      "y": 26,
      "z": 0,
      "name": "Rock_Crystal_White_Block"
    },
    {
      "x": 1,
      "y": 32,
      "z": 0,
      "name": "Rock_Crystal_White_Block"
    },
    {
      "x": 1,
      "y": 0,
      "z": 1,
      "name": "Wood_Camphor_Trunk_Full"
    },
    {
      "x": 1,
      "y": 3,
      "z": 1,
      "name": "Wood_Camphor_Trunk_Full"
    },
    {
      "x": 1,
      "y": 4,
      "z": 1,
      "name": "Wood_Camphor_Trunk_Full"
    },
    {
      "x": 1,
      "y": 5,
      "z": 1,
      "name": "Wood_Camphor_Trunk_Full"
    },
    {
      "x": 1,
      "y": 6,
      "z": 1,
      "name": "Wood_Camphor_Trunk_Full"
    },
    {
      "x": 1,
      "y": 7,
      "z": 1,
      "name": "Wood_Camphor_Trunk_Full"
    },
    {
      "x": 1,
      "y": 14,
      "z": 1,
      "name": "Wood_Camphor_Trunk_Full",
      "rotation": 1
    },
    {
      "x": 1,
      "y": 15,
      "z": 1,
      "name": "Wood_Camphor_Trunk_Full"
    },
    {
      "x": 1,
      "y": 20,
      "z": 1,
      "name": "Wood_Crystal_Trunk_Full",
      "rotation": 1
    },
    {
      "x": 1,
      "y": 26,
      "z": 1,
      "name": "Rock_Crystal_White_Block"
    },
    {
      "x": 1,
      "y": 32,
      "z": 1,
      "name": "Rock_Crystal_White_Block"
    },
    {
      "x": 1,
      "y": 0,
      "z": 2,
      "name": "Wood_Camphor_Trunk_Full"
    },
    {
      "x": 1,
      "y": 1,
      "z": 2,
      "name": "Wood_Camphor_Trunk_Full"
    },
    {
      "x": 1,
      "y": 2,
      "z": 2,
      "name": "Wood_Camphor_Trunk_Full"
    },
    {
      "x": 1,
      "y": 3,
      "z": 2,
      "name": "Wood_Camphor_Trunk_Full"
    },
    {
      "x": 1,
      "y": 16,
      "z": 2,
      "name": "Wood_Camphor_Trunk_Full"
    },
    {
      "x": 1,
      "y": 17,
      "z": 2,
      "name": "Wood_Camphor_Trunk_Full"
    },
    {
      "x": 1,
      "y": 18,
      "z": 2,
      "name": "Wood_Camphor_Trunk_Full"
    },
    {
      "x": 1,
      "y": 19,
      "z": 2,
      "name": "Wood_Camphor_Trunk_Full"
    },
    {
      "x": 1,
      "y": 20,
      "z": 2,
      "name": "Wood_Crystal_Trunk_Full"
    },
    {
      "x": 1,
      "y": 21,
      "z": 2,
      "name": "Plant_Leaves_Petrified",
      "rotation": 2
    },
    {
      "x": 1,
      "y": 27,
      "z": 2,
      "name": "Rock_Crystal_White_Block"
    },
    {
      "x": 1,
      "y": 31,
      "z": 2,
      "name": "Rock_Crystal_White_Block"
    },
    {
      "x": 1,
      "y": 0,
      "z": 3,
      "name": "Wood_Camphor_Trunk_Full"
    },
    {
      "x": 1,
      "y": 1,
      "z": 3,
      "name": "Wood_Camphor_Trunk_Full"
    },
    {
      "x": 1,
      "y": 18,
      "z": 3,
      "name": "Wood_Camphor_Trunk_Full"
    },
    {
      "x": 1,
      "y": 19,
      "z": 3,
      "name": "Wood_Camphor_Trunk_Full"
    },
    {
      "x": 1,
      "y": 20,
      "z": 3,
      "name": "Wood_Camphor_Trunk_Full"
    },
    {
      "x": 1,
      "y": 21,
      "z": 3,
      "name": "Plant_Leaves_Petrified",
      "rotation": 2
    },
    {
      "x": 1,
      "y": 28,
      "z": 3,
      "name": "Rock_Crystal_White_Block"
    },
    {
      "x": 1,
      "y": 29,
      "z": 3,
      "name": "Rock_Crystal_White_Block"
    },
    {
      "x": 1,
      "y": 30,
      "z": 3,
      "name": "Rock_Crystal_White_Block"
    },
    {
      "x": 1,
      "y": 19,
      "z": 4,
      "name": "Wood_Camphor_Trunk_Full",
      "rotation": 2
    },
    {
      "x": 1,
      "y": 20,
      "z": 4,
      "name": "Rock_Crystal_White_Large",
      "rotation": 2
    },
    {
      "x": 1,
      "y": 22,
      "z": 4,
      "name": "Plant_Leaves_Petrified",
      "rotation": 2
    },
    {
      "x": 1,
      "y": 19,
      "z": 5,
      "name": "Wood_Camphor_Trunk_Full",
      "rotation": 2
    },
    {
      "x": 1,
      "y": 20,
      "z": 5,
      "name": "Plant_Leaves_Snow"
    },
    {
      "x": 1,
      "y": 23,
      "z": 5,
      "name": "Plant_Leaves_Petrified",
      "rotation": 2
    },
    {
      "x": 1,
      "y": 19,
      "z": 6,
      "name": "Wood_Camphor_Trunk_Full",
      "rotation": 2
    },
    {
      "x": 1,
      "y": 20,
      "z": 6,
      "name": "Plant_Leaves_Snow"
    },
    {
      "x": 1,
      "y": 23,
      "z": 6,
      "name": "Plant_Leaves_Petrified",
      "rotation": 2
    },
    {
      "x": 1,
      "y": 19,
      "z": 7,
      "name": "Plant_Leaves_Snow"
    },
    {
      "x": 1,
      "y": 20,
      "z": 7,
      "name": "Plant_Leaves_Snow"
    },
    {
      "x": 1,
      "y": 24,
      "z": 7,
      "name": "Plant_Leaves_Petrified",
      "rotation": 2
    },
    {
      "x": 1,
      "y": 18,
      "z": 8,
      "name": "Plant_Leaves_Snow"
    },
    {
      "x": 1,
      "y": 19,
      "z": 8,
      "name": "Plant_Leaves_Snow"
    },
    {
      "x": 1,
      "y": 25,
      "z": 8,
      "name": "Plant_Leaves_Petrified",
      "rotation": 2
    },
    {
      "x": 1,
      "y": 26,
      "z": 8,
      "name": "Plant_Leaves_Petrified",
      "rotation": 2
    },
    {
      "x": 1,
      "y": 18,
      "z": 9,
      "name": "Plant_Leaves_Snow"
    },
    {
      "x": 1,
      "y": 19,
      "z": 9,
      "name": "Plant_Leaves_Snow"
    },
    {
      "x": 1,
      "y": 18,
      "z": 10,
      "name": "Plant_Leaves_Snow",
      "rotation": 2
    },
    {
      "x": 1,
      "y": 17,
      "z": 11,
      "name": "Plant_Leaves_Snow",
      "rotation": 2
    },
    {
      "x": 2,
      "y": 17,
      "z": -9,
      "name": "Plant_Leaves_Snow",
      "rotation": 1
    },
    {
      "x": 2,
      "y": 18,
      "z": -8,
      "name": "Plant_Leaves_Snow",
      "rotation": 1
    },
    {
      "x": 2,
      "y": 18,
      "z": -7,
      "name": "Plant_Leaves_Snow",
      "rotation": 1
    },
    {
      "x": 2,
      "y": 19,
      "z": -7,
      "name": "Plant_Leaves_Snow",
      "rotation": 1
    },
    {
      "x": 2,
      "y": 19,
      "z": -6,
      "name": "Plant_Leaves_Snow",
      "rotation": 1
    },
    {
      "x": 2,
      "y": 20,
      "z": -6,
      "name": "Plant_Leaves_Snow",
      "rotation": 1
    },
    {
      "x": 2,
      "y": 19,
      "z": -5,
      "name": "Wood_Camphor_Trunk_Full"
    },
    {
      "x": 2,
      "y": 20,
      "z": -5,
      "name": "Plant_Leaves_Snow",
      "rotation": 1
    },
    {
      "x": 2,
      "y": 19,
      "z": -4,
      "name": "Wood_Camphor_Trunk_Full"
    },
    {
      "x": 2,
      "y": 20,
      "z": -4,
      "name": "Rock_Crystal_White_Large"
    },
    {
      "x": 2,
      "y": 19,
      "z": -3,
      "name": "Wood_Camphor_Trunk_Full"
    },
    {
      "x": 2,
      "y": 22,
      "z": -3,
      "name": "Plant_Leaves_Petrified",
      "rotation": 3
    },
    {
      "x": 2,
      "y": 0,
      "z": -2,
      "name": "Wood_Camphor_Trunk_Full"
    },
    {
      "x": 2,
      "y": 8,
      "z": -2,
      "name": "Wood_Camphor_Trunk_Full"
    },
    {
      "x": 2,
      "y": 9,
      "z": -2,
      "name": "Wood_Camphor_Trunk_Full"
    },
    {
      "x": 2,
      "y": 10,
      "z": -2,
      "name": "Wood_Camphor_Trunk_Full"
    },
    {
      "x": 2,
      "y": 11,
      "z": -2,
      "name": "Wood_Camphor_Trunk_Full"
    },
    {
      "x": 2,
      "y": 12,
      "z": -2,
      "name": "Wood_Camphor_Trunk_Full"
    },
    {
      "x": 2,
      "y": 18,
      "z": -2,
      "name": "Wood_Camphor_Trunk_Full"
    },
    {
      "x": 2,
      "y": 19,
      "z": -2,
      "name": "Wood_Camphor_Trunk_Full"
    },
    {
      "x": 2,
      "y": 20,
      "z": -2,
      "name": "Wood_Camphor_Trunk_Full",
      "rotation": 1
    },
    {
      "x": 2,
      "y": 21,
      "z": -2,
      "name": "Wood_Crystal_Trunk_Full",
      "rotation": 3
    },
    {
      "x": 2,
      "y": 28,
      "z": -2,
      "name": "Rock_Crystal_White_Block"
    },
    {
      "x": 2,
      "y": 29,
      "z": -2,
      "name": "Rock_Crystal_White_Block"
    },
    {
      "x": 2,
      "y": 30,
      "z": -2,
      "name": "Rock_Crystal_White_Block"
    },
    {
      "x": 2,
      "y": 0,
      "z": -1,
      "name": "Wood_Camphor_Trunk_Full"
    },
    {
      "x": 2,
      "y": 1,
      "z": -1,
      "name": "Wood_Camphor_Trunk_Full"
    },
    {
      "x": 2,
      "y": 2,
      "z": -1,
      "name": "Wood_Camphor_Trunk_Full"
    },
    {
      "x": 2,
      "y": 6,
      "z": -1,
      "name": "Wood_Camphor_Trunk_Full"
    },
    {
      "x": 2,
      "y": 7,
      "z": -1,
      "name": "Wood_Camphor_Trunk_Full"
    },
    {
      "x": 2,
      "y": 8,
      "z": -1,
      "name": "Wood_Camphor_Trunk_Full"
    },
    {
      "x": 2,
      "y": 9,
      "z": -1,
      "name": "Wood_Camphor_Trunk_Full"
    },
    {
      "x": 2,
      "y": 11,
      "z": -1,
      "name": "Wood_Camphor_Trunk_Full"
    },
    {
      "x": 2,
      "y": 12,
      "z": -1,
      "name": "Wood_Camphor_Trunk_Full"
    },
    {
      "x": 2,
      "y": 13,
      "z": -1,
      "name": "Wood_Camphor_Trunk_Full"
    },
    {
      "x": 2,
      "y": 14,
      "z": -1,
      "name": "Wood_Camphor_Trunk_Full"
    },
    {
      "x": 2,
      "y": 17,
      "z": -1,
      "name": "Wood_Camphor_Trunk_Full"
    },
    {
      "x": 2,
      "y": 18,
      "z": -1,
      "name": "Wood_Camphor_Trunk_Full"
    },
    {
      "x": 2,
      "y": 19,
      "z": -1,
      "name": "Wood_Camphor_Trunk_Full"
    },
    {
      "x": 2,
      "y": 20,
      "z": -1,
      "name": "Wood_Crystal_Trunk_Full",
      "rotation": 1
    },
    {
      "x": 2,
      "y": 21,
      "z": -1,
      "name": "Plant_Leaves_Petrified",
      "rotation": 3
    },
    {
      "x": 2,
      "y": 27,
      "z": -1,
      "name": "Rock_Crystal_White_Block"
    },
    {
      "x": 2,
      "y": 31,
      "z": -1,
      "name": "Rock_Crystal_White_Block"
    },
    {
      "x": 2,
      "y": 0,
      "z": 0,
      "name": "Wood_Camphor_Trunk_Full"
    },
    {
      "x": 2,
      "y": 1,
      "z": 0,
      "name": "Wood_Camphor_Trunk_Full"
    },
    {
      "x": 2,
      "y": 2,
      "z": 0,
      "name": "Wood_Camphor_Trunk_Full"
    },
    {
      "x": 2,
      "y": 3,
      "z": 0,
      "name": "Wood_Camphor_Trunk_Full"
    },
    {
      "x": 2,
      "y": 4,
      "z": 0,
      "name": "Wood_Camphor_Trunk_Full"
    },
    {
      "x": 2,
      "y": 5,
      "z": 0,
      "name": "Wood_Camphor_Trunk_Full"
    },
    {
      "x": 2,
      "y": 6,
      "z": 0,
      "name": "Wood_Camphor_Trunk_Full"
    },
    {
      "x": 2,
      "y": 7,
      "z": 0,
      "name": "Wood_Camphor_Trunk_Full"
    },
    {
      "x": 2,
      "y": 8,
      "z": 0,
      "name": "Wood_Camphor_Trunk_Full"
    },
    {
      "x": 2,
      "y": 9,
      "z": 0,
      "name": "Wood_Camphor_Trunk_Full",
      "rotation": 3
    },
    {
      "x": 2,
      "y": 10,
      "z": 0,
      "name": "Wood_Camphor_Trunk_Full",
      "rotation": 3
    },
    {
      "x": 2,
      "y": 11,
      "z": 0,
      "name": "Wood_Camphor_Trunk_Full"
    },
    {
      "x": 2,
      "y": 12,
      "z": 0,
      "name": "Wood_Camphor_Trunk_Full"
    },
    {
      "x": 2,
      "y": 13,
      "z": 0,
      "name": "Wood_Camphor_Trunk_Full"
    },
    {
      "x": 2,
      "y": 14,
      "z": 0,
      "name": "Wood_Camphor_Trunk_Full"
    },
    {
      "x": 2,
      "y": 15,
      "z": 0,
      "name": "Wood_Camphor_Trunk_Full",
      "rotation": 1
    },
    {
      "x": 2,
      "y": 16,
      "z": 0,
      "name": "Wood_Camphor_Trunk_Full",
      "rotation": 1
    },
    {
      "x": 2,
      "y": 17,
      "z": 0,
      "name": "Wood_Camphor_Trunk_Full"
    },
    {
      "x": 2,
      "y": 20,
      "z": 0,
      "name": "Wood_Crystal_Trunk_Full",
      "rotation": 1
    },
    {
      "x": 2,
      "y": 26,
      "z": 0,
      "name": "Wood_Crystal_Trunk_Full"
    },
    {
      "x": 2,
      "y": 27,
      "z": 0,
      "name": "Rock_Crystal_White_Block"
    },
    {
      "x": 2,
      "y": 31,
      "z": 0,
      "name": "Rock_Crystal_White_Block"
    },
    {
      "x": 2,
      "y": 0,
      "z": 1,
      "name": "Wood_Camphor_Trunk_Full"
    },
    {
      "x": 2,
      "y": 1,
      "z": 1,
      "name": "Wood_Camphor_Trunk_Full"
    },
    {
      "x": 2,
      "y": 2,
      "z": 1,
      "name": "Wood_Camphor_Trunk_Full"
    },
    {
      "x": 2,
      "y": 3,
      "z": 1,
      "name": "Wood_Camphor_Trunk_Full"
    },
    {
      "x": 2,
      "y": 4,
      "z": 1,
      "name": "Wood_Camphor_Trunk_Full"
    },
    {
      "x": 2,
      "y": 16,
      "z": 1,
      "name": "Wood_Camphor_Trunk_Full"
    },
    {
      "x": 2,
      "y": 17,
      "z": 1,
      "name": "Wood_Camphor_Trunk_Full"
    },
    {
      "x": 2,
      "y": 18,
      "z": 1,
      "name": "Wood_Camphor_Trunk_Full"
    },
    {
      "x": 2,
      "y": 19,
      "z": 1,
      "name": "Wood_Camphor_Trunk_Full"
    },
    {
      "x": 2,
      "y": 20,
      "z": 1,
      "name": "Wood_Crystal_Trunk_Full",
      "rotation": 1
    },
    {
      "x": 2,
      "y": 21,
      "z": 1,
      "name": "Plant_Leaves_Petrified",
      "rotation": 2
    },
    {
      "x": 2,
      "y": 27,
      "z": 1,
      "name": "Rock_Crystal_White_Block"
    },
    {
      "x": 2,
      "y": 31,
      "z": 1,
      "name": "Rock_Crystal_White_Block"
    },
    {
      "x": 2,
      "y": 0,
      "z": 2,
      "name": "Wood_Camphor_Trunk_Full"
    },
    {
      "x": 2,
      "y": 1,
      "z": 2,
      "name": "Wood_Camphor_Trunk_Full"
    },
    {
      "x": 2,
      "y": 2,
      "z": 2,
      "name": "Wood_Camphor_Trunk_Full"
    },
    {
      "x": 2,
      "y": 18,
      "z": 2,
      "name": "Wood_Camphor_Trunk_Full"
    },
    {
      "x": 2,
      "y": 19,
      "z": 2,
      "name": "Wood_Camphor_Trunk_Full"
    },
    {
      "x": 2,
      "y": 20,
      "z": 2,
      "name": "Wood_Camphor_Trunk_Full"
    },
    {
      "x": 2,
      "y": 21,
      "z": 2,
      "name": "Wood_Crystal_Trunk_Full",
      "rotation": 2
    },
    {
      "x": 2,
      "y": 28,
      "z": 2,
      "name": "Rock_Crystal_White_Block"
    },
    {
      "x": 2,
      "y": 29,
      "z": 2,
      "name": "Rock_Crystal_White_Block"
    },
    {
      "x": 2,
      "y": 30,
      "z": 2,
      "name": "Rock_Crystal_White_Block"
    },
    {
      "x": 2,
      "y": 19,
      "z": 3,
      "name": "Wood_Camphor_Trunk_Full"
    },
    {
      "x": 2,
      "y": 22,
      "z": 3,
      "name": "Plant_Leaves_Petrified",
      "rotation": 2
    },
    {
      "x": 2,
      "y": 19,
      "z": 4,
      "name": "Wood_Camphor_Trunk_Full"
    },
    {
      "x": 2,
      "y": 19,
      "z": 5,
      "name": "Wood_Camphor_Trunk_Full",
      "rotation": 2
    },
    {
      "x": 2,
      "y": 20,
      "z": 5,
      "name": "Plant_Leaves_Snow"
    },
    {
      "x": 2,
      "y": 19,
      "z": 6,
      "name": "Wood_Camphor_Trunk_Full",
      "rotation": 2
    },
    {
      "x": 2,
      "y": 20,
      "z": 6,
      "name": "Plant_Leaves_Snow"
    },
    {
      "x": 2,
      "y": 19,
      "z": 7,
      "name": "Wood_Camphor_Trunk_Full",
      "rotation": 2
    },
    {
      "x": 2,
      "y": 20,
      "z": 7,
      "name": "Plant_Leaves_Snow"
    },
    {
      "x": 2,
      "y": 18,
      "z": 8,
      "name": "Wood_Camphor_Trunk_Full",
      "rotation": 2
    },
    {
      "x": 2,
      "y": 19,
      "z": 8,
      "name": "Plant_Leaves_Snow"
    },
    {
      "x": 2,
      "y": 18,
      "z": 9,
      "name": "Plant_Leaves_Snow"
    },
    {
      "x": 2,
      "y": 19,
      "z": 9,
      "name": "Plant_Leaves_Snow"
    },
    {
      "x": 2,
      "y": 17,
      "z": 10,
      "name": "Plant_Leaves_Snow"
    },
    {
      "x": 2,
      "y": 18,
      "z": 10,
      "name": "Plant_Leaves_Snow"
    },
    {
      "x": 2,
      "y": 17,
      "z": 11,
      "name": "Plant_Leaves_Snow"
    },
    {
      "x": 2,
      "y": 18,
      "z": 11,
      "name": "Plant_Leaves_Snow",
      "rotation": 2
    },
    {
      "x": 2,
      "y": 17,
      "z": 12,
      "name": "Plant_Leaves_Snow",
      "rotation": 2
    },
    {
      "x": 2,
      "y": 17,
      "z": 13,
      "name": "Plant_Leaves_Snow",
      "rotation": 2
    },
    {
      "x": 3,
      "y": 16,
      "z": -10,
      "name": "Plant_Leaves_Snow",
      "rotation": 1
    },
    {
      "x": 3,
      "y": 17,
      "z": -9,
      "name": "Plant_Leaves_Snow",
      "rotation": 1
    },
    {
      "x": 3,
      "y": 18,
      "z": -9,
      "name": "Plant_Leaves_Snow",
      "rotation": 1
    },
    {
      "x": 3,
      "y": 18,
      "z": -8,
      "name": "Plant_Leaves_Snow",
      "rotation": 1
    },
    {
      "x": 3,
      "y": 19,
      "z": -8,
      "name": "Plant_Leaves_Snow",
      "rotation": 1
    },
    {
      "x": 3,
      "y": 18,
      "z": -7,
      "name": "Wood_Camphor_Trunk_Full"
    },
    {
      "x": 3,
      "y": 19,
      "z": -7,
      "name": "Plant_Leaves_Snow",
      "rotation": 1
    },
    {
      "x": 3,
      "y": 20,
      "z": -7,
      "name": "Plant_Leaves_Snow",
      "rotation": 1
    },
    {
      "x": 3,
      "y": 19,
      "z": -6,
      "name": "Wood_Camphor_Trunk_Full"
    },
    {
      "x": 3,
      "y": 20,
      "z": -6,
      "name": "Plant_Leaves_Snow",
      "rotation": 1
    },
    {
      "x": 3,
      "y": 19,
      "z": -5,
      "name": "Wood_Camphor_Trunk_Full"
    },
    {
      "x": 3,
      "y": 20,
      "z": -5,
      "name": "Plant_Leaves_Snow",
      "rotation": 1
    },
    {
      "x": 3,
      "y": 23,
      "z": -5,
      "name": "Plant_Leaves_Petrified",
      "rotation": 3
    },
    {
      "x": 3,
      "y": 24,
      "z": -5,
      "name": "Plant_Leaves_Petrified",
      "rotation": 3
    },
    {
      "x": 3,
      "y": 19,
      "z": -4,
      "name": "Wood_Camphor_Trunk_Full",
      "rotation": 1
    },
    {
      "x": 3,
      "y": 20,
      "z": -4,
      "name": "Plant_Leaves_Snow",
      "rotation": 1
    },
    {
      "x": 3,
      "y": 22,
      "z": -4,
      "name": "Plant_Leaves_Petrified",
      "rotation": 3
    },
    {
      "x": 3,
      "y": 19,
      "z": -3,
      "name": "Wood_Camphor_Trunk_Full",
      "rotation": 1
    },
    {
      "x": 3,
      "y": 22,
      "z": -3,
      "name": "Wood_Crystal_Trunk_Full",
      "rotation": 3
    },
    {
      "x": 3,
      "y": 19,
      "z": -2,
      "name": "Wood_Camphor_Trunk_Full",
      "rotation": 1
    },
    {
      "x": 3,
      "y": 22,
      "z": -2,
      "name": "Plant_Leaves_Petrified",
      "rotation": 3
    },
    {
      "x": 3,
      "y": 0,
      "z": -1,
      "name": "Wood_Camphor_Trunk_Full"
    },
    {
      "x": 3,
      "y": 9,
      "z": -1,
      "name": "Wood_Camphor_Trunk_Full"
    },
    {
      "x": 3,
      "y": 10,
      "z": -1,
      "name": "Wood_Camphor_Trunk_Full"
    },
    {
      "x": 3,
      "y": 11,
      "z": -1,
      "name": "Wood_Camphor_Trunk_Full"
    },
    {
      "x": 3,
      "y": 18,
      "z": -1,
      "name": "Wood_Camphor_Trunk_Full"
    },
    {
      "x": 3,
      "y": 19,
      "z": -1,
      "name": "Wood_Camphor_Trunk_Full"
    },
    {
      "x": 3,
      "y": 20,
      "z": -1,
      "name": "Wood_Camphor_Trunk_Full",
      "rotation": 1
    },
    {
      "x": 3,
      "y": 21,
      "z": -1,
      "name": "Plant_Leaves_Petrified",
      "rotation": 3
    },
    {
      "x": 3,
      "y": 28,
      "z": -1,
      "name": "Rock_Crystal_White_Block"
    },
    {
      "x": 3,
      "y": 29,
      "z": -1,
      "name": "Rock_Crystal_White_Block"
    },
    {
      "x": 3,
      "y": 30,
      "z": -1,
      "name": "Rock_Crystal_White_Block"
    },
    {
      "x": 3,
      "y": 0,
      "z": 0,
      "name": "Wood_Camphor_Trunk_Full"
    },
    {
      "x": 3,
      "y": 1,
      "z": 0,
      "name": "Wood_Camphor_Trunk_Full"
    },
    {
      "x": 3,
      "y": 18,
      "z": 0,
      "name": "Wood_Camphor_Trunk_Full"
    },
    {
      "x": 3,
      "y": 19,
      "z": 0,
      "name": "Wood_Camphor_Trunk_Full"
    },
    {
      "x": 3,
      "y": 20,
      "z": 0,
      "name": "Wood_Camphor_Trunk_Full",
      "rotation": 1
    },
    {
      "x": 3,
      "y": 21,
      "z": 0,
      "name": "Wood_Crystal_Trunk_Full",
      "rotation": 2
    },
    {
      "x": 3,
      "y": 28,
      "z": 0,
      "name": "Rock_Crystal_White_Block"
    },
    {
      "x": 3,
      "y": 29,
      "z": 0,
      "name": "Rock_Crystal_White_Block"
    },
    {
      "x": 3,
      "y": 30,
      "z": 0,
      "name": "Rock_Crystal_White_Block"
    },
    {
      "x": 3,
      "y": 0,
      "z": 1,
      "name": "Wood_Camphor_Trunk_Full"
    },
    {
      "x": 3,
      "y": 1,
      "z": 1,
      "name": "Wood_Camphor_Trunk_Full"
    },
    {
      "x": 3,
      "y": 18,
