{
  "version": 8,
  "blockIdVersion": 11,
  "anchorX": 0,
  "anchorY": 0,
  "anchorZ": 0,
  "blocks": [
    {
      "x": -2,
      "y": 0,
      "z": 0,
      "name": "Rock_Crystal_White_Small",
      "rotation": 7
    },
    {
      "x": -2,
      "y": 1,
      "z": 0,
      "name": "Rock_Crystal_White_Small",
      "rotation": 7
    },
    {
      "x": -1,
      "y": -1,
      "z": -1,
      "name": "Rock_Crystal_White_Block"
    },
    {
      "x": -1,
      "y": 0,
      "z": -1,
      "name": "Rock_Crystal_White_Block"
    },
    {
      "x": -1,
      "y": 1,
      "z": -1,
      "name": "Rock_Crystal_White_Medium",
      "rotation": 7
    },
    {
      "x": -1,
      "y": 2,
      "z": -1,
      "name": "Rock_Crystal_White_Small",
      "rotation": 6
    },
    {
      "x": -1,
      "y": -1,
      "z": 0,
      "name": "Rock_Crystal_White_Block"
    },
    {
      "x": -1,
      "y": 0,
      "z": 0,
      "name": "Rock_Crystal_White_Block"
    },
    {
      "x": -1,
      "y": 1,
      "z": 0,
      "name": "Rock_Crystal_White_Block"
    },
    {
      "x": -1,
      "y": 2,
      "z": 0,
      "name": "Rock_Crystal_White_Block"
    },
    {
      "x": -1,
      "y": 3,
      "z": 0,
      "name": "Rock_Crystal_White_Block"
    },
    {
      "x": -1,
      "y": 4,
      "z": 0,
      "name": "Rock_Crystal_White_Block"
    },
    {
      "x": -1,
      "y": 5,
      "z": 0,
      "name": "Rock_Crystal_White_Medium",
      "rotation": 7
    },
    {
      "x": -1,
      "y": 6,
      "z": 0,
      "name": "Rock_Crystal_White_Medium",
      "rotation": 7
    },
    {
      "x": -1,
      "y": 7,
      "z": 0,
      "name": "Rock_Crystal_White_Small",
      "rotation": 7
    },
    {
      "x": -1,
      "y": 8,
      "z": 0,
      "name": "Rock_Crystal_White_Small",
      "rotation": 7
    },
    {
      "x": -1,
      "y": -1,
      "z": 1,
      "name": "Rock_Crystal_White_Block"
    },
    {
      "x": -1,
      "y": 0,
      "z": 1,
      "name": "Rock_Crystal_White_Block"
    },
    {
      "x": -1,
      "y": 1,
      "z": 1,
      "name": "Rock_Crystal_White_Medium",
      "rotation": 7
    },
    {
      "x": -1,
      "y": 2,
      "z": 1,
      "name": "Rock_Crystal_White_Small",
      "rotation": 4
    },
    {
      "x": 0,
      "y": 0,
      "z": -2,
      "name": "Rock_Crystal_White_Small",
      "rotation": 6
    },
    {
      "x": 0,
      "y": 1,
      "z": -2,
      "name": "Rock_Crystal_White_Small",
      "rotation": 6
    },
    {
      "x": 0,
      "y": -1,
      "z": -1,
      "name": "Rock_Crystal_White_Block"
    },
    {
      "x": 0,
      "y": 0,
      "z": -1,
      "name": "Rock_Crystal_White_Block"
    },
    {
      "x": 0,
      "y": 1,
      "z": -1,
      "name": "Rock_Crystal_White_Block"
    },
    {
      "x": 0,
      "y": 2,
      "z": -1,
      "name": "Rock_Crystal_White_Block"
    },
    {
      "x": 0,
      "y": 3,
      "z": -1,
      "name": "Rock_Crystal_White_Block"
    },
    {
      "x": 0,
      "y": 4,
      "z": -1,
      "name": "Rock_Crystal_White_Block"
    },
    {
      "x": 0,
      "y": 5,
      "z": -1,
      "name": "Rock_Crystal_White_Medium",
      "rotation": 6
    },
    {
      "x": 0,
      "y": 6,
      "z": -1,
      "name": "Rock_Crystal_White_Medium",
      "rotation": 6
    },
    {
      "x": 0,
      "y": 7,
      "z": -1,
      "name": "Rock_Crystal_White_Small",
      "rotation": 6
    },
    {
      "x": 0,
      "y": 8,
      "z": -1,
      "name": "Rock_Crystal_White_Small",
      "rotation": 6
    },
    {
      "x": 0,
      "y": -1,
      "z": 0,
      "name": "Rock_Crystal_White_Block"
    },
    {
      "x": 0,
      "y": 0,
      "z": 0,
      "name": "Rock_Crystal_White_Block"
    },
    {
      "x": 0,
      "y": 1,
      "z": 0,
      "name": "Rock_Crystal_White_Block"
    },
    {
      "x": 0,
      "y": 2,
      "z": 0,
      "name": "Rock_Crystal_White_Block"
    },
    {
      "x": 0,
      "y": 3,
      "z": 0,
      "name": "Rock_Crystal_White_Block"
    },
    {
      "x": 0,
      "y": 4,
      "z": 0,
      "name": "Rock_Crystal_White_Block"
    },
    {
      "x": 0,
      "y": 5,
      "z": 0,
      "name": "Rock_Crystal_White_Block"
    },
    {
      "x": 0,
      "y": 6,
      "z": 0,
      "name": "Rock_Crystal_White_Block"
    },
    {
      "x": 0,
      "y": 7,
      "z": 0,
      "name": "Rock_Crystal_White_Block"
    },
    {
      "x": 0,
      "y": 8,
      "z": 0,
      "name": "Rock_Crystal_White_Block"
    },
    {
      "x": 0,
      "y": 9,
      "z": 0,
      "name": "Rock_Crystal_White_Block"
    },
    {
      "x": 0,
      "y": 10,
      "z": 0,
      "name": "Rock_Crystal_White_Block"
    },
    {
      "x": 0,
      "y": 11,
      "z": 0,
      "name": "Rock_Crystal_White_Small"
    },
    {
      "x": 0,
      "y": -1,
      "z": 1,
      "name": "Rock_Crystal_White_Block"
    },
    {
      "x": 0,
      "y": 0,
      "z": 1,
      "name": "Rock_Crystal_White_Block"
    },
    {
      "x": 0,
      "y": 1,
      "z": 1,
      "name": "Rock_Crystal_White_Block"
    },
    {
      "x": 0,
      "y": 2,
      "z": 1,
      "name": "Rock_Crystal_White_Block"
    },
    {
      "x": 0,
      "y": 3,
      "z": 1,
      "name": "Rock_Crystal_White_Block"
    },
    {
      "x": 0,
      "y": 4,
      "z": 1,
      "name": "Rock_Crystal_White_Block"
    },
    {
      "x": 0,
      "y": 5,
      "z": 1,
      "name": "Rock_Crystal_White_Medium",
      "rotation": 4
    },
    {
      "x": 0,
      "y": 6,
      "z": 1,
      "name": "Rock_Crystal_White_Medium",
      "rotation": 4
    },
    {
      "x": 0,
      "y": 7,
      "z": 1,
      "name": "Rock_Crystal_White_Small",
      "rotation": 4
    },
    {
      "x": 0,
      "y": 8,
      "z": 1,
      "name": "Rock_Crystal_White_Small",
      "rotation": 4
    },
    {
      "x": 0,
      "y": 0,
      "z": 2,
      "name": "Rock_Crystal_White_Small",
      "rotation": 4
    },
    {
      "x": 0,
      "y": 1,
      "z": 2,
      "name": "Rock_Crystal_White_Small",
      "rotation": 4
    },
    {
      "x": 1,
      "y": -1,
      "z": -1,
      "name": "Rock_Crystal_White_Block"
    },
    {
      "x": 1,
      "y": 0,
      "z": -1,
      "name": "Rock_Crystal_White_Block"
    },
    {
      "x": 1,
      "y": 1,
      "z": -1,
      "name": "Rock_Crystal_White_Medium",
      "rotation": 5
    },
    {
      "x": 1,
      "y": 2,
      "z": -1,
      "name": "Rock_Crystal_White_Small",
      "rotation": 6
    },
    {
      "x": 1,
      "y": -1,
      "z": 0,
      "name": "Rock_Crystal_White_Block"
    },
    {
      "x": 1,
      "y": 0,
      "z": 0,
      "name": "Rock_Crystal_White_Block"
    },
    {
      "x": 1,
      "y": 1,
      "z": 0,
      "name": "Rock_Crystal_White_Block"
    },
    {
      "x": 1,
      "y": 2,
      "z": 0,
      "name": "Rock_Crystal_White_Block"
    },
    {
      "x": 1,
      "y": 3,
      "z": 0,
      "name": "Rock_Crystal_White_Block"
    },
    {
      "x": 1,
      "y": 4,
      "z": 0,
      "name": "Rock_Crystal_White_Block"
    },
    {
      "x": 1,
      "y": 5,
      "z": 0,
      "name": "Rock_Crystal_White_Medium",
      "rotation": 5
    },
    {
      "x": 1,
      "y": 6,
      "z": 0,
      "name": "Rock_Crystal_White_Medium",
      "rotation": 5
    },
    {
      "x": 1,
      "y": 7,
      "z": 0,
      "name": "Rock_Crystal_White_Small",
      "rotation": 5
    },
    {
      "x": 1,
      "y": 8,
      "z": 0,
      "name": "Rock_Crystal_White_Small",
      "rotation": 5
    },
    {
      "x": 1,
      "y": -1,
      "z": 1,
      "name": "Rock_Crystal_White_Block"
    },
    {
      "x": 1,
      "y": 0,
      "z": 1,
      "name": "Rock_Crystal_White_Block"
    },
    {
      "x": 1,
      "y": 1,
      "z": 1,
      "name": "Rock_Crystal_White_Medium",
      "rotation": 5
    },
    {
      "x": 1,
      "y": 2,
      "z": 1,
      "name": "Rock_Crystal_White_Small",
      "rotation": 4
    },
    {
      "x": 2,
      "y": 0,
      "z": 0,
      "name": "Rock_Crystal_White_Small",
      "rotation": 5
    },
    {
      "x": 2,
      "y": 1,
      "z": 0,
      "name": "Rock_Crystal_White_Small",
      "rotation": 5
    }
  ]
}