{
  "version": 8,
  "blockIdVersion": 11,
  "anchorX": 0,
  "anchorY": 1,
  "anchorZ": 0,
  "blocks": [
    {
      "x": -20,
      "y": 68,
      "z": -4,
      "name": "Plant_Leaves_Ash"
    },
    {
      "x": -20,
      "y": 68,
      "z": -3,
      "name": "Plant_Leaves_Ash"
    },
    {
      "x": -20,
      "y": 68,
      "z": -2,
      "name": "Plant_Leaves_Ash"
    },
    {
      "x": -20,
      "y": 68,
      "z": -1,
      "name": "Plant_Leaves_Ash"
    },
    {
      "x": -20,
      "y": 68,
      "z": 0,
      "name": "Plant_Leaves_Ash"
    },
    {
      "x": -20,
      "y": 68,
      "z": 1,
      "name": "Plant_Leaves_Ash"
    },
    {
      "x": -20,
      "y": 68,
      "z": 2,
      "name": "Plant_Leaves_Ash"
    },
    {
      "x": -20,
      "y": 68,
      "z": 3,
      "name": "Plant_Leaves_Ash"
    },
    {
      "x": -20,
      "y": 68,
      "z": 4,
      "name": "Plant_Leaves_Ash"
    },
    {
      "x": -19,
      "y": 68,
      "z": -7,
      "name": "Plant_Leaves_Ash"
    },
    {
      "x": -19,
      "y": 68,
      "z": -6,
      "name": "Plant_Leaves_Ash"
    },
    {
      "x": -19,
      "y": 68,
      "z": -5,
      "name": "Plant_Leaves_Ash"
    },
    {
      "x": -19,
      "y": 68,
      "z": -4,
      "name": "Plant_Leaves_Ash"
    },
    {
      "x": -19,
      "y": 68,
      "z": -3,
      "name": "Plant_Leaves_Ash"
    },
    {
      "x": -19,
      "y": 69,
      "z": -3,
      "name": "Plant_Leaves_Ash"
    },
    {
      "x": -19,
      "y": 68,
      "z": -2,
      "name": "Plant_Leaves_Ash"
    },
    {
      "x": -19,
      "y": 69,
      "z": -2,
      "name": "Plant_Leaves_Ash"
    },
    {
      "x": -19,
      "y": 68,
      "z": -1,
      "name": "Plant_Leaves_Ash"
    },
    {
      "x": -19,
      "y": 69,
      "z": -1,
      "name": "Plant_Leaves_Ash"
    },
    {
      "x": -19,
      "y": 68,
      "z": 0,
      "name": "Plant_Leaves_Ash"
    },
    {
      "x": -19,
      "y": 69,
      "z": 0,
      "name": "Plant_Leaves_Ash"
    },
    {
      "x": -19,
      "y": 68,
      "z": 1,
      "name": "Plant_Leaves_Ash"
    },
    {
      "x": -19,
      "y": 69,
      "z": 1,
      "name": "Plant_Leaves_Ash"
    },
    {
      "x": -19,
      "y": 68,
      "z": 2,
      "name": "Plant_Leaves_Ash"
    },
    {
      "x": -19,
      "y": 69,
      "z": 2,
      "name": "Plant_Leaves_Ash"
    },
    {
      "x": -19,
      "y": 68,
      "z": 3,
      "name": "Plant_Leaves_Ash"
    },
    {
      "x": -19,
      "y": 69,
      "z": 3,
      "name": "Plant_Leaves_Ash"
    },
    {
      "x": -19,
      "y": 68,
      "z": 4,
      "name": "Plant_Leaves_Ash"
    },
    {
      "x": -19,
      "y": 68,
      "z": 5,
      "name": "Plant_Leaves_Ash"
    },
    {
      "x": -19,
      "y": 68,
      "z": 6,
      "name": "Plant_Leaves_Ash"
    },
    {
      "x": -19,
      "y": 68,
      "z": 7,
      "name": "Plant_Leaves_Ash"
    },
    {
      "x": -18,
      "y": 68,
      "z": -9,
      "name": "Plant_Leaves_Ash"
    },
    {
      "x": -18,
      "y": 68,
      "z": -8,
      "name": "Plant_Leaves_Ash"
    },
    {
      "x": -18,
      "y": 68,
      "z": -7,
      "name": "Plant_Leaves_Ash"
    },
    {
      "x": -18,
      "y": 69,
      "z": -7,
      "name": "Plant_Leaves_Ash"
    },
    {
      "x": -18,
      "y": 68,
      "z": -6,
      "name": "Plant_Leaves_Ash"
    },
    {
      "x": -18,
      "y": 69,
      "z": -6,
      "name": "Plant_Leaves_Ash"
    },
    {
      "x": -18,
      "y": 68,
      "z": -5,
      "name": "Plant_Leaves_Ash"
    },
    {
      "x": -18,
      "y": 69,
      "z": -5,
      "name": "Plant_Leaves_Ash"
    },
    {
      "x": -18,
      "y": 68,
      "z": -4,
      "name": "Plant_Leaves_Ash"
    },
    {
      "x": -18,
      "y": 69,
      "z": -4,
      "name": "Plant_Leaves_Ash"
    },
    {
      "x": -18,
      "y": 68,
      "z": -3,
      "name": "Plant_Leaves_Ash"
    },
    {
      "x": -18,
      "y": 69,
      "z": -3,
      "name": "Plant_Leaves_Ash"
    },
    {
      "x": -18,
      "y": 68,
      "z": -2,
      "name": "Plant_Leaves_Ash"
    },
    {
      "x": -18,
      "y": 69,
      "z": -2,
      "name": "Plant_Leaves_Ash"
    },
    {
      "x": -18,
      "y": 68,
      "z": -1,
      "name": "Plant_Leaves_Ash"
    },
    {
      "x": -18,
      "y": 69,
      "z": -1,
      "name": "Plant_Leaves_Ash"
    },
    {
      "x": -18,
      "y": 68,
      "z": 0,
      "name": "Plant_Leaves_Ash"
    },
    {
      "x": -18,
      "y": 69,
      "z": 0,
      "name": "Plant_Leaves_Ash"
    },
    {
      "x": -18,
      "y": 68,
      "z": 1,
      "name": "Plant_Leaves_Ash"
    },
    {
      "x": -18,
      "y": 69,
      "z": 1,
      "name": "Plant_Leaves_Ash"
    },
    {
      "x": -18,
      "y": 68,
      "z": 2,
      "name": "Plant_Leaves_Ash"
    },
    {
      "x": -18,
      "y": 69,
      "z": 2,
      "name": "Plant_Leaves_Ash"
    },
    {
      "x": -18,
      "y": 68,
      "z": 3,
      "name": "Plant_Leaves_Ash"
    },
    {
      "x": -18,
      "y": 69,
      "z": 3,
      "name": "Plant_Leaves_Ash"
    },
    {
      "x": -18,
      "y": 68,
      "z": 4,
      "name": "Plant_Leaves_Ash"
    },
    {
      "x": -18,
      "y": 69,
      "z": 4,
      "name": "Plant_Leaves_Ash"
    },
    {
      "x": -18,
      "y": 68,
      "z": 5,
      "name": "Plant_Leaves_Ash"
    },
    {
      "x": -18,
      "y": 69,
      "z": 5,
      "name": "Plant_Leaves_Ash"
    },
    {
      "x": -18,
      "y": 68,
      "z": 6,
      "name": "Plant_Leaves_Ash"
    },
    {
      "x": -18,
      "y": 69,
      "z": 6,
      "name": "Plant_Leaves_Ash"
    },
    {
      "x": -18,
      "y": 68,
      "z": 7,
      "name": "Plant_Leaves_Ash"
    },
    {
      "x": -18,
      "y": 69,
      "z": 7,
      "name": "Plant_Leaves_Ash"
    },
    {
      "x": -18,
      "y": 68,
      "z": 8,
      "name": "Plant_Leaves_Ash"
    },
    {
      "x": -18,
      "y": 68,
      "z": 9,
      "name": "Plant_Leaves_Ash"
    },
    {
      "x": -17,
      "y": 68,
      "z": -11,
      "name": "Plant_Leaves_Ash"
    },
    {
      "x": -17,
      "y": 68,
      "z": -10,
      "name": "Plant_Leaves_Ash"
    },
    {
      "x": -17,
      "y": 68,
      "z": -9,
      "name": "Plant_Leaves_Ash"
    },
    {
      "x": -17,
      "y": 69,
      "z": -9,
      "name": "Plant_Leaves_Ash"
    },
    {
      "x": -17,
      "y": 68,
      "z": -8,
      "name": "Plant_Leaves_Ash"
    },
    {
      "x": -17,
      "y": 69,
      "z": -8,
      "name": "Plant_Leaves_Ash"
    },
    {
      "x": -17,
      "y": 68,
      "z": -7,
      "name": "Plant_Leaves_Ash"
    },
    {
      "x": -17,
      "y": 69,
      "z": -7,
      "name": "Plant_Leaves_Ash"
    },
    {
      "x": -17,
      "y": 68,
      "z": -6,
      "name": "Plant_Leaves_Ash"
    },
    {
      "x": -17,
      "y": 69,
      "z": -6,
      "name": "Plant_Leaves_Ash"
    },
    {
      "x": -17,
      "y": 68,
      "z": -5,
      "name": "Plant_Leaves_Ash"
    },
    {
      "x": -17,
      "y": 69,
      "z": -5,
      "name": "Plant_Leaves_Ash"
    },
    {
      "x": -17,
      "y": 68,
      "z": -4,
      "name": "Plant_Leaves_Ash"
    },
    {
      "x": -17,
      "y": 69,
      "z": -4,
      "name": "Plant_Leaves_Ash"
    },
    {
      "x": -17,
      "y": 69,
      "z": -3,
      "name": "Plant_Leaves_Ash"
    },
    {
      "x": -17,
      "y": 70,
      "z": -3,
      "name": "Plant_Leaves_Ash"
    },
    {
      "x": -17,
      "y": 69,
      "z": -2,
      "name": "Plant_Leaves_Ash"
    },
    {
      "x": -17,
      "y": 70,
      "z": -2,
      "name": "Plant_Leaves_Ash"
    },
    {
      "x": -17,
      "y": 69,
      "z": -1,
      "name": "Plant_Leaves_Ash"
    },
    {
      "x": -17,
      "y": 70,
      "z": -1,
      "name": "Plant_Leaves_Ash"
    },
    {
      "x": -17,
      "y": 69,
      "z": 0,
      "name": "Plant_Leaves_Ash"
    },
    {
      "x": -17,
      "y": 70,
      "z": 0,
      "name": "Plant_Leaves_Ash"
    },
    {
      "x": -17,
      "y": 69,
      "z": 1,
      "name": "Plant_Leaves_Ash"
    },
    {
      "x": -17,
      "y": 70,
      "z": 1,
      "name": "Plant_Leaves_Ash"
    },
    {
      "x": -17,
      "y": 69,
      "z": 2,
      "name": "Plant_Leaves_Ash"
    },
    {
      "x": -17,
      "y": 70,
      "z": 2,
      "name": "Plant_Leaves_Ash"
    },
    {
      "x": -17,
      "y": 69,
      "z": 3,
      "name": "Plant_Leaves_Ash"
    },
    {
      "x": -17,
      "y": 70,
      "z": 3,
      "name": "Plant_Leaves_Ash"
    },
    {
      "x": -17,
      "y": 68,
      "z": 4,
      "name": "Plant_Leaves_Ash"
    },
    {
      "x": -17,
      "y": 69,
      "z": 4,
      "name": "Plant_Leaves_Ash"
    },
    {
      "x": -17,
      "y": 68,
      "z": 5,
      "name": "Plant_Leaves_Ash"
    },
    {
      "x": -17,
      "y": 69,
      "z": 5,
      "name": "Plant_Leaves_Ash"
    },
    {
      "x": -17,
      "y": 68,
      "z": 6,
      "name": "Plant_Leaves_Ash"
    },
    {
      "x": -17,
      "y": 69,
      "z": 6,
      "name": "Plant_Leaves_Ash"
    },
    {
      "x": -17,
      "y": 68,
      "z": 7,
      "name": "Plant_Leaves_Ash"
    },
    {
      "x": -17,
      "y": 69,
      "z": 7,
      "name": "Plant_Leaves_Ash"
    },
    {
      "x": -17,
      "y": 68,
      "z": 8,
      "name": "Plant_Leaves_Ash"
    },
    {
      "x": -17,
      "y": 69,
      "z": 8,
      "name": "Plant_Leaves_Ash"
    },
    {
      "x": -17,
      "y": 68,
      "z": 9,
      "name": "Plant_Leaves_Ash"
    },
    {
      "x": -17,
      "y": 69,
      "z": 9,
      "name": "Plant_Leaves_Ash"
    },
    {
      "x": -17,
      "y": 68,
      "z": 10,
      "name": "Plant_Leaves_Ash"
    },
    {
      "x": -17,
      "y": 68,
      "z": 11,
      "name": "Plant_Leaves_Ash"
    },
    {
      "x": -16,
      "y": 68,
      "z": -12,
      "name": "Plant_Leaves_Ash"
    },
    {
      "x": -16,
      "y": 68,
      "z": -11,
      "name": "Plant_Leaves_Ash"
    },
    {
      "x": -16,
      "y": 68,
      "z": -10,
      "name": "Plant_Leaves_Ash"
    },
    {
      "x": -16,
      "y": 69,
      "z": -10,
      "name": "Plant_Leaves_Ash"
    },
    {
      "x": -16,
      "y": 68,
      "z": -9,
      "name": "Plant_Leaves_Ash"
    },
    {
      "x": -16,
      "y": 69,
      "z": -9,
      "name": "Plant_Leaves_Ash"
    },
    {
      "x": -16,
      "y": 68,
      "z": -8,
      "name": "Plant_Leaves_Ash"
    },
    {
      "x": -16,
      "y": 69,
      "z": -8,
      "name": "Plant_Leaves_Ash"
    },
    {
      "x": -16,
      "y": 68,
      "z": -7,
      "name": "Plant_Leaves_Ash"
    },
    {
      "x": -16,
      "y": 69,
      "z": -7,
      "name": "Plant_Leaves_Ash"
    },
    {
      "x": -16,
      "y": 69,
      "z": -6,
      "name": "Plant_Leaves_Ash"
    },
    {
      "x": -16,
      "y": 70,
      "z": -6,
      "name": "Plant_Leaves_Ash"
    },
    {
      "x": -16,
      "y": 69,
      "z": -5,
      "name": "Plant_Leaves_Ash"
    },
    {
      "x": -16,
      "y": 70,
      "z": -5,
      "name": "Plant_Leaves_Ash"
    },
    {
      "x": -16,
      "y": 69,
      "z": -4,
      "name": "Plant_Leaves_Ash"
    },
    {
      "x": -16,
      "y": 70,
      "z": -4,
      "name": "Plant_Leaves_Ash"
    },
    {
      "x": -16,
      "y": 69,
      "z": -3,
      "name": "Plant_Leaves_Ash"
    },
    {
      "x": -16,
      "y": 70,
      "z": -3,
      "name": "Plant_Leaves_Ash"
    },
    {
      "x": -16,
      "y": 69,
      "z": -2,
      "name": "Plant_Leaves_Ash"
    },
    {
      "x": -16,
      "y": 70,
      "z": -2,
      "name": "Plant_Leaves_Ash"
    },
    {
      "x": -16,
      "y": 69,
      "z": -1,
      "name": "Plant_Leaves_Ash"
    },
    {
      "x": -16,
      "y": 70,
      "z": -1,
      "name": "Plant_Leaves_Ash"
    },
    {
      "x": -16,
      "y": 69,
      "z": 0,
      "name": "Plant_Leaves_Ash"
    },
    {
      "x": -16,
      "y": 70,
      "z": 0,
      "name": "Plant_Leaves_Ash"
    },
    {
      "x": -16,
      "y": 69,
      "z": 1,
      "name": "Plant_Leaves_Ash"
    },
    {
      "x": -16,
      "y": 70,
      "z": 1,
      "name": "Plant_Leaves_Ash"
    },
    {
      "x": -16,
      "y": 69,
      "z": 2,
      "name": "Plant_Leaves_Ash"
    },
    {
      "x": -16,
      "y": 70,
      "z": 2,
      "name": "Plant_Leaves_Ash"
    },
    {
      "x": -16,
      "y": 69,
      "z": 3,
      "name": "Plant_Leaves_Ash"
    },
    {
      "x": -16,
      "y": 70,
      "z": 3,
      "name": "Plant_Leaves_Ash"
    },
    {
      "x": -16,
      "y": 69,
      "z": 4,
      "name": "Plant_Leaves_Ash"
    },
    {
      "x": -16,
      "y": 70,
      "z": 4,
      "name": "Plant_Leaves_Ash"
    },
    {
      "x": -16,
      "y": 69,
      "z": 5,
      "name": "Plant_Leaves_Ash"
    },
    {
      "x": -16,
      "y": 70,
      "z": 5,
      "name": "Plant_Leaves_Ash"
    },
    {
      "x": -16,
      "y": 69,
      "z": 6,
      "name": "Plant_Leaves_Ash"
    },
    {
      "x": -16,
      "y": 70,
      "z": 6,
      "name": "Plant_Leaves_Ash"
    },
    {
      "x": -16,
      "y": 68,
      "z": 7,
      "name": "Plant_Leaves_Ash"
    },
    {
      "x": -16,
      "y": 69,
      "z": 7,
      "name": "Plant_Leaves_Ash"
    },
    {
      "x": -16,
      "y": 68,
      "z": 8,
      "name": "Plant_Leaves_Ash"
    },
    {
      "x": -16,
      "y": 69,
      "z": 8,
      "name": "Plant_Leaves_Ash"
    },
    {
      "x": -16,
      "y": 68,
      "z": 9,
      "name": "Plant_Leaves_Ash"
    },
    {
      "x": -16,
      "y": 69,
      "z": 9,
      "name": "Plant_Leaves_Ash"
    },
    {
      "x": -16,
      "y": 68,
      "z": 10,
      "name": "Plant_Leaves_Ash"
    },
    {
      "x": -16,
      "y": 69,
      "z": 10,
      "name": "Plant_Leaves_Ash"
    },
    {
      "x": -16,
      "y": 68,
      "z": 11,
      "name": "Plant_Leaves_Ash"
    },
    {
      "x": -16,
      "y": 68,
      "z": 12,
      "name": "Plant_Leaves_Ash"
    },
    {
      "x": -15,
      "y": 68,
      "z": -13,
      "name": "Plant_Leaves_Ash"
    },
    {
      "x": -15,
      "y": 68,
      "z": -12,
      "name": "Plant_Leaves_Ash"
    },
    {
      "x": -15,
      "y": 69,
      "z": -12,
      "name": "Plant_Leaves_Ash"
    },
    {
      "x": -15,
      "y": 68,
      "z": -11,
      "name": "Plant_Leaves_Ash"
    },
    {
      "x": -15,
      "y": 69,
      "z": -11,
      "name": "Plant_Leaves_Ash"
    },
    {
      "x": -15,
      "y": 68,
      "z": -10,
      "name": "Plant_Leaves_Ash"
    },
    {
      "x": -15,
      "y": 69,
      "z": -10,
      "name": "Plant_Leaves_Ash"
    },
    {
      "x": -15,
      "y": 68,
      "z": -9,
      "name": "Plant_Leaves_Ash"
    },
    {
      "x": -15,
      "y": 69,
      "z": -9,
      "name": "Plant_Leaves_Ash"
    },
    {
      "x": -15,
      "y": 69,
      "z": -8,
      "name": "Plant_Leaves_Ash"
    },
    {
      "x": -15,
      "y": 70,
      "z": -8,
      "name": "Plant_Leaves_Ash"
    },
    {
      "x": -15,
      "y": 69,
      "z": -7,
      "name": "Plant_Leaves_Ash"
    },
    {
      "x": -15,
      "y": 70,
      "z": -7,
      "name": "Plant_Leaves_Ash"
    },
    {
      "x": -15,
      "y": 69,
      "z": -6,
      "name": "Plant_Leaves_Ash"
    },
    {
      "x": -15,
      "y": 70,
      "z": -6,
      "name": "Plant_Leaves_Ash"
    },
    {
      "x": -15,
      "y": 69,
      "z": -5,
      "name": "Plant_Leaves_Ash"
    },
    {
      "x": -15,
      "y": 70,
      "z": -5,
      "name": "Plant_Leaves_Ash"
    },
    {
      "x": -15,
      "y": 69,
      "z": -4,
      "name": "Plant_Leaves_Ash"
    },
    {
      "x": -15,
      "y": 70,
      "z": -4,
      "name": "Plant_Leaves_Ash"
    },
    {
      "x": -15,
      "y": 70,
      "z": -3,
      "name": "Plant_Leaves_Ash"
    },
    {
      "x": -15,
      "y": 70,
      "z": -2,
      "name": "Plant_Leaves_Ash"
    },
    {
      "x": -15,
      "y": 70,
      "z": -1,
      "name": "Plant_Leaves_Ash"
    },
    {
      "x": -15,
      "y": 70,
      "z": 0,
      "name": "Plant_Leaves_Ash"
    },
    {
      "x": -15,
      "y": 70,
      "z": 1,
      "name": "Plant_Leaves_Ash"
    },
    {
      "x": -15,
      "y": 70,
      "z": 2,
      "name": "Plant_Leaves_Ash"
    },
    {
      "x": -15,
      "y": 70,
      "z": 3,
      "name": "Plant_Leaves_Ash"
    },
    {
      "x": -15,
      "y": 69,
      "z": 4,
      "name": "Plant_Leaves_Ash"
    },
    {
      "x": -15,
      "y": 70,
      "z": 4,
      "name": "Plant_Leaves_Ash"
    },
    {
      "x": -15,
      "y": 69,
      "z": 5,
      "name": "Plant_Leaves_Ash"
    },
    {
      "x": -15,
      "y": 70,
      "z": 5,
      "name": "Plant_Leaves_Ash"
    },
    {
      "x": -15,
      "y": 69,
      "z": 6,
      "name": "Plant_Leaves_Ash"
    },
    {
      "x": -15,
      "y": 70,
      "z": 6,
      "name": "Plant_Leaves_Ash"
    },
    {
      "x": -15,
      "y": 69,
      "z": 7,
      "name": "Plant_Leaves_Ash"
    },
    {
      "x": -15,
      "y": 70,
      "z": 7,
      "name": "Plant_Leaves_Ash"
    },
    {
      "x": -15,
      "y": 69,
      "z": 8,
      "name": "Plant_Leaves_Ash"
    },
    {
      "x": -15,
      "y": 70,
      "z": 8,
      "name": "Plant_Leaves_Ash"
    },
    {
      "x": -15,
      "y": 68,
      "z": 9,
      "name": "Plant_Leaves_Ash"
    },
    {
      "x": -15,
      "y": 69,
      "z": 9,
      "name": "Plant_Leaves_Ash"
    },
    {
      "x": -15,
      "y": 68,
      "z": 10,
      "name": "Plant_Leaves_Ash"
    },
    {
      "x": -15,
      "y": 69,
      "z": 10,
      "name": "Plant_Leaves_Ash"
    },
    {
      "x": -15,
      "y": 68,
      "z": 11,
      "name": "Plant_Leaves_Ash"
    },
    {
      "x": -15,
      "y": 69,
      "z": 11,
      "name": "Plant_Leaves_Ash"
    },
    {
      "x": -15,
      "y": 68,
      "z": 12,
      "name": "Plant_Leaves_Ash"
    },
    {
      "x": -15,
      "y": 69,
      "z": 12,
      "name": "Plant_Leaves_Ash"
    },
    {
      "x": -15,
      "y": 68,
      "z": 13,
      "name": "Plant_Leaves_Ash"
    },
    {
      "x": -14,
      "y": 68,
      "z": -14,
      "name": "Plant_Leaves_Ash"
    },
    {
      "x": -14,
      "y": 68,
      "z": -13,
      "name": "Plant_Leaves_Ash"
    },
    {
      "x": -14,
      "y": 69,
      "z": -13,
      "name": "Plant_Leaves_Ash"
    },
    {
      "x": -14,
      "y": 68,
      "z": -12,
      "name": "Plant_Leaves_Ash"
    },
    {
      "x": -14,
      "y": 69,
      "z": -12,
      "name": "Plant_Leaves_Ash"
    },
    {
      "x": -14,
      "y": 68,
      "z": -11,
      "name": "Plant_Leaves_Ash"
    },
    {
      "x": -14,
      "y": 69,
      "z": -11,
      "name": "Plant_Leaves_Ash"
    },
    {
      "x": -14,
      "y": 69,
      "z": -10,
      "name": "Plant_Leaves_Ash"
    },
    {
      "x": -14,
      "y": 70,
      "z": -10,
      "name": "Plant_Leaves_Ash"
    },
    {
      "x": -14,
      "y": 69,
      "z": -9,
      "name": "Plant_Leaves_Ash"
    },
    {
      "x": -14,
      "y": 70,
      "z": -9,
      "name": "Plant_Leaves_Ash"
    },
    {
      "x": -14,
      "y": 69,
      "z": -8,
      "name": "Plant_Leaves_Ash"
    },
    {
      "x": -14,
      "y": 70,
      "z": -8,
      "name": "Plant_Leaves_Ash"
    },
    {
      "x": -14,
      "y": 69,
      "z": -7,
      "name": "Plant_Leaves_Ash"
    },
    {
      "x": -14,
      "y": 70,
      "z": -7,
      "name": "Plant_Leaves_Ash"
    },
    {
      "x": -14,
      "y": 70,
      "z": -6,
      "name": "Plant_Leaves_Ash"
    },
    {
      "x": -14,
      "y": 70,
      "z": -5,
      "name": "Plant_Leaves_Ash"
    },
    {
      "x": -14,
      "y": 70,
      "z": -4,
      "name": "Plant_Leaves_Ash"
    },
    {
      "x": -14,
      "y": 70,
      "z": -3,
      "name": "Plant_Leaves_Ash"
    },
    {
      "x": -14,
      "y": 70,
      "z": -2,
      "name": "Plant_Leaves_Ash"
    },
    {
      "x": -14,
      "y": 70,
      "z": -1,
      "name": "Plant_Leaves_Ash"
    },
    {
      "x": -14,
      "y": 70,
      "z": 0,
      "name": "Plant_Leaves_Ash"
    },
    {
      "x": -14,
      "y": 70,
      "z": 1,
      "name": "Plant_Leaves_Ash"
    },
    {
      "x": -14,
      "y": 70,
      "z": 2,
      "name": "Plant_Leaves_Ash"
    },
    {
      "x": -14,
      "y": 70,
      "z": 3,
      "name": "Plant_Leaves_Ash"
    },
    {
      "x": -14,
      "y": 70,
      "z": 4,
      "name": "Plant_Leaves_Ash"
    },
    {
      "x": -14,
      "y": 70,
      "z": 5,
      "name": "Plant_Leaves_Ash"
    },
    {
      "x": -14,
      "y": 70,
      "z": 6,
      "name": "Plant_Leaves_Ash"
    },
    {
      "x": -14,
      "y": 69,
      "z": 7,
      "name": "Plant_Leaves_Ash"
    },
    {
      "x": -14,
      "y": 70,
      "z": 7,
      "name": "Plant_Leaves_Ash"
    },
    {
      "x": -14,
      "y": 69,
      "z": 8,
      "name": "Plant_Leaves_Ash"
    },
    {
      "x": -14,
      "y": 70,
      "z": 8,
      "name": "Plant_Leaves_Ash"
    },
    {
      "x": -14,
      "y": 69,
      "z": 9,
      "name": "Plant_Leaves_Ash"
    },
    {
      "x": -14,
      "y": 70,
      "z": 9,
      "name": "Plant_Leaves_Ash"
    },
    {
      "x": -14,
      "y": 69,
      "z": 10,
      "name": "Plant_Leaves_Ash"
    },
    {
      "x": -14,
      "y": 70,
      "z": 10,
      "name": "Plant_Leaves_Ash"
    },
    {
      "x": -14,
      "y": 68,
      "z": 11,
      "name": "Plant_Leaves_Ash"
    },
    {
      "x": -14,
      "y": 69,
      "z": 11,
      "name": "Plant_Leaves_Ash"
    },
    {
      "x": -14,
      "y": 68,
      "z": 12,
      "name": "Plant_Leaves_Ash"
    },
    {
      "x": -14,
      "y": 69,
      "z": 12,
      "name": "Plant_Leaves_Ash"
    },
    {
      "x": -14,
      "y": 68,
      "z": 13,
      "name": "Plant_Leaves_Ash"
    },
    {
      "x": -14,
      "y": 69,
      "z": 13,
      "name": "Plant_Leaves_Ash"
    },
    {
      "x": -14,
      "y": 68,
      "z": 14,
      "name": "Plant_Leaves_Ash"
    },
    {
      "x": -13,
      "y": 68,
      "z": -15,
      "name": "Plant_Leaves_Ash"
    },
    {
      "x": -13,
      "y": 68,
      "z": -14,
      "name": "Plant_Leaves_Ash"
    },
    {
      "x": -13,
      "y": 69,
      "z": -14,
      "name": "Plant_Leaves_Ash"
    },
    {
      "x": -13,
      "y": 68,
      "z": -13,
      "name": "Plant_Leaves_Ash"
    },
    {
      "x": -13,
      "y": 69,
      "z": -13,
      "name": "Plant_Leaves_Ash"
    },
    {
      "x": -13,
      "y": 68,
      "z": -12,
      "name": "Plant_Leaves_Ash"
    },
    {
      "x": -13,
      "y": 69,
      "z": -12,
      "name": "Plant_Leaves_Ash"
    },
    {
      "x": -13,
      "y": 69,
      "z": -11,
      "name": "Plant_Leaves_Ash"
    },
    {
      "x": -13,
      "y": 70,
      "z": -11,
      "name": "Plant_Leaves_Ash"
    },
    {
      "x": -13,
      "y": 69,
      "z": -10,
      "name": "Plant_Leaves_Ash"
    },
    {
      "x": -13,
      "y": 70,
      "z": -10,
      "name": "Plant_Leaves_Ash"
    },
    {
      "x": -13,
      "y": 69,
      "z": -9,
      "name": "Plant_Leaves_Ash"
    },
    {
      "x": -13,
      "y": 70,
      "z": -9,
      "name": "Plant_Leaves_Ash"
    },
    {
      "x": -13,
      "y": 70,
      "z": -8,
      "name": "Plant_Leaves_Ash"
    },
    {
      "x": -13,
      "y": 70,
      "z": -7,
      "name": "Plant_Leaves_Ash"
    },
    {
      "x": -13,
      "y": 70,
      "z": -6,
      "name": "Plant_Leaves_Ash"
    },
    {
      "x": -13,
      "y": 70,
      "z": -5,
      "name": "Plant_Leaves_Ash"
    },
    {
      "x": -13,
      "y": 70,
      "z": -4,
      "name": "Plant_Leaves_Ash"
    },
    {
      "x": -13,
      "y": 70,
      "z": -3,
      "name": "Plant_Leaves_Ash"
    },
    {
      "x": -13,
      "y": 71,
      "z": -3,
      "name": "Plant_Leaves_Ash"
    },
    {
      "x": -13,
      "y": 70,
      "z": -2,
      "name": "Plant_Leaves_Ash"
    },
    {
      "x": -13,
      "y": 71,
      "z": -2,
      "name": "Plant_Leaves_Ash"
    },
    {
      "x": -13,
      "y": 70,
      "z": -1,
      "name": "Plant_Leaves_Ash"
    },
    {
      "x": -13,
      "y": 71,
      "z": -1,
      "name": "Plant_Leaves_Ash"
    },
    {
      "x": -13,
      "y": 70,
      "z": 0,
      "name": "Plant_Leaves_Ash"
    },
    {
      "x": -13,
      "y": 71,
      "z": 0,
      "name": "Plant_Leaves_Ash"
    },
    {
      "x": -13,
      "y": 70,
      "z": 1,
      "name": "Plant_Leaves_Ash"
    },
    {
      "x": -13,
      "y": 71,
      "z": 1,
      "name": "Plant_Leaves_Ash"
    },
    {
      "x": -13,
      "y": 70,
      "z": 2,
      "name": "Plant_Leaves_Ash"
    },
    {
      "x": -13,
      "y": 71,
      "z": 2,
      "name": "Plant_Leaves_Ash"
    },
    {
      "x": -13,
      "y": 70,
      "z": 3,
      "name": "Plant_Leaves_Ash"
    },
    {
      "x": -13,
      "y": 71,
      "z": 3,
      "name": "Plant_Leaves_Ash"
    },
    {
      "x": -13,
      "y": 70,
      "z": 4,
      "name": "Plant_Leaves_Ash"
    },
    {
      "x": -13,
      "y": 70,
      "z": 5,
      "name": "Plant_Leaves_Ash"
    },
    {
      "x": -13,
      "y": 70,
      "z": 6,
      "name": "Plant_Leaves_Ash"
    },
    {
      "x": -13,
      "y": 70,
      "z": 7,
      "name": "Plant_Leaves_Ash"
    },
    {
      "x": -13,
      "y": 70,
      "z": 8,
      "name": "Plant_Leaves_Ash"
    },
    {
      "x": -13,
      "y": 69,
      "z": 9,
      "name": "Plant_Leaves_Ash"
    },
    {
      "x": -13,
      "y": 70,
      "z": 9,
      "name": "Plant_Leaves_Ash"
    },
    {
      "x": -13,
      "y": 69,
      "z": 10,
      "name": "Plant_Leaves_Ash"
    },
    {
      "x": -13,
      "y": 70,
      "z": 10,
      "name": "Plant_Leaves_Ash"
    },
    {
      "x": -13,
      "y": 69,
      "z": 11,
      "name": "Plant_Leaves_Ash"
    },
    {
      "x": -13,
      "y": 70,
      "z": 11,
      "name": "Plant_Leaves_Ash"
    },
    {
      "x": -13,
      "y": 68,
      "z": 12,
      "name": "Plant_Leaves_Ash"
    },
    {
      "x": -13,
      "y": 69,
      "z": 12,
      "name": "Plant_Leaves_Ash"
    },
    {
      "x": -13,
      "y": 68,
      "z": 13,
      "name": "Plant_Leaves_Ash"
    },
    {
      "x": -13,
      "y": 69,
      "z": 13,
      "name": "Plant_Leaves_Ash"
    },
    {
      "x": -13,
      "y": 68,
      "z": 14,
      "name": "Plant_Leaves_Ash"
    },
    {
      "x": -13,
      "y": 69,
      "z": 14,
      "name": "Plant_Leaves_Ash"
    },
    {
      "x": -13,
      "y": 68,
      "z": 15,
      "name": "Plant_Leaves_Ash"
    },
    {
      "x": -12,
      "y": 68,
      "z": -16,
      "name": "Plant_Leaves_Ash"
    },
    {
      "x": -12,
      "y": 68,
      "z": -15,
      "name": "Plant_Leaves_Ash"
    },
    {
      "x": -12,
      "y": 69,
      "z": -15,
      "name": "Plant_Leaves_Ash"
    },
    {
      "x": -12,
      "y": 68,
      "z": -14,
      "name": "Plant_Leaves_Ash"
    },
    {
      "x": -12,
      "y": 69,
      "z": -14,
      "name": "Plant_Leaves_Ash"
    },
    {
      "x": -12,
      "y": 68,
      "z": -13,
      "name": "Plant_Leaves_Ash"
    },
    {
      "x": -12,
      "y": 69,
      "z": -13,
      "name": "Plant_Leaves_Ash"
    },
    {
      "x": -12,
      "y": 69,
      "z": -12,
      "name": "Plant_Leaves_Ash"
    },
    {
      "x": -12,
      "y": 70,
      "z": -12,
      "name": "Plant_Leaves_Ash"
    },
    {
      "x": -12,
      "y": 69,
      "z": -11,
      "name": "Plant_Leaves_Ash"
    },
    {
      "x": -12,
      "y": 70,
      "z": -11,
      "name": "Plant_Leaves_Ash"
    },
    {
      "x": -12,
      "y": 69,
      "z": -10,
      "name": "Plant_Leaves_Ash"
    },
    {
      "x": -12,
      "y": 70,
      "z": -10,
      "name": "Plant_Leaves_Ash"
    },
    {
      "x": -12,
      "y": 70,
      "z": -9,
      "name": "Plant_Leaves_Ash"
    },
    {
      "x": -12,
      "y": 70,
      "z": -8,
      "name": "Plant_Leaves_Ash"
    },
    {
      "x": -12,
      "y": 70,
      "z": -7,
      "name": "Plant_Leaves_Ash"
    },
    {
      "x": -12,
      "y": 70,
      "z": -6,
      "name": "Plant_Leaves_Ash"
    },
    {
      "x": -12,
      "y": 70,
      "z": -5,
      "name": "Plant_Leaves_Ash"
    },
    {
      "x": -12,
      "y": 71,
      "z": -5,
      "name": "Plant_Leaves_Ash"
    },
    {
      "x": -12,
      "y": 70,
      "z": -4,
      "name": "Plant_Leaves_Ash"
    },
    {
      "x": -12,
      "y": 71,
      "z": -4,
      "name": "Plant_Leaves_Ash"
    },
    {
      "x": -12,
      "y": 70,
      "z": -3,
      "name": "Plant_Leaves_Ash"
    },
    {
      "x": -12,
      "y": 71,
      "z": -3,
      "name": "Plant_Leaves_Ash"
    },
    {
      "x": -12,
      "y": 70,
      "z": -2,
      "name": "Plant_Leaves_Ash"
    },
    {
      "x": -12,
      "y": 71,
      "z": -2,
      "name": "Plant_Leaves_Ash"
    },
    {
      "x": -12,
      "y": 70,
      "z": -1,
      "name": "Plant_Leaves_Ash"
    },
    {
      "x": -12,
      "y": 71,
      "z": -1,
      "name": "Plant_Leaves_Ash"
    },
    {
      "x": -12,
      "y": 70,
      "z": 0,
      "name": "Plant_Leaves_Ash"
    },
    {
      "x": -12,
      "y": 71,
      "z": 0,
      "name": "Plant_Leaves_Ash"
    },
    {
      "x": -12,
      "y": 70,
      "z": 1,
      "name": "Plant_Leaves_Ash"
    },
    {
      "x": -12,
      "y": 71,
      "z": 1,
      "name": "Plant_Leaves_Ash"
    },
    {
      "x": -12,
      "y": 70,
      "z": 2,
      "name": "Plant_Leaves_Ash"
    },
    {
      "x": -12,
      "y": 71,
      "z": 2,
      "name": "Plant_Leaves_Ash"
    },
    {
      "x": -12,
      "y": 70,
      "z": 3,
      "name": "Plant_Leaves_Ash"
    },
    {
      "x": -12,
      "y": 71,
      "z": 3,
      "name": "Plant_Leaves_Ash"
    },
    {
      "x": -12,
      "y": 70,
      "z": 4,
      "name": "Plant_Leaves_Ash"
    },
    {
      "x": -12,
      "y": 71,
      "z": 4,
      "name": "Plant_Leaves_Ash"
    },
    {
      "x": -12,
      "y": 70,
      "z": 5,
      "name": "Plant_Leaves_Ash"
    },
    {
      "x": -12,
      "y": 71,
      "z": 5,
      "name": "Plant_Leaves_Ash"
    },
    {
      "x": -12,
      "y": 70,
      "z": 6,
      "name": "Plant_Leaves_Ash"
    },
    {
      "x": -12,
      "y": 70,
      "z": 7,
      "name": "Plant_Leaves_Ash"
    },
    {
      "x": -12,
      "y": 70,
      "z": 8,
      "name": "Plant_Leaves_Ash"
    },
    {
      "x": -12,
      "y": 70,
      "z": 9,
      "name": "Plant_Leaves_Ash"
    },
    {
      "x": -12,
      "y": 69,
      "z": 10,
      "name": "Plant_Leaves_Ash"
    },
    {
      "x": -12,
      "y": 70,
      "z": 10,
      "name": "Plant_Leaves_Ash"
    },
    {
      "x": -12,
      "y": 69,
      "z": 11,
      "name": "Plant_Leaves_Ash"
    },
    {
      "x": -12,
      "y": 70,
      "z": 11,
      "name": "Plant_Leaves_Ash"
    },
    {
      "x": -12,
      "y": 69,
      "z": 12,
      "name": "Plant_Leaves_Ash"
    },
    {
      "x": -12,
      "y": 70,
      "z": 12,
      "name": "Plant_Leaves_Ash"
    },
    {
      "x": -12,
      "y": 68,
      "z": 13,
      "name": "Plant_Leaves_Ash"
    },
    {
      "x": -12,
      "y": 69,
      "z": 13,
      "name": "Plant_Leaves_Ash"
    },
    {
      "x": -12,
      "y": 68,
      "z": 14,
      "name": "Plant_Leaves_Ash"
    },
    {
      "x": -12,
      "y": 69,
      "z": 14,
      "name": "Plant_Leaves_Ash"
    },
    {
      "x": -12,
      "y": 68,
      "z": 15,
      "name": "Plant_Leaves_Ash"
    },
    {
      "x": -12,
      "y": 69,
      "z": 15,
      "name": "Plant_Leaves_Ash"
    },
    {
      "x": -12,
      "y": 68,
      "z": 16,
      "name": "Plant_Leaves_Ash"
    },
    {
      "x": -11,
      "y": 68,
      "z": -17,
      "name": "Plant_Leaves_Ash"
    },
    {
      "x": -11,
      "y": 68,
      "z": -16,
      "name": "Plant_Leaves_Ash"
    },
    {
      "x": -11,
      "y": 68,
      "z": -15,
      "name": "Plant_Leaves_Ash"
    },
    {
      "x": -11,
      "y": 69,
      "z": -15,
      "name": "Plant_Leaves_Ash"
    },
    {
      "x": -11,
      "y": 68,
      "z": -14,
      "name": "Plant_Leaves_Ash"
    },
    {
      "x": -11,
      "y": 69,
      "z": -14,
      "name": "Plant_Leaves_Ash"
    },
    {
      "x": -11,
      "y": 69,
      "z": -13,
      "name": "Plant_Leaves_Ash"
    },
    {
      "x": -11,
      "y": 70,
      "z": -13,
      "name": "Plant_Leaves_Ash"
    },
    {
      "x": -11,
      "y": 69,
      "z": -12,
      "name": "Plant_Leaves_Ash"
    },
    {
      "x": -11,
      "y": 70,
      "z": -12,
      "name": "Plant_Leaves_Ash"
    },
    {
      "x": -11,
      "y": 69,
      "z": -11,
      "name": "Plant_Leaves_Ash"
    },
    {
      "x": -11,
      "y": 70,
      "z": -11,
      "name": "Plant_Leaves_Ash"
    },
    {
      "x": -11,
      "y": 70,
      "z": -10,
      "name": "Plant_Leaves_Ash"
    },
    {
      "x": -11,
      "y": 70,
      "z": -9,
      "name": "Plant_Leaves_Ash"
    },
    {
      "x": -11,
      "y": 70,
      "z": -8,
      "name": "Plant_Leaves_Ash"
    },
    {
      "x": -11,
      "y": 70,
      "z": -7,
      "name": "Plant_Leaves_Ash"
    },
    {
      "x": -11,
      "y": 71,
      "z": -7,
      "name": "Plant_Leaves_Ash"
    },
    {
      "x": -11,
      "y": 70,
      "z": -6,
      "name": "Plant_Leaves_Ash"
    },
    {
      "x": -11,
      "y": 71,
      "z": -6,
      "name": "Plant_Leaves_Ash"
    },
    {
      "x": -11,
      "y": 70,
      "z": -5,
      "name": "Plant_Leaves_Ash"
    },
    {
      "x": -11,
      "y": 71,
      "z": -5,
      "name": "Plant_Leaves_Ash"
    },
    {
      "x": -11,
      "y": 70,
      "z": -4,
      "name": "Plant_Leaves_Ash"
    },
    {
      "x": -11,
      "y": 71,
      "z": -4,
      "name": "Plant_Leaves_Ash"
    },
    {
      "x": -11,
      "y": 70,
      "z": -3,
      "name": "Plant_Leaves_Ash"
    },
    {
      "x": -11,
      "y": 71,
      "z": -3,
      "name": "Plant_Leaves_Ash"
    },
    {
      "x": -11,
      "y": 70,
      "z": -2,
      "name": "Plant_Leaves_Ash"
    },
    {
      "x": -11,
      "y": 71,
      "z": -2,
      "name": "Plant_Leaves_Ash"
    },
    {
      "x": -11,
      "y": 70,
      "z": -1,
      "name": "Plant_Leaves_Ash"
    },
    {
      "x": -11,
      "y": 71,
      "z": -1,
      "name": "Plant_Leaves_Ash"
    },
    {
      "x": -11,
      "y": 70,
      "z": 0,
      "name": "Plant_Leaves_Ash"
    },
    {
      "x": -11,
      "y": 71,
      "z": 0,
      "name": "Plant_Leaves_Ash"
    },
    {
      "x": -11,
      "y": 70,
      "z": 1,
      "name": "Plant_Leaves_Ash"
    },
    {
      "x": -11,
      "y": 71,
      "z": 1,
      "name": "Plant_Leaves_Ash"
    },
    {
      "x": -11,
      "y": 70,
      "z": 2,
      "name": "Plant_Leaves_Ash"
    },
    {
      "x": -11,
      "y": 71,
      "z": 2,
      "name": "Plant_Leaves_Ash"
    },
    {
      "x": -11,
      "y": 70,
      "z": 3,
      "name": "Plant_Leaves_Ash"
    },
    {
      "x": -11,
      "y": 71,
      "z": 3,
      "name": "Plant_Leaves_Ash"
    },
    {
      "x": -11,
      "y": 70,
      "z": 4,
      "name": "Plant_Leaves_Ash"
    },
    {
      "x": -11,
      "y": 71,
      "z": 4,
      "name": "Plant_Leaves_Ash"
    },
    {
      "x": -11,
      "y": 70,
      "z": 5,
      "name": "Plant_Leaves_Ash"
    },
    {
      "x": -11,
      "y": 71,
      "z": 5,
      "name": "Plant_Leaves_Ash"
    },
    {
      "x": -11,
      "y": 70,
      "z": 6,
      "name": "Plant_Leaves_Ash"
    },
    {
      "x": -11,
      "y": 71,
      "z": 6,
      "name": "Plant_Leaves_Ash"
    },
    {
      "x": -11,
      "y": 70,
      "z": 7,
      "name": "Plant_Leaves_Ash"
    },
    {
      "x": -11,
      "y": 71,
      "z": 7,
      "name": "Plant_Leaves_Ash"
    },
    {
      "x": -11,
      "y": 70,
      "z": 8,
      "name": "Plant_Leaves_Ash"
    },
    {
      "x": -11,
      "y": 70,
      "z": 9,
      "name": "Plant_Leaves_Ash"
    },
    {
      "x": -11,
      "y": 70,
      "z": 10,
      "name": "Plant_Leaves_Ash"
    },
    {
      "x": -11,
      "y": 69,
      "z": 11,
      "name": "Plant_Leaves_Ash"
    },
    {
      "x": -11,
      "y": 70,
      "z": 11,
      "name": "Plant_Leaves_Ash"
    },
    {
      "x": -11,
      "y": 69,
      "z": 12,
      "name": "Plant_Leaves_Ash"
    },
    {
      "x": -11,
      "y": 70,
      "z": 12,
      "name": "Plant_Leaves_Ash"
    },
    {
      "x": -11,
      "y": 69,
      "z": 13,
      "name": "Plant_Leaves_Ash"
    },
    {
      "x": -11,
      "y": 70,
      "z": 13,
      "name": "Plant_Leaves_Ash"
    },
    {
      "x": -11,
      "y": 68,
      "z": 14,
      "name": "Plant_Leaves_Ash"
    },
    {
      "x": -11,
      "y": 69,
      "z": 14,
      "name": "Plant_Leaves_Ash"
    },
    {
      "x": -11,
      "y": 68,
      "z": 15,
      "name": "Plant_Leaves_Ash"
    },
    {
      "x": -11,
      "y": 69,
      "z": 15,
      "name": "Plant_Leaves_Ash"
    },
    {
      "x": -11,
      "y": 68,
      "z": 16,
      "name": "Plant_Leaves_Ash"
    },
    {
      "x": -11,
      "y": 68,
      "z": 17,
      "name": "Plant_Leaves_Ash"
    },
    {
      "x": -10,
      "y": 68,
      "z": -17,
      "name": "Plant_Leaves_Ash"
    },
    {
      "x": -10,
      "y": 68,
      "z": -16,
      "name": "Plant_Leaves_Ash"
    },
    {
      "x": -10,
      "y": 69,
      "z": -16,
      "name": "Plant_Leaves_Ash"
    },
    {
      "x": -10,
      "y": 68,
      "z": -15,
      "name": "Plant_Leaves_Ash"
    },
    {
      "x": -10,
      "y": 69,
      "z": -15,
      "name": "Plant_Leaves_Ash"
    },
    {
      "x": -10,
      "y": 69,
      "z": -14,
      "name": "Plant_Leaves_Ash"
    },
    {
      "x": -10,
      "y": 70,
      "z": -14,
      "name": "Plant_Leaves_Ash"
    },
    {
      "x": -10,
      "y": 69,
      "z": -13,
      "name": "Plant_Leaves_Ash"
    },
    {
      "x": -10,
      "y": 70,
      "z": -13,
      "name": "Plant_Leaves_Ash"
    },
    {
      "x": -10,
      "y": 69,
      "z": -12,
      "name": "Plant_Leaves_Ash"
    },
    {
      "x": -10,
      "y": 70,
      "z": -12,
      "name": "Plant_Leaves_Ash"
    },
    {
      "x": -10,
      "y": 70,
      "z": -11,
      "name": "Plant_Leaves_Ash"
    },
    {
      "x": -10,
      "y": 70,
      "z": -10,
      "name": "Plant_Leaves_Ash"
    },
    {
      "x": -10,
      "y": 70,
      "z": -9,
      "name": "Plant_Leaves_Ash"
    },
    {
      "x": -10,
      "y": 70,
      "z": -8,
      "name": "Plant_Leaves_Ash"
    },
    {
      "x": -10,
      "y": 71,
      "z": -8,
      "name": "Plant_Leaves_Ash"
    },
    {
      "x": -10,
      "y": 70,
      "z": -7,
      "name": "Plant_Leaves_Ash"
    },
    {
      "x": -10,
      "y": 71,
      "z": -7,
      "name": "Plant_Leaves_Ash"
    },
    {
      "x": -10,
      "y": 70,
      "z": -6,
      "name": "Plant_Leaves_Ash"
    },
    {
      "x": -10,
      "y": 71,
      "z": -6,
      "name": "Plant_Leaves_Ash"
    },
    {
      "x": -10,
      "y": 70,
      "z": -5,
      "name": "Plant_Leaves_Ash"
    },
    {
      "x": -10,
      "y": 71,
      "z": -5,
      "name": "Plant_Leaves_Ash"
    },
    {
      "x": -10,
      "y": 70,
      "z": -4,
      "name": "Plant_Leaves_Ash"
    },
    {
      "x": -10,
      "y": 71,
      "z": -4,
      "name": "Plant_Leaves_Ash"
    },
    {
      "x": -10,
      "y": 70,
      "z": -3,
      "name": "Plant_Leaves_Ash"
    },
    {
      "x": -10,
      "y": 71,
      "z": -3,
      "name": "Plant_Leaves_Ash"
    },
    {
      "x": -10,
      "y": 70,
      "z": -2,
      "name": "Plant_Leaves_Ash"
    },
    {
      "x": -10,
      "y": 71,
      "z": -2,
      "name": "Plant_Leaves_Ash"
    },
    {
      "x": -10,
      "y": 70,
      "z": -1,
      "name": "Plant_Leaves_Ash"
    },
    {
      "x": -10,
      "y": 71,
      "z": -1,
      "name": "Plant_Leaves_Ash"
    },
    {
      "x": -10,
      "y": 70,
      "z": 0,
      "name": "Plant_Leaves_Ash"
    },
    {
      "x": -10,
      "y": 71,
      "z": 0,
      "name": "Plant_Leaves_Ash"
    },
    {
      "x": -10,
      "y": 70,
      "z": 1,
      "name": "Plant_Leaves_Ash"
    },
    {
      "x": -10,
      "y": 71,
      "z": 1,
      "name": "Plant_Leaves_Ash"
    },
    {
      "x": -10,
      "y": 70,
      "z": 2,
      "name": "Plant_Leaves_Ash"
    },
    {
      "x": -10,
      "y": 71,
      "z": 2,
      "name": "Plant_Leaves_Ash"
    },
    {
      "x": -10,
      "y": 70,
      "z": 3,
      "name": "Plant_Leaves_Ash"
    },
    {
      "x": -10,
      "y": 71,
      "z": 3,
      "name": "Plant_Leaves_Ash"
    },
    {
      "x": -10,
      "y": 70,
      "z": 4,
      "name": "Plant_Leaves_Ash"
    },
    {
      "x": -10,
      "y": 71,
      "z": 4,
      "name": "Plant_Leaves_Ash"
    },
    {
      "x": -10,
      "y": 70,
      "z": 5,
      "name": "Plant_Leaves_Ash"
    },
    {
      "x": -10,
      "y": 71,
      "z": 5,
      "name": "Plant_Leaves_Ash"
    },
    {
      "x": -10,
      "y": 70,
      "z": 6,
      "name": "Plant_Leaves_Ash"
    },
    {
      "x": -10,
      "y": 71,
      "z": 6,
      "name": "Plant_Leaves_Ash"
    },
    {
      "x": -10,
      "y": 70,
      "z": 7,
      "name": "Plant_Leaves_Ash"
    },
    {
      "x": -10,
      "y": 71,
      "z": 7,
      "name": "Plant_Leaves_Ash"
    },
    {
      "x": -10,
      "y": 70,
      "z": 8,
      "name": "Plant_Leaves_Ash"
    },
    {
      "x": -10,
      "y": 71,
      "z": 8,
      "name": "Plant_Leaves_Ash"
    },
    {
      "x": -10,
      "y": 70,
      "z": 9,
      "name": "Plant_Leaves_Ash"
    },
    {
      "x": -10,
      "y": 70,
      "z": 10,
      "name": "Plant_Leaves_Ash"
    },
    {
      "x": -10,
      "y": 70,
      "z": 11,
      "name": "Plant_Leaves_Ash"
    },
    {
      "x": -10,
      "y": 69,
      "z": 12,
      "name": "Plant_Leaves_Ash"
    },
    {
      "x": -10,
      "y": 70,
      "z": 12,
      "name": "Plant_Leaves_Ash"
    },
    {
      "x": -10,
      "y": 69,
      "z": 13,
      "name": "Plant_Leaves_Ash"
    },
    {
      "x": -10,
      "y": 70,
      "z": 13,
      "name": "Plant_Leaves_Ash"
    },
    {
      "x": -10,
      "y": 69,
      "z": 14,
      "name": "Plant_Leaves_Ash"
    },
    {
      "x": -10,
      "y": 70,
      "z": 14,
      "name": "Plant_Leaves_Ash"
    },
    {
      "x": -10,
      "y": 68,
      "z": 15,
      "name": "Plant_Leaves_Ash"
    },
    {
      "x": -10,
      "y": 69,
      "z": 15,
      "name": "Plant_Leaves_Ash"
    },
    {
      "x": -10,
      "y": 68,
      "z": 16,
      "name": "Plant_Leaves_Ash"
    },
    {
      "x": -10,
      "y": 69,
      "z": 16,
      "name": "Plant_Leaves_Ash"
    },
    {
      "x": -10,
      "y": 68,
      "z": 17,
      "name": "Plant_Leaves_Ash"
    },
    {
      "x": -9,
      "y": 68,
      "z": -18,
      "name": "Plant_Leaves_Ash"
    },
    {
      "x": -9,
      "y": 68,
      "z": -17,
      "name": "Plant_Leaves_Ash"
    },
    {
      "x": -9,
      "y": 69,
      "z": -17,
      "name": "Plant_Leaves_Ash"
    },
    {
      "x": -9,
      "y": 68,
      "z": -16,
      "name": "Plant_Leaves_Ash"
    },
    {
      "x": -9,
      "y": 69,
      "z": -16,
      "name": "Plant_Leaves_Ash"
    },
    {
      "x": -9,
      "y": 68,
      "z": -15,
      "name": "Plant_Leaves_Ash"
    },
    {
      "x": -9,
      "y": 69,
      "z": -15,
      "name": "Plant_Leaves_Ash"
    },
    {
      "x": -9,
      "y": 69,
      "z": -14,
      "name": "Plant_Leaves_Ash"
    },
    {
      "x": -9,
      "y": 70,
      "z": -14,
      "name": "Plant_Leaves_Ash"
    },
    {
      "x": -9,
      "y": 69,
      "z": -13,
      "name": "Plant_Leaves_Ash"
    },
    {
      "x": -9,
      "y": 70,
      "z": -13,
      "name": "Plant_Leaves_Ash"
    },
    {
      "x": -9,
      "y": 70,
      "z": -12,
      "name": "Plant_Leaves_Ash"
    },
    {
      "x": -9,
      "y": 70,
      "z": -11,
      "name": "Plant_Leaves_Ash"
    },
    {
      "x": -9,
      "y": 70,
      "z": -10,
      "name": "Plant_Leaves_Ash"
    },
    {
      "x": -9,
      "y": 70,
      "z": -9,
      "name": "Plant_Leaves_Ash"
    },
    {
      "x": -9,
      "y": 71,
      "z": -9,
      "name": "Plant_Leaves_Ash"
    },
    {
      "x": -9,
      "y": 70,
      "z": -8,
      "name": "Plant_Leaves_Ash"
    },
    {
      "x": -9,
      "y": 71,
      "z": -8,
      "name": "Plant_Leaves_Ash"
    },
    {
      "x": -9,
      "y": 70,
      "z": -7,
      "name": "Plant_Leaves_Ash"
    },
    {
      "x": -9,
      "y": 71,
      "z": -7,
      "name": "Plant_Leaves_Ash"
    },
    {
      "x": -9,
      "y": 70,
      "z": -6,
      "name": "Plant_Leaves_Ash"
    },
    {
      "x": -9,
      "y": 71,
      "z": -6,
      "name": "Plant_Leaves_Ash"
    },
    {
      "x": -9,
      "y": 70,
      "z": -5,
      "name": "Plant_Leaves_Ash"
    },
    {
      "x": -9,
      "y": 71,
      "z": -5,
      "name": "Plant_Leaves_Ash"
    },
    {
      "x": -9,
      "y": 70,
      "z": -4,
      "name": "Plant_Leaves_Ash"
    },
    {
      "x": -9,
      "y": 71,
      "z": -4,
      "name": "Plant_Leaves_Ash"
    },
    {
      "x": -9,
      "y": 70,
      "z": -3,
      "name": "Plant_Leaves_Ash"
    },
    {
      "x": -9,
      "y": 71,
      "z": -3,
      "name": "Plant_Leaves_Ash"
    },
    {
      "x": -9,
      "y": 70,
      "z": -2,
      "name": "Plant_Leaves_Ash"
    },
    {
      "x": -9,
      "y": 71,
      "z": -2,
      "name": "Plant_Leaves_Ash"
    },
    {
      "x": -9,
      "y": 70,
      "z": -1,
      "name": "Plant_Leaves_Ash"
    },
    {
      "x": -9,
      "y": 71,
      "z": -1,
      "name": "Plant_Leaves_Ash"
    },
    {
      "x": -9,
      "y": 70,
      "z": 0,
      "name": "Plant_Leaves_Ash"
    },
    {
      "x": -9,
      "y": 71,
      "z": 0,
      "name": "Plant_Leaves_Ash"
    },
    {
      "x": -9,
      "y": 70,
      "z": 1,
      "name": "Plant_Leaves_Ash"
    },
    {
      "x": -9,
      "y": 71,
      "z": 1,
      "name": "Plant_Leaves_Ash"
    },
    {
      "x": -9,
      "y": 70,
      "z": 2,
      "name": "Plant_Leaves_Ash"
    },
    {
      "x": -9,
      "y": 71,
      "z": 2,
      "name": "Plant_Leaves_Ash"
    },
    {
      "x": -9,
      "y": 70,
      "z": 3,
      "name": "Plant_Leaves_Ash"
    },
    {
      "x": -9,
      "y": 71,
      "z": 3,
      "name": "Plant_Leaves_Ash"
    },
    {
      "x": -9,
      "y": 70,
      "z": 4,
      "name": "Plant_Leaves_Ash"
    },
    {
      "x": -9,
      "y": 71,
      "z": 4,
      "name": "Plant_Leaves_Ash"
    },
    {
      "x": -9,
      "y": 70,
      "z": 5,
      "name": "Plant_Leaves_Ash"
    },
    {
      "x": -9,
      "y": 71,
      "z": 5,
      "name": "Plant_Leaves_Ash"
    },
    {
      "x": -9,
      "y": 70,
      "z": 6,
      "name": "Plant_Leaves_Ash"
    },
    {
      "x": -9,
      "y": 71,
      "z": 6,
      "name": "Plant_Leaves_Ash"
    },
    {
      "x": -9,
      "y": 70,
      "z": 7,
      "name": "Plant_Leaves_Ash"
    },
    {
      "x": -9,
      "y": 71,
      "z": 7,
      "name": "Plant_Leaves_Ash"
    },
    {
      "x": -9,
      "y": 70,
      "z": 8,
      "name": "Plant_Leaves_Ash"
    },
    {
      "x": -9,
      "y": 71,
      "z": 8,
      "name": "Plant_Leaves_Ash"
    },
    {
      "x": -9,
      "y": 70,
      "z": 9,
      "name": "Plant_Leaves_Ash"
    },
    {
      "x": -9,
      "y": 71,
      "z": 9,
      "name": "Plant_Leaves_Ash"
    },
    {
      "x": -9,
      "y": 70,
      "z": 10,
      "name": "Plant_Leaves_Ash"
    },
    {
      "x": -9,
      "y": 70,
      "z": 11,
      "name": "Plant_Leaves_Ash"
    },
    {
      "x": -9,
      "y": 70,
      "z": 12,
      "name": "Plant_Leaves_Ash"
    },
    {
      "x": -9,
      "y": 69,
      "z": 13,
      "name": "Plant_Leaves_Ash"
    },
    {
      "x": -9,
      "y": 70,
      "z": 13,
      "name": "Plant_Leaves_Ash"
    },
    {
      "x": -9,
      "y": 69,
      "z": 14,
      "name": "Plant_Leaves_Ash"
    },
    {
      "x": -9,
      "y": 70,
      "z": 14,
      "name": "Plant_Leaves_Ash"
    },
    {
      "x": -9,
      "y": 68,
      "z": 15,
      "name": "Plant_Leaves_Ash"
    },
    {
      "x": -9,
      "y": 69,
      "z": 15,
      "name": "Plant_Leaves_Ash"
    },
    {
      "x": -9,
      "y": 68,
      "z": 16,
      "name": "Plant_Leaves_Ash"
    },
    {
      "x": -9,
      "y": 69,
      "z": 16,
      "name": "Plant_Leaves_Ash"
    },
    {
      "x": -9,
      "y": 68,
      "z": 17,
      "name": "Plant_Leaves_Ash"
    },
    {
      "x": -9,
      "y": 69,
      "z": 17,
      "name": "Plant_Leaves_Ash"
    },
    {
      "x": -9,
      "y": 68,
      "z": 18,
      "name": "Plant_Leaves_Ash"
    },
    {
      "x": -8,
      "y": 68,
      "z": -18,
      "name": "Plant_Leaves_Ash"
    },
    {
      "x": -8,
      "y": 68,
      "z": -17,
      "name": "Plant_Leaves_Ash"
    },
    {
      "x": -8,
      "y": 69,
      "z": -17,
      "name": "Plant_Leaves_Ash"
    },
    {
      "x": -8,
      "y": 68,
      "z": -16,
      "name": "Plant_Leaves_Ash"
    },
    {
      "x": -8,
      "y": 69,
      "z": -16,
      "name": "Plant_Leaves_Ash"
    },
    {
      "x": -8,
      "y": 69,
      "z": -15,
      "name": "Plant_Leaves_Ash"
    },
    {
      "x": -8,
      "y": 70,
      "z": -15,
      "name": "Plant_Leaves_Ash"
    },
    {
      "x": -8,
      "y": 69,
      "z": -14,
      "name": "Plant_Leaves_Ash"
    },
    {
      "x": -8,
      "y": 70,
      "z": -14,
      "name": "Plant_Leaves_Ash"
    },
    {
      "x": -8,
      "y": 70,
      "z": -13,
      "name": "Plant_Leaves_Ash"
    },
    {
      "x": -8,
      "y": 70,
      "z": -12,
      "name": "Plant_Leaves_Ash"
    },
    {
      "x": -8,
      "y": 70,
      "z": -11,
      "name": "Plant_Leaves_Ash"
    },
    {
      "x": -8,
      "y": 70,
      "z": -10,
      "name": "Plant_Leaves_Ash"
    },
    {
      "x": -8,
      "y": 71,
      "z": -10,
      "name": "Plant_Leaves_Ash"
    },
    {
      "x": -8,
      "y": 70,
      "z": -9,
      "name": "Plant_Leaves_Ash"
    },
    {
      "x": -8,
      "y": 71,
      "z": -9,
      "name": "Plant_Leaves_Ash"
    },
    {
      "x": -8,
      "y": 70,
      "z": -8,
      "name": "Plant_Leaves_Ash"
    },
    {
      "x": -8,
      "y": 71,
      "z": -8,
      "name": "Plant_Leaves_Ash"
    },
    {
      "x": -8,
      "y": 70,
      "z": -7,
      "name": "Plant_Leaves_Ash"
    },
    {
      "x": -8,
      "y": 71,
      "z": -7,
      "name": "Plant_Leaves_Ash"
    },
    {
      "x": -8,
      "y": 70,
      "z": -6,
      "name": "Plant_Leaves_Ash"
    },
    {
      "x": -8,
      "y": 71,
      "z": -6,
      "name": "Plant_Leaves_Ash"
    },
    {
      "x": -8,
      "y": 70,
      "z": -5,
      "name": "Plant_Leaves_Ash"
    },
    {
      "x": -8,
      "y": 71,
      "z": -5,
      "name": "Plant_Leaves_Ash"
    },
    {
      "x": -8,
      "y": 70,
      "z": -4,
      "name": "Plant_Leaves_Ash"
    },
    {
      "x": -8,
      "y": 71,
      "z": -4,
      "name": "Plant_Leaves_Ash"
    },
    {
      "x": -8,
      "y": 70,
      "z": -3,
      "name": "Plant_Leaves_Ash"
    },
    {
      "x": -8,
      "y": 71,
      "z": -3,
      "name": "Plant_Leaves_Ash"
    },
    {
      "x": -8,
      "y": 70,
      "z": -2,
      "name": "Plant_Leaves_Ash"
    },
    {
      "x": -8,
      "y": 71,
      "z": -2,
      "name": "Plant_Leaves_Ash"
    },
    {
      "x": -8,
      "y": 70,
      "z": -1,
      "name": "Plant_Leaves_Ash"
    },
    {
      "x": -8,
      "y": 71,
      "z": -1,
      "name": "Plant_Leaves_Ash"
    },
    {
      "x": -8,
      "y": 70,
      "z": 0,
      "name": "Plant_Leaves_Ash"
    },
    {
      "x": -8,
      "y": 71,
      "z": 0,
      "name": "Plant_Leaves_Ash"
    },
    {
      "x": -8,
      "y": 70,
      "z": 1,
      "name": "Plant_Leaves_Ash"
    },
    {
      "x": -8,
      "y": 71,
      "z": 1,
      "name": "Plant_Leaves_Ash"
    },
    {
      "x": -8,
      "y": 70,
      "z": 2,
      "name": "Plant_Leaves_Ash"
    },
    {
      "x": -8,
      "y": 71,
      "z": 2,
      "name": "Plant_Leaves_Ash"
    },
    {
      "x": -8,
      "y": 70,
      "z": 3,
      "name": "Plant_Leaves_Ash"
    },
    {
      "x": -8,
      "y": 71,
      "z": 3,
      "name": "Plant_Leaves_Ash"
    },
    {
      "x": -8,
      "y": 70,
      "z": 4,
      "name": "Plant_Leaves_Ash"
    },
    {
      "x": -8,
      "y": 71,
      "z": 4,
      "name": "Plant_Leaves_Ash"
    },
    {
      "x": -8,
      "y": 70,
      "z": 5,
      "name": "Plant_Leaves_Ash"
    },
    {
      "x": -8,
      "y": 71,
      "z": 5,
      "name": "Plant_Leaves_Ash"
    },
    {
      "x": -8,
      "y": 70,
      "z": 6,
      "name": "Plant_Leaves_Ash"
    },
    {
      "x": -8,
      "y": 71,
      "z": 6,
      "name": "Plant_Leaves_Ash"
    },
    {
      "x": -8,
      "y": 70,
      "z": 7,
      "name": "Plant_Leaves_Ash"
    },
    {
      "x": -8,
      "y": 71,
      "z": 7,
      "name": "Plant_Leaves_Ash"
    },
    {
      "x": -8,
      "y": 70,
      "z": 8,
      "name": "Plant_Leaves_Ash"
    },
    {
      "x": -8,
      "y": 71,
      "z": 8,
      "name": "Plant_Leaves_Ash"
    },
    {
      "x": -8,
      "y": 70,
      "z": 9,
      "name": "Plant_Leaves_Ash"
    },
    {
      "x": -8,
      "y": 71,
      "z": 9,
      "name": "Plant_Leaves_Ash"
    },
    {
      "x": -8,
      "y": 70,
      "z": 10,
      "name": "Plant_Leaves_Ash"
    },
    {
      "x": -8,
      "y": 71,
      "z": 10,
      "name": "Plant_Leaves_Ash"
    },
    {
      "x": -8,
      "y": 70,
      "z": 11,
      "name": "Plant_Leaves_Ash"
    },
    {
      "x": -8,
      "y": 70,
      "z": 12,
      "name": "Plant_Leaves_Ash"
    },
    {
      "x": -8,
      "y": 70,
      "z": 13,
      "name": "Plant_Leaves_Ash"
    },
    {
      "x": -8,
      "y": 69,
      "z": 14,
      "name": "Plant_Leaves_Ash"
    },
    {
      "x": -8,
      "y": 70,
      "z": 14,
      "name": "Plant_Leaves_Ash"
    },
    {
      "x": -8,
      "y": 69,
      "z": 15,
      "name": "Plant_Leaves_Ash"
    },
    {
      "x": -8,
      "y": 70,
      "z": 15,
      "name": "Plant_Leaves_Ash"
    },
    {
      "x": -8,
      "y": 68,
      "z": 16,
      "name": "Plant_Leaves_Ash"
    },
    {
      "x": -8,
      "y": 69,
      "z": 16,
      "name": "Plant_Leaves_Ash"
    },
    {
      "x": -8,
      "y": 68,
      "z": 17,
      "name": "Plant_Leaves_Ash"
    },
    {
      "x": -8,
      "y": 69,
      "z": 17,
      "name": "Plant_Leaves_Ash"
    },
    {
      "x": -8,
      "y": 68,
      "z": 18,
      "name": "Plant_Leaves_Ash"
    },
    {
      "x": -7,
      "y": 68,
      "z": -19,
      "name": "Plant_Leaves_Ash"
    },
    {
      "x": -7,
      "y": 68,
      "z": -18,
      "name": "Plant_Leaves_Ash"
    },
    {
      "x": -7,
      "y": 69,
      "z": -18,
      "name": "Plant_Leaves_Ash"
    },
    {
      "x": -7,
      "y": 68,
      "z": -17,
      "name": "Plant_Leaves_Ash"
    },
    {
      "x": -7,
      "y": 69,
      "z": -17,
      "name": "Plant_Leaves_Ash"
    },
    {
      "x": -7,
      "y": 68,
      "z": -16,
      "name": "Plant_Leaves_Ash"
    },
    {
      "x": -7,
      "y": 69,
      "z": -16,
      "name": "Plant_Leaves_Ash"
    },
    {
      "x": -7,
      "y": 69,
      "z": -15,
      "name": "Plant_Leaves_Ash"
    },
    {
      "x": -7,
      "y": 70,
      "z": -15,
      "name": "Plant_Leaves_Ash"
    },
    {
      "x": -7,
      "y": 69,
      "z": -14,
      "name": "Plant_Leaves_Ash"
    },
    {
      "x": -7,
      "y": 70,
      "z": -14,
      "name": "Plant_Leaves_Ash"
    },
    {
      "x": -7,
      "y": 70,
      "z": -13,
      "name": "Plant_Leaves_Ash"
    },
    {
      "x": -7,
      "y": 70,
      "z": -12,
      "name": "Plant_Leaves_Ash"
    },
    {
      "x": -7,
      "y": 70,
      "z": -11,
      "name": "Plant_Leaves_Ash"
    },
    {
      "x": -7,
      "y": 71,
      "z": -11,
      "name": "Plant_Leaves_Ash"
    },
    {
      "x": -7,
      "y": 70,
      "z": -10,
      "name": "Plant_Leaves_Ash"
    },
    {
      "x": -7,
      "y": 71,
      "z": -10,
      "name": "Plant_Leaves_Ash"
    },
    {
      "x": -7,
      "y": 70,
      "z": -9,
      "name": "Plant_Leaves_Ash"
    },
    {
      "x": -7,
      "y": 71,
      "z": -9,
      "name": "Plant_Leaves_Ash"
    },
    {
      "x": -7,
      "y": 70,
      "z": -8,
      "name": "Plant_Leaves_Ash"
    },
    {
      "x": -7,
      "y": 71,
      "z": -8,
      "name": "Plant_Leaves_Ash"
    },
    {
      "x": -7,
      "y": 70,
      "z": -7,
      "name": "Plant_Leaves_Ash"
    },
    {
      "x": -7,
      "y": 71,
      "z": -7,
      "name": "Plant_Leaves_Ash"
    },
    {
      "x": -7,
      "y": 70,
      "z": -6,
      "name": "Plant_Leaves_Ash"
    },
    {
      "x": -7,
      "y": 71,
      "z": -6,
      "name": "Plant_Leaves_Ash"
    },
    {
      "x": -7,
      "y": 70,
      "z": -5,
      "name": "Plant_Leaves_Ash"
    },
    {
      "x": -7,
      "y": 71,
      "z": -5,
      "name": "Plant_Leaves_Ash"
    },
    {
      "x": -7,
      "y": 70,
      "z": -4,
      "name": "Plant_Leaves_Ash"
    },
    {
      "x": -7,
      "y": 71,
      "z": -4,
      "name": "Plant_Leaves_Ash"
    },
    {
      "x": -7,
      "y": 70,
      "z": -3,
      "name": "Plant_Leaves_Ash"
    },
    {
      "x": -7,
      "y": 71,
      "z": -3,
      "name": "Plant_Leaves_Ash"
    },
    {
      "x": -7,
      "y": 70,
      "z": -2,
      "name": "Plant_Leaves_Ash"
    },
    {
      "x": -7,
      "y": 71,
      "z": -2,
      "name": "Plant_Leaves_Ash"
    },
    {
      "x": -7,
      "y": 70,
      "z": -1,
      "name": "Plant_Leaves_Ash"
    },
    {
      "x": -7,
      "y": 71,
      "z": -1,
      "name": "Plant_Leaves_Ash"
    },
    {
      "x": -7,
      "y": 70,
      "z": 0,
      "name": "Plant_Leaves_Ash"
    },
    {
      "x": -7,
      "y": 71,
      "z": 0,
      "name": "Plant_Leaves_Ash"
    },
    {
      "x": -7,
      "y": 70,
      "z": 1,
      "name": "Plant_Leaves_Ash"
    },
    {
      "x": -7,
      "y": 71,
      "z": 1,
      "name": "Plant_Leaves_Ash"
    },
    {
      "x": -7,
      "y": 70,
      "z": 2,
      "name": "Plant_Leaves_Ash"
    },
    {
      "x": -7,
      "y": 71,
      "z": 2,
      "name": "Plant_Leaves_Ash"
    },
    {
      "x": -7,
      "y": 70,
      "z": 3,
      "name": "Plant_Leaves_Ash"
    },
    {
      "x": -7,
      "y": 71,
      "z": 3,
      "name": "Plant_Leaves_Ash"
    },
    {
      "x": -7,
      "y": 70,
      "z": 4,
      "name": "Plant_Leaves_Ash"
    },
    {
      "x": -7,
      "y": 71,
      "z": 4,
      "name": "Plant_Leaves_Ash"
    },
    {
      "x": -7,
      "y": 70,
      "z": 5,
      "name": "Plant_Leaves_Ash"
    },
    {
      "x": -7,
      "y": 71,
      "z": 5,
      "name": "Plant_Leaves_Ash"
    },
    {
      "x": -7,
      "y": 70,
      "z": 6,
      "name": "Plant_Leaves_Ash"
    },
    {
      "x": -7,
      "y": 71,
      "z": 6,
      "name": "Plant_Leaves_Ash"
    },
    {
      "x": -7,
      "y": 70,
      "z": 7,
      "name": "Plant_Leaves_Ash"
    },
    {
      "x": -7,
      "y": 71,
      "z": 7,
      "name": "Plant_Leaves_Ash"
    },
    {
      "x": -7,
      "y": 70,
      "z": 8,
      "name": "Plant_Leaves_Ash"
    },
    {
      "x": -7,
      "y": 71,
      "z": 8,
      "name": "Plant_Leaves_Ash"
    },
    {
      "x": -7,
      "y": 70,
      "z": 9,
      "name": "Plant_Leaves_Ash"
    },
    {
      "x": -7,
      "y": 71,
      "z": 9,
      "name": "Plant_Leaves_Ash"
    },
    {
      "x": -7,
      "y": 70,
      "z": 10,
      "name": "Plant_Leaves_Ash"
    },
    {
      "x": -7,
      "y": 71,
      "z": 10,
      "name": "Plant_Leaves_Ash"
    },
    {
      "x": -7,
      "y": 70,
      "z": 11,
      "name": "Plant_Leaves_Ash"
    },
    {
      "x": -7,
      "y": 71,
      "z": 11,
      "name": "Plant_Leaves_Ash"
    },
    {
      "x": -7,
      "y": 70,
      "z": 12,
      "name": "Plant_Leaves_Ash"
    },
    {
      "x": -7,
      "y": 70,
      "z": 13,
      "name": "Plant_Leaves_Ash"
    },
    {
      "x": -7,
      "y": 69,
      "z": 14,
      "name": "Plant_Leaves_Ash"
    },
    {
      "x": -7,
      "y": 70,
      "z": 14,
      "name": "Plant_Leaves_Ash"
    },
    {
      "x": -7,
      "y": 69,
      "z": 15,
      "name": "Plant_Leaves_Ash"
    },
    {
      "x": -7,
      "y": 70,
      "z": 15,
      "name": "Plant_Leaves_Ash"
    },
    {
      "x": -7,
      "y": 68,
      "z": 16,
      "name": "Plant_Leaves_Ash"
    },
    {
      "x": -7,
      "y": 69,
      "z": 16,
      "name": "Plant_Leaves_Ash"
    },
    {
      "x": -7,
      "y": 68,
      "z": 17,
      "name": "Plant_Leaves_Ash"
    },
    {
      "x": -7,
      "y": 69,
      "z": 17,
      "name": "Plant_Leaves_Ash"
    },
    {
      "x": -7,
      "y": 68,
      "z": 18,
      "name": "Plant_Leaves_Ash"
    },
    {
      "x": -7,
      "y": 69,
      "z": 18,
      "name": "Plant_Leaves_Ash"
    },
    {
      "x": -7,
      "y": 68,
      "z": 19,
      "name": "Plant_Leaves_Ash"
    },
    {
      "x": -6,
      "y": 68,
      "z": -19,
      "name": "Plant_Leaves_Ash"
    },
    {
      "x": -6,
      "y": 68,
      "z": -18,
      "name": "Plant_Leaves_Ash"
    },
    {
      "x": -6,
      "y": 69,
      "z": -18,
      "name": "Plant_Leaves_Ash"
    },
    {
      "x": -6,
      "y": 68,
      "z": -17,
      "name": "Plant_Leaves_Ash"
    },
    {
      "x": -6,
      "y": 69,
      "z": -17,
      "name": "Plant_Leaves_Ash"
    },
    {
      "x": -6,
      "y": 69,
      "z": -16,
      "name": "Plant_Leaves_Ash"
    },
    {
      "x": -6,
      "y": 70,
      "z": -16,
      "name": "Plant_Leaves_Ash"
    },
    {
      "x": -6,
      "y": 69,
      "z": -15,
      "name": "Plant_Leaves_Ash"
    },
    {
      "x": -6,
      "y": 70,
      "z": -15,
      "name": "Plant_Leaves_Ash"
    },
    {
      "x": -6,
      "y": 70,
      "z": -14,
      "name": "Plant_Leaves_Ash"
    },
    {
      "x": -6,
      "y": 70,
      "z": -13,
      "name": "Plant_Leaves_Ash"
    },
    {
      "x": -6,
      "y": 70,
      "z": -12,
      "name": "Plant_Leaves_Ash"
    },
    {
      "x": -6,
      "y": 70,
      "z": -11,
      "name": "Plant_Leaves_Ash"
    },
    {
      "x": -6,
      "y": 71,
      "z": -11,
      "name": "Plant_Leaves_Ash"
    },
    {
      "x": -6,
      "y": 70,
      "z": -10,
      "name": "Plant_Leaves_Ash"
    },
    {
      "x": -6,
      "y": 71,
      "z": -10,
      "name": "Plant_Leaves_Ash"
    },
    {
      "x": -6,
      "y": 70,
      "z": -9,
      "name": "Plant_Leaves_Ash"
    },
    {
      "x": -6,
      "y": 71,
      "z": -9,
      "name": "Plant_Leaves_Ash"
    },
    {
      "x": -6,
      "y": 70,
      "z": -8,
      "name": "Plant_Leaves_Ash"
    },
    {
      "x": -6,
      "y": 71,
      "z": -8,
      "name": "Plant_Leaves_Ash"
    },
    {
      "x": -6,
      "y": 70,
      "z": -7,
      "name": "Plant_Leaves_Ash"
    },
    {
      "x": -6,
      "y": 71,
      "z": -7,
      "name": "Plant_Leaves_Ash"
    },
    {
      "x": -6,
      "y": 70,
      "z": -6,
      "name": "Plant_Leaves_Ash"
    },
    {
      "x": -6,
      "y": 71,
      "z": -6,
      "name": "Plant_Leaves_Ash"
    },
    {
      "x": -6,
      "y": 70,
      "z": -5,
      "name": "Plant_Leaves_Ash"
    },
    {
      "x": -6,
      "y": 71,
      "z": -5,
      "name": "Plant_Leaves_Ash"
    },
    {
      "x": -6,
      "y": 70,
      "z": -4,
      "name": "Plant_Leaves_Ash"
    },
    {
      "x": -6,
      "y": 71,
      "z": -4,
      "name": "Plant_Leaves_Ash"
    },
    {
      "x": -6,
      "y": 70,
      "z": -3,
      "name": "Plant_Leaves_Ash"
    },
    {
      "x": -6,
      "y": 71,
      "z": -3,
      "name": "Plant_Leaves_Ash"
    },
    {
      "x": -6,
      "y": 70,
      "z": -2,
      "name": "Plant_Leaves_Ash"
    },
    {
      "x": -6,
      "y": 71,
      "z": -2,
      "name": "Plant_Leaves_Ash"
    },
    {
      "x": -6,
      "y": 70,
      "z": -1,
      "name": "Plant_Leaves_Ash"
    },
    {
      "x": -6,
      "y": 71,
      "z": -1,
      "name": "Plant_Leaves_Ash"
    },
    {
      "x": -6,
      "y": 70,
      "z": 0,
      "name": "Plant_Leaves_Ash"
    },
    {
      "x": -6,
      "y": 71,
      "z": 0,
      "name": "Plant_Leaves_Ash"
    },
    {
      "x": -6,
      "y": 70,
      "z": 1,
      "name": "Plant_Leaves_Ash"
    },
    {
      "x": -6,
      "y": 71,
      "z": 1,
      "name": "Plant_Leaves_Ash"
    },
    {
      "x": -6,
      "y": 70,
      "z": 2,
      "name": "Plant_Leaves_Ash"
    },
    {
      "x": -6,
      "y": 71,
      "z": 2,
      "name": "Plant_Leaves_Ash"
    },
    {
      "x": -6,
      "y": 70,
      "z": 3,
      "name": "Plant_Leaves_Ash"
    },
    {
      "x": -6,
      "y": 71,
      "z": 3,
      "name": "Plant_Leaves_Ash"
    },
    {
      "x": -6,
      "y": 70,
      "z": 4,
      "name": "Plant_Leaves_Ash"
    },
    {
      "x": -6,
      "y": 71,
      "z": 4,
      "name": "Plant_Leaves_Ash"
    },
    {
      "x": -6,
      "y": 70,
      "z": 5,
      "name": "Plant_Leaves_Ash"
    },
    {
      "x": -6,
      "y": 71,
      "z": 5,
      "name": "Plant_Leaves_Ash"
    },
    {
      "x": -6,
      "y": 70,
      "z": 6,
      "name": "Plant_Leaves_Ash"
    },
    {
      "x": -6,
      "y": 71,
      "z": 6,
      "name": "Plant_Leaves_Ash"
    },
    {
      "x": -6,
      "y": 70,
      "z": 7,
      "name": "Plant_Leaves_Ash"
    },
    {
      "x": -6,
      "y": 71,
      "z": 7,
      "name": "Plant_Leaves_Ash"
    },
    {
      "x": -6,
      "y": 70,
      "z": 8,
      "name": "Plant_Leaves_Ash"
    },
    {
      "x": -6,
      "y": 71,
      "z": 8,
      "name": "Plant_Leaves_Ash"
    },
    {
      "x": -6,
      "y": 70,
      "z": 9,
      "name": "Plant_Leaves_Ash"
    },
    {
      "x": -6,
      "y": 71,
      "z": 9,
      "name": "Plant_Leaves_Ash"
    },
    {
      "x": -6,
      "y": 70,
      "z": 10,
      "name": "Plant_Leaves_Ash"
    },
    {
      "x": -6,
      "y": 71,
      "z": 10,
      "name": "Plant_Leaves_Ash"
    },
    {
      "x": -6,
      "y": 70,
      "z": 11,
      "name": "Plant_Leaves_Ash"
    },
    {
      "x": -6,
      "y": 71,
      "z": 11,
      "name": "Plant_Leaves_Ash"
    },
    {
      "x": -6,
      "y": 70,
      "z": 12,
      "name": "Plant_Leaves_Ash"
    },
    {
      "x": -6,
      "y": 70,
      "z": 13,
      "name": "Plant_Leaves_Ash"
    },
    {
      "x": -6,
      "y": 70,
      "z": 14,
      "name": "Plant_Leaves_Ash"
    },
    {
      "x": -6,
      "y": 69,
      "z": 15,
      "name": "Plant_Leaves_Ash"
    },
    {
      "x": -6,
      "y": 70,
      "z": 15,
      "name": "Plant_Leaves_Ash"
    },
    {
      "x": -6,
      "y": 69,
      "z": 16,
      "name": "Plant_Leaves_Ash"
    },
    {
      "x": -6,
      "y": 70,
      "z": 16,
      "name": "Plant_Leaves_Ash"
    },
    {
      "x": -6,
      "y": 68,
      "z": 17,
      "name": "Plant_Leaves_Ash"
    },
    {
      "x": -6,
      "y": 69,
      "z": 17,
      "name": "Plant_Leaves_Ash"
    },
    {
      "x": -6,
      "y": 68,
      "z": 18,
      "name": "Plant_Leaves_Ash"
    },
    {
      "x": -6,
      "y": 69,
      "z": 18,
      "name": "Plant_Leaves_Ash"
    },
    {
      "x": -6,
      "y": 68,
      "z": 19,
      "name": "Plant_Leaves_Ash"
    },
    {
      "x": -5,
      "y": 68,
      "z": -19,
      "name": "Plant_Leaves_Ash"
    },
    {
      "x": -5,
      "y": 68,
      "z": -18,
      "name": "Plant_Leaves_Ash"
    },
    {
      "x": -5,
      "y": 69,
      "z": -18,
      "name": "Plant_Leaves_Ash"
    },
    {
      "x": -5,
      "y": 68,
      "z": -17,
      "name": "Plant_Leaves_Ash"
    },
    {
      "x": -5,
      "y": 69,
      "z": -17,
      "name": "Plant_Leaves_Ash"
    },
    {
      "x": -5,
      "y": 69,
      "z": -16,
      "name": "Plant_Leaves_Ash"
    },
    {
      "x": -5,
      "y": 70,
      "z": -16,
      "name": "Plant_Leaves_Ash"
    },
    {
      "x": -5,
      "y": 69,
      "z": -15,
      "name": "Plant_Leaves_Ash"
    },
    {
      "x": -5,
      "y": 70,
      "z": -15,
      "name": "Plant_Leaves_Ash"
    },
    {
      "x": -5,
      "y": 70,
      "z": -14,
      "name": "Plant_Leaves_Ash"
    },
    {
      "x": -5,
      "y": 70,
      "z": -13,
      "name": "Plant_Leaves_Ash"
    },
    {
      "x": -5,
      "y": 70,
      "z": -12,
      "name": "Plant_Leaves_Ash"
    },
    {
      "x": -5,
      "y": 71,
      "z": -12,
      "name": "Plant_Leaves_Ash"
    },
    {
      "x": -5,
      "y": 70,
      "z": -11,
      "name": "Plant_Leaves_Ash"
    },
    {
      "x": -5,
      "y": 71,
      "z": -11,
      "name": "Plant_Leaves_Ash"
    },
    {
      "x": -5,
      "y": 70,
      "z": -10,
      "name": "Plant_Leaves_Ash"
    },
    {
      "x": -5,
      "y": 71,
      "z": -10,
      "name": "Plant_Leaves_Ash"
    },
    {
      "x": -5,
      "y": 70,
      "z": -9,
      "name": "Plant_Leaves_Ash"
    },
    {
      "x": -5,
      "y": 71,
      "z": -9,
      "name": "Plant_Leaves_Ash"
    },
    {
      "x": -5,
      "y": 70,
      "z": -8,
      "name": "Plant_Leaves_Ash"
    },
    {
      "x": -5,
      "y": 71,
      "z": -8,
      "name": "Plant_Leaves_Ash"
    },
    {
      "x": -5,
      "y": 70,
      "z": -7,
      "name": "Plant_Leaves_Ash"
    },
    {
      "x": -5,
      "y": 71,
      "z": -7,
      "name": "Plant_Leaves_Ash"
    },
    {
      "x": -5,
      "y": 70,
      "z": -6,
      "name": "Plant_Leaves_Ash"
    },
    {
      "x": -5,
      "y": 71,
      "z": -6,
      "name": "Plant_Leaves_Ash"
    },
    {
      "x": -5,
      "y": 70,
      "z": -5,
      "name": "Plant_Leaves_Ash"
    },
    {
      "x": -5,
      "y": 71,
      "z": -5,
      "name": "Plant_Leaves_Ash"
    },
    {
      "x": -5,
      "y": 70,
      "z": -4,
      "name": "Plant_Leaves_Ash"
    },
    {
      "x": -5,
      "y": 71,
      "z": -4,
      "name": "Plant_Leaves_Ash"
    },
    {
      "x": -5,
      "y": 70,
      "z": -3,
      "name": "Plant_Leaves_Ash"
    },
    {
      "x": -5,
      "y": 71,
      "z": -3,
      "name": "Plant_Leaves_Ash"
    },
    {
      "x": -5,
      "y": 70,
      "z": -2,
      "name": "Plant_Leaves_Ash"
    },
    {
      "x": -5,
      "y": 71,
      "z": -2,
      "name": "Plant_Leaves_Ash"
    },
    {
      "x": -5,
      "y": 70,
      "z": -1,
      "name": "Plant_Leaves_Ash"
    },
    {
      "x": -5,
      "y": 71,
      "z": -1,
      "name": "Plant_Leaves_Ash"
    },
    {
      "x": -5,
      "y": 70,
      "z": 0,
      "name": "Plant_Leaves_Ash"
    },
    {
      "x": -5,
      "y": 71,
      "z": 0,
      "name": "Plant_Leaves_Ash"
    },
    {
      "x": -5,
      "y": 70,
      "z": 1,
      "name": "Plant_Leaves_Ash"
    },
    {
      "x": -5,
      "y": 71,
      "z": 1,
      "name": "Plant_Leaves_Ash"
    },
    {
      "x": -5,
      "y": 70,
      "z": 2,
      "name": "Plant_Leaves_Ash"
    },
    {
      "x": -5,
      "y": 71,
      "z": 2,
      "name": "Plant_Leaves_Ash"
    },
    {
      "x": -5,
      "y": 70,
      "z": 3,
      "name": "Plant_Leaves_Ash"
    },
    {
      "x": -5,
      "y": 71,
      "z": 3,
      "name": "Plant_Leaves_Ash"
    },
    {
      "x": -5,
      "y": 70,
      "z": 4,
      "name": "Plant_Leaves_Ash"
    },
    {
      "x": -5,
      "y": 71,
      "z": 4,
      "name": "Plant_Leaves_Ash"
    },
    {
      "x": -5,
      "y": 70,
      "z": 5,
      "name": "Plant_Leaves_Ash"
    },
    {
      "x": -5,
      "y": 71,
      "z": 5,
      "name": "Plant_Leaves_Ash"
    },
    {
      "x": -5,
      "y": 70,
      "z": 6,
      "name": "Plant_Leaves_Ash"
    },
    {
      "x": -5,
      "y": 71,
      "z": 6,
      "name": "Plant_Leaves_Ash"
    },
    {
      "x": -5,
      "y": 70,
      "z": 7,
      "name": "Plant_Leaves_Ash"
    },
    {
      "x": -5,
      "y": 71,
      "z": 7,
      "name": "Plant_Leaves_Ash"
    },
    {
      "x": -5,
      "y": 70,
      "z": 8,
      "name": "Plant_Leaves_Ash"
    },
    {
      "x": -5,
      "y": 71,
      "z": 8,
      "name": "Plant_Leaves_Ash"
    },
    {
      "x": -5,
      "y": 70,
      "z": 9,
      "name": "Plant_Leaves_Ash"
    },
    {
      "x": -5,
      "y": 71,
      "z": 9,
      "name": "Plant_Leaves_Ash"
    },
    {
      "x": -5,
      "y": 70,
      "z": 10,
      "name": "Plant_Leaves_Ash"
    },
    {
      "x": -5,
      "y": 71,
      "z": 10,
      "name": "Plant_Leaves_Ash"
    },
    {
      "x": -5,
      "y": 70,
      "z": 11,
      "name": "Plant_Leaves_Ash"
    },
    {
      "x": -5,
      "y": 71,
      "z": 11,
      "name": "Plant_Leaves_Ash"
    },
    {
      "x": -5,
      "y": 70,
      "z": 12,
      "name": "Plant_Leaves_Ash"
    },
    {
      "x": -5,
      "y": 71,
      "z": 12,
      "name": "Plant_Leaves_Ash"
    },
    {
      "x": -5,
      "y": 70,
      "z": 13,
      "name": "Plant_Leaves_Ash"
    },
    {
      "x": -5,
      "y": 70,
      "z": 14,
      "name": "Plant_Leaves_Ash"
    },
    {
      "x": -5,
      "y": 69,
      "z": 15,
      "name": "Plant_Leaves_Ash"
    },
    {
      "x": -5,
      "y": 70,
      "z": 15,
      "name": "Plant_Leaves_Ash"
    },
    {
      "x": -5,
      "y": 69,
      "z": 16,
      "name": "Plant_Leaves_Ash"
    },
    {
      "x": -5,
      "y": 70,
      "z": 16,
      "name": "Plant_Leaves_Ash"
    },
    {
      "x": -5,
      "y": 68,
      "z": 17,
      "name": "Plant_Leaves_Ash"
    },
    {
      "x": -5,
      "y": 69,
      "z": 17,
      "name": "Plant_Leaves_Ash"
    },
    {
      "x": -5,
      "y": 68,
      "z": 18,
      "name": "Plant_Leaves_Ash"
    },
    {
      "x": -5,
      "y": 69,
      "z": 18,
      "name": "Plant_Leaves_Ash"
    },
    {
      "x": -5,
      "y": 68,
      "z": 19,
      "name": "Plant_Leaves_Ash"
    },
    {
      "x": -4,
      "y": 68,
      "z": -20,
      "name": "Plant_Leaves_Ash"
    },
    {
      "x": -4,
      "y": 68,
      "z": -19,
      "name": "Plant_Leaves_Ash"
    },
    {
      "x": -4,
      "y": 68,
      "z": -18,
      "name": "Plant_Leaves_Ash"
    },
    {
      "x": -4,
      "y": 69,
      "z": -18,
      "name": "Plant_Leaves_Ash"
    },
    {
      "x": -4,
      "y": 68,
      "z": -17,
      "name": "Plant_Leaves_Ash"
    },
    {
      "x": -4,
      "y": 69,
      "z": -17,
      "name": "Plant_Leaves_Ash"
    },
    {
      "x": -4,
      "y": 69,
      "z": -16,
      "name": "Plant_Leaves_Ash"
    },
    {
      "x": -4,
      "y": 70,
      "z": -16,
      "name": "Plant_Leaves_Ash"
    },
    {
      "x": -4,
      "y": 69,
      "z": -15,
      "name": "Plant_Leaves_Ash"
    },
    {
      "x": -4,
      "y": 70,
      "z": -15,
      "name": "Plant_Leaves_Ash"
    },
    {
      "x": -4,
      "y": 70,
      "z": -14,
      "name": "Plant_Leaves_Ash"
    },
    {
      "x": -4,
      "y": 70,
      "z": -13,
      "name": "Plant_Leaves_Ash"
    },
    {
      "x": -4,
      "y": 70,
      "z": -12,
      "name": "Plant_Leaves_Ash"
    },
    {
      "x": -4,
      "y": 71,
      "z": -12,
      "name": "Plant_Leaves_Ash"
    },
    {
      "x": -4,
      "y": 70,
      "z": -11,
      "name": "Plant_Leaves_Ash"
    },
    {
      "x": -4,
      "y": 71,
      "z": -11,
      "name": "Plant_Leaves_Ash"
    },
    {
      "x": -4,
      "y": 70,
      "z": -10,
      "name": "Plant_Leaves_Ash"
    },
    {
      "x": -4,
      "y": 71,
      "z": -10,
      "name": "Plant_Leaves_Ash"
    },
    {
      "x": -4,
      "y": 70,
      "z": -9,
      "name": "Plant_Leaves_Ash"
    },
    {
      "x": -4,
      "y": 71,
      "z": -9,
      "name": "Plant_Leaves_Ash"
    },
    {
      "x": -4,
      "y": 70,
      "z": -8,
      "name": "Plant_Leaves_Ash"
    },
    {
      "x": -4,
      "y": 71,
      "z": -8,
      "name": "Plant_Leaves_Ash"
    },
    {
      "x": -4,
      "y": 70,
      "z": -7,
      "name": "Plant_Leaves_Ash"
    },
    {
      "x": -4,
      "y": 71,
      "z": -7,
      "name": "Plant_Leaves_Ash"
    },
    {
      "x": -4,
      "y": 70,
      "z": -6,
      "name": "Plant_Leaves_Ash"
    },
    {
      "x": -4,
      "y": 71,
      "z": -6,
      "name": "Plant_Leaves_Ash"
    },
    {
      "x": -4,
      "y": 70,
      "z": -5,
      "name": "Plant_Leaves_Ash"
    },
    {
      "x": -4,
      "y": 71,
      "z": -5,
      "name": "Plant_Leaves_Ash"
    },
    {
      "x": -4,
      "y": 70,
      "z": -4,
      "name": "Plant_Leaves_Ash"
    },
    {
      "x": -4,
      "y": 71,
      "z": -4,
      "name": "Plant_Leaves_Ash"
    },
    {
      "x": -4,
      "y": 70,
      "z": -3,
      "name": "Plant_Leaves_Ash"
    },
    {
      "x": -4,
      "y": 71,
      "z": -3,
      "name": "Plant_Leaves_Ash"
    },
    {
      "x": -4,
      "y": 70,
      "z": -2,
      "name": "Plant_Leaves_Ash"
    },
    {
      "x": -4,
      "y": 71,
      "z": -2,
      "name": "Plant_Leaves_Ash"
    },
    {
      "x": -4,
      "y": 70,
      "z": -1,
      "name": "Plant_Leaves_Ash"
    },
    {
      "x": -4,
      "y": 71,
      "z": -1,
      "name": "Plant_Leaves_Ash"
    },
    {
      "x": -4,
      "y": 70,
      "z": 0,
      "name": "Plant_Leaves_Ash"
    },
    {
      "x": -4,
      "y": 71,
      "z": 0,
      "name": "Plant_Leaves_Ash"
    },
    {
      "x": -4,
      "y": 70,
      "z": 1,
      "name": "Plant_Leaves_Ash"
    },
    {
      "x": -4,
      "y": 71,
      "z": 1,
      "name": "Plant_Leaves_Ash"
    },
    {
      "x": -4,
      "y": 70,
      "z": 2,
      "name": "Plant_Leaves_Ash"
    },
    {
      "x": -4,
      "y": 71,
      "z": 2,
      "name": "Plant_Leaves_Ash"
    },
    {
      "x": -4,
      "y": 70,
      "z": 3,
      "name": "Plant_Leaves_Ash"
    },
    {
      "x": -4,
      "y": 71,
      "z": 3,
      "name": "Plant_Leaves_Ash"
    },
    {
      "x": -4,
      "y": 70,
      "z": 4,
      "name": "Plant_Leaves_Ash"
    },
    {
      "x": -4,
      "y": 71,
      "z": 4,
      "name": "Plant_Leaves_Ash"
    },
    {
      "x": -4,
      "y": 70,
      "z": 5,
      "name": "Plant_Leaves_Ash"
    },
    {
      "x": -4,
      "y": 71,
      "z": 5,
      "name": "Plant_Leaves_Ash"
    },
    {
      "x": -4,
      "y": 70,
      "z": 6,
      "name": "Plant_Leaves_Ash"
    },
    {
      "x": -4,
      "y": 71,
      "z": 6,
      "name": "Plant_Leaves_Ash"
    },
    {
      "x": -4,
      "y": 70,
      "z": 7,
      "name": "Plant_Leaves_Ash"
    },
    {
      "x": -4,
      "y": 71,
      "z": 7,
      "name": "Plant_Leaves_Ash"
    },
    {
      "x": -4,
      "y": 70,
      "z": 8,
      "name": "Plant_Leaves_Ash"
    },
    {
      "x": -4,
      "y": 71,
      "z": 8,
      "name": "Plant_Leaves_Ash"
    },
    {
      "x": -4,
      "y": 70,
      "z": 9,
      "name": "Plant_Leaves_Ash"
    },
    {
      "x": -4,
      "y": 71,
      "z": 9,
      "name": "Plant_Leaves_Ash"
    },
    {
      "x": -4,
      "y": 70,
      "z": 10,
      "name": "Plant_Leaves_Ash"
    },
    {
      "x": -4,
      "y": 71,
      "z": 10,
      "name": "Plant_Leaves_Ash"
    },
    {
      "x": -4,
      "y": 70,
      "z": 11,
      "name": "Plant_Leaves_Ash"
    },
    {
      "x": -4,
      "y": 71,
      "z": 11,
      "name": "Plant_Leaves_Ash"
    },
    {
      "x": -4,
      "y": 70,
      "z": 12,
      "name": "Plant_Leaves_Ash"
    },
    {
      "x": -4,
      "y": 71,
      "z": 12,
      "name": "Plant_Leaves_Ash"
    },
    {
      "x": -4,
      "y": 70,
      "z": 13,
      "name": "Plant_Leaves_Ash"
    },
    {
      "x": -4,
      "y": 70,
      "z": 14,
      "name": "Plant_Leaves_Ash"
    },
    {
      "x": -4,
      "y": 69,
      "z": 15,
      "name": "Plant_Leaves_Ash"
    },
    {
      "x": -4,
      "y": 70,
      "z": 15,
      "name": "Plant_Leaves_Ash"
    },
    {
      "x": -4,
      "y": 69,
      "z": 16,
      "name": "Plant_Leaves_Ash"
    },
    {
      "x": -4,
      "y": 70,
      "z": 16,
      "name": "Plant_Leaves_Ash"
    },
    {
      "x": -4,
      "y": 68,
      "z": 17,
      "name": "Plant_Leaves_Ash"
    },
    {
      "x": -4,
      "y": 69,
      "z": 17,
      "name": "Plant_Leaves_Ash"
    },
    {
      "x": -4,
      "y": 68,
      "z": 18,
      "name": "Plant_Leaves_Ash"
    },
    {
      "x": -4,
      "y": 69,
      "z": 18,
      "name": "Plant_Leaves_Ash"
    },
    {
      "x": -4,
      "y": 68,
      "z": 19,
      "name": "Plant_Leaves_Ash"
    },
    {
      "x": -4,
      "y": 68,
      "z": 20,
      "name": "Plant_Leaves_Ash"
    },
    {
      "x": -3,
      "y": 68,
      "z": -20,
      "name": "Plant_Leaves_Ash"
    },
    {
      "x": -3,
      "y": 68,
      "z": -19,
      "name": "Plant_Leaves_Ash"
    },
    {
      "x": -3,
      "y": 69,
      "z": -19,
      "name": "Plant_Leaves_Ash"
    },
    {
      "x": -3,
      "y": 68,
      "z": -18,
      "name": "Plant_Leaves_Ash"
    },
    {
      "x": -3,
      "y": 69,
      "z": -18,
      "name": "Plant_Leaves_Ash"
    },
    {
      "x": -3,
      "y": 69,
      "z": -17,
      "name": "Plant_Leaves_Ash"
    },
    {
      "x": -3,
      "y": 70,
      "z": -17,
      "name": "Plant_Leaves_Ash"
    },
    {
      "x": -3,
      "y": 69,
      "z": -16,
      "name": "Plant_Leaves_Ash"
    },
    {
      "x": -3,
      "y": 70,
      "z": -16,
      "name": "Plant_Leaves_Ash"
    },
    {
      "x": -3,
      "y": 70,
      "z": -15,
      "name": "Plant_Leaves_Ash"
    },
    {
      "x": -3,
      "y": 70,
      "z": -14,
      "name": "Plant_Leaves_Ash"
    },
    {
      "x": -3,
      "y": 70,
      "z": -13,
      "name": "Plant_Leaves_Ash"
    },
    {
      "x": -3,
      "y": 71,
      "z": -13,
      "name": "Plant_Leaves_Ash"
    },
    {
      "x": -3,
      "y": 70,
      "z": -12,
      "name": "Plant_Leaves_Ash"
    },
    {
      "x": -3,
      "y": 71,
      "z": -12,
      "name": "Plant_Leaves_Ash"
    },
    {
      "x": -3,
      "y": 70,
      "z": -11,
      "name": "Plant_Leaves_Ash"
    },
    {
      "x": -3,
      "y": 71,
      "z": -11,
      "name": "Plant_Leaves_Ash"
    },
    {
      "x": -3,
      "y": 70,
      "z": -10,
      "name": "Plant_Leaves_Ash"
    },
    {
      "x": -3,
      "y": 71,
      "z": -10,
      "name": "Plant_Leaves_Ash"
    },
    {
      "x": -3,
      "y": 70,
      "z": -9,
      "name": "Plant_Leaves_Ash"
    },
    {
      "x": -3,
      "y": 71,
      "z": -9,
      "name": "Plant_Leaves_Ash"
    },
    {
      "x": -3,
      "y": 70,
      "z": -8,
      "name": "Plant_Leaves_Ash"
    },
    {
      "x": -3,
      "y": 71,
      "z": -8,
      "name": "Plant_Leaves_Ash"
    },
    {
      "x": -3,
      "y": 70,
      "z": -7,
      "name": "Plant_Leaves_Ash"
    },
    {
      "x": -3,
      "y": 71,
      "z": -7,
      "name": "Plant_Leaves_Ash"
    },
    {
      "x": -3,
      "y": 70,
      "z": -6,
      "name": "Plant_Leaves_Ash"
    },
    {
      "x": -3,
      "y": 71,
      "z": -6,
      "name": "Plant_Leaves_Ash"
    },
    {
      "x": -3,
      "y": 70,
      "z": -5,
      "name": "Plant_Leaves_Ash"
    },
    {
      "x": -3,
      "y": 71,
      "z": -5,
      "name": "Plant_Leaves_Ash"
    },
    {
      "x": -3,
      "y": 70,
      "z": -4,
      "name": "Plant_Leaves_Ash"
    },
    {
      "x": -3,
      "y": 71,
      "z": -4,
      "name": "Plant_Leaves_Ash"
    },
    {
      "x": -3,
      "y": 70,
      "z": -3,
      "name": "Plant_Leaves_Ash"
    },
    {
      "x": -3,
      "y": 71,
      "z": -3,
      "name": "Plant_Leaves_Ash"
    },
    {
      "x": -3,
      "y": 70,
      "z": -2,
      "name": "Plant_Leaves_Ash"
    },
    {
      "x": -3,
      "y": 71,
      "z": -2,
      "name": "Plant_Leaves_Ash"
    },
    {
      "x": -3,
      "y": 70,
      "z": -1,
      "name": "Plant_Leaves_Ash"
    },
    {
      "x": -3,
      "y": 71,
      "z": -1,
      "name": "Plant_Leaves_Ash"
    },
    {
      "x": -3,
      "y": 70,
      "z": 0,
      "name": "Plant_Leaves_Ash"
    },
    {
      "x": -3,
      "y": 71,
      "z": 0,
      "name": "Plant_Leaves_Ash"
    },
    {
      "x": -3,
      "y": 70,
      "z": 1,
      "name": "Plant_Leaves_Ash"
    },
    {
      "x": -3,
      "y": 71,
      "z": 1,
      "name": "Plant_Leaves_Ash"
    },
    {
      "x": -3,
      "y": 70,
      "z": 2,
      "name": "Plant_Leaves_Ash"
    },
    {
      "x": -3,
      "y": 71,
      "z": 2,
      "name": "Plant_Leaves_Ash"
    },
    {
      "x": -3,
      "y": 70,
      "z": 3,
      "name": "Plant_Leaves_Ash"
    },
    {
      "x": -3,
      "y": 71,
      "z": 3,
      "name": "Plant_Leaves_Ash"
    },
    {
      "x": -3,
      "y": 70,
      "z": 4,
      "name": "Plant_Leaves_Ash"
    },
    {
      "x": -3,
      "y": 71,
      "z": 4,
      "name": "Plant_Leaves_Ash"
    },
    {
      "x": -3,
      "y": 70,
      "z": 5,
      "name": "Plant_Leaves_Ash"
    },
    {
      "x": -3,
      "y": 71,
      "z": 5,
      "name": "Plant_Leaves_Ash"
    },
    {
      "x": -3,
      "y": 70,
      "z": 6,
      "name": "Plant_Leaves_Ash"
    },
    {
      "x": -3,
      "y": 71,
      "z": 6,
      "name": "Plant_Leaves_Ash"
    },
    {
      "x": -3,
      "y": 70,
      "z": 7,
      "name": "Plant_Leaves_Ash"
    },
    {
      "x": -3,
      "y": 71,
      "z": 7,
      "name": "Plant_Leaves_Ash"
    },
    {
      "x": -3,
      "y": 70,
      "z": 8,
      "name": "Plant_Leaves_Ash"
    },
    {
      "x": -3,
      "y": 71,
      "z": 8,
      "name": "Plant_Leaves_Ash"
    },
    {
      "x": -3,
      "y": 70,
      "z": 9,
      "name": "Plant_Leaves_Ash"
    },
    {
      "x": -3,
      "y": 71,
      "z": 9,
      "name": "Plant_Leaves_Ash"
    },
    {
      "x": -3,
      "y": 70,
      "z": 10,
      "name": "Plant_Leaves_Ash"
    },
    {
      "x": -3,
      "y": 71,
      "z": 10,
      "name": "Plant_Leaves_Ash"
    },
    {
      "x": -3,
      "y": 70,
      "z": 11,
      "name": "Plant_Leaves_Ash"
    },
    {
      "x": -3,
      "y": 71,
      "z": 11,
      "name": "Plant_Leaves_Ash"
    },
    {
      "x": -3,
      "y": 70,
      "z": 12,
      "name": "Plant_Leaves_Ash"
    },
    {
      "x": -3,
      "y": 71,
      "z": 12,
      "name": "Plant_Leaves_Ash"
    },
    {
      "x": -3,
      "y": 70,
      "z": 13,
      "name": "Plant_Leaves_Ash"
    },
    {
      "x": -3,
      "y": 71,
      "z": 13,
      "name": "Plant_Leaves_Ash"
    },
    {
      "x": -3,
      "y": 70,
      "z": 14,
      "name": "Plant_Leaves_Ash"
    },
    {
      "x": -3,
      "y": 70,
      "z": 15,
      "name": "Plant_Leaves_Ash"
    },
    {
      "x": -3,
      "y": 69,
      "z": 16,
      "name": "Plant_Leaves_Ash"
    },
    {
      "x": -3,
      "y": 70,
      "z": 16,
      "name": "Plant_Leaves_Ash"
    },
    {
      "x": -3,
      "y": 69,
      "z": 17,
      "name": "Plant_Leaves_Ash"
    },
    {
      "x": -3,
      "y": 70,
      "z": 17,
      "name": "Plant_Leaves_Ash"
    },
    {
      "x": -3,
      "y": 68,
      "z": 18,
      "name": "Plant_Leaves_Ash"
    },
    {
      "x": -3,
      "y": 69,
      "z": 18,
      "name": "Plant_Leaves_Ash"
    },
    {
      "x": -3,
      "y": 68,
      "z": 19,
      "name": "Plant_Leaves_Ash"
    },
    {
      "x": -3,
      "y": 69,
      "z": 19,
      "name": "Plant_Leaves_Ash"
    },
    {
      "x": -3,
      "y": 68,
      "z": 20,
      "name": "Plant_Leaves_Ash"
    },
    {
      "x": -2,
      "y": 68,
      "z": -20,
      "name": "Plant_Leaves_Ash"
    },
    {
      "x": -2,
      "y": 68,
      "z": -19,
      "name": "Plant_Leaves_Ash"
    },
    {
      "x": -2,
      "y": 69,
      "z": -19,
      "name": "Plant_Leaves_Ash"
    },
    {
      "x": -2,
      "y": 68,
      "z": -18,
      "name": "Plant_Leaves_Ash"
    },
    {
      "x": -2,
      "y": 69,
      "z": -18,
      "name": "Plant_Leaves_Ash"
    },
    {
      "x": -2,
      "y": 69,
      "z": -17,
      "name": "Plant_Leaves_Ash"
    },
    {
      "x": -2,
      "y": 70,
      "z": -17,
      "name": "Plant_Leaves_Ash"
    },
    {
      "x": -2,
      "y": 69,
      "z": -16,
      "name": "Plant_Leaves_Ash"
    },
    {
      "x": -2,
      "y": 70,
      "z": -16,
      "name": "Plant_Leaves_Ash"
    },
    {
      "x": -2,
      "y": 70,
      "z": -15,
      "name": "Plant_Leaves_Ash"
    },
    {
      "x": -2,
      "y": 70,
      "z": -14,
      "name": "Plant_Leaves_Ash"
    },
    {
      "x": -2,
      "y": 70,
      "z": -13,
      "name": "Plant_Leaves_Ash"
    },
    {
      "x": -2,
      "y": 71,
      "z": -13,
      "name": "Plant_Leaves_Ash"
    },
    {
      "x": -2,
      "y": 70,
      "z": -12,
      "name": "Plant_Leaves_Ash"
    },
    {
      "x": -2,
      "y": 71,
      "z": -12,
      "name": "Plant_Leaves_Ash"
    },
    {
      "x": -2,
      "y": 70,
      "z": -11,
      "name": "Plant_Leaves_Ash"
    },
    {
      "x": -2,
      "y": 71,
      "z": -11,
      "name": "Plant_Leaves_Ash"
    },
    {
      "x": -2,
      "y": 70,
      "z": -10,
      "name": "Plant_Leaves_Ash"
    },
    {
      "x": -2,
      "y": 71,
      "z": -10,
      "name": "Plant_Leaves_Ash"
    },
    {
      "x": -2,
      "y": 70,
      "z": -9,
      "name": "Plant_Leaves_Ash"
    },
    {
      "x": -2,
      "y": 71,
      "z": -9,
      "name": "Plant_Leaves_Ash"
    },
    {
      "x": -2,
      "y": 70,
      "z": -8,
      "name": "Plant_Leaves_Ash"
    },
    {
      "x": -2,
      "y": 71,
      "z": -8,
      "name": "Plant_Leaves_Ash"
    },
    {
      "x": -2,
      "y": 70,
      "z": -7,
      "name": "Plant_Leaves_Ash"
    },
    {
      "x": -2,
      "y": 71,
      "z": -7,
      "name": "Plant_Leaves_Ash"
    },
    {
      "x": -2,
      "y": 70,
      "z": -6,
      "name": "Plant_Leaves_Ash"
    },
    {
      "x": -2,
      "y": 71,
      "z": -6,
      "name": "Plant_Leaves_Ash"
    },
    {
      "x": -2,
      "y": 70,
      "z": -5,
      "name": "Plant_Leaves_Ash"
    },
    {
      "x": -2,
      "y": 71,
      "z": -5,
      "name": "Plant_Leaves_Ash"
    },
    {
      "x": -2,
      "y": 70,
      "z": -4,
      "name": "Plant_Leaves_Ash"
    },
    {
      "x": -2,
      "y": 71,
      "z": -4,
      "name": "Plant_Leaves_Ash"
    },
    {
      "x": -2,
      "y": 70,
      "z": -3,
      "name": "Plant_Leaves_Ash"
    },
    {
      "x": -2,
      "y": 71,
      "z": -3,
      "name": "Plant_Leaves_Ash"
    },
    {
      "x": -2,
      "y": 70,
      "z": -2,
      "name": "Plant_Leaves_Ash"
    },
    {
      "x": -2,
      "y": 71,
      "z": -2,
      "name": "Plant_Leaves_Ash"
    },
    {
      "x": -2,
      "y": 70,
      "z": -1,
      "name": "Plant_Leaves_Ash"
    },
    {
      "x": -2,
      "y": 71,
      "z": -1,
      "name": "Plant_Leaves_Ash"
    },
    {
      "x": -2,
      "y": 70,
      "z": 0,
      "name": "Plant_Leaves_Ash"
    },
    {
      "x": -2,
      "y": 71,
      "z": 0,
      "name": "Plant_Leaves_Ash"
    },
    {
      "x": -2,
      "y": 70,
      "z": 1,
      "name": "Plant_Leaves_Ash"
    },
    {
      "x": -2,
      "y": 71,
      "z": 1,
      "name": "Plant_Leaves_Ash"
    },
    {
      "x": -2,
      "y": 70,
      "z": 2,
      "name": "Plant_Leaves_Ash"
    },
    {
      "x": -2,
      "y": 71,
      "z": 2,
      "name": "Plant_Leaves_Ash"
    },
    {
      "x": -2,
      "y": 70,
      "z": 3,
      "name": "Plant_Leaves_Ash"
    },
    {
      "x": -2,
      "y": 71,
      "z": 3,
      "name": "Plant_Leaves_Ash"
    },
    {
      "x": -2,
      "y": 70,
      "z": 4,
      "name": "Plant_Leaves_Ash"
    },
    {
      "x": -2,
      "y": 71,
      "z": 4,
      "name": "Plant_Leaves_Ash"
    },
    {
      "x": -2,
      "y": 70,
      "z": 5,
      "name": "Plant_Leaves_Ash"
    },
    {
      "x": -2,
      "y": 71,
      "z": 5,
      "name": "Plant_Leaves_Ash"
    },
    {
      "x": -2,
      "y": 70,
      "z": 6,
      "name": "Plant_Leaves_Ash"
    },
    {
      "x": -2,
      "y": 71,
      "z": 6,
      "name": "Plant_Leaves_Ash"
    },
    {
      "x": -2,
      "y": 70,
      "z": 7,
      "name": "Plant_Leaves_Ash"
    },
    {
      "x": -2,
      "y": 71,
      "z": 7,
      "name": "Plant_Leaves_Ash"
    },
    {
      "x": -2,
      "y": 70,
      "z": 8,
      "name": "Plant_Leaves_Ash"
    },
    {
      "x": -2,
      "y": 71,
      "z": 8,
      "name": "Plant_Leaves_Ash"
    },
    {
      "x": -2,
      "y": 70,
      "z": 9,
      "name": "Plant_Leaves_Ash"
    },
    {
      "x": -2,
      "y": 71,
      "z": 9,
      "name": "Plant_Leaves_Ash"
    },
    {
      "x": -2,
      "y": 70,
      "z": 10,
      "name": "Plant_Leaves_Ash"
    },
    {
      "x": -2,
      "y": 71,
      "z": 10,
      "name": "Plant_Leaves_Ash"
    },
    {
      "x": -2,
      "y": 70,
      "z": 11,
      "name": "Plant_Leaves_Ash"
    },
    {
      "x": -2,
      "y": 71,
      "z": 11,
      "name": "Plant_Leaves_Ash"
    },
    {
      "x": -2,
      "y": 70,
      "z": 12,
      "name": "Plant_Leaves_Ash"
    },
    {
      "x": -2,
      "y": 71,
      "z": 12,
      "name": "Plant_Leaves_Ash"
    },
    {
      "x": -2,
      "y": 70,
      "z": 13,
      "name": "Plant_Leaves_Ash"
    },
    {
      "x": -2,
      "y": 71,
      "z": 13,
      "name": "Plant_Leaves_Ash"
    },
    {
      "x": -2,
      "y": 70,
      "z": 14,
      "name": "Plant_Leaves_Ash"
    },
    {
      "x": -2,
      "y": 70,
      "z": 15,
      "name": "Plant_Leaves_Ash"
    },
    {
      "x": -2,
      "y": 69,
      "z": 16,
      "name": "Plant_Leaves_Ash"
    },
    {
      "x": -2,
      "y": 70,
      "z": 16,
      "name": "Plant_Leaves_Ash"
    },
    {
      "x": -2,
      "y": 69,
      "z": 17,
      "name": "Plant_Leaves_Ash"
    },
    {
      "x": -2,
      "y": 70,
      "z": 17,
      "name": "Plant_Leaves_Ash"
    },
    {
      "x": -2,
      "y": 68,
      "z": 18,
      "name": "Plant_Leaves_Ash"
    },
    {
      "x": -2,
      "y": 69,
      "z": 18,
      "name": "Plant_Leaves_Ash"
    },
    {
      "x": -2,
      "y": 68,
      "z": 19,
      "name": "Plant_Leaves_Ash"
    },
    {
      "x": -2,
      "y": 69,
      "z": 19,
      "name": "Plant_Leaves_Ash"
    },
    {
      "x": -2,
      "y": 68,
      "z": 20,
      "name": "Plant_Leaves_Ash"
    },
    {
      "x": -1,
      "y": 68,
      "z": -20,
      "name": "Plant_Leaves_Ash"
    },
    {
      "x": -1,
      "y": 68,
      "z": -19,
      "name": "Plant_Leaves_Ash"
    },
    {
      "x": -1,
      "y": 69,
      "z": -19,
      "name": "Plant_Leaves_Ash"
    },
    {
      "x": -1,
      "y": 68,
      "z": -18,
      "name": "Plant_Leaves_Ash"
    },
    {
      "x": -1,
      "y": 69,
      "z": -18,
      "name": "Plant_Leaves_Ash"
    },
    {
      "x": -1,
      "y": 69,
      "z": -17,
      "name": "Plant_Leaves_Ash"
    },
    {
      "x": -1,
      "y": 70,
      "z": -17,
      "name": "Plant_Leaves_Ash"
    },
    {
      "x": -1,
      "y": 69,
      "z": -16,
      "name": "Plant_Leaves_Ash"
    },
    {
      "x": -1,
      "y": 70,
      "z": -16,
      "name": "Plant_Leaves_Ash"
    },
    {
      "x": -1,
      "y": 70,
      "z": -15,
      "name": "Plant_Leaves_Ash"
    },
    {
      "x": -1,
      "y": 70,
      "z": -14,
      "name": "Plant_Leaves_Ash"
    },
    {
      "x": -1,
      "y": 70,
      "z": -13,
      "name": "Plant_Leaves_Ash"
    },
    {
      "x": -1,
      "y": 71,
      "z": -13,
      "name": "Plant_Leaves_Ash"
    },
    {
      "x": -1,
      "y": 70,
      "z": -12,
      "name": "Plant_Leaves_Ash"
    },
    {
      "x": -1,
      "y": 71,
      "z": -12,
      "name": "Plant_Leaves_Ash"
    },
    {
      "x": -1,
      "y": 70,
      "z": -11,
      "name": "Plant_Leaves_Ash"
    },
    {
      "x": -1,
      "y": 71,
      "z": -11,
      "name": "Plant_Leaves_Ash"
    },
    {
      "x": -1,
      "y": 70,
      "z": -10,
      "name": "Plant_Leaves_Ash"
    },
    {
      "x": -1,
      "y": 71,
      "z": -10,
      "name": "Plant_Leaves_Ash"
    },
    {
      "x": -1,
      "y": 70,
      "z": -9,
      "name": "Plant_Leaves_Ash"
    },
    {
      "x": -1,
      "y": 71,
      "z": -9,
      "name": "Plant_Leaves_Ash"
    },
    {
      "x": -1,
      "y": 70,
      "z": -8,
      "name": "Plant_Leaves_Ash"
    },
    {
      "x": -1,
      "y": 71,
      "z": -8,
      "name": "Plant_Leaves_Ash"
    },
    {
      "x": -1,
      "y": 70,
      "z": -7,
      "name": "Plant_Leaves_Ash"
    },
    {
      "x": -1,
      "y": 71,
      "z": -7,
      "name": "Plant_Leaves_Ash"
    },
    {
      "x": -1,
      "y": 70,
      "z": -6,
      "name": "Plant_Leaves_Ash"
    },
    {
      "x": -1,
      "y": 71,
      "z": -6,
      "name": "Plant_Leaves_Ash"
    },
    {
      "x": -1,
      "y": 70,
      "z": -5,
      "name": "Plant_Leaves_Ash"
    },
    {
      "x": -1,
      "y": 71,
      "z": -5,
      "name": "Plant_Leaves_Ash"
    },
    {
      "x": -1,
      "y": 70,
      "z": -4,
      "name": "Plant_Leaves_Ash"
    },
    {
      "x": -1,
      "y": 71,
      "z": -4,
      "name": "Plant_Leaves_Ash"
    },
    {
      "x": -1,
      "y": 70,
      "z": -3,
      "name": "Plant_Leaves_Ash"
    },
    {
      "x": -1,
      "y": 71,
      "z": -3,
      "name": "Plant_Leaves_Ash"
    },
    {
      "x": -1,
      "y": 70,
      "z": -2,
      "name": "Plant_Leaves_Ash"
    },
    {
      "x": -1,
      "y": 71,
      "z": -2,
      "name": "Plant_Leaves_Ash"
    },
    {
      "x": -1,
      "y": 0,
      "z": -1,
      "name": "Wood_Oak_Trunk",
      "support": 15
    },
    {
      "x": -1,
      "y": 1,
      "z": -1,
      "name": "Wood_Oak_Trunk",
      "support": 15
    },
    {
      "x": -1,
      "y": 2,
      "z": -1,
      "name": "Wood_Oak_Trunk",
      "support": 15
    },
    {
      "x": -1,
      "y": 3,
      "z": -1,
      "name": "Wood_Oak_Trunk",
      "support": 15
    },
    {
      "x": -1,
      "y": 4,
      "z": -1,
      "name": "Wood_Oak_Trunk",
      "support": 15
    },
    {
      "x": -1,
      "y": 5,
      "z": -1,
      "name": "Wood_Oak_Trunk"
    },
    {
      "x": -1,
      "y": 6,
      "z": -1,
      "name": "Wood_Oak_Trunk"
    },
    {
      "x": -1,
      "y": 7,
      "z": -1,
      "name": "Wood_Oak_Trunk"
    },
    {
      "x": -1,
      "y": 8,
      "z": -1,
      "name": "Wood_Oak_Trunk"
    },
    {
      "x": -1,
      "y": 9,
      "z": -1,
      "name": "Wood_Oak_Trunk"
    },
    {
      "x": -1,
      "y": 10,
      "z": -1,
      "name": "Wood_Oak_Trunk"
    },
    {
      "x": -1,
      "y": 11,
      "z": -1,
      "name": "Wood_Oak_Trunk"
    },
    {
      "x": -1,
      "y": 12,
      "z": -1,
      "name": "Wood_Oak_Trunk"
    },
    {
      "x": -1,
      "y": 13,
      "z": -1,
      "name": "Wood_Oak_Trunk"
    },
    {
      "x": -1,
      "y": 14,
      "z": -1,
      "name": "Wood_Oak_Trunk"
    },
    {
      "x": -1,
      "y": 15,
      "z": -1,
      "name": "Wood_Oak_Trunk"
    },
    {
      "x": -1,
      "y": 16,
      "z": -1,
      "name": "Wood_Oak_Trunk"
    },
    {
