{
  "version": 8,
  "blockIdVersion": 11,
  "anchorX": 0,
  "anchorY": 1,
  "anchorZ": 0,
  "blocks": [
    {
      "x": -20,
      "y": 58,
      "z": -4,
      "name": "Plant_Leaves_Ash"
    },
    {
      "x": -20,
      "y": 58,
      "z": -3,
      "name": "Plant_Leaves_Ash"
    },
    {
      "x": -20,
      "y": 58,
      "z": -2,
      "name": "Plant_Leaves_Ash"
    },
    {
      "x": -20,
      "y": 58,
      "z": -1,
      "name": "Plant_Leaves_Ash"
    },
    {
      "x": -20,
      "y": 58,
      "z": 0,
      "name": "Plant_Leaves_Ash"
    },
    {
      "x": -20,
      "y": 58,
      "z": 1,
      "name": "Plant_Leaves_Ash"
    },
    {
      "x": -20,
      "y": 58,
      "z": 2,
      "name": "Plant_Leaves_Ash"
    },
    {
      "x": -20,
      "y": 58,
      "z": 3,
      "name": "Plant_Leaves_Ash"
    },
    {
      "x": -20,
      "y": 58,
      "z": 4,
      "name": "Plant_Leaves_Ash"
    },
    {
      "x": -19,
      "y": 58,
      "z": -7,
      "name": "Plant_Leaves_Ash"
    },
    {
      "x": -19,
      "y": 58,
      "z": -6,
      "name": "Plant_Leaves_Ash"
    },
    {
      "x": -19,
      "y": 58,
      "z": -5,
      "name": "Plant_Leaves_Ash"
    },
    {
      "x": -19,
      "y": 58,
      "z": -4,
      "name": "Plant_Leaves_Ash"
    },
    {
      "x": -19,
      "y": 58,
      "z": -3,
      "name": "Plant_Leaves_Ash"
    },
    {
      "x": -19,
      "y": 59,
      "z": -3,
      "name": "Plant_Leaves_Ash"
    },
    {
      "x": -19,
      "y": 58,
      "z": -2,
      "name": "Plant_Leaves_Ash"
    },
    {
      "x": -19,
      "y": 59,
      "z": -2,
      "name": "Plant_Leaves_Ash"
    },
    {
      "x": -19,
      "y": 58,
      "z": -1,
      "name": "Plant_Leaves_Ash"
    },
    {
      "x": -19,
      "y": 59,
      "z": -1,
      "name": "Plant_Leaves_Ash"
    },
    {
      "x": -19,
      "y": 58,
      "z": 0,
      "name": "Plant_Leaves_Ash"
    },
    {
      "x": -19,
      "y": 59,
      "z": 0,
      "name": "Plant_Leaves_Ash"
    },
    {
      "x": -19,
      "y": 58,
      "z": 1,
      "name": "Plant_Leaves_Ash"
    },
    {
      "x": -19,
      "y": 59,
      "z": 1,
      "name": "Plant_Leaves_Ash"
    },
    {
      "x": -19,
      "y": 58,
      "z": 2,
      "name": "Plant_Leaves_Ash"
    },
    {
      "x": -19,
      "y": 59,
      "z": 2,
      "name": "Plant_Leaves_Ash"
    },
    {
      "x": -19,
      "y": 58,
      "z": 3,
      "name": "Plant_Leaves_Ash"
    },
    {
      "x": -19,
      "y": 59,
      "z": 3,
      "name": "Plant_Leaves_Ash"
    },
    {
      "x": -19,
      "y": 58,
      "z": 4,
      "name": "Plant_Leaves_Ash"
    },
    {
      "x": -19,
      "y": 58,
      "z": 5,
      "name": "Plant_Leaves_Ash"
    },
    {
      "x": -19,
      "y": 58,
      "z": 6,
      "name": "Plant_Leaves_Ash"
    },
    {
      "x": -19,
      "y": 58,
      "z": 7,
      "name": "Plant_Leaves_Ash"
    },
    {
      "x": -18,
      "y": 58,
      "z": -9,
      "name": "Plant_Leaves_Ash"
    },
    {
      "x": -18,
      "y": 58,
      "z": -8,
      "name": "Plant_Leaves_Ash"
    },
    {
      "x": -18,
      "y": 58,
      "z": -7,
      "name": "Plant_Leaves_Ash"
    },
    {
      "x": -18,
      "y": 59,
      "z": -7,
      "name": "Plant_Leaves_Ash"
    },
    {
      "x": -18,
      "y": 58,
      "z": -6,
      "name": "Plant_Leaves_Ash"
    },
    {
      "x": -18,
      "y": 59,
      "z": -6,
      "name": "Plant_Leaves_Ash"
    },
    {
      "x": -18,
      "y": 58,
      "z": -5,
      "name": "Plant_Leaves_Ash"
    },
    {
      "x": -18,
      "y": 59,
      "z": -5,
      "name": "Plant_Leaves_Ash"
    },
    {
      "x": -18,
      "y": 58,
      "z": -4,
      "name": "Plant_Leaves_Ash"
    },
    {
      "x": -18,
      "y": 59,
      "z": -4,
      "name": "Plant_Leaves_Ash"
    },
    {
      "x": -18,
      "y": 58,
      "z": -3,
      "name": "Plant_Leaves_Ash"
    },
    {
      "x": -18,
      "y": 59,
      "z": -3,
      "name": "Plant_Leaves_Ash"
    },
    {
      "x": -18,
      "y": 58,
      "z": -2,
      "name": "Plant_Leaves_Ash"
    },
    {
      "x": -18,
      "y": 59,
      "z": -2,
      "name": "Plant_Leaves_Ash"
    },
    {
      "x": -18,
      "y": 58,
      "z": -1,
      "name": "Plant_Leaves_Ash"
    },
    {
      "x": -18,
      "y": 59,
      "z": -1,
      "name": "Plant_Leaves_Ash"
    },
    {
      "x": -18,
      "y": 58,
      "z": 0,
      "name": "Plant_Leaves_Ash"
    },
    {
      "x": -18,
      "y": 59,
      "z": 0,
      "name": "Plant_Leaves_Ash"
    },
    {
      "x": -18,
      "y": 58,
      "z": 1,
      "name": "Plant_Leaves_Ash"
    },
    {
      "x": -18,
      "y": 59,
      "z": 1,
      "name": "Plant_Leaves_Ash"
    },
    {
      "x": -18,
      "y": 58,
      "z": 2,
      "name": "Plant_Leaves_Ash"
    },
    {
      "x": -18,
      "y": 59,
      "z": 2,
      "name": "Plant_Leaves_Ash"
    },
    {
      "x": -18,
      "y": 58,
      "z": 3,
      "name": "Plant_Leaves_Ash"
    },
    {
      "x": -18,
      "y": 59,
      "z": 3,
      "name": "Plant_Leaves_Ash"
    },
    {
      "x": -18,
      "y": 58,
      "z": 4,
      "name": "Plant_Leaves_Ash"
    },
    {
      "x": -18,
      "y": 59,
      "z": 4,
      "name": "Plant_Leaves_Ash"
    },
    {
      "x": -18,
      "y": 58,
      "z": 5,
      "name": "Plant_Leaves_Ash"
    },
    {
      "x": -18,
      "y": 59,
      "z": 5,
      "name": "Plant_Leaves_Ash"
    },
    {
      "x": -18,
      "y": 58,
      "z": 6,
      "name": "Plant_Leaves_Ash"
    },
    {
      "x": -18,
      "y": 59,
      "z": 6,
      "name": "Plant_Leaves_Ash"
    },
    {
      "x": -18,
      "y": 58,
      "z": 7,
      "name": "Plant_Leaves_Ash"
    },
    {
      "x": -18,
      "y": 59,
      "z": 7,
      "name": "Plant_Leaves_Ash"
    },
    {
      "x": -18,
      "y": 58,
      "z": 8,
      "name": "Plant_Leaves_Ash"
    },
    {
      "x": -18,
      "y": 58,
      "z": 9,
      "name": "Plant_Leaves_Ash"
    },
    {
      "x": -17,
      "y": 58,
      "z": -11,
      "name": "Plant_Leaves_Ash"
    },
    {
      "x": -17,
      "y": 58,
      "z": -10,
      "name": "Plant_Leaves_Ash"
    },
    {
      "x": -17,
      "y": 58,
      "z": -9,
      "name": "Plant_Leaves_Ash"
    },
    {
      "x": -17,
      "y": 59,
      "z": -9,
      "name": "Plant_Leaves_Ash"
    },
    {
      "x": -17,
      "y": 58,
      "z": -8,
      "name": "Plant_Leaves_Ash"
    },
    {
      "x": -17,
      "y": 59,
      "z": -8,
      "name": "Plant_Leaves_Ash"
    },
    {
      "x": -17,
      "y": 58,
      "z": -7,
      "name": "Plant_Leaves_Ash"
    },
    {
      "x": -17,
      "y": 59,
      "z": -7,
      "name": "Plant_Leaves_Ash"
    },
    {
      "x": -17,
      "y": 58,
      "z": -6,
      "name": "Plant_Leaves_Ash"
    },
    {
      "x": -17,
      "y": 59,
      "z": -6,
      "name": "Plant_Leaves_Ash"
    },
    {
      "x": -17,
      "y": 58,
      "z": -5,
      "name": "Plant_Leaves_Ash"
    },
    {
      "x": -17,
      "y": 59,
      "z": -5,
      "name": "Plant_Leaves_Ash"
    },
    {
      "x": -17,
      "y": 58,
      "z": -4,
      "name": "Plant_Leaves_Ash"
    },
    {
      "x": -17,
      "y": 59,
      "z": -4,
      "name": "Plant_Leaves_Ash"
    },
    {
      "x": -17,
      "y": 59,
      "z": -3,
      "name": "Plant_Leaves_Ash"
    },
    {
      "x": -17,
      "y": 60,
      "z": -3,
      "name": "Plant_Leaves_Ash"
    },
    {
      "x": -17,
      "y": 59,
      "z": -2,
      "name": "Plant_Leaves_Ash"
    },
    {
      "x": -17,
      "y": 60,
      "z": -2,
      "name": "Plant_Leaves_Ash"
    },
    {
      "x": -17,
      "y": 59,
      "z": -1,
      "name": "Plant_Leaves_Ash"
    },
    {
      "x": -17,
      "y": 60,
      "z": -1,
      "name": "Plant_Leaves_Ash"
    },
    {
      "x": -17,
      "y": 59,
      "z": 0,
      "name": "Plant_Leaves_Ash"
    },
    {
      "x": -17,
      "y": 60,
      "z": 0,
      "name": "Plant_Leaves_Ash"
    },
    {
      "x": -17,
      "y": 59,
      "z": 1,
      "name": "Plant_Leaves_Ash"
    },
    {
      "x": -17,
      "y": 60,
      "z": 1,
      "name": "Plant_Leaves_Ash"
    },
    {
      "x": -17,
      "y": 59,
      "z": 2,
      "name": "Plant_Leaves_Ash"
    },
    {
      "x": -17,
      "y": 60,
      "z": 2,
      "name": "Plant_Leaves_Ash"
    },
    {
      "x": -17,
      "y": 59,
      "z": 3,
      "name": "Plant_Leaves_Ash"
    },
    {
      "x": -17,
      "y": 60,
      "z": 3,
      "name": "Plant_Leaves_Ash"
    },
    {
      "x": -17,
      "y": 58,
      "z": 4,
      "name": "Plant_Leaves_Ash"
    },
    {
      "x": -17,
      "y": 59,
      "z": 4,
      "name": "Plant_Leaves_Ash"
    },
    {
      "x": -17,
      "y": 58,
      "z": 5,
      "name": "Plant_Leaves_Ash"
    },
    {
      "x": -17,
      "y": 59,
      "z": 5,
      "name": "Plant_Leaves_Ash"
    },
    {
      "x": -17,
      "y": 58,
      "z": 6,
      "name": "Plant_Leaves_Ash"
    },
    {
      "x": -17,
      "y": 59,
      "z": 6,
      "name": "Plant_Leaves_Ash"
    },
    {
      "x": -17,
      "y": 58,
      "z": 7,
      "name": "Plant_Leaves_Ash"
    },
    {
      "x": -17,
      "y": 59,
      "z": 7,
      "name": "Plant_Leaves_Ash"
    },
    {
      "x": -17,
      "y": 58,
      "z": 8,
      "name": "Plant_Leaves_Ash"
    },
    {
      "x": -17,
      "y": 59,
      "z": 8,
      "name": "Plant_Leaves_Ash"
    },
    {
      "x": -17,
      "y": 58,
      "z": 9,
      "name": "Plant_Leaves_Ash"
    },
    {
      "x": -17,
      "y": 59,
      "z": 9,
      "name": "Plant_Leaves_Ash"
    },
    {
      "x": -17,
      "y": 58,
      "z": 10,
      "name": "Plant_Leaves_Ash"
    },
    {
      "x": -17,
      "y": 58,
      "z": 11,
      "name": "Plant_Leaves_Ash"
    },
    {
      "x": -16,
      "y": 58,
      "z": -12,
      "name": "Plant_Leaves_Ash"
    },
    {
      "x": -16,
      "y": 58,
      "z": -11,
      "name": "Plant_Leaves_Ash"
    },
    {
      "x": -16,
      "y": 58,
      "z": -10,
      "name": "Plant_Leaves_Ash"
    },
    {
      "x": -16,
      "y": 59,
      "z": -10,
      "name": "Plant_Leaves_Ash"
    },
    {
      "x": -16,
      "y": 58,
      "z": -9,
      "name": "Plant_Leaves_Ash"
    },
    {
      "x": -16,
      "y": 59,
      "z": -9,
      "name": "Plant_Leaves_Ash"
    },
    {
      "x": -16,
      "y": 58,
      "z": -8,
      "name": "Plant_Leaves_Ash"
    },
    {
      "x": -16,
      "y": 59,
      "z": -8,
      "name": "Plant_Leaves_Ash"
    },
    {
      "x": -16,
      "y": 58,
      "z": -7,
      "name": "Plant_Leaves_Ash"
    },
    {
      "x": -16,
      "y": 59,
      "z": -7,
      "name": "Plant_Leaves_Ash"
    },
    {
      "x": -16,
      "y": 59,
      "z": -6,
      "name": "Plant_Leaves_Ash"
    },
    {
      "x": -16,
      "y": 60,
      "z": -6,
      "name": "Plant_Leaves_Ash"
    },
    {
      "x": -16,
      "y": 59,
      "z": -5,
      "name": "Plant_Leaves_Ash"
    },
    {
      "x": -16,
      "y": 60,
      "z": -5,
      "name": "Plant_Leaves_Ash"
    },
    {
      "x": -16,
      "y": 59,
      "z": -4,
      "name": "Plant_Leaves_Ash"
    },
    {
      "x": -16,
      "y": 60,
      "z": -4,
      "name": "Plant_Leaves_Ash"
    },
    {
      "x": -16,
      "y": 59,
      "z": -3,
      "name": "Plant_Leaves_Ash"
    },
    {
      "x": -16,
      "y": 60,
      "z": -3,
      "name": "Plant_Leaves_Ash"
    },
    {
      "x": -16,
      "y": 59,
      "z": -2,
      "name": "Plant_Leaves_Ash"
    },
    {
      "x": -16,
      "y": 60,
      "z": -2,
      "name": "Plant_Leaves_Ash"
    },
    {
      "x": -16,
      "y": 59,
      "z": -1,
      "name": "Plant_Leaves_Ash"
    },
    {
      "x": -16,
      "y": 60,
      "z": -1,
      "name": "Plant_Leaves_Ash"
    },
    {
      "x": -16,
      "y": 59,
      "z": 0,
      "name": "Plant_Leaves_Ash"
    },
    {
      "x": -16,
      "y": 60,
      "z": 0,
      "name": "Plant_Leaves_Ash"
    },
    {
      "x": -16,
      "y": 59,
      "z": 1,
      "name": "Plant_Leaves_Ash"
    },
    {
      "x": -16,
      "y": 60,
      "z": 1,
      "name": "Plant_Leaves_Ash"
    },
    {
      "x": -16,
      "y": 59,
      "z": 2,
      "name": "Plant_Leaves_Ash"
    },
    {
      "x": -16,
      "y": 60,
      "z": 2,
      "name": "Plant_Leaves_Ash"
    },
    {
      "x": -16,
      "y": 59,
      "z": 3,
      "name": "Plant_Leaves_Ash"
    },
    {
      "x": -16,
      "y": 60,
      "z": 3,
      "name": "Plant_Leaves_Ash"
    },
    {
      "x": -16,
      "y": 59,
      "z": 4,
      "name": "Plant_Leaves_Ash"
    },
    {
      "x": -16,
      "y": 60,
      "z": 4,
      "name": "Plant_Leaves_Ash"
    },
    {
      "x": -16,
      "y": 59,
      "z": 5,
      "name": "Plant_Leaves_Ash"
    },
    {
      "x": -16,
      "y": 60,
      "z": 5,
      "name": "Plant_Leaves_Ash"
    },
    {
      "x": -16,
      "y": 59,
      "z": 6,
      "name": "Plant_Leaves_Ash"
    },
    {
      "x": -16,
      "y": 60,
      "z": 6,
      "name": "Plant_Leaves_Ash"
    },
    {
      "x": -16,
      "y": 58,
      "z": 7,
      "name": "Plant_Leaves_Ash"
    },
    {
      "x": -16,
      "y": 59,
      "z": 7,
      "name": "Plant_Leaves_Ash"
    },
    {
      "x": -16,
      "y": 58,
      "z": 8,
      "name": "Plant_Leaves_Ash"
    },
    {
      "x": -16,
      "y": 59,
      "z": 8,
      "name": "Plant_Leaves_Ash"
    },
    {
      "x": -16,
      "y": 58,
      "z": 9,
      "name": "Plant_Leaves_Ash"
    },
    {
      "x": -16,
      "y": 59,
      "z": 9,
      "name": "Plant_Leaves_Ash"
    },
    {
      "x": -16,
      "y": 58,
      "z": 10,
      "name": "Plant_Leaves_Ash"
    },
    {
      "x": -16,
      "y": 59,
      "z": 10,
      "name": "Plant_Leaves_Ash"
    },
    {
      "x": -16,
      "y": 58,
      "z": 11,
      "name": "Plant_Leaves_Ash"
    },
    {
      "x": -16,
      "y": 58,
      "z": 12,
      "name": "Plant_Leaves_Ash"
    },
    {
      "x": -15,
      "y": 58,
      "z": -13,
      "name": "Plant_Leaves_Ash"
    },
    {
      "x": -15,
      "y": 58,
      "z": -12,
      "name": "Plant_Leaves_Ash"
    },
    {
      "x": -15,
      "y": 59,
      "z": -12,
      "name": "Plant_Leaves_Ash"
    },
    {
      "x": -15,
      "y": 58,
      "z": -11,
      "name": "Plant_Leaves_Ash"
    },
    {
      "x": -15,
      "y": 59,
      "z": -11,
      "name": "Plant_Leaves_Ash"
    },
    {
      "x": -15,
      "y": 58,
      "z": -10,
      "name": "Plant_Leaves_Ash"
    },
    {
      "x": -15,
      "y": 59,
      "z": -10,
      "name": "Plant_Leaves_Ash"
    },
    {
      "x": -15,
      "y": 58,
      "z": -9,
      "name": "Plant_Leaves_Ash"
    },
    {
      "x": -15,
      "y": 59,
      "z": -9,
      "name": "Plant_Leaves_Ash"
    },
    {
      "x": -15,
      "y": 59,
      "z": -8,
      "name": "Plant_Leaves_Ash"
    },
    {
      "x": -15,
      "y": 60,
      "z": -8,
      "name": "Plant_Leaves_Ash"
    },
    {
      "x": -15,
      "y": 59,
      "z": -7,
      "name": "Plant_Leaves_Ash"
    },
    {
      "x": -15,
      "y": 60,
      "z": -7,
      "name": "Plant_Leaves_Ash"
    },
    {
      "x": -15,
      "y": 59,
      "z": -6,
      "name": "Plant_Leaves_Ash"
    },
    {
      "x": -15,
      "y": 60,
      "z": -6,
      "name": "Plant_Leaves_Ash"
    },
    {
      "x": -15,
      "y": 59,
      "z": -5,
      "name": "Plant_Leaves_Ash"
    },
    {
      "x": -15,
      "y": 60,
      "z": -5,
      "name": "Plant_Leaves_Ash"
    },
    {
      "x": -15,
      "y": 59,
      "z": -4,
      "name": "Plant_Leaves_Ash"
    },
    {
      "x": -15,
      "y": 60,
      "z": -4,
      "name": "Plant_Leaves_Ash"
    },
    {
      "x": -15,
      "y": 60,
      "z": -3,
      "name": "Plant_Leaves_Ash"
    },
    {
      "x": -15,
      "y": 60,
      "z": -2,
      "name": "Plant_Leaves_Ash"
    },
    {
      "x": -15,
      "y": 60,
      "z": -1,
      "name": "Plant_Leaves_Ash"
    },
    {
      "x": -15,
      "y": 60,
      "z": 0,
      "name": "Plant_Leaves_Ash"
    },
    {
      "x": -15,
      "y": 60,
      "z": 1,
      "name": "Plant_Leaves_Ash"
    },
    {
      "x": -15,
      "y": 60,
      "z": 2,
      "name": "Plant_Leaves_Ash"
    },
    {
      "x": -15,
      "y": 60,
      "z": 3,
      "name": "Plant_Leaves_Ash"
    },
    {
      "x": -15,
      "y": 59,
      "z": 4,
      "name": "Plant_Leaves_Ash"
    },
    {
      "x": -15,
      "y": 60,
      "z": 4,
      "name": "Plant_Leaves_Ash"
    },
    {
      "x": -15,
      "y": 59,
      "z": 5,
      "name": "Plant_Leaves_Ash"
    },
    {
      "x": -15,
      "y": 60,
      "z": 5,
      "name": "Plant_Leaves_Ash"
    },
    {
      "x": -15,
      "y": 59,
      "z": 6,
      "name": "Plant_Leaves_Ash"
    },
    {
      "x": -15,
      "y": 60,
      "z": 6,
      "name": "Plant_Leaves_Ash"
    },
    {
      "x": -15,
      "y": 59,
      "z": 7,
      "name": "Plant_Leaves_Ash"
    },
    {
      "x": -15,
      "y": 60,
      "z": 7,
      "name": "Plant_Leaves_Ash"
    },
    {
      "x": -15,
      "y": 59,
      "z": 8,
      "name": "Plant_Leaves_Ash"
    },
    {
      "x": -15,
      "y": 60,
      "z": 8,
      "name": "Plant_Leaves_Ash"
    },
    {
      "x": -15,
      "y": 58,
      "z": 9,
      "name": "Plant_Leaves_Ash"
    },
    {
      "x": -15,
      "y": 59,
      "z": 9,
      "name": "Plant_Leaves_Ash"
    },
    {
      "x": -15,
      "y": 58,
      "z": 10,
      "name": "Plant_Leaves_Ash"
    },
    {
      "x": -15,
      "y": 59,
      "z": 10,
      "name": "Plant_Leaves_Ash"
    },
    {
      "x": -15,
      "y": 58,
      "z": 11,
      "name": "Plant_Leaves_Ash"
    },
    {
      "x": -15,
      "y": 59,
      "z": 11,
      "name": "Plant_Leaves_Ash"
    },
    {
      "x": -15,
      "y": 58,
      "z": 12,
      "name": "Plant_Leaves_Ash"
    },
    {
      "x": -15,
      "y": 59,
      "z": 12,
      "name": "Plant_Leaves_Ash"
    },
    {
      "x": -15,
      "y": 58,
      "z": 13,
      "name": "Plant_Leaves_Ash"
    },
    {
      "x": -14,
      "y": 58,
      "z": -14,
      "name": "Plant_Leaves_Ash"
    },
    {
      "x": -14,
      "y": 58,
      "z": -13,
      "name": "Plant_Leaves_Ash"
    },
    {
      "x": -14,
      "y": 59,
      "z": -13,
      "name": "Plant_Leaves_Ash"
    },
    {
      "x": -14,
      "y": 58,
      "z": -12,
      "name": "Plant_Leaves_Ash"
    },
    {
      "x": -14,
      "y": 59,
      "z": -12,
      "name": "Plant_Leaves_Ash"
    },
    {
      "x": -14,
      "y": 58,
      "z": -11,
      "name": "Plant_Leaves_Ash"
    },
    {
      "x": -14,
      "y": 59,
      "z": -11,
      "name": "Plant_Leaves_Ash"
    },
    {
      "x": -14,
      "y": 59,
      "z": -10,
      "name": "Plant_Leaves_Ash"
    },
    {
      "x": -14,
      "y": 60,
      "z": -10,
      "name": "Plant_Leaves_Ash"
    },
    {
      "x": -14,
      "y": 59,
      "z": -9,
      "name": "Plant_Leaves_Ash"
    },
    {
      "x": -14,
      "y": 60,
      "z": -9,
      "name": "Plant_Leaves_Ash"
    },
    {
      "x": -14,
      "y": 59,
      "z": -8,
      "name": "Plant_Leaves_Ash"
    },
    {
      "x": -14,
      "y": 60,
      "z": -8,
      "name": "Plant_Leaves_Ash"
    },
    {
      "x": -14,
      "y": 59,
      "z": -7,
      "name": "Plant_Leaves_Ash"
    },
    {
      "x": -14,
      "y": 60,
      "z": -7,
      "name": "Plant_Leaves_Ash"
    },
    {
      "x": -14,
      "y": 60,
      "z": -6,
      "name": "Plant_Leaves_Ash"
    },
    {
      "x": -14,
      "y": 60,
      "z": -5,
      "name": "Plant_Leaves_Ash"
    },
    {
      "x": -14,
      "y": 60,
      "z": -4,
      "name": "Plant_Leaves_Ash"
    },
    {
      "x": -14,
      "y": 60,
      "z": -3,
      "name": "Plant_Leaves_Ash"
    },
    {
      "x": -14,
      "y": 60,
      "z": -2,
      "name": "Plant_Leaves_Ash"
    },
    {
      "x": -14,
      "y": 60,
      "z": -1,
      "name": "Plant_Leaves_Ash"
    },
    {
      "x": -14,
      "y": 60,
      "z": 0,
      "name": "Plant_Leaves_Ash"
    },
    {
      "x": -14,
      "y": 60,
      "z": 1,
      "name": "Plant_Leaves_Ash"
    },
    {
      "x": -14,
      "y": 60,
      "z": 2,
      "name": "Plant_Leaves_Ash"
    },
    {
      "x": -14,
      "y": 60,
      "z": 3,
      "name": "Plant_Leaves_Ash"
    },
    {
      "x": -14,
      "y": 60,
      "z": 4,
      "name": "Plant_Leaves_Ash"
    },
    {
      "x": -14,
      "y": 60,
      "z": 5,
      "name": "Plant_Leaves_Ash"
    },
    {
      "x": -14,
      "y": 60,
      "z": 6,
      "name": "Plant_Leaves_Ash"
    },
    {
      "x": -14,
      "y": 59,
      "z": 7,
      "name": "Plant_Leaves_Ash"
    },
    {
      "x": -14,
      "y": 60,
      "z": 7,
      "name": "Plant_Leaves_Ash"
    },
    {
      "x": -14,
      "y": 59,
      "z": 8,
      "name": "Plant_Leaves_Ash"
    },
    {
      "x": -14,
      "y": 60,
      "z": 8,
      "name": "Plant_Leaves_Ash"
    },
    {
      "x": -14,
      "y": 59,
      "z": 9,
      "name": "Plant_Leaves_Ash"
    },
    {
      "x": -14,
      "y": 60,
      "z": 9,
      "name": "Plant_Leaves_Ash"
    },
    {
      "x": -14,
      "y": 59,
      "z": 10,
      "name": "Plant_Leaves_Ash"
    },
    {
      "x": -14,
      "y": 60,
      "z": 10,
      "name": "Plant_Leaves_Ash"
    },
    {
      "x": -14,
      "y": 58,
      "z": 11,
      "name": "Plant_Leaves_Ash"
    },
    {
      "x": -14,
      "y": 59,
      "z": 11,
      "name": "Plant_Leaves_Ash"
    },
    {
      "x": -14,
      "y": 58,
      "z": 12,
      "name": "Plant_Leaves_Ash"
    },
    {
      "x": -14,
      "y": 59,
      "z": 12,
      "name": "Plant_Leaves_Ash"
    },
    {
      "x": -14,
      "y": 58,
      "z": 13,
      "name": "Plant_Leaves_Ash"
    },
    {
      "x": -14,
      "y": 59,
      "z": 13,
      "name": "Plant_Leaves_Ash"
    },
    {
      "x": -14,
      "y": 58,
      "z": 14,
      "name": "Plant_Leaves_Ash"
    },
    {
      "x": -13,
      "y": 58,
      "z": -15,
      "name": "Plant_Leaves_Ash"
    },
    {
      "x": -13,
      "y": 58,
      "z": -14,
      "name": "Plant_Leaves_Ash"
    },
    {
      "x": -13,
      "y": 59,
      "z": -14,
      "name": "Plant_Leaves_Ash"
    },
    {
      "x": -13,
      "y": 58,
      "z": -13,
      "name": "Plant_Leaves_Ash"
    },
    {
      "x": -13,
      "y": 59,
      "z": -13,
      "name": "Plant_Leaves_Ash"
    },
    {
      "x": -13,
      "y": 58,
      "z": -12,
      "name": "Plant_Leaves_Ash"
    },
    {
      "x": -13,
      "y": 59,
      "z": -12,
      "name": "Plant_Leaves_Ash"
    },
    {
      "x": -13,
      "y": 59,
      "z": -11,
      "name": "Plant_Leaves_Ash"
    },
    {
      "x": -13,
      "y": 60,
      "z": -11,
      "name": "Plant_Leaves_Ash"
    },
    {
      "x": -13,
      "y": 59,
      "z": -10,
      "name": "Plant_Leaves_Ash"
    },
    {
      "x": -13,
      "y": 60,
      "z": -10,
      "name": "Plant_Leaves_Ash"
    },
    {
      "x": -13,
      "y": 59,
      "z": -9,
      "name": "Plant_Leaves_Ash"
    },
    {
      "x": -13,
      "y": 60,
      "z": -9,
      "name": "Plant_Leaves_Ash"
    },
    {
      "x": -13,
      "y": 60,
      "z": -8,
      "name": "Plant_Leaves_Ash"
    },
    {
      "x": -13,
      "y": 60,
      "z": -7,
      "name": "Plant_Leaves_Ash"
    },
    {
      "x": -13,
      "y": 60,
      "z": -6,
      "name": "Plant_Leaves_Ash"
    },
    {
      "x": -13,
      "y": 60,
      "z": -5,
      "name": "Plant_Leaves_Ash"
    },
    {
      "x": -13,
      "y": 60,
      "z": -4,
      "name": "Plant_Leaves_Ash"
    },
    {
      "x": -13,
      "y": 60,
      "z": -3,
      "name": "Plant_Leaves_Ash"
    },
    {
      "x": -13,
      "y": 61,
      "z": -3,
      "name": "Plant_Leaves_Ash"
    },
    {
      "x": -13,
      "y": 60,
      "z": -2,
      "name": "Plant_Leaves_Ash"
    },
    {
      "x": -13,
      "y": 61,
      "z": -2,
      "name": "Plant_Leaves_Ash"
    },
    {
      "x": -13,
      "y": 60,
      "z": -1,
      "name": "Plant_Leaves_Ash"
    },
    {
      "x": -13,
      "y": 61,
      "z": -1,
      "name": "Plant_Leaves_Ash"
    },
    {
      "x": -13,
      "y": 60,
      "z": 0,
      "name": "Plant_Leaves_Ash"
    },
    {
      "x": -13,
      "y": 61,
      "z": 0,
      "name": "Plant_Leaves_Ash"
    },
    {
      "x": -13,
      "y": 60,
      "z": 1,
      "name": "Plant_Leaves_Ash"
    },
    {
      "x": -13,
      "y": 61,
      "z": 1,
      "name": "Plant_Leaves_Ash"
    },
    {
      "x": -13,
      "y": 60,
      "z": 2,
      "name": "Plant_Leaves_Ash"
    },
    {
      "x": -13,
      "y": 61,
      "z": 2,
      "name": "Plant_Leaves_Ash"
    },
    {
      "x": -13,
      "y": 60,
      "z": 3,
      "name": "Plant_Leaves_Ash"
    },
    {
      "x": -13,
      "y": 61,
      "z": 3,
      "name": "Plant_Leaves_Ash"
    },
    {
      "x": -13,
      "y": 60,
      "z": 4,
      "name": "Plant_Leaves_Ash"
    },
    {
      "x": -13,
      "y": 60,
      "z": 5,
      "name": "Plant_Leaves_Ash"
    },
    {
      "x": -13,
      "y": 60,
      "z": 6,
      "name": "Plant_Leaves_Ash"
    },
    {
      "x": -13,
      "y": 60,
      "z": 7,
      "name": "Plant_Leaves_Ash"
    },
    {
      "x": -13,
      "y": 60,
      "z": 8,
      "name": "Plant_Leaves_Ash"
    },
    {
      "x": -13,
      "y": 59,
      "z": 9,
      "name": "Plant_Leaves_Ash"
    },
    {
      "x": -13,
      "y": 60,
      "z": 9,
      "name": "Plant_Leaves_Ash"
    },
    {
      "x": -13,
      "y": 59,
      "z": 10,
      "name": "Plant_Leaves_Ash"
    },
    {
      "x": -13,
      "y": 60,
      "z": 10,
      "name": "Plant_Leaves_Ash"
    },
    {
      "x": -13,
      "y": 59,
      "z": 11,
      "name": "Plant_Leaves_Ash"
    },
    {
      "x": -13,
      "y": 60,
      "z": 11,
      "name": "Plant_Leaves_Ash"
    },
    {
      "x": -13,
      "y": 58,
      "z": 12,
      "name": "Plant_Leaves_Ash"
    },
    {
      "x": -13,
      "y": 59,
      "z": 12,
      "name": "Plant_Leaves_Ash"
    },
    {
      "x": -13,
      "y": 58,
      "z": 13,
      "name": "Plant_Leaves_Ash"
    },
    {
      "x": -13,
      "y": 59,
      "z": 13,
      "name": "Plant_Leaves_Ash"
    },
    {
      "x": -13,
      "y": 58,
      "z": 14,
      "name": "Plant_Leaves_Ash"
    },
    {
      "x": -13,
      "y": 59,
      "z": 14,
      "name": "Plant_Leaves_Ash"
    },
    {
      "x": -13,
      "y": 58,
      "z": 15,
      "name": "Plant_Leaves_Ash"
    },
    {
      "x": -12,
      "y": 58,
      "z": -16,
      "name": "Plant_Leaves_Ash"
    },
    {
      "x": -12,
      "y": 58,
      "z": -15,
      "name": "Plant_Leaves_Ash"
    },
    {
      "x": -12,
      "y": 59,
      "z": -15,
      "name": "Plant_Leaves_Ash"
    },
    {
      "x": -12,
      "y": 58,
      "z": -14,
      "name": "Plant_Leaves_Ash"
    },
    {
      "x": -12,
      "y": 59,
      "z": -14,
      "name": "Plant_Leaves_Ash"
    },
    {
      "x": -12,
      "y": 58,
      "z": -13,
      "name": "Plant_Leaves_Ash"
    },
    {
      "x": -12,
      "y": 59,
      "z": -13,
      "name": "Plant_Leaves_Ash"
    },
    {
      "x": -12,
      "y": 59,
      "z": -12,
      "name": "Plant_Leaves_Ash"
    },
    {
      "x": -12,
      "y": 60,
      "z": -12,
      "name": "Plant_Leaves_Ash"
    },
    {
      "x": -12,
      "y": 59,
      "z": -11,
      "name": "Plant_Leaves_Ash"
    },
    {
      "x": -12,
      "y": 60,
      "z": -11,
      "name": "Plant_Leaves_Ash"
    },
    {
      "x": -12,
      "y": 59,
      "z": -10,
      "name": "Plant_Leaves_Ash"
    },
    {
      "x": -12,
      "y": 60,
      "z": -10,
      "name": "Plant_Leaves_Ash"
    },
    {
      "x": -12,
      "y": 60,
      "z": -9,
      "name": "Plant_Leaves_Ash"
    },
    {
      "x": -12,
      "y": 60,
      "z": -8,
      "name": "Plant_Leaves_Ash"
    },
    {
      "x": -12,
      "y": 60,
      "z": -7,
      "name": "Plant_Leaves_Ash"
    },
    {
      "x": -12,
      "y": 60,
      "z": -6,
      "name": "Plant_Leaves_Ash"
    },
    {
      "x": -12,
      "y": 60,
      "z": -5,
      "name": "Plant_Leaves_Ash"
    },
    {
      "x": -12,
      "y": 61,
      "z": -5,
      "name": "Plant_Leaves_Ash"
    },
    {
      "x": -12,
      "y": 60,
      "z": -4,
      "name": "Plant_Leaves_Ash"
    },
    {
      "x": -12,
      "y": 61,
      "z": -4,
      "name": "Plant_Leaves_Ash"
    },
    {
      "x": -12,
      "y": 60,
      "z": -3,
      "name": "Plant_Leaves_Ash"
    },
    {
      "x": -12,
      "y": 61,
      "z": -3,
      "name": "Plant_Leaves_Ash"
    },
    {
      "x": -12,
      "y": 60,
      "z": -2,
      "name": "Plant_Leaves_Ash"
    },
    {
      "x": -12,
      "y": 61,
      "z": -2,
      "name": "Plant_Leaves_Ash"
    },
    {
      "x": -12,
      "y": 60,
      "z": -1,
      "name": "Plant_Leaves_Ash"
    },
    {
      "x": -12,
      "y": 61,
      "z": -1,
      "name": "Plant_Leaves_Ash"
    },
    {
      "x": -12,
      "y": 60,
      "z": 0,
      "name": "Plant_Leaves_Ash"
    },
    {
      "x": -12,
      "y": 61,
      "z": 0,
      "name": "Plant_Leaves_Ash"
    },
    {
      "x": -12,
      "y": 60,
      "z": 1,
      "name": "Plant_Leaves_Ash"
    },
    {
      "x": -12,
      "y": 61,
      "z": 1,
      "name": "Plant_Leaves_Ash"
    },
    {
      "x": -12,
      "y": 60,
      "z": 2,
      "name": "Plant_Leaves_Ash"
    },
    {
      "x": -12,
      "y": 61,
      "z": 2,
      "name": "Plant_Leaves_Ash"
    },
    {
      "x": -12,
      "y": 60,
      "z": 3,
      "name": "Plant_Leaves_Ash"
    },
    {
      "x": -12,
      "y": 61,
      "z": 3,
      "name": "Plant_Leaves_Ash"
    },
    {
      "x": -12,
      "y": 60,
      "z": 4,
      "name": "Plant_Leaves_Ash"
    },
    {
      "x": -12,
      "y": 61,
      "z": 4,
      "name": "Plant_Leaves_Ash"
    },
    {
      "x": -12,
      "y": 60,
      "z": 5,
      "name": "Plant_Leaves_Ash"
    },
    {
      "x": -12,
      "y": 61,
      "z": 5,
      "name": "Plant_Leaves_Ash"
    },
    {
      "x": -12,
      "y": 60,
      "z": 6,
      "name": "Plant_Leaves_Ash"
    },
    {
      "x": -12,
      "y": 60,
      "z": 7,
      "name": "Plant_Leaves_Ash"
    },
    {
      "x": -12,
      "y": 60,
      "z": 8,
      "name": "Plant_Leaves_Ash"
    },
    {
      "x": -12,
      "y": 60,
      "z": 9,
      "name": "Plant_Leaves_Ash"
    },
    {
      "x": -12,
      "y": 59,
      "z": 10,
      "name": "Plant_Leaves_Ash"
    },
    {
      "x": -12,
      "y": 60,
      "z": 10,
      "name": "Plant_Leaves_Ash"
    },
    {
      "x": -12,
      "y": 59,
      "z": 11,
      "name": "Plant_Leaves_Ash"
    },
    {
      "x": -12,
      "y": 60,
      "z": 11,
      "name": "Plant_Leaves_Ash"
    },
    {
      "x": -12,
      "y": 59,
      "z": 12,
      "name": "Plant_Leaves_Ash"
    },
    {
      "x": -12,
      "y": 60,
      "z": 12,
      "name": "Plant_Leaves_Ash"
    },
    {
      "x": -12,
      "y": 58,
      "z": 13,
      "name": "Plant_Leaves_Ash"
    },
    {
      "x": -12,
      "y": 59,
      "z": 13,
      "name": "Plant_Leaves_Ash"
    },
    {
      "x": -12,
      "y": 58,
      "z": 14,
      "name": "Plant_Leaves_Ash"
    },
    {
      "x": -12,
      "y": 59,
      "z": 14,
      "name": "Plant_Leaves_Ash"
    },
    {
      "x": -12,
      "y": 58,
      "z": 15,
      "name": "Plant_Leaves_Ash"
    },
    {
      "x": -12,
      "y": 59,
      "z": 15,
      "name": "Plant_Leaves_Ash"
    },
    {
      "x": -12,
      "y": 58,
      "z": 16,
      "name": "Plant_Leaves_Ash"
    },
    {
      "x": -11,
      "y": 58,
      "z": -17,
      "name": "Plant_Leaves_Ash"
    },
    {
      "x": -11,
      "y": 58,
      "z": -16,
      "name": "Plant_Leaves_Ash"
    },
    {
      "x": -11,
      "y": 58,
      "z": -15,
      "name": "Plant_Leaves_Ash"
    },
    {
      "x": -11,
      "y": 59,
      "z": -15,
      "name": "Plant_Leaves_Ash"
    },
    {
      "x": -11,
      "y": 58,
      "z": -14,
      "name": "Plant_Leaves_Ash"
    },
    {
      "x": -11,
      "y": 59,
      "z": -14,
      "name": "Plant_Leaves_Ash"
    },
    {
      "x": -11,
      "y": 59,
      "z": -13,
      "name": "Plant_Leaves_Ash"
    },
    {
      "x": -11,
      "y": 60,
      "z": -13,
      "name": "Plant_Leaves_Ash"
    },
    {
      "x": -11,
      "y": 59,
      "z": -12,
      "name": "Plant_Leaves_Ash"
    },
    {
      "x": -11,
      "y": 60,
      "z": -12,
      "name": "Plant_Leaves_Ash"
    },
    {
      "x": -11,
      "y": 59,
      "z": -11,
      "name": "Plant_Leaves_Ash"
    },
    {
      "x": -11,
      "y": 60,
      "z": -11,
      "name": "Plant_Leaves_Ash"
    },
    {
      "x": -11,
      "y": 60,
      "z": -10,
      "name": "Plant_Leaves_Ash"
    },
    {
      "x": -11,
      "y": 60,
      "z": -9,
      "name": "Plant_Leaves_Ash"
    },
    {
      "x": -11,
      "y": 60,
      "z": -8,
      "name": "Plant_Leaves_Ash"
    },
    {
      "x": -11,
      "y": 60,
      "z": -7,
      "name": "Plant_Leaves_Ash"
    },
    {
      "x": -11,
      "y": 61,
      "z": -7,
      "name": "Plant_Leaves_Ash"
    },
    {
      "x": -11,
      "y": 60,
      "z": -6,
      "name": "Plant_Leaves_Ash"
    },
    {
      "x": -11,
      "y": 61,
      "z": -6,
      "name": "Plant_Leaves_Ash"
    },
    {
      "x": -11,
      "y": 60,
      "z": -5,
      "name": "Plant_Leaves_Ash"
    },
    {
      "x": -11,
      "y": 61,
      "z": -5,
      "name": "Plant_Leaves_Ash"
    },
    {
      "x": -11,
      "y": 60,
      "z": -4,
      "name": "Plant_Leaves_Ash"
    },
    {
      "x": -11,
      "y": 61,
      "z": -4,
      "name": "Plant_Leaves_Ash"
    },
    {
      "x": -11,
      "y": 60,
      "z": -3,
      "name": "Plant_Leaves_Ash"
    },
    {
      "x": -11,
      "y": 61,
      "z": -3,
      "name": "Plant_Leaves_Ash"
    },
    {
      "x": -11,
      "y": 60,
      "z": -2,
      "name": "Plant_Leaves_Ash"
    },
    {
      "x": -11,
      "y": 61,
      "z": -2,
      "name": "Plant_Leaves_Ash"
    },
    {
      "x": -11,
      "y": 60,
      "z": -1,
      "name": "Plant_Leaves_Ash"
    },
    {
      "x": -11,
      "y": 61,
      "z": -1,
      "name": "Plant_Leaves_Ash"
    },
    {
      "x": -11,
      "y": 60,
      "z": 0,
      "name": "Plant_Leaves_Ash"
    },
    {
      "x": -11,
      "y": 61,
      "z": 0,
      "name": "Plant_Leaves_Ash"
    },
    {
      "x": -11,
      "y": 60,
      "z": 1,
      "name": "Plant_Leaves_Ash"
    },
    {
      "x": -11,
      "y": 61,
      "z": 1,
      "name": "Plant_Leaves_Ash"
    },
    {
      "x": -11,
      "y": 60,
      "z": 2,
      "name": "Plant_Leaves_Ash"
    },
    {
      "x": -11,
      "y": 61,
      "z": 2,
      "name": "Plant_Leaves_Ash"
    },
    {
      "x": -11,
      "y": 60,
      "z": 3,
      "name": "Plant_Leaves_Ash"
    },
    {
      "x": -11,
      "y": 61,
      "z": 3,
      "name": "Plant_Leaves_Ash"
    },
    {
      "x": -11,
      "y": 60,
      "z": 4,
      "name": "Plant_Leaves_Ash"
    },
    {
      "x": -11,
      "y": 61,
      "z": 4,
      "name": "Plant_Leaves_Ash"
    },
    {
      "x": -11,
      "y": 60,
      "z": 5,
      "name": "Plant_Leaves_Ash"
    },
    {
      "x": -11,
      "y": 61,
      "z": 5,
      "name": "Plant_Leaves_Ash"
    },
    {
      "x": -11,
      "y": 60,
      "z": 6,
      "name": "Plant_Leaves_Ash"
    },
    {
      "x": -11,
      "y": 61,
      "z": 6,
      "name": "Plant_Leaves_Ash"
    },
    {
      "x": -11,
      "y": 60,
      "z": 7,
      "name": "Plant_Leaves_Ash"
    },
    {
      "x": -11,
      "y": 61,
      "z": 7,
      "name": "Plant_Leaves_Ash"
    },
    {
      "x": -11,
      "y": 60,
      "z": 8,
      "name": "Plant_Leaves_Ash"
    },
    {
      "x": -11,
      "y": 60,
      "z": 9,
      "name": "Plant_Leaves_Ash"
    },
    {
      "x": -11,
      "y": 60,
      "z": 10,
      "name": "Plant_Leaves_Ash"
    },
    {
      "x": -11,
      "y": 59,
      "z": 11,
      "name": "Plant_Leaves_Ash"
    },
    {
      "x": -11,
      "y": 60,
      "z": 11,
      "name": "Plant_Leaves_Ash"
    },
    {
      "x": -11,
      "y": 59,
      "z": 12,
      "name": "Plant_Leaves_Ash"
    },
    {
      "x": -11,
      "y": 60,
      "z": 12,
      "name": "Plant_Leaves_Ash"
    },
    {
      "x": -11,
      "y": 59,
      "z": 13,
      "name": "Plant_Leaves_Ash"
    },
    {
      "x": -11,
      "y": 60,
      "z": 13,
      "name": "Plant_Leaves_Ash"
    },
    {
      "x": -11,
      "y": 58,
      "z": 14,
      "name": "Plant_Leaves_Ash"
    },
    {
      "x": -11,
      "y": 59,
      "z": 14,
      "name": "Plant_Leaves_Ash"
    },
    {
      "x": -11,
      "y": 58,
      "z": 15,
      "name": "Plant_Leaves_Ash"
    },
    {
      "x": -11,
      "y": 59,
      "z": 15,
      "name": "Plant_Leaves_Ash"
    },
    {
      "x": -11,
      "y": 58,
      "z": 16,
      "name": "Plant_Leaves_Ash"
    },
    {
      "x": -11,
      "y": 58,
      "z": 17,
      "name": "Plant_Leaves_Ash"
    },
    {
      "x": -10,
      "y": 58,
      "z": -17,
      "name": "Plant_Leaves_Ash"
    },
    {
      "x": -10,
      "y": 58,
      "z": -16,
      "name": "Plant_Leaves_Ash"
    },
    {
      "x": -10,
      "y": 59,
      "z": -16,
      "name": "Plant_Leaves_Ash"
    },
    {
      "x": -10,
      "y": 58,
      "z": -15,
      "name": "Plant_Leaves_Ash"
    },
    {
      "x": -10,
      "y": 59,
      "z": -15,
      "name": "Plant_Leaves_Ash"
    },
    {
      "x": -10,
      "y": 59,
      "z": -14,
      "name": "Plant_Leaves_Ash"
    },
    {
      "x": -10,
      "y": 60,
      "z": -14,
      "name": "Plant_Leaves_Ash"
    },
    {
      "x": -10,
      "y": 59,
      "z": -13,
      "name": "Plant_Leaves_Ash"
    },
    {
      "x": -10,
      "y": 60,
      "z": -13,
      "name": "Plant_Leaves_Ash"
    },
    {
      "x": -10,
      "y": 59,
      "z": -12,
      "name": "Plant_Leaves_Ash"
    },
    {
      "x": -10,
      "y": 60,
      "z": -12,
      "name": "Plant_Leaves_Ash"
    },
    {
      "x": -10,
      "y": 60,
      "z": -11,
      "name": "Plant_Leaves_Ash"
    },
    {
      "x": -10,
      "y": 60,
      "z": -10,
      "name": "Plant_Leaves_Ash"
    },
    {
      "x": -10,
      "y": 60,
      "z": -9,
      "name": "Plant_Leaves_Ash"
    },
    {
      "x": -10,
      "y": 60,
      "z": -8,
      "name": "Plant_Leaves_Ash"
    },
    {
      "x": -10,
      "y": 61,
      "z": -8,
      "name": "Plant_Leaves_Ash"
    },
    {
      "x": -10,
      "y": 60,
      "z": -7,
      "name": "Plant_Leaves_Ash"
    },
    {
      "x": -10,
      "y": 61,
      "z": -7,
      "name": "Plant_Leaves_Ash"
    },
    {
      "x": -10,
      "y": 60,
      "z": -6,
      "name": "Plant_Leaves_Ash"
    },
    {
      "x": -10,
      "y": 61,
      "z": -6,
      "name": "Plant_Leaves_Ash"
    },
    {
      "x": -10,
      "y": 60,
      "z": -5,
      "name": "Plant_Leaves_Ash"
    },
    {
      "x": -10,
      "y": 61,
      "z": -5,
      "name": "Plant_Leaves_Ash"
    },
    {
      "x": -10,
      "y": 60,
      "z": -4,
      "name": "Plant_Leaves_Ash"
    },
    {
      "x": -10,
      "y": 61,
      "z": -4,
      "name": "Plant_Leaves_Ash"
    },
    {
      "x": -10,
      "y": 60,
      "z": -3,
      "name": "Plant_Leaves_Ash"
    },
    {
      "x": -10,
      "y": 61,
      "z": -3,
      "name": "Plant_Leaves_Ash"
    },
    {
      "x": -10,
      "y": 60,
      "z": -2,
      "name": "Plant_Leaves_Ash"
    },
    {
      "x": -10,
      "y": 61,
      "z": -2,
      "name": "Plant_Leaves_Ash"
    },
    {
      "x": -10,
      "y": 60,
      "z": -1,
      "name": "Plant_Leaves_Ash"
    },
    {
      "x": -10,
      "y": 61,
      "z": -1,
      "name": "Plant_Leaves_Ash"
    },
    {
      "x": -10,
      "y": 60,
      "z": 0,
      "name": "Plant_Leaves_Ash"
    },
    {
      "x": -10,
      "y": 61,
      "z": 0,
      "name": "Plant_Leaves_Ash"
    },
    {
      "x": -10,
      "y": 60,
      "z": 1,
      "name": "Plant_Leaves_Ash"
    },
    {
      "x": -10,
      "y": 61,
      "z": 1,
      "name": "Plant_Leaves_Ash"
    },
    {
      "x": -10,
      "y": 60,
      "z": 2,
      "name": "Plant_Leaves_Ash"
    },
    {
      "x": -10,
      "y": 61,
      "z": 2,
      "name": "Plant_Leaves_Ash"
    },
    {
      "x": -10,
      "y": 60,
      "z": 3,
      "name": "Plant_Leaves_Ash"
    },
    {
      "x": -10,
      "y": 61,
      "z": 3,
      "name": "Plant_Leaves_Ash"
    },
    {
      "x": -10,
      "y": 60,
      "z": 4,
      "name": "Plant_Leaves_Ash"
    },
    {
      "x": -10,
      "y": 61,
      "z": 4,
      "name": "Plant_Leaves_Ash"
    },
    {
      "x": -10,
      "y": 60,
      "z": 5,
      "name": "Plant_Leaves_Ash"
    },
    {
      "x": -10,
      "y": 61,
      "z": 5,
      "name": "Plant_Leaves_Ash"
    },
    {
      "x": -10,
      "y": 60,
      "z": 6,
      "name": "Plant_Leaves_Ash"
    },
    {
      "x": -10,
      "y": 61,
      "z": 6,
      "name": "Plant_Leaves_Ash"
    },
    {
      "x": -10,
      "y": 60,
      "z": 7,
      "name": "Plant_Leaves_Ash"
    },
    {
      "x": -10,
      "y": 61,
      "z": 7,
      "name": "Plant_Leaves_Ash"
    },
    {
      "x": -10,
      "y": 60,
      "z": 8,
      "name": "Plant_Leaves_Ash"
    },
    {
      "x": -10,
      "y": 61,
      "z": 8,
      "name": "Plant_Leaves_Ash"
    },
    {
      "x": -10,
      "y": 60,
      "z": 9,
      "name": "Plant_Leaves_Ash"
    },
    {
      "x": -10,
      "y": 60,
      "z": 10,
      "name": "Plant_Leaves_Ash"
    },
    {
      "x": -10,
      "y": 60,
      "z": 11,
      "name": "Plant_Leaves_Ash"
    },
    {
      "x": -10,
      "y": 59,
      "z": 12,
      "name": "Plant_Leaves_Ash"
    },
    {
      "x": -10,
      "y": 60,
      "z": 12,
      "name": "Plant_Leaves_Ash"
    },
    {
      "x": -10,
      "y": 59,
      "z": 13,
      "name": "Plant_Leaves_Ash"
    },
    {
      "x": -10,
      "y": 60,
      "z": 13,
      "name": "Plant_Leaves_Ash"
    },
    {
      "x": -10,
      "y": 59,
      "z": 14,
      "name": "Plant_Leaves_Ash"
    },
    {
      "x": -10,
      "y": 60,
      "z": 14,
      "name": "Plant_Leaves_Ash"
    },
    {
      "x": -10,
      "y": 58,
      "z": 15,
      "name": "Plant_Leaves_Ash"
    },
    {
      "x": -10,
      "y": 59,
      "z": 15,
      "name": "Plant_Leaves_Ash"
    },
    {
      "x": -10,
      "y": 58,
      "z": 16,
      "name": "Plant_Leaves_Ash"
    },
    {
      "x": -10,
      "y": 59,
      "z": 16,
      "name": "Plant_Leaves_Ash"
    },
    {
      "x": -10,
      "y": 58,
      "z": 17,
      "name": "Plant_Leaves_Ash"
    },
    {
      "x": -9,
      "y": 58,
      "z": -18,
      "name": "Plant_Leaves_Ash"
    },
    {
      "x": -9,
      "y": 58,
      "z": -17,
      "name": "Plant_Leaves_Ash"
    },
    {
      "x": -9,
      "y": 59,
      "z": -17,
      "name": "Plant_Leaves_Ash"
    },
    {
      "x": -9,
      "y": 58,
      "z": -16,
      "name": "Plant_Leaves_Ash"
    },
    {
      "x": -9,
      "y": 59,
      "z": -16,
      "name": "Plant_Leaves_Ash"
    },
    {
      "x": -9,
      "y": 58,
      "z": -15,
      "name": "Plant_Leaves_Ash"
    },
    {
      "x": -9,
      "y": 59,
      "z": -15,
      "name": "Plant_Leaves_Ash"
    },
    {
      "x": -9,
      "y": 59,
      "z": -14,
      "name": "Plant_Leaves_Ash"
    },
    {
      "x": -9,
      "y": 60,
      "z": -14,
      "name": "Plant_Leaves_Ash"
    },
    {
      "x": -9,
      "y": 59,
      "z": -13,
      "name": "Plant_Leaves_Ash"
    },
    {
      "x": -9,
      "y": 60,
      "z": -13,
      "name": "Plant_Leaves_Ash"
    },
    {
      "x": -9,
      "y": 60,
      "z": -12,
      "name": "Plant_Leaves_Ash"
    },
    {
      "x": -9,
      "y": 60,
      "z": -11,
      "name": "Plant_Leaves_Ash"
    },
    {
      "x": -9,
      "y": 60,
      "z": -10,
      "name": "Plant_Leaves_Ash"
    },
    {
      "x": -9,
      "y": 60,
      "z": -9,
      "name": "Plant_Leaves_Ash"
    },
    {
      "x": -9,
      "y": 61,
      "z": -9,
      "name": "Plant_Leaves_Ash"
    },
    {
      "x": -9,
      "y": 60,
      "z": -8,
      "name": "Plant_Leaves_Ash"
    },
    {
      "x": -9,
      "y": 61,
      "z": -8,
      "name": "Plant_Leaves_Ash"
    },
    {
      "x": -9,
      "y": 60,
      "z": -7,
      "name": "Plant_Leaves_Ash"
    },
    {
      "x": -9,
      "y": 61,
      "z": -7,
      "name": "Plant_Leaves_Ash"
    },
    {
      "x": -9,
      "y": 60,
      "z": -6,
      "name": "Plant_Leaves_Ash"
    },
    {
      "x": -9,
      "y": 61,
      "z": -6,
      "name": "Plant_Leaves_Ash"
    },
    {
      "x": -9,
      "y": 60,
      "z": -5,
      "name": "Plant_Leaves_Ash"
    },
    {
      "x": -9,
      "y": 61,
      "z": -5,
      "name": "Plant_Leaves_Ash"
    },
    {
      "x": -9,
      "y": 60,
      "z": -4,
      "name": "Plant_Leaves_Ash"
    },
    {
      "x": -9,
      "y": 61,
      "z": -4,
      "name": "Plant_Leaves_Ash"
    },
    {
      "x": -9,
      "y": 60,
      "z": -3,
      "name": "Plant_Leaves_Ash"
    },
    {
      "x": -9,
      "y": 61,
      "z": -3,
      "name": "Plant_Leaves_Ash"
    },
    {
      "x": -9,
      "y": 60,
      "z": -2,
      "name": "Plant_Leaves_Ash"
    },
    {
      "x": -9,
      "y": 61,
      "z": -2,
      "name": "Plant_Leaves_Ash"
    },
    {
      "x": -9,
      "y": 60,
      "z": -1,
      "name": "Plant_Leaves_Ash"
    },
    {
      "x": -9,
      "y": 61,
      "z": -1,
      "name": "Plant_Leaves_Ash"
    },
    {
      "x": -9,
      "y": 60,
      "z": 0,
      "name": "Plant_Leaves_Ash"
    },
    {
      "x": -9,
      "y": 61,
      "z": 0,
      "name": "Plant_Leaves_Ash"
    },
    {
      "x": -9,
      "y": 60,
      "z": 1,
      "name": "Plant_Leaves_Ash"
    },
    {
      "x": -9,
      "y": 61,
      "z": 1,
      "name": "Plant_Leaves_Ash"
    },
    {
      "x": -9,
      "y": 60,
      "z": 2,
      "name": "Plant_Leaves_Ash"
    },
    {
      "x": -9,
      "y": 61,
      "z": 2,
      "name": "Plant_Leaves_Ash"
    },
    {
      "x": -9,
      "y": 60,
      "z": 3,
      "name": "Plant_Leaves_Ash"
    },
    {
      "x": -9,
      "y": 61,
      "z": 3,
      "name": "Plant_Leaves_Ash"
    },
    {
      "x": -9,
      "y": 60,
      "z": 4,
      "name": "Plant_Leaves_Ash"
    },
    {
      "x": -9,
      "y": 61,
      "z": 4,
      "name": "Plant_Leaves_Ash"
    },
    {
      "x": -9,
      "y": 60,
      "z": 5,
      "name": "Plant_Leaves_Ash"
    },
    {
      "x": -9,
      "y": 61,
      "z": 5,
      "name": "Plant_Leaves_Ash"
    },
    {
      "x": -9,
      "y": 60,
      "z": 6,
      "name": "Plant_Leaves_Ash"
    },
    {
      "x": -9,
      "y": 61,
      "z": 6,
      "name": "Plant_Leaves_Ash"
    },
    {
      "x": -9,
      "y": 60,
      "z": 7,
      "name": "Plant_Leaves_Ash"
    },
    {
      "x": -9,
      "y": 61,
      "z": 7,
      "name": "Plant_Leaves_Ash"
    },
    {
      "x": -9,
      "y": 60,
      "z": 8,
      "name": "Plant_Leaves_Ash"
    },
    {
      "x": -9,
      "y": 61,
      "z": 8,
      "name": "Plant_Leaves_Ash"
    },
    {
      "x": -9,
      "y": 60,
      "z": 9,
      "name": "Plant_Leaves_Ash"
    },
    {
      "x": -9,
      "y": 61,
      "z": 9,
      "name": "Plant_Leaves_Ash"
    },
    {
      "x": -9,
      "y": 60,
      "z": 10,
      "name": "Plant_Leaves_Ash"
    },
    {
      "x": -9,
      "y": 60,
      "z": 11,
      "name": "Plant_Leaves_Ash"
    },
    {
      "x": -9,
      "y": 60,
      "z": 12,
      "name": "Plant_Leaves_Ash"
    },
    {
      "x": -9,
      "y": 59,
      "z": 13,
      "name": "Plant_Leaves_Ash"
    },
    {
      "x": -9,
      "y": 60,
      "z": 13,
      "name": "Plant_Leaves_Ash"
    },
    {
      "x": -9,
      "y": 59,
      "z": 14,
      "name": "Plant_Leaves_Ash"
    },
    {
      "x": -9,
      "y": 60,
      "z": 14,
      "name": "Plant_Leaves_Ash"
    },
    {
      "x": -9,
      "y": 58,
      "z": 15,
      "name": "Plant_Leaves_Ash"
    },
    {
      "x": -9,
      "y": 59,
      "z": 15,
      "name": "Plant_Leaves_Ash"
    },
    {
      "x": -9,
      "y": 58,
      "z": 16,
      "name": "Plant_Leaves_Ash"
    },
    {
      "x": -9,
      "y": 59,
      "z": 16,
      "name": "Plant_Leaves_Ash"
    },
    {
      "x": -9,
      "y": 58,
      "z": 17,
      "name": "Plant_Leaves_Ash"
    },
    {
      "x": -9,
      "y": 59,
      "z": 17,
      "name": "Plant_Leaves_Ash"
    },
    {
      "x": -9,
      "y": 58,
      "z": 18,
      "name": "Plant_Leaves_Ash"
    },
    {
      "x": -8,
      "y": 58,
      "z": -18,
      "name": "Plant_Leaves_Ash"
    },
    {
      "x": -8,
      "y": 58,
      "z": -17,
      "name": "Plant_Leaves_Ash"
    },
    {
      "x": -8,
      "y": 59,
      "z": -17,
      "name": "Plant_Leaves_Ash"
    },
    {
      "x": -8,
      "y": 58,
      "z": -16,
      "name": "Plant_Leaves_Ash"
    },
    {
      "x": -8,
      "y": 59,
      "z": -16,
      "name": "Plant_Leaves_Ash"
    },
    {
      "x": -8,
      "y": 59,
      "z": -15,
      "name": "Plant_Leaves_Ash"
    },
    {
      "x": -8,
      "y": 60,
      "z": -15,
      "name": "Plant_Leaves_Ash"
    },
    {
      "x": -8,
      "y": 59,
      "z": -14,
      "name": "Plant_Leaves_Ash"
    },
    {
      "x": -8,
      "y": 60,
      "z": -14,
      "name": "Plant_Leaves_Ash"
    },
    {
      "x": -8,
      "y": 60,
      "z": -13,
      "name": "Plant_Leaves_Ash"
    },
    {
      "x": -8,
      "y": 60,
      "z": -12,
      "name": "Plant_Leaves_Ash"
    },
    {
      "x": -8,
      "y": 60,
      "z": -11,
      "name": "Plant_Leaves_Ash"
    },
    {
      "x": -8,
      "y": 60,
      "z": -10,
      "name": "Plant_Leaves_Ash"
    },
    {
      "x": -8,
      "y": 61,
      "z": -10,
      "name": "Plant_Leaves_Ash"
    },
    {
      "x": -8,
      "y": 60,
      "z": -9,
      "name": "Plant_Leaves_Ash"
    },
    {
      "x": -8,
      "y": 61,
      "z": -9,
      "name": "Plant_Leaves_Ash"
    },
    {
      "x": -8,
      "y": 60,
      "z": -8,
      "name": "Plant_Leaves_Ash"
    },
    {
      "x": -8,
      "y": 61,
      "z": -8,
      "name": "Plant_Leaves_Ash"
    },
    {
      "x": -8,
      "y": 60,
      "z": -7,
      "name": "Plant_Leaves_Ash"
    },
    {
      "x": -8,
      "y": 61,
      "z": -7,
      "name": "Plant_Leaves_Ash"
    },
    {
      "x": -8,
      "y": 60,
      "z": -6,
      "name": "Plant_Leaves_Ash"
    },
    {
      "x": -8,
      "y": 61,
      "z": -6,
      "name": "Plant_Leaves_Ash"
    },
    {
      "x": -8,
      "y": 60,
      "z": -5,
      "name": "Plant_Leaves_Ash"
    },
    {
      "x": -8,
      "y": 61,
      "z": -5,
      "name": "Plant_Leaves_Ash"
    },
    {
      "x": -8,
      "y": 60,
      "z": -4,
      "name": "Plant_Leaves_Ash"
    },
    {
      "x": -8,
      "y": 61,
      "z": -4,
      "name": "Plant_Leaves_Ash"
    },
    {
      "x": -8,
      "y": 60,
      "z": -3,
      "name": "Plant_Leaves_Ash"
    },
    {
      "x": -8,
      "y": 61,
      "z": -3,
      "name": "Plant_Leaves_Ash"
    },
    {
      "x": -8,
      "y": 60,
      "z": -2,
      "name": "Plant_Leaves_Ash"
    },
    {
      "x": -8,
      "y": 61,
      "z": -2,
      "name": "Plant_Leaves_Ash"
    },
    {
      "x": -8,
      "y": 60,
      "z": -1,
      "name": "Plant_Leaves_Ash"
    },
    {
      "x": -8,
      "y": 61,
      "z": -1,
      "name": "Plant_Leaves_Ash"
    },
    {
      "x": -8,
      "y": 60,
      "z": 0,
      "name": "Plant_Leaves_Ash"
    },
    {
      "x": -8,
      "y": 61,
      "z": 0,
      "name": "Plant_Leaves_Ash"
    },
    {
      "x": -8,
      "y": 60,
      "z": 1,
      "name": "Plant_Leaves_Ash"
    },
    {
      "x": -8,
      "y": 61,
      "z": 1,
      "name": "Plant_Leaves_Ash"
    },
    {
      "x": -8,
      "y": 60,
      "z": 2,
      "name": "Plant_Leaves_Ash"
    },
    {
      "x": -8,
      "y": 61,
      "z": 2,
      "name": "Plant_Leaves_Ash"
    },
    {
      "x": -8,
      "y": 60,
      "z": 3,
      "name": "Plant_Leaves_Ash"
    },
    {
      "x": -8,
      "y": 61,
      "z": 3,
      "name": "Plant_Leaves_Ash"
    },
    {
      "x": -8,
      "y": 60,
      "z": 4,
      "name": "Plant_Leaves_Ash"
    },
    {
      "x": -8,
      "y": 61,
      "z": 4,
      "name": "Plant_Leaves_Ash"
    },
    {
      "x": -8,
      "y": 60,
      "z": 5,
      "name": "Plant_Leaves_Ash"
    },
    {
      "x": -8,
      "y": 61,
      "z": 5,
      "name": "Plant_Leaves_Ash"
    },
    {
      "x": -8,
      "y": 60,
      "z": 6,
      "name": "Plant_Leaves_Ash"
    },
    {
      "x": -8,
      "y": 61,
      "z": 6,
      "name": "Plant_Leaves_Ash"
    },
    {
      "x": -8,
      "y": 60,
      "z": 7,
      "name": "Plant_Leaves_Ash"
    },
    {
      "x": -8,
      "y": 61,
      "z": 7,
      "name": "Plant_Leaves_Ash"
    },
    {
      "x": -8,
      "y": 60,
      "z": 8,
      "name": "Plant_Leaves_Ash"
    },
    {
      "x": -8,
      "y": 61,
      "z": 8,
      "name": "Plant_Leaves_Ash"
    },
    {
      "x": -8,
      "y": 60,
      "z": 9,
      "name": "Plant_Leaves_Ash"
    },
    {
      "x": -8,
      "y": 61,
      "z": 9,
      "name": "Plant_Leaves_Ash"
    },
    {
      "x": -8,
      "y": 60,
      "z": 10,
      "name": "Plant_Leaves_Ash"
    },
    {
      "x": -8,
      "y": 61,
      "z": 10,
      "name": "Plant_Leaves_Ash"
    },
    {
      "x": -8,
      "y": 60,
      "z": 11,
      "name": "Plant_Leaves_Ash"
    },
    {
      "x": -8,
      "y": 60,
      "z": 12,
      "name": "Plant_Leaves_Ash"
    },
    {
      "x": -8,
      "y": 60,
      "z": 13,
      "name": "Plant_Leaves_Ash"
    },
    {
      "x": -8,
      "y": 59,
      "z": 14,
      "name": "Plant_Leaves_Ash"
    },
    {
      "x": -8,
      "y": 60,
      "z": 14,
      "name": "Plant_Leaves_Ash"
    },
    {
      "x": -8,
      "y": 59,
      "z": 15,
      "name": "Plant_Leaves_Ash"
    },
    {
      "x": -8,
      "y": 60,
      "z": 15,
      "name": "Plant_Leaves_Ash"
    },
    {
      "x": -8,
      "y": 58,
      "z": 16,
      "name": "Plant_Leaves_Ash"
    },
    {
      "x": -8,
      "y": 59,
      "z": 16,
      "name": "Plant_Leaves_Ash"
    },
    {
      "x": -8,
      "y": 58,
      "z": 17,
      "name": "Plant_Leaves_Ash"
    },
    {
      "x": -8,
      "y": 59,
      "z": 17,
      "name": "Plant_Leaves_Ash"
    },
    {
      "x": -8,
      "y": 58,
      "z": 18,
      "name": "Plant_Leaves_Ash"
    },
    {
      "x": -7,
      "y": 58,
      "z": -19,
      "name": "Plant_Leaves_Ash"
    },
    {
      "x": -7,
      "y": 58,
      "z": -18,
      "name": "Plant_Leaves_Ash"
    },
    {
      "x": -7,
      "y": 59,
      "z": -18,
      "name": "Plant_Leaves_Ash"
    },
    {
      "x": -7,
      "y": 58,
      "z": -17,
      "name": "Plant_Leaves_Ash"
    },
    {
      "x": -7,
      "y": 59,
      "z": -17,
      "name": "Plant_Leaves_Ash"
    },
    {
      "x": -7,
      "y": 58,
      "z": -16,
      "name": "Plant_Leaves_Ash"
    },
    {
      "x": -7,
      "y": 59,
      "z": -16,
      "name": "Plant_Leaves_Ash"
    },
    {
      "x": -7,
      "y": 59,
      "z": -15,
      "name": "Plant_Leaves_Ash"
    },
    {
      "x": -7,
      "y": 60,
      "z": -15,
      "name": "Plant_Leaves_Ash"
    },
    {
      "x": -7,
      "y": 59,
      "z": -14,
      "name": "Plant_Leaves_Ash"
    },
    {
      "x": -7,
      "y": 60,
      "z": -14,
      "name": "Plant_Leaves_Ash"
    },
    {
      "x": -7,
      "y": 60,
      "z": -13,
      "name": "Plant_Leaves_Ash"
    },
    {
      "x": -7,
      "y": 60,
      "z": -12,
      "name": "Plant_Leaves_Ash"
    },
    {
      "x": -7,
      "y": 60,
      "z": -11,
      "name": "Plant_Leaves_Ash"
    },
    {
      "x": -7,
      "y": 61,
      "z": -11,
      "name": "Plant_Leaves_Ash"
    },
    {
      "x": -7,
      "y": 60,
      "z": -10,
      "name": "Plant_Leaves_Ash"
    },
    {
      "x": -7,
      "y": 61,
      "z": -10,
      "name": "Plant_Leaves_Ash"
    },
    {
      "x": -7,
      "y": 60,
      "z": -9,
      "name": "Plant_Leaves_Ash"
    },
    {
      "x": -7,
      "y": 61,
      "z": -9,
      "name": "Plant_Leaves_Ash"
    },
    {
      "x": -7,
      "y": 60,
      "z": -8,
      "name": "Plant_Leaves_Ash"
    },
    {
      "x": -7,
      "y": 61,
      "z": -8,
      "name": "Plant_Leaves_Ash"
    },
    {
      "x": -7,
      "y": 60,
      "z": -7,
      "name": "Plant_Leaves_Ash"
    },
    {
      "x": -7,
      "y": 61,
      "z": -7,
      "name": "Plant_Leaves_Ash"
    },
    {
      "x": -7,
      "y": 60,
      "z": -6,
      "name": "Plant_Leaves_Ash"
    },
    {
      "x": -7,
      "y": 61,
      "z": -6,
      "name": "Plant_Leaves_Ash"
    },
    {
      "x": -7,
      "y": 60,
      "z": -5,
      "name": "Plant_Leaves_Ash"
    },
    {
      "x": -7,
      "y": 61,
      "z": -5,
      "name": "Plant_Leaves_Ash"
    },
    {
      "x": -7,
      "y": 60,
      "z": -4,
      "name": "Plant_Leaves_Ash"
    },
    {
      "x": -7,
      "y": 61,
      "z": -4,
      "name": "Plant_Leaves_Ash"
    },
    {
      "x": -7,
      "y": 60,
      "z": -3,
      "name": "Plant_Leaves_Ash"
    },
    {
      "x": -7,
      "y": 61,
      "z": -3,
      "name": "Plant_Leaves_Ash"
    },
    {
      "x": -7,
      "y": 60,
      "z": -2,
      "name": "Plant_Leaves_Ash"
    },
    {
      "x": -7,
      "y": 61,
      "z": -2,
      "name": "Plant_Leaves_Ash"
    },
    {
      "x": -7,
      "y": 60,
      "z": -1,
      "name": "Plant_Leaves_Ash"
    },
    {
      "x": -7,
      "y": 61,
      "z": -1,
      "name": "Plant_Leaves_Ash"
    },
    {
      "x": -7,
      "y": 60,
      "z": 0,
      "name": "Plant_Leaves_Ash"
    },
    {
      "x": -7,
      "y": 61,
      "z": 0,
      "name": "Plant_Leaves_Ash"
    },
    {
      "x": -7,
      "y": 60,
      "z": 1,
      "name": "Plant_Leaves_Ash"
    },
    {
      "x": -7,
      "y": 61,
      "z": 1,
      "name": "Plant_Leaves_Ash"
    },
    {
      "x": -7,
      "y": 60,
      "z": 2,
      "name": "Plant_Leaves_Ash"
    },
    {
      "x": -7,
      "y": 61,
      "z": 2,
      "name": "Plant_Leaves_Ash"
    },
    {
      "x": -7,
      "y": 60,
      "z": 3,
      "name": "Plant_Leaves_Ash"
    },
    {
      "x": -7,
      "y": 61,
      "z": 3,
      "name": "Plant_Leaves_Ash"
    },
    {
      "x": -7,
      "y": 60,
      "z": 4,
      "name": "Plant_Leaves_Ash"
    },
    {
      "x": -7,
      "y": 61,
      "z": 4,
      "name": "Plant_Leaves_Ash"
    },
    {
      "x": -7,
      "y": 60,
      "z": 5,
      "name": "Plant_Leaves_Ash"
    },
    {
      "x": -7,
      "y": 61,
      "z": 5,
      "name": "Plant_Leaves_Ash"
    },
    {
      "x": -7,
      "y": 60,
      "z": 6,
      "name": "Plant_Leaves_Ash"
    },
    {
      "x": -7,
      "y": 61,
      "z": 6,
      "name": "Plant_Leaves_Ash"
    },
    {
      "x": -7,
      "y": 60,
      "z": 7,
      "name": "Plant_Leaves_Ash"
    },
    {
      "x": -7,
      "y": 61,
      "z": 7,
      "name": "Plant_Leaves_Ash"
    },
    {
      "x": -7,
      "y": 60,
      "z": 8,
      "name": "Plant_Leaves_Ash"
    },
    {
      "x": -7,
      "y": 61,
      "z": 8,
      "name": "Plant_Leaves_Ash"
    },
    {
      "x": -7,
      "y": 60,
      "z": 9,
      "name": "Plant_Leaves_Ash"
    },
    {
      "x": -7,
      "y": 61,
      "z": 9,
      "name": "Plant_Leaves_Ash"
    },
    {
      "x": -7,
      "y": 60,
      "z": 10,
      "name": "Plant_Leaves_Ash"
    },
    {
      "x": -7,
      "y": 61,
      "z": 10,
      "name": "Plant_Leaves_Ash"
    },
    {
      "x": -7,
      "y": 60,
      "z": 11,
      "name": "Plant_Leaves_Ash"
    },
    {
      "x": -7,
      "y": 61,
      "z": 11,
      "name": "Plant_Leaves_Ash"
    },
    {
      "x": -7,
      "y": 60,
      "z": 12,
      "name": "Plant_Leaves_Ash"
    },
    {
      "x": -7,
      "y": 60,
      "z": 13,
      "name": "Plant_Leaves_Ash"
    },
    {
      "x": -7,
      "y": 59,
      "z": 14,
      "name": "Plant_Leaves_Ash"
    },
    {
      "x": -7,
      "y": 60,
      "z": 14,
      "name": "Plant_Leaves_Ash"
    },
    {
      "x": -7,
      "y": 59,
      "z": 15,
      "name": "Plant_Leaves_Ash"
    },
    {
      "x": -7,
      "y": 60,
      "z": 15,
      "name": "Plant_Leaves_Ash"
    },
    {
      "x": -7,
      "y": 58,
      "z": 16,
      "name": "Plant_Leaves_Ash"
    },
    {
      "x": -7,
      "y": 59,
      "z": 16,
      "name": "Plant_Leaves_Ash"
    },
    {
      "x": -7,
      "y": 58,
      "z": 17,
      "name": "Plant_Leaves_Ash"
    },
    {
      "x": -7,
      "y": 59,
      "z": 17,
      "name": "Plant_Leaves_Ash"
    },
    {
      "x": -7,
      "y": 58,
      "z": 18,
      "name": "Plant_Leaves_Ash"
    },
    {
      "x": -7,
      "y": 59,
      "z": 18,
      "name": "Plant_Leaves_Ash"
    },
    {
      "x": -7,
      "y": 58,
      "z": 19,
      "name": "Plant_Leaves_Ash"
    },
    {
      "x": -6,
      "y": 58,
      "z": -19,
      "name": "Plant_Leaves_Ash"
    },
    {
      "x": -6,
      "y": 58,
      "z": -18,
      "name": "Plant_Leaves_Ash"
    },
    {
      "x": -6,
      "y": 59,
      "z": -18,
      "name": "Plant_Leaves_Ash"
    },
    {
      "x": -6,
      "y": 58,
      "z": -17,
      "name": "Plant_Leaves_Ash"
    },
    {
      "x": -6,
      "y": 59,
      "z": -17,
      "name": "Plant_Leaves_Ash"
    },
    {
      "x": -6,
      "y": 59,
      "z": -16,
      "name": "Plant_Leaves_Ash"
    },
    {
      "x": -6,
      "y": 60,
      "z": -16,
      "name": "Plant_Leaves_Ash"
    },
    {
      "x": -6,
      "y": 59,
      "z": -15,
      "name": "Plant_Leaves_Ash"
    },
    {
      "x": -6,
      "y": 60,
      "z": -15,
      "name": "Plant_Leaves_Ash"
    },
    {
      "x": -6,
      "y": 60,
      "z": -14,
      "name": "Plant_Leaves_Ash"
    },
    {
      "x": -6,
      "y": 60,
      "z": -13,
      "name": "Plant_Leaves_Ash"
    },
    {
      "x": -6,
      "y": 60,
      "z": -12,
      "name": "Plant_Leaves_Ash"
    },
    {
      "x": -6,
      "y": 60,
      "z": -11,
      "name": "Plant_Leaves_Ash"
    },
    {
      "x": -6,
      "y": 61,
      "z": -11,
      "name": "Plant_Leaves_Ash"
    },
    {
      "x": -6,
      "y": 60,
      "z": -10,
      "name": "Plant_Leaves_Ash"
    },
    {
      "x": -6,
      "y": 61,
      "z": -10,
      "name": "Plant_Leaves_Ash"
    },
    {
      "x": -6,
      "y": 60,
      "z": -9,
      "name": "Plant_Leaves_Ash"
    },
    {
      "x": -6,
      "y": 61,
      "z": -9,
      "name": "Plant_Leaves_Ash"
    },
    {
      "x": -6,
      "y": 60,
      "z": -8,
      "name": "Plant_Leaves_Ash"
    },
    {
      "x": -6,
      "y": 61,
      "z": -8,
      "name": "Plant_Leaves_Ash"
    },
    {
      "x": -6,
      "y": 60,
      "z": -7,
      "name": "Plant_Leaves_Ash"
    },
    {
      "x": -6,
      "y": 61,
      "z": -7,
      "name": "Plant_Leaves_Ash"
    },
    {
      "x": -6,
      "y": 60,
      "z": -6,
      "name": "Plant_Leaves_Ash"
    },
    {
      "x": -6,
      "y": 61,
      "z": -6,
      "name": "Plant_Leaves_Ash"
    },
    {
      "x": -6,
      "y": 60,
      "z": -5,
      "name": "Plant_Leaves_Ash"
    },
    {
      "x": -6,
      "y": 61,
      "z": -5,
      "name": "Plant_Leaves_Ash"
    },
    {
      "x": -6,
      "y": 60,
      "z": -4,
      "name": "Plant_Leaves_Ash"
    },
    {
      "x": -6,
      "y": 61,
      "z": -4,
      "name": "Plant_Leaves_Ash"
    },
    {
      "x": -6,
      "y": 60,
      "z": -3,
      "name": "Plant_Leaves_Ash"
    },
    {
      "x": -6,
      "y": 61,
      "z": -3,
      "name": "Plant_Leaves_Ash"
    },
    {
      "x": -6,
      "y": 60,
      "z": -2,
      "name": "Plant_Leaves_Ash"
    },
    {
      "x": -6,
      "y": 61,
      "z": -2,
      "name": "Plant_Leaves_Ash"
    },
    {
      "x": -6,
      "y": 60,
      "z": -1,
      "name": "Plant_Leaves_Ash"
    },
    {
      "x": -6,
      "y": 61,
      "z": -1,
      "name": "Plant_Leaves_Ash"
    },
    {
      "x": -6,
      "y": 60,
      "z": 0,
      "name": "Plant_Leaves_Ash"
    },
    {
      "x": -6,
      "y": 61,
      "z": 0,
      "name": "Plant_Leaves_Ash"
    },
    {
      "x": -6,
      "y": 60,
      "z": 1,
      "name": "Plant_Leaves_Ash"
    },
    {
      "x": -6,
      "y": 61,
      "z": 1,
      "name": "Plant_Leaves_Ash"
    },
    {
      "x": -6,
      "y": 60,
      "z": 2,
      "name": "Plant_Leaves_Ash"
    },
    {
      "x": -6,
      "y": 61,
      "z": 2,
      "name": "Plant_Leaves_Ash"
    },
    {
      "x": -6,
      "y": 60,
      "z": 3,
      "name": "Plant_Leaves_Ash"
    },
    {
      "x": -6,
      "y": 61,
      "z": 3,
      "name": "Plant_Leaves_Ash"
    },
    {
      "x": -6,
      "y": 60,
      "z": 4,
      "name": "Plant_Leaves_Ash"
    },
    {
      "x": -6,
      "y": 61,
      "z": 4,
      "name": "Plant_Leaves_Ash"
    },
    {
      "x": -6,
      "y": 60,
      "z": 5,
      "name": "Plant_Leaves_Ash"
    },
    {
      "x": -6,
      "y": 61,
      "z": 5,
      "name": "Plant_Leaves_Ash"
    },
    {
      "x": -6,
      "y": 60,
      "z": 6,
      "name": "Plant_Leaves_Ash"
    },
    {
      "x": -6,
      "y": 61,
      "z": 6,
      "name": "Plant_Leaves_Ash"
    },
    {
      "x": -6,
      "y": 60,
      "z": 7,
      "name": "Plant_Leaves_Ash"
    },
    {
      "x": -6,
      "y": 61,
      "z": 7,
      "name": "Plant_Leaves_Ash"
    },
    {
      "x": -6,
      "y": 60,
      "z": 8,
      "name": "Plant_Leaves_Ash"
    },
    {
      "x": -6,
      "y": 61,
      "z": 8,
      "name": "Plant_Leaves_Ash"
    },
    {
      "x": -6,
      "y": 60,
      "z": 9,
      "name": "Plant_Leaves_Ash"
    },
    {
      "x": -6,
      "y": 61,
      "z": 9,
      "name": "Plant_Leaves_Ash"
    },
    {
      "x": -6,
      "y": 60,
      "z": 10,
      "name": "Plant_Leaves_Ash"
    },
    {
      "x": -6,
      "y": 61,
      "z": 10,
      "name": "Plant_Leaves_Ash"
    },
    {
      "x": -6,
      "y": 60,
      "z": 11,
      "name": "Plant_Leaves_Ash"
    },
    {
      "x": -6,
      "y": 61,
      "z": 11,
      "name": "Plant_Leaves_Ash"
    },
    {
      "x": -6,
      "y": 60,
      "z": 12,
      "name": "Plant_Leaves_Ash"
    },
    {
      "x": -6,
      "y": 60,
      "z": 13,
      "name": "Plant_Leaves_Ash"
    },
    {
      "x": -6,
      "y": 60,
      "z": 14,
      "name": "Plant_Leaves_Ash"
    },
    {
      "x": -6,
      "y": 59,
      "z": 15,
      "name": "Plant_Leaves_Ash"
    },
    {
      "x": -6,
      "y": 60,
      "z": 15,
      "name": "Plant_Leaves_Ash"
    },
    {
      "x": -6,
      "y": 59,
      "z": 16,
      "name": "Plant_Leaves_Ash"
    },
    {
      "x": -6,
      "y": 60,
      "z": 16,
      "name": "Plant_Leaves_Ash"
    },
    {
      "x": -6,
      "y": 58,
      "z": 17,
      "name": "Plant_Leaves_Ash"
    },
    {
      "x": -6,
      "y": 59,
      "z": 17,
      "name": "Plant_Leaves_Ash"
    },
    {
      "x": -6,
      "y": 58,
      "z": 18,
      "name": "Plant_Leaves_Ash"
    },
    {
      "x": -6,
      "y": 59,
      "z": 18,
      "name": "Plant_Leaves_Ash"
    },
    {
      "x": -6,
      "y": 58,
      "z": 19,
      "name": "Plant_Leaves_Ash"
    },
    {
      "x": -5,
      "y": 58,
      "z": -19,
      "name": "Plant_Leaves_Ash"
    },
    {
      "x": -5,
      "y": 58,
      "z": -18,
      "name": "Plant_Leaves_Ash"
    },
    {
      "x": -5,
      "y": 59,
      "z": -18,
      "name": "Plant_Leaves_Ash"
    },
    {
      "x": -5,
      "y": 58,
      "z": -17,
      "name": "Plant_Leaves_Ash"
    },
    {
      "x": -5,
      "y": 59,
      "z": -17,
      "name": "Plant_Leaves_Ash"
    },
    {
      "x": -5,
      "y": 59,
      "z": -16,
      "name": "Plant_Leaves_Ash"
    },
    {
      "x": -5,
      "y": 60,
      "z": -16,
      "name": "Plant_Leaves_Ash"
    },
    {
      "x": -5,
      "y": 59,
      "z": -15,
      "name": "Plant_Leaves_Ash"
    },
    {
      "x": -5,
      "y": 60,
      "z": -15,
      "name": "Plant_Leaves_Ash"
    },
    {
      "x": -5,
      "y": 60,
      "z": -14,
      "name": "Plant_Leaves_Ash"
    },
    {
      "x": -5,
      "y": 60,
      "z": -13,
      "name": "Plant_Leaves_Ash"
    },
    {
      "x": -5,
      "y": 60,
      "z": -12,
      "name": "Plant_Leaves_Ash"
    },
    {
      "x": -5,
      "y": 61,
      "z": -12,
      "name": "Plant_Leaves_Ash"
    },
    {
      "x": -5,
      "y": 60,
      "z": -11,
      "name": "Plant_Leaves_Ash"
    },
    {
      "x": -5,
      "y": 61,
      "z": -11,
      "name": "Plant_Leaves_Ash"
    },
    {
      "x": -5,
      "y": 60,
      "z": -10,
      "name": "Plant_Leaves_Ash"
    },
    {
      "x": -5,
      "y": 61,
      "z": -10,
      "name": "Plant_Leaves_Ash"
    },
    {
      "x": -5,
      "y": 60,
      "z": -9,
      "name": "Plant_Leaves_Ash"
    },
    {
      "x": -5,
      "y": 61,
      "z": -9,
      "name": "Plant_Leaves_Ash"
    },
    {
      "x": -5,
      "y": 60,
      "z": -8,
      "name": "Plant_Leaves_Ash"
    },
    {
      "x": -5,
      "y": 61,
      "z": -8,
      "name": "Plant_Leaves_Ash"
    },
    {
      "x": -5,
      "y": 60,
      "z": -7,
      "name": "Plant_Leaves_Ash"
    },
    {
      "x": -5,
      "y": 61,
      "z": -7,
      "name": "Plant_Leaves_Ash"
    },
    {
      "x": -5,
      "y": 60,
      "z": -6,
      "name": "Plant_Leaves_Ash"
    },
    {
      "x": -5,
      "y": 61,
      "z": -6,
      "name": "Plant_Leaves_Ash"
    },
    {
      "x": -5,
      "y": 60,
      "z": -5,
      "name": "Plant_Leaves_Ash"
    },
    {
      "x": -5,
      "y": 61,
      "z": -5,
      "name": "Plant_Leaves_Ash"
    },
    {
      "x": -5,
      "y": 60,
      "z": -4,
      "name": "Plant_Leaves_Ash"
    },
    {
      "x": -5,
      "y": 61,
      "z": -4,
      "name": "Plant_Leaves_Ash"
    },
    {
      "x": -5,
      "y": 60,
      "z": -3,
      "name": "Plant_Leaves_Ash"
    },
    {
      "x": -5,
      "y": 61,
      "z": -3,
      "name": "Plant_Leaves_Ash"
    },
    {
      "x": -5,
      "y": 60,
      "z": -2,
      "name": "Plant_Leaves_Ash"
    },
    {
      "x": -5,
      "y": 61,
      "z": -2,
      "name": "Plant_Leaves_Ash"
    },
    {
      "x": -5,
      "y": 60,
      "z": -1,
      "name": "Plant_Leaves_Ash"
    },
    {
      "x": -5,
      "y": 61,
      "z": -1,
      "name": "Plant_Leaves_Ash"
    },
    {
      "x": -5,
      "y": 60,
      "z": 0,
      "name": "Plant_Leaves_Ash"
    },
    {
      "x": -5,
      "y": 61,
      "z": 0,
      "name": "Plant_Leaves_Ash"
    },
    {
      "x": -5,
      "y": 60,
      "z": 1,
      "name": "Plant_Leaves_Ash"
    },
    {
      "x": -5,
      "y": 61,
      "z": 1,
      "name": "Plant_Leaves_Ash"
    },
    {
      "x": -5,
      "y": 60,
      "z": 2,
      "name": "Plant_Leaves_Ash"
    },
    {
      "x": -5,
      "y": 61,
      "z": 2,
      "name": "Plant_Leaves_Ash"
    },
    {
      "x": -5,
      "y": 60,
      "z": 3,
      "name": "Plant_Leaves_Ash"
    },
    {
      "x": -5,
      "y": 61,
      "z": 3,
      "name": "Plant_Leaves_Ash"
    },
    {
      "x": -5,
      "y": 60,
      "z": 4,
      "name": "Plant_Leaves_Ash"
    },
    {
      "x": -5,
      "y": 61,
      "z": 4,
      "name": "Plant_Leaves_Ash"
    },
    {
      "x": -5,
      "y": 60,
      "z": 5,
      "name": "Plant_Leaves_Ash"
    },
    {
      "x": -5,
      "y": 61,
      "z": 5,
      "name": "Plant_Leaves_Ash"
    },
    {
      "x": -5,
      "y": 60,
      "z": 6,
      "name": "Plant_Leaves_Ash"
    },
    {
      "x": -5,
      "y": 61,
      "z": 6,
      "name": "Plant_Leaves_Ash"
    },
    {
      "x": -5,
      "y": 60,
      "z": 7,
      "name": "Plant_Leaves_Ash"
    },
    {
      "x": -5,
      "y": 61,
      "z": 7,
      "name": "Plant_Leaves_Ash"
    },
    {
      "x": -5,
      "y": 60,
      "z": 8,
      "name": "Plant_Leaves_Ash"
    },
    {
      "x": -5,
      "y": 61,
      "z": 8,
      "name": "Plant_Leaves_Ash"
    },
    {
      "x": -5,
      "y": 60,
      "z": 9,
      "name": "Plant_Leaves_Ash"
    },
    {
      "x": -5,
      "y": 61,
      "z": 9,
      "name": "Plant_Leaves_Ash"
    },
    {
      "x": -5,
      "y": 60,
      "z": 10,
      "name": "Plant_Leaves_Ash"
    },
    {
      "x": -5,
      "y": 61,
      "z": 10,
      "name": "Plant_Leaves_Ash"
    },
    {
      "x": -5,
      "y": 60,
      "z": 11,
      "name": "Plant_Leaves_Ash"
    },
    {
      "x": -5,
      "y": 61,
      "z": 11,
      "name": "Plant_Leaves_Ash"
    },
    {
      "x": -5,
      "y": 60,
      "z": 12,
      "name": "Plant_Leaves_Ash"
    },
    {
      "x": -5,
      "y": 61,
      "z": 12,
      "name": "Plant_Leaves_Ash"
    },
    {
      "x": -5,
      "y": 60,
      "z": 13,
      "name": "Plant_Leaves_Ash"
    },
    {
      "x": -5,
      "y": 60,
      "z": 14,
      "name": "Plant_Leaves_Ash"
    },
    {
      "x": -5,
      "y": 59,
      "z": 15,
      "name": "Plant_Leaves_Ash"
    },
    {
      "x": -5,
      "y": 60,
      "z": 15,
      "name": "Plant_Leaves_Ash"
    },
    {
      "x": -5,
      "y": 59,
      "z": 16,
      "name": "Plant_Leaves_Ash"
    },
    {
      "x": -5,
      "y": 60,
      "z": 16,
      "name": "Plant_Leaves_Ash"
    },
    {
      "x": -5,
      "y": 58,
      "z": 17,
      "name": "Plant_Leaves_Ash"
    },
    {
      "x": -5,
      "y": 59,
      "z": 17,
      "name": "Plant_Leaves_Ash"
    },
    {
      "x": -5,
      "y": 58,
      "z": 18,
      "name": "Plant_Leaves_Ash"
    },
    {
      "x": -5,
      "y": 59,
      "z": 18,
      "name": "Plant_Leaves_Ash"
    },
    {
      "x": -5,
      "y": 58,
      "z": 19,
      "name": "Plant_Leaves_Ash"
    },
    {
      "x": -4,
      "y": 58,
      "z": -20,
      "name": "Plant_Leaves_Ash"
    },
    {
      "x": -4,
      "y": 58,
      "z": -19,
      "name": "Plant_Leaves_Ash"
    },
    {
      "x": -4,
      "y": 58,
      "z": -18,
      "name": "Plant_Leaves_Ash"
    },
    {
      "x": -4,
      "y": 59,
      "z": -18,
      "name": "Plant_Leaves_Ash"
    },
    {
      "x": -4,
      "y": 58,
      "z": -17,
      "name": "Plant_Leaves_Ash"
    },
    {
      "x": -4,
      "y": 59,
      "z": -17,
      "name": "Plant_Leaves_Ash"
    },
    {
      "x": -4,
      "y": 59,
      "z": -16,
      "name": "Plant_Leaves_Ash"
    },
    {
      "x": -4,
      "y": 60,
      "z": -16,
      "name": "Plant_Leaves_Ash"
    },
    {
      "x": -4,
      "y": 59,
      "z": -15,
      "name": "Plant_Leaves_Ash"
    },
    {
      "x": -4,
      "y": 60,
      "z": -15,
      "name": "Plant_Leaves_Ash"
    },
    {
      "x": -4,
      "y": 60,
      "z": -14,
      "name": "Plant_Leaves_Ash"
    },
    {
      "x": -4,
      "y": 60,
      "z": -13,
      "name": "Plant_Leaves_Ash"
    },
    {
      "x": -4,
      "y": 60,
      "z": -12,
      "name": "Plant_Leaves_Ash"
    },
    {
      "x": -4,
      "y": 61,
      "z": -12,
      "name": "Plant_Leaves_Ash"
    },
    {
      "x": -4,
      "y": 60,
      "z": -11,
      "name": "Plant_Leaves_Ash"
    },
    {
      "x": -4,
      "y": 61,
      "z": -11,
      "name": "Plant_Leaves_Ash"
    },
    {
      "x": -4,
      "y": 60,
      "z": -10,
      "name": "Plant_Leaves_Ash"
    },
    {
      "x": -4,
      "y": 61,
      "z": -10,
      "name": "Plant_Leaves_Ash"
    },
    {
      "x": -4,
      "y": 60,
      "z": -9,
      "name": "Plant_Leaves_Ash"
    },
    {
      "x": -4,
      "y": 61,
      "z": -9,
      "name": "Plant_Leaves_Ash"
    },
    {
      "x": -4,
      "y": 60,
      "z": -8,
      "name": "Plant_Leaves_Ash"
    },
    {
      "x": -4,
      "y": 61,
      "z": -8,
      "name": "Plant_Leaves_Ash"
    },
    {
      "x": -4,
      "y": 60,
      "z": -7,
      "name": "Plant_Leaves_Ash"
    },
    {
      "x": -4,
      "y": 61,
      "z": -7,
      "name": "Plant_Leaves_Ash"
    },
    {
      "x": -4,
      "y": 60,
      "z": -6,
      "name": "Plant_Leaves_Ash"
    },
    {
      "x": -4,
      "y": 61,
      "z": -6,
      "name": "Plant_Leaves_Ash"
    },
    {
      "x": -4,
      "y": 60,
      "z": -5,
      "name": "Plant_Leaves_Ash"
    },
    {
      "x": -4,
      "y": 61,
      "z": -5,
      "name": "Plant_Leaves_Ash"
    },
    {
      "x": -4,
      "y": 60,
      "z": -4,
      "name": "Plant_Leaves_Ash"
    },
    {
      "x": -4,
      "y": 61,
      "z": -4,
      "name": "Plant_Leaves_Ash"
    },
    {
      "x": -4,
      "y": 60,
      "z": -3,
      "name": "Plant_Leaves_Ash"
    },
    {
      "x": -4,
      "y": 61,
      "z": -3,
      "name": "Plant_Leaves_Ash"
    },
    {
      "x": -4,
      "y": 60,
      "z": -2,
      "name": "Plant_Leaves_Ash"
    },
    {
      "x": -4,
      "y": 61,
      "z": -2,
      "name": "Plant_Leaves_Ash"
    },
    {
      "x": -4,
      "y": 60,
      "z": -1,
      "name": "Plant_Leaves_Ash"
    },
    {
      "x": -4,
      "y": 61,
      "z": -1,
      "name": "Plant_Leaves_Ash"
    },
    {
      "x": -4,
      "y": 60,
      "z": 0,
      "name": "Plant_Leaves_Ash"
    },
    {
      "x": -4,
      "y": 61,
      "z": 0,
      "name": "Plant_Leaves_Ash"
    },
    {
      "x": -4,
      "y": 60,
      "z": 1,
      "name": "Plant_Leaves_Ash"
    },
    {
      "x": -4,
      "y": 61,
      "z": 1,
      "name": "Plant_Leaves_Ash"
    },
    {
      "x": -4,
      "y": 60,
      "z": 2,
      "name": "Plant_Leaves_Ash"
    },
    {
      "x": -4,
      "y": 61,
      "z": 2,
      "name": "Plant_Leaves_Ash"
    },
    {
      "x": -4,
      "y": 60,
      "z": 3,
      "name": "Plant_Leaves_Ash"
    },
    {
      "x": -4,
      "y": 61,
      "z": 3,
      "name": "Plant_Leaves_Ash"
    },
    {
      "x": -4,
      "y": 60,
      "z": 4,
      "name": "Plant_Leaves_Ash"
    },
    {
      "x": -4,
      "y": 61,
      "z": 4,
      "name": "Plant_Leaves_Ash"
    },
    {
      "x": -4,
      "y": 60,
      "z": 5,
      "name": "Plant_Leaves_Ash"
    },
    {
      "x": -4,
      "y": 61,
      "z": 5,
      "name": "Plant_Leaves_Ash"
    },
    {
      "x": -4,
      "y": 60,
      "z": 6,
      "name": "Plant_Leaves_Ash"
    },
    {
      "x": -4,
      "y": 61,
      "z": 6,
      "name": "Plant_Leaves_Ash"
    },
    {
      "x": -4,
      "y": 60,
      "z": 7,
      "name": "Plant_Leaves_Ash"
    },
    {
      "x": -4,
      "y": 61,
      "z": 7,
      "name": "Plant_Leaves_Ash"
    },
    {
      "x": -4,
      "y": 60,
      "z": 8,
      "name": "Plant_Leaves_Ash"
    },
    {
      "x": -4,
      "y": 61,
      "z": 8,
      "name": "Plant_Leaves_Ash"
    },
    {
      "x": -4,
      "y": 60,
      "z": 9,
      "name": "Plant_Leaves_Ash"
    },
    {
      "x": -4,
      "y": 61,
      "z": 9,
      "name": "Plant_Leaves_Ash"
    },
    {
      "x": -4,
      "y": 60,
      "z": 10,
      "name": "Plant_Leaves_Ash"
    },
    {
      "x": -4,
      "y": 61,
      "z": 10,
      "name": "Plant_Leaves_Ash"
    },
    {
      "x": -4,
      "y": 60,
      "z": 11,
      "name": "Plant_Leaves_Ash"
    },
    {
      "x": -4,
      "y": 61,
      "z": 11,
      "name": "Plant_Leaves_Ash"
    },
    {
      "x": -4,
      "y": 60,
      "z": 12,
      "name": "Plant_Leaves_Ash"
    },
    {
      "x": -4,
      "y": 61,
      "z": 12,
      "name": "Plant_Leaves_Ash"
    },
    {
      "x": -4,
      "y": 60,
      "z": 13,
      "name": "Plant_Leaves_Ash"
    },
    {
      "x": -4,
      "y": 60,
      "z": 14,
      "name": "Plant_Leaves_Ash"
    },
    {
      "x": -4,
      "y": 59,
      "z": 15,
      "name": "Plant_Leaves_Ash"
    },
    {
      "x": -4,
      "y": 60,
      "z": 15,
      "name": "Plant_Leaves_Ash"
    },
    {
      "x": -4,
      "y": 59,
      "z": 16,
      "name": "Plant_Leaves_Ash"
    },
    {
      "x": -4,
      "y": 60,
      "z": 16,
      "name": "Plant_Leaves_Ash"
    },
    {
      "x": -4,
      "y": 58,
      "z": 17,
      "name": "Plant_Leaves_Ash"
    },
    {
      "x": -4,
      "y": 59,
      "z": 17,
      "name": "Plant_Leaves_Ash"
    },
    {
      "x": -4,
      "y": 58,
      "z": 18,
      "name": "Plant_Leaves_Ash"
    },
    {
      "x": -4,
      "y": 59,
      "z": 18,
      "name": "Plant_Leaves_Ash"
    },
    {
      "x": -4,
      "y": 58,
      "z": 19,
      "name": "Plant_Leaves_Ash"
    },
    {
      "x": -4,
      "y": 58,
      "z": 20,
      "name": "Plant_Leaves_Ash"
    },
    {
      "x": -3,
      "y": 58,
      "z": -20,
      "name": "Plant_Leaves_Ash"
    },
    {
      "x": -3,
      "y": 58,
      "z": -19,
      "name": "Plant_Leaves_Ash"
    },
    {
      "x": -3,
      "y": 59,
      "z": -19,
      "name": "Plant_Leaves_Ash"
    },
    {
      "x": -3,
      "y": 58,
      "z": -18,
      "name": "Plant_Leaves_Ash"
    },
    {
      "x": -3,
      "y": 59,
      "z": -18,
      "name": "Plant_Leaves_Ash"
    },
    {
      "x": -3,
      "y": 59,
      "z": -17,
      "name": "Plant_Leaves_Ash"
    },
    {
      "x": -3,
      "y": 60,
      "z": -17,
      "name": "Plant_Leaves_Ash"
    },
    {
      "x": -3,
      "y": 59,
      "z": -16,
      "name": "Plant_Leaves_Ash"
    },
    {
      "x": -3,
      "y": 60,
      "z": -16,
      "name": "Plant_Leaves_Ash"
    },
    {
      "x": -3,
      "y": 60,
      "z": -15,
      "name": "Plant_Leaves_Ash"
    },
    {
      "x": -3,
      "y": 60,
      "z": -14,
      "name": "Plant_Leaves_Ash"
    },
    {
      "x": -3,
      "y": 60,
      "z": -13,
      "name": "Plant_Leaves_Ash"
    },
    {
      "x": -3,
      "y": 61,
      "z": -13,
      "name": "Plant_Leaves_Ash"
    },
    {
      "x": -3,
      "y": 60,
      "z": -12,
      "name": "Plant_Leaves_Ash"
    },
    {
      "x": -3,
      "y": 61,
      "z": -12,
      "name": "Plant_Leaves_Ash"
    },
    {
      "x": -3,
      "y": 60,
      "z": -11,
      "name": "Plant_Leaves_Ash"
    },
    {
      "x": -3,
      "y": 61,
      "z": -11,
      "name": "Plant_Leaves_Ash"
    },
    {
      "x": -3,
      "y": 60,
      "z": -10,
      "name": "Plant_Leaves_Ash"
    },
    {
      "x": -3,
      "y": 61,
      "z": -10,
      "name": "Plant_Leaves_Ash"
    },
    {
      "x": -3,
      "y": 60,
      "z": -9,
      "name": "Plant_Leaves_Ash"
    },
    {
      "x": -3,
      "y": 61,
      "z": -9,
      "name": "Plant_Leaves_Ash"
    },
    {
      "x": -3,
      "y": 60,
      "z": -8,
      "name": "Plant_Leaves_Ash"
    },
    {
      "x": -3,
      "y": 61,
      "z": -8,
      "name": "Plant_Leaves_Ash"
    },
    {
      "x": -3,
      "y": 60,
      "z": -7,
      "name": "Plant_Leaves_Ash"
    },
    {
      "x": -3,
      "y": 61,
      "z": -7,
      "name": "Plant_Leaves_Ash"
    },
    {
      "x": -3,
      "y": 60,
      "z": -6,
      "name": "Plant_Leaves_Ash"
    },
    {
      "x": -3,
      "y": 61,
      "z": -6,
      "name": "Plant_Leaves_Ash"
    },
    {
      "x": -3,
      "y": 60,
      "z": -5,
      "name": "Plant_Leaves_Ash"
    },
    {
      "x": -3,
      "y": 61,
      "z": -5,
      "name": "Plant_Leaves_Ash"
    },
    {
      "x": -3,
      "y": 60,
      "z": -4,
      "name": "Plant_Leaves_Ash"
    },
    {
      "x": -3,
      "y": 61,
      "z": -4,
      "name": "Plant_Leaves_Ash"
    },
    {
      "x": -3,
      "y": 60,
      "z": -3,
      "name": "Plant_Leaves_Ash"
    },
    {
      "x": -3,
      "y": 61,
      "z": -3,
      "name": "Plant_Leaves_Ash"
    },
    {
      "x": -3,
      "y": 60,
      "z": -2,
      "name": "Plant_Leaves_Ash"
    },
    {
      "x": -3,
      "y": 61,
      "z": -2,
      "name": "Plant_Leaves_Ash"
    },
    {
      "x": -3,
      "y": 60,
      "z": -1,
      "name": "Plant_Leaves_Ash"
    },
    {
      "x": -3,
      "y": 61,
      "z": -1,
      "name": "Plant_Leaves_Ash"
    },
    {
      "x": -3,
      "y": 60,
      "z": 0,
      "name": "Plant_Leaves_Ash"
    },
    {
      "x": -3,
      "y": 61,
      "z": 0,
      "name": "Plant_Leaves_Ash"
    },
    {
      "x": -3,
      "y": 60,
      "z": 1,
      "name": "Plant_Leaves_Ash"
    },
    {
      "x": -3,
      "y": 61,
      "z": 1,
      "name": "Plant_Leaves_Ash"
    },
    {
      "x": -3,
      "y": 60,
      "z": 2,
      "name": "Plant_Leaves_Ash"
    },
    {
      "x": -3,
      "y": 61,
      "z": 2,
      "name": "Plant_Leaves_Ash"
    },
    {
      "x": -3,
      "y": 60,
      "z": 3,
      "name": "Plant_Leaves_Ash"
    },
    {
      "x": -3,
      "y": 61,
      "z": 3,
      "name": "Plant_Leaves_Ash"
    },
    {
      "x": -3,
      "y": 60,
      "z": 4,
      "name": "Plant_Leaves_Ash"
    },
    {
      "x": -3,
      "y": 61,
      "z": 4,
      "name": "Plant_Leaves_Ash"
    },
    {
      "x": -3,
      "y": 60,
      "z": 5,
      "name": "Plant_Leaves_Ash"
    },
    {
      "x": -3,
      "y": 61,
      "z": 5,
      "name": "Plant_Leaves_Ash"
    },
    {
      "x": -3,
      "y": 60,
      "z": 6,
      "name": "Plant_Leaves_Ash"
    },
    {
      "x": -3,
      "y": 61,
      "z": 6,
      "name": "Plant_Leaves_Ash"
    },
    {
      "x": -3,
      "y": 60,
      "z": 7,
      "name": "Plant_Leaves_Ash"
    },
    {
      "x": -3,
      "y": 61,
      "z": 7,
      "name": "Plant_Leaves_Ash"
    },
    {
      "x": -3,
      "y": 60,
      "z": 8,
      "name": "Plant_Leaves_Ash"
    },
    {
      "x": -3,
      "y": 61,
      "z": 8,
      "name": "Plant_Leaves_Ash"
    },
    {
      "x": -3,
      "y": 60,
      "z": 9,
      "name": "Plant_Leaves_Ash"
    },
    {
      "x": -3,
      "y": 61,
      "z": 9,
      "name": "Plant_Leaves_Ash"
    },
    {
      "x": -3,
      "y": 60,
      "z": 10,
      "name": "Plant_Leaves_Ash"
    },
    {
      "x": -3,
      "y": 61,
      "z": 10,
      "name": "Plant_Leaves_Ash"
    },
    {
      "x": -3,
      "y": 60,
      "z": 11,
      "name": "Plant_Leaves_Ash"
    },
    {
      "x": -3,
      "y": 61,
      "z": 11,
      "name": "Plant_Leaves_Ash"
    },
    {
      "x": -3,
      "y": 60,
      "z": 12,
      "name": "Plant_Leaves_Ash"
    },
    {
      "x": -3,
      "y": 61,
      "z": 12,
      "name": "Plant_Leaves_Ash"
    },
    {
      "x": -3,
      "y": 60,
      "z": 13,
      "name": "Plant_Leaves_Ash"
    },
    {
      "x": -3,
      "y": 61,
      "z": 13,
      "name": "Plant_Leaves_Ash"
    },
    {
      "x": -3,
      "y": 60,
      "z": 14,
      "name": "Plant_Leaves_Ash"
    },
    {
      "x": -3,
      "y": 60,
      "z": 15,
      "name": "Plant_Leaves_Ash"
    },
    {
      "x": -3,
      "y": 59,
      "z": 16,
      "name": "Plant_Leaves_Ash"
    },
    {
      "x": -3,
      "y": 60,
      "z": 16,
      "name": "Plant_Leaves_Ash"
    },
    {
      "x": -3,
      "y": 59,
      "z": 17,
      "name": "Plant_Leaves_Ash"
    },
    {
      "x": -3,
      "y": 60,
      "z": 17,
      "name": "Plant_Leaves_Ash"
    },
    {
      "x": -3,
      "y": 58,
      "z": 18,
      "name": "Plant_Leaves_Ash"
    },
    {
      "x": -3,
      "y": 59,
      "z": 18,
      "name": "Plant_Leaves_Ash"
    },
    {
      "x": -3,
      "y": 58,
      "z": 19,
      "name": "Plant_Leaves_Ash"
    },
    {
      "x": -3,
      "y": 59,
      "z": 19,
      "name": "Plant_Leaves_Ash"
    },
    {
      "x": -3,
      "y": 58,
      "z": 20,
      "name": "Plant_Leaves_Ash"
    },
    {
      "x": -2,
      "y": 58,
      "z": -20,
      "name": "Plant_Leaves_Ash"
    },
    {
      "x": -2,
      "y": 58,
      "z": -19,
      "name": "Plant_Leaves_Ash"
    },
    {
      "x": -2,
      "y": 59,
      "z": -19,
      "name": "Plant_Leaves_Ash"
    },
    {
      "x": -2,
      "y": 58,
      "z": -18,
      "name": "Plant_Leaves_Ash"
    },
    {
      "x": -2,
      "y": 59,
      "z": -18,
      "name": "Plant_Leaves_Ash"
    },
    {
      "x": -2,
      "y": 59,
      "z": -17,
      "name": "Plant_Leaves_Ash"
    },
    {
      "x": -2,
      "y": 60,
      "z": -17,
      "name": "Plant_Leaves_Ash"
    },
    {
      "x": -2,
      "y": 59,
      "z": -16,
      "name": "Plant_Leaves_Ash"
    },
    {
      "x": -2,
      "y": 60,
      "z": -16,
      "name": "Plant_Leaves_Ash"
    },
    {
      "x": -2,
      "y": 60,
      "z": -15,
      "name": "Plant_Leaves_Ash"
    },
    {
      "x": -2,
      "y": 60,
      "z": -14,
      "name": "Plant_Leaves_Ash"
    },
    {
      "x": -2,
      "y": 60,
      "z": -13,
      "name": "Plant_Leaves_Ash"
    },
    {
      "x": -2,
      "y": 61,
      "z": -13,
      "name": "Plant_Leaves_Ash"
    },
    {
      "x": -2,
      "y": 60,
      "z": -12,
      "name": "Plant_Leaves_Ash"
    },
    {
      "x": -2,
      "y": 61,
      "z": -12,
      "name": "Plant_Leaves_Ash"
    },
    {
      "x": -2,
      "y": 60,
      "z": -11,
      "name": "Plant_Leaves_Ash"
    },
    {
      "x": -2,
      "y": 61,
      "z": -11,
      "name": "Plant_Leaves_Ash"
    },
    {
      "x": -2,
      "y": 60,
      "z": -10,
      "name": "Plant_Leaves_Ash"
    },
    {
      "x": -2,
      "y": 61,
      "z": -10,
      "name": "Plant_Leaves_Ash"
    },
    {
      "x": -2,
      "y": 60,
      "z": -9,
      "name": "Plant_Leaves_Ash"
    },
    {
      "x": -2,
      "y": 61,
      "z": -9,
      "name": "Plant_Leaves_Ash"
    },
    {
      "x": -2,
      "y": 60,
      "z": -8,
      "name": "Plant_Leaves_Ash"
    },
    {
      "x": -2,
      "y": 61,
      "z": -8,
      "name": "Plant_Leaves_Ash"
    },
    {
      "x": -2,
      "y": 60,
      "z": -7,
      "name": "Plant_Leaves_Ash"
    },
    {
      "x": -2,
      "y": 61,
      "z": -7,
      "name": "Plant_Leaves_Ash"
    },
    {
      "x": -2,
      "y": 60,
      "z": -6,
      "name": "Plant_Leaves_Ash"
    },
    {
      "x": -2,
      "y": 61,
      "z": -6,
      "name": "Plant_Leaves_Ash"
    },
    {
      "x": -2,
      "y": 60,
      "z": -5,
      "name": "Plant_Leaves_Ash"
    },
    {
      "x": -2,
      "y": 61,
      "z": -5,
      "name": "Plant_Leaves_Ash"
    },
    {
      "x": -2,
      "y": 60,
      "z": -4,
      "name": "Plant_Leaves_Ash"
    },
    {
      "x": -2,
      "y": 61,
      "z": -4,
      "name": "Plant_Leaves_Ash"
    },
    {
      "x": -2,
      "y": 60,
      "z": -3,
      "name": "Plant_Leaves_Ash"
    },
    {
      "x": -2,
      "y": 61,
      "z": -3,
      "name": "Plant_Leaves_Ash"
    },
    {
      "x": -2,
      "y": 60,
      "z": -2,
      "name": "Plant_Leaves_Ash"
    },
    {
      "x": -2,
      "y": 61,
      "z": -2,
      "name": "Plant_Leaves_Ash"
    },
    {
      "x": -2,
      "y": 60,
      "z": -1,
      "name": "Plant_Leaves_Ash"
    },
    {
      "x": -2,
      "y": 61,
      "z": -1,
      "name": "Plant_Leaves_Ash"
    },
    {
      "x": -2,
      "y": 60,
      "z": 0,
      "name": "Plant_Leaves_Ash"
    },
    {
      "x": -2,
      "y": 61,
      "z": 0,
      "name": "Plant_Leaves_Ash"
    },
    {
      "x": -2,
      "y": 60,
      "z": 1,
      "name": "Plant_Leaves_Ash"
    },
    {
      "x": -2,
      "y": 61,
      "z": 1,
      "name": "Plant_Leaves_Ash"
    },
    {
      "x": -2,
      "y": 60,
      "z": 2,
      "name": "Plant_Leaves_Ash"
    },
    {
      "x": -2,
      "y": 61,
      "z": 2,
      "name": "Plant_Leaves_Ash"
    },
    {
      "x": -2,
      "y": 60,
      "z": 3,
      "name": "Plant_Leaves_Ash"
    },
    {
      "x": -2,
      "y": 61,
      "z": 3,
      "name": "Plant_Leaves_Ash"
    },
    {
      "x": -2,
      "y": 60,
      "z": 4,
      "name": "Plant_Leaves_Ash"
    },
    {
      "x": -2,
      "y": 61,
      "z": 4,
      "name": "Plant_Leaves_Ash"
    },
    {
      "x": -2,
      "y": 60,
      "z": 5,
      "name": "Plant_Leaves_Ash"
    },
    {
      "x": -2,
      "y": 61,
      "z": 5,
      "name": "Plant_Leaves_Ash"
    },
    {
      "x": -2,
      "y": 60,
      "z": 6,
      "name": "Plant_Leaves_Ash"
    },
    {
      "x": -2,
      "y": 61,
      "z": 6,
      "name": "Plant_Leaves_Ash"
    },
    {
      "x": -2,
      "y": 60,
      "z": 7,
      "name": "Plant_Leaves_Ash"
    },
    {
      "x": -2,
      "y": 61,
      "z": 7,
      "name": "Plant_Leaves_Ash"
    },
    {
      "x": -2,
      "y": 60,
      "z": 8,
      "name": "Plant_Leaves_Ash"
    },
    {
      "x": -2,
      "y": 61,
      "z": 8,
      "name": "Plant_Leaves_Ash"
    },
    {
      "x": -2,
      "y": 60,
      "z": 9,
      "name": "Plant_Leaves_Ash"
    },
    {
      "x": -2,
      "y": 61,
      "z": 9,
      "name": "Plant_Leaves_Ash"
    },
    {
      "x": -2,
      "y": 60,
      "z": 10,
      "name": "Plant_Leaves_Ash"
    },
    {
      "x": -2,
      "y": 61,
      "z": 10,
      "name": "Plant_Leaves_Ash"
    },
    {
      "x": -2,
      "y": 60,
      "z": 11,
      "name": "Plant_Leaves_Ash"
    },
    {
      "x": -2,
      "y": 61,
      "z": 11,
      "name": "Plant_Leaves_Ash"
    },
    {
      "x": -2,
      "y": 60,
      "z": 12,
      "name": "Plant_Leaves_Ash"
    },
    {
      "x": -2,
      "y": 61,
      "z": 12,
      "name": "Plant_Leaves_Ash"
    },
    {
      "x": -2,
      "y": 60,
      "z": 13,
      "name": "Plant_Leaves_Ash"
    },
    {
      "x": -2,
      "y": 61,
      "z": 13,
      "name": "Plant_Leaves_Ash"
    },
    {
      "x": -2,
      "y": 60,
      "z": 14,
      "name": "Plant_Leaves_Ash"
    },
    {
      "x": -2,
      "y": 60,
      "z": 15,
      "name": "Plant_Leaves_Ash"
    },
    {
      "x": -2,
      "y": 59,
      "z": 16,
      "name": "Plant_Leaves_Ash"
    },
    {
      "x": -2,
      "y": 60,
      "z": 16,
      "name": "Plant_Leaves_Ash"
    },
    {
      "x": -2,
      "y": 59,
      "z": 17,
      "name": "Plant_Leaves_Ash"
    },
    {
      "x": -2,
      "y": 60,
      "z": 17,
      "name": "Plant_Leaves_Ash"
    },
    {
      "x": -2,
      "y": 58,
      "z": 18,
      "name": "Plant_Leaves_Ash"
    },
    {
      "x": -2,
      "y": 59,
      "z": 18,
      "name": "Plant_Leaves_Ash"
    },
    {
      "x": -2,
      "y": 58,
      "z": 19,
      "name": "Plant_Leaves_Ash"
    },
    {
      "x": -2,
      "y": 59,
      "z": 19,
      "name": "Plant_Leaves_Ash"
    },
    {
      "x": -2,
      "y": 58,
      "z": 20,
      "name": "Plant_Leaves_Ash"
    },
    {
      "x": -1,
      "y": 58,
      "z": -20,
      "name": "Plant_Leaves_Ash"
    },
    {
      "x": -1,
      "y": 58,
      "z": -19,
      "name": "Plant_Leaves_Ash"
    },
    {
      "x": -1,
      "y": 59,
      "z": -19,
      "name": "Plant_Leaves_Ash"
    },
    {
      "x": -1,
      "y": 58,
      "z": -18,
      "name": "Plant_Leaves_Ash"
    },
    {
      "x": -1,
      "y": 59,
      "z": -18,
      "name": "Plant_Leaves_Ash"
    },
    {
      "x": -1,
      "y": 59,
      "z": -17,
      "name": "Plant_Leaves_Ash"
    },
    {
      "x": -1,
      "y": 60,
      "z": -17,
      "name": "Plant_Leaves_Ash"
    },
    {
      "x": -1,
      "y": 59,
      "z": -16,
      "name": "Plant_Leaves_Ash"
    },
    {
      "x": -1,
      "y": 60,
      "z": -16,
      "name": "Plant_Leaves_Ash"
    },
    {
      "x": -1,
      "y": 60,
      "z": -15,
      "name": "Plant_Leaves_Ash"
    },
    {
      "x": -1,
      "y": 60,
      "z": -14,
      "name": "Plant_Leaves_Ash"
    },
    {
      "x": -1,
      "y": 60,
      "z": -13,
      "name": "Plant_Leaves_Ash"
    },
    {
      "x": -1,
      "y": 61,
      "z": -13,
      "name": "Plant_Leaves_Ash"
    },
    {
      "x": -1,
      "y": 60,
      "z": -12,
      "name": "Plant_Leaves_Ash"
    },
    {
      "x": -1,
      "y": 61,
      "z": -12,
      "name": "Plant_Leaves_Ash"
    },
    {
      "x": -1,
      "y": 60,
      "z": -11,
      "name": "Plant_Leaves_Ash"
    },
    {
      "x": -1,
      "y": 61,
      "z": -11,
      "name": "Plant_Leaves_Ash"
    },
    {
      "x": -1,
      "y": 60,
      "z": -10,
      "name": "Plant_Leaves_Ash"
    },
    {
      "x": -1,
      "y": 61,
      "z": -10,
      "name": "Plant_Leaves_Ash"
    },
    {
      "x": -1,
      "y": 60,
      "z": -9,
      "name": "Plant_Leaves_Ash"
    },
    {
      "x": -1,
      "y": 61,
      "z": -9,
      "name": "Plant_Leaves_Ash"
    },
    {
      "x": -1,
      "y": 60,
      "z": -8,
      "name": "Plant_Leaves_Ash"
    },
    {
      "x": -1,
      "y": 61,
      "z": -8,
      "name": "Plant_Leaves_Ash"
    },
    {
      "x": -1,
      "y": 60,
      "z": -7,
      "name": "Plant_Leaves_Ash"
    },
    {
      "x": -1,
      "y": 61,
      "z": -7,
      "name": "Plant_Leaves_Ash"
    },
    {
      "x": -1,
      "y": 60,
      "z": -6,
      "name": "Plant_Leaves_Ash"
    },
    {
      "x": -1,
      "y": 61,
      "z": -6,
      "name": "Plant_Leaves_Ash"
    },
    {
      "x": -1,
      "y": 60,
      "z": -5,
      "name": "Plant_Leaves_Ash"
    },
    {
      "x": -1,
      "y": 61,
      "z": -5,
      "name": "Plant_Leaves_Ash"
    },
    {
      "x": -1,
      "y": 60,
      "z": -4,
      "name": "Plant_Leaves_Ash"
    },
    {
      "x": -1,
      "y": 61,
      "z": -4,
      "name": "Plant_Leaves_Ash"
    },
    {
      "x": -1,
      "y": 60,
      "z": -3,
      "name": "Plant_Leaves_Ash"
    },
    {
      "x": -1,
      "y": 61,
      "z": -3,
      "name": "Plant_Leaves_Ash"
    },
    {
      "x": -1,
      "y": 60,
      "z": -2,
      "name": "Plant_Leaves_Ash"
    },
    {
      "x": -1,
      "y": 61,
      "z": -2,
      "name": "Plant_Leaves_Ash"
    },
    {
      "x": -1,
      "y": 0,
      "z": -1,
      "name": "Wood_Oak_Trunk"
    },
    {
      "x": -1,
      "y": 1,
      "z": -1,
      "name": "Wood_Oak_Trunk"
    },
    {
      "x": -1,
      "y": 2,
      "z": -1,
      "name": "Wood_Oak_Trunk"
    },
    {
      "x": -1,
      "y": 3,
      "z": -1,
      "name": "Wood_Oak_Trunk"
    },
    {
      "x": -1,
      "y": 4,
      "z": -1,
      "name": "Wood_Oak_Trunk"
    },
    {
      "x": -1,
      "y": 5,
      "z": -1,
      "name": "Wood_Oak_Trunk"
    },
    {
      "x": -1,
      "y": 6,
      "z": -1,
      "name": "Wood_Oak_Trunk"
    },
    {
      "x": -1,
      "y": 7,
      "z": -1,
      "name": "Wood_Oak_Trunk"
    },
    {
      "x": -1,
      "y": 8,
      "z": -1,
      "name": "Wood_Oak_Trunk"
    },
    {
      "x": -1,
      "y": 9,
      "z": -1,
      "name": "Wood_Oak_Trunk"
    },
    {
      "x": -1,
      "y": 10,
      "z": -1,
      "name": "Wood_Oak_Trunk"
    },
    {
      "x": -1,
      "y": 11,
      "z": -1,
      "name": "Wood_Oak_Trunk"
    },
    {
      "x": -1,
      "y": 12,
      "z": -1,
      "name": "Wood_Oak_Trunk"
    },
    {
      "x": -1,
      "y": 13,
      "z": -1,
      "name": "Wood_Oak_Trunk"
    },
    {
      "x": -1,
      "y": 14,
      "z": -1,
      "name": "Wood_Oak_Trunk"
    },
    {
      "x": -1,
      "y": 15,
      "z": -1,
      "name": "Wood_Oak_Trunk"
    },
    {
      "x": -1,
      "y": 16,
      "z": -1,
      "name": "Wood_Oak_Trunk"
    },
    {
      "x": -1,
      "y": 17,
      "z": -1,
      "name": "Wood_Oak_Trunk"
    },
    {
      "x": -1,
