{
  "version": 8,
  "blockIdVersion": 11,
  "anchorX": 0,
  "anchorY": 15,
  "anchorZ": 0,
  "blocks": [
    {
      "x": -20,
      "y": 77,
      "z": -4,
      "name": "Plant_Leaves_Ash"
    },
    {
      "x": -20,
      "y": 77,
      "z": -3,
      "name": "Plant_Leaves_Ash"
    },
    {
      "x": -20,
      "y": 77,
      "z": -2,
      "name": "Plant_Leaves_Ash"
    },
    {
      "x": -20,
      "y": 77,
      "z": -1,
      "name": "Plant_Leaves_Ash"
    },
    {
      "x": -20,
      "y": 77,
      "z": 0,
      "name": "Plant_Leaves_Ash"
    },
    {
      "x": -20,
      "y": 77,
      "z": 1,
      "name": "Plant_Leaves_Ash"
    },
    {
      "x": -20,
      "y": 77,
      "z": 2,
      "name": "Plant_Leaves_Ash"
    },
    {
      "x": -20,
      "y": 77,
      "z": 3,
      "name": "Plant_Leaves_Ash"
    },
    {
      "x": -20,
      "y": 77,
      "z": 4,
      "name": "Plant_Leaves_Ash"
    },
    {
      "x": -19,
      "y": 77,
      "z": -7,
      "name": "Plant_Leaves_Ash"
    },
    {
      "x": -19,
      "y": 77,
      "z": -6,
      "name": "Plant_Leaves_Ash"
    },
    {
      "x": -19,
      "y": 77,
      "z": -5,
      "name": "Plant_Leaves_Ash"
    },
    {
      "x": -19,
      "y": 77,
      "z": -4,
      "name": "Plant_Leaves_Ash"
    },
    {
      "x": -19,
      "y": 77,
      "z": -3,
      "name": "Plant_Leaves_Ash"
    },
    {
      "x": -19,
      "y": 78,
      "z": -3,
      "name": "Plant_Leaves_Ash"
    },
    {
      "x": -19,
      "y": 77,
      "z": -2,
      "name": "Plant_Leaves_Ash"
    },
    {
      "x": -19,
      "y": 78,
      "z": -2,
      "name": "Plant_Leaves_Ash"
    },
    {
      "x": -19,
      "y": 77,
      "z": -1,
      "name": "Plant_Leaves_Ash"
    },
    {
      "x": -19,
      "y": 78,
      "z": -1,
      "name": "Plant_Leaves_Ash"
    },
    {
      "x": -19,
      "y": 77,
      "z": 0,
      "name": "Plant_Leaves_Ash"
    },
    {
      "x": -19,
      "y": 78,
      "z": 0,
      "name": "Plant_Leaves_Ash"
    },
    {
      "x": -19,
      "y": 77,
      "z": 1,
      "name": "Plant_Leaves_Ash"
    },
    {
      "x": -19,
      "y": 78,
      "z": 1,
      "name": "Plant_Leaves_Ash"
    },
    {
      "x": -19,
      "y": 77,
      "z": 2,
      "name": "Plant_Leaves_Ash"
    },
    {
      "x": -19,
      "y": 78,
      "z": 2,
      "name": "Plant_Leaves_Ash"
    },
    {
      "x": -19,
      "y": 77,
      "z": 3,
      "name": "Plant_Leaves_Ash"
    },
    {
      "x": -19,
      "y": 78,
      "z": 3,
      "name": "Plant_Leaves_Ash"
    },
    {
      "x": -19,
      "y": 77,
      "z": 4,
      "name": "Plant_Leaves_Ash"
    },
    {
      "x": -19,
      "y": 77,
      "z": 5,
      "name": "Plant_Leaves_Ash"
    },
    {
      "x": -19,
      "y": 77,
      "z": 6,
      "name": "Plant_Leaves_Ash"
    },
    {
      "x": -19,
      "y": 77,
      "z": 7,
      "name": "Plant_Leaves_Ash"
    },
    {
      "x": -18,
      "y": 77,
      "z": -9,
      "name": "Plant_Leaves_Ash"
    },
    {
      "x": -18,
      "y": 77,
      "z": -8,
      "name": "Plant_Leaves_Ash"
    },
    {
      "x": -18,
      "y": 77,
      "z": -7,
      "name": "Plant_Leaves_Ash"
    },
    {
      "x": -18,
      "y": 78,
      "z": -7,
      "name": "Plant_Leaves_Ash"
    },
    {
      "x": -18,
      "y": 77,
      "z": -6,
      "name": "Plant_Leaves_Ash"
    },
    {
      "x": -18,
      "y": 78,
      "z": -6,
      "name": "Plant_Leaves_Ash"
    },
    {
      "x": -18,
      "y": 77,
      "z": -5,
      "name": "Plant_Leaves_Ash"
    },
    {
      "x": -18,
      "y": 78,
      "z": -5,
      "name": "Plant_Leaves_Ash"
    },
    {
      "x": -18,
      "y": 77,
      "z": -4,
      "name": "Plant_Leaves_Ash"
    },
    {
      "x": -18,
      "y": 78,
      "z": -4,
      "name": "Plant_Leaves_Ash"
    },
    {
      "x": -18,
      "y": 77,
      "z": -3,
      "name": "Plant_Leaves_Ash"
    },
    {
      "x": -18,
      "y": 78,
      "z": -3,
      "name": "Plant_Leaves_Ash"
    },
    {
      "x": -18,
      "y": 77,
      "z": -2,
      "name": "Plant_Leaves_Ash"
    },
    {
      "x": -18,
      "y": 78,
      "z": -2,
      "name": "Plant_Leaves_Ash"
    },
    {
      "x": -18,
      "y": 77,
      "z": -1,
      "name": "Plant_Leaves_Ash"
    },
    {
      "x": -18,
      "y": 78,
      "z": -1,
      "name": "Plant_Leaves_Ash"
    },
    {
      "x": -18,
      "y": 77,
      "z": 0,
      "name": "Plant_Leaves_Ash"
    },
    {
      "x": -18,
      "y": 78,
      "z": 0,
      "name": "Plant_Leaves_Ash"
    },
    {
      "x": -18,
      "y": 77,
      "z": 1,
      "name": "Plant_Leaves_Ash"
    },
    {
      "x": -18,
      "y": 78,
      "z": 1,
      "name": "Plant_Leaves_Ash"
    },
    {
      "x": -18,
      "y": 77,
      "z": 2,
      "name": "Plant_Leaves_Ash"
    },
    {
      "x": -18,
      "y": 78,
      "z": 2,
      "name": "Plant_Leaves_Ash"
    },
    {
      "x": -18,
      "y": 77,
      "z": 3,
      "name": "Plant_Leaves_Ash"
    },
    {
      "x": -18,
      "y": 78,
      "z": 3,
      "name": "Plant_Leaves_Ash"
    },
    {
      "x": -18,
      "y": 77,
      "z": 4,
      "name": "Plant_Leaves_Ash"
    },
    {
      "x": -18,
      "y": 78,
      "z": 4,
      "name": "Plant_Leaves_Ash"
    },
    {
      "x": -18,
      "y": 77,
      "z": 5,
      "name": "Plant_Leaves_Ash"
    },
    {
      "x": -18,
      "y": 78,
      "z": 5,
      "name": "Plant_Leaves_Ash"
    },
    {
      "x": -18,
      "y": 77,
      "z": 6,
      "name": "Plant_Leaves_Ash"
    },
    {
      "x": -18,
      "y": 78,
      "z": 6,
      "name": "Plant_Leaves_Ash"
    },
    {
      "x": -18,
      "y": 77,
      "z": 7,
      "name": "Plant_Leaves_Ash"
    },
    {
      "x": -18,
      "y": 78,
      "z": 7,
      "name": "Plant_Leaves_Ash"
    },
    {
      "x": -18,
      "y": 77,
      "z": 8,
      "name": "Plant_Leaves_Ash"
    },
    {
      "x": -18,
      "y": 77,
      "z": 9,
      "name": "Plant_Leaves_Ash"
    },
    {
      "x": -17,
      "y": 77,
      "z": -11,
      "name": "Plant_Leaves_Ash"
    },
    {
      "x": -17,
      "y": 77,
      "z": -10,
      "name": "Plant_Leaves_Ash"
    },
    {
      "x": -17,
      "y": 77,
      "z": -9,
      "name": "Plant_Leaves_Ash"
    },
    {
      "x": -17,
      "y": 78,
      "z": -9,
      "name": "Plant_Leaves_Ash"
    },
    {
      "x": -17,
      "y": 77,
      "z": -8,
      "name": "Plant_Leaves_Ash"
    },
    {
      "x": -17,
      "y": 78,
      "z": -8,
      "name": "Plant_Leaves_Ash"
    },
    {
      "x": -17,
      "y": 77,
      "z": -7,
      "name": "Plant_Leaves_Ash"
    },
    {
      "x": -17,
      "y": 78,
      "z": -7,
      "name": "Plant_Leaves_Ash"
    },
    {
      "x": -17,
      "y": 77,
      "z": -6,
      "name": "Plant_Leaves_Ash"
    },
    {
      "x": -17,
      "y": 78,
      "z": -6,
      "name": "Plant_Leaves_Ash"
    },
    {
      "x": -17,
      "y": 77,
      "z": -5,
      "name": "Plant_Leaves_Ash"
    },
    {
      "x": -17,
      "y": 78,
      "z": -5,
      "name": "Plant_Leaves_Ash"
    },
    {
      "x": -17,
      "y": 77,
      "z": -4,
      "name": "Plant_Leaves_Ash"
    },
    {
      "x": -17,
      "y": 78,
      "z": -4,
      "name": "Plant_Leaves_Ash"
    },
    {
      "x": -17,
      "y": 78,
      "z": -3,
      "name": "Plant_Leaves_Ash"
    },
    {
      "x": -17,
      "y": 79,
      "z": -3,
      "name": "Plant_Leaves_Ash"
    },
    {
      "x": -17,
      "y": 78,
      "z": -2,
      "name": "Plant_Leaves_Ash"
    },
    {
      "x": -17,
      "y": 79,
      "z": -2,
      "name": "Plant_Leaves_Ash"
    },
    {
      "x": -17,
      "y": 78,
      "z": -1,
      "name": "Plant_Leaves_Ash"
    },
    {
      "x": -17,
      "y": 79,
      "z": -1,
      "name": "Plant_Leaves_Ash"
    },
    {
      "x": -17,
      "y": 78,
      "z": 0,
      "name": "Plant_Leaves_Ash"
    },
    {
      "x": -17,
      "y": 79,
      "z": 0,
      "name": "Plant_Leaves_Ash"
    },
    {
      "x": -17,
      "y": 78,
      "z": 1,
      "name": "Plant_Leaves_Ash"
    },
    {
      "x": -17,
      "y": 79,
      "z": 1,
      "name": "Plant_Leaves_Ash"
    },
    {
      "x": -17,
      "y": 78,
      "z": 2,
      "name": "Plant_Leaves_Ash"
    },
    {
      "x": -17,
      "y": 79,
      "z": 2,
      "name": "Plant_Leaves_Ash"
    },
    {
      "x": -17,
      "y": 78,
      "z": 3,
      "name": "Plant_Leaves_Ash"
    },
    {
      "x": -17,
      "y": 79,
      "z": 3,
      "name": "Plant_Leaves_Ash"
    },
    {
      "x": -17,
      "y": 77,
      "z": 4,
      "name": "Plant_Leaves_Ash"
    },
    {
      "x": -17,
      "y": 78,
      "z": 4,
      "name": "Plant_Leaves_Ash"
    },
    {
      "x": -17,
      "y": 77,
      "z": 5,
      "name": "Plant_Leaves_Ash"
    },
    {
      "x": -17,
      "y": 78,
      "z": 5,
      "name": "Plant_Leaves_Ash"
    },
    {
      "x": -17,
      "y": 77,
      "z": 6,
      "name": "Plant_Leaves_Ash"
    },
    {
      "x": -17,
      "y": 78,
      "z": 6,
      "name": "Plant_Leaves_Ash"
    },
    {
      "x": -17,
      "y": 77,
      "z": 7,
      "name": "Plant_Leaves_Ash"
    },
    {
      "x": -17,
      "y": 78,
      "z": 7,
      "name": "Plant_Leaves_Ash"
    },
    {
      "x": -17,
      "y": 77,
      "z": 8,
      "name": "Plant_Leaves_Ash"
    },
    {
      "x": -17,
      "y": 78,
      "z": 8,
      "name": "Plant_Leaves_Ash"
    },
    {
      "x": -17,
      "y": 77,
      "z": 9,
      "name": "Plant_Leaves_Ash"
    },
    {
      "x": -17,
      "y": 78,
      "z": 9,
      "name": "Plant_Leaves_Ash"
    },
    {
      "x": -17,
      "y": 77,
      "z": 10,
      "name": "Plant_Leaves_Ash"
    },
    {
      "x": -17,
      "y": 77,
      "z": 11,
      "name": "Plant_Leaves_Ash"
    },
    {
      "x": -16,
      "y": 77,
      "z": -12,
      "name": "Plant_Leaves_Ash"
    },
    {
      "x": -16,
      "y": 77,
      "z": -11,
      "name": "Plant_Leaves_Ash"
    },
    {
      "x": -16,
      "y": 77,
      "z": -10,
      "name": "Plant_Leaves_Ash"
    },
    {
      "x": -16,
      "y": 78,
      "z": -10,
      "name": "Plant_Leaves_Ash"
    },
    {
      "x": -16,
      "y": 77,
      "z": -9,
      "name": "Plant_Leaves_Ash"
    },
    {
      "x": -16,
      "y": 78,
      "z": -9,
      "name": "Plant_Leaves_Ash"
    },
    {
      "x": -16,
      "y": 77,
      "z": -8,
      "name": "Plant_Leaves_Ash"
    },
    {
      "x": -16,
      "y": 78,
      "z": -8,
      "name": "Plant_Leaves_Ash"
    },
    {
      "x": -16,
      "y": 77,
      "z": -7,
      "name": "Plant_Leaves_Ash"
    },
    {
      "x": -16,
      "y": 78,
      "z": -7,
      "name": "Plant_Leaves_Ash"
    },
    {
      "x": -16,
      "y": 78,
      "z": -6,
      "name": "Plant_Leaves_Ash"
    },
    {
      "x": -16,
      "y": 79,
      "z": -6,
      "name": "Plant_Leaves_Ash"
    },
    {
      "x": -16,
      "y": 78,
      "z": -5,
      "name": "Plant_Leaves_Ash"
    },
    {
      "x": -16,
      "y": 79,
      "z": -5,
      "name": "Plant_Leaves_Ash"
    },
    {
      "x": -16,
      "y": 78,
      "z": -4,
      "name": "Plant_Leaves_Ash"
    },
    {
      "x": -16,
      "y": 79,
      "z": -4,
      "name": "Plant_Leaves_Ash"
    },
    {
      "x": -16,
      "y": 78,
      "z": -3,
      "name": "Plant_Leaves_Ash"
    },
    {
      "x": -16,
      "y": 79,
      "z": -3,
      "name": "Plant_Leaves_Ash"
    },
    {
      "x": -16,
      "y": 78,
      "z": -2,
      "name": "Plant_Leaves_Ash"
    },
    {
      "x": -16,
      "y": 79,
      "z": -2,
      "name": "Plant_Leaves_Ash"
    },
    {
      "x": -16,
      "y": 78,
      "z": -1,
      "name": "Plant_Leaves_Ash"
    },
    {
      "x": -16,
      "y": 79,
      "z": -1,
      "name": "Plant_Leaves_Ash"
    },
    {
      "x": -16,
      "y": 78,
      "z": 0,
      "name": "Plant_Leaves_Ash"
    },
    {
      "x": -16,
      "y": 79,
      "z": 0,
      "name": "Plant_Leaves_Ash"
    },
    {
      "x": -16,
      "y": 78,
      "z": 1,
      "name": "Plant_Leaves_Ash"
    },
    {
      "x": -16,
      "y": 79,
      "z": 1,
      "name": "Plant_Leaves_Ash"
    },
    {
      "x": -16,
      "y": 78,
      "z": 2,
      "name": "Plant_Leaves_Ash"
    },
    {
      "x": -16,
      "y": 79,
      "z": 2,
      "name": "Plant_Leaves_Ash"
    },
    {
      "x": -16,
      "y": 78,
      "z": 3,
      "name": "Plant_Leaves_Ash"
    },
    {
      "x": -16,
      "y": 79,
      "z": 3,
      "name": "Plant_Leaves_Ash"
    },
    {
      "x": -16,
      "y": 78,
      "z": 4,
      "name": "Plant_Leaves_Ash"
    },
    {
      "x": -16,
      "y": 79,
      "z": 4,
      "name": "Plant_Leaves_Ash"
    },
    {
      "x": -16,
      "y": 78,
      "z": 5,
      "name": "Plant_Leaves_Ash"
    },
    {
      "x": -16,
      "y": 79,
      "z": 5,
      "name": "Plant_Leaves_Ash"
    },
    {
      "x": -16,
      "y": 78,
      "z": 6,
      "name": "Plant_Leaves_Ash"
    },
    {
      "x": -16,
      "y": 79,
      "z": 6,
      "name": "Plant_Leaves_Ash"
    },
    {
      "x": -16,
      "y": 77,
      "z": 7,
      "name": "Plant_Leaves_Ash"
    },
    {
      "x": -16,
      "y": 78,
      "z": 7,
      "name": "Plant_Leaves_Ash"
    },
    {
      "x": -16,
      "y": 77,
      "z": 8,
      "name": "Plant_Leaves_Ash"
    },
    {
      "x": -16,
      "y": 78,
      "z": 8,
      "name": "Plant_Leaves_Ash"
    },
    {
      "x": -16,
      "y": 77,
      "z": 9,
      "name": "Plant_Leaves_Ash"
    },
    {
      "x": -16,
      "y": 78,
      "z": 9,
      "name": "Plant_Leaves_Ash"
    },
    {
      "x": -16,
      "y": 77,
      "z": 10,
      "name": "Plant_Leaves_Ash"
    },
    {
      "x": -16,
      "y": 78,
      "z": 10,
      "name": "Plant_Leaves_Ash"
    },
    {
      "x": -16,
      "y": 77,
      "z": 11,
      "name": "Plant_Leaves_Ash"
    },
    {
      "x": -16,
      "y": 77,
      "z": 12,
      "name": "Plant_Leaves_Ash"
    },
    {
      "x": -15,
      "y": 77,
      "z": -13,
      "name": "Plant_Leaves_Ash"
    },
    {
      "x": -15,
      "y": 77,
      "z": -12,
      "name": "Plant_Leaves_Ash"
    },
    {
      "x": -15,
      "y": 78,
      "z": -12,
      "name": "Plant_Leaves_Ash"
    },
    {
      "x": -15,
      "y": 77,
      "z": -11,
      "name": "Plant_Leaves_Ash"
    },
    {
      "x": -15,
      "y": 78,
      "z": -11,
      "name": "Plant_Leaves_Ash"
    },
    {
      "x": -15,
      "y": 77,
      "z": -10,
      "name": "Plant_Leaves_Ash"
    },
    {
      "x": -15,
      "y": 78,
      "z": -10,
      "name": "Plant_Leaves_Ash"
    },
    {
      "x": -15,
      "y": 77,
      "z": -9,
      "name": "Plant_Leaves_Ash"
    },
    {
      "x": -15,
      "y": 78,
      "z": -9,
      "name": "Plant_Leaves_Ash"
    },
    {
      "x": -15,
      "y": 78,
      "z": -8,
      "name": "Plant_Leaves_Ash"
    },
    {
      "x": -15,
      "y": 79,
      "z": -8,
      "name": "Plant_Leaves_Ash"
    },
    {
      "x": -15,
      "y": 78,
      "z": -7,
      "name": "Plant_Leaves_Ash"
    },
    {
      "x": -15,
      "y": 79,
      "z": -7,
      "name": "Plant_Leaves_Ash"
    },
    {
      "x": -15,
      "y": 78,
      "z": -6,
      "name": "Plant_Leaves_Ash"
    },
    {
      "x": -15,
      "y": 79,
      "z": -6,
      "name": "Plant_Leaves_Ash"
    },
    {
      "x": -15,
      "y": 78,
      "z": -5,
      "name": "Plant_Leaves_Ash"
    },
    {
      "x": -15,
      "y": 79,
      "z": -5,
      "name": "Plant_Leaves_Ash"
    },
    {
      "x": -15,
      "y": 78,
      "z": -4,
      "name": "Plant_Leaves_Ash"
    },
    {
      "x": -15,
      "y": 79,
      "z": -4,
      "name": "Plant_Leaves_Ash"
    },
    {
      "x": -15,
      "y": 79,
      "z": -3,
      "name": "Plant_Leaves_Ash"
    },
    {
      "x": -15,
      "y": 79,
      "z": -2,
      "name": "Plant_Leaves_Ash"
    },
    {
      "x": -15,
      "y": 79,
      "z": -1,
      "name": "Plant_Leaves_Ash"
    },
    {
      "x": -15,
      "y": 79,
      "z": 0,
      "name": "Plant_Leaves_Ash"
    },
    {
      "x": -15,
      "y": 79,
      "z": 1,
      "name": "Plant_Leaves_Ash"
    },
    {
      "x": -15,
      "y": 79,
      "z": 2,
      "name": "Plant_Leaves_Ash"
    },
    {
      "x": -15,
      "y": 79,
      "z": 3,
      "name": "Plant_Leaves_Ash"
    },
    {
      "x": -15,
      "y": 78,
      "z": 4,
      "name": "Plant_Leaves_Ash"
    },
    {
      "x": -15,
      "y": 79,
      "z": 4,
      "name": "Plant_Leaves_Ash"
    },
    {
      "x": -15,
      "y": 78,
      "z": 5,
      "name": "Plant_Leaves_Ash"
    },
    {
      "x": -15,
      "y": 79,
      "z": 5,
      "name": "Plant_Leaves_Ash"
    },
    {
      "x": -15,
      "y": 78,
      "z": 6,
      "name": "Plant_Leaves_Ash"
    },
    {
      "x": -15,
      "y": 79,
      "z": 6,
      "name": "Plant_Leaves_Ash"
    },
    {
      "x": -15,
      "y": 78,
      "z": 7,
      "name": "Plant_Leaves_Ash"
    },
    {
      "x": -15,
      "y": 79,
      "z": 7,
      "name": "Plant_Leaves_Ash"
    },
    {
      "x": -15,
      "y": 78,
      "z": 8,
      "name": "Plant_Leaves_Ash"
    },
    {
      "x": -15,
      "y": 79,
      "z": 8,
      "name": "Plant_Leaves_Ash"
    },
    {
      "x": -15,
      "y": 77,
      "z": 9,
      "name": "Plant_Leaves_Ash"
    },
    {
      "x": -15,
      "y": 78,
      "z": 9,
      "name": "Plant_Leaves_Ash"
    },
    {
      "x": -15,
      "y": 77,
      "z": 10,
      "name": "Plant_Leaves_Ash"
    },
    {
      "x": -15,
      "y": 78,
      "z": 10,
      "name": "Plant_Leaves_Ash"
    },
    {
      "x": -15,
      "y": 77,
      "z": 11,
      "name": "Plant_Leaves_Ash"
    },
    {
      "x": -15,
      "y": 78,
      "z": 11,
      "name": "Plant_Leaves_Ash"
    },
    {
      "x": -15,
      "y": 77,
      "z": 12,
      "name": "Plant_Leaves_Ash"
    },
    {
      "x": -15,
      "y": 78,
      "z": 12,
      "name": "Plant_Leaves_Ash"
    },
    {
      "x": -15,
      "y": 77,
      "z": 13,
      "name": "Plant_Leaves_Ash"
    },
    {
      "x": -14,
      "y": 77,
      "z": -14,
      "name": "Plant_Leaves_Ash"
    },
    {
      "x": -14,
      "y": 77,
      "z": -13,
      "name": "Plant_Leaves_Ash"
    },
    {
      "x": -14,
      "y": 78,
      "z": -13,
      "name": "Plant_Leaves_Ash"
    },
    {
      "x": -14,
      "y": 77,
      "z": -12,
      "name": "Plant_Leaves_Ash"
    },
    {
      "x": -14,
      "y": 78,
      "z": -12,
      "name": "Plant_Leaves_Ash"
    },
    {
      "x": -14,
      "y": 77,
      "z": -11,
      "name": "Plant_Leaves_Ash"
    },
    {
      "x": -14,
      "y": 78,
      "z": -11,
      "name": "Plant_Leaves_Ash"
    },
    {
      "x": -14,
      "y": 78,
      "z": -10,
      "name": "Plant_Leaves_Ash"
    },
    {
      "x": -14,
      "y": 79,
      "z": -10,
      "name": "Plant_Leaves_Ash"
    },
    {
      "x": -14,
      "y": 78,
      "z": -9,
      "name": "Plant_Leaves_Ash"
    },
    {
      "x": -14,
      "y": 79,
      "z": -9,
      "name": "Plant_Leaves_Ash"
    },
    {
      "x": -14,
      "y": 78,
      "z": -8,
      "name": "Plant_Leaves_Ash"
    },
    {
      "x": -14,
      "y": 79,
      "z": -8,
      "name": "Plant_Leaves_Ash"
    },
    {
      "x": -14,
      "y": 78,
      "z": -7,
      "name": "Plant_Leaves_Ash"
    },
    {
      "x": -14,
      "y": 79,
      "z": -7,
      "name": "Plant_Leaves_Ash"
    },
    {
      "x": -14,
      "y": 79,
      "z": -6,
      "name": "Plant_Leaves_Ash"
    },
    {
      "x": -14,
      "y": 79,
      "z": -5,
      "name": "Plant_Leaves_Ash"
    },
    {
      "x": -14,
      "y": 79,
      "z": -4,
      "name": "Plant_Leaves_Ash"
    },
    {
      "x": -14,
      "y": 79,
      "z": -3,
      "name": "Plant_Leaves_Ash"
    },
    {
      "x": -14,
      "y": 79,
      "z": -2,
      "name": "Plant_Leaves_Ash"
    },
    {
      "x": -14,
      "y": 79,
      "z": -1,
      "name": "Plant_Leaves_Ash"
    },
    {
      "x": -14,
      "y": 79,
      "z": 0,
      "name": "Plant_Leaves_Ash"
    },
    {
      "x": -14,
      "y": 79,
      "z": 1,
      "name": "Plant_Leaves_Ash"
    },
    {
      "x": -14,
      "y": 79,
      "z": 2,
      "name": "Plant_Leaves_Ash"
    },
    {
      "x": -14,
      "y": 79,
      "z": 3,
      "name": "Plant_Leaves_Ash"
    },
    {
      "x": -14,
      "y": 79,
      "z": 4,
      "name": "Plant_Leaves_Ash"
    },
    {
      "x": -14,
      "y": 79,
      "z": 5,
      "name": "Plant_Leaves_Ash"
    },
    {
      "x": -14,
      "y": 79,
      "z": 6,
      "name": "Plant_Leaves_Ash"
    },
    {
      "x": -14,
      "y": 78,
      "z": 7,
      "name": "Plant_Leaves_Ash"
    },
    {
      "x": -14,
      "y": 79,
      "z": 7,
      "name": "Plant_Leaves_Ash"
    },
    {
      "x": -14,
      "y": 78,
      "z": 8,
      "name": "Plant_Leaves_Ash"
    },
    {
      "x": -14,
      "y": 79,
      "z": 8,
      "name": "Plant_Leaves_Ash"
    },
    {
      "x": -14,
      "y": 78,
      "z": 9,
      "name": "Plant_Leaves_Ash"
    },
    {
      "x": -14,
      "y": 79,
      "z": 9,
      "name": "Plant_Leaves_Ash"
    },
    {
      "x": -14,
      "y": 78,
      "z": 10,
      "name": "Plant_Leaves_Ash"
    },
    {
      "x": -14,
      "y": 79,
      "z": 10,
      "name": "Plant_Leaves_Ash"
    },
    {
      "x": -14,
      "y": 77,
      "z": 11,
      "name": "Plant_Leaves_Ash"
    },
    {
      "x": -14,
      "y": 78,
      "z": 11,
      "name": "Plant_Leaves_Ash"
    },
    {
      "x": -14,
      "y": 77,
      "z": 12,
      "name": "Plant_Leaves_Ash"
    },
    {
      "x": -14,
      "y": 78,
      "z": 12,
      "name": "Plant_Leaves_Ash"
    },
    {
      "x": -14,
      "y": 77,
      "z": 13,
      "name": "Plant_Leaves_Ash"
    },
    {
      "x": -14,
      "y": 78,
      "z": 13,
      "name": "Plant_Leaves_Ash"
    },
    {
      "x": -14,
      "y": 77,
      "z": 14,
      "name": "Plant_Leaves_Ash"
    },
    {
      "x": -13,
      "y": 77,
      "z": -15,
      "name": "Plant_Leaves_Ash"
    },
    {
      "x": -13,
      "y": 77,
      "z": -14,
      "name": "Plant_Leaves_Ash"
    },
    {
      "x": -13,
      "y": 78,
      "z": -14,
      "name": "Plant_Leaves_Ash"
    },
    {
      "x": -13,
      "y": 77,
      "z": -13,
      "name": "Plant_Leaves_Ash"
    },
    {
      "x": -13,
      "y": 78,
      "z": -13,
      "name": "Plant_Leaves_Ash"
    },
    {
      "x": -13,
      "y": 77,
      "z": -12,
      "name": "Plant_Leaves_Ash"
    },
    {
      "x": -13,
      "y": 78,
      "z": -12,
      "name": "Plant_Leaves_Ash"
    },
    {
      "x": -13,
      "y": 78,
      "z": -11,
      "name": "Plant_Leaves_Ash"
    },
    {
      "x": -13,
      "y": 79,
      "z": -11,
      "name": "Plant_Leaves_Ash"
    },
    {
      "x": -13,
      "y": 78,
      "z": -10,
      "name": "Plant_Leaves_Ash"
    },
    {
      "x": -13,
      "y": 79,
      "z": -10,
      "name": "Plant_Leaves_Ash"
    },
    {
      "x": -13,
      "y": 78,
      "z": -9,
      "name": "Plant_Leaves_Ash"
    },
    {
      "x": -13,
      "y": 79,
      "z": -9,
      "name": "Plant_Leaves_Ash"
    },
    {
      "x": -13,
      "y": 79,
      "z": -8,
      "name": "Plant_Leaves_Ash"
    },
    {
      "x": -13,
      "y": 79,
      "z": -7,
      "name": "Plant_Leaves_Ash"
    },
    {
      "x": -13,
      "y": 79,
      "z": -6,
      "name": "Plant_Leaves_Ash"
    },
    {
      "x": -13,
      "y": 79,
      "z": -5,
      "name": "Plant_Leaves_Ash"
    },
    {
      "x": -13,
      "y": 79,
      "z": -4,
      "name": "Plant_Leaves_Ash"
    },
    {
      "x": -13,
      "y": 79,
      "z": -3,
      "name": "Plant_Leaves_Ash"
    },
    {
      "x": -13,
      "y": 80,
      "z": -3,
      "name": "Plant_Leaves_Ash"
    },
    {
      "x": -13,
      "y": 79,
      "z": -2,
      "name": "Plant_Leaves_Ash"
    },
    {
      "x": -13,
      "y": 80,
      "z": -2,
      "name": "Plant_Leaves_Ash"
    },
    {
      "x": -13,
      "y": 79,
      "z": -1,
      "name": "Plant_Leaves_Ash"
    },
    {
      "x": -13,
      "y": 80,
      "z": -1,
      "name": "Plant_Leaves_Ash"
    },
    {
      "x": -13,
      "y": 79,
      "z": 0,
      "name": "Plant_Leaves_Ash"
    },
    {
      "x": -13,
      "y": 80,
      "z": 0,
      "name": "Plant_Leaves_Ash"
    },
    {
      "x": -13,
      "y": 79,
      "z": 1,
      "name": "Plant_Leaves_Ash"
    },
    {
      "x": -13,
      "y": 80,
      "z": 1,
      "name": "Plant_Leaves_Ash"
    },
    {
      "x": -13,
      "y": 79,
      "z": 2,
      "name": "Plant_Leaves_Ash"
    },
    {
      "x": -13,
      "y": 80,
      "z": 2,
      "name": "Plant_Leaves_Ash"
    },
    {
      "x": -13,
      "y": 79,
      "z": 3,
      "name": "Plant_Leaves_Ash"
    },
    {
      "x": -13,
      "y": 80,
      "z": 3,
      "name": "Plant_Leaves_Ash"
    },
    {
      "x": -13,
      "y": 79,
      "z": 4,
      "name": "Plant_Leaves_Ash"
    },
    {
      "x": -13,
      "y": 79,
      "z": 5,
      "name": "Plant_Leaves_Ash"
    },
    {
      "x": -13,
      "y": 79,
      "z": 6,
      "name": "Plant_Leaves_Ash"
    },
    {
      "x": -13,
      "y": 79,
      "z": 7,
      "name": "Plant_Leaves_Ash"
    },
    {
      "x": -13,
      "y": 79,
      "z": 8,
      "name": "Plant_Leaves_Ash"
    },
    {
      "x": -13,
      "y": 78,
      "z": 9,
      "name": "Plant_Leaves_Ash"
    },
    {
      "x": -13,
      "y": 79,
      "z": 9,
      "name": "Plant_Leaves_Ash"
    },
    {
      "x": -13,
      "y": 78,
      "z": 10,
      "name": "Plant_Leaves_Ash"
    },
    {
      "x": -13,
      "y": 79,
      "z": 10,
      "name": "Plant_Leaves_Ash"
    },
    {
      "x": -13,
      "y": 78,
      "z": 11,
      "name": "Plant_Leaves_Ash"
    },
    {
      "x": -13,
      "y": 79,
      "z": 11,
      "name": "Plant_Leaves_Ash"
    },
    {
      "x": -13,
      "y": 77,
      "z": 12,
      "name": "Plant_Leaves_Ash"
    },
    {
      "x": -13,
      "y": 78,
      "z": 12,
      "name": "Plant_Leaves_Ash"
    },
    {
      "x": -13,
      "y": 77,
      "z": 13,
      "name": "Plant_Leaves_Ash"
    },
    {
      "x": -13,
      "y": 78,
      "z": 13,
      "name": "Plant_Leaves_Ash"
    },
    {
      "x": -13,
      "y": 77,
      "z": 14,
      "name": "Plant_Leaves_Ash"
    },
    {
      "x": -13,
      "y": 78,
      "z": 14,
      "name": "Plant_Leaves_Ash"
    },
    {
      "x": -13,
      "y": 77,
      "z": 15,
      "name": "Plant_Leaves_Ash"
    },
    {
      "x": -12,
      "y": 77,
      "z": -16,
      "name": "Plant_Leaves_Ash"
    },
    {
      "x": -12,
      "y": 77,
      "z": -15,
      "name": "Plant_Leaves_Ash"
    },
    {
      "x": -12,
      "y": 78,
      "z": -15,
      "name": "Plant_Leaves_Ash"
    },
    {
      "x": -12,
      "y": 77,
      "z": -14,
      "name": "Plant_Leaves_Ash"
    },
    {
      "x": -12,
      "y": 78,
      "z": -14,
      "name": "Plant_Leaves_Ash"
    },
    {
      "x": -12,
      "y": 77,
      "z": -13,
      "name": "Plant_Leaves_Ash"
    },
    {
      "x": -12,
      "y": 78,
      "z": -13,
      "name": "Plant_Leaves_Ash"
    },
    {
      "x": -12,
      "y": 78,
      "z": -12,
      "name": "Plant_Leaves_Ash"
    },
    {
      "x": -12,
      "y": 79,
      "z": -12,
      "name": "Plant_Leaves_Ash"
    },
    {
      "x": -12,
      "y": 78,
      "z": -11,
      "name": "Plant_Leaves_Ash"
    },
    {
      "x": -12,
      "y": 79,
      "z": -11,
      "name": "Plant_Leaves_Ash"
    },
    {
      "x": -12,
      "y": 78,
      "z": -10,
      "name": "Plant_Leaves_Ash"
    },
    {
      "x": -12,
      "y": 79,
      "z": -10,
      "name": "Plant_Leaves_Ash"
    },
    {
      "x": -12,
      "y": 79,
      "z": -9,
      "name": "Plant_Leaves_Ash"
    },
    {
      "x": -12,
      "y": 79,
      "z": -8,
      "name": "Plant_Leaves_Ash"
    },
    {
      "x": -12,
      "y": 79,
      "z": -7,
      "name": "Plant_Leaves_Ash"
    },
    {
      "x": -12,
      "y": 79,
      "z": -6,
      "name": "Plant_Leaves_Ash"
    },
    {
      "x": -12,
      "y": 79,
      "z": -5,
      "name": "Plant_Leaves_Ash"
    },
    {
      "x": -12,
      "y": 80,
      "z": -5,
      "name": "Plant_Leaves_Ash"
    },
    {
      "x": -12,
      "y": 79,
      "z": -4,
      "name": "Plant_Leaves_Ash"
    },
    {
      "x": -12,
      "y": 80,
      "z": -4,
      "name": "Plant_Leaves_Ash"
    },
    {
      "x": -12,
      "y": 79,
      "z": -3,
      "name": "Plant_Leaves_Ash"
    },
    {
      "x": -12,
      "y": 80,
      "z": -3,
      "name": "Plant_Leaves_Ash"
    },
    {
      "x": -12,
      "y": 79,
      "z": -2,
      "name": "Plant_Leaves_Ash"
    },
    {
      "x": -12,
      "y": 80,
      "z": -2,
      "name": "Plant_Leaves_Ash"
    },
    {
      "x": -12,
      "y": 79,
      "z": -1,
      "name": "Plant_Leaves_Ash"
    },
    {
      "x": -12,
      "y": 80,
      "z": -1,
      "name": "Plant_Leaves_Ash"
    },
    {
      "x": -12,
      "y": 79,
      "z": 0,
      "name": "Plant_Leaves_Ash"
    },
    {
      "x": -12,
      "y": 80,
      "z": 0,
      "name": "Plant_Leaves_Ash"
    },
    {
      "x": -12,
      "y": 79,
      "z": 1,
      "name": "Plant_Leaves_Ash"
    },
    {
      "x": -12,
      "y": 80,
      "z": 1,
      "name": "Plant_Leaves_Ash"
    },
    {
      "x": -12,
      "y": 79,
      "z": 2,
      "name": "Plant_Leaves_Ash"
    },
    {
      "x": -12,
      "y": 80,
      "z": 2,
      "name": "Plant_Leaves_Ash"
    },
    {
      "x": -12,
      "y": 79,
      "z": 3,
      "name": "Plant_Leaves_Ash"
    },
    {
      "x": -12,
      "y": 80,
      "z": 3,
      "name": "Plant_Leaves_Ash"
    },
    {
      "x": -12,
      "y": 79,
      "z": 4,
      "name": "Plant_Leaves_Ash"
    },
    {
      "x": -12,
      "y": 80,
      "z": 4,
      "name": "Plant_Leaves_Ash"
    },
    {
      "x": -12,
      "y": 79,
      "z": 5,
      "name": "Plant_Leaves_Ash"
    },
    {
      "x": -12,
      "y": 80,
      "z": 5,
      "name": "Plant_Leaves_Ash"
    },
    {
      "x": -12,
      "y": 79,
      "z": 6,
      "name": "Plant_Leaves_Ash"
    },
    {
      "x": -12,
      "y": 79,
      "z": 7,
      "name": "Plant_Leaves_Ash"
    },
    {
      "x": -12,
      "y": 79,
      "z": 8,
      "name": "Plant_Leaves_Ash"
    },
    {
      "x": -12,
      "y": 79,
      "z": 9,
      "name": "Plant_Leaves_Ash"
    },
    {
      "x": -12,
      "y": 78,
      "z": 10,
      "name": "Plant_Leaves_Ash"
    },
    {
      "x": -12,
      "y": 79,
      "z": 10,
      "name": "Plant_Leaves_Ash"
    },
    {
      "x": -12,
      "y": 78,
      "z": 11,
      "name": "Plant_Leaves_Ash"
    },
    {
      "x": -12,
      "y": 79,
      "z": 11,
      "name": "Plant_Leaves_Ash"
    },
    {
      "x": -12,
      "y": 78,
      "z": 12,
      "name": "Plant_Leaves_Ash"
    },
    {
      "x": -12,
      "y": 79,
      "z": 12,
      "name": "Plant_Leaves_Ash"
    },
    {
      "x": -12,
      "y": 77,
      "z": 13,
      "name": "Plant_Leaves_Ash"
    },
    {
      "x": -12,
      "y": 78,
      "z": 13,
      "name": "Plant_Leaves_Ash"
    },
    {
      "x": -12,
      "y": 77,
      "z": 14,
      "name": "Plant_Leaves_Ash"
    },
    {
      "x": -12,
      "y": 78,
      "z": 14,
      "name": "Plant_Leaves_Ash"
    },
    {
      "x": -12,
      "y": 77,
      "z": 15,
      "name": "Plant_Leaves_Ash"
    },
    {
      "x": -12,
      "y": 78,
      "z": 15,
      "name": "Plant_Leaves_Ash"
    },
    {
      "x": -12,
      "y": 77,
      "z": 16,
      "name": "Plant_Leaves_Ash"
    },
    {
      "x": -11,
      "y": 77,
      "z": -17,
      "name": "Plant_Leaves_Ash"
    },
    {
      "x": -11,
      "y": 77,
      "z": -16,
      "name": "Plant_Leaves_Ash"
    },
    {
      "x": -11,
      "y": 77,
      "z": -15,
      "name": "Plant_Leaves_Ash"
    },
    {
      "x": -11,
      "y": 78,
      "z": -15,
      "name": "Plant_Leaves_Ash"
    },
    {
      "x": -11,
      "y": 77,
      "z": -14,
      "name": "Plant_Leaves_Ash"
    },
    {
      "x": -11,
      "y": 78,
      "z": -14,
      "name": "Plant_Leaves_Ash"
    },
    {
      "x": -11,
      "y": 78,
      "z": -13,
      "name": "Plant_Leaves_Ash"
    },
    {
      "x": -11,
      "y": 79,
      "z": -13,
      "name": "Plant_Leaves_Ash"
    },
    {
      "x": -11,
      "y": 78,
      "z": -12,
      "name": "Plant_Leaves_Ash"
    },
    {
      "x": -11,
      "y": 79,
      "z": -12,
      "name": "Plant_Leaves_Ash"
    },
    {
      "x": -11,
      "y": 78,
      "z": -11,
      "name": "Plant_Leaves_Ash"
    },
    {
      "x": -11,
      "y": 79,
      "z": -11,
      "name": "Plant_Leaves_Ash"
    },
    {
      "x": -11,
      "y": 79,
      "z": -10,
      "name": "Plant_Leaves_Ash"
    },
    {
      "x": -11,
      "y": 79,
      "z": -9,
      "name": "Plant_Leaves_Ash"
    },
    {
      "x": -11,
      "y": 79,
      "z": -8,
      "name": "Plant_Leaves_Ash"
    },
    {
      "x": -11,
      "y": 79,
      "z": -7,
      "name": "Plant_Leaves_Ash"
    },
    {
      "x": -11,
      "y": 80,
      "z": -7,
      "name": "Plant_Leaves_Ash"
    },
    {
      "x": -11,
      "y": 79,
      "z": -6,
      "name": "Plant_Leaves_Ash"
    },
    {
      "x": -11,
      "y": 80,
      "z": -6,
      "name": "Plant_Leaves_Ash"
    },
    {
      "x": -11,
      "y": 79,
      "z": -5,
      "name": "Plant_Leaves_Ash"
    },
    {
      "x": -11,
      "y": 80,
      "z": -5,
      "name": "Plant_Leaves_Ash"
    },
    {
      "x": -11,
      "y": 79,
      "z": -4,
      "name": "Plant_Leaves_Ash"
    },
    {
      "x": -11,
      "y": 80,
      "z": -4,
      "name": "Plant_Leaves_Ash"
    },
    {
      "x": -11,
      "y": 79,
      "z": -3,
      "name": "Plant_Leaves_Ash"
    },
    {
      "x": -11,
      "y": 80,
      "z": -3,
      "name": "Plant_Leaves_Ash"
    },
    {
      "x": -11,
      "y": 79,
      "z": -2,
      "name": "Plant_Leaves_Ash"
    },
    {
      "x": -11,
      "y": 80,
      "z": -2,
      "name": "Plant_Leaves_Ash"
    },
    {
      "x": -11,
      "y": 79,
      "z": -1,
      "name": "Plant_Leaves_Ash"
    },
    {
      "x": -11,
      "y": 80,
      "z": -1,
      "name": "Plant_Leaves_Ash"
    },
    {
      "x": -11,
      "y": 79,
      "z": 0,
      "name": "Plant_Leaves_Ash"
    },
    {
      "x": -11,
      "y": 80,
      "z": 0,
      "name": "Plant_Leaves_Ash"
    },
    {
      "x": -11,
      "y": 79,
      "z": 1,
      "name": "Plant_Leaves_Ash"
    },
    {
      "x": -11,
      "y": 80,
      "z": 1,
      "name": "Plant_Leaves_Ash"
    },
    {
      "x": -11,
      "y": 79,
      "z": 2,
      "name": "Plant_Leaves_Ash"
    },
    {
      "x": -11,
      "y": 80,
      "z": 2,
      "name": "Plant_Leaves_Ash"
    },
    {
      "x": -11,
      "y": 79,
      "z": 3,
      "name": "Plant_Leaves_Ash"
    },
    {
      "x": -11,
      "y": 80,
      "z": 3,
      "name": "Plant_Leaves_Ash"
    },
    {
      "x": -11,
      "y": 79,
      "z": 4,
      "name": "Plant_Leaves_Ash"
    },
    {
      "x": -11,
      "y": 80,
      "z": 4,
      "name": "Plant_Leaves_Ash"
    },
    {
      "x": -11,
      "y": 79,
      "z": 5,
      "name": "Plant_Leaves_Ash"
    },
    {
      "x": -11,
      "y": 80,
      "z": 5,
      "name": "Plant_Leaves_Ash"
    },
    {
      "x": -11,
      "y": 79,
      "z": 6,
      "name": "Plant_Leaves_Ash"
    },
    {
      "x": -11,
      "y": 80,
      "z": 6,
      "name": "Plant_Leaves_Ash"
    },
    {
      "x": -11,
      "y": 79,
      "z": 7,
      "name": "Plant_Leaves_Ash"
    },
    {
      "x": -11,
      "y": 80,
      "z": 7,
      "name": "Plant_Leaves_Ash"
    },
    {
      "x": -11,
      "y": 79,
      "z": 8,
      "name": "Plant_Leaves_Ash"
    },
    {
      "x": -11,
      "y": 79,
      "z": 9,
      "name": "Plant_Leaves_Ash"
    },
    {
      "x": -11,
      "y": 79,
      "z": 10,
      "name": "Plant_Leaves_Ash"
    },
    {
      "x": -11,
      "y": 78,
      "z": 11,
      "name": "Plant_Leaves_Ash"
    },
    {
      "x": -11,
      "y": 79,
      "z": 11,
      "name": "Plant_Leaves_Ash"
    },
    {
      "x": -11,
      "y": 78,
      "z": 12,
      "name": "Plant_Leaves_Ash"
    },
    {
      "x": -11,
      "y": 79,
      "z": 12,
      "name": "Plant_Leaves_Ash"
    },
    {
      "x": -11,
      "y": 78,
      "z": 13,
      "name": "Plant_Leaves_Ash"
    },
    {
      "x": -11,
      "y": 79,
      "z": 13,
      "name": "Plant_Leaves_Ash"
    },
    {
      "x": -11,
      "y": 77,
      "z": 14,
      "name": "Plant_Leaves_Ash"
    },
    {
      "x": -11,
      "y": 78,
      "z": 14,
      "name": "Plant_Leaves_Ash"
    },
    {
      "x": -11,
      "y": 77,
      "z": 15,
      "name": "Plant_Leaves_Ash"
    },
    {
      "x": -11,
      "y": 78,
      "z": 15,
      "name": "Plant_Leaves_Ash"
    },
    {
      "x": -11,
      "y": 77,
      "z": 16,
      "name": "Plant_Leaves_Ash"
    },
    {
      "x": -11,
      "y": 77,
      "z": 17,
      "name": "Plant_Leaves_Ash"
    },
    {
      "x": -10,
      "y": 77,
      "z": -17,
      "name": "Plant_Leaves_Ash"
    },
    {
      "x": -10,
      "y": 77,
      "z": -16,
      "name": "Plant_Leaves_Ash"
    },
    {
      "x": -10,
      "y": 78,
      "z": -16,
      "name": "Plant_Leaves_Ash"
    },
    {
      "x": -10,
      "y": 77,
      "z": -15,
      "name": "Plant_Leaves_Ash"
    },
    {
      "x": -10,
      "y": 78,
      "z": -15,
      "name": "Plant_Leaves_Ash"
    },
    {
      "x": -10,
      "y": 78,
      "z": -14,
      "name": "Plant_Leaves_Ash"
    },
    {
      "x": -10,
      "y": 79,
      "z": -14,
      "name": "Plant_Leaves_Ash"
    },
    {
      "x": -10,
      "y": 78,
      "z": -13,
      "name": "Plant_Leaves_Ash"
    },
    {
      "x": -10,
      "y": 79,
      "z": -13,
      "name": "Plant_Leaves_Ash"
    },
    {
      "x": -10,
      "y": 78,
      "z": -12,
      "name": "Plant_Leaves_Ash"
    },
    {
      "x": -10,
      "y": 79,
      "z": -12,
      "name": "Plant_Leaves_Ash"
    },
    {
      "x": -10,
      "y": 79,
      "z": -11,
      "name": "Plant_Leaves_Ash"
    },
    {
      "x": -10,
      "y": 79,
      "z": -10,
      "name": "Plant_Leaves_Ash"
    },
    {
      "x": -10,
      "y": 79,
      "z": -9,
      "name": "Plant_Leaves_Ash"
    },
    {
      "x": -10,
      "y": 79,
      "z": -8,
      "name": "Plant_Leaves_Ash"
    },
    {
      "x": -10,
      "y": 80,
      "z": -8,
      "name": "Plant_Leaves_Ash"
    },
    {
      "x": -10,
      "y": 79,
      "z": -7,
      "name": "Plant_Leaves_Ash"
    },
    {
      "x": -10,
      "y": 80,
      "z": -7,
      "name": "Plant_Leaves_Ash"
    },
    {
      "x": -10,
      "y": 79,
      "z": -6,
      "name": "Plant_Leaves_Ash"
    },
    {
      "x": -10,
      "y": 80,
      "z": -6,
      "name": "Plant_Leaves_Ash"
    },
    {
      "x": -10,
      "y": 79,
      "z": -5,
      "name": "Plant_Leaves_Ash"
    },
    {
      "x": -10,
      "y": 80,
      "z": -5,
      "name": "Plant_Leaves_Ash"
    },
    {
      "x": -10,
      "y": 79,
      "z": -4,
      "name": "Plant_Leaves_Ash"
    },
    {
      "x": -10,
      "y": 80,
      "z": -4,
      "name": "Plant_Leaves_Ash"
    },
    {
      "x": -10,
      "y": 79,
      "z": -3,
      "name": "Plant_Leaves_Ash"
    },
    {
      "x": -10,
      "y": 80,
      "z": -3,
      "name": "Plant_Leaves_Ash"
    },
    {
      "x": -10,
      "y": 79,
      "z": -2,
      "name": "Plant_Leaves_Ash"
    },
    {
      "x": -10,
      "y": 80,
      "z": -2,
      "name": "Plant_Leaves_Ash"
    },
    {
      "x": -10,
      "y": 79,
      "z": -1,
      "name": "Plant_Leaves_Ash"
    },
    {
      "x": -10,
      "y": 80,
      "z": -1,
      "name": "Plant_Leaves_Ash"
    },
    {
      "x": -10,
      "y": 79,
      "z": 0,
      "name": "Plant_Leaves_Ash"
    },
    {
      "x": -10,
      "y": 80,
      "z": 0,
      "name": "Plant_Leaves_Ash"
    },
    {
      "x": -10,
      "y": 79,
      "z": 1,
      "name": "Plant_Leaves_Ash"
    },
    {
      "x": -10,
      "y": 80,
      "z": 1,
      "name": "Plant_Leaves_Ash"
    },
    {
      "x": -10,
      "y": 79,
      "z": 2,
      "name": "Plant_Leaves_Ash"
    },
    {
      "x": -10,
      "y": 80,
      "z": 2,
      "name": "Plant_Leaves_Ash"
    },
    {
      "x": -10,
      "y": 79,
      "z": 3,
      "name": "Plant_Leaves_Ash"
    },
    {
      "x": -10,
      "y": 80,
      "z": 3,
      "name": "Plant_Leaves_Ash"
    },
    {
      "x": -10,
      "y": 79,
      "z": 4,
      "name": "Plant_Leaves_Ash"
    },
    {
      "x": -10,
      "y": 80,
      "z": 4,
      "name": "Plant_Leaves_Ash"
    },
    {
      "x": -10,
      "y": 79,
      "z": 5,
      "name": "Plant_Leaves_Ash"
    },
    {
      "x": -10,
      "y": 80,
      "z": 5,
      "name": "Plant_Leaves_Ash"
    },
    {
      "x": -10,
      "y": 79,
      "z": 6,
      "name": "Plant_Leaves_Ash"
    },
    {
      "x": -10,
      "y": 80,
      "z": 6,
      "name": "Plant_Leaves_Ash"
    },
    {
      "x": -10,
      "y": 79,
      "z": 7,
      "name": "Plant_Leaves_Ash"
    },
    {
      "x": -10,
      "y": 80,
      "z": 7,
      "name": "Plant_Leaves_Ash"
    },
    {
      "x": -10,
      "y": 79,
      "z": 8,
      "name": "Plant_Leaves_Ash"
    },
    {
      "x": -10,
      "y": 80,
      "z": 8,
      "name": "Plant_Leaves_Ash"
    },
    {
      "x": -10,
      "y": 79,
      "z": 9,
      "name": "Plant_Leaves_Ash"
    },
    {
      "x": -10,
      "y": 79,
      "z": 10,
      "name": "Plant_Leaves_Ash"
    },
    {
      "x": -10,
      "y": 79,
      "z": 11,
      "name": "Plant_Leaves_Ash"
    },
    {
      "x": -10,
      "y": 78,
      "z": 12,
      "name": "Plant_Leaves_Ash"
    },
    {
      "x": -10,
      "y": 79,
      "z": 12,
      "name": "Plant_Leaves_Ash"
    },
    {
      "x": -10,
      "y": 78,
      "z": 13,
      "name": "Plant_Leaves_Ash"
    },
    {
      "x": -10,
      "y": 79,
      "z": 13,
      "name": "Plant_Leaves_Ash"
    },
    {
      "x": -10,
      "y": 78,
      "z": 14,
      "name": "Plant_Leaves_Ash"
    },
    {
      "x": -10,
      "y": 79,
      "z": 14,
      "name": "Plant_Leaves_Ash"
    },
    {
      "x": -10,
      "y": 77,
      "z": 15,
      "name": "Plant_Leaves_Ash"
    },
    {
      "x": -10,
      "y": 78,
      "z": 15,
      "name": "Plant_Leaves_Ash"
    },
    {
      "x": -10,
      "y": 77,
      "z": 16,
      "name": "Plant_Leaves_Ash"
    },
    {
      "x": -10,
      "y": 78,
      "z": 16,
      "name": "Plant_Leaves_Ash"
    },
    {
      "x": -10,
      "y": 77,
      "z": 17,
      "name": "Plant_Leaves_Ash"
    },
    {
      "x": -9,
      "y": 77,
      "z": -18,
      "name": "Plant_Leaves_Ash"
    },
    {
      "x": -9,
      "y": 77,
      "z": -17,
      "name": "Plant_Leaves_Ash"
    },
    {
      "x": -9,
      "y": 78,
      "z": -17,
      "name": "Plant_Leaves_Ash"
    },
    {
      "x": -9,
      "y": 77,
      "z": -16,
      "name": "Plant_Leaves_Ash"
    },
    {
      "x": -9,
      "y": 78,
      "z": -16,
      "name": "Plant_Leaves_Ash"
    },
    {
      "x": -9,
      "y": 77,
      "z": -15,
      "name": "Plant_Leaves_Ash"
    },
    {
      "x": -9,
      "y": 78,
      "z": -15,
      "name": "Plant_Leaves_Ash"
    },
    {
      "x": -9,
      "y": 78,
      "z": -14,
      "name": "Plant_Leaves_Ash"
    },
    {
      "x": -9,
      "y": 79,
      "z": -14,
      "name": "Plant_Leaves_Ash"
    },
    {
      "x": -9,
      "y": 78,
      "z": -13,
      "name": "Plant_Leaves_Ash"
    },
    {
      "x": -9,
      "y": 79,
      "z": -13,
      "name": "Plant_Leaves_Ash"
    },
    {
      "x": -9,
      "y": 79,
      "z": -12,
      "name": "Plant_Leaves_Ash"
    },
    {
      "x": -9,
      "y": 79,
      "z": -11,
      "name": "Plant_Leaves_Ash"
    },
    {
      "x": -9,
      "y": 79,
      "z": -10,
      "name": "Plant_Leaves_Ash"
    },
    {
      "x": -9,
      "y": 79,
      "z": -9,
      "name": "Plant_Leaves_Ash"
    },
    {
      "x": -9,
      "y": 80,
      "z": -9,
      "name": "Plant_Leaves_Ash"
    },
    {
      "x": -9,
      "y": 79,
      "z": -8,
      "name": "Plant_Leaves_Ash"
    },
    {
      "x": -9,
      "y": 80,
      "z": -8,
      "name": "Plant_Leaves_Ash"
    },
    {
      "x": -9,
      "y": 79,
      "z": -7,
      "name": "Plant_Leaves_Ash"
    },
    {
      "x": -9,
      "y": 80,
      "z": -7,
      "name": "Plant_Leaves_Ash"
    },
    {
      "x": -9,
      "y": 79,
      "z": -6,
      "name": "Plant_Leaves_Ash"
    },
    {
      "x": -9,
      "y": 80,
      "z": -6,
      "name": "Plant_Leaves_Ash"
    },
    {
      "x": -9,
      "y": 79,
      "z": -5,
      "name": "Plant_Leaves_Ash"
    },
    {
      "x": -9,
      "y": 80,
      "z": -5,
      "name": "Plant_Leaves_Ash"
    },
    {
      "x": -9,
      "y": 79,
      "z": -4,
      "name": "Plant_Leaves_Ash"
    },
    {
      "x": -9,
      "y": 80,
      "z": -4,
      "name": "Plant_Leaves_Ash"
    },
    {
      "x": -9,
      "y": 79,
      "z": -3,
      "name": "Plant_Leaves_Ash"
    },
    {
      "x": -9,
      "y": 80,
      "z": -3,
      "name": "Plant_Leaves_Ash"
    },
    {
      "x": -9,
      "y": 79,
      "z": -2,
      "name": "Plant_Leaves_Ash"
    },
    {
      "x": -9,
      "y": 80,
      "z": -2,
      "name": "Plant_Leaves_Ash"
    },
    {
      "x": -9,
      "y": 79,
      "z": -1,
      "name": "Plant_Leaves_Ash"
    },
    {
      "x": -9,
      "y": 80,
      "z": -1,
      "name": "Plant_Leaves_Ash"
    },
    {
      "x": -9,
      "y": 79,
      "z": 0,
      "name": "Plant_Leaves_Ash"
    },
    {
      "x": -9,
      "y": 80,
      "z": 0,
      "name": "Plant_Leaves_Ash"
    },
    {
      "x": -9,
      "y": 79,
      "z": 1,
      "name": "Plant_Leaves_Ash"
    },
    {
      "x": -9,
      "y": 80,
      "z": 1,
      "name": "Plant_Leaves_Ash"
    },
    {
      "x": -9,
      "y": 79,
      "z": 2,
      "name": "Plant_Leaves_Ash"
    },
    {
      "x": -9,
      "y": 80,
      "z": 2,
      "name": "Plant_Leaves_Ash"
    },
    {
      "x": -9,
      "y": 79,
      "z": 3,
      "name": "Plant_Leaves_Ash"
    },
    {
      "x": -9,
      "y": 80,
      "z": 3,
      "name": "Plant_Leaves_Ash"
    },
    {
      "x": -9,
      "y": 79,
      "z": 4,
      "name": "Plant_Leaves_Ash"
    },
    {
      "x": -9,
      "y": 80,
      "z": 4,
      "name": "Plant_Leaves_Ash"
    },
    {
      "x": -9,
      "y": 79,
      "z": 5,
      "name": "Plant_Leaves_Ash"
    },
    {
      "x": -9,
      "y": 80,
      "z": 5,
      "name": "Plant_Leaves_Ash"
    },
    {
      "x": -9,
      "y": 79,
      "z": 6,
      "name": "Plant_Leaves_Ash"
    },
    {
      "x": -9,
      "y": 80,
      "z": 6,
      "name": "Plant_Leaves_Ash"
    },
    {
      "x": -9,
      "y": 79,
      "z": 7,
      "name": "Plant_Leaves_Ash"
    },
    {
      "x": -9,
      "y": 80,
      "z": 7,
      "name": "Plant_Leaves_Ash"
    },
    {
      "x": -9,
      "y": 79,
      "z": 8,
      "name": "Plant_Leaves_Ash"
    },
    {
      "x": -9,
      "y": 80,
      "z": 8,
      "name": "Plant_Leaves_Ash"
    },
    {
      "x": -9,
      "y": 79,
      "z": 9,
      "name": "Plant_Leaves_Ash"
    },
    {
      "x": -9,
      "y": 80,
      "z": 9,
      "name": "Plant_Leaves_Ash"
    },
    {
      "x": -9,
      "y": 79,
      "z": 10,
      "name": "Plant_Leaves_Ash"
    },
    {
      "x": -9,
      "y": 79,
      "z": 11,
      "name": "Plant_Leaves_Ash"
    },
    {
      "x": -9,
      "y": 79,
      "z": 12,
      "name": "Plant_Leaves_Ash"
    },
    {
      "x": -9,
      "y": 78,
      "z": 13,
      "name": "Plant_Leaves_Ash"
    },
    {
      "x": -9,
      "y": 79,
      "z": 13,
      "name": "Plant_Leaves_Ash"
    },
    {
      "x": -9,
      "y": 78,
      "z": 14,
      "name": "Plant_Leaves_Ash"
    },
    {
      "x": -9,
      "y": 79,
      "z": 14,
      "name": "Plant_Leaves_Ash"
    },
    {
      "x": -9,
      "y": 77,
      "z": 15,
      "name": "Plant_Leaves_Ash"
    },
    {
      "x": -9,
      "y": 78,
      "z": 15,
      "name": "Plant_Leaves_Ash"
    },
    {
      "x": -9,
      "y": 77,
      "z": 16,
      "name": "Plant_Leaves_Ash"
    },
    {
      "x": -9,
      "y": 78,
      "z": 16,
      "name": "Plant_Leaves_Ash"
    },
    {
      "x": -9,
      "y": 77,
      "z": 17,
      "name": "Plant_Leaves_Ash"
    },
    {
      "x": -9,
      "y": 78,
      "z": 17,
      "name": "Plant_Leaves_Ash"
    },
    {
      "x": -9,
      "y": 77,
      "z": 18,
      "name": "Plant_Leaves_Ash"
    },
    {
      "x": -8,
      "y": 77,
      "z": -18,
      "name": "Plant_Leaves_Ash"
    },
    {
      "x": -8,
      "y": 77,
      "z": -17,
      "name": "Plant_Leaves_Ash"
    },
    {
      "x": -8,
      "y": 78,
      "z": -17,
      "name": "Plant_Leaves_Ash"
    },
    {
      "x": -8,
      "y": 77,
      "z": -16,
      "name": "Plant_Leaves_Ash"
    },
    {
      "x": -8,
      "y": 78,
      "z": -16,
      "name": "Plant_Leaves_Ash"
    },
    {
      "x": -8,
      "y": 78,
      "z": -15,
      "name": "Plant_Leaves_Ash"
    },
    {
      "x": -8,
      "y": 79,
      "z": -15,
      "name": "Plant_Leaves_Ash"
    },
    {
      "x": -8,
      "y": 78,
      "z": -14,
      "name": "Plant_Leaves_Ash"
    },
    {
      "x": -8,
      "y": 79,
      "z": -14,
      "name": "Plant_Leaves_Ash"
    },
    {
      "x": -8,
      "y": 79,
      "z": -13,
      "name": "Plant_Leaves_Ash"
    },
    {
      "x": -8,
      "y": 79,
      "z": -12,
      "name": "Plant_Leaves_Ash"
    },
    {
      "x": -8,
      "y": 79,
      "z": -11,
      "name": "Plant_Leaves_Ash"
    },
    {
      "x": -8,
      "y": 79,
      "z": -10,
      "name": "Plant_Leaves_Ash"
    },
    {
      "x": -8,
      "y": 80,
      "z": -10,
      "name": "Plant_Leaves_Ash"
    },
    {
      "x": -8,
      "y": 79,
      "z": -9,
      "name": "Plant_Leaves_Ash"
    },
    {
      "x": -8,
      "y": 80,
      "z": -9,
      "name": "Plant_Leaves_Ash"
    },
    {
      "x": -8,
      "y": 79,
      "z": -8,
      "name": "Plant_Leaves_Ash"
    },
    {
      "x": -8,
      "y": 80,
      "z": -8,
      "name": "Plant_Leaves_Ash"
    },
    {
      "x": -8,
      "y": 79,
      "z": -7,
      "name": "Plant_Leaves_Ash"
    },
    {
      "x": -8,
      "y": 80,
      "z": -7,
      "name": "Plant_Leaves_Ash"
    },
    {
      "x": -8,
      "y": 79,
      "z": -6,
      "name": "Plant_Leaves_Ash"
    },
    {
      "x": -8,
      "y": 80,
      "z": -6,
      "name": "Plant_Leaves_Ash"
    },
    {
      "x": -8,
      "y": 79,
      "z": -5,
      "name": "Plant_Leaves_Ash"
    },
    {
      "x": -8,
      "y": 80,
      "z": -5,
      "name": "Plant_Leaves_Ash"
    },
    {
      "x": -8,
      "y": 79,
      "z": -4,
      "name": "Plant_Leaves_Ash"
    },
    {
      "x": -8,
      "y": 80,
      "z": -4,
      "name": "Plant_Leaves_Ash"
    },
    {
      "x": -8,
      "y": 79,
      "z": -3,
      "name": "Plant_Leaves_Ash"
    },
    {
      "x": -8,
      "y": 80,
      "z": -3,
      "name": "Plant_Leaves_Ash"
    },
    {
      "x": -8,
      "y": 79,
      "z": -2,
      "name": "Plant_Leaves_Ash"
    },
    {
      "x": -8,
      "y": 80,
      "z": -2,
      "name": "Plant_Leaves_Ash"
    },
    {
      "x": -8,
      "y": 79,
      "z": -1,
      "name": "Plant_Leaves_Ash"
    },
    {
      "x": -8,
      "y": 80,
      "z": -1,
      "name": "Plant_Leaves_Ash"
    },
    {
      "x": -8,
      "y": 79,
      "z": 0,
      "name": "Plant_Leaves_Ash"
    },
    {
      "x": -8,
      "y": 80,
      "z": 0,
      "name": "Plant_Leaves_Ash"
    },
    {
      "x": -8,
      "y": 79,
      "z": 1,
      "name": "Plant_Leaves_Ash"
    },
    {
      "x": -8,
      "y": 80,
      "z": 1,
      "name": "Plant_Leaves_Ash"
    },
    {
      "x": -8,
      "y": 79,
      "z": 2,
      "name": "Plant_Leaves_Ash"
    },
    {
      "x": -8,
      "y": 80,
      "z": 2,
      "name": "Plant_Leaves_Ash"
    },
    {
      "x": -8,
      "y": 79,
      "z": 3,
      "name": "Plant_Leaves_Ash"
    },
    {
      "x": -8,
      "y": 80,
      "z": 3,
      "name": "Plant_Leaves_Ash"
    },
    {
      "x": -8,
      "y": 79,
      "z": 4,
      "name": "Plant_Leaves_Ash"
    },
    {
      "x": -8,
      "y": 80,
      "z": 4,
      "name": "Plant_Leaves_Ash"
    },
    {
      "x": -8,
      "y": 79,
      "z": 5,
      "name": "Plant_Leaves_Ash"
    },
    {
      "x": -8,
      "y": 80,
      "z": 5,
      "name": "Plant_Leaves_Ash"
    },
    {
      "x": -8,
      "y": 79,
      "z": 6,
      "name": "Plant_Leaves_Ash"
    },
    {
      "x": -8,
      "y": 80,
      "z": 6,
      "name": "Plant_Leaves_Ash"
    },
    {
      "x": -8,
      "y": 79,
      "z": 7,
      "name": "Plant_Leaves_Ash"
    },
    {
      "x": -8,
      "y": 80,
      "z": 7,
      "name": "Plant_Leaves_Ash"
    },
    {
      "x": -8,
      "y": 79,
      "z": 8,
      "name": "Plant_Leaves_Ash"
    },
    {
      "x": -8,
      "y": 80,
      "z": 8,
      "name": "Plant_Leaves_Ash"
    },
    {
      "x": -8,
      "y": 79,
      "z": 9,
      "name": "Plant_Leaves_Ash"
    },
    {
      "x": -8,
      "y": 80,
      "z": 9,
      "name": "Plant_Leaves_Ash"
    },
    {
      "x": -8,
      "y": 79,
      "z": 10,
      "name": "Plant_Leaves_Ash"
    },
    {
      "x": -8,
      "y": 80,
      "z": 10,
      "name": "Plant_Leaves_Ash"
    },
    {
      "x": -8,
      "y": 79,
      "z": 11,
      "name": "Plant_Leaves_Ash"
    },
    {
      "x": -8,
      "y": 79,
      "z": 12,
      "name": "Plant_Leaves_Ash"
    },
    {
      "x": -8,
      "y": 79,
      "z": 13,
      "name": "Plant_Leaves_Ash"
    },
    {
      "x": -8,
      "y": 78,
      "z": 14,
      "name": "Plant_Leaves_Ash"
    },
    {
      "x": -8,
      "y": 79,
      "z": 14,
      "name": "Plant_Leaves_Ash"
    },
    {
      "x": -8,
      "y": 78,
      "z": 15,
      "name": "Plant_Leaves_Ash"
    },
    {
      "x": -8,
      "y": 79,
      "z": 15,
      "name": "Plant_Leaves_Ash"
    },
    {
      "x": -8,
      "y": 77,
      "z": 16,
      "name": "Plant_Leaves_Ash"
    },
    {
      "x": -8,
      "y": 78,
      "z": 16,
      "name": "Plant_Leaves_Ash"
    },
    {
      "x": -8,
      "y": 77,
      "z": 17,
      "name": "Plant_Leaves_Ash"
    },
    {
      "x": -8,
      "y": 78,
      "z": 17,
      "name": "Plant_Leaves_Ash"
    },
    {
      "x": -8,
      "y": 77,
      "z": 18,
      "name": "Plant_Leaves_Ash"
    },
    {
      "x": -7,
      "y": 77,
      "z": -19,
      "name": "Plant_Leaves_Ash"
    },
    {
      "x": -7,
      "y": 77,
      "z": -18,
      "name": "Plant_Leaves_Ash"
    },
    {
      "x": -7,
      "y": 78,
      "z": -18,
      "name": "Plant_Leaves_Ash"
    },
    {
      "x": -7,
      "y": 77,
      "z": -17,
      "name": "Plant_Leaves_Ash"
    },
    {
      "x": -7,
      "y": 78,
      "z": -17,
      "name": "Plant_Leaves_Ash"
    },
    {
      "x": -7,
      "y": 77,
      "z": -16,
      "name": "Plant_Leaves_Ash"
    },
    {
      "x": -7,
      "y": 78,
      "z": -16,
      "name": "Plant_Leaves_Ash"
    },
    {
      "x": -7,
      "y": 78,
      "z": -15,
      "name": "Plant_Leaves_Ash"
    },
    {
      "x": -7,
      "y": 79,
      "z": -15,
      "name": "Plant_Leaves_Ash"
    },
    {
      "x": -7,
      "y": 78,
      "z": -14,
      "name": "Plant_Leaves_Ash"
    },
    {
      "x": -7,
      "y": 79,
      "z": -14,
      "name": "Plant_Leaves_Ash"
    },
    {
      "x": -7,
      "y": 79,
      "z": -13,
      "name": "Plant_Leaves_Ash"
    },
    {
      "x": -7,
      "y": 79,
      "z": -12,
      "name": "Plant_Leaves_Ash"
    },
    {
      "x": -7,
      "y": 79,
      "z": -11,
      "name": "Plant_Leaves_Ash"
    },
    {
      "x": -7,
      "y": 80,
      "z": -11,
      "name": "Plant_Leaves_Ash"
    },
    {
      "x": -7,
      "y": 79,
      "z": -10,
      "name": "Plant_Leaves_Ash"
    },
    {
      "x": -7,
      "y": 80,
      "z": -10,
      "name": "Plant_Leaves_Ash"
    },
    {
      "x": -7,
      "y": 79,
      "z": -9,
      "name": "Plant_Leaves_Ash"
    },
    {
      "x": -7,
      "y": 80,
      "z": -9,
      "name": "Plant_Leaves_Ash"
    },
    {
      "x": -7,
      "y": 79,
      "z": -8,
      "name": "Plant_Leaves_Ash"
    },
    {
      "x": -7,
      "y": 80,
      "z": -8,
      "name": "Plant_Leaves_Ash"
    },
    {
      "x": -7,
      "y": 79,
      "z": -7,
      "name": "Plant_Leaves_Ash"
    },
    {
      "x": -7,
      "y": 80,
      "z": -7,
      "name": "Plant_Leaves_Ash"
    },
    {
      "x": -7,
      "y": 79,
      "z": -6,
      "name": "Plant_Leaves_Ash"
    },
    {
      "x": -7,
      "y": 80,
      "z": -6,
      "name": "Plant_Leaves_Ash"
    },
    {
      "x": -7,
      "y": 79,
      "z": -5,
      "name": "Plant_Leaves_Ash"
    },
    {
      "x": -7,
      "y": 80,
      "z": -5,
      "name": "Plant_Leaves_Ash"
    },
    {
      "x": -7,
      "y": 79,
      "z": -4,
      "name": "Plant_Leaves_Ash"
    },
    {
      "x": -7,
      "y": 80,
      "z": -4,
      "name": "Plant_Leaves_Ash"
    },
    {
      "x": -7,
      "y": 79,
      "z": -3,
      "name": "Plant_Leaves_Ash"
    },
    {
      "x": -7,
      "y": 80,
      "z": -3,
      "name": "Plant_Leaves_Ash"
    },
    {
      "x": -7,
      "y": 79,
      "z": -2,
      "name": "Plant_Leaves_Ash"
    },
    {
      "x": -7,
      "y": 80,
      "z": -2,
      "name": "Plant_Leaves_Ash"
    },
    {
      "x": -7,
      "y": 79,
      "z": -1,
      "name": "Plant_Leaves_Ash"
    },
    {
      "x": -7,
      "y": 80,
      "z": -1,
      "name": "Plant_Leaves_Ash"
    },
    {
      "x": -7,
      "y": 79,
      "z": 0,
      "name": "Plant_Leaves_Ash"
    },
    {
      "x": -7,
      "y": 80,
      "z": 0,
      "name": "Plant_Leaves_Ash"
    },
    {
      "x": -7,
      "y": 79,
      "z": 1,
      "name": "Plant_Leaves_Ash"
    },
    {
      "x": -7,
      "y": 80,
      "z": 1,
      "name": "Plant_Leaves_Ash"
    },
    {
      "x": -7,
      "y": 79,
      "z": 2,
      "name": "Plant_Leaves_Ash"
    },
    {
      "x": -7,
      "y": 80,
      "z": 2,
      "name": "Plant_Leaves_Ash"
    },
    {
      "x": -7,
      "y": 79,
      "z": 3,
      "name": "Plant_Leaves_Ash"
    },
    {
      "x": -7,
      "y": 80,
      "z": 3,
      "name": "Plant_Leaves_Ash"
    },
    {
      "x": -7,
      "y": 79,
      "z": 4,
      "name": "Plant_Leaves_Ash"
    },
    {
      "x": -7,
      "y": 80,
      "z": 4,
      "name": "Plant_Leaves_Ash"
    },
    {
      "x": -7,
      "y": 79,
      "z": 5,
      "name": "Plant_Leaves_Ash"
    },
    {
      "x": -7,
      "y": 80,
      "z": 5,
      "name": "Plant_Leaves_Ash"
    },
    {
      "x": -7,
      "y": 79,
      "z": 6,
      "name": "Plant_Leaves_Ash"
    },
    {
      "x": -7,
      "y": 80,
      "z": 6,
      "name": "Plant_Leaves_Ash"
    },
    {
      "x": -7,
      "y": 79,
      "z": 7,
      "name": "Plant_Leaves_Ash"
    },
    {
      "x": -7,
      "y": 80,
      "z": 7,
      "name": "Plant_Leaves_Ash"
    },
    {
      "x": -7,
      "y": 79,
      "z": 8,
      "name": "Plant_Leaves_Ash"
    },
    {
      "x": -7,
      "y": 80,
      "z": 8,
      "name": "Plant_Leaves_Ash"
    },
    {
      "x": -7,
      "y": 79,
      "z": 9,
      "name": "Plant_Leaves_Ash"
    },
    {
      "x": -7,
      "y": 80,
      "z": 9,
      "name": "Plant_Leaves_Ash"
    },
    {
      "x": -7,
      "y": 79,
      "z": 10,
      "name": "Plant_Leaves_Ash"
    },
    {
      "x": -7,
      "y": 80,
      "z": 10,
      "name": "Plant_Leaves_Ash"
    },
    {
      "x": -7,
      "y": 79,
      "z": 11,
      "name": "Plant_Leaves_Ash"
    },
    {
      "x": -7,
      "y": 80,
      "z": 11,
      "name": "Plant_Leaves_Ash"
    },
    {
      "x": -7,
      "y": 79,
      "z": 12,
      "name": "Plant_Leaves_Ash"
    },
    {
      "x": -7,
      "y": 79,
      "z": 13,
      "name": "Plant_Leaves_Ash"
    },
    {
      "x": -7,
      "y": 78,
      "z": 14,
      "name": "Plant_Leaves_Ash"
    },
    {
      "x": -7,
      "y": 79,
      "z": 14,
      "name": "Plant_Leaves_Ash"
    },
    {
      "x": -7,
      "y": 78,
      "z": 15,
      "name": "Plant_Leaves_Ash"
    },
    {
      "x": -7,
      "y": 79,
      "z": 15,
      "name": "Plant_Leaves_Ash"
    },
    {
      "x": -7,
      "y": 77,
      "z": 16,
      "name": "Plant_Leaves_Ash"
    },
    {
      "x": -7,
      "y": 78,
      "z": 16,
      "name": "Plant_Leaves_Ash"
    },
    {
      "x": -7,
      "y": 77,
      "z": 17,
      "name": "Plant_Leaves_Ash"
    },
    {
      "x": -7,
      "y": 78,
      "z": 17,
      "name": "Plant_Leaves_Ash"
    },
    {
      "x": -7,
      "y": 77,
      "z": 18,
      "name": "Plant_Leaves_Ash"
    },
    {
      "x": -7,
      "y": 78,
      "z": 18,
      "name": "Plant_Leaves_Ash"
    },
    {
      "x": -7,
      "y": 77,
      "z": 19,
      "name": "Plant_Leaves_Ash"
    },
    {
      "x": -6,
      "y": 77,
      "z": -19,
      "name": "Plant_Leaves_Ash"
    },
    {
      "x": -6,
      "y": 77,
      "z": -18,
      "name": "Plant_Leaves_Ash"
    },
    {
      "x": -6,
      "y": 78,
      "z": -18,
      "name": "Plant_Leaves_Ash"
    },
    {
      "x": -6,
      "y": 77,
      "z": -17,
      "name": "Plant_Leaves_Ash"
    },
    {
      "x": -6,
      "y": 78,
      "z": -17,
      "name": "Plant_Leaves_Ash"
    },
    {
      "x": -6,
      "y": 78,
      "z": -16,
      "name": "Plant_Leaves_Ash"
    },
    {
      "x": -6,
      "y": 79,
      "z": -16,
      "name": "Plant_Leaves_Ash"
    },
    {
      "x": -6,
      "y": 78,
      "z": -15,
      "name": "Plant_Leaves_Ash"
    },
    {
      "x": -6,
      "y": 79,
      "z": -15,
      "name": "Plant_Leaves_Ash"
    },
    {
      "x": -6,
      "y": 79,
      "z": -14,
      "name": "Plant_Leaves_Ash"
    },
    {
      "x": -6,
      "y": 79,
      "z": -13,
      "name": "Plant_Leaves_Ash"
    },
    {
      "x": -6,
      "y": 79,
      "z": -12,
      "name": "Plant_Leaves_Ash"
    },
    {
      "x": -6,
      "y": 79,
      "z": -11,
      "name": "Plant_Leaves_Ash"
    },
    {
      "x": -6,
      "y": 80,
      "z": -11,
      "name": "Plant_Leaves_Ash"
    },
    {
      "x": -6,
      "y": 79,
      "z": -10,
      "name": "Plant_Leaves_Ash"
    },
    {
      "x": -6,
      "y": 80,
      "z": -10,
      "name": "Plant_Leaves_Ash"
    },
    {
      "x": -6,
      "y": 79,
      "z": -9,
      "name": "Plant_Leaves_Ash"
    },
    {
      "x": -6,
      "y": 80,
      "z": -9,
      "name": "Plant_Leaves_Ash"
    },
    {
      "x": -6,
      "y": 79,
      "z": -8,
      "name": "Plant_Leaves_Ash"
    },
    {
      "x": -6,
      "y": 80,
      "z": -8,
      "name": "Plant_Leaves_Ash"
    },
    {
      "x": -6,
      "y": 79,
      "z": -7,
      "name": "Plant_Leaves_Ash"
    },
    {
      "x": -6,
      "y": 80,
      "z": -7,
      "name": "Plant_Leaves_Ash"
    },
    {
      "x": -6,
      "y": 79,
      "z": -6,
      "name": "Plant_Leaves_Ash"
    },
    {
      "x": -6,
      "y": 80,
      "z": -6,
      "name": "Plant_Leaves_Ash"
    },
    {
      "x": -6,
      "y": 79,
      "z": -5,
      "name": "Plant_Leaves_Ash"
    },
    {
      "x": -6,
      "y": 80,
      "z": -5,
      "name": "Plant_Leaves_Ash"
    },
    {
      "x": -6,
      "y": 79,
      "z": -4,
      "name": "Plant_Leaves_Ash"
    },
    {
      "x": -6,
      "y": 80,
      "z": -4,
      "name": "Plant_Leaves_Ash"
    },
    {
      "x": -6,
      "y": 79,
      "z": -3,
      "name": "Plant_Leaves_Ash"
    },
    {
      "x": -6,
      "y": 80,
      "z": -3,
      "name": "Plant_Leaves_Ash"
    },
    {
      "x": -6,
      "y": 79,
      "z": -2,
      "name": "Plant_Leaves_Ash"
    },
    {
      "x": -6,
      "y": 80,
      "z": -2,
      "name": "Plant_Leaves_Ash"
    },
    {
      "x": -6,
      "y": 79,
      "z": -1,
      "name": "Plant_Leaves_Ash"
    },
    {
      "x": -6,
      "y": 80,
      "z": -1,
      "name": "Plant_Leaves_Ash"
    },
    {
      "x": -6,
      "y": 79,
      "z": 0,
      "name": "Plant_Leaves_Ash"
    },
    {
      "x": -6,
      "y": 80,
      "z": 0,
      "name": "Plant_Leaves_Ash"
    },
    {
      "x": -6,
      "y": 79,
      "z": 1,
      "name": "Plant_Leaves_Ash"
    },
    {
      "x": -6,
      "y": 80,
      "z": 1,
      "name": "Plant_Leaves_Ash"
    },
    {
      "x": -6,
      "y": 79,
      "z": 2,
      "name": "Plant_Leaves_Ash"
    },
    {
      "x": -6,
      "y": 80,
      "z": 2,
      "name": "Plant_Leaves_Ash"
    },
    {
      "x": -6,
      "y": 79,
      "z": 3,
      "name": "Plant_Leaves_Ash"
    },
    {
      "x": -6,
      "y": 80,
      "z": 3,
      "name": "Plant_Leaves_Ash"
    },
    {
      "x": -6,
      "y": 79,
      "z": 4,
      "name": "Plant_Leaves_Ash"
    },
    {
      "x": -6,
      "y": 80,
      "z": 4,
      "name": "Plant_Leaves_Ash"
    },
    {
      "x": -6,
      "y": 79,
      "z": 5,
      "name": "Plant_Leaves_Ash"
    },
    {
      "x": -6,
      "y": 80,
      "z": 5,
      "name": "Plant_Leaves_Ash"
    },
    {
      "x": -6,
      "y": 79,
      "z": 6,
      "name": "Plant_Leaves_Ash"
    },
    {
      "x": -6,
      "y": 80,
      "z": 6,
      "name": "Plant_Leaves_Ash"
    },
    {
      "x": -6,
      "y": 79,
      "z": 7,
      "name": "Plant_Leaves_Ash"
    },
    {
      "x": -6,
      "y": 80,
      "z": 7,
      "name": "Plant_Leaves_Ash"
    },
    {
      "x": -6,
      "y": 79,
      "z": 8,
      "name": "Plant_Leaves_Ash"
    },
    {
      "x": -6,
      "y": 80,
      "z": 8,
      "name": "Plant_Leaves_Ash"
    },
    {
      "x": -6,
      "y": 79,
      "z": 9,
      "name": "Plant_Leaves_Ash"
    },
    {
      "x": -6,
      "y": 80,
      "z": 9,
      "name": "Plant_Leaves_Ash"
    },
    {
      "x": -6,
      "y": 79,
      "z": 10,
      "name": "Plant_Leaves_Ash"
    },
    {
      "x": -6,
      "y": 80,
      "z": 10,
      "name": "Plant_Leaves_Ash"
    },
    {
      "x": -6,
      "y": 79,
      "z": 11,
      "name": "Plant_Leaves_Ash"
    },
    {
      "x": -6,
      "y": 80,
      "z": 11,
      "name": "Plant_Leaves_Ash"
    },
    {
      "x": -6,
      "y": 79,
      "z": 12,
      "name": "Plant_Leaves_Ash"
    },
    {
      "x": -6,
      "y": 79,
      "z": 13,
      "name": "Plant_Leaves_Ash"
    },
    {
      "x": -6,
      "y": 79,
      "z": 14,
      "name": "Plant_Leaves_Ash"
    },
    {
      "x": -6,
      "y": 78,
      "z": 15,
      "name": "Plant_Leaves_Ash"
    },
    {
      "x": -6,
      "y": 79,
      "z": 15,
      "name": "Plant_Leaves_Ash"
    },
    {
      "x": -6,
      "y": 78,
      "z": 16,
      "name": "Plant_Leaves_Ash"
    },
    {
      "x": -6,
      "y": 79,
      "z": 16,
      "name": "Plant_Leaves_Ash"
    },
    {
      "x": -6,
      "y": 77,
      "z": 17,
      "name": "Plant_Leaves_Ash"
    },
    {
      "x": -6,
      "y": 78,
      "z": 17,
      "name": "Plant_Leaves_Ash"
    },
    {
      "x": -6,
      "y": 77,
      "z": 18,
      "name": "Plant_Leaves_Ash"
    },
    {
      "x": -6,
      "y": 78,
      "z": 18,
      "name": "Plant_Leaves_Ash"
    },
    {
      "x": -6,
      "y": 77,
      "z": 19,
      "name": "Plant_Leaves_Ash"
    },
    {
      "x": -5,
      "y": 77,
      "z": -19,
      "name": "Plant_Leaves_Ash"
    },
    {
      "x": -5,
      "y": 77,
      "z": -18,
      "name": "Plant_Leaves_Ash"
    },
    {
      "x": -5,
      "y": 78,
      "z": -18,
      "name": "Plant_Leaves_Ash"
    },
    {
      "x": -5,
      "y": 77,
      "z": -17,
      "name": "Plant_Leaves_Ash"
    },
    {
      "x": -5,
      "y": 78,
      "z": -17,
      "name": "Plant_Leaves_Ash"
    },
    {
      "x": -5,
      "y": 78,
      "z": -16,
      "name": "Plant_Leaves_Ash"
    },
    {
      "x": -5,
      "y": 79,
      "z": -16,
      "name": "Plant_Leaves_Ash"
    },
    {
      "x": -5,
      "y": 78,
      "z": -15,
      "name": "Plant_Leaves_Ash"
    },
    {
      "x": -5,
      "y": 79,
      "z": -15,
      "name": "Plant_Leaves_Ash"
    },
    {
      "x": -5,
      "y": 79,
      "z": -14,
      "name": "Plant_Leaves_Ash"
    },
    {
      "x": -5,
      "y": 79,
      "z": -13,
      "name": "Plant_Leaves_Ash"
    },
    {
      "x": -5,
      "y": 79,
      "z": -12,
      "name": "Plant_Leaves_Ash"
    },
    {
      "x": -5,
      "y": 80,
      "z": -12,
      "name": "Plant_Leaves_Ash"
    },
    {
      "x": -5,
      "y": 79,
      "z": -11,
      "name": "Plant_Leaves_Ash"
    },
    {
      "x": -5,
      "y": 80,
      "z": -11,
      "name": "Plant_Leaves_Ash"
    },
    {
      "x": -5,
      "y": 79,
      "z": -10,
      "name": "Plant_Leaves_Ash"
    },
    {
      "x": -5,
      "y": 80,
      "z": -10,
      "name": "Plant_Leaves_Ash"
    },
    {
      "x": -5,
      "y": 79,
      "z": -9,
      "name": "Plant_Leaves_Ash"
    },
    {
      "x": -5,
      "y": 80,
      "z": -9,
      "name": "Plant_Leaves_Ash"
    },
    {
      "x": -5,
      "y": 79,
      "z": -8,
      "name": "Plant_Leaves_Ash"
    },
    {
      "x": -5,
      "y": 80,
      "z": -8,
      "name": "Plant_Leaves_Ash"
    },
    {
      "x": -5,
      "y": 79,
      "z": -7,
      "name": "Plant_Leaves_Ash"
    },
    {
      "x": -5,
      "y": 80,
      "z": -7,
      "name": "Plant_Leaves_Ash"
    },
    {
      "x": -5,
      "y": 79,
      "z": -6,
      "name": "Plant_Leaves_Ash"
    },
    {
      "x": -5,
      "y": 80,
      "z": -6,
      "name": "Plant_Leaves_Ash"
    },
    {
      "x": -5,
      "y": 79,
      "z": -5,
      "name": "Plant_Leaves_Ash"
    },
    {
      "x": -5,
      "y": 80,
      "z": -5,
      "name": "Plant_Leaves_Ash"
    },
    {
      "x": -5,
      "y": 79,
      "z": -4,
      "name": "Plant_Leaves_Ash"
    },
    {
      "x": -5,
      "y": 80,
      "z": -4,
      "name": "Plant_Leaves_Ash"
    },
    {
      "x": -5,
      "y": 79,
      "z": -3,
      "name": "Plant_Leaves_Ash"
    },
    {
      "x": -5,
      "y": 80,
      "z": -3,
      "name": "Plant_Leaves_Ash"
    },
    {
      "x": -5,
      "y": 79,
      "z": -2,
      "name": "Plant_Leaves_Ash"
    },
    {
      "x": -5,
      "y": 80,
      "z": -2,
      "name": "Plant_Leaves_Ash"
    },
    {
      "x": -5,
      "y": 79,
      "z": -1,
      "name": "Plant_Leaves_Ash"
    },
    {
      "x": -5,
      "y": 80,
      "z": -1,
      "name": "Plant_Leaves_Ash"
    },
    {
      "x": -5,
      "y": 79,
      "z": 0,
      "name": "Plant_Leaves_Ash"
    },
    {
      "x": -5,
      "y": 80,
      "z": 0,
      "name": "Plant_Leaves_Ash"
    },
    {
      "x": -5,
      "y": 79,
      "z": 1,
      "name": "Plant_Leaves_Ash"
    },
    {
      "x": -5,
      "y": 80,
      "z": 1,
      "name": "Plant_Leaves_Ash"
    },
    {
      "x": -5,
      "y": 79,
      "z": 2,
      "name": "Plant_Leaves_Ash"
    },
    {
      "x": -5,
      "y": 80,
      "z": 2,
      "name": "Plant_Leaves_Ash"
    },
    {
      "x": -5,
      "y": 79,
      "z": 3,
      "name": "Plant_Leaves_Ash"
    },
    {
      "x": -5,
      "y": 80,
      "z": 3,
      "name": "Plant_Leaves_Ash"
    },
    {
      "x": -5,
      "y": 79,
      "z": 4,
      "name": "Plant_Leaves_Ash"
    },
    {
      "x": -5,
      "y": 80,
      "z": 4,
      "name": "Plant_Leaves_Ash"
    },
    {
      "x": -5,
      "y": 79,
      "z": 5,
      "name": "Plant_Leaves_Ash"
    },
    {
      "x": -5,
      "y": 80,
      "z": 5,
      "name": "Plant_Leaves_Ash"
    },
    {
      "x": -5,
      "y": 79,
      "z": 6,
      "name": "Plant_Leaves_Ash"
    },
    {
      "x": -5,
      "y": 80,
      "z": 6,
      "name": "Plant_Leaves_Ash"
    },
    {
      "x": -5,
      "y": 79,
      "z": 7,
      "name": "Plant_Leaves_Ash"
    },
    {
      "x": -5,
      "y": 80,
      "z": 7,
      "name": "Plant_Leaves_Ash"
    },
    {
      "x": -5,
      "y": 79,
      "z": 8,
      "name": "Plant_Leaves_Ash"
    },
    {
      "x": -5,
      "y": 80,
      "z": 8,
      "name": "Plant_Leaves_Ash"
    },
    {
      "x": -5,
      "y": 79,
      "z": 9,
      "name": "Plant_Leaves_Ash"
    },
    {
      "x": -5,
      "y": 80,
      "z": 9,
      "name": "Plant_Leaves_Ash"
    },
    {
      "x": -5,
      "y": 79,
      "z": 10,
      "name": "Plant_Leaves_Ash"
    },
    {
      "x": -5,
      "y": 80,
      "z": 10,
      "name": "Plant_Leaves_Ash"
    },
    {
      "x": -5,
      "y": 79,
      "z": 11,
      "name": "Plant_Leaves_Ash"
    },
    {
      "x": -5,
      "y": 80,
      "z": 11,
      "name": "Plant_Leaves_Ash"
    },
    {
      "x": -5,
      "y": 79,
      "z": 12,
      "name": "Plant_Leaves_Ash"
    },
    {
      "x": -5,
      "y": 80,
      "z": 12,
      "name": "Plant_Leaves_Ash"
    },
    {
      "x": -5,
      "y": 79,
      "z": 13,
      "name": "Plant_Leaves_Ash"
    },
    {
      "x": -5,
      "y": 79,
      "z": 14,
      "name": "Plant_Leaves_Ash"
    },
    {
      "x": -5,
      "y": 78,
      "z": 15,
      "name": "Plant_Leaves_Ash"
    },
    {
      "x": -5,
      "y": 79,
      "z": 15,
      "name": "Plant_Leaves_Ash"
    },
    {
      "x": -5,
      "y": 78,
      "z": 16,
      "name": "Plant_Leaves_Ash"
    },
    {
      "x": -5,
      "y": 79,
      "z": 16,
      "name": "Plant_Leaves_Ash"
    },
    {
      "x": -5,
      "y": 77,
      "z": 17,
      "name": "Plant_Leaves_Ash"
    },
    {
      "x": -5,
      "y": 78,
      "z": 17,
      "name": "Plant_Leaves_Ash"
    },
    {
      "x": -5,
      "y": 77,
      "z": 18,
      "name": "Plant_Leaves_Ash"
    },
    {
      "x": -5,
      "y": 78,
      "z": 18,
      "name": "Plant_Leaves_Ash"
    },
    {
      "x": -5,
      "y": 77,
      "z": 19,
      "name": "Plant_Leaves_Ash"
    },
    {
      "x": -4,
      "y": 77,
      "z": -20,
      "name": "Plant_Leaves_Ash"
    },
    {
      "x": -4,
      "y": 77,
      "z": -19,
      "name": "Plant_Leaves_Ash"
    },
    {
      "x": -4,
      "y": 77,
      "z": -18,
      "name": "Plant_Leaves_Ash"
    },
    {
      "x": -4,
      "y": 78,
      "z": -18,
      "name": "Plant_Leaves_Ash"
    },
    {
      "x": -4,
      "y": 77,
      "z": -17,
      "name": "Plant_Leaves_Ash"
    },
    {
      "x": -4,
      "y": 78,
      "z": -17,
      "name": "Plant_Leaves_Ash"
    },
    {
      "x": -4,
      "y": 78,
      "z": -16,
      "name": "Plant_Leaves_Ash"
    },
    {
      "x": -4,
      "y": 79,
      "z": -16,
      "name": "Plant_Leaves_Ash"
    },
    {
      "x": -4,
      "y": 78,
      "z": -15,
      "name": "Plant_Leaves_Ash"
    },
    {
      "x": -4,
      "y": 79,
      "z": -15,
      "name": "Plant_Leaves_Ash"
    },
    {
      "x": -4,
      "y": 79,
      "z": -14,
      "name": "Plant_Leaves_Ash"
    },
    {
      "x": -4,
      "y": 79,
      "z": -13,
      "name": "Plant_Leaves_Ash"
    },
    {
      "x": -4,
      "y": 79,
      "z": -12,
      "name": "Plant_Leaves_Ash"
    },
    {
      "x": -4,
      "y": 80,
      "z": -12,
      "name": "Plant_Leaves_Ash"
    },
    {
      "x": -4,
      "y": 79,
      "z": -11,
      "name": "Plant_Leaves_Ash"
    },
    {
      "x": -4,
      "y": 80,
      "z": -11,
      "name": "Plant_Leaves_Ash"
    },
    {
      "x": -4,
      "y": 79,
      "z": -10,
      "name": "Plant_Leaves_Ash"
    },
    {
      "x": -4,
      "y": 80,
      "z": -10,
      "name": "Plant_Leaves_Ash"
    },
    {
      "x": -4,
      "y": 79,
      "z": -9,
      "name": "Plant_Leaves_Ash"
    },
    {
      "x": -4,
      "y": 80,
      "z": -9,
      "name": "Plant_Leaves_Ash"
    },
    {
      "x": -4,
      "y": 79,
      "z": -8,
      "name": "Plant_Leaves_Ash"
    },
    {
      "x": -4,
      "y": 80,
      "z": -8,
      "name": "Plant_Leaves_Ash"
    },
    {
      "x": -4,
      "y": 79,
      "z": -7,
      "name": "Plant_Leaves_Ash"
    },
    {
      "x": -4,
      "y": 80,
      "z": -7,
      "name": "Plant_Leaves_Ash"
    },
    {
      "x": -4,
      "y": 79,
      "z": -6,
      "name": "Plant_Leaves_Ash"
    },
    {
      "x": -4,
      "y": 80,
      "z": -6,
      "name": "Plant_Leaves_Ash"
    },
    {
      "x": -4,
      "y": 79,
      "z": -5,
      "name": "Plant_Leaves_Ash"
    },
    {
      "x": -4,
      "y": 80,
      "z": -5,
      "name": "Plant_Leaves_Ash"
    },
    {
      "x": -4,
      "y": 79,
      "z": -4,
      "name": "Plant_Leaves_Ash"
    },
    {
      "x": -4,
      "y": 80,
      "z": -4,
      "name": "Plant_Leaves_Ash"
    },
    {
      "x": -4,
      "y": 79,
      "z": -3,
      "name": "Plant_Leaves_Ash"
    },
    {
      "x": -4,
      "y": 80,
      "z": -3,
      "name": "Plant_Leaves_Ash"
    },
    {
      "x": -4,
      "y": 79,
      "z": -2,
      "name": "Plant_Leaves_Ash"
    },
    {
      "x": -4,
      "y": 80,
      "z": -2,
      "name": "Plant_Leaves_Ash"
    },
    {
      "x": -4,
      "y": 79,
      "z": -1,
      "name": "Plant_Leaves_Ash"
    },
    {
      "x": -4,
      "y": 80,
      "z": -1,
      "name": "Plant_Leaves_Ash"
    },
    {
      "x": -4,
      "y": 79,
      "z": 0,
      "name": "Plant_Leaves_Ash"
    },
    {
      "x": -4,
      "y": 80,
      "z": 0,
      "name": "Plant_Leaves_Ash"
    },
    {
      "x": -4,
      "y": 79,
      "z": 1,
      "name": "Plant_Leaves_Ash"
    },
    {
      "x": -4,
      "y": 80,
      "z": 1,
      "name": "Plant_Leaves_Ash"
    },
    {
      "x": -4,
      "y": 79,
      "z": 2,
      "name": "Plant_Leaves_Ash"
    },
    {
      "x": -4,
      "y": 80,
      "z": 2,
      "name": "Plant_Leaves_Ash"
    },
    {
      "x": -4,
      "y": 79,
      "z": 3,
      "name": "Plant_Leaves_Ash"
    },
    {
      "x": -4,
      "y": 80,
      "z": 3,
      "name": "Plant_Leaves_Ash"
    },
    {
      "x": -4,
      "y": 79,
      "z": 4,
      "name": "Plant_Leaves_Ash"
    },
    {
      "x": -4,
      "y": 80,
      "z": 4,
      "name": "Plant_Leaves_Ash"
    },
    {
      "x": -4,
      "y": 79,
      "z": 5,
      "name": "Plant_Leaves_Ash"
    },
    {
      "x": -4,
      "y": 80,
      "z": 5,
      "name": "Plant_Leaves_Ash"
    },
    {
      "x": -4,
      "y": 79,
      "z": 6,
      "name": "Plant_Leaves_Ash"
    },
    {
      "x": -4,
      "y": 80,
      "z": 6,
      "name": "Plant_Leaves_Ash"
    },
    {
      "x": -4,
      "y": 79,
      "z": 7,
      "name": "Plant_Leaves_Ash"
    },
    {
      "x": -4,
      "y": 80,
      "z": 7,
      "name": "Plant_Leaves_Ash"
    },
    {
      "x": -4,
      "y": 79,
      "z": 8,
      "name": "Plant_Leaves_Ash"
    },
    {
      "x": -4,
      "y": 80,
      "z": 8,
      "name": "Plant_Leaves_Ash"
    },
    {
      "x": -4,
      "y": 79,
      "z": 9,
      "name": "Plant_Leaves_Ash"
    },
    {
      "x": -4,
      "y": 80,
      "z": 9,
      "name": "Plant_Leaves_Ash"
    },
    {
      "x": -4,
      "y": 79,
      "z": 10,
      "name": "Plant_Leaves_Ash"
    },
    {
      "x": -4,
      "y": 80,
      "z": 10,
      "name": "Plant_Leaves_Ash"
    },
    {
      "x": -4,
      "y": 79,
      "z": 11,
      "name": "Plant_Leaves_Ash"
    },
    {
      "x": -4,
      "y": 80,
      "z": 11,
      "name": "Plant_Leaves_Ash"
    },
    {
      "x": -4,
      "y": 79,
      "z": 12,
      "name": "Plant_Leaves_Ash"
    },
    {
      "x": -4,
      "y": 80,
      "z": 12,
      "name": "Plant_Leaves_Ash"
    },
    {
      "x": -4,
      "y": 79,
      "z": 13,
      "name": "Plant_Leaves_Ash"
    },
    {
      "x": -4,
      "y": 79,
      "z": 14,
      "name": "Plant_Leaves_Ash"
    },
    {
      "x": -4,
      "y": 78,
      "z": 15,
      "name": "Plant_Leaves_Ash"
    },
    {
      "x": -4,
      "y": 79,
      "z": 15,
      "name": "Plant_Leaves_Ash"
    },
    {
      "x": -4,
      "y": 78,
      "z": 16,
      "name": "Plant_Leaves_Ash"
    },
    {
      "x": -4,
      "y": 79,
      "z": 16,
      "name": "Plant_Leaves_Ash"
    },
    {
      "x": -4,
      "y": 77,
      "z": 17,
      "name": "Plant_Leaves_Ash"
    },
    {
      "x": -4,
      "y": 78,
      "z": 17,
      "name": "Plant_Leaves_Ash"
    },
    {
      "x": -4,
      "y": 77,
      "z": 18,
      "name": "Plant_Leaves_Ash"
    },
    {
      "x": -4,
      "y": 78,
      "z": 18,
      "name": "Plant_Leaves_Ash"
    },
    {
      "x": -4,
      "y": 77,
      "z": 19,
      "name": "Plant_Leaves_Ash"
    },
    {
      "x": -4,
      "y": 77,
      "z": 20,
      "name": "Plant_Leaves_Ash"
    },
    {
      "x": -3,
      "y": 77,
      "z": -20,
      "name": "Plant_Leaves_Ash"
    },
    {
      "x": -3,
      "y": 77,
      "z": -19,
      "name": "Plant_Leaves_Ash"
    },
    {
      "x": -3,
      "y": 78,
      "z": -19,
      "name": "Plant_Leaves_Ash"
    },
    {
      "x": -3,
      "y": 77,
      "z": -18,
      "name": "Plant_Leaves_Ash"
    },
    {
      "x": -3,
      "y": 78,
      "z": -18,
      "name": "Plant_Leaves_Ash"
    },
    {
      "x": -3,
      "y": 78,
      "z": -17,
      "name": "Plant_Leaves_Ash"
    },
    {
      "x": -3,
      "y": 79,
      "z": -17,
      "name": "Plant_Leaves_Ash"
    },
    {
      "x": -3,
      "y": 78,
      "z": -16,
      "name": "Plant_Leaves_Ash"
    },
    {
      "x": -3,
      "y": 79,
      "z": -16,
      "name": "Plant_Leaves_Ash"
    },
    {
      "x": -3,
      "y": 79,
      "z": -15,
      "name": "Plant_Leaves_Ash"
    },
    {
      "x": -3,
      "y": 79,
      "z": -14,
      "name": "Plant_Leaves_Ash"
    },
    {
      "x": -3,
      "y": 79,
      "z": -13,
      "name": "Plant_Leaves_Ash"
    },
    {
      "x": -3,
      "y": 80,
      "z": -13,
      "name": "Plant_Leaves_Ash"
    },
    {
      "x": -3,
      "y": 79,
      "z": -12,
      "name": "Plant_Leaves_Ash"
    },
    {
      "x": -3,
      "y": 80,
      "z": -12,
      "name": "Plant_Leaves_Ash"
    },
    {
      "x": -3,
      "y": 79,
      "z": -11,
      "name": "Plant_Leaves_Ash"
    },
    {
      "x": -3,
      "y": 80,
      "z": -11,
      "name": "Plant_Leaves_Ash"
    },
    {
      "x": -3,
      "y": 79,
      "z": -10,
      "name": "Plant_Leaves_Ash"
    },
    {
      "x": -3,
      "y": 80,
      "z": -10,
      "name": "Plant_Leaves_Ash"
    },
    {
      "x": -3,
      "y": 79,
      "z": -9,
      "name": "Plant_Leaves_Ash"
    },
    {
      "x": -3,
      "y": 80,
      "z": -9,
      "name": "Plant_Leaves_Ash"
    },
    {
      "x": -3,
      "y": 79,
      "z": -8,
      "name": "Plant_Leaves_Ash"
    },
    {
      "x": -3,
      "y": 80,
      "z": -8,
      "name": "Plant_Leaves_Ash"
    },
    {
      "x": -3,
      "y": 79,
      "z": -7,
      "name": "Plant_Leaves_Ash"
    },
    {
      "x": -3,
      "y": 80,
      "z": -7,
      "name": "Plant_Leaves_Ash"
    },
    {
      "x": -3,
      "y": 79,
      "z": -6,
      "name": "Plant_Leaves_Ash"
    },
    {
      "x": -3,
      "y": 80,
      "z": -6,
      "name": "Plant_Leaves_Ash"
    },
    {
      "x": -3,
      "y": 79,
      "z": -5,
      "name": "Plant_Leaves_Ash"
    },
    {
      "x": -3,
      "y": 80,
      "z": -5,
      "name": "Plant_Leaves_Ash"
    },
    {
      "x": -3,
      "y": 79,
      "z": -4,
      "name": "Plant_Leaves_Ash"
    },
    {
      "x": -3,
      "y": 80,
      "z": -4,
      "name": "Plant_Leaves_Ash"
    },
    {
      "x": -3,
      "y": 79,
      "z": -3,
      "name": "Plant_Leaves_Ash"
    },
    {
      "x": -3,
      "y": 80,
      "z": -3,
      "name": "Plant_Leaves_Ash"
    },
    {
      "x": -3,
      "y": 79,
      "z": -2,
      "name": "Plant_Leaves_Ash"
    },
    {
      "x": -3,
      "y": 80,
      "z": -2,
      "name": "Plant_Leaves_Ash"
    },
    {
      "x": -3,
      "y": 79,
      "z": -1,
      "name": "Plant_Leaves_Ash"
    },
    {
      "x": -3,
      "y": 80,
      "z": -1,
      "name": "Plant_Leaves_Ash"
    },
    {
      "x": -3,
      "y": 79,
      "z": 0,
      "name": "Plant_Leaves_Ash"
    },
    {
      "x": -3,
      "y": 80,
      "z": 0,
      "name": "Plant_Leaves_Ash"
    },
    {
      "x": -3,
      "y": 79,
      "z": 1,
      "name": "Plant_Leaves_Ash"
    },
    {
      "x": -3,
      "y": 80,
      "z": 1,
      "name": "Plant_Leaves_Ash"
    },
    {
      "x": -3,
      "y": 79,
      "z": 2,
      "name": "Plant_Leaves_Ash"
    },
    {
      "x": -3,
      "y": 80,
      "z": 2,
      "name": "Plant_Leaves_Ash"
    },
    {
      "x": -3,
      "y": 79,
      "z": 3,
      "name": "Plant_Leaves_Ash"
    },
    {
      "x": -3,
      "y": 80,
      "z": 3,
      "name": "Plant_Leaves_Ash"
    },
    {
      "x": -3,
      "y": 79,
      "z": 4,
      "name": "Plant_Leaves_Ash"
    },
    {
      "x": -3,
      "y": 80,
      "z": 4,
      "name": "Plant_Leaves_Ash"
    },
    {
      "x": -3,
      "y": 79,
      "z": 5,
      "name": "Plant_Leaves_Ash"
    },
    {
      "x": -3,
      "y": 80,
      "z": 5,
      "name": "Plant_Leaves_Ash"
    },
    {
      "x": -3,
      "y": 79,
      "z": 6,
      "name": "Plant_Leaves_Ash"
    },
    {
      "x": -3,
      "y": 80,
      "z": 6,
      "name": "Plant_Leaves_Ash"
    },
    {
      "x": -3,
      "y": 79,
      "z": 7,
      "name": "Plant_Leaves_Ash"
    },
    {
      "x": -3,
      "y": 80,
      "z": 7,
      "name": "Plant_Leaves_Ash"
    },
    {
      "x": -3,
      "y": 79,
      "z": 8,
      "name": "Plant_Leaves_Ash"
    },
    {
      "x": -3,
      "y": 80,
      "z": 8,
      "name": "Plant_Leaves_Ash"
    },
    {
      "x": -3,
      "y": 79,
      "z": 9,
      "name": "Plant_Leaves_Ash"
    },
    {
      "x": -3,
      "y": 80,
      "z": 9,
      "name": "Plant_Leaves_Ash"
    },
    {
      "x": -3,
      "y": 79,
      "z": 10,
      "name": "Plant_Leaves_Ash"
    },
    {
      "x": -3,
      "y": 80,
      "z": 10,
      "name": "Plant_Leaves_Ash"
    },
    {
      "x": -3,
      "y": 79,
      "z": 11,
      "name": "Plant_Leaves_Ash"
    },
    {
      "x": -3,
      "y": 80,
      "z": 11,
      "name": "Plant_Leaves_Ash"
    },
    {
      "x": -3,
      "y": 79,
      "z": 12,
      "name": "Plant_Leaves_Ash"
    },
    {
      "x": -3,
      "y": 80,
      "z": 12,
      "name": "Plant_Leaves_Ash"
    },
    {
      "x": -3,
      "y": 79,
      "z": 13,
      "name": "Plant_Leaves_Ash"
    },
    {
      "x": -3,
      "y": 80,
      "z": 13,
      "name": "Plant_Leaves_Ash"
    },
    {
      "x": -3,
      "y": 79,
      "z": 14,
      "name": "Plant_Leaves_Ash"
    },
    {
      "x": -3,
      "y": 79,
      "z": 15,
      "name": "Plant_Leaves_Ash"
    },
    {
      "x": -3,
      "y": 78,
      "z": 16,
      "name": "Plant_Leaves_Ash"
    },
    {
      "x": -3,
      "y": 79,
      "z": 16,
      "name": "Plant_Leaves_Ash"
    },
    {
      "x": -3,
      "y": 78,
      "z": 17,
      "name": "Plant_Leaves_Ash"
    },
    {
      "x": -3,
      "y": 79,
      "z": 17,
      "name": "Plant_Leaves_Ash"
    },
    {
      "x": -3,
      "y": 77,
      "z": 18,
      "name": "Plant_Leaves_Ash"
    },
    {
      "x": -3,
      "y": 78,
      "z": 18,
      "name": "Plant_Leaves_Ash"
    },
    {
      "x": -3,
      "y": 77,
      "z": 19,
      "name": "Plant_Leaves_Ash"
    },
    {
      "x": -3,
      "y": 78,
      "z": 19,
      "name": "Plant_Leaves_Ash"
    },
    {
      "x": -3,
      "y": 77,
      "z": 20,
      "name": "Plant_Leaves_Ash"
    },
    {
      "x": -2,
      "y": 77,
      "z": -20,
      "name": "Plant_Leaves_Ash"
    },
    {
      "x": -2,
      "y": 77,
      "z": -19,
      "name": "Plant_Leaves_Ash"
    },
    {
      "x": -2,
      "y": 78,
      "z": -19,
      "name": "Plant_Leaves_Ash"
    },
    {
      "x": -2,
      "y": 77,
      "z": -18,
      "name": "Plant_Leaves_Ash"
    },
    {
      "x": -2,
      "y": 78,
      "z": -18,
      "name": "Plant_Leaves_Ash"
    },
    {
      "x": -2,
      "y": 78,
      "z": -17,
      "name": "Plant_Leaves_Ash"
    },
    {
      "x": -2,
      "y": 79,
      "z": -17,
      "name": "Plant_Leaves_Ash"
    },
    {
      "x": -2,
      "y": 78,
      "z": -16,
      "name": "Plant_Leaves_Ash"
    },
    {
      "x": -2,
      "y": 79,
      "z": -16,
      "name": "Plant_Leaves_Ash"
    },
    {
      "x": -2,
      "y": 79,
      "z": -15,
      "name": "Plant_Leaves_Ash"
    },
    {
      "x": -2,
      "y": 79,
      "z": -14,
      "name": "Plant_Leaves_Ash"
    },
    {
      "x": -2,
      "y": 79,
      "z": -13,
      "name": "Plant_Leaves_Ash"
    },
    {
      "x": -2,
      "y": 80,
      "z": -13,
      "name": "Plant_Leaves_Ash"
    },
    {
      "x": -2,
      "y": 79,
      "z": -12,
      "name": "Plant_Leaves_Ash"
    },
    {
      "x": -2,
      "y": 80,
      "z": -12,
      "name": "Plant_Leaves_Ash"
    },
    {
      "x": -2,
      "y": 79,
      "z": -11,
      "name": "Plant_Leaves_Ash"
    },
    {
      "x": -2,
      "y": 80,
      "z": -11,
      "name": "Plant_Leaves_Ash"
    },
    {
      "x": -2,
      "y": 79,
      "z": -10,
      "name": "Plant_Leaves_Ash"
    },
    {
      "x": -2,
      "y": 80,
      "z": -10,
      "name": "Plant_Leaves_Ash"
    },
    {
      "x": -2,
      "y": 79,
      "z": -9,
      "name": "Plant_Leaves_Ash"
    },
    {
      "x": -2,
      "y": 80,
      "z": -9,
      "name": "Plant_Leaves_Ash"
    },
    {
      "x": -2,
      "y": 79,
      "z": -8,
      "name": "Plant_Leaves_Ash"
    },
    {
      "x": -2,
      "y": 80,
      "z": -8,
      "name": "Plant_Leaves_Ash"
    },
    {
      "x": -2,
      "y": 79,
      "z": -7,
      "name": "Plant_Leaves_Ash"
    },
    {
      "x": -2,
      "y": 80,
      "z": -7,
      "name": "Plant_Leaves_Ash"
    },
    {
      "x": -2,
      "y": 79,
      "z": -6,
      "name": "Plant_Leaves_Ash"
    },
    {
      "x": -2,
      "y": 80,
      "z": -6,
      "name": "Plant_Leaves_Ash"
    },
    {
      "x": -2,
      "y": 79,
      "z": -5,
      "name": "Plant_Leaves_Ash"
    },
    {
      "x": -2,
      "y": 80,
      "z": -5,
      "name": "Plant_Leaves_Ash"
    },
    {
      "x": -2,
      "y": 79,
      "z": -4,
      "name": "Plant_Leaves_Ash"
    },
    {
      "x": -2,
      "y": 80,
      "z": -4,
      "name": "Plant_Leaves_Ash"
    },
    {
      "x": -2,
      "y": 79,
      "z": -3,
      "name": "Plant_Leaves_Ash"
    },
    {
      "x": -2,
      "y": 80,
      "z": -3,
      "name": "Plant_Leaves_Ash"
    },
    {
      "x": -2,
      "y": 79,
      "z": -2,
      "name": "Plant_Leaves_Ash"
    },
    {
      "x": -2,
      "y": 80,
      "z": -2,
      "name": "Plant_Leaves_Ash"
    },
    {
      "x": -2,
      "y": 79,
      "z": -1,
      "name": "Plant_Leaves_Ash"
    },
    {
      "x": -2,
      "y": 80,
      "z": -1,
      "name": "Plant_Leaves_Ash"
    },
    {
      "x": -2,
      "y": 79,
      "z": 0,
      "name": "Plant_Leaves_Ash"
    },
    {
      "x": -2,
      "y": 80,
      "z": 0,
      "name": "Plant_Leaves_Ash"
    },
    {
      "x": -2,
      "y": 79,
      "z": 1,
      "name": "Plant_Leaves_Ash"
    },
    {
      "x": -2,
      "y": 80,
      "z": 1,
      "name": "Plant_Leaves_Ash"
    },
    {
      "x": -2,
      "y": 79,
      "z": 2,
      "name": "Plant_Leaves_Ash"
    },
    {
      "x": -2,
      "y": 80,
      "z": 2,
      "name": "Plant_Leaves_Ash"
    },
    {
      "x": -2,
      "y": 79,
      "z": 3,
      "name": "Plant_Leaves_Ash"
    },
    {
      "x": -2,
      "y": 80,
      "z": 3,
      "name": "Plant_Leaves_Ash"
    },
    {
      "x": -2,
      "y": 79,
      "z": 4,
      "name": "Plant_Leaves_Ash"
    },
    {
      "x": -2,
      "y": 80,
      "z": 4,
      "name": "Plant_Leaves_Ash"
    },
    {
      "x": -2,
      "y": 79,
      "z": 5,
      "name": "Plant_Leaves_Ash"
    },
    {
      "x": -2,
      "y": 80,
      "z": 5,
      "name": "Plant_Leaves_Ash"
    },
    {
      "x": -2,
      "y": 79,
      "z": 6,
      "name": "Plant_Leaves_Ash"
    },
    {
      "x": -2,
      "y": 80,
      "z": 6,
      "name": "Plant_Leaves_Ash"
    },
    {
      "x": -2,
      "y": 79,
      "z": 7,
      "name": "Plant_Leaves_Ash"
    },
    {
      "x": -2,
      "y": 80,
      "z": 7,
      "name": "Plant_Leaves_Ash"
    },
    {
      "x": -2,
      "y": 79,
      "z": 8,
      "name": "Plant_Leaves_Ash"
    },
    {
      "x": -2,
      "y": 80,
      "z": 8,
      "name": "Plant_Leaves_Ash"
    },
    {
      "x": -2,
      "y": 79,
      "z": 9,
      "name": "Plant_Leaves_Ash"
    },
    {
      "x": -2,
      "y": 80,
      "z": 9,
      "name": "Plant_Leaves_Ash"
    },
    {
      "x": -2,
      "y": 79,
      "z": 10,
      "name": "Plant_Leaves_Ash"
    },
    {
      "x": -2,
      "y": 80,
      "z": 10,
      "name": "Plant_Leaves_Ash"
    },
    {
      "x": -2,
      "y": 79,
      "z": 11,
      "name": "Plant_Leaves_Ash"
    },
    {
      "x": -2,
      "y": 80,
      "z": 11,
      "name": "Plant_Leaves_Ash"
    },
    {
      "x": -2,
      "y": 79,
      "z": 12,
      "name": "Plant_Leaves_Ash"
    },
    {
      "x": -2,
      "y": 80,
      "z": 12,
      "name": "Plant_Leaves_Ash"
    },
    {
      "x": -2,
      "y": 79,
      "z": 13,
      "name": "Plant_Leaves_Ash"
    },
    {
      "x": -2,
      "y": 80,
      "z": 13,
      "name": "Plant_Leaves_Ash"
    },
    {
      "x": -2,
      "y": 79,
      "z": 14,
      "name": "Plant_Leaves_Ash"
    },
    {
      "x": -2,
      "y": 79,
      "z": 15,
      "name": "Plant_Leaves_Ash"
    },
    {
      "x": -2,
      "y": 78,
      "z": 16,
      "name": "Plant_Leaves_Ash"
    },
    {
      "x": -2,
      "y": 79,
      "z": 16,
      "name": "Plant_Leaves_Ash"
    },
    {
      "x": -2,
      "y": 78,
      "z": 17,
      "name": "Plant_Leaves_Ash"
    },
    {
      "x": -2,
      "y": 79,
      "z": 17,
      "name": "Plant_Leaves_Ash"
    },
    {
      "x": -2,
      "y": 77,
      "z": 18,
      "name": "Plant_Leaves_Ash"
    },
    {
      "x": -2,
      "y": 78,
      "z": 18,
      "name": "Plant_Leaves_Ash"
    },
    {
      "x": -2,
      "y": 77,
      "z": 19,
      "name": "Plant_Leaves_Ash"
    },
    {
      "x": -2,
      "y": 78,
      "z": 19,
      "name": "Plant_Leaves_Ash"
    },
    {
      "x": -2,
      "y": 77,
      "z": 20,
      "name": "Plant_Leaves_Ash"
    },
    {
      "x": -1,
      "y": 77,
      "z": -20,
      "name": "Plant_Leaves_Ash"
    },
    {
      "x": -1,
      "y": 77,
      "z": -19,
      "name": "Plant_Leaves_Ash"
    },
    {
      "x": -1,
      "y": 78,
      "z": -19,
      "name": "Plant_Leaves_Ash"
    },
    {
      "x": -1,
      "y": 77,
      "z": -18,
      "name": "Plant_Leaves_Ash"
    },
    {
      "x": -1,
      "y": 78,
      "z": -18,
      "name": "Plant_Leaves_Ash"
    },
    {
      "x": -1,
      "y": 78,
      "z": -17,
      "name": "Plant_Leaves_Ash"
    },
    {
      "x": -1,
      "y": 79,
      "z": -17,
      "name": "Plant_Leaves_Ash"
    },
    {
      "x": -1,
      "y": 78,
      "z": -16,
      "name": "Plant_Leaves_Ash"
    },
    {
      "x": -1,
      "y": 79,
      "z": -16,
      "name": "Plant_Leaves_Ash"
    },
    {
      "x": -1,
      "y": 79,
      "z": -15,
      "name": "Plant_Leaves_Ash"
    },
    {
      "x": -1,
      "y": 79,
      "z": -14,
      "name": "Plant_Leaves_Ash"
    },
    {
      "x": -1,
      "y": 79,
      "z": -13,
      "name": "Plant_Leaves_Ash"
    },
    {
      "x": -1,
      "y": 80,
      "z": -13,
      "name": "Plant_Leaves_Ash"
    },
    {
      "x": -1,
      "y": 79,
      "z": -12,
      "name": "Plant_Leaves_Ash"
    },
    {
      "x": -1,
      "y": 80,
      "z": -12,
      "name": "Plant_Leaves_Ash"
    },
    {
      "x": -1,
      "y": 79,
      "z": -11,
      "name": "Plant_Leaves_Ash"
    },
    {
      "x": -1,
      "y": 80,
      "z": -11,
      "name": "Plant_Leaves_Ash"
    },
    {
      "x": -1,
      "y": 79,
      "z": -10,
      "name": "Plant_Leaves_Ash"
    },
    {
      "x": -1,
      "y": 80,
      "z": -10,
      "name": "Plant_Leaves_Ash"
    },
    {
      "x": -1,
      "y": 79,
      "z": -9,
      "name": "Plant_Leaves_Ash"
    },
    {
      "x": -1,
      "y": 80,
      "z": -9,
      "name": "Plant_Leaves_Ash"
    },
    {
      "x": -1,
      "y": 79,
      "z": -8,
      "name": "Plant_Leaves_Ash"
    },
    {
      "x": -1,
      "y": 80,
      "z": -8,
      "name": "Plant_Leaves_Ash"
    },
    {
      "x": -1,
      "y": 79,
      "z": -7,
      "name": "Plant_Leaves_Ash"
    },
    {
      "x": -1,
      "y": 80,
      "z": -7,
      "name": "Plant_Leaves_Ash"
    },
    {
      "x": -1,
      "y": 79,
      "z": -6,
      "name": "Plant_Leaves_Ash"
    },
    {
      "x": -1,
      "y": 80,
      "z": -6,
      "name": "Plant_Leaves_Ash"
    },
    {
      "x": -1,
      "y": 79,
      "z": -5,
      "name": "Plant_Leaves_Ash"
    },
    {
      "x": -1,
      "y": 80,
      "z": -5,
      "name": "Plant_Leaves_Ash"
    },
    {
      "x": -1,
      "y": 79,
      "z": -4,
      "name": "Plant_Leaves_Ash"
    },
    {
      "x": -1,
      "y": 80,
      "z": -4,
      "name": "Plant_Leaves_Ash"
    },
    {
      "x": -1,
      "y": 79,
      "z": -3,
      "name": "Plant_Leaves_Ash"
    },
    {
      "x": -1,
      "y": 80,
      "z": -3,
      "name": "Plant_Leaves_Ash"
    },
    {
      "x": -1,
      "y": 79,
      "z": -2,
      "name": "Plant_Leaves_Ash"
    },
    {
      "x": -1,
      "y": 80,
      "z": -2,
      "name": "Plant_Leaves_Ash"
    },
    {
      "x": -1,
      "y": 14,
      "z": -1,
      "name": "Wood_Oak_Trunk"
    },
    {
      "x": -1,
      "y": 15,
      "z": -1,
      "name": "Wood_Oak_Trunk"
    },
    {
      "x": -1,
      "y": 16,
      "z": -1,
      "name": "Wood_Oak_Trunk"
    },
    {
      "x": -1,
      "y": 17,
      "z": -1,
      "name": "Wood_Oak_Trunk"
    },
    {
      "x": -1,
      "y": 18,
      "z": -1,
      "name": "Wood_Oak_Trunk"
    },
    {
      "x": -1,
      "y": 19,
      "z": -1,
      "name": "Wood_Oak_Trunk"
    },
    {
      "x": -1,
      "y": 20,
      "z": -1,
      "name": "Wood_Oak_Trunk"
    },
    {
      "x": -1,
      "y": 21,
      "z": -1,
      "name": "Wood_Oak_Trunk"
    },
    {
      "x": -1,
      "y": 22,
      "z": -1,
      "name": "Wood_Oak_Trunk"
    },
    {
      "x": -1,
      "y": 23,
      "z": -1,
      "name": "Wood_Oak_Trunk"
    },
    {
      "x": -1,
      "y": 24,
      "z": -1,
      "name": "Wood_Oak_Trunk"
    },
    {
      "x": -1,
      "y": 25,
      "z": -1,
      "name": "Wood_Oak_Trunk"
    },
    {
      "x": -1,
      "y": 26,
      "z": -1,
      "name": "Wood_Oak_Trunk"
    },
    {
      "x": -1,
      "y": 27,
      "z": -1,
      "name": "Wood_Oak_Trunk"
    },
    {
      "x": -1,
      "y": 28,
      "z": -1,
      "name": "Wood_Oak_Trunk"
    },
    {
      "x": -1,
      "y": 29,
      "z": -1,
      "name": "Wood_Oak_Trunk"
    },
    {
      "x": -1,
      "y": 30,
      "z": -1,
      "name": "Wood_Oak_Trunk"
    },
    {
      "x": -1,
      "y": 31,
      "z": -1,
      "name": "Wood_Oak_Trunk"
    },
    {
